Workbook

Sheet Summary
A1: Sunrise Shore Mutual Water Company
A2: Financial Summary - multi-year overview (USD)
A3: Entity ID: cawc_0111 | Fiscal year ends December 31.
A5: Presentation standard: every figure on the statement tabs is verified to its source filing and shown clean. A cell the filing does not report reads "not reported" (never estimated, never guessed).
A6: Citations, confidence tiers, and the filed-vs-computed tie-out checks live on the "Sources & audit" tab, keyed by cell, so every number is fully traceable without cluttering the statements. These pages are ready to use as filed.
A8: Metric | B8: FY2021 | C8: FY2022 | D8: FY2023 | E8: FY2023 | F8: FY2024 | G8: FY2025
A9: Operating results (USD)
A10: Total revenue | B10: 90215 | C10: 64916 | D10: 49315 | E10: 6288 | F10: 164078 | G10: 128861
A11: Total expenses | B11: 49334 | C11: 62570 | D11: 41225 | E11: 41361 | F11: 154000 | G11: 135276
A12: Net income | B12: 40881 | C12: 2346 | D12: 8090 | E12: -35073 | F12: 10078 | G12: -6415
A14: Financial position (USD, end of year)
A15: Total assets | B15: 417466 | C15: 414093 | D15: 364265 | E15: 316875 | F15: 308939 | G15: 276635
A16: Total liabilities | B16: 123228 | C16: 109076 | D16: 89026 | E16: 76709 | F16: 55518 | G16: 33109
A17: Net assets | B17: 294238 | C17: 305017 | D17: 275239 | E17: 240166 | F17: 253421 | G17: 243526
A19: Headline ratios
A20: Operating margin | B20: 0.45315081 | C20: 0.03613901 | D20: 0.16404745 | E20: -5.5777672 | F20: 0.061422007 | G20: -0.049782324
A21: Revenue growth (YoY)
A22: Return on assets | B22: 0.097926538 | C22: 0.005665394 | D22: 0.022209106 | E22: -0.11068402 | F22: 0.032621327 | G22: -0.023189401
A24: Figures as reported in source filings (full provenance on the Sources & audit tab). Parentheses denote negatives; ratios are computed upstream in financials_annual.

Sheet Notes
A1: Notes
A2: Human annotations from the versioned store (data/notes/). Annotations only: they never change a reported figure or a confidence tier.
A4: Date | B4: Tag | C4: Author | D4: Note
A5: No notes recorded yet.

Sheet Financial Statements
A1: Sunrise Shore Mutual Water Company
A2: Financial Statements - income statement, balance sheet, cash flow, member income test (USD)
A3: Entity ID: cawc_0111 | Fiscal year ends December 31.
A5: INCOME STATEMENT - as reported (USD)
A6: Line item | B6: FY2021 | C6: FY2022 | D6: FY2023 | E6: FY2023 | F6: FY2024 | G6: FY2025
A7: Revenue
A8: Program service revenue
A9: Investment income
A10: Net rental income
A11: Net gain/(loss) on investment sales
A12: Other revenue
A13: Contributions & grants
A14: Total revenue
A16: Expenses
A17: Depreciation
A18: Interest expense
A19: Total expenses | B19: 49334 | C19: 62570 | D19: 41225 | E19: 41361 | F19: 154000 | G19: 135276
A21: Net income | B21: 40881 | C21: 2346 | D21: 8090 | E21: -35073 | F21: 10078 | G21: -6415
A24: BALANCE SHEET - as reported (USD, end of year)
A25: Line item | B25: FY2021 | C25: FY2022 | D25: FY2023 | E25: FY2023 | F25: FY2024 | G25: FY2025
A26: Assets
A27: Cash | B27: 84838 | C27: 64680 | D27: 64143 | E27: 34155 | F27: 18504 | G27: 10379
A28: Savings & temporary investments
A29: Accounts receivable
A30: Inventories
A31: Prepaid expenses
A32: Property, plant & equipment (gross)
A33: Less: accumulated depreciation
A34: Net property, plant & equipment | B34: 98140 | C34: 98140 | D34: 98140 | E34: 98140 | F34: 98140 | G34: 98140
A35: Total assets | B35: 417466 | C35: 414093 | D35: 364265 | E35: 316875 | F35: 308939 | G35: 276635
A37: Liabilities
A38: Accounts payable
A39: Mortgages & notes payable
A40: Total liabilities | B40: 123228 | C40: 109076 | D40: 89026 | E40: 76709 | F40: 55518 | G40: 33109
A42: Net Assets / Equity
A43: Capital stock
A44: Paid-in capital
A45: Retained earnings
A46: Net assets | B46: 294238 | C46: 305017 | D46: 275239 | E46: 240166 | F46: 253421 | G46: 243526
A49: CASH FLOW - derived proxy (USD)
...

Sheet Balance Sheet
A1: Sunrise Shore Mutual Water Company
A2: Balance Sheet - as reported (USD, end of year)
A3: Entity ID: cawc_0111 | Fiscal year ends December 31.
A5: Line item | B5: FY2021 | C5: FY2022 | D5: FY2023 | E5: FY2023 | F5: FY2024 | G5: FY2025
A6: Assets
A7: Cash | B7: 84838 | C7: 64680 | D7: 64143 | E7: 34155 | F7: 18504 | G7: 10379
A8: Savings & temporary investments
A9: Accounts receivable
A10: Inventories
A11: Prepaid expenses
A12: Property, plant & equipment (gross)
A13: Less: accumulated depreciation
A14: Net property, plant & equipment | B14: 98140 | C14: 98140 | D14: 98140 | E14: 98140 | F14: 98140 | G14: 98140
A15: Total assets | B15: 417466 | C15: 414093 | D15: 364265 | E15: 316875 | F15: 308939 | G15: 276635
A17: Liabilities
A18: Accounts payable
A19: Mortgages & notes payable
A20: Total liabilities | B20: 123228 | C20: 109076 | D20: 89026 | E20: 76709 | F20: 55518 | G20: 33109
A22: Net Assets / Equity
A23: Capital stock
A24: Paid-in capital
A25: Retained earnings
A26: Net assets | B26: 294238 | C26: 305017 | D26: 275239 | E26: 240166 | F26: 253421 | G26: 243526
A28: Balance check (assets − liab. − net assets) | B28: 0 | C28: 0 | D28: 0 | E28: 0 | F28: 0 | G28: 0
A30: Net PP&E is the reported ppe_net column (gross less accumulated depreciation). The balance check should be ~0 where all three totals are reported; a non-zero value flags a reporting or extraction discrepancy worth reviewing.

Sheet Form 990-EZ Parts I & II
A1: Sunrise Shore Mutual Water Company
A2: Form 990-EZ - Part I (revenue, expenses, net assets) and Part II (balance sheet), as filed (USD)
A3: Entity ID: cawc_0111 | Fiscal year ends December 31.
A5: Form 990-EZ line | B5: FY2021 | C5: FY2022 | D5: FY2023 | E5: FY2023 | F5: FY2024 | G5: FY2025
A6: Revenue (Part I)
A7: 1. Contributions, gifts, grants | B7: 11886 | C7: 16379 | D7: not reported | E7: not reported | F7: 100526 | G7: 91059
A8: 3. Membership dues and assessments | B8: 78329 | C8: 48387 | D8: 49165 | E8: 49165 | F8: 62902 | G8: 37652
A9: 8. Other revenue | B9: not reported | C9: 150 | D9: 150 | E9: 150 | F9: 650 | G9: 150
A10: 9. Total revenue | B10: 90215 | C10: 64916 | D10: 49315 | E10: 49315 | F10: 164078 | G10: 128861
A12: Expenses (Part I)
A13: 13. Fees for services (independent contractors) | B13: 5355 | C13: 6400 | D13: 6356 | E13: 6356 | F13: 107846 | G13: 100664
A14: 15. Printing, publications, postage | B14: not reported | C14: 62 | D14: 36 | E14: 36 | F14: 73 | G14: not reported
A15: 16. Other expenses | B15: 43979 | C15: 56108 | D15: 34833 | E15: 34833 | F15: 46081 | G15: 34612
A16: 17. Total expenses | B16: =SUM(B13:B15) | C16: =SUM(C13:C15) | D16: =SUM(D13:D15) | E16: =SUM(E13:E15) | F16: =SUM(F13:F15) | G16: =SUM(G13:G15)
A18: Net-assets reconciliation (Part I)
A19: 19. Net assets or fund balances, beginning of year | B19: 237934 | C19: 294238 | D19: 305017 | E19: 305017 | F19: 240166 | G19: 253421
A20: 18. Excess or (deficit) for the year | B20: 40881 | C20: 2346 | D20: 8090 | E20: 8090 | F20: 10078 | G20: -6415
A21: 21. Net assets or fund balances, end of year | B21: =SUM(B19,B20) | C21: =SUM(C19,C20) | D21: =SUM(D19,D20) | E21: =SUM(E19,E20) | F21: =SUM(F19,F20) | G21: =SUM(G19,G20)
A23: Balance sheet (Part II, end of year - column B)
A24: 22. Cash, savings, and investments | B24: 84838 | C24: 64680 | D24: 64143 | E24: 64143 | F24: 18504 | G24: 10379
A25: 23. Land and buildings | B25: 98140 | C25: 98140 | D25: 98140 | E25: 98140 | F25: 98140 | G25: 98140
A26: 24. Other assets | B26: 234488 | C26: 251273 | D26: 201982 | E26: 201982 | F26: 192295 | G26: 168116
A27: 25. Total assets | B27: =SUM(B24:B26) | C27: =SUM(C24:C26) | D27: =SUM(D24:D26) | E27: =SUM(E24:E26) | F27: =SUM(F24:F26) | G27: =SUM(G24:G26)
A28: 26. Total liabilities | B28: 123228 | C28: 109076 | D28: 89026 | E28: 89026 | F28: 55518 | G28: 33109
A29: 27. Net assets or fund balances | B29: 294238 | C29: 305017 | D29: 275239 | E29: 275239 | F29: 253421 | G29: 243526
A31: Form 990-EZ is the short form: revenue and expenses are on Part I and the balance sheet is the six-line Part II (no full-990 Parts VII-XI). Total expenses (line 17) and Total assets (line 25) are live SUMs of the lines above; Total revenue (line 9) is shown as filed because the EZ nets its lines 5-7 (sales of assets, gaming, inventory) into line 9 without itemizing them. Ending net assets (line 21) is recomputed live as beginning net assets (line 19) plus the excess or deficit (line 18); where the filer's own line 21 does not equal that sum, the variance is flagged red on the Sources & audit tab and carried exactly as filed, not reconciled. Every figure's citation and confidence are on the Sources & audit tab.

Sheet Cash flow proxies
A1: Sunrise Shore Mutual Water Company
A2: Cash Flow Proxies - derived (USD)
A3: Entity ID: cawc_0111 | Fiscal year ends December 31.
A5: PROXY ONLY. The source filings contain no statement of cash flows. Lines below are derived from the reported income statement and year-over-year balance-sheet changes; treat as directional estimates, not GAAP cash flows. The earliest year has no prior period, so its delta cells are blank.
A7: Proxy line (USD) | B7: FY2021 | C7: FY2022 | D7: FY2023 | E7: FY2023 | F7: FY2024 | G7: FY2025
A8: Operating
A9: Net income | B9: 40881 | C9: 2346 | D9: 8090 | E9: -35073 | F9: 10078 | G9: -6415
A10: + Depreciation (reported)
A11: − Δ Accounts receivable
A12: − Δ Inventories
A13: − Δ Prepaid expenses
A14: + Δ Accounts payable
A15: Operating cash flow proxy | C15: 2346 | D15: 8090 | E15: -35073 | F15: 10078 | G15: -6415
A17: Investing
A18: − Δ PP&E gross (capex proxy)
A20: Financing
A21: Δ Mortgages & notes payable
A23: Reconciliation
A24: Δ Cash + temp. investments (actual) | C24: -20158 | D24: -537 | E24: -29988 | F24: -15651 | G24: -8125
A26: The capex proxy assumes gross PP&E rises only via capital spending (it ignores disposals). 'Δ Cash + temp. investments (actual)' is the real reported change in liquid funds and is the most reliable line here; the operating/investing/financing proxies will not perfectly reconcile to it.

Sheet Ratios
A1: Sunrise Shore Mutual Water Company
A2: Financial Ratios
A3: Entity ID: cawc_0111 | Fiscal year ends December 31.
A5: Ratio | B5: FY2021 | C5: FY2022 | D5: FY2023 | E5: FY2023 | F5: FY2024 | G5: FY2025
A6: Profitability (computed upstream)
A7: Operating margin (NI / revenue) | B7: 0.45315081 | C7: 0.03613901 | D7: 0.16404745 | E7: -5.5777672 | F7: 0.061422007 | G7: -0.049782324
A8: Expense ratio (expenses / revenue) | B8: 0.54684919 | C8: 0.96386099 | D8: 0.83595255 | E8: 6.5777672 | F8: 0.93857799 | G8: 1.0497823
A9: Return on assets (NI / assets) | B9: 0.097926538 | C9: 0.005665394 | D9: 0.022209106 | E9: -0.11068402 | F9: 0.032621327 | G9: -0.023189401
A10: Revenue growth (YoY)
A12: Leverage & solvency
A13: Debt-to-assets (liab. / assets) | B13: 0.29518092 | C13: 0.26340943 | D13: 0.244399 | E13: 0.24207968 | F13: 0.17970538 | G13: 0.11968478
A14: Equity ratio (net assets / assets) | B14: 0.70481908 | C14: 0.73659057 | D14: 0.755601 | E14: 0.75792032 | F14: 0.82029462 | G14: 0.88031522
A16: Liquidity & asset profile (derived here)
A17: Current ratio (current assets / AP)
A18: Cash ratio ((cash+temp inv.) / total liab.) | B18: 0.68846366 | C18: 0.59298104 | D18: 0.72049738 | E18: 0.44525414 | F18: 0.33329731 | G18: 0.31347972
A19: Asset age proxy (accum. deprec. / gross PP&E)
A21: Upstream ratios are read from financials_annual; derived ratios are computed only where inputs are reported. Current ratio uses accounts payable as the current-liability proxy (the filings do not split current vs. long-term liabilities). Asset age proxy: a higher % implies older / more depreciated infrastructure.

Sheet Short filed periods
A1: Sunrise Shore Mutual Water Company
A2: Filed periods shorter than a full year, carried exactly as filed
A3: Entity ID: cawc_0111 | Fiscal year ends December 31.
A5: This system filed a reporting period shorter than twelve months because it changed its fiscal year end. The period is kept exactly as filed, with its own row, and no figure on it is annualized or scaled to a twelve-month equivalent. Metrics that measure activity over a period are not computed on it, because a ratio taken over a different number of months is a different measurement. It is excluded from this company's multi-year figures and from every cohort comparison for the same reason.
A6: This system's filed period end has moved. Earlier filings on the spine end May 31; the latest ends December 31. Both are carried as filed and neither is restated.
A8: FY2023: June 1, 2023 to December 31, 2023, 7 months
A9: Metric | B9: As stated | C9: Why it reads that way
A10: Operating ratio | B10: not a full year: 7-month transition period | C10: A flow metric measures activity over a period, so it is not computed on a period of a different length. The figure is not withheld for doubt; it would be a different measurement.
A11: Days cash on hand | B11: not a full year: 7-month transition period | C11: A flow metric measures activity over a period, so it is not computed on a period of a different length. The figure is not withheld for doubt; it would be a different measurement.
A12: Reinvestment ratio | B12: not a full year: 7-month transition period | C12: A flow metric measures activity over a period, so it is not computed on a period of a different length. The figure is not withheld for doubt; it would be a different measurement.
A13: Rate discipline | B13: not a full year: 7-month transition period | C13: A flow metric measures activity over a period, so it is not computed on a period of a different length. The figure is not withheld for doubt; it would be a different measurement.
A14: Equity as a share of assets | B14: 75.79% | C14: A balance sheet ratio, so the length of the period does not affect it. It is stated for this period and is read by no cohort figure, because this row is outside every window.
A15: Source: 990-EZ return header, period June 1, 2023 to December 31, 2023

Sheet Unit economics
A1: Sunrise Shore Mutual Water Company
A2: Unit economics - per-customer revenue by category (USD)
A3: Entity ID: cawc_0111 | Fiscal year ends December 31.
A5: Every metric here is PER CUSTOMER (a metered service connection). It is not a per-member figure; the member (shareholder) count is a different denominator, shown in the denominator block. The visible cell shows the value and its classification; the numerator, denominator, formula, and rationale are in each metric's LOGIC popup.
A6: Per-customer denominator (service connections) | C6: State Water Board eAR Section 4
A7: Total annual revenue (eAR Section 8b B1.8) | C7: eAR Section 8b total annual revenue not reported for this system.
A8: Primary source
A10: Revenue categories (value, classification, per customer, share)
A11: Revenue category | B11: Classification | C11: Value (USD) | D11: Per customer | E11: Share of revenue
A12: Water sales revenue | B12: not reported | C12: not reported | D12: not reported | E12: not reported
A13: Assessment revenue (990 program-service revenue not matched to eAR water-rate revenue) | B13: IMPOSSIBLE | C13: IMPOSSIBLE | D13: IMPOSSIBLE | E13: IMPOSSIBLE
A14: Meter revenue | B14: not reported | C14: not reported | D14: not reported | E14: not reported
A15: Overage or tiered penalty revenue | B15: not reported | C15: not reported | D15: not reported | E15: not reported
A17: Water sales revenue - not reported
A18: Not reported: this system filed an eAR but no Section 8b revenue block, so there is no filed water-sales figure. Not fallen back to a different year.
A19: Reason: No filed eAR Section 8b water-rate revenue for this system.
A21: Assessment revenue (990 program-service revenue not matched to eAR water-rate revenue) - IMPOSSIBLE
A22: Not computed. A period-aligned residual is not possible for this filer.
A23: Reason: Not derivable. The eAR Section 8b is reporting year None while the Form 990 fiscal year ends None; the two period ends are not aligned, so a period-aligned residual cannot be computed.
A25: Meter revenue - not reported
A26: Not reported. This category is not built because doing so would double-count.
A27: Reason: The eAR Section 8a reports a base/meter rate PRICE, but the filing carries no meter revenue line and no tier volume, and the base charge is already inside the water-sales revenue (eAR Section 8b water rates). Building a separate meter figure would double-count. Not backed into from a total.
A29: Overage or tiered penalty revenue - not reported
A30: Not reported. This category is not built because doing so would double-count.
A31: Reason: The eAR Section 8a reports tiered/overage rate PRICES, but the filing carries no overage revenue and no tier consumption volume, and any overage billed is already inside the water-sales revenue. Building it would double-count. Not backed into from a total.

Sheet Rate structure
A1: Sunrise Shore Mutual Water Company
A2: Rate structure and representative bill - eAR Section 8a
A3: Entity ID: cawc_0111 | Fiscal year ends December 31.
A5: This block is a rate-schedule illustration at defined usage levels. It is NOT billed revenue and not a claim about any real customer's usage. The revenue side of unit economics is the separate Unit Economics block.
A6: No filed eAR Section 8a rate schedule is staged for this system.

Sheet Operational metrics
A1: Sunrise Shore Mutual Water Company
A2: Operational metrics - plant per acre, density, terrain
A3: Entity ID: cawc_0111 | Fiscal year ends December 31.
A5: Connections per acre
A6: Connections per acre | B6: 1.72 | C6: 42 connections / 24.4 acres. CA State Water Board SABL SERVICE_CONNECTIONS; Geodesic area (WGS84 spherical excess) of the SABL service-area polygon.

Sheet Supply & weather
A1: Sunrise Shore Mutual Water Company
A2: Supply and weather indicators (DWR water year)
A3: Entity ID: cawc_0111 | Fiscal year ends December 31.
A5: Reporting calendar: Different reporting periods. The DWR water year runs October 1 to September 30; this system's fiscal year ends December 31, so the two period ends are three months apart. Read the two side by side with that in mind. Neither series is recast: both are reported as filed. A water year is named for the calendar year it ends in, so WY2024 and FY2024 share a number without covering the same twelve months.
A7: Indicator | B7: WY2021 | C7: WY2022 | D7: WY2023 | E7: WY2024 | F7: WY2025
A8: Water-year type (Sacramento Valley) | B8: Critical | C8: Critical | D8: Wet | E8: Above Normal | F8: not reported
A9: Peak drought, county County | B9: not reported | C9: not reported | D9: not reported | E9: not reported | F9: not reported
A10: Precip, percent of normal (8-Station Index) | B10: 48 | C10: 86 | D10: 133 | E10: 96 | F10: 113
A11: Snowpack, April 1 percent of average | B11: 59% | C11: 38% | D11: 237% | E11: 110% | F11: 96%
A12: State Water Project allocation | B12: 5% | C12: 5% | D12: 100% | E12: 40% | F12: 50%

Sheet How this was built
A1: Sunrise Shore Mutual Water Company
A2: How this was built - forensic lineage
A3: Entity ID: cawc_0111 | Fiscal year ends December 31.
A5: A plain account of the forensic lineage behind the hard-to-source metrics: what sources were checked, what was found, what was derived, and what could not be built and why. Every figure marked DERIVED or IMPOSSIBLE above is traceable to a line here.
A7: Water-sales revenue per customer - not reported
A8: Sources checked | B8: State Water Board eAR Section 8b (water-rate revenue B1.1/B1.2); State Water Board eAR Section 4 (connection count, same reporting year); audited financial statement (secondary cross-check, where published)
A9: What was found | B9: The eAR Section 8b reports water-rate revenue for reporting year None, so this is a DIRECT filed figure; per customer it is divided by the eAR Section 4 connection count for the same reporting year, so numerator and denominator share the year.
A11: Assessment revenue (residual) - IMPOSSIBLE
A12: Sources checked | B12: Form 990 Part VIII line 2 (program-service revenue); State Water Board eAR Section 8b (water-rate revenue B1.1/B1.2); eAR Section 8b filer comment (WRRevenueComments)
A13: What was found | B13: A period-aligned residual cannot be computed for this filer, so the metric is rendered IMPOSSIBLE rather than guessed.
A14: Caveat | B14: Not derivable. The eAR Section 8b is reporting year None while the Form 990 fiscal year ends None; the two period ends are not aligned, so a period-aligned residual cannot be computed.
A16: Meter revenue - not reported
A17: Sources checked | B17: State Water Board eAR Section 8a (rate prices); State Water Board eAR Section 8b (revenue lines); audited financial statement
A18: What was found | B18: The rate price exists in Section 8a but no revenue or tier volume is reported, and the base charge is already inside water sales.
A19: Caveat | B19: The eAR Section 8a reports a base/meter rate PRICE, but the filing carries no meter revenue line and no tier volume, and the base charge is already inside the water-sales revenue (eAR Section 8b water rates). Building a separate meter figure would double-count. Not backed into from a total.
A21: Overage / tiered-penalty revenue - not reported
A22: Sources checked | B22: State Water Board eAR Section 8a (rate prices); State Water Board eAR Section 8b (revenue lines); audited financial statement
A23: What was found | B23: The rate price exists in Section 8a but no revenue or tier volume is reported, and the base charge is already inside water sales.
A24: Caveat | B24: The eAR Section 8a reports tiered/overage rate PRICES, but the filing carries no overage revenue and no tier consumption volume, and any overage billed is already inside the water-sales revenue. Building it would double-count. Not backed into from a total.
A26: eAR Section 8b reporting-period basis - sourced
A27: Sources checked | B27: eAR Section 8b B0.1 (WRFinancialReportingPeriod); eAR Section 8b B0.2 (WRFiscalYearStartDate)
A28: What was found | B28: The reporting basis (fiscal vs calendar year) is read from the filer's own B0.1/B0.2 answer and staged verbatim, never hardcoded, so the 990 comparison and the residual are period-aligned.
A30: Member (shareholder) count denominator - not reported
A31: Sources checked | B31: Form 990 (no member count stated); company website
A32: What was found | B32: No filing states a member/shareholder count, so the per-member unit economics read not reported rather than borrowing the connection count.
A34: Water volume delivered (acre-feet) - not reported
A35: Sources checked | B35: Form 990 (not in the filing); Consumer Confidence Report; eAR Section 6 (PRA-gated)
A36: What was found | B36: Volume delivered in acre-feet is not in the Form 990 and the CCR states only a source mix, so the per-acre-foot metrics read not reported; the eAR Section 6 is named as the source still needed.

Sheet Anomaly Flags
A1: Sunrise Shore Mutual Water Company
A2: Anomaly Flags (automated; kept separate from the clean statements)
A3: Entity ID: cawc_0111 | Fiscal year ends December 31.
A5: Material irregularities found automatically in the filed financials by the Hydronomics anomaly flagger. Each flag has two clearly separated layers. WHAT is mechanical, certain, and sourced: the exact filed lines, years, and amounts, carried as filed and never reconciled. WHY is attempted: the filing's own narrative is checked first, and when it states no reason a single best-guess hypothesis is shown, clearly labelled as a guess that is not in the filing and is not a verified figure.
A7: Flag: FY2023 opening net assets differ from FY2022 closing
A8: Affected figure | B8: Net assets FY2023
A9: Confidence | B9: high
A10: What happened (filed, sourced) | B10: The company filed $275,239 as its beginning net assets for FY2023 and $305,017 as its ending net assets for FY2022, a difference of $-29,778. Both figures are carried exactly as each year's own filing reports them. Neither is adjusted to match the other.
A11: Source lines | B11: - FY2023 net assets, beginning of year (as filed): $275,239 - FY2022 net assets, end of year (as filed): $305,017 - Difference: $-29,778
A12: Confidence reasoning | B12: Both are direct filed line items read from two different returns, so the difference between them is high confidence as an observation. What caused it is not stated on either form.
A13: Why (not stated in the filing) | B13: The filing does not state a reason.
A14: Possible explanation (guess) | B14: Possible explanation, not stated in filing: a beginning balance that differs from the prior year's ending balance usually means the earlier year was restated, or a balance-sheet line was reclassified between the two filings. This is an educated guess, not something either filing says.

Sheet Sources & audit
A1: Sunrise Shore Mutual Water Company
A2: Sources & audit - full provenance and tie-outs (kept off the statements so they read clean)
A3: Entity ID: cawc_0111 | Fiscal year ends December 31.
A5: Presentation standard: every figure on the statement tabs is verified to its source filing and shown clean. A cell the filing does not report reads "not reported" (never estimated, never guessed).
A6: Citations, confidence tiers, and the filed-vs-computed tie-out checks live on the "Sources & audit" tab, keyed by cell, so every number is fully traceable without cluttering the statements. These pages are ready to use as filed.
A8: A. Filing provenance (one row per staged extraction)
A9: Fiscal year | B9: Period end | C9: Filing type | D9: Confidence | E9: Extraction ID | F9: Object ID | G9: Extracted by | H9: Extracted at | I9: Source URL
A10: FY2021 | B10: 2021-05-31 | C10: 990-EZ | D10: high | E10: c7765b45-6b3c-43ed-b4da-cecf5237be04 | F10: 202102569349200835 | G10: claude-opus-5 | H10: 2026-09-23T17:59:36+00:00 | I10: https://apps.irs.gov/pub/epostcard/990/xml/2021/2021_TEOS_XML_01A.zip#202102569349200835_public.xml
A11: FY2022 | B11: 2022-05-31 | C11: 990-EZ | D11: high | E11: 1edf6793-a297-42d1-b0bf-a1753c0430f3 | F11: 202212449349200831 | G11: claude-opus-5 | H11: 2026-09-23T17:59:36+00:00 | I11: https://apps.irs.gov/pub/epostcard/990/xml/2022/2022_TEOS_XML_01A.zip#202212449349200831_public.xml
A12: FY2023 | B12: 2023-05-31 | C12: 990-EZ | D12: high | E12: 2e120290-6b99-47ec-9abe-eedca4d0d2e6 | F12: 202323009349201282 | G12: claude-opus-5 | H12: 2026-09-23T17:59:36+00:00 | I12: https://apps.irs.gov/pub/epostcard/990/xml/2023/2023_TEOS_XML_11A.zip#202323009349201282_public.xml
A13: FY2023 | B13: 2023-12-31 | C13: 990-EZ | D13: high | E13: 76a3da77-c4a9-47fe-9837-58c0a4e9b013 | F13: 202410759349201256 | G13: claude-opus-5 | H13: 2026-09-23T17:59:36+00:00 | I13: https://apps.irs.gov/pub/epostcard/990/xml/2024/2024_TEOS_XML_03A.zip#202410759349201256_public.xml
A14: FY2024 | B14: 2024-12-31 | C14: 990-EZ | D14: high | E14: 393d4559-01e0-497a-975f-b0b1304a7dea | F14: 202511039349201446 | G14: claude-opus-5 | H14: 2026-09-23T17:59:36+00:00 | I14: https://apps.irs.gov/pub/epostcard/990/xml/2025/2025_TEOS_XML_04A.zip#202511039349201446_public.xml
A15: FY2025 | B15: 2025-12-31 | C15: 990-EZ | D15: high | E15: 37f868a2-df33-466c-ad0a-0890f86c331a | F15: 202620539349200602 | G15: claude-opus-5 | H15: 2026-09-23T17:59:36+00:00 | I15: https://apps.irs.gov/pub/epostcard/990/xml/2026/2026_TEOS_XML_03A.zip#202620539349200602_public.xml
A17: B. Figure citations (every figure on the statement tabs, keyed by cell)
A18: Tab | B18: Cell | C18: Line item | D18: Form 990 line | E18: Key path | F18: Confidence | G18: As filed
A19: Form 990-EZ Parts I & II | B19: B7 | C19: 1. Contributions, gifts, grants | D19: Part I line 1 | E19: part_i_revenue_expenses.contributions_grants | F19: high | G19: 11886
A20: Form 990-EZ Parts I & II | B20: C7 | C20: 1. Contributions, gifts, grants | D20: Part I line 1 | E20: part_i_revenue_expenses.contributions_grants | F20: high | G20: 16379
A21: Form 990-EZ Parts I & II | B21: F7 | C21: 1. Contributions, gifts, grants | D21: Part I line 1 | E21: part_i_revenue_expenses.contributions_grants | F21: high | G21: 100526
A22: Form 990-EZ Parts I & II | B22: G7 | C22: 1. Contributions, gifts, grants | D22: Part I line 1 | E22: part_i_revenue_expenses.contributions_grants | F22: high | G22: 91059
A23: Form 990-EZ Parts I & II | B23: B8 | C23: 3. Membership dues and assessments | D23: Part I line 3 | E23: part_i_revenue_expenses.membership_dues | F23: high | G23: 78329
A24: Form 990-EZ Parts I & II | B24: C8 | C24: 3. Membership dues and assessments | D24: Part I line 3 | E24: part_i_revenue_expenses.membership_dues | F24: high | G24: 48387
A25: Form 990-EZ Parts I & II | B25: D8 | C25: 3. Membership dues and assessments | D25: Part I line 3 | E25: part_i_revenue_expenses.membership_dues | F25: high | G25: 49165
A26: Form 990-EZ Parts I & II | B26: E8 | C26: 3. Membership dues and assessments | D26: Part I line 3 | E26: part_i_revenue_expenses.membership_dues | F26: high | G26: 49165
A27: Form 990-EZ Parts I & II | B27: F8 | C27: 3. Membership dues and assessments | D27: Part I line 3 | E27: part_i_revenue_expenses.membership_dues | F27: high | G27: 62902
A28: Form 990-EZ Parts I & II | B28: G8 | C28: 3. Membership dues and assessments | D28: Part I line 3 | E28: part_i_revenue_expenses.membership_dues | F28: high | G28: 37652
A29: Form 990-EZ Parts I & II | B29: C9 | C29: 8. Other revenue | D29: Part I line 8 | E29: part_i_revenue_expenses.other_revenue_total | F29: high | G29: 150
A30: Form 990-EZ Parts I & II | B30: D9 | C30: 8. Other revenue | D30: Part I line 8 | E30: part_i_revenue_expenses.other_revenue_total | F30: high | G30: 150
... A97: Form 990-EZ Parts I & II | B97: G29 | C97: 27. Net assets or fund balances | D97: Part II line 27 col B | E97: part_ii_balance_sheet.net_assets_eoy | F97: high | G97: 243526
A99: C. Tie-out checks (filed vs computed; any nonzero variance is flagged red)
A100: Tab | B100: Check | C100: Fiscal year | D100: Filed | E100: Computed | F100: Variance (computed - filed)
A101: Form 990-EZ Parts I & II | B101: 17. Total expenses | C101: FY2021 | D101: 49334 | E101: ='Form 990-EZ Parts I & II'!B16 | F101: =E101-D101
A102: Form 990-EZ Parts I & II | B102: 17. Total expenses | C102: FY2022 | D102: 62570 | E102: ='Form 990-EZ Parts I & II'!C16 | F102: =E102-D102
A103: Form 990-EZ Parts I & II | B103: 17. Total expenses | C103: FY2023 | D103: 41225 | E103: ='Form 990-EZ Parts I & II'!E16 | F103: =E103-D103
A104: Form 990-EZ Parts I & II | B104: 17. Total expenses | C104: FY2023 | D104: 41225 | E104: ='Form 990-EZ Parts I & II'!E16 | F104: =E104-D104
A105: Form 990-EZ Parts I & II | B105: 17. Total expenses | C105: FY2024 | D105: 154000 | E105: ='Form 990-EZ Parts I & II'!F16 | F105: =E105-D105
A106: Form 990-EZ Parts I & II | B106: 17. Total expenses | C106: FY2025 | D106: 135276 | E106: ='Form 990-EZ Parts I & II'!G16 | F106: =E106-D106
A107: Form 990-EZ Parts I & II | B107: 21. Net assets or fund balances, end of year | C107: FY2021 | D107: 294238 | E107: ='Form 990-EZ Parts I & II'!B21 | F107: =E107-D107
A108: Form 990-EZ Parts I & II | B108: 21. Net assets or fund balances, end of year | C108: FY2022 | D108: 305017 | E108: ='Form 990-EZ Parts I & II'!C21 | F108: =E108-D108
A109: Form 990-EZ Parts I & II | B109: 21. Net assets or fund balances, end of year | C109: FY2023 | D109: 275239 | E109: ='Form 990-EZ Parts I & II'!E21 | F109: =E109-D109
A110: Form 990-EZ Parts I & II | B110: 21. Net assets or fund balances, end of year | C110: FY2023 | D110: 275239 | E110: ='Form 990-EZ Parts I & II'!E21 | F110: =E110-D110
...

Sheet Provenance
A1: Build provenance | B1: Built from source commit d418ffb17485 (2026-10-06); source fingerprint a75a8eee82c65cf7; 192 companies (179 retail mutual, 4 irrigation mutual, 3 mutual, no PWSID, purpose not stated, 2 frozen non-mutual (special district), 2 wholesale mutual, 1 frozen non-mutual (investor-owned), 1 frozen non-mutual (municipal)); 91 gates; build id 3d08d6d2a855.
A2: source_commit | B2: d418ffb174855ab78000d391d42f898397b0d8aa
A3: source_commit_date | B3: 2026-10-06
A4: source_fingerprint | B4: a75a8eee82c65cf7096931f06e18affdc28686a02895b46538e7298b57c04d94
A5: gate_count | B5: 91
A6: build_id | B6: 3d08d6d2a855
A7: registry: frozen non-mutual (investor-owned) | B7: 1
A8: registry: frozen non-mutual (municipal) | B8: 1
A9: registry: frozen non-mutual (special district) | B9: 2
A10: registry: irrigation mutual | B10: 4
A11: registry: mutual, no PWSID, purpose not stated | B11: 3
A12: registry: retail mutual | B12: 179
A13: registry: wholesale mutual | B13: 2
