Workbook

Sheet Summary
A1: Baron Canyon Mutual Water Company Inc
A2: Financial Summary - multi-year overview (USD)
A3: Entity ID: cawc_0060 | Fiscal year ends June 30.
A5: Presentation standard: every figure on the statement tabs is verified to its source filing and shown clean. A cell the filing does not report reads "not reported" (never estimated, never guessed).
A6: Citations, confidence tiers, and the filed-vs-computed tie-out checks live on the "Sources & audit" tab, keyed by cell, so every number is fully traceable without cluttering the statements. These pages are ready to use as filed.
A8: Metric | B8: FY2020 | C8: FY2021 | D8: FY2022 | E8: FY2023 | F8: FY2024 | G8: FY2025
A9: Operating results (USD)
A10: Total revenue | B10: 51001 | C10: 60591 | D10: 65897 | E10: 170283 | F10: 639401 | G10: 1155136
A11: Total expenses | B11: 54005 | C11: 56357 | D11: 80707 | E11: 144270 | F11: 564421 | G11: 1090610
A12: Net income | B12: -3004 | C12: 4234 | D12: -14810 | E12: 26013 | F12: 74980 | G12: 64526
A14: Financial position (USD, end of year)
A15: Total assets | B15: 141316 | C15: 145147 | D15: 139893 | E15: 198740 | F15: 281683 | G15: 674968
A16: Total liabilities | B16: 4168 | C16: 3765 | D16: 9675 | E16: 41569 | F16: 49532 | G16: 439413
A17: Net assets | B17: 137148 | C17: 141382 | D17: 130218 | E17: 157171 | F17: 232151 | G17: 235555
A19: Headline ratios
A20: Operating margin | B20: -0.058900806 | C20: 0.069878365 | D20: -0.22474468 | E20: 0.15276334 | F20: 0.117266 | G20: 0.055860089
A21: Revenue growth (YoY) | F21: 2.7549315 | G21: 0.80659086
A22: Return on assets | B22: -0.021257324 | C22: 0.029170427 | D22: -0.10586663 | E22: 0.1308896 | F22: 0.26618575 | G22: 0.095598606
A24: Figures as reported in source filings (full provenance on the Sources & audit tab). Parentheses denote negatives; ratios are computed upstream in financials_annual.

Sheet Notes
A1: Notes
A2: Human annotations from the versioned store (data/notes/). Annotations only: they never change a reported figure or a confidence tier.
A4: Date | B4: Tag | C4: Author | D4: Note
A5: 2026-08-31 | B5: clarification | C5: Claude | D5: Form type changes mid-history: this filer filed the Form 990-EZ for FY2020 through FY2023 and the full Form 990 for FY2024 and FY2025, and both are staged. The FY2020 return sits in processing year 2020, which predates the current IRS bulk archive naming and ships as download990xml_2020_4.zip; a scan starting at the 2021 index does not see it. filing_type is recorded per year rather than per company because it selects the projection migration and the validator dialect.

Sheet Financial Statements
A1: Baron Canyon Mutual Water Company Inc
A2: Financial Statements - income statement, balance sheet, cash flow, member income test (USD)
A3: Entity ID: cawc_0060 | Fiscal year ends June 30.
A5: INCOME STATEMENT - as reported (USD)
A6: Line item | B6: FY2020 | C6: FY2021 | D6: FY2022 | E6: FY2023 | F6: FY2024 | G6: FY2025
A7: Revenue
A8: Program service revenue | F8: 376858 | G8: 292261
A9: Investment income | F9: 3269 | G9: 3761
A10: Net rental income
A11: Net gain/(loss) on investment sales
A12: Other revenue
A13: Contributions & grants | F13: 259274 | G13: 859114
A14: Total revenue | F14: 639401 | G14: 1155136
A16: Expenses
A17: Depreciation
A18: Interest expense
A19: Total expenses | B19: 54005 | C19: 56357 | D19: 80707 | E19: 144270 | F19: 564421 | G19: 1090610
A21: Net income | B21: -3004 | C21: 4234 | D21: -14810 | E21: 26013 | F21: 74980 | G21: 64526
A24: BALANCE SHEET - as reported (USD, end of year)
A25: Line item | B25: FY2020 | C25: FY2021 | D25: FY2022 | E25: FY2023 | F25: FY2024 | G25: FY2025
A26: Assets
A27: Cash | B27: 138727 | C27: 138521 | D27: 131175 | E27: 197850 | F27: 281214 | G27: 623178
A28: Savings & temporary investments
A29: Accounts receivable | F29: 303 | G29: 1624
A30: Inventories
A31: Prepaid expenses
A32: Property, plant & equipment (gross)
A33: Less: accumulated depreciation
A34: Net property, plant & equipment
A35: Total assets | B35: 141316 | C35: 145147 | D35: 139893 | E35: 198740 | F35: 281683 | G35: 674968
A37: Liabilities
A38: Accounts payable | F38: 20417 | G38: 23601
A39: Mortgages & notes payable
A40: Total liabilities | B40: 4168 | C40: 3765 | D40: 9675 | E40: 41569 | F40: 49532 | G40: 439413
A42: Net Assets / Equity
A43: Capital stock
A44: Paid-in capital
A45: Retained earnings
A46: Net assets | B46: 137148 | C46: 141382 | D46: 130218 | E46: 157171 | F46: 232151 | G46: 235555
A49: CASH FLOW - derived proxy (USD)
...

Sheet Balance Sheet
A1: Baron Canyon Mutual Water Company Inc
A2: Balance Sheet - as reported (USD, end of year)
A3: Entity ID: cawc_0060 | Fiscal year ends June 30.
A5: Line item | B5: FY2020 | C5: FY2021 | D5: FY2022 | E5: FY2023 | F5: FY2024 | G5: FY2025
A6: Assets
A7: Cash | B7: 138727 | C7: 138521 | D7: 131175 | E7: 197850 | F7: 281214 | G7: 623178
A8: Savings & temporary investments
A9: Accounts receivable | F9: 303 | G9: 1624
A10: Inventories
A11: Prepaid expenses
A12: Property, plant & equipment (gross)
A13: Less: accumulated depreciation
A14: Net property, plant & equipment
A15: Total assets | B15: 141316 | C15: 145147 | D15: 139893 | E15: 198740 | F15: 281683 | G15: 674968
A17: Liabilities
A18: Accounts payable | F18: 20417 | G18: 23601
A19: Mortgages & notes payable
A20: Total liabilities | B20: 4168 | C20: 3765 | D20: 9675 | E20: 41569 | F20: 49532 | G20: 439413
A22: Net Assets / Equity
A23: Capital stock
A24: Paid-in capital
A25: Retained earnings
A26: Net assets | B26: 137148 | C26: 141382 | D26: 130218 | E26: 157171 | F26: 232151 | G26: 235555
A28: Balance check (assets − liab. − net assets) | B28: 0 | C28: 0 | D28: 0 | E28: 0 | F28: 0 | G28: 0
A30: Net PP&E is the reported ppe_net column (gross less accumulated depreciation). The balance check should be ~0 where all three totals are reported; a non-zero value flags a reporting or extraction discrepancy worth reviewing.

Sheet Officers & contractors
A1: Baron Canyon Mutual Water Company Inc
A2: Officers, Directors & Contractors - Form 990 Part VII (FY2025; USD)
A3: Entity ID: cawc_0060 | Fiscal year ends June 30.
A5: Section A - Officers, directors, trustees, key employees
A6: Name | B6: Title | C6: Reportable comp (org) | D6: Reportable comp (related) | E6: Other comp | F6: Total compensation
A7: BILL CHADWICK | B7: PRESIDENT | C7: 0 | D7: 0 | E7: 0 | F7: 0
A8: THOMAS BOWER | B8: VICE PRESIDE | C8: 0 | D8: 0 | E8: 0 | F8: 0
A9: PAUL GREILING | B9: TREASURER | C9: 0 | D9: 0 | E9: 0 | F9: 0
A10: COLBY COUTER | B10: SECRETARY | C10: 0 | D10: 0 | E10: 0 | F10: 0
A12: Section B - Independent contractors (over $100,000)
A13: Contractor | B13: Services | C13: Compensation
A14: CROSNO CONSTRUCTION | B14: CONSTRUCTION | C14: 609590
A15: WATER SYSTEMS CONSULTING | B15: WATER SYSTEM RM | C15: 210100
A16: HARTZELL GENERAL ENGINEERING | B16: ENGINEERING | C16: 180556
A18: Section A lists every officer, director, trustee and key employee filed for the latest year; the two with the highest total compensation are highlighted. Total compensation is computed (reportable org + related + other). Section B lists each independent contractor paid over $100,000; the return reports 3 such contractor(s). Source and confidence for every figure are on the Sources & audit tab.

Sheet Revenue (detail)
A1: Baron Canyon Mutual Water Company Inc
A2: Revenue - Form 990 Part VIII (USD)
A3: Entity ID: cawc_0060 | Fiscal year ends June 30.
A5: Part VIII line | B5: FY2024 | C5: FY2025
A6: Revenue by category
A7: 1h. Total contributions, gifts, grants | B7: 259274 | C7: 859114
A8: 2g. Total program service revenue | B8: 376858 | C8: 292261
A9: 3. Investment income | B9: 3269 | C9: 3761
A10: 6d. Net rental income | B10: not reported | C10: not reported
A11: 7d. Net gain/(loss) from investment sales | B11: not reported | C11: not reported
A12: 11e. Other revenue | B12: not reported | C12: not reported
A13: 12. Total revenue | B13: =SUM(B7:B12) | C13: =SUM(C7:C12)
A15: Program service revenue detail - FY2025 (lines 2a-2f)
A16: Description | B16: Business code | C16: Total revenue
A17: SPECIAL ASSESSMENTS | B17: 839900 | C17: 150000
A18: MEMBER-RELATED INCOME | B18: 839900 | C18: 78541
A19: MEMBER WATER FEES | B19: 839900 | C19: 63720
A20: Revenue category subtotals are as filed. Total revenue (line 12) is a live SUM of the category cells above; its tie-out to the filed total is on the Sources & audit tab. Program service revenue detail is shown for the latest year, with its sum-to-line-2g check on that same audit tab.

Sheet Operating expenses (detail)
A1: Baron Canyon Mutual Water Company Inc
A2: Statement of Functional Expenses - Form 990 Part IX (USD)
A3: Entity ID: cawc_0060 | Fiscal year ends June 30.
A5: Part IX line (column A Total) | B5: FY2024 | C5: FY2025
A6: Functional expenses, column A Total - by year
A7: 11a. Fees for services: management | B7: 7675 | C7: 8400
A8: 11b. Fees for services: legal | B8: 3604 | C8: 864
A9: 13. Office expenses | B9: 1621 | C9: 761
A10: 23. Insurance | B10: 5451 | C10: 6363
A11: 24. RESERVE EXPENSES | B11: 513115 | C11: 1042095
A12: 24. REPAIRS/MAINTENANCE | B12: 21773 | C12: 16014
A13: 24. ELECTRIC | B13: 8211 | C13: 10350
A14: 24. LICENSES, FEES & PERMITS | B14: 2971 | C14: 3308
A15: 24e. All other expenses | B15: not reported | C15: 2455
A16: 25. Total functional expenses | B16: =SUM(B7:B15) | C16: =SUM(C7:C15)
A18: Functional column split - FY2025 (col A = B + C + D)
A19: Part IX line | B19: A. Total | C19: B. Program services | D19: C. Management & general | E19: D. Fundraising
A20: 11a. Fees for services: management | B20: 8400 | C20: 8400
A21: 11b. Fees for services: legal | B21: 864 | C21: 864
A22: 13. Office expenses | B22: 761 | C22: 761
A23: 23. Insurance | B23: 6363 | C23: 6363
A24: 25. Total (filed col A / B / C / D) | B24: 1090610 | C24: 1090610 | D24: 0 | E24: 0
A26: Top block: each Part IX line, column A (Total), by year, as filed. Total functional expenses (line 25) is a live SUM of the line cells; its tie-out to the filed total is on the Sources & audit tab. Filer-itemized 24a-24d rows show the most recent year's as-filed wording; rows are aligned across years case-insensitively with collapsed spacing, so a line filed only in a different capitalization or spacing shares one row, while genuinely different wording stays a separate row (every as-filed variant is recorded on the Sources & audit tab). Lower block: the program / management / fundraising split for the latest year, with its col A = B + C + D check on the audit tab. Lines this filer does not report are omitted rather than shown empty.

Sheet Balance sheet (detail)
A1: Baron Canyon Mutual Water Company Inc
A2: Balance Sheet - Form 990 Part X (end of year, USD)
A3: Entity ID: cawc_0060 | Fiscal year ends June 30.
A5: Part X line (column B, EOY) | B5: FY2024 | C5: FY2025
A6: Assets
A7: 1. Cash - non-interest-bearing | B7: 281214 | C7: 623178
A8: 4. Accounts receivable, net | B8: 303 | C8: 1624
A9: 15. Other assets | B9: 166 | C9: 50166
A10: 16. Total assets | B10: =SUM(B7:B9) | C10: =SUM(C7:C9)
A12: Liabilities
A13: 17. Accounts payable and accrued expenses | B13: 20417 | C13: 23601
A14: 19. Deferred revenue | B14: 29115 | C14: 812
A15: 25. Other liabilities | B15: not reported | C15: 415000
A16: 26. Total liabilities | B16: =SUM(B13:B15) | C16: =SUM(C13:C15)
A18: Net assets / fund balances
A19: 27. Net assets without donor restrictions | B19: -18574 | C19: -178518
A20: 28. Net assets with donor restrictions | B20: 250725 | C20: 414073
A21: 32. Total net assets / fund balances | B21: =SUM(B19:B20) | C21: =SUM(C19:C20)
A23: Every Part X line is end-of-year (column B), as filed. Section totals (lines 16 / 26 / 32) are live SUMs of the lines above; their tie-outs and the balance-sheet identity (16 = 26 + 32) are on the Sources & audit tab. This filer files as a non-FASB mutual, so net assets sit on lines 29-31 (capital stock / paid-in capital / retained earnings); lines this filer does not report are omitted. Lines 10a/10b net into line 10c (shown).

Sheet Net-assets reconciliation
A1: Baron Canyon Mutual Water Company Inc
A2: Reconciliation of Net Assets - Form 990 Part XI (USD)
A3: Entity ID: cawc_0060 | Fiscal year ends June 30.
A5: Part XI line | B5: FY2024 | C5: FY2025
A6: Reconciliation
A7: 4. Net assets, beginning of year | B7: 157171 | C7: 232151
A8: 3. Revenue less expenses | B8: 74980 | C8: 64526
A9: 8. Prior period adjustments | B9: not reported | C9: not reported
A10: 9. Other changes in net assets | B10: not reported | C10: -61122
A11: 10. Net assets, end of year | B11: =SUM(B7,B8,B9,B10) | C11: =SUM(C7,C8,C9,C10)
A13: Part XI reconciles beginning to ending net assets. Ending net assets (line 10) is a live formula: beginning balance (line 4) + revenue less expenses (line 3) + prior-period adjustments (8) + other changes (9). Its tie-out to the filed line 10 (and to Part X line 32) is on the Sources & audit tab. Lines 5-7 (unrealized gains, donated services, investment expenses) are not filed by this entity.

Sheet Cash flow proxies
A1: Baron Canyon Mutual Water Company Inc
A2: Cash Flow Proxies - derived (USD)
A3: Entity ID: cawc_0060 | Fiscal year ends June 30.
A5: PROXY ONLY. The source filings contain no statement of cash flows. Lines below are derived from the reported income statement and year-over-year balance-sheet changes; treat as directional estimates, not GAAP cash flows. The earliest year has no prior period, so its delta cells are blank.
A7: Proxy line (USD) | B7: FY2020 | C7: FY2021 | D7: FY2022 | E7: FY2023 | F7: FY2024 | G7: FY2025
A8: Operating
A9: Net income | B9: -3004 | C9: 4234 | D9: -14810 | E9: 26013 | F9: 74980 | G9: 64526
A10: + Depreciation (reported)
A11: − Δ Accounts receivable | G11: -1321
A12: − Δ Inventories
A13: − Δ Prepaid expenses
A14: + Δ Accounts payable | G14: 3184
A15: Operating cash flow proxy | C15: 4234 | D15: -14810 | E15: 26013 | F15: 74980 | G15: 66389
A17: Investing
A18: − Δ PP&E gross (capex proxy)
A20: Financing
A21: Δ Mortgages & notes payable
A23: Reconciliation
A24: Δ Cash + temp. investments (actual) | C24: -206 | D24: -7346 | E24: 66675 | F24: 83364 | G24: 341964
A26: The capex proxy assumes gross PP&E rises only via capital spending (it ignores disposals). 'Δ Cash + temp. investments (actual)' is the real reported change in liquid funds and is the most reliable line here; the operating/investing/financing proxies will not perfectly reconcile to it.

Sheet Ratios
A1: Baron Canyon Mutual Water Company Inc
A2: Financial Ratios
A3: Entity ID: cawc_0060 | Fiscal year ends June 30.
A5: Ratio | B5: FY2020 | C5: FY2021 | D5: FY2022 | E5: FY2023 | F5: FY2024 | G5: FY2025
A6: Profitability (computed upstream)
A7: Operating margin (NI / revenue) | B7: -0.058900806 | C7: 0.069878365 | D7: -0.22474468 | E7: 0.15276334 | F7: 0.117266 | G7: 0.055860089
A8: Expense ratio (expenses / revenue) | B8: 1.0589008 | C8: 0.93012164 | D8: 1.2247447 | E8: 0.84723666 | F8: 0.882734 | G8: 0.94413991
A9: Return on assets (NI / assets) | B9: -0.021257324 | C9: 0.029170427 | D9: -0.10586663 | E9: 0.1308896 | F9: 0.26618575 | G9: 0.095598606
A10: Revenue growth (YoY) | F10: 2.7549315 | G10: 0.80659086
A12: Leverage & solvency
A13: Debt-to-assets (liab. / assets) | B13: 0.029494183 | C13: 0.02593922 | D13: 0.069160001 | E13: 0.20916273 | F13: 0.17584306 | G13: 0.65101309
A14: Equity ratio (net assets / assets) | B14: 0.97050582 | C14: 0.97406078 | D14: 0.93084 | E14: 0.79083727 | F14: 0.82415694 | G14: 0.34898691
A16: Liquidity & asset profile (derived here)
A17: Current ratio (current assets / AP) | F17: 13.788363 | G17: 26.473539
A18: Cash ratio ((cash+temp inv.) / total liab.) | B18: 33.283829 | C18: 36.791766 | D18: 13.55814 | E18: 4.7595564 | F18: 5.6774207 | G18: 1.4182057
A19: Asset age proxy (accum. deprec. / gross PP&E)
A21: Upstream ratios are read from financials_annual; derived ratios are computed only where inputs are reported. Current ratio uses accounts payable as the current-liability proxy (the filings do not split current vs. long-term liabilities). Asset age proxy: a higher % implies older / more depreciated infrastructure.

Sheet Unit economics
A1: Baron Canyon Mutual Water Company Inc
A2: Unit economics - per-customer revenue by category (USD)
A3: Entity ID: cawc_0060 | Fiscal year ends June 30.
A5: Every metric here is PER CUSTOMER (a metered service connection). It is not a per-member figure; the member (shareholder) count is a different denominator, shown in the denominator block. The visible cell shows the value and its classification; the numerator, denominator, formula, and rationale are in each metric's LOGIC popup.
A6: Per-customer denominator (service connections) | C6: State Water Board eAR Section 4
A7: Total annual revenue (eAR Section 8b B1.8) | C7: eAR Section 8b total annual revenue not reported for this system.
A8: Primary source
A10: Revenue categories (value, classification, per customer, share)
A11: Revenue category | B11: Classification | C11: Value (USD) | D11: Per customer | E11: Share of revenue
A12: Water sales revenue | B12: not reported | C12: not reported | D12: not reported | E12: not reported
A13: Assessment revenue (990 program-service revenue not matched to eAR water-rate revenue) | B13: IMPOSSIBLE | C13: IMPOSSIBLE | D13: IMPOSSIBLE | E13: IMPOSSIBLE
A14: Meter revenue | B14: not reported | C14: not reported | D14: not reported | E14: not reported
A15: Overage or tiered penalty revenue | B15: not reported | C15: not reported | D15: not reported | E15: not reported
A17: Water sales revenue - not reported
A18: Not reported: this system filed an eAR but no Section 8b revenue block, so there is no filed water-sales figure. Not fallen back to a different year.
A19: Reason: No filed eAR Section 8b water-rate revenue for this system.
A21: Assessment revenue (990 program-service revenue not matched to eAR water-rate revenue) - IMPOSSIBLE
A22: Not computed. A period-aligned residual is not possible for this filer.
A23: Reason: Not derivable. The eAR Section 8b is reporting year None while the Form 990 fiscal year ends None; the two period ends are not aligned, so a period-aligned residual cannot be computed.
A25: Meter revenue - not reported
A26: Not reported. This category is not built because doing so would double-count.
A27: Reason: The eAR Section 8a reports a base/meter rate PRICE, but the filing carries no meter revenue line and no tier volume, and the base charge is already inside the water-sales revenue (eAR Section 8b water rates). Building a separate meter figure would double-count. Not backed into from a total.
A29: Overage or tiered penalty revenue - not reported
A30: Not reported. This category is not built because doing so would double-count.
A31: Reason: The eAR Section 8a reports tiered/overage rate PRICES, but the filing carries no overage revenue and no tier consumption volume, and any overage billed is already inside the water-sales revenue. Building it would double-count. Not backed into from a total.

Sheet Rate structure
A1: Baron Canyon Mutual Water Company Inc
A2: Rate structure and representative bill - eAR Section 8a
A3: Entity ID: cawc_0060 | Fiscal year ends June 30.
A5: This block is a rate-schedule illustration at defined usage levels. It is NOT billed revenue and not a claim about any real customer's usage. The revenue side of unit economics is the separate Unit Economics block.
A6: No filed eAR Section 8a rate schedule is staged for this system.

Sheet Operational metrics
A1: Baron Canyon Mutual Water Company Inc
A2: Operational metrics - plant per acre, density, terrain
A3: Entity ID: cawc_0060 | Fiscal year ends June 30.
A5: Connections per acre
A6: Connections per acre | B6: 0.05 | C6: 25 connections / 490.5 acres. CA State Water Board SABL SERVICE_CONNECTIONS; Geodesic area (WGS84 spherical excess) of the SABL service-area polygon.

Sheet Supply & weather
A1: Baron Canyon Mutual Water Company Inc
A2: Supply and weather indicators (DWR water year)
A3: Entity ID: cawc_0060 | Fiscal year ends June 30.
A5: Reporting calendar: Different reporting periods. The DWR water year runs October 1 to September 30; this system's fiscal year ends June 30, so the two period ends are three months apart. Read the two side by side with that in mind. Neither series is recast: both are reported as filed. A water year is named for the calendar year it ends in, so WY2024 and FY2024 share a number without covering the same twelve months.
A7: Indicator | B7: WY2021 | C7: WY2022 | D7: WY2023 | E7: WY2024 | F7: WY2025
A8: Water-year type (Sacramento Valley) | B8: Critical | C8: Critical | D8: Wet | E8: Above Normal | F8: not reported
A9: Peak drought, San Luis Obispo County | B9: D4 | C9: D4 | D9: D4 | E9: None (no D0-D4 during the fiscal year) | F9: D1
A10: Precip, percent of normal (8-Station Index) | B10: 48 | C10: 86 | D10: 133 | E10: 96 | F10: 113
A11: Snowpack, April 1 percent of average | B11: 59% | C11: 38% | D11: 237% | E11: 110% | F11: 96%
A12: State Water Project allocation | B12: 5% | C12: 5% | D12: 100% | E12: 40% | F12: 50%

Sheet How this was built
A1: Baron Canyon Mutual Water Company Inc
A2: How this was built - forensic lineage
A3: Entity ID: cawc_0060 | Fiscal year ends June 30.
A5: A plain account of the forensic lineage behind the hard-to-source metrics: what sources were checked, what was found, what was derived, and what could not be built and why. Every figure marked DERIVED or IMPOSSIBLE above is traceable to a line here.
A7: Water-sales revenue per customer - not reported
A8: Sources checked | B8: State Water Board eAR Section 8b (water-rate revenue B1.1/B1.2); State Water Board eAR Section 4 (connection count, same reporting year); audited financial statement (secondary cross-check, where published)
A9: What was found | B9: The eAR Section 8b reports water-rate revenue for reporting year None, so this is a DIRECT filed figure; per customer it is divided by the eAR Section 4 connection count for the same reporting year, so numerator and denominator share the year.
A11: Assessment revenue (residual) - IMPOSSIBLE
A12: Sources checked | B12: Form 990 Part VIII line 2 (program-service revenue); State Water Board eAR Section 8b (water-rate revenue B1.1/B1.2); eAR Section 8b filer comment (WRRevenueComments)
A13: What was found | B13: A period-aligned residual cannot be computed for this filer, so the metric is rendered IMPOSSIBLE rather than guessed.
A14: Caveat | B14: Not derivable. The eAR Section 8b is reporting year None while the Form 990 fiscal year ends None; the two period ends are not aligned, so a period-aligned residual cannot be computed.
A16: Meter revenue - not reported
A17: Sources checked | B17: State Water Board eAR Section 8a (rate prices); State Water Board eAR Section 8b (revenue lines); audited financial statement
A18: What was found | B18: The rate price exists in Section 8a but no revenue or tier volume is reported, and the base charge is already inside water sales.
A19: Caveat | B19: The eAR Section 8a reports a base/meter rate PRICE, but the filing carries no meter revenue line and no tier volume, and the base charge is already inside the water-sales revenue (eAR Section 8b water rates). Building a separate meter figure would double-count. Not backed into from a total.
A21: Overage / tiered-penalty revenue - not reported
A22: Sources checked | B22: State Water Board eAR Section 8a (rate prices); State Water Board eAR Section 8b (revenue lines); audited financial statement
A23: What was found | B23: The rate price exists in Section 8a but no revenue or tier volume is reported, and the base charge is already inside water sales.
A24: Caveat | B24: The eAR Section 8a reports tiered/overage rate PRICES, but the filing carries no overage revenue and no tier consumption volume, and any overage billed is already inside the water-sales revenue. Building it would double-count. Not backed into from a total.
A26: eAR Section 8b reporting-period basis - sourced
A27: Sources checked | B27: eAR Section 8b B0.1 (WRFinancialReportingPeriod); eAR Section 8b B0.2 (WRFiscalYearStartDate)
A28: What was found | B28: The reporting basis (fiscal vs calendar year) is read from the filer's own B0.1/B0.2 answer and staged verbatim, never hardcoded, so the 990 comparison and the residual are period-aligned.
A30: Member (shareholder) count denominator - not reported
A31: Sources checked | B31: Form 990 (no member count stated); company website
A32: What was found | B32: No filing states a member/shareholder count, so the per-member unit economics read not reported rather than borrowing the connection count.
A34: Water volume delivered (acre-feet) - not reported
A35: Sources checked | B35: Form 990 (not in the filing); Consumer Confidence Report; eAR Section 6 (PRA-gated)
A36: What was found | B36: Volume delivered in acre-feet is not in the Form 990 and the CCR states only a source mix, so the per-acre-foot metrics read not reported; the eAR Section 6 is named as the source still needed.

Sheet Sources & audit
A1: Baron Canyon Mutual Water Company Inc
A2: Sources & audit - full provenance and tie-outs (kept off the statements so they read clean)
A3: Entity ID: cawc_0060 | Fiscal year ends June 30.
A5: Presentation standard: every figure on the statement tabs is verified to its source filing and shown clean. A cell the filing does not report reads "not reported" (never estimated, never guessed).
A6: Citations, confidence tiers, and the filed-vs-computed tie-out checks live on the "Sources & audit" tab, keyed by cell, so every number is fully traceable without cluttering the statements. These pages are ready to use as filed.
A8: A. Filing provenance (one row per staged extraction)
A9: Fiscal year | B9: Period end | C9: Filing type | D9: Confidence | E9: Extraction ID | F9: Object ID | G9: Extracted by | H9: Extracted at | I9: Source URL
A10: FY2020 | B10: 2020-06-30 | C10: 990-EZ | D10: high | E10: 9758cba5-b314-4619-be2f-ae4af6a22e34 | F10: 202022399349200612 | G10: claude-opus-5 | H10: 2026-09-14T20:40:28+00:00 | I10: https://apps.irs.gov/pub/epostcard/990/xml/2020/download990xml_2020_4.zip#202022399349200612_public.xml
A11: FY2021 | B11: 2021-06-30 | C11: 990-EZ | D11: high | E11: 9407e0c3-9ca5-458d-a928-a78bb0620abc | F11: 202143139349202744 | G11: claude-opus-5 | H11: 2026-09-14T20:40:28+00:00 | I11: https://apps.irs.gov/pub/epostcard/990/xml/2021/2021_TEOS_XML_01A.zip#202143139349202744_public.xml
A12: FY2022 | B12: 2022-06-30 | C12: 990-EZ | D12: high | E12: fa01cd7d-b764-4ea9-bc98-2916e3675959 | F12: 202223559349200617 | G12: claude-opus-5 | H12: 2026-09-14T20:40:28+00:00 | I12: https://apps.irs.gov/pub/epostcard/990/xml/2022/2022_TEOS_XML_02A.zip#202223559349200617_public.xml
A13: FY2023 | B13: 2023-06-30 | C13: 990-EZ | D13: high | E13: c002c4c7-aa87-4574-b4fd-9fbda8ca3a04 | F13: 202401309349202285 | G13: claude-opus-5 | H13: 2026-09-14T20:40:28+00:00 | I13: https://apps.irs.gov/pub/epostcard/990/xml/2024/2024_TEOS_XML_05A.zip#202401309349202285_public.xml
A14: FY2024 | B14: 2024-06-30 | C14: 990 | D14: high | E14: 898d2fcf-de45-4e05-aa1c-f4e1cd5a4e0b | F14: 202511139349300846 | G14: claude-opus-5 | H14: 2026-09-14T20:40:28+00:00 | I14: https://apps.irs.gov/pub/epostcard/990/xml/2025/2025_TEOS_XML_04A.zip#202511139349300846_public.xml
A15: FY2025 | B15: 2025-06-30 | C15: 990 | D15: high | E15: 9535aa5d-1ec4-4d2c-b030-e64cb357a643 | F15: 202533459349301318 | G15: claude-opus-5 | H15: 2026-09-14T20:40:28+00:00 | I15: https://apps.irs.gov/pub/epostcard/990/xml/2025/2025_TEOS_XML_12A.zip#202533459349301318_public.xml
A17: B. Figure citations (every figure on the statement tabs, keyed by cell)
A18: Tab | B18: Cell | C18: Line item | D18: Form 990 line | E18: Key path | F18: Confidence | G18: As filed
A19: Financial Statements | B19: B73 | C19: 11a. Gross income from members or shareholders | D19: 11a | E19: part_v_other_irs_filings.members_and_shareholders_gross_income | F19: high | G19: 376858
A20: Financial Statements | B20: C73 | C20: 11a. Gross income from members or shareholders | D20: 11a | E20: part_v_other_irs_filings.members_and_shareholders_gross_income | F20: high | G20: 292261
A21: Financial Statements | B21: B74 | C21: 11b. Gross income from other sources | D21: 11b | E21: part_v_other_irs_filings.other_sources_gross_income | F21: high | G21: 262543
A22: Financial Statements | B22: C74 | C22: 11b. Gross income from other sources | D22: 11b | E22: part_v_other_irs_filings.other_sources_gross_income | F22: high | G22: 862875
A23: Revenue (detail) | B23: B7 | C23: 1h. Total contributions, gifts, grants | D23: 1h | E23: part_viii_revenue.total_contributions | F23: high | G23: 259274
A24: Revenue (detail) | B24: C7 | C24: 1h. Total contributions, gifts, grants | D24: 1h | E24: part_viii_revenue.total_contributions | F24: high | G24: 859114
A25: Revenue (detail) | B25: B8 | C25: 2g. Total program service revenue | D25: 2g | E25: part_viii_revenue.total_program_service_revenue | F25: high | G25: 376858
A26: Revenue (detail) | B26: C8 | C26: 2g. Total program service revenue | D26: 2g | E26: part_viii_revenue.total_program_service_revenue | F26: high | G26: 292261
A27: Revenue (detail) | B27: B9 | C27: 3. Investment income | D27: 3 | E27: part_viii_revenue.investment_income | F27: high | G27: 3269
A28: Revenue (detail) | B28: C9 | C28: 3. Investment income | D28: 3 | E28: part_viii_revenue.investment_income | F28: high | G28: 3761
A29: Operating expenses (detail) | B29: B7 | C29: 11a. Fees for services: management | D29: 11a | E29: part_ix_expenses.fees_management | F29: high | G29: 7675
A30: Operating expenses (detail) | B30: C7 | C30: 11a. Fees for services: management | D30: 11a | E30: part_ix_expenses.fees_management | F30: high | G30: 8400
... A57: Net-assets reconciliation | B57: C10 | C57: 9. Other changes in net assets | D57: Part XI line 9 | E57: part_xi_reconciliation.other_changes_net_assets | F57: high | G57: -61122
A59: C. Tie-out checks (filed vs computed; any nonzero variance is flagged red)
A60: Tab | B60: Check | C60: Fiscal year | D60: Filed | E60: Computed | F60: Variance (computed - filed)
A61: Revenue (detail) | B61: 12. Total revenue | C61: FY2024 | D61: 639401 | E61: ='Revenue (detail)'!B13 | F61: =E61-D61
A62: Revenue (detail) | B62: 12. Total revenue | C62: FY2025 | D62: 1155136 | E62: ='Revenue (detail)'!C13 | F62: =E62-D62
A63: Revenue (detail) | B63: 2g program service revenue = sum of lines 2a-2f (FY2025) | C63: FY2025 | D63: 292261 | E63: =SUM('Revenue (detail)'!C17:C19) | F63: =E63-D63
A64: Operating expenses (detail) | B64: 25. Total functional expenses | C64: FY2024 | D64: 564421 | E64: ='Operating expenses (detail)'!B16 | F64: =E64-D64
A65: Operating expenses (detail) | B65: 25. Total functional expenses | C65: FY2025 | D65: 1090610 | E65: ='Operating expenses (detail)'!C16 | F65: =E65-D65
A66: Operating expenses (detail) | B66: Part IX column split: col A = B + C + D (FY2025) | C66: FY2025 | D66: ='Operating expenses (detail)'!B24 | E66: ='Operating expenses (detail)'!C24+'Operating expenses (detail)'!D24+'Operating expenses (detail)'!E24 | F66: =E66-D66
A67: Balance sheet (detail) | B67: 16. Total assets | C67: FY2024 | D67: 281683 | E67: ='Balance sheet (detail)'!B10 | F67: =E67-D67
A68: Balance sheet (detail) | B68: 16. Total assets | C68: FY2025 | D68: 674968 | E68: ='Balance sheet (detail)'!C10 | F68: =E68-D68
A69: Balance sheet (detail) | B69: 26. Total liabilities | C69: FY2024 | D69: 49532 | E69: ='Balance sheet (detail)'!B16 | F69: =E69-D69
A70: Balance sheet (detail) | B70: 26. Total liabilities | C70: FY2025 | D70: 439413 | E70: ='Balance sheet (detail)'!C16 | F70: =E70-D70
...

Sheet Provenance
A1: Build provenance | B1: Built from source commit d418ffb17485 (2026-10-06); source fingerprint a75a8eee82c65cf7; 192 companies (179 retail mutual, 4 irrigation mutual, 3 mutual, no PWSID, purpose not stated, 2 frozen non-mutual (special district), 2 wholesale mutual, 1 frozen non-mutual (investor-owned), 1 frozen non-mutual (municipal)); 91 gates; build id 3d08d6d2a855.
A2: source_commit | B2: d418ffb174855ab78000d391d42f898397b0d8aa
A3: source_commit_date | B3: 2026-10-06
A4: source_fingerprint | B4: a75a8eee82c65cf7096931f06e18affdc28686a02895b46538e7298b57c04d94
A5: gate_count | B5: 91
A6: build_id | B6: 3d08d6d2a855
A7: registry: frozen non-mutual (investor-owned) | B7: 1
A8: registry: frozen non-mutual (municipal) | B8: 1
A9: registry: frozen non-mutual (special district) | B9: 2
A10: registry: irrigation mutual | B10: 4
A11: registry: mutual, no PWSID, purpose not stated | B11: 3
A12: registry: retail mutual | B12: 179
A13: registry: wholesale mutual | B13: 2
