Workbook

Sheet Summary
A1: Paradise Lake Mutual Water Company
A2: Financial Summary - multi-year overview (USD)
A3: Entity ID: cawc_0179 | Fiscal year ends May 31.
A5: Presentation standard: every figure on the statement tabs is verified to its source filing and shown clean. A cell the filing does not report reads "not reported" (never estimated, never guessed).
A6: Citations, confidence tiers, and the filed-vs-computed tie-out checks live on the "Sources & audit" tab, keyed by cell, so every number is fully traceable without cluttering the statements. These pages are ready to use as filed.
A8: Metric | B8: FY2020 | C8: FY2021 | D8: FY2022 | E8: FY2023 | F8: FY2024 | G8: FY2025
A9: Operating results (USD)
A10: Total revenue | B10: 90592 | C10: 85680 | D10: 87177 | E10: 103848 | F10: 115150 | G10: 111618
A11: Total expenses | B11: 47945 | C11: 38440 | D11: 38354 | E11: 56978 | F11: 61982 | G11: 69619
A12: Net income | B12: 42647 | C12: 47240 | D12: 48823 | E12: 46870 | F12: 53168 | G12: 41999
A14: Financial position (USD, end of year)
A15: Total assets | B15: 362310 | C15: 387609 | D15: 439167 | E15: 505822 | F15: 556403 | G15: 578789
A16: Total liabilities | B16: 4900 | C16: 7160 | D16: 9895 | E16: 29680 | F16: 27093 | G16: 7480
A17: Net assets | B17: 357410 | C17: 380449 | D17: 429272 | E17: 476142 | F17: 529310 | G17: 571309
A19: Headline ratios
A20: Operating margin | B20: 0.47075901 | C20: 0.55135387 | D20: 0.56004451 | E20: 0.45133272 | F20: 0.46172818 | G20: 0.37627444
A21: Revenue growth (YoY) | E21: 0.19123163 | F21: 0.10883214 | G21: -0.030673035
A22: Return on assets | B22: 0.11770859 | C22: 0.1218754 | D22: 0.11117183 | E22: 0.092661055 | F22: 0.095556638 | G22: 0.072563577
A24: Figures as reported in source filings (full provenance on the Sources & audit tab). Parentheses denote negatives; ratios are computed upstream in financials_annual.

Sheet Notes
A1: Notes
A2: Human annotations from the versioned store (data/notes/). Annotations only: they never change a reported figure or a confidence tier.
A4: Date | B4: Tag | C4: Author | D4: Note
A5: No notes recorded yet.

Sheet Financial Statements
A1: Paradise Lake Mutual Water Company
A2: Financial Statements - income statement, balance sheet, cash flow, member income test (USD)
A3: Entity ID: cawc_0179 | Fiscal year ends May 31.
A5: INCOME STATEMENT - as reported (USD)
A6: Line item | B6: FY2020 | C6: FY2021 | D6: FY2022 | E6: FY2023 | F6: FY2024 | G6: FY2025
A7: Revenue
A8: Program service revenue | E8: 92696 | F8: 94032 | G8: 91540
A9: Investment income | E9: 10652 | F9: 21118 | G9: 20078
A10: Net rental income
A11: Net gain/(loss) on investment sales
A12: Other revenue | E12: 500
A13: Contributions & grants
A14: Total revenue | E14: 103848 | F14: 115150 | G14: 111618
A16: Expenses
A17: Depreciation | E17: 4646 | F17: 4085 | G17: 7710
A18: Interest expense
A19: Total expenses | B19: 47945 | C19: 38440 | D19: 38354 | E19: 56978 | F19: 61982 | G19: 69619
A21: Net income | B21: 42647 | C21: 47240 | D21: 48823 | E21: 46870 | F21: 53168 | G21: 41999
A24: BALANCE SHEET - as reported (USD, end of year)
A25: Line item | B25: FY2020 | C25: FY2021 | D25: FY2022 | E25: FY2023 | F25: FY2024 | G25: FY2025
A26: Assets
A27: Cash | B27: 281323 | C27: 341470 | D27: 387072 | E27: 57754 | F27: 99814 | G27: 24178
A28: Savings & temporary investments | E28: 393665 | F28: 414783 | G28: 434861
A29: Accounts receivable | E29: 1867 | F29: 3343 | G29: 1871
A30: Inventories
A31: Prepaid expenses | E31: 13172 | F31: 5216 | G31: 2566
A32: Property, plant & equipment (gross) | E32: 533228 | F32: 527086 | G32: 616862
A33: Less: accumulated depreciation | E33: -493864 | F33: -493839 | G33: -501549
A34: Net property, plant & equipment | C34: 42518 | D34: 44011 | E34: 39364 | F34: 33247 | G34: 115313
A35: Total assets | B35: 362310 | C35: 387609 | D35: 439167 | E35: 505822 | F35: 556403 | G35: 578789
A37: Liabilities
A38: Accounts payable | E38: 21435 | F38: 16798 | G38: 907
A39: Mortgages & notes payable
A40: Total liabilities | B40: 4900 | C40: 7160 | D40: 9895 | E40: 29680 | F40: 27093 | G40: 7480
A42: Net Assets / Equity
A43: Capital stock
A44: Paid-in capital
A45: Retained earnings
A46: Net assets | B46: 357410 | C46: 380449 | D46: 429272 | E46: 476142 | F46: 529310 | G46: 571309
A49: CASH FLOW - derived proxy (USD)
...

Sheet Balance Sheet
A1: Paradise Lake Mutual Water Company
A2: Balance Sheet - as reported (USD, end of year)
A3: Entity ID: cawc_0179 | Fiscal year ends May 31.
A5: Line item | B5: FY2020 | C5: FY2021 | D5: FY2022 | E5: FY2023 | F5: FY2024 | G5: FY2025
A6: Assets
A7: Cash | B7: 281323 | C7: 341470 | D7: 387072 | E7: 57754 | F7: 99814 | G7: 24178
A8: Savings & temporary investments | E8: 393665 | F8: 414783 | G8: 434861
A9: Accounts receivable | E9: 1867 | F9: 3343 | G9: 1871
A10: Inventories
A11: Prepaid expenses | E11: 13172 | F11: 5216 | G11: 2566
A12: Property, plant & equipment (gross) | E12: 533228 | F12: 527086 | G12: 616862
A13: Less: accumulated depreciation | E13: -493864 | F13: -493839 | G13: -501549
A14: Net property, plant & equipment | C14: 42518 | D14: 44011 | E14: 39364 | F14: 33247 | G14: 115313
A15: Total assets | B15: 362310 | C15: 387609 | D15: 439167 | E15: 505822 | F15: 556403 | G15: 578789
A17: Liabilities
A18: Accounts payable | E18: 21435 | F18: 16798 | G18: 907
A19: Mortgages & notes payable
A20: Total liabilities | B20: 4900 | C20: 7160 | D20: 9895 | E20: 29680 | F20: 27093 | G20: 7480
A22: Net Assets / Equity
A23: Capital stock
A24: Paid-in capital
A25: Retained earnings
A26: Net assets | B26: 357410 | C26: 380449 | D26: 429272 | E26: 476142 | F26: 529310 | G26: 571309
A28: Balance check (assets − liab. − net assets) | B28: 0 | C28: 0 | D28: 0 | E28: 0 | F28: 0 | G28: 0
A30: Net PP&E is the reported ppe_net column (gross less accumulated depreciation). The balance check should be ~0 where all three totals are reported; a non-zero value flags a reporting or extraction discrepancy worth reviewing.

Sheet Officers & contractors
A1: Paradise Lake Mutual Water Company
A2: Officers, Directors & Contractors - Form 990 Part VII (FY2025; USD)
A3: Entity ID: cawc_0179 | Fiscal year ends May 31.
A5: Section A - Officers, directors, trustees, key employees
A6: Name | B6: Title | C6: Reportable comp (org) | D6: Reportable comp (related) | E6: Other comp | F6: Total compensation
A7: GARY HOLZHAUSEN | B7: PRESIDENT | C7: 0 | D7: 0 | E7: 0 | F7: 0
A8: ROBERT MANN | B8: VP & SECRETARY | C8: 0 | D8: 0 | E8: 0 | F8: 0
A9: JULIA HICKS | B9: TREASURER | C9: 0 | D9: 0 | E9: 0 | F9: 0
A10: JOSIE AVILA | B10: BOARD MEMBER | C10: 0 | D10: 0 | E10: 0 | F10: 0
A11: ERYN CASTOR | B11: BOARD MEMBER | C11: 0 | D11: 0 | E11: 0 | F11: 0
A12: JEANNIE WHITMORE | B12: BOARD MEMBER | C12: 0 | D12: 0 | E12: 0 | F12: 0
A13: JORGE OVANDO | B13: BOARD MEMBER | C13: 0 | D13: 0 | E13: 0 | F13: 0
A15: Section B - Independent contractors (over $100,000)
A16: Contractor | B16: Services | C16: Compensation
A18: Section A lists every officer, director, trustee and key employee filed for the latest year; the two with the highest total compensation are highlighted. Total compensation is computed (reportable org + related + other). Section B lists each independent contractor paid over $100,000; the return reports 0 such contractor(s). Source and confidence for every figure are on the Sources & audit tab.

Sheet Revenue (detail)
A1: Paradise Lake Mutual Water Company
A2: Revenue - Form 990 Part VIII (USD)
A3: Entity ID: cawc_0179 | Fiscal year ends May 31.
A5: Part VIII line | B5: FY2023 | C5: FY2024 | D5: FY2025
A6: Revenue by category
A7: 1h. Total contributions, gifts, grants | B7: not reported | C7: not reported | D7: not reported
A8: 2g. Total program service revenue | B8: 92696 | C8: 94032 | D8: 91540
A9: 3. Investment income | B9: 10652 | C9: 21118 | D9: 20078
A10: 6d. Net rental income | B10: not reported | C10: not reported | D10: not reported
A11: 7d. Net gain/(loss) from investment sales | B11: not reported | C11: not reported | D11: not reported
A12: 11e. Other revenue | B12: 500 | C12: not reported | D12: not reported
A13: 12. Total revenue | B13: =SUM(B7:B12) | C13: =SUM(C7:C12) | D13: =SUM(D7:D12)
A15: Program service revenue detail - FY2025 (lines 2a-2f)
A16: Description | B16: Business code | C16: Total revenue
A17: ASSESSMENTS & FEES | B17: 900099 | C17: 91540
A18: Revenue category subtotals are as filed. Total revenue (line 12) is a live SUM of the category cells above; its tie-out to the filed total is on the Sources & audit tab. Program service revenue detail is shown for the latest year, with its sum-to-line-2g check on that same audit tab.

Sheet Operating expenses (detail)
A1: Paradise Lake Mutual Water Company
A2: Statement of Functional Expenses - Form 990 Part IX (USD)
A3: Entity ID: cawc_0179 | Fiscal year ends May 31.
A5: Part IX line (column A Total) | B5: FY2023 | C5: FY2024 | D5: FY2025
A6: Functional expenses, column A Total - by year
A7: 11b. Fees for services: legal | B7: 350 | C7: not reported | D7: not reported
A8: 11c. Fees for services: accounting | B8: 24298 | C8: 18697 | D8: 18298
A9: 11g. Fees for services: other | B9: 286 | C9: 397 | D9: 856
A10: 13. Office expenses | B10: 96 | C10: 240 | D10: 238
A11: 22. Depreciation, depletion, and amortization | B11: 4646 | C11: 4085 | D11: 7710
A12: 23. Insurance | B12: 1673 | C12: 1796 | D12: 1824
A13: 24. REPAIRS & MAINTENANCE | B13: 7859 | C13: 19585 | D13: 17710
A14: 24. UTILITIES | B14: 6593 | C14: 7775 | D14: 9583
A15: 24. WATER QUALITY REPORT/TE | B15: 4503 | C15: 3567 | D15: 7609
A16: 24. HEALTH DEPT FEES - MONT | B16: 2528 | C16: 2880 | D16: 3072
A17: 24e. All other expenses | B17: 4146 | C17: 2960 | D17: 2719
A18: 25. Total functional expenses | B18: =SUM(B7:B17) | C18: =SUM(C7:C17) | D18: =SUM(D7:D17)
A20: Functional column split - FY2025
A21: Not reported. This filer reports only column A (Total) of Part IX; the program / management / fundraising split (columns B-D) is not filed, so it is left as not reported rather than shown empty or inferred.
A22: Top block: each Part IX line, column A (Total), by year, as filed. Total functional expenses (line 25) is a live SUM of the line cells; its tie-out to the filed total is on the Sources & audit tab. Filer-itemized 24a-24d rows show the most recent year's as-filed wording; rows are aligned across years case-insensitively with collapsed spacing, so a line filed only in a different capitalization or spacing shares one row, while genuinely different wording stays a separate row (every as-filed variant is recorded on the Sources & audit tab). This filer reports only column A (Total); the program / management / fundraising split (columns B-D) is not reported. Lines this filer does not report are omitted rather than shown empty.

Sheet Balance sheet (detail)
A1: Paradise Lake Mutual Water Company
A2: Balance Sheet - Form 990 Part X (end of year, USD)
A3: Entity ID: cawc_0179 | Fiscal year ends May 31.
A5: Part X line (column B, EOY) | B5: FY2023 | C5: FY2024 | D5: FY2025
A6: Assets
A7: 1. Cash - non-interest-bearing | B7: 57754 | C7: 99814 | D7: 24178
A8: 2. Savings and temporary cash investments | B8: 393665 | C8: 414783 | D8: 434861
A9: 4. Accounts receivable, net | B9: 1867 | C9: 3343 | D9: 1871
A10: 9. Prepaid expenses and deferred charges | B10: 13172 | C10: 5216 | D10: 2566
A11: 10c. Land, buildings, and equipment, net | B11: 39364 | C11: 33247 | D11: 115313
A12: 16. Total assets | B12: =SUM(B7:B11) | C12: =SUM(C7:C11) | D12: =SUM(D7:D11)
A14: Liabilities
A15: 17. Accounts payable and accrued expenses | B15: 21435 | C15: 16798 | D15: 907
A16: 19. Deferred revenue | B16: 8245 | C16: 7279 | D16: 6573
A17: 25. Other liabilities | B17: not reported | C17: 3016 | D17: 0
A18: 26. Total liabilities | B18: =SUM(B15:B17) | C18: =SUM(C15:C17) | D18: =SUM(D15:D17)
A20: Net assets / fund balances
A21: 27. Net assets without donor restrictions | B21: 476142 | C21: 529310 | D21: 571309
A22: 32. Total net assets / fund balances | B22: =SUM(B21:B21) | C22: =SUM(C21:C21) | D22: =SUM(D21:D21)
A24: Every Part X line is end-of-year (column B), as filed. Section totals (lines 16 / 26 / 32) are live SUMs of the lines above; their tie-outs and the balance-sheet identity (16 = 26 + 32) are on the Sources & audit tab. This filer files as a non-FASB mutual, so net assets sit on lines 29-31 (capital stock / paid-in capital / retained earnings); lines this filer does not report are omitted. Lines 10a/10b net into line 10c (shown).

Sheet Net-assets reconciliation
A1: Paradise Lake Mutual Water Company
A2: Reconciliation of Net Assets - Form 990 Part XI (USD)
A3: Entity ID: cawc_0179 | Fiscal year ends May 31.
A5: Part XI line | B5: FY2023 | C5: FY2024 | D5: FY2025
A6: Reconciliation
A7: 4. Net assets, beginning of year | B7: 429272 | C7: 476142 | D7: 529310
A8: 3. Revenue less expenses | B8: 46870 | C8: 53168 | D8: 41999
A9: 8. Prior period adjustments | B9: not reported | C9: not reported | D9: not reported
A10: 9. Other changes in net assets | B10: 0 | C10: 0 | D10: 0
A11: 10. Net assets, end of year | B11: =SUM(B7,B8,B9,B10) | C11: =SUM(C7,C8,C9,C10) | D11: =SUM(D7,D8,D9,D10)
A13: Part XI reconciles beginning to ending net assets. Ending net assets (line 10) is a live formula: beginning balance (line 4) + revenue less expenses (line 3) + prior-period adjustments (8) + other changes (9). Its tie-out to the filed line 10 (and to Part X line 32) is on the Sources & audit tab. Lines 5-7 (unrealized gains, donated services, investment expenses) are not filed by this entity.

Sheet Cash flow proxies
A1: Paradise Lake Mutual Water Company
A2: Cash Flow Proxies - derived (USD)
A3: Entity ID: cawc_0179 | Fiscal year ends May 31.
A5: PROXY ONLY. The source filings contain no statement of cash flows. Lines below are derived from the reported income statement and year-over-year balance-sheet changes; treat as directional estimates, not GAAP cash flows. The earliest year has no prior period, so its delta cells are blank.
A7: Proxy line (USD) | B7: FY2020 | C7: FY2021 | D7: FY2022 | E7: FY2023 | F7: FY2024 | G7: FY2025
A8: Operating
A9: Net income | B9: 42647 | C9: 47240 | D9: 48823 | E9: 46870 | F9: 53168 | G9: 41999
A10: + Depreciation (reported) | E10: 4646 | F10: 4085 | G10: 7710
A11: − Δ Accounts receivable | F11: -1476 | G11: 1472
A12: − Δ Inventories
A13: − Δ Prepaid expenses | F13: 7956 | G13: 2650
A14: + Δ Accounts payable | F14: -4637 | G14: -15891
A15: Operating cash flow proxy | C15: 47240 | D15: 48823 | E15: 51516 | F15: 59096 | G15: 37940
A17: Investing
A18: − Δ PP&E gross (capex proxy) | F18: 6142 | G18: -89776
A20: Financing
A21: Δ Mortgages & notes payable
A23: Reconciliation
A24: Δ Cash + temp. investments (actual) | C24: 60147 | D24: 45602 | E24: 64347 | F24: 63178 | G24: -55558
A26: The capex proxy assumes gross PP&E rises only via capital spending (it ignores disposals). 'Δ Cash + temp. investments (actual)' is the real reported change in liquid funds and is the most reliable line here; the operating/investing/financing proxies will not perfectly reconcile to it.

Sheet Ratios
A1: Paradise Lake Mutual Water Company
A2: Financial Ratios
A3: Entity ID: cawc_0179 | Fiscal year ends May 31.
A5: Ratio | B5: FY2020 | C5: FY2021 | D5: FY2022 | E5: FY2023 | F5: FY2024 | G5: FY2025
A6: Profitability (computed upstream)
A7: Operating margin (NI / revenue) | B7: 0.47075901 | C7: 0.55135387 | D7: 0.56004451 | E7: 0.45133272 | F7: 0.46172818 | G7: 0.37627444
A8: Expense ratio (expenses / revenue) | B8: 0.52924099 | C8: 0.44864613 | D8: 0.43995549 | E8: 0.54866728 | F8: 0.53827182 | G8: 0.62372556
A9: Return on assets (NI / assets) | B9: 0.11770859 | C9: 0.1218754 | D9: 0.11117183 | E9: 0.092661055 | F9: 0.095556638 | G9: 0.072563577
A10: Revenue growth (YoY) | E10: 0.19123163 | F10: 0.10883214 | G10: -0.030673035
A12: Leverage & solvency
A13: Debt-to-assets (liab. / assets) | B13: 0.01352433 | C13: 0.018472223 | D13: 0.022531292 | E13: 0.058676768 | F13: 0.048693124 | G13: 0.012923535
A14: Equity ratio (net assets / assets) | B14: 0.98647567 | C14: 0.98152778 | D14: 0.97746871 | E14: 0.94132323 | F14: 0.95130688 | G14: 0.98707646
A16: Liquidity & asset profile (derived here)
A17: Current ratio (current assets / AP) | E17: 21.761512 | F17: 31.143946 | G17: 510.9989
A18: Cash ratio ((cash+temp inv.) / total liab.) | B18: 57.412857 | C18: 47.691341 | D18: 39.117938 | E18: 15.209535 | F18: 18.993725 | G18: 61.36885
A19: Asset age proxy (accum. deprec. / gross PP&E) | E19: 0.92617792 | F19: 0.93692301 | G19: 0.81306516
A21: Upstream ratios are read from financials_annual; derived ratios are computed only where inputs are reported. Current ratio uses accounts payable as the current-liability proxy (the filings do not split current vs. long-term liabilities). Asset age proxy: a higher % implies older / more depreciated infrastructure.

Sheet Unit economics
A1: Paradise Lake Mutual Water Company
A2: Unit economics - per-customer revenue by category (USD)
A3: Entity ID: cawc_0179 | Fiscal year ends May 31.
A5: Every metric here is PER CUSTOMER (a metered service connection). It is not a per-member figure; the member (shareholder) count is a different denominator, shown in the denominator block. The visible cell shows the value and its classification; the numerator, denominator, formula, and rationale are in each metric's LOGIC popup.
A6: Per-customer denominator (service connections) | C6: State Water Board eAR Section 4
A7: Total annual revenue (eAR Section 8b B1.8) | C7: eAR Section 8b total annual revenue not reported for this system.
A8: Primary source
A10: Revenue categories (value, classification, per customer, share)
A11: Revenue category | B11: Classification | C11: Value (USD) | D11: Per customer | E11: Share of revenue
A12: Water sales revenue | B12: not reported | C12: not reported | D12: not reported | E12: not reported
A13: Assessment revenue (990 program-service revenue not matched to eAR water-rate revenue) | B13: IMPOSSIBLE | C13: IMPOSSIBLE | D13: IMPOSSIBLE | E13: IMPOSSIBLE
A14: Meter revenue | B14: not reported | C14: not reported | D14: not reported | E14: not reported
A15: Overage or tiered penalty revenue | B15: not reported | C15: not reported | D15: not reported | E15: not reported
A17: Water sales revenue - not reported
A18: Not reported: this system filed an eAR but no Section 8b revenue block, so there is no filed water-sales figure. Not fallen back to a different year.
A19: Reason: No filed eAR Section 8b water-rate revenue for this system.
A21: Assessment revenue (990 program-service revenue not matched to eAR water-rate revenue) - IMPOSSIBLE
A22: Not computed. A period-aligned residual is not possible for this filer.
A23: Reason: Not derivable. The eAR Section 8b is reporting year None while the Form 990 fiscal year ends None; the two period ends are not aligned, so a period-aligned residual cannot be computed.
A25: Meter revenue - not reported
A26: Not reported. This category is not built because doing so would double-count.
A27: Reason: The eAR Section 8a reports a base/meter rate PRICE, but the filing carries no meter revenue line and no tier volume, and the base charge is already inside the water-sales revenue (eAR Section 8b water rates). Building a separate meter figure would double-count. Not backed into from a total.
A29: Overage or tiered penalty revenue - not reported
A30: Not reported. This category is not built because doing so would double-count.
A31: Reason: The eAR Section 8a reports tiered/overage rate PRICES, but the filing carries no overage revenue and no tier consumption volume, and any overage billed is already inside the water-sales revenue. Building it would double-count. Not backed into from a total.

Sheet Rate structure
A1: Paradise Lake Mutual Water Company
A2: Rate structure and representative bill - eAR Section 8a
A3: Entity ID: cawc_0179 | Fiscal year ends May 31.
A5: This block is a rate-schedule illustration at defined usage levels. It is NOT billed revenue and not a claim about any real customer's usage. The revenue side of unit economics is the separate Unit Economics block.
A6: No filed eAR Section 8a rate schedule is staged for this system.

Sheet Operational metrics
A1: Paradise Lake Mutual Water Company
A2: Operational metrics - plant per acre, density, terrain
A3: Entity ID: cawc_0179 | Fiscal year ends May 31.
A5: Plant assets per acre
A6: Service-area acres | B6: 110.9 | C6: Geodesic area (WGS84 spherical excess) of the SABL service-area polygon.
A7: Fiscal year | B7: Gross plant per acre (primary) | C7: Net plant per acre
A8: FY2021 | C8: 383.3904
A9: FY2022 | C9: 396.853
A10: FY2023 | B10: 4808.1876 | C10: 354.9504
A11: FY2024 | B11: 4752.8043 | C11: 299.7926
A12: FY2025 | B12: 5562.3264 | C12: 1039.7926
A13: Infrastructure built per acre of service area. Gross plant per acre is the primary read because it measures how much plant the system has put in the ground per acre, and unlike net plant it does not fall over time purely because the assets depreciate on the books. Net plant per acre is shown alongside as the depreciated book value per acre.
A14: Formula: gross plant per acre = Form 990 Part X line 10a (land, buildings, and equipment, gross) / SABL service-area acres; net plant per acre uses Part X line 10c (net)
A15: Source lines: Form 990 Part X line 10a (gross) and line 10c (net); Geodesic area (WGS84 spherical excess) of the SABL service-area polygon.
A16: Confidence: medium. This is worked out from filed figures (a ratio, or a year-to-year change), so it is one step removed from the raw numbers.. Filed gross/net plant over the measured SABL service-area acreage.
A18: Connections per acre
A19: Connections per acre | B19: 0.69 | C19: 76 connections / 110.9 acres. CA State Water Board SABL SERVICE_CONNECTIONS; Geodesic area (WGS84 spherical excess) of the SABL service-area polygon.

Sheet Supply & weather
A1: Paradise Lake Mutual Water Company
A2: Supply and weather indicators (DWR water year)
A3: Entity ID: cawc_0179 | Fiscal year ends May 31.
A5: Reporting calendar: Different reporting periods. The DWR water year runs October 1 to September 30; this system's fiscal year ends May 31, so the two period ends are four months apart. Read the two side by side with that in mind. Neither series is recast: both are reported as filed. A water year is named for the calendar year it ends in, so WY2024 and FY2024 share a number without covering the same twelve months.
A7: Indicator | B7: WY2021 | C7: WY2022 | D7: WY2023 | E7: WY2024 | F7: WY2025
A8: Water-year type (Sacramento Valley) | B8: Critical | C8: Critical | D8: Wet | E8: Above Normal | F8: not reported
A9: Peak drought, county County | B9: not reported | C9: not reported | D9: not reported | E9: not reported | F9: not reported
A10: Precip, percent of normal (8-Station Index) | B10: 48 | C10: 86 | D10: 133 | E10: 96 | F10: 113
A11: Snowpack, April 1 percent of average | B11: 59% | C11: 38% | D11: 237% | E11: 110% | F11: 96%
A12: State Water Project allocation | B12: 5% | C12: 5% | D12: 100% | E12: 40% | F12: 50%

Sheet How this was built
A1: Paradise Lake Mutual Water Company
A2: How this was built - forensic lineage
A3: Entity ID: cawc_0179 | Fiscal year ends May 31.
A5: A plain account of the forensic lineage behind the hard-to-source metrics: what sources were checked, what was found, what was derived, and what could not be built and why. Every figure marked DERIVED or IMPOSSIBLE above is traceable to a line here.
A7: Water-sales revenue per customer - not reported
A8: Sources checked | B8: State Water Board eAR Section 8b (water-rate revenue B1.1/B1.2); State Water Board eAR Section 4 (connection count, same reporting year); audited financial statement (secondary cross-check, where published)
A9: What was found | B9: The eAR Section 8b reports water-rate revenue for reporting year None, so this is a DIRECT filed figure; per customer it is divided by the eAR Section 4 connection count for the same reporting year, so numerator and denominator share the year.
A11: Assessment revenue (residual) - IMPOSSIBLE
A12: Sources checked | B12: Form 990 Part VIII line 2 (program-service revenue); State Water Board eAR Section 8b (water-rate revenue B1.1/B1.2); eAR Section 8b filer comment (WRRevenueComments)
A13: What was found | B13: A period-aligned residual cannot be computed for this filer, so the metric is rendered IMPOSSIBLE rather than guessed.
A14: Caveat | B14: Not derivable. The eAR Section 8b is reporting year None while the Form 990 fiscal year ends None; the two period ends are not aligned, so a period-aligned residual cannot be computed.
A16: Meter revenue - not reported
A17: Sources checked | B17: State Water Board eAR Section 8a (rate prices); State Water Board eAR Section 8b (revenue lines); audited financial statement
A18: What was found | B18: The rate price exists in Section 8a but no revenue or tier volume is reported, and the base charge is already inside water sales.
A19: Caveat | B19: The eAR Section 8a reports a base/meter rate PRICE, but the filing carries no meter revenue line and no tier volume, and the base charge is already inside the water-sales revenue (eAR Section 8b water rates). Building a separate meter figure would double-count. Not backed into from a total.
A21: Overage / tiered-penalty revenue - not reported
A22: Sources checked | B22: State Water Board eAR Section 8a (rate prices); State Water Board eAR Section 8b (revenue lines); audited financial statement
A23: What was found | B23: The rate price exists in Section 8a but no revenue or tier volume is reported, and the base charge is already inside water sales.
A24: Caveat | B24: The eAR Section 8a reports tiered/overage rate PRICES, but the filing carries no overage revenue and no tier consumption volume, and any overage billed is already inside the water-sales revenue. Building it would double-count. Not backed into from a total.
A26: eAR Section 8b reporting-period basis - sourced
A27: Sources checked | B27: eAR Section 8b B0.1 (WRFinancialReportingPeriod); eAR Section 8b B0.2 (WRFiscalYearStartDate)
A28: What was found | B28: The reporting basis (fiscal vs calendar year) is read from the filer's own B0.1/B0.2 answer and staged verbatim, never hardcoded, so the 990 comparison and the residual are period-aligned.
A30: Member (shareholder) count denominator - not reported
A31: Sources checked | B31: Form 990 (no member count stated); company website
A32: What was found | B32: No filing states a member/shareholder count, so the per-member unit economics read not reported rather than borrowing the connection count.
A34: Water volume delivered (acre-feet) - not reported
A35: Sources checked | B35: Form 990 (not in the filing); Consumer Confidence Report; eAR Section 6 (PRA-gated)
A36: What was found | B36: Volume delivered in acre-feet is not in the Form 990 and the CCR states only a source mix, so the per-acre-foot metrics read not reported; the eAR Section 6 is named as the source still needed.

Sheet Sources & audit
A1: Paradise Lake Mutual Water Company
A2: Sources & audit - full provenance and tie-outs (kept off the statements so they read clean)
A3: Entity ID: cawc_0179 | Fiscal year ends May 31.
A5: Presentation standard: every figure on the statement tabs is verified to its source filing and shown clean. A cell the filing does not report reads "not reported" (never estimated, never guessed).
A6: Citations, confidence tiers, and the filed-vs-computed tie-out checks live on the "Sources & audit" tab, keyed by cell, so every number is fully traceable without cluttering the statements. These pages are ready to use as filed.
A8: A. Filing provenance (one row per staged extraction)
A9: Fiscal year | B9: Period end | C9: Filing type | D9: Confidence | E9: Extraction ID | F9: Object ID | G9: Extracted by | H9: Extracted at | I9: Source URL
A10: FY2020 | B10: 2020-05-31 | C10: 990-EZ | D10: high | E10: d09c98d4-4a20-4db6-b2d2-7a4b8a68e813 | F10: 202012469349200216 | G10: claude-opus-5 | H10: 2026-10-06T04:29:04+00:00 | I10: https://apps.irs.gov/pub/epostcard/990/xml/2020/download990xml_2020_3.zip#202012469349200216_public.xml
A11: FY2021 | B11: 2021-05-31 | C11: 990-EZ | D11: high | E11: 7aa07c15-7905-4fdf-a54a-8e96df8a40ad | F11: 202112809349201806 | G11: claude-opus-5 | H11: 2026-10-06T04:29:07+00:00 | I11: https://apps.irs.gov/pub/epostcard/990/xml/2021/2021_TEOS_XML_01A.zip#202112809349201806_public.xml
A12: FY2022 | B12: 2022-05-31 | C12: 990-EZ | D12: high | E12: 12465fe7-91a0-4064-a344-81c4c825b7b8 | F12: 202242499349200449 | G12: claude-opus-5 | H12: 2026-10-06T04:29:09+00:00 | I12: https://apps.irs.gov/pub/epostcard/990/xml/2022/2022_TEOS_XML_01A.zip#202242499349200449_public.xml
A13: FY2023 | B13: 2023-05-31 | C13: 990 | D13: high | E13: ec6080b6-8466-4960-87e2-f86bb1b2d1bd | F13: 202332729349301623 | G13: claude-opus-5 | H13: 2026-10-06T04:29:10+00:00 | I13: https://apps.irs.gov/pub/epostcard/990/xml/2023/2023_TEOS_XML_10A.zip#202332729349301623_public.xml
A14: FY2024 | B14: 2024-05-31 | C14: 990 | D14: high | E14: f1ee4879-d2ff-4d5a-8f07-a7a26874507b | F14: 202412229349301906 | G14: claude-opus-5 | H14: 2026-10-06T04:29:11+00:00 | I14: https://apps.irs.gov/pub/epostcard/990/xml/2024/2024_TEOS_XML_08A.zip#202412229349301906_public.xml
A15: FY2025 | B15: 2025-05-31 | C15: 990 | D15: high | E15: 0f83850e-9c5d-40bd-9068-775ed561392c | F15: 202542519349300544 | G15: claude-opus-5 | H15: 2026-10-06T04:29:12+00:00 | I15: https://apps.irs.gov/pub/epostcard/990/xml/2025/2025_TEOS_XML_09A.zip#202542519349300544_public.xml
A17: B. Figure citations (every figure on the statement tabs, keyed by cell)
A18: Tab | B18: Cell | C18: Line item | D18: Form 990 line | E18: Key path | F18: Confidence | G18: As filed
A19: Financial Statements | B19: B73 | C19: 11a. Gross income from members or shareholders | D19: 11a | E19: part_v_other_irs_filings.members_and_shareholders_gross_income | F19: high | G19: 93196
A20: Financial Statements | B20: C73 | C20: 11a. Gross income from members or shareholders | D20: 11a | E20: part_v_other_irs_filings.members_and_shareholders_gross_income | F20: high | G20: 94032
A21: Financial Statements | B21: D73 | C21: 11a. Gross income from members or shareholders | D21: 11a | E21: part_v_other_irs_filings.members_and_shareholders_gross_income | F21: high | G21: 91540
A22: Financial Statements | B22: B74 | C22: 11b. Gross income from other sources | D22: 11b | E22: part_v_other_irs_filings.other_sources_gross_income | F22: high | G22: 10652
A23: Financial Statements | B23: C74 | C23: 11b. Gross income from other sources | D23: 11b | E23: part_v_other_irs_filings.other_sources_gross_income | F23: high | G23: 21118
A24: Financial Statements | B24: D74 | C24: 11b. Gross income from other sources | D24: 11b | E24: part_v_other_irs_filings.other_sources_gross_income | F24: high | G24: 20078
A25: Revenue (detail) | B25: B8 | C25: 2g. Total program service revenue | D25: 2g | E25: part_viii_revenue.total_program_service_revenue | F25: high | G25: 92696
A26: Revenue (detail) | B26: C8 | C26: 2g. Total program service revenue | D26: 2g | E26: part_viii_revenue.total_program_service_revenue | F26: high | G26: 94032
A27: Revenue (detail) | B27: D8 | C27: 2g. Total program service revenue | D27: 2g | E27: part_viii_revenue.total_program_service_revenue | F27: high | G27: 91540
A28: Revenue (detail) | B28: B9 | C28: 3. Investment income | D28: 3 | E28: part_viii_revenue.investment_income | F28: high | G28: 10652
A29: Revenue (detail) | B29: C9 | C29: 3. Investment income | D29: 3 | E29: part_viii_revenue.investment_income | F29: high | G29: 21118
A30: Revenue (detail) | B30: D9 | C30: 3. Investment income | D30: 3 | E30: part_viii_revenue.investment_income | F30: high | G30: 20078
... A85: Net-assets reconciliation | B85: D10 | C85: 9. Other changes in net assets | D85: Part XI line 9 | E85: part_xi_reconciliation.other_changes_net_assets | F85: high | G85: 0
A87: C. Tie-out checks (filed vs computed; any nonzero variance is flagged red)
A88: Tab | B88: Check | C88: Fiscal year | D88: Filed | E88: Computed | F88: Variance (computed - filed)
A89: Revenue (detail) | B89: 12. Total revenue | C89: FY2023 | D89: 103848 | E89: ='Revenue (detail)'!B13 | F89: =E89-D89
A90: Revenue (detail) | B90: 12. Total revenue | C90: FY2024 | D90: 115150 | E90: ='Revenue (detail)'!C13 | F90: =E90-D90
A91: Revenue (detail) | B91: 12. Total revenue | C91: FY2025 | D91: 111618 | E91: ='Revenue (detail)'!D13 | F91: =E91-D91
A92: Revenue (detail) | B92: 2g program service revenue = sum of lines 2a-2f (FY2025) | C92: FY2025 | D92: 91540 | E92: =SUM('Revenue (detail)'!C17:C17) | F92: =E92-D92
A93: Operating expenses (detail) | B93: 25. Total functional expenses | C93: FY2023 | D93: 56978 | E93: ='Operating expenses (detail)'!B18 | F93: =E93-D93
A94: Operating expenses (detail) | B94: 25. Total functional expenses | C94: FY2024 | D94: 61982 | E94: ='Operating expenses (detail)'!C18 | F94: =E94-D94
A95: Operating expenses (detail) | B95: 25. Total functional expenses | C95: FY2025 | D95: 69619 | E95: ='Operating expenses (detail)'!D18 | F95: =E95-D95
A96: Balance sheet (detail) | B96: 16. Total assets | C96: FY2023 | D96: 505822 | E96: ='Balance sheet (detail)'!B12 | F96: =E96-D96
A97: Balance sheet (detail) | B97: 16. Total assets | C97: FY2024 | D97: 556403 | E97: ='Balance sheet (detail)'!C12 | F97: =E97-D97
A98: Balance sheet (detail) | B98: 16. Total assets | C98: FY2025 | D98: 578789 | E98: ='Balance sheet (detail)'!D12 | F98: =E98-D98
...

Sheet Provenance
A1: Build provenance | B1: Built from source commit d418ffb17485 (2026-10-06); source fingerprint a75a8eee82c65cf7; 192 companies (179 retail mutual, 4 irrigation mutual, 3 mutual, no PWSID, purpose not stated, 2 frozen non-mutual (special district), 2 wholesale mutual, 1 frozen non-mutual (investor-owned), 1 frozen non-mutual (municipal)); 91 gates; build id 3d08d6d2a855.
A2: source_commit | B2: d418ffb174855ab78000d391d42f898397b0d8aa
A3: source_commit_date | B3: 2026-10-06
A4: source_fingerprint | B4: a75a8eee82c65cf7096931f06e18affdc28686a02895b46538e7298b57c04d94
A5: gate_count | B5: 91
A6: build_id | B6: 3d08d6d2a855
A7: registry: frozen non-mutual (investor-owned) | B7: 1
A8: registry: frozen non-mutual (municipal) | B8: 1
A9: registry: frozen non-mutual (special district) | B9: 2
A10: registry: irrigation mutual | B10: 4
A11: registry: mutual, no PWSID, purpose not stated | B11: 3
A12: registry: retail mutual | B12: 179
A13: registry: wholesale mutual | B13: 2
