Workbook

Sheet Summary
A1: San Cayetano Mutual Water Company
A2: Financial Summary - multi-year overview (USD)
A3: Entity ID: cawc_0012 | Fiscal year ends December 31.
A5: Presentation standard: every figure on the statement tabs is verified to its source filing and shown clean. A cell the filing does not report reads "not reported" (never estimated, never guessed).
A6: Citations, confidence tiers, and the filed-vs-computed tie-out checks live on the "Sources & audit" tab, keyed by cell, so every number is fully traceable without cluttering the statements. These pages are ready to use as filed.
A8: Metric | B8: FY2020 | C8: FY2021 | D8: FY2022 | E8: FY2023 | F8: FY2024 | G8: FY2025
A9: Operating results (USD)
A10: Total revenue | B10: 550804 | C10: 614919 | D10: 622008 | E10: 504438 | F10: 688756 | G10: 740896
A11: Total expenses | B11: 638511 | C11: 666664 | D11: 776385 | E11: 675762 | F11: 850296 | G11: 849440
A12: Net income | B12: -87707 | C12: -51745 | D12: -154377 | E12: -171324 | F12: -161540 | G12: -108544
A14: Financial position (USD, end of year)
A15: Total assets | B15: 2314486 | C15: 2338149 | D15: 2298858 | E15: 2274179 | F15: 2320111 | G15: 2312922
A16: Total liabilities | B16: 136442 | C16: 91972 | D16: 84828 | E16: 111413 | F16: 198830 | G16: 171125
A17: Net assets | B17: 2178044 | C17: 2246177 | D17: 2214030 | E17: 2162766 | F17: 2121281 | G17: 2141797
A19: Headline ratios
A20: Operating margin | B20: -0.1592345 | C20: -0.084149294 | D20: -0.24819134 | E20: -0.33963341 | F20: -0.23453879 | G20: -0.14650369
A21: Revenue growth (YoY) | B21: 0.15056692 | C21: 0.11640257 | D21: 0.011528348 | E21: -0.18901686 | F21: 0.36539277 | G21: 0.0757017
A22: Return on assets | B22: -0.037894807 | C22: -0.022130754 | D22: -0.067153778 | E22: -0.075334439 | F22: -0.069625979 | G22: -0.046929382
A24: Figures as reported in source filings (full provenance on the Sources & audit tab). Parentheses denote negatives; ratios are computed upstream in financials_annual.

Sheet Notes
A1: Notes
A2: Human annotations from the versioned store (data/notes/). Annotations only: they never change a reported figure or a confidence tier.
A4: Date | B4: Tag | C4: Author | D4: Note
A5: No notes recorded yet.

Sheet Financial Statements
A1: San Cayetano Mutual Water Company
A2: Financial Statements - income statement, balance sheet, cash flow, member income test (USD)
A3: Entity ID: cawc_0012 | Fiscal year ends December 31.
A5: INCOME STATEMENT - as reported (USD)
A6: Line item | B6: FY2020 | C6: FY2021 | D6: FY2022 | E6: FY2023 | F6: FY2024 | G6: FY2025
A7: Revenue
A8: Program service revenue | B8: 550422 | C8: 614301 | D8: 621870 | E8: 504433 | F8: 688217 | G8: 737231
A9: Investment income | B9: 382 | C9: 618 | D9: 138 | E9: 5 | F9: 539 | G9: 177
A10: Net rental income | G10: 3750
A11: Net gain/(loss) on investment sales
A12: Other revenue | G12: -262
A13: Contributions & grants
A14: Total revenue | B14: 550804 | C14: 614919 | D14: 622008 | E14: 504438 | F14: 688756 | G14: 740896
A16: Expenses
A17: Depreciation | B17: 142732 | C17: 148842 | D17: 153708 | E17: 154263 | F17: 154118 | G17: 159525
A18: Interest expense
A19: Total expenses | B19: 638511 | C19: 666664 | D19: 776385 | E19: 675762 | F19: 850296 | G19: 849440
A21: Net income | B21: -87707 | C21: -51745 | D21: -154377 | E21: -171324 | F21: -161540 | G21: -108544
A24: BALANCE SHEET - as reported (USD, end of year)
A25: Line item | B25: FY2020 | C25: FY2021 | D25: FY2022 | E25: FY2023 | F25: FY2024 | G25: FY2025
A26: Assets
A27: Cash | B27: 420890 | C27: 449579 | D27: 572896 | E27: 659108 | F27: 257151 | G27: 242796
A28: Savings & temporary investments | B28: 15016 | C28: 15017 | D28: 15019 | E28: 15024 | F28: 25384 | G28: 25561
A29: Accounts receivable | B29: 85416 | C29: 70456 | D29: 65917 | E29: 109284 | F29: 140711 | G29: 95086
A30: Inventories
A31: Prepaid expenses | B31: 7236 | C31: 7963 | D31: 3600 | E31: 3600 | F31: 4651 | G31: 3600
A32: Property, plant & equipment (gross) | B32: 3593211 | C32: 3751257 | D32: 3751256 | E32: 3751256 | F32: 4299876 | G32: 4347319
A33: Less: accumulated depreciation | B33: -1815283 | C33: -1964123 | D33: -2117830 | E33: -2272093 | F33: -2426212 | G33: -2558665
A34: Net property, plant & equipment | B34: 1777928 | C34: 1787134 | D34: 1633426 | E34: 1479163 | F34: 1873664 | G34: 1788654
A35: Total assets | B35: 2314486 | C35: 2338149 | D35: 2298858 | E35: 2274179 | F35: 2320111 | G35: 2312922
A37: Liabilities
A38: Accounts payable | B38: 136442 | C38: 91972 | D38: 84828 | E38: 111413 | F38: 198830 | G38: 171125
A39: Mortgages & notes payable
A40: Total liabilities | B40: 136442 | C40: 91972 | D40: 84828 | E40: 111413 | F40: 198830 | G40: 171125
A42: Net Assets / Equity
A43: Capital stock | B43: 75432 | C43: 75432 | D43: 75432 | E43: 75432 | F43: 75432 | G43: 75432
A44: Paid-in capital | B44: 63402 | C44: 63402 | D44: 63402 | E44: 63402 | F44: 63402 | G44: 63402
A45: Retained earnings | B45: 2039210 | C45: 2107343 | D45: 2075196 | E45: 2023932 | F45: 1982447 | G45: 2002963
A46: Net assets | B46: 2178044 | C46: 2246177 | D46: 2214030 | E46: 2162766 | F46: 2121281 | G46: 2141797
A49: CASH FLOW - derived proxy (USD)
...

Sheet Balance Sheet
A1: San Cayetano Mutual Water Company
A2: Balance Sheet - as reported (USD, end of year)
A3: Entity ID: cawc_0012 | Fiscal year ends December 31.
A5: Line item | B5: FY2020 | C5: FY2021 | D5: FY2022 | E5: FY2023 | F5: FY2024 | G5: FY2025
A6: Assets
A7: Cash | B7: 420890 | C7: 449579 | D7: 572896 | E7: 659108 | F7: 257151 | G7: 242796
A8: Savings & temporary investments | B8: 15016 | C8: 15017 | D8: 15019 | E8: 15024 | F8: 25384 | G8: 25561
A9: Accounts receivable | B9: 85416 | C9: 70456 | D9: 65917 | E9: 109284 | F9: 140711 | G9: 95086
A10: Inventories
A11: Prepaid expenses | B11: 7236 | C11: 7963 | D11: 3600 | E11: 3600 | F11: 4651 | G11: 3600
A12: Property, plant & equipment (gross) | B12: 3593211 | C12: 3751257 | D12: 3751256 | E12: 3751256 | F12: 4299876 | G12: 4347319
A13: Less: accumulated depreciation | B13: -1815283 | C13: -1964123 | D13: -2117830 | E13: -2272093 | F13: -2426212 | G13: -2558665
A14: Net property, plant & equipment | B14: 1777928 | C14: 1787134 | D14: 1633426 | E14: 1479163 | F14: 1873664 | G14: 1788654
A15: Total assets | B15: 2314486 | C15: 2338149 | D15: 2298858 | E15: 2274179 | F15: 2320111 | G15: 2312922
A17: Liabilities
A18: Accounts payable | B18: 136442 | C18: 91972 | D18: 84828 | E18: 111413 | F18: 198830 | G18: 171125
A19: Mortgages & notes payable
A20: Total liabilities | B20: 136442 | C20: 91972 | D20: 84828 | E20: 111413 | F20: 198830 | G20: 171125
A22: Net Assets / Equity
A23: Capital stock | B23: 75432 | C23: 75432 | D23: 75432 | E23: 75432 | F23: 75432 | G23: 75432
A24: Paid-in capital | B24: 63402 | C24: 63402 | D24: 63402 | E24: 63402 | F24: 63402 | G24: 63402
A25: Retained earnings | B25: 2039210 | C25: 2107343 | D25: 2075196 | E25: 2023932 | F25: 1982447 | G25: 2002963
A26: Net assets | B26: 2178044 | C26: 2246177 | D26: 2214030 | E26: 2162766 | F26: 2121281 | G26: 2141797
A28: Balance check (assets − liab. − net assets) | B28: 0 | C28: 0 | D28: 0 | E28: 0 | F28: 0 | G28: 0
A30: Net PP&E is the reported ppe_net column (gross less accumulated depreciation). The balance check should be ~0 where all three totals are reported; a non-zero value flags a reporting or extraction discrepancy worth reviewing.

Sheet Officers & contractors
A1: San Cayetano Mutual Water Company
A2: Officers, Directors & Contractors - Form 990 Part VII (FY2025; USD)
A3: Entity ID: cawc_0012 | Fiscal year ends December 31.
A5: Section A - Officers, directors, trustees, key employees
A6: Name | B6: Title | C6: Reportable comp (org) | D6: Reportable comp (related) | E6: Other comp | F6: Total compensation
A7: Vince Giacolone | B7: President | C7: 0 | D7: 0 | E7: 0 | F7: 0
A8: Paul Romero | B8: Vice President | C8: 0 | D8: 0 | E8: 0 | F8: 0
A9: Salvador Dominguez | B9: Secretary/Treasurer | C9: 0 | D9: 0 | E9: 0 | F9: 0
A10: Gary Ball | B10: Assistant Secretary | C10: 0 | D10: 0 | E10: 0 | F10: 0
A11: Myles Shoemaker | B11: Director | C11: 0 | D11: 0 | E11: 0 | F11: 0
A13: Section B - Independent contractors (over $100,000)
A14: Contractor | B14: Services | C14: Compensation
A16: Section A lists every officer, director, trustee and key employee filed for the latest year; the two with the highest total compensation are highlighted. Total compensation is computed (reportable org + related + other). Section B lists each independent contractor paid over $100,000; the return reports None such contractor(s). Source and confidence for every figure are on the Sources & audit tab.

Sheet Revenue (detail)
A1: San Cayetano Mutual Water Company
A2: Revenue - Form 990 Part VIII (USD)
A3: Entity ID: cawc_0012 | Fiscal year ends December 31.
A5: Part VIII line | B5: FY2020 | C5: FY2021 | D5: FY2022 | E5: FY2023 | F5: FY2024 | G5: FY2025
A6: Revenue by category
A7: 1h. Total contributions, gifts, grants | B7: not reported | C7: not reported | D7: not reported | E7: not reported | F7: not reported | G7: not reported
A8: 2g. Total program service revenue | B8: 550422 | C8: 614301 | D8: 621870 | E8: 504433 | F8: 688217 | G8: 737231
A9: 3. Investment income | B9: 382 | C9: 618 | D9: 138 | E9: 5 | F9: 539 | G9: 177
A10: 6d. Net rental income | B10: not reported | C10: not reported | D10: not reported | E10: not reported | F10: not reported | G10: 3750
A11: 7d. Net gain/(loss) from investment sales | B11: not reported | C11: not reported | D11: not reported | E11: not reported | F11: not reported | G11: not reported
A12: 11e. Other revenue | B12: not reported | C12: not reported | D12: not reported | E12: not reported | F12: not reported | G12: -262
A13: 12. Total revenue | B13: =SUM(B7:B12) | C13: =SUM(C7:C12) | D13: =SUM(D7:D12) | E13: =SUM(E7:E12) | F13: =SUM(F7:F12) | G13: =SUM(G7:G12)
A15: Program service revenue detail - FY2025 (lines 2a-2f)
A16: Description | B16: Business code | C16: Total revenue
A17: Irrigation Water | B17: 221310 | C17: 535433
A18: Operations Assessments | B18: 221310 | C18: 154800
A19: Domestic Water | B19: 221310 | C19: 31690
A20: Other Program Services | B20: 221310 | C20: 15308
A21: Revenue category subtotals are as filed. Total revenue (line 12) is a live SUM of the category cells above; its tie-out to the filed total is on the Sources & audit tab. Program service revenue detail is shown for the latest year, with its sum-to-line-2g check on that same audit tab.

Sheet Operating expenses (detail)
A1: San Cayetano Mutual Water Company
A2: Statement of Functional Expenses - Form 990 Part IX (USD)
A3: Entity ID: cawc_0012 | Fiscal year ends December 31.
A5: Part IX line (column A Total) | B5: FY2020 | C5: FY2021 | D5: FY2022 | E5: FY2023 | F5: FY2024 | G5: FY2025
A6: Functional expenses, column A Total - by year
A7: 5. Compensation of current officers, directors, trustees | B7: not reported | C7: not reported | D7: 20700 | E7: not reported | F7: 0 | G7: not reported
A8: 6. Compensation to disqualified persons | B8: 20700 | C8: not reported | D8: not reported | E8: not reported | F8: not reported | G8: not reported
A9: 7. Other salaries and wages | B9: not reported | C9: 22425 | D9: not reported | E9: 12075 | F9: not reported | G9: not reported
A10: 10. Payroll taxes | B10: 2006 | C10: 1571 | D10: 2060 | E10: 1088 | F10: not reported | G10: not reported
A11: 11c. Fees for services: accounting | B11: 5075 | C11: 24888 | D11: 24718 | E11: 22670 | F11: 25915 | G11: 25230
A12: 13. Office expenses | B12: 554 | C12: 1113 | D12: not reported | E12: not reported | F12: not reported | G12: not reported
A13: 22. Depreciation, depletion, and amortization | B13: 142732 | C13: 148842 | D13: 153708 | E13: 154263 | F13: 154118 | G13: 159525
A14: 23. Insurance | B14: 6234 | C14: 5823 | D14: 9398 | E14: 7814 | F14: 5931 | G14: 7951
A15: 24. Well Power - SCE | B15: 203918 | C15: 267290 | D15: not reported | E15: not reported | F15: not reported | G15: not reported
A16: 24. Gas Company | B16: 557 | C16: 1225 | D16: 1386 | E16: 300 | F16: 2620 | G16: 2695
A17: 24. Fillmore Pumpers Association | B17: 1953 | C17: 2022 | D17: not reported | E17: not reported | F17: not reported | G17: not reported
A18: 24. UWCD Pump Tax | B18: 115858 | C18: 146648 | D18: not reported | E18: not reported | F18: not reported | G18: not reported
A19: 24. Utilities - SCE | B19: not reported | C19: not reported | D19: 301887 | E19: 275482 | F19: 277059 | G19: 262993
A20: 24. Fillmore Piru Basin | B20: not reported | C20: not reported | D20: 35003 | E20: 14388 | F20: 20747 | G20: 18809
A21: 24. Fillmore Pumpers Assoc | B21: not reported | C21: not reported | D21: 867 | E21: 571 | F21: 661 | G21: 574
A22: 24e. All other expenses | B22: 138924 | C22: 44817 | D22: 226658 | E22: 187111 | F22: 363245 | G22: 371663
A23: 25. Total functional expenses | B23: =SUM(B7:B22) | C23: =SUM(C7:C22) | D23: =SUM(D7:D22) | E23: =SUM(E7:E22) | F23: =SUM(F7:F22) | G23: =SUM(G7:G22)
A25: Functional column split - FY2025 (col A = B + C + D)
A26: Part IX line | B26: A. Total | C26: B. Program services | D26: C. Management & general | E26: D. Fundraising
A27: 11c. Fees for services: accounting | B27: 25230 | C27: 25230 | D27: 0 | E27: 0
A28: 22. Depreciation, depletion, and amortization | B28: 159525 | C28: 159525 | D28: 0 | E28: 0
A29: 23. Insurance | B29: 7951 | C29: 7951 | D29: 0 | E29: 0
A30: 25. Total (filed col A / B / C / D) | B30: 849440 | C30: 849440 | D30: 0 | E30: 0
A32: Top block: each Part IX line, column A (Total), by year, as filed. Total functional expenses (line 25) is a live SUM of the line cells; its tie-out to the filed total is on the Sources & audit tab. Filer-itemized 24a-24d rows show the most recent year's as-filed wording; rows are aligned across years case-insensitively with collapsed spacing, so a line filed only in a different capitalization or spacing shares one row, while genuinely different wording stays a separate row (every as-filed variant is recorded on the Sources & audit tab). Lower block: the program / management / fundraising split for the latest year, with its col A = B + C + D check on the audit tab. Lines this filer does not report are omitted rather than shown empty.

Sheet Balance sheet (detail)
A1: San Cayetano Mutual Water Company
A2: Balance Sheet - Form 990 Part X (end of year, USD)
A3: Entity ID: cawc_0012 | Fiscal year ends December 31.
A5: Part X line (column B, EOY) | B5: FY2020 | C5: FY2021 | D5: FY2022 | E5: FY2023 | F5: FY2024 | G5: FY2025
A6: Assets
A7: 1. Cash - non-interest-bearing | B7: 420890 | C7: 449579 | D7: 572896 | E7: 659108 | F7: 257151 | G7: 242796
A8: 2. Savings and temporary cash investments | B8: 15016 | C8: 15017 | D8: 15019 | E8: 15024 | F8: 25384 | G8: 25561
A9: 4. Accounts receivable, net | B9: 85416 | C9: 70456 | D9: 65917 | E9: 109284 | F9: 140711 | G9: 95086
A10: 9. Prepaid expenses and deferred charges | B10: 7236 | C10: 7963 | D10: 3600 | E10: 3600 | F10: 4651 | G10: 3600
A11: 10c. Land, buildings, and equipment, net | B11: 1777928 | C11: 1787134 | D11: 1633426 | E11: 1479163 | F11: 1873664 | G11: 1788654
A12: 14. Intangible assets | B12: 8000 | C12: 8000 | D12: 8000 | E12: 8000 | F12: 8000 | G12: 30789
A13: 15. Other assets | B13: not reported | C13: not reported | D13: not reported | E13: not reported | F13: 10550 | G13: 126436
A14: 16. Total assets | B14: =SUM(B7:B13) | C14: =SUM(C7:C13) | D14: =SUM(D7:D13) | E14: =SUM(E7:E13) | F14: =SUM(F7:F13) | G14: =SUM(G7:G13)
A16: Liabilities
A17: 17. Accounts payable and accrued expenses | B17: 136442 | C17: 91972 | D17: 84828 | E17: 111413 | F17: 198830 | G17: 171125
A18: 26. Total liabilities | B18: =SUM(B17:B17) | C18: =SUM(C17:C17) | D18: =SUM(D17:D17) | E18: =SUM(E17:E17) | F18: =SUM(F17:F17) | G18: =SUM(G17:G17)
A20: Net assets / fund balances
A21: 29. Capital stock or trust principal | B21: 75432 | C21: 75432 | D21: 75432 | E21: 75432 | F21: 75432 | G21: 75432
A22: 30. Paid-in or capital surplus | B22: 63402 | C22: 63402 | D22: 63402 | E22: 63402 | F22: 63402 | G22: 63402
A23: 31. Retained earnings / accumulated funds | B23: 2039210 | C23: 2107343 | D23: 2075196 | E23: 2023932 | F23: 1982447 | G23: 2002963
A24: 32. Total net assets / fund balances | B24: =SUM(B21:B23) | C24: =SUM(C21:C23) | D24: =SUM(D21:D23) | E24: =SUM(E21:E23) | F24: =SUM(F21:F23) | G24: =SUM(G21:G23)
A26: Every Part X line is end-of-year (column B), as filed. Section totals (lines 16 / 26 / 32) are live SUMs of the lines above; their tie-outs and the balance-sheet identity (16 = 26 + 32) are on the Sources & audit tab. This filer files as a non-FASB mutual, so net assets sit on lines 29-31 (capital stock / paid-in capital / retained earnings); lines this filer does not report are omitted. Lines 10a/10b net into line 10c (shown).

Sheet Net-assets reconciliation
A1: San Cayetano Mutual Water Company
A2: Reconciliation of Net Assets - Form 990 Part XI (USD)
A3: Entity ID: cawc_0012 | Fiscal year ends December 31.
A5: Part XI line | B5: FY2020 | C5: FY2021 | D5: FY2022 | E5: FY2023 | F5: FY2024 | G5: FY2025
A6: Reconciliation
A7: 4. Net assets, beginning of year | B7: 2141902 | C7: 2178044 | D7: 2246177 | E7: 2214030 | F7: 2162766 | G7: 2121281
A8: 3. Revenue less expenses | B8: -87707 | C8: -51745 | D8: -154377 | E8: -171324 | F8: -161540 | G8: -108544
A9: 8. Prior period adjustments | B9: not reported | C9: not reported | D9: not reported | E9: not reported | F9: not reported | G9: not reported
A10: 9. Other changes in net assets | B10: 123849 | C10: 119878 | D10: not reported | E10: 120060 | F10: 120055 | G10: 129060
A11: 10. Net assets, end of year | B11: =SUM(B7,B8,B9,B10) | C11: =SUM(C7,C8,C9,C10) | D11: =SUM(D7,D8,D9,D10) | E11: =SUM(E7,E8,E9,E10) | F11: =SUM(F7,F8,F9,F10) | G11: =SUM(G7,G8,G9,G10)
A13: Part XI reconciles beginning to ending net assets. Ending net assets (line 10) is a live formula: beginning balance (line 4) + revenue less expenses (line 3) + prior-period adjustments (8) + other changes (9). Its tie-out to the filed line 10 (and to Part X line 32) is on the Sources & audit tab. Lines 5-7 (unrealized gains, donated services, investment expenses) are not filed by this entity.

Sheet Cash flow proxies
A1: San Cayetano Mutual Water Company
A2: Cash Flow Proxies - derived (USD)
A3: Entity ID: cawc_0012 | Fiscal year ends December 31.
A5: PROXY ONLY. The source filings contain no statement of cash flows. Lines below are derived from the reported income statement and year-over-year balance-sheet changes; treat as directional estimates, not GAAP cash flows. The earliest year has no prior period, so its delta cells are blank.
A7: Proxy line (USD) | B7: FY2020 | C7: FY2021 | D7: FY2022 | E7: FY2023 | F7: FY2024 | G7: FY2025
A8: Operating
A9: Net income | B9: -87707 | C9: -51745 | D9: -154377 | E9: -171324 | F9: -161540 | G9: -108544
A10: + Depreciation (reported) | B10: 142732 | C10: 148842 | D10: 153708 | E10: 154263 | F10: 154118 | G10: 159525
A11: − Δ Accounts receivable | C11: 14960 | D11: 4539 | E11: -43367 | F11: -31427 | G11: 45625
A12: − Δ Inventories
A13: − Δ Prepaid expenses | C13: -727 | D13: 4363 | E13: 0 | F13: -1051 | G13: 1051
A14: + Δ Accounts payable | C14: -44470 | D14: -7144 | E14: 26585 | F14: 87417 | G14: -27705
A15: Operating cash flow proxy | C15: 66860 | D15: 1089 | E15: -33843 | F15: 47517 | G15: 69952
A17: Investing
A18: − Δ PP&E gross (capex proxy) | C18: -158046 | D18: 1 | E18: 0 | F18: -548620 | G18: -47443
A20: Financing
A21: Δ Mortgages & notes payable
A23: Reconciliation
A24: Δ Cash + temp. investments (actual) | C24: 28690 | D24: 123319 | E24: 86217 | F24: -391597 | G24: -14178
A26: The capex proxy assumes gross PP&E rises only via capital spending (it ignores disposals). 'Δ Cash + temp. investments (actual)' is the real reported change in liquid funds and is the most reliable line here; the operating/investing/financing proxies will not perfectly reconcile to it.

Sheet Ratios
A1: San Cayetano Mutual Water Company
A2: Financial Ratios
A3: Entity ID: cawc_0012 | Fiscal year ends December 31.
A5: Ratio | B5: FY2020 | C5: FY2021 | D5: FY2022 | E5: FY2023 | F5: FY2024 | G5: FY2025
A6: Profitability (computed upstream)
A7: Operating margin (NI / revenue) | B7: -0.1592345 | C7: -0.084149294 | D7: -0.24819134 | E7: -0.33963341 | F7: -0.23453879 | G7: -0.14650369
A8: Expense ratio (expenses / revenue) | B8: 1.1592345 | C8: 1.0841493 | D8: 1.2481913 | E8: 1.3396334 | F8: 1.2345388 | G8: 1.1465037
A9: Return on assets (NI / assets) | B9: -0.037894807 | C9: -0.022130754 | D9: -0.067153778 | E9: -0.075334439 | F9: -0.069625979 | G9: -0.046929382
A10: Revenue growth (YoY) | B10: 0.15056692 | C10: 0.11640257 | D10: 0.011528348 | E10: -0.18901686 | F10: 0.36539277 | G10: 0.0757017
A12: Leverage & solvency
A13: Debt-to-assets (liab. / assets) | B13: 0.058951318 | C13: 0.039335389 | D13: 0.036900061 | E13: 0.048990427 | F13: 0.085698486 | G13: 0.073986498
A14: Equity ratio (net assets / assets) | B14: 0.94104868 | C14: 0.96066461 | D14: 0.96309994 | E14: 0.95100957 | F14: 0.91430151 | G14: 0.9260135
A16: Liquidity & asset profile (derived here)
A17: Current ratio (current assets / AP) | B17: 3.8738658 | C17: 5.9041339 | D17: 7.7501768 | E17: 7.0639512 | F17: 2.1520746 | G17: 2.1448824
A18: Cash ratio ((cash+temp inv.) / total liab.) | B18: 3.1948081 | C18: 5.0514939 | D18: 6.9306715 | E18: 6.0507481 | F18: 1.4209878 | G18: 1.5681928
A19: Asset age proxy (accum. deprec. / gross PP&E) | B19: 0.505198 | C19: 0.52359063 | D19: 0.56456557 | E19: 0.6056886 | F19: 0.56425162 | G19: 0.58856159
A21: Upstream ratios are read from financials_annual; derived ratios are computed only where inputs are reported. Current ratio uses accounts payable as the current-liability proxy (the filings do not split current vs. long-term liabilities). Asset age proxy: a higher % implies older / more depreciated infrastructure.

Sheet Unit economics
A1: San Cayetano Mutual Water Company
A2: Unit economics - per-customer revenue by category (USD)
A3: Entity ID: cawc_0012 | Fiscal year ends December 31.
A5: Every metric here is PER CUSTOMER (a metered service connection). It is not a per-member figure; the member (shareholder) count is a different denominator, shown in the denominator block. The visible cell shows the value and its classification; the numerator, denominator, formula, and rationale are in each metric's LOGIC popup.
A6: Per-customer denominator (service connections) | B6: 50 | C6: State Water Board eAR Section 4 (CurTotalConnections), reporting year 2023
A7: Total annual revenue (eAR Section 8b B1.8) | B7: 13753 | C7: State Water Board eAR Section 8b, question B1.8 (total annual revenue), reporting year 2023
A8: Primary source | C8: State Water Board eAR Section 8b (revenue by rate/fee), reporting year 2023
A10: Revenue categories (value, classification, per customer, share)
A11: Revenue category | B11: Classification | C11: Value (USD) | D11: Per customer | E11: Share of revenue
A12: Water sales revenue | B12: DIRECT | C12: 13753 | D12: 275.06 | E12: 1
A13: Assessment revenue (990 program-service revenue not matched to eAR water-rate revenue) | B13: DERIVED | C13: 490680 | D13: 9813.6 | E13: 0.9727
A14: Meter revenue | B14: not reported | C14: not reported | D14: not reported | E14: not reported
A15: Overage or tiered penalty revenue | B15: not reported | C15: not reported | D15: not reported | E15: not reported
A17: Water sales revenue - DIRECT
A18: Revenue customers paid for water service, read straight off the filed eAR Section 8b water-rate line. A DIRECT filed figure, not computed by us.
A19: Numerator: Water rate revenue | B19: 13753 | C19: eAR Section 8b field B1.1 (residential water rates) only (this filer reported no non-residential water-rate revenue). State Water Board eAR Section 8b, question B1.1 + B1.2 (revenue from water rates), reporting year 2023
A20: Denominator: Total service connections | B20: 50 | C20: eAR Section 4 CurTotalConnections, reporting year 2023. State Water Board eAR Section 4 (CurTotalConnections), reporting year 2023
A21: Per customer: water rate revenue $13,753 / 50 connections = $275.06 per connection
A22: Share of revenue: water rate revenue $13,753 / total annual revenue (eAR Section 8b B1.8) $13,753 = 100.00%
A23: Period treatment: Numerator (eAR Section 8b, the calendar year 2023) and denominator (eAR Section 4 connections reported in the same eAR filing) are both the eAR reporting year 2023, so the two sides are bound to the same reporting year.
A24: Rationale: Dividing water-rate revenue by the number of metered service connections gives the average revenue per customer; dividing by total annual revenue shows how much of the system's income comes from water rates.
A26: Assessment revenue (990 program-service revenue not matched to eAR water-rate revenue) - DERIVED
A27: A DERIVED residual (medium confidence): the part of the Form 990 program-service revenue that is not matched by the eAR water-rate revenue for the same period. Computed by us, not a filed line.
A28: Input A: Form 990 program-service revenue | B28: 504433 | C28: Form 990 Part VIII line 2 (total program-service revenue), fiscal year 2023 ending December 31, 2023
A29: Input B: eAR water-rate revenue | B29: 13753 | C29: State Water Board eAR Section 8b, question B1.1 + B1.2 (revenue from water rates), reporting year 2023
A30: Residual (A minus B) = assessment revenue | B30: =B28-B29 | C30: $504,433 (990 program-service revenue) minus $13,753 (eAR water-rate revenue) = $490,680
A31: Period alignment: Both inputs cover the same period: the eAR Section 8b is the calendar year 2023 and the Form 990 fiscal year 2023 ends December 31, 2023, so the residual is period-aligned.
A32: What it IS: revenue the system booked as program service on its 990 that is not accounted for by the eAR water-rate line, plausibly member assessments and other service revenue.
A33: This residual is a difference between two sources for the same period; it is not a separately filed assessment line and may include other unmatched revenue.
A34: Denominator: Total service connections | B34: 50 | C34: eAR Section 4 CurTotalConnections, reporting year 2023. State Water Board eAR Section 4 (CurTotalConnections), reporting year 2023
A35: Per customer: residual $490,680 / 50 connections = $9,813.60 per connection
A36: Share of revenue: residual $490,680 / 990 program-service revenue $504,433 = 97.27%
A38: Meter revenue - not reported
A39: Not reported. This category is not built because doing so would double-count.
A40: Reason: The eAR Section 8a reports a base/meter rate PRICE, but the filing carries no meter revenue line and no tier volume, and the base charge is already inside the water-sales revenue (eAR Section 8b water rates). Building a separate meter figure would double-count. Not backed into from a total.
A42: Overage or tiered penalty revenue - not reported
A43: Not reported. This category is not built because doing so would double-count.
A44: Reason: The eAR Section 8a reports tiered/overage rate PRICES, but the filing carries no overage revenue and no tier consumption volume, and any overage billed is already inside the water-sales revenue. Building it would double-count. Not backed into from a total.

Sheet Rate structure
A1: San Cayetano Mutual Water Company
A2: Rate structure and representative bill - eAR Section 8a (RY2024)
A3: Entity ID: cawc_0012 | Fiscal year ends December 31.
A5: This block is a rate-schedule illustration at defined usage levels. It is NOT billed revenue and not a claim about any real customer's usage. The revenue side of unit economics is the separate Unit Economics block.
A6: Structure: Uniform: fixed base plus a single volumetric rate, billed monthly, priced per HCF. Rate schedule last updated 07/01/2025.
A7: Defined single-family usage levels, identical for every company so the bill is comparable: Low = 5 HCF/month (~125 gallons/day); Median = 10 HCF/month (~249 gallons/day); High = 25 HCF/month (~623 gallons/day). 1 HCF = 748 gallons, and 1 thousand gallons = 1,000 gallons. The usage is converted into the company's own filed unit before the filed tiers are applied, and the bill is stated as a monthly equivalent: a bimonthly structure is computed at twice the monthly usage and divided by two, and any other billing period the same way with its factor stated. These are an illustration, not a measured usage for any real customer.
A9: Defined usage levels (EDITABLE - change a yellow cell to move the bill)
B10: Low | C10: Median | D10: High
A11: Monthly usage (HCF) | B11: 5 | C11: 10 | D11: 25
A12: Months per bill (from filed billing frequency) | B12: 1 | C12: monthly biller
A14: Filed rate table - single-family residential (as filed, eAR Section 8a)
A15: Base / fixed charge per monthly bill ($) | B15: 20
A16: Tier | B16: Range (HCF) | C16: Price ($/HCF) | D16: Upper limit (HCF)
A17: Tier 1 | B17: all usage (HCF) | C17: 8.38 | D17: no limit
A19: Representative monthly bill - LIVE (edit a yellow usage cell to recompute)
B20: Low | C20: Median | D20: High
A21: Usage per bill (HCF) | B21: =B11*$B$12 | C21: =C11*$B$12 | D21: =D11*$B$12
A22: Tier 1 charge per bill ($) | B22: =$C$17*MAX(0,B21-0) | C22: =$C$17*MAX(0,C21-0) | D22: =$C$17*MAX(0,D21-0)
A23: Volumetric charge per bill ($) | B23: =SUM(B22) | C23: =SUM(C22) | D23: =SUM(D22)
A24: Base charge per bill ($) | B24: =$B$15 | C24: =$B$15 | D24: =$B$15
A25: Total per bill ($) | B25: =B24+B23 | C25: =C24+C23 | D25: =D24+D23
A26: Total per MONTH ($) | B26: =B25/$B$12 | C26: =C25/$B$12 | D26: =D25/$B$12
A27: Fixed per month ($) | B27: =$B$15/$B$12 | C27: =$B$15/$B$12 | D27: =$B$15/$B$12
A28: Volumetric per month ($) | B28: =B23/$B$12 | C28: =C23/$B$12 | D28: =D23/$B$12
A29: Effective price ($/HCF) | B29: =IF(B11=0,"",B26/B11) | C29: =IF(C11=0,"",C26/C11) | D29: =IF(D11=0,"",D26/D11)
A31: Rate-structure comparison metrics
A32: Fixed share of the bill at median usage | B32: =C27/C26 | C32: fixed / total at 10 HCF/month
A33: Tier price ratio (highest to lowest positive tier) | B33: =$C$17/$C$17 | C33: uniform structure: a single volumetric rate, so the ratio is 1.00 (flat).
A34: Rate structure (as filed) | B34: uniform (Uniform Usage)
A36: State Water Board eAR Section 8a (Customer Charges), single- and multi-family residential charges grid, reporting year 2024. Rate structure only; no revenue.

Sheet eAR revenue & expenses
A1: San Cayetano Mutual Water Company
A2: eAR annual revenue and expenses - State Water Board eAR Section 8b (USD)
A3: Entity ID: cawc_0012 | Fiscal year ends December 31.
A5: The water system's own annual figures from the public eAR Section 8b, on the calendar year 2023 the filer self-reported (B0.1/B0.2). Shown beside the period-aligned Form 990 with the variance flagged: a different source (a State Water Board self-report vs an IRS filing). Preserved as filed, never reconciled.
A6: Reporting period basis (self-reported) | B6: calendar year 2023 | C6: eAR Section 8b B0.1 (WRFinancialReportingPeriod)
A8: Revenue (eAR Section 8b, questions B1.x)
A9: Line | B9: Amount (USD) | C9: Citation
A10: Water rate revenue | B10: 13753 | C10: State Water Board eAR Section 8b, question B1.1 + B1.2 (revenue from water rates), reporting year 2023
A11: Other fees and charges | B11: 0 | C11: State Water Board eAR Section 8b, question B1.3 + B1.4 (revenue from other fees), reporting year 2023
A12: Non-customer revenue | B12: 0 | C12: State Water Board eAR Section 8b, question B1.7 (grants, interest, and other non-customer), reporting year 2023
A13: Total annual revenue | B13: 13753 | C13: State Water Board eAR Section 8b, question B1.8 (total annual revenue for the reporting year), reporting year 2023
A15: Expenses (eAR Section 8b, questions B2.x)
A16: Line | B16: Amount (USD) | C16: Citation
A17: Operations and maintenance | B17: 521499 | C17: State Water Board eAR Section 8b, question B2.1 (annual O and M expense), reporting year 2023
A18: Capital | B18: 0 | C18: State Water Board eAR Section 8b, question B2.2 (annual expenses from investing or capital), reporting year 2023
A19: Financing | B19: 0 | C19: State Water Board eAR Section 8b, question B2.3 (annual expenses from financing), reporting year 2023
A20: Other | B20: 154263 | C20: State Water Board eAR Section 8b, question B2.4 (total other annual expenses), reporting year 2023
A21: Total annual expenses | B21: 675762 | C21: State Water Board eAR Section 8b, question B2.5 (total annual expenses), reporting year 2023
A23: Period-aligned Form 990 comparison (variance surfaced, never reconciled)
A24: Measure | B24: eAR Section 8b | C24: Form 990
A25: total revenue | B25: 13753 | C25: 504438
A26: Variance (eAR minus Form 990) | B26: =B25-C25
A27: The eAR Section 8b total revenue (State Water Board self-report, calendar year 2023) and the Form 990 total revenue (IRS filing) are a different source and cover the same calendar year 2023. Both are carried as filed; the variance is surfaced, never reconciled.
A28: total expenses | B28: 675762 | C28: 675762
A29: Variance (eAR minus Form 990) | B29: =B28-C28
A30: The eAR Section 8b total expenses (State Water Board self-report, calendar year 2023) and the Form 990 total expenses (IRS filing) are a different source and cover the same calendar year 2023. Both are carried as filed; the variance is surfaced, never reconciled.

Sheet Denominators & alignment
A1: San Cayetano Mutual Water Company
A2: Denominators and calendar alignment
A3: Entity ID: cawc_0012 | Fiscal year ends December 31.
A5: System size and water use per fiscal year (the operating denominators that per-customer and per-acre metrics divide by), each cited to file and field. The eAR is reported on the calendar year; the 990 fiscal year differs by company. A calendar-year filer's volume is the eAR annual total (fiscal year = calendar year); an offset filer's is recast by a true monthly sum of the covered calendar months, or read not reported naming the missing months. Point-in-time counts (connections, population) are matched to the closest eAR year and never summed. Every derived figure states its formula and accounting rationale.
A6: Member vs customer (two different denominators, both preserved)
A7: Customer (service connection) | B7: 47 | C7: State Water Board eAR Section 4 (CurTotalConnections), reporting year 2024
A8: SDWIS service-connection count (different registry) | B8: 47
A9: Member (shareholder) | C9: No published shareholder count
A10: In a mutual water company a MEMBER is a shareholder who owns part of the system; a CUSTOMER is a metered service connection that receives water. The two diverge because one owner can hold several connections, a connection can serve people who are not owners, and some mutuals attach shares to land by acreage rather than counting heads. Per-customer metrics divide by service connections; per-member metrics divide by shareholders; the two counts are never used interchangeably.
A12: Denominator layer by fiscal year
A13: Fiscal year (end) | B13: Connections | C13: Population | D13: Service-area acres | E13: Water produced (AF) | F13: Water delivered (AF) | G13: Alignment method
A14: FY2021 (2021-12-31) | B14: 50 | C14: not reported | D14: 3177.2 | E14: 2196.5 | F14: 2196.5 | G14: eAR annual total, calendar filer, equals fiscal year (not a monthly recast)
A15: FY2022 (2022-12-31) | B15: 50 | C15: not reported | D15: 3177.2 | E15: 2164.8 | F15: 2164.8 | G15: eAR annual total, calendar filer, equals fiscal year (not a monthly recast)
A16: FY2023 (2023-12-31) | B16: 50 | C16: 46 | D16: 3177.2 | E16: not reported | F16: not reported | G16: eAR annual total, calendar filer, equals fiscal year (not a monthly recast)
A17: FY2024 (2024-12-31) | B17: 47 | C17: 46 | D17: 3177.2 | E17: not reported | F17: not reported | G17: eAR annual total, calendar filer, equals fiscal year (not a monthly recast)
A18: FY2025 (2025-12-31) | B18: 47 | C18: 46 | D18: 3177.2 | E18: not reported | F18: not reported | G18: eAR annual total, calendar filer, equals fiscal year (not a monthly recast)
A20: Connections by class - FY2025 (eAR Section 4)
A21: Single-family residential | B21: 33
A22: Commercial and institutional | B22: 0
A23: Agricultural | B23: 36
A24: Monthly-volume source: California open-data portal (data.ca.gov): the separate Produced Water (by month and source) and Delivered Water (by month and connection type) resources, which cover every public water system (not only urban suppliers), one resource per reporting year, matched by exact PWSID. This is the aggregate publication of eAR Section 6.

Sheet Governance evidence
A1: San Cayetano Mutual Water Company
A2: Governance evidence status - Ostrom's eight design principles
A3: Entity ID: cawc_0012 | Fiscal year ends December 31.
A5: Evidence summary: 5 documented, 1 partial, 2 not documented of eight principles.
A6: A count of how many of Elinor Ostrom's eight design principles have a supporting record on file, not a grade. NOT DOCUMENTED means the supporting record was not found, not that the company governs badly. It marks a gap in the documentary record, an evidence gap to close, never a governance failing.
A7: Each mutual is read against Elinor Ostrom's eight design principles for institutions that govern a shared resource durably. Per principle: a one-line finding, the observable signal, a citation, and an evidence status stating whether the supporting record exists: DOCUMENTED (a cited record supports alignment), PARTIAL (some evidence exists but it is incomplete), or NOT DOCUMENTED (no supporting record was found). This is an evidence-status read, not a grade: the principles are never ranked, weighted, or given a letter, consistent with reporting as filed and not grading companies. NOT DOCUMENTED means the supporting record was not found, not that the company governs badly. It marks a gap in the documentary record, an evidence gap to close, never a governance failing.
A9: Principle | B9: Evidence status | C9: Finding | D9: Signal | E9: Citation
A10: Clearly defined boundaries | B10: DOCUMENTED | C10: The system is a defined public water system: 47 service connections over a State-published service-area boundary. | D10: SDWIS Community water system; SABL service-area boundary (not verified (sabl)); connections defined. | E10: [C][G]
A11: What the record shows: SDWIS defines the membership as a fixed set of service connections and the State Water Board publishes a SABL service-area polygon, so who is inside and outside the system is documented. The boundary is Not Verified (SABL), so its outer edge rests on that State layer.
A12: Rules fit local conditions | B12: DOCUMENTED | C12: Charges are tied to service under a documented rate or share-based allocation rule reported to the State or set in the company's structure. | D12: eAR Section 8a customer charges; documented rate or share-allocation rule. | E12: [E][r1]
A13: What the record shows: The record documents how charges are set, whether a filed metered rate schedule or a share-and-acreage allocation, so cost tracks service. Whether every tier scales precisely with use is only partially visible at this scale, but a real cost-to-service rule is on record.
A14: Collective-choice arrangements | B14: DOCUMENTED | C14: The company is owned by its customer-shareholders and run by a named board they elect, documented in its Form 990 governance section. | D14: Mutual ownership; named elected board of directors (Form 990). | E14: [990][r1]
A15: What the record shows: The record documents a collective-choice mechanism: customers are shareholders who elect a named board that governs the company. Turnout and specific member votes on major decisions are not documented, but the elected-board structure and its membership are on record.
A16: Monitoring | B16: DOCUMENTED | C16: The system is metered and monitored: the State SAFER risk assessment shows it Not Failing, and it files an annual eAR. | D16: SAFER Not Failing; annual eAR reporting; metered connections. | E16: [S][E]
A17: What the record shows: Operational monitoring is documented: the State rates the system Not Failing on its drinking-water risk assessment and the system files an annual eAR. No independent audited financial statement is published, so financial monitoring is weaker, but the operational record is present.
A18: Graduated sanctions | B18: NOT DOCUMENTED | C18: No published shut-off, penalty, or delinquency policy was found for this system. | D18: No sourced sanctions policy. | E18: not reported
A19: What the record shows: No public record of a graduated shut-off or penalty policy was found for a system this small. NOT DOCUMENTED means the supporting record was not found, not that the company governs badly. It marks a gap in the documentary record, an evidence gap to close, never a governance failing.
A20: Conflict-resolution mechanisms | B20: NOT DOCUMENTED | C20: No published bylaws, dispute procedure, or grievance mechanism was found for this system. | D20: No sourced conflict-resolution record. | E20: not reported
A21: What the record shows: No public record of a member dispute or conflict-resolution procedure was found. NOT DOCUMENTED means the supporting record was not found, not that the company governs badly. It marks a gap in the documentary record, an evidence gap to close, never a governance failing.
A22: Recognized right to organize | B22: DOCUMENTED | C22: An incorporated California mutual water company recognized by the IRS (501(c)(12)) and by the State Water Board as a public water system. | D22: IRS 501(c)(12) exempt filer (Form 990); SDWIS public water system. | E22: [990][C][SOS]
A23: What the record shows: Baseline legal standing is documented: the company is an incorporated mutual recognized by the IRS as a tax-exempt filer and by the State Water Board as a regulated water system. This records the right to organize as a member entity, not a documented instance of exercising it. The California Secretary of State holds the company as a registered corporation, entity number 0071659, first registered 01/02/1913, status as filed "Active", with a governing body named in the Statement of Information filed 2/2/2026. That is a direct state record of the right to organize being recognized, so the evidence behind this status is now a filed corporate record rather than an inference from the company's tax form. The status was already DOCUMENTED and does not move.
A24: Nested enterprises | B24: PARTIAL | C24: The system draws on a shared local groundwater basin, embedding it in a larger physical water system, though its role in basin governance is not documented. | D24: SDWIS Primary Water Source Type: groundwater (shared basin). | E24: [C]
A25: What the record shows: The system relies on a shared groundwater basin, so it is physically nested in a larger hydrologic system. Its participation in a groundwater sustainability agency or basin governance is not documented, so the nesting evidence is partial.

Sheet Operational metrics
A1: San Cayetano Mutual Water Company
A2: Operational metrics - plant per acre, density, terrain
A3: Entity ID: cawc_0012 | Fiscal year ends December 31.
A5: Plant assets per acre
A6: Service-area acres | B6: 3177.2 | C6: Geodesic area (WGS84 spherical excess) of the SABL service-area polygon.
A7: Fiscal year | B7: Gross plant per acre (primary) | C7: Net plant per acre
A8: FY2021 | B8: 1180.6802 | C8: 562.4871
A9: FY2022 | B9: 1180.6798 | C9: 514.1086
A10: FY2023 | B10: 1180.6798 | C10: 465.5555
A11: FY2024 | B11: 1353.3539 | C11: 589.7218
A12: FY2025 | B12: 1368.2862 | C12: 562.9655
A13: Infrastructure built per acre of service area. Gross plant per acre is the primary read because it measures how much plant the system has put in the ground per acre, and unlike net plant it does not fall over time purely because the assets depreciate on the books. Net plant per acre is shown alongside as the depreciated book value per acre.
A14: Formula: gross plant per acre = Form 990 Part X line 10a (land, buildings, and equipment, gross) / SABL service-area acres; net plant per acre uses Part X line 10c (net)
A15: Source lines: Form 990 Part X line 10a (gross) and line 10c (net); Geodesic area (WGS84 spherical excess) of the SABL service-area polygon.
A16: Confidence: medium. This is worked out from filed figures (a ratio, or a year-to-year change), so it is one step removed from the raw numbers.. Filed gross/net plant over the measured SABL service-area acreage.
A18: Connections per acre
A19: Connections per acre | B19: 0.02 | C19: 69 connections / 3,177.2 acres. CA State Water Board SABL SERVICE_CONNECTIONS; Geodesic area (WGS84 spherical excess) of the SABL service-area polygon.
A21: Who they are
A22: Terrain class | B22: flat valley | C22: Company context page (BLUEPRINT 5B)
A23: A California mutual water company (501(c)(12)) serving about 47 service connections in Fillmore, in the Santa Clara River valley of Ventura County, and describing itself as providing both agricultural and domestic water to its members.

Sheet Supply & weather
A1: San Cayetano Mutual Water Company
A2: Supply and weather indicators (DWR water year)
A3: Entity ID: cawc_0012 | Fiscal year ends December 31.
A5: Reporting calendar: Different reporting periods. The DWR water year runs October 1 to September 30; this system's fiscal year ends December 31, so the two period ends are three months apart. Read the two side by side with that in mind. Neither series is recast: both are reported as filed. A water year is named for the calendar year it ends in, so WY2024 and FY2024 share a number without covering the same twelve months.
A7: Indicator | B7: WY2021 | C7: WY2022 | D7: WY2023 | E7: WY2024 | F7: WY2025
A8: Water-year type (Sacramento Valley) | B8: Critical | C8: Critical | D8: Wet | E8: Above Normal | F8: not reported
A9: Peak drought, Ventura County | B9: D4 | C9: D4 | D9: D3 | E9: None (no D0-D4 during the fiscal year) | F9: D3
A10: Precip, percent of normal (8-Station Index) | B10: 48 | C10: 86 | D10: 133 | E10: 96 | F10: 113
A11: Snowpack, April 1 percent of average | B11: 59% | C11: 38% | D11: 237% | E11: 110% | F11: 96%
A12: State Water Project allocation | B12: 5% | C12: 5% | D12: 100% | E12: 40% | F12: 50%

Sheet How this was built
A1: San Cayetano Mutual Water Company
A2: How this was built - forensic lineage
A3: Entity ID: cawc_0012 | Fiscal year ends December 31.
A5: A plain account of the forensic lineage behind the hard-to-source metrics: what sources were checked, what was found, what was derived, and what could not be built and why. Every figure marked DERIVED or IMPOSSIBLE above is traceable to a line here.
A7: Water-sales revenue per customer - DIRECT
A8: Sources checked | B8: State Water Board eAR Section 8b (water-rate revenue B1.1/B1.2); State Water Board eAR Section 4 (connection count, same reporting year); audited financial statement (secondary cross-check, where published)
A9: What was found | B9: The eAR Section 8b reports water-rate revenue for reporting year 2023, so this is a DIRECT filed figure; per customer it is divided by the eAR Section 4 connection count for the same reporting year, so numerator and denominator share the year.
A11: Assessment revenue (residual) - DERIVED
A12: Sources checked | B12: Form 990 Part VIII line 2 (program-service revenue); State Water Board eAR Section 8b (water-rate revenue B1.1/B1.2)
A13: What was found | B13: No source separately reports a member assessment, so it is DERIVED as a residual: $504,433 (990 program-service revenue) minus $13,753 (eAR water-rate revenue) = $490,680. Period-aligned; medium confidence.
A14: Caveat | B14: This residual is a difference between two sources for the same period; it is not a separately filed assessment line and may include other unmatched revenue.
A16: Meter revenue - not reported
A17: Sources checked | B17: State Water Board eAR Section 8a (rate prices); State Water Board eAR Section 8b (revenue lines); audited financial statement
A18: What was found | B18: The rate price exists in Section 8a but no revenue or tier volume is reported, and the base charge is already inside water sales.
A19: Caveat | B19: The eAR Section 8a reports a base/meter rate PRICE, but the filing carries no meter revenue line and no tier volume, and the base charge is already inside the water-sales revenue (eAR Section 8b water rates). Building a separate meter figure would double-count. Not backed into from a total.
A21: Overage / tiered-penalty revenue - not reported
A22: Sources checked | B22: State Water Board eAR Section 8a (rate prices); State Water Board eAR Section 8b (revenue lines); audited financial statement
A23: What was found | B23: The rate price exists in Section 8a but no revenue or tier volume is reported, and the base charge is already inside water sales.
A24: Caveat | B24: The eAR Section 8a reports tiered/overage rate PRICES, but the filing carries no overage revenue and no tier consumption volume, and any overage billed is already inside the water-sales revenue. Building it would double-count. Not backed into from a total.
A26: eAR Section 8b reporting-period basis - sourced
A27: Sources checked | B27: eAR Section 8b B0.1 (WRFinancialReportingPeriod); eAR Section 8b B0.2 (WRFiscalYearStartDate)
A28: What was found | B28: The reporting basis (fiscal vs calendar year) is read from the filer's own B0.1/B0.2 answer and staged verbatim, never hardcoded, so the 990 comparison and the residual are period-aligned.
A30: Member (shareholder) count denominator - not reported
A31: Sources checked | B31: Form 990 (no member count stated); company website
A32: What was found | B32: No filing states a member/shareholder count, so the per-member unit economics read not reported rather than borrowing the connection count.
A34: Water volume delivered (acre-feet) - not reported
A35: Sources checked | B35: Form 990 (not in the filing); Consumer Confidence Report; eAR Section 6 (PRA-gated)
A36: What was found | B36: Volume delivered in acre-feet is not in the Form 990 and the CCR states only a source mix, so the per-acre-foot metrics read not reported; the eAR Section 6 is named as the source still needed.

Sheet Water Operations
A1: San Cayetano Mutual Water Company
A2: Water Operations (sourced outside the financial filings)
A3: Entity ID: cawc_0012 | Fiscal year ends December 31.
A5: A separate dialect of data from the financial statements: the system's water supply, from the California State Water Board records (the Consumer Confidence Report served by the eAR portal, and SDWIS Drinking Water Watch). Each field carries its source, year, and confidence the same way a financial line item does; a field the source does not state reads 'not reported' with the source still needed. Figures are as reported, never estimated or reconciled across sources.
A7: Field | B7: Value | C7: Source | D7: Year | E7: Confidence | F7: Source excerpt / cross-source note
A8: Water type | B8: Potable (community drinking water) | C8: SDWIS Drinking Water Watch (State Water Board) | D8: 2024 | E8: high | F8: SAN CAYETANO MUTUAL WATER CO: State Water System Type = Community.
A9: Source mix | B9: Primary source: local groundwater wells (SDWIS Primary Water Source Type: Groundwater). SDWIS classifies the primary supply type; it states no acre-foot volume by source. | C9: SDWIS Drinking Water Watch (State Water Board) | D9: 2024 | E9: high | F9: SAN CAYETANO MUTUAL WATER CO: Primary Water Source Type = Groundwater.
A10: Service connections (total) | B10: 47 connections | C10: SDWIS Drinking Water Watch (State Water Board) | D10: 2024 | E10: high | F10: SAN CAYETANO MUTUAL WATER CO: Total Number of Service Connections = 47. [cross-source: SDWIS connection snapshot; the eAR reports active service connections on its own basis and per reporting year. Both preserved, not reconciled.]
A11: Connections by class | B11: Service connections by type (SDWIS snapshot): Residential 14; Agricultural 33; Total 47. | C11: SDWIS Drinking Water Watch (State Water Board) | D11: 2024 | E11: high | F11: SAN CAYETANO MUTUAL WATER CO: connections by type - Residential 14; Agricultural 33; Total 47.
A12: Population served | B12: 46 residents | C12: SDWIS Drinking Water Watch (State Water Board) | D12: 2024 | E12: high | F12: SAN CAYETANO MUTUAL WATER CO: Total Population = 46.
A13: Treatment and water quality | B13: Operator certification on file: Treatment or distribution operator of any grade; Distribution Operator Level 1. SDWIS states operator grades, not the treatment process detail. | C13: SDWIS Drinking Water Watch (State Water Board) | D13: 2024 | E13: high | F13: SAN CAYETANO MUTUAL WATER CO: Treatment Plant Class = Treatment or distribution operator of any grade; Distribution System Class = Distribution Operator Level 1.
A15: Not reported (source still needed)
A16: Annual volume delivered (acre-feet) | B16: not reported - needs annual volume in acre-feet (State Water Board eAR Section 6 or company production records); the CCR states only a percentage mix
A17: Customer classes served | B17: not reported - needs the State Water Board eAR or the system CCR

Sheet Anomaly Flags
A1: San Cayetano Mutual Water Company
A2: Anomaly Flags (automated; kept separate from the clean statements)
A3: Entity ID: cawc_0012 | Fiscal year ends December 31.
A5: Material irregularities found automatically in the filed financials by the Hydronomics anomaly flagger. Each flag has two clearly separated layers. WHAT is mechanical, certain, and sourced: the exact filed lines, years, and amounts, carried as filed and never reconciled. WHY is attempted: the filing's own narrative is checked first, and when it states no reason a single best-guess hypothesis is shown, clearly labelled as a guess that is not in the filing and is not a verified figure.
A7: Flag: FY2022 net assets do not sum to the lines we extract
A8: Affected figure | B8: Net assets FY2022
A9: Confidence | B9: medium
A10: What happened (filed, sourced) | B10: FY2022 net assets are carried exactly as filed at $2,214,030. The lines we extracted do not sum to that total: the ending net assets it reports (Form 990 Part XI line 10) should equal the beginning net assets (line 4) plus revenue less expenses (line 3) plus other changes (lines 5-9), which computes to $2,091,800 (a difference of $122,230 against the $2,214,030 on the form). This may mean a line on the form that we do not yet read, rather than an error by the company. The filed figure is kept and the difference is flagged, not reconciled.
A11: Source lines | B11: - Net assets, end of year (as filed): $2,214,030 (Form 990 Part XI line 10 / Part X line 32 (net assets, end of year)) - Net assets, end of year (recomputed from the lines we extract): $2,091,800 - Difference (as filed less our computed sum): $122,230
A12: Confidence reasoning | B12: The net-assets figure is a direct filed line item, carried exactly as filed; confidence is held to medium (not high) because the lines we extract do not sum to the total on the form, so the figure is flagged rather than presented as clean. That can mean a line we do not read as easily as an inconsistency in the filing, and this project has found the former three times. Nothing is reconciled.
A13: Why (not stated in the filing) | B13: The filing does not state a reason.
A14: Possible explanation (guess) | B14: Possible explanation, not stated in filing: an ending net-worth figure that does not equal the beginning balance plus the year's surplus or deficit usually reflects a prior-year adjustment, a reclassification between balance-sheet lines, or a rounding or transcription difference on the filed form. This is an educated guess, not something the filing actually says.

Sheet Sources & audit
A1: San Cayetano Mutual Water Company
A2: Sources & audit - full provenance and tie-outs (kept off the statements so they read clean)
A3: Entity ID: cawc_0012 | Fiscal year ends December 31.
A5: Presentation standard: every figure on the statement tabs is verified to its source filing and shown clean. A cell the filing does not report reads "not reported" (never estimated, never guessed).
A6: Citations, confidence tiers, and the filed-vs-computed tie-out checks live on the "Sources & audit" tab, keyed by cell, so every number is fully traceable without cluttering the statements. These pages are ready to use as filed.
A8: A. Filing provenance (one row per staged extraction)
A9: Fiscal year | B9: Period end | C9: Filing type | D9: Confidence | E9: Extraction ID | F9: Object ID | G9: Extracted by | H9: Extracted at | I9: Source URL
A10: FY2020 | B10: 2020-12-31 | C10: 990 | D10: high | E10: ac7c7c0a-6935-4d23-b163-d6cd47b4d4e4 | F10: 202103169349309475 | G10: claude-opus-5 | H10: 2026-09-14T20:40:22+00:00 | I10: https://apps.irs.gov/pub/epostcard/990/xml/2021/2021_TEOS_XML_01A.zip#202103169349309475_public.xml
A11: FY2021 | B11: 2021-12-31 | C11: 990 | D11: high | E11: 8f74250f-dd55-4289-ad55-1ed560fe1ab9 | F11: 202240809349301054 | G11: claude-opus-5 | H11: 2026-09-14T20:40:22+00:00 | I11: https://apps.irs.gov/pub/epostcard/990/xml/2022/2022_TEOS_XML_01A.zip#202240809349301054_public.xml
A12: FY2022 | B12: 2022-12-31 | C12: 990 | D12: medium | E12: ef74464b-78b1-4ea2-a793-cceee795e81a | F12: 202340599349301559 | G12: claude-opus-5 | H12: 2026-09-14T20:40:22+00:00 | I12: https://apps.irs.gov/pub/epostcard/990/xml/2023/2023_TEOS_XML_03A.zip#202340599349301559_public.xml
A13: FY2023 | B13: 2023-12-31 | C13: 990 | D13: high | E13: 96a7ebe1-994b-4278-aebf-11edf6468dff | F13: 202420539349301667 | G13: claude-opus-5 | H13: 2026-09-14T20:40:22+00:00 | I13: https://apps.irs.gov/pub/epostcard/990/xml/2024/2024_TEOS_XML_02A.zip#202420539349301667_public.xml
A14: FY2024 | B14: 2024-12-31 | C14: 990 | D14: high | E14: b5757961-d4c0-43cf-b507-00f5412f8aca | F14: 202541449349300304 | G14: claude-opus-5 | H14: 2026-09-14T20:40:22+00:00 | I14: https://apps.irs.gov/pub/epostcard/990/xml/2025/2025_TEOS_XML_06A.zip#202541449349300304_public.xml
A15: FY2025 | B15: 2025-12-31 | C15: 990 | D15: high | E15: fc1db36f-e1e8-4a3f-8fa6-99b9ba98bda3 | F15: 202601319349306955 | G15: claude-opus-5 | H15: 2026-09-14T20:40:22+00:00 | I15: https://apps.irs.gov/pub/epostcard/990/xml/2026/2026_TEOS_XML_05A.zip#202601319349306955_public.xml
A17: B. Figure citations (every figure on the statement tabs, keyed by cell)
A18: Tab | B18: Cell | C18: Line item | D18: Form 990 line | E18: Key path | F18: Confidence | G18: As filed
A19: Financial Statements | B19: B73 | C19: 11a. Gross income from members or shareholders | D19: 11a | E19: part_v_other_irs_filings.members_and_shareholders_gross_income | F19: high | G19: 550421
A20: Financial Statements | B20: C73 | C20: 11a. Gross income from members or shareholders | D20: 11a | E20: part_v_other_irs_filings.members_and_shareholders_gross_income | F20: high | G20: 614301
A21: Financial Statements | B21: D73 | C21: 11a. Gross income from members or shareholders | D21: 11a | E21: part_v_other_irs_filings.members_and_shareholders_gross_income | F21: high | G21: 621870
A22: Financial Statements | B22: E73 | C22: 11a. Gross income from members or shareholders | D22: 11a | E22: part_v_other_irs_filings.members_and_shareholders_gross_income | F22: high | G22: 504433
A23: Financial Statements | B23: F73 | C23: 11a. Gross income from members or shareholders | D23: 11a | E23: part_v_other_irs_filings.members_and_shareholders_gross_income | F23: high | G23: 688217
A24: Financial Statements | B24: G73 | C24: 11a. Gross income from members or shareholders | D24: 11a | E24: part_v_other_irs_filings.members_and_shareholders_gross_income | F24: high | G24: 737231
A25: Financial Statements | B25: B74 | C25: 11b. Gross income from other sources | D25: 11b | E25: part_v_other_irs_filings.other_sources_gross_income | F25: high | G25: 382
