Workbook

Sheet Summary
A1: Gill Creek Mutual Water Company
A2: Financial Summary - multi-year overview (USD)
A3: Entity ID: cawc_0169 | Fiscal year ends March 31.
A5: Presentation standard: every figure on the statement tabs is verified to its source filing and shown clean. A cell the filing does not report reads "not reported" (never estimated, never guessed).
A6: Citations, confidence tiers, and the filed-vs-computed tie-out checks live on the "Sources & audit" tab, keyed by cell, so every number is fully traceable without cluttering the statements. These pages are ready to use as filed.
A8: Metric | B8: FY2020 | C8: FY2021 | D8: FY2022 | E8: FY2023 | F8: FY2024 | G8: FY2025
A9: Operating results (USD)
A10: Total revenue | B10: 110719 | C10: 125848 | D10: 97371 | E10: 112625 | F10: 181936 | G10: 229871
A11: Total expenses | B11: 95430 | C11: 91118 | D11: 94853 | E11: 106792 | F11: 117392 | G11: 168998
A12: Net income | B12: 15289 | C12: 34730 | D12: 2518 | E12: 5833 | F12: 64544 | G12: 60873
A14: Financial position (USD, end of year)
A15: Total assets | B15: 358188 | C15: 400288 | D15: 388220 | E15: 391676 | F15: 457171 | G15: 517817
A16: Total liabilities | B16: 13034 | C16: 20404 | D16: 5818 | E16: 3441 | F16: 4392 | G16: 4165
A17: Net assets | B17: 345154 | C17: 379884 | D17: 382402 | E17: 388235 | F17: 452779 | G17: 513652
A19: Headline ratios
A20: Operating margin | B20: 0.13808831 | C20: 0.27596783 | D20: 0.025859856 | E20: 0.051791343 | F20: 0.35476211 | G20: 0.26481374
A21: Revenue growth (YoY)
A22: Return on assets | B22: 0.042684289 | C22: 0.086762531 | D22: 0.0064860131 | E22: 0.014892411 | F22: 0.14118131 | G22: 0.11755697
A24: Figures as reported in source filings (full provenance on the Sources & audit tab). Parentheses denote negatives; ratios are computed upstream in financials_annual.

Sheet Notes
A1: Notes
A2: Human annotations from the versioned store (data/notes/). Annotations only: they never change a reported figure or a confidence tier.
A4: Date | B4: Tag | C4: Author | D4: Note
A5: No notes recorded yet.

Sheet Financial Statements
A1: Gill Creek Mutual Water Company
A2: Financial Statements - income statement, balance sheet, cash flow, member income test (USD)
A3: Entity ID: cawc_0169 | Fiscal year ends March 31.
A5: INCOME STATEMENT - as reported (USD)
A6: Line item | B6: FY2020 | C6: FY2021 | D6: FY2022 | E6: FY2023 | F6: FY2024 | G6: FY2025
A7: Revenue
A8: Program service revenue | G8: 173093
A9: Investment income | G9: 8778
A10: Net rental income
A11: Net gain/(loss) on investment sales
A12: Other revenue | G12: 48000
A13: Contributions & grants
A14: Total revenue | G14: 229871
A16: Expenses
A17: Depreciation | G17: 21771
A18: Interest expense
A19: Total expenses | B19: 95430 | C19: 91118 | D19: 94853 | E19: 106792 | F19: 117392 | G19: 168998
A21: Net income | B21: 15289 | C21: 34730 | D21: 2518 | E21: 5833 | F21: 64544 | G21: 60873
A24: BALANCE SHEET - as reported (USD, end of year)
A25: Line item | B25: FY2020 | C25: FY2021 | D25: FY2022 | E25: FY2023 | F25: FY2024 | G25: FY2025
A26: Assets
A27: Cash | B27: 131133 | C27: 167698 | D27: 165039 | E27: 151017 | F27: 156349 | G27: 27524
A28: Savings & temporary investments | G28: 198416
A29: Accounts receivable | G29: -4005
A30: Inventories
A31: Prepaid expenses | G31: 56000
A32: Property, plant & equipment (gross) | G32: 513616
A33: Less: accumulated depreciation | G33: -282782
A34: Net property, plant & equipment | B34: 171055 | C34: 82701 | D34: 80597 | G34: 230834
A35: Total assets | B35: 358188 | C35: 400288 | D35: 388220 | E35: 391676 | F35: 457171 | G35: 517817
A37: Liabilities
A38: Accounts payable
A39: Mortgages & notes payable
A40: Total liabilities | B40: 13034 | C40: 20404 | D40: 5818 | E40: 3441 | F40: 4392 | G40: 4165
A42: Net Assets / Equity
A43: Capital stock | G43: 13080
A44: Paid-in capital | G44: 187100
A45: Retained earnings | G45: 313472
A46: Net assets | B46: 345154 | C46: 379884 | D46: 382402 | E46: 388235 | F46: 452779 | G46: 513652
A49: CASH FLOW - derived proxy (USD)
...

Sheet Balance Sheet
A1: Gill Creek Mutual Water Company
A2: Balance Sheet - as reported (USD, end of year)
A3: Entity ID: cawc_0169 | Fiscal year ends March 31.
A5: Line item | B5: FY2020 | C5: FY2021 | D5: FY2022 | E5: FY2023 | F5: FY2024 | G5: FY2025
A6: Assets
A7: Cash | B7: 131133 | C7: 167698 | D7: 165039 | E7: 151017 | F7: 156349 | G7: 27524
A8: Savings & temporary investments | G8: 198416
A9: Accounts receivable | G9: -4005
A10: Inventories
A11: Prepaid expenses | G11: 56000
A12: Property, plant & equipment (gross) | G12: 513616
A13: Less: accumulated depreciation | G13: -282782
A14: Net property, plant & equipment | B14: 171055 | C14: 82701 | D14: 80597 | G14: 230834
A15: Total assets | B15: 358188 | C15: 400288 | D15: 388220 | E15: 391676 | F15: 457171 | G15: 517817
A17: Liabilities
A18: Accounts payable
A19: Mortgages & notes payable
A20: Total liabilities | B20: 13034 | C20: 20404 | D20: 5818 | E20: 3441 | F20: 4392 | G20: 4165
A22: Net Assets / Equity
A23: Capital stock | G23: 13080
A24: Paid-in capital | G24: 187100
A25: Retained earnings | G25: 313472
A26: Net assets | B26: 345154 | C26: 379884 | D26: 382402 | E26: 388235 | F26: 452779 | G26: 513652
A28: Balance check (assets − liab. − net assets) | B28: 0 | C28: 0 | D28: 0 | E28: 0 | F28: 0 | G28: 0
A30: Net PP&E is the reported ppe_net column (gross less accumulated depreciation). The balance check should be ~0 where all three totals are reported; a non-zero value flags a reporting or extraction discrepancy worth reviewing.

Sheet Officers & contractors
A1: Gill Creek Mutual Water Company
A2: Officers, Directors & Contractors - Form 990 Part VII (FY2025; USD)
A3: Entity ID: cawc_0169 | Fiscal year ends March 31.
A5: Section A - Officers, directors, trustees, key employees
A6: Name | B6: Title | C6: Reportable comp (org) | D6: Reportable comp (related) | E6: Other comp | F6: Total compensation
A7: PAUL CONNORS | B7: DIRECTOR | C7: 0 | D7: 0 | E7: 0 | F7: 0
A8: GENE SCHNAIR | B8: DIRECTOR | C8: 0 | D8: 0 | E8: 0 | F8: 0
A9: TIM BROWN | B9: VICE PRESIDE | C9: 0 | D9: 0 | E9: 0 | F9: 0
A10: CATHY HALLIGAN | B10: SECRETARY | C10: 0 | D10: 0 | E10: 0 | F10: 0
A11: JAMES LAZARUS | B11: PRESIDENT | C11: 0 | D11: 0 | E11: 0 | F11: 0
A12: PETER SAGUES | B12: TREASURER | C12: 0 | D12: 0 | E12: 0 | F12: 0
A14: Section B - Independent contractors (over $100,000)
A15: Contractor | B15: Services | C15: Compensation
A17: Section A lists every officer, director, trustee and key employee filed for the latest year; the two with the highest total compensation are highlighted. Total compensation is computed (reportable org + related + other). Section B lists each independent contractor paid over $100,000; the return reports None such contractor(s). Source and confidence for every figure are on the Sources & audit tab.

Sheet Revenue (detail)
A1: Gill Creek Mutual Water Company
A2: Revenue - Form 990 Part VIII (USD)
A3: Entity ID: cawc_0169 | Fiscal year ends March 31.
A5: Part VIII line | B5: FY2025
A6: Revenue by category
A7: 1h. Total contributions, gifts, grants | B7: not reported
A8: 2g. Total program service revenue | B8: 173093
A9: 3. Investment income | B9: 8778
A10: 6d. Net rental income | B10: not reported
A11: 7d. Net gain/(loss) from investment sales | B11: not reported
A12: 11e. Other revenue | B12: 48000
A13: 12. Total revenue | B13: =SUM(B7:B12)
A15: Program service revenue detail - FY2025 (lines 2a-2f)
A16: Description | B16: Business code | C16: Total revenue
A17: WATER SERVICE FEES | C17: 130510
A18: PROPERTY WORK | C18: 40633
A19: OTHER FEES | C19: 1950
A20: Revenue category subtotals are as filed. Total revenue (line 12) is a live SUM of the category cells above; its tie-out to the filed total is on the Sources & audit tab. Program service revenue detail is shown for the latest year, with its sum-to-line-2g check on that same audit tab.

Sheet Operating expenses (detail)
A1: Gill Creek Mutual Water Company
A2: Statement of Functional Expenses - Form 990 Part IX (USD)
A3: Entity ID: cawc_0169 | Fiscal year ends March 31.
A5: Part IX line (column A Total) | B5: FY2025
A6: Functional expenses, column A Total - by year
A7: 7. Other salaries and wages | B7: 30900
A8: 10. Payroll taxes | B8: 4933
A9: 11g. Fees for services: other | B9: 3428
A10: 13. Office expenses | B10: 3233
A11: 22. Depreciation, depletion, and amortization | B11: 21771
A12: 23. Insurance | B12: 10329
A13: 24. PROPERTY WORK | B13: 40614
A14: 24. REPAIRS & MAINTENANCE | B14: 25636
A15: 24. UTILITIES | B15: 15192
A16: 24. SAMPLING AND TREATMENT | B16: 5395
A17: 24e. All other expenses | B17: 7567
A18: 25. Total functional expenses | B18: =SUM(B7:B17)
A20: Functional column split - FY2025 (col A = B + C + D)
A21: Part IX line | B21: A. Total | C21: B. Program services | D21: C. Management & general | E21: D. Fundraising
A22: 7. Other salaries and wages | B22: 30900 | D22: 30900
A23: 10. Payroll taxes | B23: 4933 | C23: 2466 | D23: 2467
A24: 11g. Fees for services: other | B24: 3428 | C24: 3428
A25: 13. Office expenses | B25: 3233 | C25: 3233
A26: 22. Depreciation, depletion, and amortization | B26: 21771 | C26: 21771
A27: 23. Insurance | B27: 10329 | C27: 10329
A28: 25. Total (filed col A / B / C / D) | B28: 168998 | C28: 135631 | D28: 33367 | E28: 0
A30: Top block: each Part IX line, column A (Total), by year, as filed. Total functional expenses (line 25) is a live SUM of the line cells; its tie-out to the filed total is on the Sources & audit tab. Filer-itemized 24a-24d rows show the most recent year's as-filed wording; rows are aligned across years case-insensitively with collapsed spacing, so a line filed only in a different capitalization or spacing shares one row, while genuinely different wording stays a separate row (every as-filed variant is recorded on the Sources & audit tab). Lower block: the program / management / fundraising split for the latest year, with its col A = B + C + D check on the audit tab. Lines this filer does not report are omitted rather than shown empty.

Sheet Balance sheet (detail)
A1: Gill Creek Mutual Water Company
A2: Balance Sheet - Form 990 Part X (end of year, USD)
A3: Entity ID: cawc_0169 | Fiscal year ends March 31.
A5: Part X line (column B, EOY) | B5: FY2025
A6: Assets
A7: 1. Cash - non-interest-bearing | B7: 27524
A8: 2. Savings and temporary cash investments | B8: 198416
A9: 4. Accounts receivable, net | B9: -4005
A10: 9. Prepaid expenses and deferred charges | B10: 56000
A11: 10c. Land, buildings, and equipment, net | B11: 230834
A12: 15. Other assets | B12: 9048
A13: 16. Total assets | B13: =SUM(B7:B12)
A15: Liabilities
A16: 25. Other liabilities | B16: 4165
A17: 26. Total liabilities | B17: =SUM(B16:B16)
A19: Net assets / fund balances
A20: 29. Capital stock or trust principal | B20: 13080
A21: 30. Paid-in or capital surplus | B21: 187100
A22: 31. Retained earnings / accumulated funds | B22: 313472
A23: 32. Total net assets / fund balances | B23: =SUM(B20:B22)
A25: Every Part X line is end-of-year (column B), as filed. Section totals (lines 16 / 26 / 32) are live SUMs of the lines above; their tie-outs and the balance-sheet identity (16 = 26 + 32) are on the Sources & audit tab. This filer files as a non-FASB mutual, so net assets sit on lines 29-31 (capital stock / paid-in capital / retained earnings); lines this filer does not report are omitted. Lines 10a/10b net into line 10c (shown).

Sheet Net-assets reconciliation
A1: Gill Creek Mutual Water Company
A2: Reconciliation of Net Assets - Form 990 Part XI (USD)
A3: Entity ID: cawc_0169 | Fiscal year ends March 31.
A5: Part XI line | B5: FY2025
A6: Reconciliation
A7: 4. Net assets, beginning of year | B7: 452779
A8: 3. Revenue less expenses | B8: 60873
A9: 8. Prior period adjustments | B9: not reported
A10: 9. Other changes in net assets | B10: not reported
A11: 10. Net assets, end of year | B11: =SUM(B7,B8,B9,B10)
A13: Part XI reconciles beginning to ending net assets. Ending net assets (line 10) is a live formula: beginning balance (line 4) + revenue less expenses (line 3) + prior-period adjustments (8) + other changes (9). Its tie-out to the filed line 10 (and to Part X line 32) is on the Sources & audit tab. Lines 5-7 (unrealized gains, donated services, investment expenses) are not filed by this entity.

Sheet Cash flow proxies
A1: Gill Creek Mutual Water Company
A2: Cash Flow Proxies - derived (USD)
A3: Entity ID: cawc_0169 | Fiscal year ends March 31.
A5: PROXY ONLY. The source filings contain no statement of cash flows. Lines below are derived from the reported income statement and year-over-year balance-sheet changes; treat as directional estimates, not GAAP cash flows. The earliest year has no prior period, so its delta cells are blank.
A7: Proxy line (USD) | B7: FY2020 | C7: FY2021 | D7: FY2022 | E7: FY2023 | F7: FY2024 | G7: FY2025
A8: Operating
A9: Net income | B9: 15289 | C9: 34730 | D9: 2518 | E9: 5833 | F9: 64544 | G9: 60873
A10: + Depreciation (reported) | G10: 21771
A11: − Δ Accounts receivable
A12: − Δ Inventories
A13: − Δ Prepaid expenses
A14: + Δ Accounts payable
A15: Operating cash flow proxy | C15: 34730 | D15: 2518 | E15: 5833 | F15: 64544 | G15: 82644
A17: Investing
A18: − Δ PP&E gross (capex proxy)
A20: Financing
A21: Δ Mortgages & notes payable
A23: Reconciliation
A24: Δ Cash + temp. investments (actual) | C24: 36565 | D24: -2659 | E24: -14022 | F24: 5332 | G24: 69591
A26: The capex proxy assumes gross PP&E rises only via capital spending (it ignores disposals). 'Δ Cash + temp. investments (actual)' is the real reported change in liquid funds and is the most reliable line here; the operating/investing/financing proxies will not perfectly reconcile to it.

Sheet Ratios
A1: Gill Creek Mutual Water Company
A2: Financial Ratios
A3: Entity ID: cawc_0169 | Fiscal year ends March 31.
A5: Ratio | B5: FY2020 | C5: FY2021 | D5: FY2022 | E5: FY2023 | F5: FY2024 | G5: FY2025
A6: Profitability (computed upstream)
A7: Operating margin (NI / revenue) | B7: 0.13808831 | C7: 0.27596783 | D7: 0.025859856 | E7: 0.051791343 | F7: 0.35476211 | G7: 0.26481374
A8: Expense ratio (expenses / revenue) | B8: 0.86191169 | C8: 0.72403217 | D8: 0.97414014 | E8: 0.94820866 | F8: 0.64523789 | G8: 0.73518626
A9: Return on assets (NI / assets) | B9: 0.042684289 | C9: 0.086762531 | D9: 0.0064860131 | E9: 0.014892411 | F9: 0.14118131 | G9: 0.11755697
A10: Revenue growth (YoY)
A12: Leverage & solvency
A13: Debt-to-assets (liab. / assets) | B13: 0.036388712 | C13: 0.050973299 | D13: 0.014986348 | E13: 0.0087853226 | F13: 0.0096069086 | G13: 0.0080433821
A14: Equity ratio (net assets / assets) | B14: 0.96361129 | C14: 0.9490267 | D14: 0.98501365 | E14: 0.99121468 | F14: 0.99039309 | G14: 0.99195662
A16: Liquidity & asset profile (derived here)
A17: Current ratio (current assets / AP)
A18: Cash ratio ((cash+temp inv.) / total liab.) | B18: 10.060841 | C18: 8.2188787 | D18: 28.366965 | E18: 43.887533 | F18: 35.598588 | G18: 54.247299
A19: Asset age proxy (accum. deprec. / gross PP&E) | G19: 0.55057085
A21: Upstream ratios are read from financials_annual; derived ratios are computed only where inputs are reported. Current ratio uses accounts payable as the current-liability proxy (the filings do not split current vs. long-term liabilities). Asset age proxy: a higher % implies older / more depreciated infrastructure.

Sheet Unit economics
A1: Gill Creek Mutual Water Company
A2: Unit economics - per-customer revenue by category (USD)
A3: Entity ID: cawc_0169 | Fiscal year ends March 31.
A5: Every metric here is PER CUSTOMER (a metered service connection). It is not a per-member figure; the member (shareholder) count is a different denominator, shown in the denominator block. The visible cell shows the value and its classification; the numerator, denominator, formula, and rationale are in each metric's LOGIC popup.
A6: Per-customer denominator (service connections) | C6: State Water Board eAR Section 4
A7: Total annual revenue (eAR Section 8b B1.8) | C7: eAR Section 8b total annual revenue not reported for this system.
A8: Primary source
A10: Revenue categories (value, classification, per customer, share)
A11: Revenue category | B11: Classification | C11: Value (USD) | D11: Per customer | E11: Share of revenue
A12: Water sales revenue | B12: not reported | C12: not reported | D12: not reported | E12: not reported
A13: Assessment revenue (990 program-service revenue not matched to eAR water-rate revenue) | B13: IMPOSSIBLE | C13: IMPOSSIBLE | D13: IMPOSSIBLE | E13: IMPOSSIBLE
A14: Meter revenue | B14: not reported | C14: not reported | D14: not reported | E14: not reported
A15: Overage or tiered penalty revenue | B15: not reported | C15: not reported | D15: not reported | E15: not reported
A17: Water sales revenue - not reported
A18: Not reported: this system filed an eAR but no Section 8b revenue block, so there is no filed water-sales figure. Not fallen back to a different year.
A19: Reason: No filed eAR Section 8b water-rate revenue for this system.
A21: Assessment revenue (990 program-service revenue not matched to eAR water-rate revenue) - IMPOSSIBLE
A22: Not computed. A period-aligned residual is not possible for this filer.
A23: Reason: Not derivable. The eAR Section 8b is reporting year None while the Form 990 fiscal year ends None; the two period ends are not aligned, so a period-aligned residual cannot be computed.
A25: Meter revenue - not reported
A26: Not reported. This category is not built because doing so would double-count.
A27: Reason: The eAR Section 8a reports a base/meter rate PRICE, but the filing carries no meter revenue line and no tier volume, and the base charge is already inside the water-sales revenue (eAR Section 8b water rates). Building a separate meter figure would double-count. Not backed into from a total.
A29: Overage or tiered penalty revenue - not reported
A30: Not reported. This category is not built because doing so would double-count.
A31: Reason: The eAR Section 8a reports tiered/overage rate PRICES, but the filing carries no overage revenue and no tier consumption volume, and any overage billed is already inside the water-sales revenue. Building it would double-count. Not backed into from a total.

Sheet Rate structure
A1: Gill Creek Mutual Water Company
A2: Rate structure and representative bill - eAR Section 8a
A3: Entity ID: cawc_0169 | Fiscal year ends March 31.
A5: This block is a rate-schedule illustration at defined usage levels. It is NOT billed revenue and not a claim about any real customer's usage. The revenue side of unit economics is the separate Unit Economics block.
A6: No filed eAR Section 8a rate schedule is staged for this system.

Sheet Operational metrics
A1: Gill Creek Mutual Water Company
A2: Operational metrics - plant per acre, density, terrain
A3: Entity ID: cawc_0169 | Fiscal year ends March 31.
A5: Plant assets per acre
A6: Service-area acres | B6: 106.3 | C6: Geodesic area (WGS84 spherical excess) of the SABL service-area polygon.
A7: Fiscal year | B7: Gross plant per acre (primary) | C7: Net plant per acre
A8: FY2021 | C8: 777.9962
A9: FY2022 | C9: 758.2032
A10: FY2023
A11: FY2024
A12: FY2025 | B12: 4831.7592 | C12: 2171.5334
A13: Infrastructure built per acre of service area. Gross plant per acre is the primary read because it measures how much plant the system has put in the ground per acre, and unlike net plant it does not fall over time purely because the assets depreciate on the books. Net plant per acre is shown alongside as the depreciated book value per acre.
A14: Formula: gross plant per acre = Form 990 Part X line 10a (land, buildings, and equipment, gross) / SABL service-area acres; net plant per acre uses Part X line 10c (net)
A15: Source lines: Form 990 Part X line 10a (gross) and line 10c (net); Geodesic area (WGS84 spherical excess) of the SABL service-area polygon.
A16: Confidence: medium. This is worked out from filed figures (a ratio, or a year-to-year change), so it is one step removed from the raw numbers.. Filed gross/net plant over the measured SABL service-area acreage.
A18: Connections per acre
A19: Connections per acre | B19: 0.87 | C19: 92 connections / 106.3 acres. CA State Water Board SABL SERVICE_CONNECTIONS; Geodesic area (WGS84 spherical excess) of the SABL service-area polygon.

Sheet Supply & weather
A1: Gill Creek Mutual Water Company
A2: Supply and weather indicators (DWR water year)
A3: Entity ID: cawc_0169 | Fiscal year ends March 31.
A5: Reporting calendar: Different reporting periods. The DWR water year runs October 1 to September 30; this system's fiscal year ends March 31, so the two period ends are six months apart. Read the two side by side with that in mind. Neither series is recast: both are reported as filed. A water year is named for the calendar year it ends in, so WY2024 and FY2024 share a number without covering the same twelve months.
A7: Indicator | B7: WY2021 | C7: WY2022 | D7: WY2023 | E7: WY2024 | F7: WY2025
A8: Water-year type (Sacramento Valley) | B8: Critical | C8: Critical | D8: Wet | E8: Above Normal | F8: not reported
A9: Peak drought, county County | B9: not reported | C9: not reported | D9: not reported | E9: not reported | F9: not reported
A10: Precip, percent of normal (8-Station Index) | B10: 48 | C10: 86 | D10: 133 | E10: 96 | F10: 113
A11: Snowpack, April 1 percent of average | B11: 59% | C11: 38% | D11: 237% | E11: 110% | F11: 96%
A12: State Water Project allocation | B12: 5% | C12: 5% | D12: 100% | E12: 40% | F12: 50%

Sheet How this was built
A1: Gill Creek Mutual Water Company
A2: How this was built - forensic lineage
A3: Entity ID: cawc_0169 | Fiscal year ends March 31.
A5: A plain account of the forensic lineage behind the hard-to-source metrics: what sources were checked, what was found, what was derived, and what could not be built and why. Every figure marked DERIVED or IMPOSSIBLE above is traceable to a line here.
A7: Water-sales revenue per customer - not reported
A8: Sources checked | B8: State Water Board eAR Section 8b (water-rate revenue B1.1/B1.2); State Water Board eAR Section 4 (connection count, same reporting year); audited financial statement (secondary cross-check, where published)
A9: What was found | B9: The eAR Section 8b reports water-rate revenue for reporting year None, so this is a DIRECT filed figure; per customer it is divided by the eAR Section 4 connection count for the same reporting year, so numerator and denominator share the year.
A11: Assessment revenue (residual) - IMPOSSIBLE
A12: Sources checked | B12: Form 990 Part VIII line 2 (program-service revenue); State Water Board eAR Section 8b (water-rate revenue B1.1/B1.2); eAR Section 8b filer comment (WRRevenueComments)
A13: What was found | B13: A period-aligned residual cannot be computed for this filer, so the metric is rendered IMPOSSIBLE rather than guessed.
A14: Caveat | B14: Not derivable. The eAR Section 8b is reporting year None while the Form 990 fiscal year ends None; the two period ends are not aligned, so a period-aligned residual cannot be computed.
A16: Meter revenue - not reported
A17: Sources checked | B17: State Water Board eAR Section 8a (rate prices); State Water Board eAR Section 8b (revenue lines); audited financial statement
A18: What was found | B18: The rate price exists in Section 8a but no revenue or tier volume is reported, and the base charge is already inside water sales.
A19: Caveat | B19: The eAR Section 8a reports a base/meter rate PRICE, but the filing carries no meter revenue line and no tier volume, and the base charge is already inside the water-sales revenue (eAR Section 8b water rates). Building a separate meter figure would double-count. Not backed into from a total.
A21: Overage / tiered-penalty revenue - not reported
A22: Sources checked | B22: State Water Board eAR Section 8a (rate prices); State Water Board eAR Section 8b (revenue lines); audited financial statement
A23: What was found | B23: The rate price exists in Section 8a but no revenue or tier volume is reported, and the base charge is already inside water sales.
A24: Caveat | B24: The eAR Section 8a reports tiered/overage rate PRICES, but the filing carries no overage revenue and no tier consumption volume, and any overage billed is already inside the water-sales revenue. Building it would double-count. Not backed into from a total.
A26: eAR Section 8b reporting-period basis - sourced
A27: Sources checked | B27: eAR Section 8b B0.1 (WRFinancialReportingPeriod); eAR Section 8b B0.2 (WRFiscalYearStartDate)
A28: What was found | B28: The reporting basis (fiscal vs calendar year) is read from the filer's own B0.1/B0.2 answer and staged verbatim, never hardcoded, so the 990 comparison and the residual are period-aligned.
A30: Member (shareholder) count denominator - not reported
A31: Sources checked | B31: Form 990 (no member count stated); company website
A32: What was found | B32: No filing states a member/shareholder count, so the per-member unit economics read not reported rather than borrowing the connection count.
A34: Water volume delivered (acre-feet) - not reported
A35: Sources checked | B35: Form 990 (not in the filing); Consumer Confidence Report; eAR Section 6 (PRA-gated)
A36: What was found | B36: Volume delivered in acre-feet is not in the Form 990 and the CCR states only a source mix, so the per-acre-foot metrics read not reported; the eAR Section 6 is named as the source still needed.

Sheet Sources & audit
A1: Gill Creek Mutual Water Company
A2: Sources & audit - full provenance and tie-outs (kept off the statements so they read clean)
A3: Entity ID: cawc_0169 | Fiscal year ends March 31.
A5: Presentation standard: every figure on the statement tabs is verified to its source filing and shown clean. A cell the filing does not report reads "not reported" (never estimated, never guessed).
A6: Citations, confidence tiers, and the filed-vs-computed tie-out checks live on the "Sources & audit" tab, keyed by cell, so every number is fully traceable without cluttering the statements. These pages are ready to use as filed.
A8: A. Filing provenance (one row per staged extraction)
A9: Fiscal year | B9: Period end | C9: Filing type | D9: Confidence | E9: Extraction ID | F9: Object ID | G9: Extracted by | H9: Extracted at | I9: Source URL
A10: FY2020 | B10: 2020-03-31 | C10: 990-EZ | D10: high | E10: 3a0b88ef-640c-46c0-aaaa-0ef0ee5455c2 | F10: 202002529349200165 | G10: claude-opus-5 | H10: 2026-10-05T16:06:10+00:00 | I10: https://apps.irs.gov/pub/epostcard/990/xml/2020/download990xml_2020_1.zip#202002529349200165_public.xml
A11: FY2021 | B11: 2021-03-31 | C11: 990-EZ | D11: high | E11: d6038090-3746-4630-a818-0f1cec06184c | F11: 202112369349200126 | G11: claude-opus-5 | H11: 2026-10-05T16:06:10+00:00 | I11: https://apps.irs.gov/pub/epostcard/990/xml/2021/2021_TEOS_XML_01A.zip#202112369349200126_public.xml
A12: FY2022 | B12: 2022-03-31 | C12: 990-EZ | D12: high | E12: 9d186f7e-53dc-4279-bc13-cf826ee25cf5 | F12: 202241519349200319 | G12: claude-opus-5 | H12: 2026-10-05T16:06:10+00:00 | I12: https://apps.irs.gov/pub/epostcard/990/xml/2022/2022_TEOS_XML_01A.zip#202241519349200319_public.xml
A13: FY2023 | B13: 2023-03-31 | C13: 990-EZ | D13: high | E13: ac76f20e-d696-49df-b9d8-e8077471c4ca | F13: 202312589349201506 | G13: claude-opus-5 | H13: 2026-10-05T16:06:10+00:00 | I13: https://apps.irs.gov/pub/epostcard/990/xml/2023/2023_TEOS_XML_09A.zip#202312589349201506_public.xml
A14: FY2024 | B14: 2024-03-31 | C14: 990-EZ | D14: high | E14: c212bb7e-283d-4f1f-a36c-13599e7b770f | F14: 202401939349201355 | G14: claude-opus-5 | H14: 2026-10-05T16:06:10+00:00 | I14: https://apps.irs.gov/pub/epostcard/990/xml/2024/2024_TEOS_XML_07A.zip#202401939349201355_public.xml
A15: FY2025 | B15: 2025-03-31 | C15: 990 | D15: high | E15: 28191bce-e220-4ab0-ab3a-c55cc9864c21 | F15: 202532409349300863 | G15: claude-opus-5 | H15: 2026-10-05T16:06:10+00:00 | I15: https://apps.irs.gov/pub/epostcard/990/xml/2025/2025_TEOS_XML_09A.zip#202532409349300863_public.xml
A17: B. Figure citations (every figure on the statement tabs, keyed by cell)
A18: Tab | B18: Cell | C18: Line item | D18: Form 990 line | E18: Key path | F18: Confidence | G18: As filed
A19: Revenue (detail) | B19: B8 | C19: 2g. Total program service revenue | D19: 2g | E19: part_viii_revenue.total_program_service_revenue | F19: high | G19: 173093
A20: Revenue (detail) | B20: B9 | C20: 3. Investment income | D20: 3 | E20: part_viii_revenue.investment_income | F20: high | G20: 8778
A21: Revenue (detail) | B21: B12 | C21: 11e. Other revenue | D21: 11e | E21: part_viii_revenue.other_revenue_total | F21: high | G21: 48000
A22: Operating expenses (detail) | B22: B7 | C22: 7. Other salaries and wages | D22: 7 | E22: part_ix_expenses.other_salaries_and_wages | F22: high | G22: 30900
A23: Operating expenses (detail) | B23: B8 | C23: 10. Payroll taxes | D23: 10 | E23: part_ix_expenses.payroll_taxes | F23: high | G23: 4933
A24: Operating expenses (detail) | B24: B9 | C24: 11g. Fees for services: other | D24: 11g | E24: part_ix_expenses.fees_other | F24: high | G24: 3428
A25: Operating expenses (detail) | B25: B10 | C25: 13. Office expenses | D25: 13 | E25: part_ix_expenses.office_expenses | F25: high | G25: 3233
A26: Operating expenses (detail) | B26: B11 | C26: 22. Depreciation, depletion, and amortization | D26: 22 | E26: part_ix_expenses.depreciation | F26: high | G26: 21771
A27: Operating expenses (detail) | B27: B12 | C27: 23. Insurance | D27: 23 | E27: part_ix_expenses.insurance | F27: high | G27: 10329
A28: Operating expenses (detail) | B28: B17 | C28: 24e. All other expenses | D28: 24e | E28: part_ix_expenses.all_other_expenses | F28: high | G28: 7567
A29: Balance sheet (detail) | B29: B7 | C29: 1. Cash - non-interest-bearing | D29: 1E | E29: part_x_balance_sheet.cash_noninterest_eoy | F29: high | G29: 27524
A30: Balance sheet (detail) | B30: B8 | C30: 2. Savings and temporary cash investments | D30: 2E | E30: part_x_balance_sheet.savings_temp_invest_eoy | F30: high | G30: 198416
... A40: Net-assets reconciliation | B40: B8 | C40: 3. Revenue less expenses | D40: Part XI line 3 | E40: part_xi_reconciliation.reconciliation_revenue_expenses | F40: high | G40: 60873
A42: C. Tie-out checks (filed vs computed; any nonzero variance is flagged red)
A43: Tab | B43: Check | C43: Fiscal year | D43: Filed | E43: Computed | F43: Variance (computed - filed)
A44: Revenue (detail) | B44: 12. Total revenue | C44: FY2025 | D44: 229871 | E44: ='Revenue (detail)'!B13 | F44: =E44-D44
A45: Revenue (detail) | B45: 2g program service revenue = sum of lines 2a-2f (FY2025) | C45: FY2025 | D45: 173093 | E45: =SUM('Revenue (detail)'!C17:C19) | F45: =E45-D45
A46: Operating expenses (detail) | B46: 25. Total functional expenses | C46: FY2025 | D46: 168998 | E46: ='Operating expenses (detail)'!B18 | F46: =E46-D46
A47: Operating expenses (detail) | B47: Part IX column split: col A = B + C + D (FY2025) | C47: FY2025 | D47: ='Operating expenses (detail)'!B28 | E47: ='Operating expenses (detail)'!C28+'Operating expenses (detail)'!D28+'Operating expenses (detail)'!E28 | F47: =E47-D47
A48: Balance sheet (detail) | B48: 16. Total assets | C48: FY2025 | D48: 517817 | E48: ='Balance sheet (detail)'!B13 | F48: =E48-D48
A49: Balance sheet (detail) | B49: 26. Total liabilities | C49: FY2025 | D49: 4165 | E49: ='Balance sheet (detail)'!B17 | F49: =E49-D49
A50: Balance sheet (detail) | B50: 32. Total net assets / fund balances | C50: FY2025 | D50: 513652 | E50: ='Balance sheet (detail)'!B23 | F50: =E50-D50
A51: Balance sheet (detail) | B51: Balance sheet identity: line 16 = line 26 + line 32 (EOY) | C51: FY2025 | D51: ='Balance sheet (detail)'!B13 | E51: =SUM('Balance sheet (detail)'!B17,'Balance sheet (detail)'!B23) | F51: =E51-D51
A52: Net-assets reconciliation | B52: 10. Net assets, end of year | C52: FY2025 | D52: 513652 | E52: ='Net-assets reconciliation'!B11 | F52: =E52-D52
A54: D. Preparer / auditor trail (one row per fiscal year, as filed)
...

Sheet Provenance
A1: Build provenance | B1: Built from source commit d418ffb17485 (2026-10-06); source fingerprint a75a8eee82c65cf7; 192 companies (179 retail mutual, 4 irrigation mutual, 3 mutual, no PWSID, purpose not stated, 2 frozen non-mutual (special district), 2 wholesale mutual, 1 frozen non-mutual (investor-owned), 1 frozen non-mutual (municipal)); 91 gates; build id 3d08d6d2a855.
A2: source_commit | B2: d418ffb174855ab78000d391d42f898397b0d8aa
A3: source_commit_date | B3: 2026-10-06
A4: source_fingerprint | B4: a75a8eee82c65cf7096931f06e18affdc28686a02895b46538e7298b57c04d94
A5: gate_count | B5: 91
A6: build_id | B6: 3d08d6d2a855
A7: registry: frozen non-mutual (investor-owned) | B7: 1
A8: registry: frozen non-mutual (municipal) | B8: 1
A9: registry: frozen non-mutual (special district) | B9: 2
A10: registry: irrigation mutual | B10: 4
A11: registry: mutual, no PWSID, purpose not stated | B11: 3
A12: registry: retail mutual | B12: 179
A13: registry: wholesale mutual | B13: 2
