Workbook

Sheet Summary
A1: Oildale Mutual Water Company
A2: Financial Summary - multi-year overview (USD)
A3: Entity ID: cawc_0006 | Fiscal year ends June 30.
A5: Presentation standard: every figure on the statement tabs is verified to its source filing and shown clean. A cell the filing does not report reads "not reported" (never estimated, never guessed).
A6: Citations, confidence tiers, and the filed-vs-computed tie-out checks live on the "Sources & audit" tab, keyed by cell, so every number is fully traceable without cluttering the statements. These pages are ready to use as filed.
A8: Metric | B8: FY2021 | C8: FY2022 | D8: FY2023 | E8: FY2024
A9: Operating results (USD)
A10: Total revenue | B10: 9702473 | C10: 11045397 | D10: 11329134 | E10: 11267619
A11: Total expenses | B11: 6649178 | C11: 9806553 | D11: 11023709 | E11: 5702750
A12: Net income | B12: 3053295 | C12: 1238844 | D12: 305425 | E12: 5564869
A14: Financial position (USD, end of year)
A15: Total assets | B15: 40080458 | C15: 46887728 | D15: 47332418 | E15: 59815004
A16: Total liabilities | B16: 12350469 | C16: 17898260 | D16: 18069175 | E16: 24981391
A17: Net assets | B17: 27729989 | C17: 28989468 | D17: 29263243 | E17: 34833613
A19: Headline ratios
A20: Operating margin | B20: 0.31469245 | C20: 0.1121593 | D20: 0.026959254 | E20: 0.49388154
A21: Revenue growth (YoY) | B21: -0.0065931071 | C21: 0.13841049 | D21: 0.025688257 | E21: -0.005429806
A22: Return on assets | B22: 0.076179144 | C22: 0.026421498 | D22: 0.0064527656 | E22: 0.093034667
A24: Figures as reported in source filings (full provenance on the Sources & audit tab). Parentheses denote negatives; ratios are computed upstream in financials_annual.

Sheet Notes
A1: Notes
A2: Human annotations from the versioned store (data/notes/). Annotations only: they never change a reported figure or a confidence tier.
A4: Date | B4: Tag | C4: Author | D4: Note
A5: No notes recorded yet.

Sheet Financial Statements
A1: Oildale Mutual Water Company
A2: Financial Statements - income statement, balance sheet, cash flow, member income test (USD)
A3: Entity ID: cawc_0006 | Fiscal year ends June 30.
A5: INCOME STATEMENT - as reported (USD)
A6: Line item | B6: FY2021 | C6: FY2022 | D6: FY2023 | E6: FY2024
A7: Revenue
A8: Program service revenue | B8: 9569181 | C8: 10996285 | D8: 10868355 | E8: 10476825
A9: Investment income | B9: 32992 | D9: 402031 | E9: 363479
A10: Net rental income | B10: 0
A11: Net gain/(loss) on investment sales | B11: 100300 | C11: 49112 | D11: 5498 | E11: 49641
A12: Other revenue | B12: 0 | D12: 53250 | E12: 377674
A13: Contributions & grants | B13: 0
A14: Total revenue | B14: 9702473 | C14: 11045397 | D14: 11329134 | E14: 11267619
A16: Expenses
A17: Depreciation | B17: 538372 | C17: 528881 | D17: 620909 | E17: 698760
A18: Interest expense | B18: 0 | C18: 116553
A19: Total expenses | B19: 6649178 | C19: 9806553 | D19: 11023709 | E19: 5702750
A21: Net income | B21: 3053295 | C21: 1238844 | D21: 305425 | E21: 5564869
A24: BALANCE SHEET - as reported (USD, end of year)
A25: Line item | B25: FY2021 | C25: FY2022 | D25: FY2023 | E25: FY2024
A26: Assets
A27: Cash | B27: 3572160 | C27: 1624752 | D27: 907881 | E27: 844633
A28: Savings & temporary investments | B28: 13606674 | C28: 14843672 | D28: 8297164 | E28: 8360628
A29: Accounts receivable | B29: 695678 | C29: 490782 | D29: 472706 | E29: 512049
A30: Inventories | B30: 495881 | C30: 992515 | D30: 803462 | E30: 835298
A31: Prepaid expenses | B31: 16532 | C31: 0
A32: Property, plant & equipment (gross) | B32: 33167978 | C32: 41368569 | D32: 50422521 | E32: 64150676
A33: Less: accumulated depreciation | B33: -11474445 | C33: -12432562 | D33: -13571316 | E33: -14888280
A34: Net property, plant & equipment | B34: 21693533 | C34: 28936007 | D34: 36851205 | E34: 49262396
A35: Total assets | B35: 40080458 | C35: 46887728 | D35: 47332418 | E35: 59815004
A37: Liabilities
A38: Accounts payable | B38: 723891 | C38: 602496 | D38: 489012 | E38: 830364
A39: Mortgages & notes payable | B39: 42105 | C39: 40545 | D39: 37426 | E39: 32748
A40: Total liabilities | B40: 12350469 | C40: 17898260 | D40: 18069175 | E40: 24981391
A42: Net Assets / Equity
A43: Capital stock | B43: 3440614 | C43: 3461249 | D43: 3512057 | E43: 3517559
A44: Paid-in capital | B44: 5731277 | C44: 5731277 | D44: 5731277 | E44: 5731277
A45: Retained earnings | B45: 18558098 | C45: 19796942 | D45: 20019909 | E45: 25584777
A46: Net assets | B46: 27729989 | C46: 28989468 | D46: 29263243 | E46: 34833613
A49: CASH FLOW - derived proxy (USD)
...

Sheet Balance Sheet
A1: Oildale Mutual Water Company
A2: Balance Sheet - as reported (USD, end of year)
A3: Entity ID: cawc_0006 | Fiscal year ends June 30.
A5: Line item | B5: FY2021 | C5: FY2022 | D5: FY2023 | E5: FY2024
A6: Assets
A7: Cash | B7: 3572160 | C7: 1624752 | D7: 907881 | E7: 844633
A8: Savings & temporary investments | B8: 13606674 | C8: 14843672 | D8: 8297164 | E8: 8360628
A9: Accounts receivable | B9: 695678 | C9: 490782 | D9: 472706 | E9: 512049
A10: Inventories | B10: 495881 | C10: 992515 | D10: 803462 | E10: 835298
A11: Prepaid expenses | B11: 16532 | C11: 0
A12: Property, plant & equipment (gross) | B12: 33167978 | C12: 41368569 | D12: 50422521 | E12: 64150676
A13: Less: accumulated depreciation | B13: -11474445 | C13: -12432562 | D13: -13571316 | E13: -14888280
A14: Net property, plant & equipment | B14: 21693533 | C14: 28936007 | D14: 36851205 | E14: 49262396
A15: Total assets | B15: 40080458 | C15: 46887728 | D15: 47332418 | E15: 59815004
A17: Liabilities
A18: Accounts payable | B18: 723891 | C18: 602496 | D18: 489012 | E18: 830364
A19: Mortgages & notes payable | B19: 42105 | C19: 40545 | D19: 37426 | E19: 32748
A20: Total liabilities | B20: 12350469 | C20: 17898260 | D20: 18069175 | E20: 24981391
A22: Net Assets / Equity
A23: Capital stock | B23: 3440614 | C23: 3461249 | D23: 3512057 | E23: 3517559
A24: Paid-in capital | B24: 5731277 | C24: 5731277 | D24: 5731277 | E24: 5731277
A25: Retained earnings | B25: 18558098 | C25: 19796942 | D25: 20019909 | E25: 25584777
A26: Net assets | B26: 27729989 | C26: 28989468 | D26: 29263243 | E26: 34833613
A28: Balance check (assets − liab. − net assets) | B28: 0 | C28: 0 | D28: 0 | E28: 0
A30: Net PP&E is the reported ppe_net column (gross less accumulated depreciation). The balance check should be ~0 where all three totals are reported; a non-zero value flags a reporting or extraction discrepancy worth reviewing.

Sheet Officers & contractors
A1: Oildale Mutual Water Company
A2: Officers, Directors & Contractors - Form 990 Part VII (FY2024; USD)
A3: Entity ID: cawc_0006 | Fiscal year ends June 30.
A5: Section A - Officers, directors, trustees, key employees
A6: Name | B6: Title | C6: Reportable comp (org) | D6: Reportable comp (related) | E6: Other comp | F6: Total compensation
A7: LONNEY BOLLER | B7: DIRECTOR | C7: 6250 | D7: 0 | E7: 0 | F7: 6250
A8: JASON WATTENBARGER | B8: PRESIDENT | C8: 7300 | D8: 0 | E8: 0 | F8: 7300
A9: ROSS JOHNSON | B9: VICE PRESIDENT | C9: 6050 | D9: 0 | E9: 0 | F9: 6050
A10: DON WATTENBARGER | B10: DIRECTOR | C10: 6300 | D10: 0 | E10: 0 | F10: 6300
A11: RYAN NUNNELEY | B11: GENERAL MANAGER/SECRETARY | C11: 151800 | D11: 0 | E11: 0 | F11: 151800
A12: JUDE HUPP | B12: VICE PRESIDENT | C12: 6050 | D12: 0 | E12: 0 | F12: 6050
A13: DOUGLAS NUNNELEY | B13: FORMER SECRETARY | C13: 240000 | D13: 0 | E13: 0 | F13: 240000
A14: ALLAN EVANS | B14: OPERATIONS MANAGER | C14: 129244 | D14: 0 | E14: 0 | F14: 129244
A16: Section B - Independent contractors (over $100,000)
A17: Contractor | B17: Services | C17: Compensation
A19: Section A lists every officer, director, trustee and key employee filed for the latest year; the two with the highest total compensation are highlighted. Total compensation is computed (reportable org + related + other). Section B lists each independent contractor paid over $100,000; the return reports 0 such contractor(s). Source and confidence for every figure are on the Sources & audit tab.

Sheet Revenue (detail)
A1: Oildale Mutual Water Company
A2: Revenue - Form 990 Part VIII (USD)
A3: Entity ID: cawc_0006 | Fiscal year ends June 30.
A5: Part VIII line | B5: FY2021 | C5: FY2022 | D5: FY2023 | E5: FY2024
A6: Revenue by category
A7: 1h. Total contributions, gifts, grants | B7: 0 | C7: not reported | D7: not reported | E7: not reported
A8: 2g. Total program service revenue | B8: 9569181 | C8: 10996285 | D8: 10868355 | E8: 10476825
A9: 3. Investment income | B9: 32992 | C9: not reported | D9: 402031 | E9: 363479
A10: 6d. Net rental income | B10: 0 | C10: not reported | D10: not reported | E10: not reported
A11: 7d. Net gain/(loss) from investment sales | B11: 100300 | C11: 49112 | D11: 5498 | E11: 49641
A12: 11e. Other revenue | B12: 0 | C12: not reported | D12: 53250 | E12: 377674
A13: 12. Total revenue | B13: =SUM(B7:B12) | C13: =SUM(C7:C12) | D13: =SUM(D7:D12) | E13: =SUM(E7:E12)
A15: Program service revenue detail - FY2024 (lines 2a-2f)
A16: Description | B16: Business code | C16: Total revenue
A17: WATER ASSESSMENTS | B17: 221000 | C17: 10476825
A18: Revenue category subtotals are as filed. Total revenue (line 12) is a live SUM of the category cells above; its tie-out to the filed total is on the Sources & audit tab. Program service revenue detail is shown for the latest year, with its sum-to-line-2g check on that same audit tab.

Sheet Operating expenses (detail)
A1: Oildale Mutual Water Company
A2: Statement of Functional Expenses - Form 990 Part IX (USD)
A3: Entity ID: cawc_0006 | Fiscal year ends June 30.
A5: Part IX line (column A Total) | B5: FY2021 | C5: FY2022 | D5: FY2023 | E5: FY2024
A6: Functional expenses, column A Total - by year
A7: 1. Grants to domestic organizations and governments | B7: 0 | C7: not reported | D7: not reported | E7: not reported
A8: 2. Grants to domestic individuals | B8: 0 | C8: not reported | D8: not reported | E8: not reported
A9: 3. Grants to foreign organizations and individuals | B9: 0 | C9: not reported | D9: not reported | E9: not reported
A10: 4. Benefits paid to or for members | B10: 0 | C10: not reported | D10: not reported | E10: not reported
A11: 5. Compensation of current officers, directors, trustees | B11: 289486 | C11: 690828 | D11: 492249 | E11: 552994
A12: 6. Compensation to disqualified persons | B12: 0 | C12: not reported | D12: not reported | E12: not reported
A13: 7. Other salaries and wages | B13: 1195777 | C13: 931891 | D13: 1182252 | E13: 1060074
A14: 8. Pension plan accruals and contributions | B14: 94623 | C14: 93471 | D14: 121241 | E14: 94513
A15: 9. Other employee benefits | B15: 386076 | C15: 296222 | D15: 318406 | E15: 318151
A16: 10. Payroll taxes | B16: 103269 | C16: 120308 | D16: 125860 | E16: 133121
A17: 11a. Fees for services: management | B17: 0 | C17: not reported | D17: not reported | E17: not reported
A18: 11b. Fees for services: legal | B18: 27060 | C18: 45048 | D18: 196450 | E18: 293826
A19: 11c. Fees for services: accounting | B19: 33830 | C19: not reported | D19: not reported | E19: not reported
A20: 11d. Fees for services: lobbying | B20: 0 | C20: not reported | D20: not reported | E20: not reported
A21: 11e. Fees for services: professional fundraising | B21: 0 | C21: not reported | D21: not reported | E21: not reported
A22: 11f. Fees for services: investment management | B22: 0 | C22: not reported | D22: not reported | E22: not reported
A23: 11g. Fees for services: other | B23: 0 | C23: 49648 | D23: 31542 | E23: 17954
A24: 12. Advertising and promotion | B24: 0 | C24: not reported | D24: not reported | E24: not reported
A25: 13. Office expenses | B25: 241028 | C25: 274063 | D25: 271183 | E25: 332598
A26: 14. Information technology | B26: 0 | C26: not reported | D26: not reported | E26: not reported
A27: 15. Royalties | B27: 0 | C27: not reported | D27: not reported | E27: not reported
A28: 16. Occupancy | B28: 0 | C28: not reported | D28: not reported | E28: not reported
A29: 17. Travel | B29: 0 | C29: not reported | D29: not reported | E29: not reported
A30: 18. Payments of travel/entertainment for public officials | B30: 0 | C30: not reported | D30: not reported | E30: not reported
A31: 19. Conferences, conventions, and meetings | B31: 0 | C31: 15255 | D31: 4044 | E31: 16494
A32: 20. Interest | B32: 0 | C32: 116553 | D32: not reported | E32: not reported
A33: 21. Payments to affiliates | B33: 0 | C33: not reported | D33: not reported | E33: not reported
A34: 22. Depreciation, depletion, and amortization | B34: 538372 | C34: 528881 | D34: 620909 | E34: 698760
A35: 23. Insurance | B35: 57530 | C35: 172363 | D35: 227426 | E35: 287362
A36: 24. WATER PURCHASES | B36: 2481654 | C36: not reported | D36: not reported | E36: not reported
A37: 24. REPAIRS & MAINTENANCE | B37: 573437 | C37: not reported | D37: not reported | E37: not reported
A38: 24. UTILITIES | B38: 276546 | C38: not reported | D38: not reported | E38: 167677
A39: 24. PROPERTY AND FRANCHISE TAX | B39: 161494 | C39: not reported | D39: not reported | E39: not reported
A40: 24. ANNUAL ENTITLEMENT | B40: not reported | C40: 2098365 | D40: 2314598 | E40: not reported
A41: 24. CAPITAL FAC | B41: not reported | C41: 1994193 | D41: 1995518 | E41: not reported
...

Sheet Balance sheet (detail)
A1: Oildale Mutual Water Company
A2: Balance Sheet - Form 990 Part X (end of year, USD)
A3: Entity ID: cawc_0006 | Fiscal year ends June 30.
A5: Part X line (column B, EOY) | B5: FY2021 | C5: FY2022 | D5: FY2023 | E5: FY2024
A6: Assets
A7: 1. Cash - non-interest-bearing | B7: 3572160 | C7: 1624752 | D7: 907881 | E7: 844633
A8: 2. Savings and temporary cash investments | B8: 13606674 | C8: 14843672 | D8: 8297164 | E8: 8360628
A9: 3. Pledges and grants receivable, net | B9: 0 | C9: not reported | D9: not reported | E9: not reported
A10: 4. Accounts receivable, net | B10: 695678 | C10: 490782 | D10: 472706 | E10: 512049
A11: 5. Receivables from officers/directors/trustees | B11: 0 | C11: not reported | D11: not reported | E11: not reported
A12: 6. Receivables from disqualified persons | B12: 0 | C12: not reported | D12: not reported | E12: not reported
A13: 7. Notes and loans receivable, net | B13: 0 | C13: not reported | D13: not reported | E13: not reported
A14: 8. Inventories for sale or use | B14: 495881 | C14: 992515 | D14: 803462 | E14: 835298
A15: 9. Prepaid expenses and deferred charges | B15: 16532 | C15: 0 | D15: not reported | E15: not reported
A16: 10c. Land, buildings, and equipment, net | B16: 21693533 | C16: 28936007 | D16: 36851205 | E16: 49262396
A17: 11. Investments - publicly traded securities | B17: 0 | C17: not reported | D17: not reported | E17: not reported
A18: 12. Investments - other securities | B18: 0 | C18: not reported | D18: not reported | E18: not reported
A19: 13. Investments - program-related | B19: 0 | C19: not reported | D19: not reported | E19: not reported
A20: 14. Intangible assets | B20: 0 | C20: not reported | D20: not reported | E20: not reported
A21: 15. Other assets | B21: 0 | C21: not reported | D21: not reported | E21: not reported
A22: 16. Total assets | B22: =SUM(B7:B21) | C22: =SUM(C7:C21) | D22: =SUM(D7:D21) | E22: =SUM(E7:E21)
A24: Liabilities
A25: 17. Accounts payable and accrued expenses | B25: 723891 | C25: 602496 | D25: 489012 | E25: 830364
A26: 23. Secured mortgages and notes payable | B26: 42105 | C26: 40545 | D26: 37426 | E26: 32748
A27: 25. Other liabilities | B27: 11584473 | C27: 17255219 | D27: 17542737 | E27: 24118279
A28: 26. Total liabilities | B28: =SUM(B25:B27) | C28: =SUM(C25:C27) | D28: =SUM(D25:D27) | E28: =SUM(E25:E27)
A30: Net assets / fund balances
A31: 29. Capital stock or trust principal | B31: 3440614 | C31: 3461249 | D31: 3512057 | E31: 3517559
A32: 30. Paid-in or capital surplus | B32: 5731277 | C32: 5731277 | D32: 5731277 | E32: 5731277
A33: 31. Retained earnings / accumulated funds | B33: 18558098 | C33: 19796942 | D33: 20019909 | E33: 25584777
A34: 32. Total net assets / fund balances | B34: =SUM(B31:B33) | C34: =SUM(C31:C33) | D34: =SUM(D31:D33) | E34: =SUM(E31:E33)
A36: Every Part X line is end-of-year (column B), as filed. Section totals (lines 16 / 26 / 32) are live SUMs of the lines above; their tie-outs and the balance-sheet identity (16 = 26 + 32) are on the Sources & audit tab. This filer files as a non-FASB mutual, so net assets sit on lines 29-31 (capital stock / paid-in capital / retained earnings); lines this filer does not report are omitted. Lines 10a/10b net into line 10c (shown).

Sheet Net-assets reconciliation
A1: Oildale Mutual Water Company
A2: Reconciliation of Net Assets - Form 990 Part XI (USD)
A3: Entity ID: cawc_0006 | Fiscal year ends June 30.
A5: Part XI line | B5: FY2021 | C5: FY2022 | D5: FY2023 | E5: FY2024
A6: Reconciliation
A7: 4. Net assets, beginning of year | B7: 24596472 | C7: 27729989 | D7: 28989468 | E7: 29263243
A8: 3. Revenue less expenses | B8: 3053295 | C8: 1238844 | D8: 305425 | E8: 5564869
A9: 8. Prior period adjustments | B9: not reported | C9: not reported | D9: not reported | E9: not reported
A10: 9. Other changes in net assets | B10: 80222 | C10: 20635 | D10: 50808 | E10: 5502
A11: 10. Net assets, end of year | B11: =SUM(B7,B8,B9,B10) | C11: =SUM(C7,C8,C9,C10) | D11: =SUM(D7,D8,D9,D10) | E11: =SUM(E7,E8,E9,E10)
A13: Part XI reconciles beginning to ending net assets. Ending net assets (line 10) is a live formula: beginning balance (line 4) + revenue less expenses (line 3) + prior-period adjustments (8) + other changes (9). Its tie-out to the filed line 10 (and to Part X line 32) is on the Sources & audit tab. Lines 5-7 (unrealized gains, donated services, investment expenses) are not filed by this entity.

Sheet Cash flow proxies
A1: Oildale Mutual Water Company
A2: Cash Flow Proxies - derived (USD)
A3: Entity ID: cawc_0006 | Fiscal year ends June 30.
A5: PROXY ONLY. The source filings contain no statement of cash flows. Lines below are derived from the reported income statement and year-over-year balance-sheet changes; treat as directional estimates, not GAAP cash flows. The earliest year has no prior period, so its delta cells are blank.
A7: Proxy line (USD) | B7: FY2021 | C7: FY2022 | D7: FY2023 | E7: FY2024
A8: Operating
A9: Net income | B9: 3053295 | C9: 1238844 | D9: 305425 | E9: 5564869
A10: + Depreciation (reported) | B10: 538372 | C10: 528881 | D10: 620909 | E10: 698760
A11: − Δ Accounts receivable | C11: 204896 | D11: 18076 | E11: -39343
A12: − Δ Inventories | C12: -496634 | D12: 189053 | E12: -31836
A13: − Δ Prepaid expenses | C13: 16532
A14: + Δ Accounts payable | C14: -121395 | D14: -113484 | E14: 341352
A15: Operating cash flow proxy | C15: 1371124 | D15: 1019979 | E15: 6533802
A17: Investing
A18: − Δ PP&E gross (capex proxy) | C18: -8200591 | D18: -9053952 | E18: -13728155
A20: Financing
A21: Δ Mortgages & notes payable | C21: -1560 | D21: -3119 | E21: -4678
A23: Reconciliation
A24: Δ Cash + temp. investments (actual) | C24: -710410 | D24: -7263379 | E24: 216
A26: The capex proxy assumes gross PP&E rises only via capital spending (it ignores disposals). 'Δ Cash + temp. investments (actual)' is the real reported change in liquid funds and is the most reliable line here; the operating/investing/financing proxies will not perfectly reconcile to it.

Sheet Ratios
A1: Oildale Mutual Water Company
A2: Financial Ratios
A3: Entity ID: cawc_0006 | Fiscal year ends June 30.
A5: Ratio | B5: FY2021 | C5: FY2022 | D5: FY2023 | E5: FY2024
A6: Profitability (computed upstream)
A7: Operating margin (NI / revenue) | B7: 0.31469245 | C7: 0.1121593 | D7: 0.026959254 | E7: 0.49388154
A8: Expense ratio (expenses / revenue) | B8: 0.68530755 | C8: 0.8878407 | D8: 0.97304075 | E8: 0.50611846
A9: Return on assets (NI / assets) | B9: 0.076179144 | C9: 0.026421498 | D9: 0.0064527656 | E9: 0.093034667
A10: Revenue growth (YoY) | B10: -0.0065931071 | C10: 0.13841049 | D10: 0.025688257 | E10: -0.005429806
A12: Leverage & solvency
A13: Debt-to-assets (liab. / assets) | B13: 0.30814191 | C13: 0.3817259 | D13: 0.38175052 | E13: 0.41764423
A14: Equity ratio (net assets / assets) | B14: 0.69185809 | C14: 0.6182741 | D14: 0.61824948 | E14: 0.58235577
A16: Liquidity & asset profile (derived here)
A17: Current ratio (current assets / AP) | B17: 25.400129 | C17: 29.795585 | D17: 21.433447 | E17: 12.708412
A18: Cash ratio ((cash+temp inv.) / total liab.) | B18: 1.3909459 | C18: 0.92011313 | D18: 0.50943361 | E18: 0.36848473
A19: Asset age proxy (accum. deprec. / gross PP&E) | B19: 0.34594949 | C19: 0.30053159 | D19: 0.26915187 | E19: 0.23208298
A21: Upstream ratios are read from financials_annual; derived ratios are computed only where inputs are reported. Current ratio uses accounts payable as the current-liability proxy (the filings do not split current vs. long-term liabilities). Asset age proxy: a higher % implies older / more depreciated infrastructure.

Sheet Unit economics
A1: Oildale Mutual Water Company
A2: Unit economics - per-customer revenue by category (USD)
A3: Entity ID: cawc_0006 | Fiscal year ends June 30.
A5: Every metric here is PER CUSTOMER (a metered service connection). It is not a per-member figure; the member (shareholder) count is a different denominator, shown in the denominator block. The visible cell shows the value and its classification; the numerator, denominator, formula, and rationale are in each metric's LOGIC popup.
A6: Per-customer denominator (service connections) | B6: 12207 | C6: State Water Board eAR Section 4 (CurTotalConnections), reporting year 2023
A7: Total annual revenue (eAR Section 8b B1.8) | B7: 8393855 | C7: State Water Board eAR Section 8b, question B1.8 (total annual revenue), reporting year 2023
A8: Primary source | C8: State Water Board eAR Section 8b (revenue by rate/fee), reporting year 2023
A9: Audit cross-check source | C9: Oildale Mutual Water Company audited financial statement (income statement), year ended June 30, 2024
A11: Revenue categories (value, classification, per customer, share)
A12: Revenue category | B12: Classification | C12: Value (USD) | D12: Per customer | E12: Share of revenue
A13: Water sales revenue | B13: DIRECT | C13: 8042213 | D13: 658.82 | E13: 0.9581
A14: Assessment revenue (990 program-service revenue not matched to eAR water-rate revenue) | B14: DERIVED | C14: 2826142 | D14: 231.52 | E14: 0.26
A15: Meter revenue | B15: not reported | C15: not reported | D15: not reported | E15: not reported
A16: Overage or tiered penalty revenue | B16: not reported | C16: not reported | D16: not reported | E16: not reported
A18: Water sales revenue - DIRECT
A19: Revenue customers paid for water service, read straight off the filed eAR Section 8b water-rate line. A DIRECT filed figure, not computed by us.
A20: Numerator: Water rate revenue | B20: 8042213 | C20: eAR Section 8b field B1.1 (residential water rates) + B1.2 (non-residential water rates). State Water Board eAR Section 8b, question B1.1 + B1.2 (revenue from water rates), reporting year 2023
A21: Denominator: Total service connections | B21: 12207 | C21: eAR Section 4 CurTotalConnections, reporting year 2023. State Water Board eAR Section 4 (CurTotalConnections), reporting year 2023
A22: Per customer: water rate revenue $8,042,213 / 12,207 connections = $658.82 per connection
A23: Share of revenue: water rate revenue $8,042,213 / total annual revenue (eAR Section 8b B1.8) $8,393,855 = 95.81%
A24: Period treatment: Numerator (eAR Section 8b, the fiscal year ending June 30, 2023) and denominator (eAR Section 4 connections reported in the same eAR filing) are both the eAR reporting year 2023, so the two sides are bound to the same reporting year.
A25: Rationale: Dividing water-rate revenue by the number of metered service connections gives the average revenue per customer; dividing by total annual revenue shows how much of the system's income comes from water rates.
A26: Cross-check: No like-for-like cross-check available: the only staged audited statement covers the June 30, 2024 fiscal year, a DIFFERENT fiscal year than the eAR Section 8b period (the fiscal year ending June 30, 2023). Cross-checks compare like fiscal years only, so the audit's Water Sales and Related Charges of $9,348,617 (page 2) is not compared against the eAR figure here.
A28: Assessment revenue (990 program-service revenue not matched to eAR water-rate revenue) - DERIVED
A29: A DERIVED residual (medium confidence): the part of the Form 990 program-service revenue that is not matched by the eAR water-rate revenue for the same period. Computed by us, not a filed line.
A30: Input A: Form 990 program-service revenue | B30: 10868355 | C30: Form 990 Part VIII line 2 (total program-service revenue), fiscal year 2023 ending June 30, 2023
A31: Input B: eAR water-rate revenue | B31: 8042213 | C31: State Water Board eAR Section 8b, question B1.1 + B1.2 (revenue from water rates), reporting year 2023
A32: Residual (A minus B) = assessment revenue | B32: =B30-B31 | C32: $10,868,355 (990 program-service revenue) minus $8,042,213 (eAR water-rate revenue) = $2,826,142
A33: Period alignment: Both inputs cover the same period: the eAR Section 8b is the fiscal year ending June 30, 2023 and the Form 990 fiscal year 2023 ends June 30, 2023, so the residual is period-aligned.
A34: What it IS: revenue the system booked as program service on its 990 that is not accounted for by the eAR water-rate line, plausibly member assessments and other service revenue.
A35: For Oildale this residual is NOT cleanly assessment revenue: it partly reflects the unreconciled gap between the eAR Section 8b total and the Form 990 total for the same fiscal year, so part of it is a source-to-source difference rather than a distinct assessment line.
A36: Denominator: Total service connections | B36: 12207 | C36: eAR Section 4 CurTotalConnections, reporting year 2023. State Water Board eAR Section 4 (CurTotalConnections), reporting year 2023
A37: Per customer: residual $2,826,142 / 12,207 connections = $231.52 per connection
A38: Share of revenue: residual $2,826,142 / 990 program-service revenue $10,868,355 = 26.00%
A40: Meter revenue - not reported
A41: Not reported. This category is not built because doing so would double-count.
A42: Reason: The eAR Section 8a reports a base/meter rate PRICE, but the filing carries no meter revenue line and no tier volume, and the base charge is already inside the water-sales revenue (eAR Section 8b water rates). Building a separate meter figure would double-count. Not backed into from a total.
A44: Overage or tiered penalty revenue - not reported
A45: Not reported. This category is not built because doing so would double-count.
A46: Reason: The eAR Section 8a reports tiered/overage rate PRICES, but the filing carries no overage revenue and no tier consumption volume, and any overage billed is already inside the water-sales revenue. Building it would double-count. Not backed into from a total.

Sheet Rate structure
A1: Oildale Mutual Water Company
A2: Rate structure and representative bill - eAR Section 8a (RY2024)
A3: Entity ID: cawc_0006 | Fiscal year ends June 30.
A5: This block is a rate-schedule illustration at defined usage levels. It is NOT billed revenue and not a claim about any real customer's usage. The revenue side of unit economics is the separate Unit Economics block.
A6: Structure: Uniform: fixed base plus a single volumetric rate, billed monthly, priced per HCF. Rate schedule last updated 01/01/2022.
A7: Defined single-family usage levels, identical for every company so the bill is comparable: Low = 5 HCF/month (~125 gallons/day); Median = 10 HCF/month (~249 gallons/day); High = 25 HCF/month (~623 gallons/day). 1 HCF = 748 gallons, and 1 thousand gallons = 1,000 gallons. The usage is converted into the company's own filed unit before the filed tiers are applied, and the bill is stated as a monthly equivalent: a bimonthly structure is computed at twice the monthly usage and divided by two, and any other billing period the same way with its factor stated. These are an illustration, not a measured usage for any real customer.
A9: Defined usage levels (EDITABLE - change a yellow cell to move the bill)
B10: Low | C10: Median | D10: High
A11: Monthly usage (HCF) | B11: 5 | C11: 10 | D11: 25
A12: Months per bill (from filed billing frequency) | B12: 1 | C12: monthly biller
A14: Filed rate table - single-family residential (as filed, eAR Section 8a)
A15: Base / fixed charge per monthly bill ($) | B15: 23.4
A16: Tier | B16: Range (HCF) | C16: Price ($/HCF) | D16: Upper limit (HCF)
A17: Tier 1 | B17: all usage (HCF) | C17: 1.2 | D17: no limit
A19: Representative monthly bill - LIVE (edit a yellow usage cell to recompute)
B20: Low | C20: Median | D20: High
A21: Usage per bill (HCF) | B21: =B11*$B$12 | C21: =C11*$B$12 | D21: =D11*$B$12
A22: Tier 1 charge per bill ($) | B22: =$C$17*MAX(0,B21-0) | C22: =$C$17*MAX(0,C21-0) | D22: =$C$17*MAX(0,D21-0)
A23: Volumetric charge per bill ($) | B23: =SUM(B22) | C23: =SUM(C22) | D23: =SUM(D22)
A24: Base charge per bill ($) | B24: =$B$15 | C24: =$B$15 | D24: =$B$15
A25: Total per bill ($) | B25: =B24+B23 | C25: =C24+C23 | D25: =D24+D23
A26: Total per MONTH ($) | B26: =B25/$B$12 | C26: =C25/$B$12 | D26: =D25/$B$12
A27: Fixed per month ($) | B27: =$B$15/$B$12 | C27: =$B$15/$B$12 | D27: =$B$15/$B$12
A28: Volumetric per month ($) | B28: =B23/$B$12 | C28: =C23/$B$12 | D28: =D23/$B$12
A29: Effective price ($/HCF) | B29: =IF(B11=0,"",B26/B11) | C29: =IF(C11=0,"",C26/C11) | D29: =IF(D11=0,"",D26/D11)
A31: Rate-structure comparison metrics
A32: Fixed share of the bill at median usage | B32: =C27/C26 | C32: fixed / total at 10 HCF/month
A33: Tier price ratio (highest to lowest positive tier) | B33: =$C$17/$C$17 | C33: uniform structure: a single volumetric rate, so the ratio is 1.00 (flat).
A34: Rate structure (as filed) | B34: uniform (Uniform Usage)
A36: State Water Board eAR Section 8a (Customer Charges), single- and multi-family residential charges grid, reporting year 2024. Rate structure only; no revenue.

Sheet eAR revenue & expenses
A1: Oildale Mutual Water Company
A2: eAR annual revenue and expenses - State Water Board eAR Section 8b (USD)
A3: Entity ID: cawc_0006 | Fiscal year ends June 30.
A5: The water system's own annual figures from the public eAR Section 8b, on the fiscal year ending June 30, 2023 the filer self-reported (B0.1/B0.2). Shown beside the period-aligned Form 990 with the variance flagged: a different source (a State Water Board self-report vs an IRS filing). Preserved as filed, never reconciled.
A6: Reporting period basis (self-reported) | B6: fiscal year ending June 30, 2023 | C6: eAR Section 8b B0.1 (WRFinancialReportingPeriod) / B0.2 start 07/01/2022
A8: Revenue (eAR Section 8b, questions B1.x)
A9: Line | B9: Amount (USD) | C9: Citation
A10: Water rate revenue | B10: 8042213 | C10: State Water Board eAR Section 8b, question B1.1 + B1.2 (revenue from water rates), reporting year 2023
A11: Other fees and charges | B11: 351643 | C11: State Water Board eAR Section 8b, question B1.3 + B1.4 (revenue from other fees), reporting year 2023
A12: Non-customer revenue | B12: 0 | C12: State Water Board eAR Section 8b, question B1.7 (grants, interest, and other non-customer), reporting year 2023
A13: Total annual revenue | B13: 8393855 | C13: State Water Board eAR Section 8b, question B1.8 (total annual revenue for the reporting year), reporting year 2023
A15: Expenses (eAR Section 8b, questions B2.x)
A16: Line | B16: Amount (USD) | C16: Citation
A17: Operations and maintenance | B17: 10388352 | C17: State Water Board eAR Section 8b, question B2.1 (annual O and M expense), reporting year 2023
A18: Capital | B18: 8233312 | C18: State Water Board eAR Section 8b, question B2.2 (annual expenses from investing or capital), reporting year 2023
A19: Financing | B19: 0 | C19: State Water Board eAR Section 8b, question B2.3 (annual expenses from financing), reporting year 2023
A20: Other | B20: 0 | C20: State Water Board eAR Section 8b, question B2.4 (total other annual expenses), reporting year 2023
A21: Total annual expenses | B21: 18621664 | C21: State Water Board eAR Section 8b, question B2.5 (total annual expenses), reporting year 2023
A23: Period-aligned Form 990 comparison (variance surfaced, never reconciled)
A24: Measure | B24: eAR Section 8b | C24: Form 990
A25: total revenue | B25: 8393855 | C25: 11329134
A26: Variance (eAR minus Form 990) | B26: =B25-C25
A27: The eAR Section 8b total revenue (State Water Board self-report, fiscal year ending June 30, 2023) and the Form 990 total revenue (IRS filing) are a different source and cover the same fiscal year (July 1, 2022 to June 30, 2023): the water system self-reported the eAR Section 8b on a fiscal year (B0.1 Fiscal, B0.2 start 07/01/2022), which matches the Form 990 fiscal year. Both are carried as filed; the variance is surfaced, never reconciled.
A28: total expenses | B28: 18621664 | C28: 11023709
A29: Variance (eAR minus Form 990) | B29: =B28-C28
A30: The eAR Section 8b total expenses (State Water Board self-report, fiscal year ending June 30, 2023) and the Form 990 total expenses (IRS filing) are a different source and cover the same fiscal year (July 1, 2022 to June 30, 2023): the water system self-reported the eAR Section 8b on a fiscal year (B0.1 Fiscal, B0.2 start 07/01/2022), which matches the Form 990 fiscal year. Both are carried as filed; the variance is surfaced, never reconciled.

Sheet Denominators & alignment
A1: Oildale Mutual Water Company
A2: Denominators and calendar alignment
A3: Entity ID: cawc_0006 | Fiscal year ends June 30.
A5: System size and water use per fiscal year (the operating denominators that per-customer and per-acre metrics divide by), each cited to file and field. The eAR is reported on the calendar year; the 990 fiscal year differs by company. A calendar-year filer's volume is the eAR annual total (fiscal year = calendar year); an offset filer's is recast by a true monthly sum of the covered calendar months, or read not reported naming the missing months. Point-in-time counts (connections, population) are matched to the closest eAR year and never summed. Every derived figure states its formula and accounting rationale.
A6: Member vs customer (two different denominators, both preserved)
A7: Customer (service connection) | B7: 12207 | C7: State Water Board eAR Section 4 (CurTotalConnections), reporting year 2023
A8: SDWIS service-connection count (different registry) | B8: 13172 | C8: SDWIS reports 13,172 service connections for the same system; the eAR and SDWIS use different registries, so the two counts differ and are both preserved, not reconciled.
A9: Member (shareholder) | B9: 11500 | C9: Form 990 Part III (DELIVERY OF WATER TO 11,500 MEMBERS)
A10: Difference (customers minus members) | B10: 707 | C10: As found: 12,207 service connections and 11,500 members, a difference of 707. Stated as found and not reconciled.
A11: In a mutual water company a MEMBER is a shareholder who owns part of the system; a CUSTOMER is a metered service connection that receives water. The two diverge because one owner can hold several connections, a connection can serve people who are not owners, and some mutuals attach shares to land by acreage rather than counting heads. Per-customer metrics divide by service connections; per-member metrics divide by shareholders; the two counts are never used interchangeably.
A13: Denominator layer by fiscal year
A14: Fiscal year (end) | B14: Connections | C14: Population | D14: Service-area acres | E14: Water produced (AF) | F14: Water delivered (AF) | G14: Alignment method
A15: FY2020 (2020-06-30) | B15: 11693 | C15: not reported | D15: 10873 | E15: 9139.5 | F15: 9136.7 | G15: recast from monthly eAR data to fiscal year ending June 30, 2020
A16: FY2021 (2021-06-30) | B16: 11693 | C16: not reported | D16: 10873 | E16: 9584.7 | F16: 9583.6 | G16: recast from monthly eAR data to fiscal year ending June 30, 2021
A17: FY2022 (2022-06-30) | B17: 11690 | C17: not reported | D17: 10873 | E17: 9204.8 | F17: 7056.9 | G17: recast from monthly eAR data to fiscal year ending June 30, 2022
A18: FY2023 (2023-06-30) | B18: 12207 | C18: not reported | D18: 10873 | E18: not reported | F18: not reported | G18: recast from monthly eAR data to fiscal year ending June 30, 2023
A19: FY2024 (2024-06-30) | B19: 12207 | C19: 39756 | D19: 10873 | E19: not reported | F19: not reported | G19: recast from monthly eAR data to fiscal year ending June 30, 2024
A21: Connections by class - FY2024 (eAR Section 4)
A22: Single-family residential | B22: 11281
A23: Multi-family residential | B23: 570
A24: Commercial and institutional | B24: 733
A25: Industrial | B25: 17
A26: Landscape irrigation | B26: 82
A27: Monthly-volume source: California open-data portal (data.ca.gov): the separate Produced Water (by month and source) and Delivered Water (by month and connection type) resources, which cover every public water system (not only urban suppliers), one resource per reporting year, matched by exact PWSID. This is the aggregate publication of eAR Section 6.

Sheet Governance evidence
A1: Oildale Mutual Water Company
A2: Governance evidence status - Ostrom's eight design principles
A3: Entity ID: cawc_0006 | Fiscal year ends June 30.
A5: Evidence summary: 5 documented, 2 partial, 1 not documented of eight principles.
A6: A count of how many of Elinor Ostrom's eight design principles have a supporting record on file, not a grade. NOT DOCUMENTED means the supporting record was not found, not that the company governs badly. It marks a gap in the documentary record, an evidence gap to close, never a governance failing.
A7: Each mutual is read against Elinor Ostrom's eight design principles for institutions that govern a shared resource durably. Per principle: a one-line finding, the observable signal, a citation, and an evidence status stating whether the supporting record exists: DOCUMENTED (a cited record supports alignment), PARTIAL (some evidence exists but it is incomplete), or NOT DOCUMENTED (no supporting record was found). This is an evidence-status read, not a grade: the principles are never ranked, weighted, or given a letter, consistent with reporting as filed and not grading companies. NOT DOCUMENTED means the supporting record was not found, not that the company governs badly. It marks a gap in the documentary record, an evidence gap to close, never a governance failing.
A9: Principle | B9: Evidence status | C9: Finding | D9: Signal | E9: Citation
A10: Clearly defined boundaries | B10: DOCUMENTED | C10: Members are shareholders, and the service area covers roughly ten square miles with 12,683 eAR connections. | D10: eAR total connections 12,683; about ten square miles served. | E10: [E][1]
A11: What the record shows: Membership is by shareholding and the service area is a well-defined roughly ten-square-mile footprint with 12,683 eAR connections. The SABL service-area boundary is present but Not Verified by the State, and the shareholder roll is not in the record, so the documentation is present but rests on a weaker source than a State-verified polygon.
A12: Rules fit local conditions | B12: PARTIAL | C12: A uniform volumetric rate ties cost to volume, but metering is still being completed under the 2025 State mandate, so charges were historically flat. | D12: eAR rate structure: Uniform Usage; metering conversion underway. | E12: [E][1]
A13: What the record shows: A uniform volumetric rate documents that cost is tied to volume in principle, but metering is still being completed under the 2025 State mandate, so charges have historically been flat and do not yet track each member's actual use. Congruence is documented as a work in progress, so the evidence is partial.
A14: Collective-choice arrangements | B14: DOCUMENTED | C14: Stockholders elect five directors each year, vote by proxy, and may bring stockholder proposals at the annual meeting. | D14: Audited-statement notice: annual election of five directors, 20 percent quorum, proxy voting, stockholder proposals. | E14: [6][1]
A15: What the record shows: The audited-statement notice documents a real, recurring mechanism: annual election of five directors, proxy voting, a 20 percent quorum, and a right to bring stockholder proposals. This is the best-documented collective-choice machinery among the three mutuals. Turnout and contested elections are not in the record.
A16: Monitoring | B16: DOCUMENTED | C16: The company issues an annual audited financial statement and the State risk assessment shows it Not At-Risk with zero violations. | D16: Annual audited income statement; SAFER Not At-Risk, 0 of 6 categories. | E16: [6][S]
A17: What the record shows: The company publishes an annual audited financial statement (an independent financial monitor the other two mutuals lack) and the State rates it Not At-Risk with zero violations, so monitoring is independently documented on two fronts. The audit's scope and any operational-performance monitoring beyond the financial statements and the state risk screen are not in the record.
A18: Graduated sanctions | B18: NOT DOCUMENTED | C18: A schedule of graduated sanctions for non-payment or rule violations is not in the record. | D18: Not reported. | E18: not reported
A19: What the record shows: No schedule of graduated sanctions for non-payment or rule violations appears anywhere in the record. NOT DOCUMENTED means the supporting record was not found; it is a documentary gap, not a finding that the company fails to enforce its rules or governs badly.
A20: Conflict-resolution mechanisms | B20: DOCUMENTED | C20: Monthly open board meetings and legal counsel on retainer provide a standing local forum. | D20: Monthly open board meetings; legal firm on retainer. | E20: [1][2]
A21: What the record shows: Monthly open board meetings and legal counsel on retainer document a standing, regular local forum and access to counsel. The record documents a general governance venue rather than a dedicated dispute-resolution or member-grievance procedure with defined steps.
A22: Recognized right to organize | B22: DOCUMENTED | C22: Recognized by the State Water Board as a privately owned mutual water company and by the IRS as a 501(c)(12). | D22: eAR ownership 'Privately owned Mutual Water Company'; IRS 501(c)(12). | E22: [E][D][SOS]
A23: What the record shows: Documented independently by the State Water Board as a privately owned mutual water company and by the IRS as a 501(c)(12). The record documents baseline legal recognition common to every lawful mutual, with no record of the right being actively used to reshape governance. The California Secretary of State holds the company as a registered corporation, entity number 0089591, first registered 10/30/1919, status as filed "Active", with a governing body named in the Statement of Information filed 6/10/2026. That is a direct state record of the right to organize being recognized, so the evidence behind this status is now a filed corporate record rather than an inference from the company's tax form. The status was already DOCUMENTED and does not move.
A24: Nested enterprises | B24: PARTIAL | C24: Purchases surface water and sits within the Kern County water network alongside neighboring districts, though a formal shared-governance body is not documented. | D24: eAR purchased surface water; Water Association of Kern County member. | E24: [E][2]
A25: What the record shows: The company purchases surface water and belongs to the Water Association of Kern County, so participation in the wider Kern water network is documented. No formal shared-governance body or agreement is documented, so the nesting on record is an informal membership and a purchase relationship rather than a governed layer, and the evidence is partial.

Sheet Operational metrics
A1: Oildale Mutual Water Company
A2: Operational metrics - plant per acre, density, terrain
A3: Entity ID: cawc_0006 | Fiscal year ends June 30.
A5: Plant assets per acre
A6: Service-area acres | B6: 10873 | C6: Geodesic area (WGS84 spherical excess) of the SABL service-area polygon.
A7: Fiscal year | B7: Gross plant per acre (primary) | C7: Net plant per acre
A8: FY2020
A9: FY2021 | B9: 3050.49 | C9: 1995.1746
A10: FY2022 | B10: 3804.7061 | C10: 2661.2717
A11: FY2023 | B11: 4637.4065 | C11: 3389.2399
A12: FY2024 | B12: 5899.9978 | C12: 4530.7087
A13: Infrastructure built per acre of service area. Gross plant per acre is the primary read because it measures how much plant the system has put in the ground per acre, and unlike net plant it does not fall over time purely because the assets depreciate on the books. Net plant per acre is shown alongside as the depreciated book value per acre.
A14: Formula: gross plant per acre = Form 990 Part X line 10a (land, buildings, and equipment, gross) / SABL service-area acres; net plant per acre uses Part X line 10c (net)
A15: Source lines: Form 990 Part X line 10a (gross) and line 10c (net); Geodesic area (WGS84 spherical excess) of the SABL service-area polygon.
A16: Confidence: medium. This is worked out from filed figures (a ratio, or a year-to-year change), so it is one step removed from the raw numbers.. Filed gross/net plant over the measured SABL service-area acreage.
A18: Connections per acre
A19: Connections per acre | B19: 1.26 | C19: 13,733 connections / 10,873.0 acres. CA State Water Board SABL SERVICE_CONNECTIONS; Geodesic area (WGS84 spherical excess) of the SABL service-area polygon.
A21: Weak points and watch items
A22: Terrain class | B22: flat valley | C22: Company context page (BLUEPRINT 5B)
A23: Flat valley urban setting carries minimal WUI risk, but San Joaquin subsidence and SGMA groundwater politics are long-run watch items.

Sheet Supply & weather
A1: Oildale Mutual Water Company
A2: Supply and weather indicators (DWR water year)
A3: Entity ID: cawc_0006 | Fiscal year ends June 30.
A5: Reporting calendar: Different reporting periods. The DWR water year runs October 1 to September 30; this system's fiscal year ends June 30, so the two period ends are three months apart. Read the two side by side with that in mind. Neither series is recast: both are reported as filed. A water year is named for the calendar year it ends in, so WY2024 and FY2024 share a number without covering the same twelve months.
A6: Supply profile: Oildale serves the Bakersfield area and relies on Kern River and purchased surface water plus groundwater, with system metering still being completed, so its supply and cost move with Central Valley hydrology.
A7: Weather link: For Oildale the weather link runs mainly through cost, not revenue: dry years shift it from surface water to pumped groundwater, raising energy and treatment expense, while its historically flat billing kept revenue steadier than a metered peer's.
A9: Indicator | B9: WY2020 | C9: WY2021 | D9: WY2022 | E9: WY2023 | F9: WY2024
A10: Water-year type (Sacramento Valley) | B10: Dry | C10: Critical | D10: Critical | E10: Wet | F10: Above Normal
A11: Peak drought, Kern County | B11: D1 | C11: D4 | D11: D4 | E11: D4 | F11: None (no D0-D4 during the fiscal year)
A12: Precip, percent of normal (8-Station Index) | B12: 63 | C12: 48 | D12: 86 | E12: 133 | F12: 96
A13: Snowpack, April 1 percent of average | B13: 53% | C13: 59% | D13: 38% | E13: 237% | F13: 110%
A14: State Water Project allocation | B14: 20% | C14: 5% | D14: 5% | E14: 100% | F14: 40%
A16: How each dimension reads for this company
A17: Water-year type: A dry water-year type cuts Kern River and project surface-water deliveries, pushing Oildale toward more groundwater pumping, which raises energy and treatment cost.
A18: Drought stage: Kern County drought stage drives conservation, but because much of Oildale's billing was historically flat rather than metered, dry-year demand changes hit its revenue less directly than a fully metered system.
A19: Precipitation: Local and statewide precipitation feed the Kern River and the valley aquifer Oildale draws on, so a dry precipitation year is a lower-surface-supply, higher-pumping-cost year for it.
A20: Snowpack: Southern Sierra snowpack feeds the Kern River, a core Oildale supply, so a thin snowpack year directly reduces its cheapest surface water and raises reliance on pumped groundwater.
A21: State Water Project allocation: State Water Project allocation matters to Oildale through Kern County Water Agency deliveries; a low allocation year tightens the regional surface-water pool it buys into.

Sheet How this was built
A1: Oildale Mutual Water Company
A2: How this was built - forensic lineage
A3: Entity ID: cawc_0006 | Fiscal year ends June 30.
A5: A plain account of the forensic lineage behind the hard-to-source metrics: what sources were checked, what was found, what was derived, and what could not be built and why. Every figure marked DERIVED or IMPOSSIBLE above is traceable to a line here.
A7: Water-sales revenue per customer - DIRECT
A8: Sources checked | B8: State Water Board eAR Section 8b (water-rate revenue B1.1/B1.2); State Water Board eAR Section 4 (connection count, same reporting year); audited financial statement (secondary cross-check, where published)
A9: What was found | B9: The eAR Section 8b reports water-rate revenue for reporting year 2023, so this is a DIRECT filed figure; per customer it is divided by the eAR Section 4 connection count for the same reporting year, so numerator and denominator share the year.
A10: Caveat | B10: No like-for-like cross-check available: the only staged audited statement covers the June 30, 2024 fiscal year, a DIFFERENT fiscal year than the eAR Section 8b period (the fiscal year ending June 30, 2023). Cross-checks compare like fiscal years only, so the audit's Water Sales and Related Charges of $9,348,617 (page 2) is not compared against the eAR figure here.
A12: Assessment revenue (residual) - DERIVED
A13: Sources checked | B13: Form 990 Part VIII line 2 (program-service revenue); State Water Board eAR Section 8b (water-rate revenue B1.1/B1.2)
A14: What was found | B14: No source separately reports a member assessment, so it is DERIVED as a residual: $10,868,355 (990 program-service revenue) minus $8,042,213 (eAR water-rate revenue) = $2,826,142. Period-aligned; medium confidence.
A15: Caveat | B15: For Oildale this residual is NOT cleanly assessment revenue: it partly reflects the unreconciled gap between the eAR Section 8b total and the Form 990 total for the same fiscal year, so part of it is a source-to-source difference rather than a distinct assessment line.
A17: Meter revenue - not reported
A18: Sources checked | B18: State Water Board eAR Section 8a (rate prices); State Water Board eAR Section 8b (revenue lines); audited financial statement
A19: What was found | B19: The rate price exists in Section 8a but no revenue or tier volume is reported, and the base charge is already inside water sales.
A20: Caveat | B20: The eAR Section 8a reports a base/meter rate PRICE, but the filing carries no meter revenue line and no tier volume, and the base charge is already inside the water-sales revenue (eAR Section 8b water rates). Building a separate meter figure would double-count. Not backed into from a total.
A22: Overage / tiered-penalty revenue - not reported
A23: Sources checked | B23: State Water Board eAR Section 8a (rate prices); State Water Board eAR Section 8b (revenue lines); audited financial statement
A24: What was found | B24: The rate price exists in Section 8a but no revenue or tier volume is reported, and the base charge is already inside water sales.
A25: Caveat | B25: The eAR Section 8a reports tiered/overage rate PRICES, but the filing carries no overage revenue and no tier consumption volume, and any overage billed is already inside the water-sales revenue. Building it would double-count. Not backed into from a total.
A27: eAR Section 8b reporting-period basis - sourced
A28: Sources checked | B28: eAR Section 8b B0.1 (WRFinancialReportingPeriod); eAR Section 8b B0.2 (WRFiscalYearStartDate)
A29: What was found | B29: The reporting basis (fiscal vs calendar year) is read from the filer's own B0.1/B0.2 answer and staged verbatim, never hardcoded, so the 990 comparison and the residual are period-aligned.
A31: Member (shareholder) count denominator - sourced
A32: Sources checked | B32: Form 990 (no member count stated); form 990 part iii
A33: What was found | B33: The Form 990 does not state a member count, so it is sourced from form 990 part iii at medium confidence and only used for per-member metrics, never mixed with the customer (connection) count.

Sheet Water Operations
A1: Oildale Mutual Water Company
A2: Water Operations (sourced outside the financial filings)
A3: Entity ID: cawc_0006 | Fiscal year ends June 30.
A5: A separate dialect of data from the financial statements: the system's water supply, from the California State Water Board records (the Consumer Confidence Report served by the eAR portal, and SDWIS Drinking Water Watch). Each field carries its source, year, and confidence the same way a financial line item does; a field the source does not state reads 'not reported' with the source still needed. Figures are as reported, never estimated or reconciled across sources.
A7: Field | B7: Value | C7: Source | D7: Year | E7: Confidence | F7: Source excerpt / cross-source note
A8: Water type | B8: Potable (community drinking water) | C8: Consumer Confidence Report (State Water Board eAR portal) | D8: 2024 | E8: high | F8: 2024 Consumer Confidence Report, Oildale Mutual Water Company and North of the River Municipal Water District
A9: Source mix | B9: 2024 supply: 8,069 acre-feet purchased treated surface water from the Kern County Water Agency H.C. Garnett Water Purification Plant (sourced from the Friant-Kern Canal, California Aqueduct, or Kern River) plus 1,093 acre-feet pumped from company-owned groundwater wells (peaking and emergency backup). | C9: Consumer Confidence Report (State Water Board eAR portal) | D9: 2024 | E9: medium | F9: In 2024 the Company purchased 8,069 acre-feet of treated surface water from the Kern County Water Agency H.C Garnett Water Purification Plant and pumped 1,093 acre-feet from company owned wells.
A10: Annual volume delivered (acre-feet) | B10: 9,162 acre-feet (8,069 purchased treated surface + 1,093 groundwater) | C10: Consumer Confidence Report (State Water Board eAR portal) | D10: 2024 | E10: medium | F10: purchased 8,069 acre-feet of treated surface water ... and pumped 1,093 acre-feet from company owned wells (2024) [cross-source: Volume is CALENDAR year 2024 (CCR); the Form 990 financials are FISCAL year ending June 30, 2024. The periods overlap but are not identical, so per-acre-foot ratios built from both are approximate and capped at medium confidence. Preserved, not reconciled.]
A11: Customer classes served | B11: Residential, commercial, agricultural, industrial | C11: SDWIS Drinking Water Watch (State Water Board) | D11: snapshot | E11: medium | F11: Connection classes: RS, CM, AG, IN
A12: Service connections (total) | B12: Residential 12,328 (9,864 + 2,464); Commercial 743; Agricultural 85; Industrial 16 | C12: SDWIS Drinking Water Watch (State Water Board) | D12: snapshot | E12: medium | F12: RS 9,864 + RS 2,464; CM 743; AG 85; IN 16 service connections [cross-source: SDWIS service connections (about 13,172) differ from the Form 990 member_count (11,500) and the industry figure (about 12,500 connections). Members, connections, and accounts are different bases; all preserved, not reconciled.]
A13: Connections by class | B13: Residential 12,328; Commercial 743; Agricultural 85; Industrial 16 | C13: SDWIS Drinking Water Watch (State Water Board) | D13: snapshot | E13: medium | F13: RS 9,864 + RS 2,464; CM 743; AG 85; IN 16
A14: Population served | B14: 44,899 | C14: SDWIS Drinking Water Watch (State Water Board) | D14: snapshot | E14: medium | F14: Population served 44,899 [cross-source: SDWIS population (44,899) differs from the 2024 CCR service-area figure (about 34,133 residents) and tapwaterdata (38,232). Snapshot and reporting periods differ; all preserved, not reconciled.]
A15: Treatment and water quality | B15: Purchased treated surface water from the Kern County Water Agency H.C. Garnett Water Purification Plant (delivered via the North of the River Municipal Water District); company groundwater wells for peaking and backup; chlorine disinfection. | C15: Consumer Confidence Report (State Water Board eAR portal) | D15: 2024 | E15: medium | F15: purchased treated surface water from the Kern County Water Agency H.C Garnett Water Purification Plant ... company owned wells which are presently used for peaking and emergency back-up supply

Sheet Anomaly Flags
A1: Oildale Mutual Water Company
A2: Anomaly Flags (automated; kept separate from the clean statements)
A3: Entity ID: cawc_0006 | Fiscal year ends June 30.
A5: Material irregularities found automatically in the filed financials by the Hydronomics anomaly flagger. Each flag has two clearly separated layers. WHAT is mechanical, certain, and sourced: the exact filed lines, years, and amounts, carried as filed and never reconciled. WHY is attempted: the filing's own narrative is checked first, and when it states no reason a single best-guess hypothesis is shown, clearly labelled as a guess that is not in the filing and is not a verified figure.
A7: Flag: FY2024 expense drop and net income swing
A8: Affected figure | B8: Total expenses FY2024, Net income FY2024
A9: Confidence | B9: high
A10: What happened (filed, sourced) | B10: FY2024 total functional expenses (Form 990 Part IX line 25) fell to $5,702,750 from $11,023,709 in FY2023, a 48 percent drop, while total revenue (Part VIII line 12) held roughly flat ($11,267,619 vs $11,329,134), so net income (Part I, revenue less expenses) rose to $5,564,869 from $305,425. The drop is concentrated in 2 filer-itemized Other expenses lines (Part IX line 24) present in prior years but absent in FY2024: ANNUAL ENTITLEMENT ($2,098,365 FY2022, $2,314,598 FY2023) and CAPITAL FAC ($1,994,193 FY2022, $1,995,518 FY2023). MISC EXPENSES ($544,912 FY2023) also drops out. Carried as filed and flagged as a documented anomaly, not smoothed; the remaining line-24 movement is left as filed, not reconciled.
A11: Source lines | B11: - Form 990 Part IX line 25 (total functional expenses): $11,023,709 FY2023, $5,702,750 FY2024 - Form 990 Part IX line 24 (ANNUAL ENTITLEMENT): $2,098,365 FY2022; $2,314,598 FY2023; absent FY2024 - Form 990 Part IX line 24 (CAPITAL FAC): $1,994,193 FY2022; $1,995,518 FY2023; absent FY2024 - Form 990 Part IX line 24 (MISC EXPENSES): $544,912 FY2023; absent FY2024 - Form 990 Part VIII line 12 (total revenue): $11,329,134 FY2023, $11,267,619 FY2024 - Form 990 Part I (revenue less expenses): $305,425 FY2023, $5,564,869 FY2024
A12: Confidence reasoning | B12: Every figure is a direct filed line item (Form 990 Part IX lines 25 and 24, Part VIII line 12, Part I), carried as filed from the analytical layer that round-trips to the IRS efile XML. The cause of the swing is addressed in the why layer and is not asserted as fact (prefer-unknown).
A13: Why (not stated in the filing) | B13: The filing does not state a reason.
A14: Possible explanation (guess) | B14: Possible explanation, not stated in filing: ANNUAL ENTITLEMENT, CAPITAL FAC, and MISC EXPENSES being gone in the latest year may reflect a one-time cost that was recorded only in the earlier years, a change in how these costs were labeled or grouped, or a real drop in them. This is an educated guess from the nature of the line items, not something the filing actually says.

Sheet Sources & audit
A1: Oildale Mutual Water Company
A2: Sources & audit - full provenance and tie-outs (kept off the statements so they read clean)
A3: Entity ID: cawc_0006 | Fiscal year ends June 30.
