Workbook

Sheet Summary
A1: New Auberry Water Association
A2: Financial Summary - multi-year overview (USD)
A3: Entity ID: cawc_0081 | Fiscal year ends January 31.
A5: Presentation standard: every figure on the statement tabs is verified to its source filing and shown clean. A cell the filing does not report reads "not reported" (never estimated, never guessed).
A6: Citations, confidence tiers, and the filed-vs-computed tie-out checks live on the "Sources & audit" tab, keyed by cell, so every number is fully traceable without cluttering the statements. These pages are ready to use as filed.
A8: Metric | B8: FY2020 | C8: FY2021 | D8: FY2023 | E8: FY2024 | F8: FY2025
A9: Operating results (USD)
A10: Total revenue | B10: 67733 | C10: 82985 | D10: 170657 | E10: 407311 | F10: 244350
A11: Total expenses | B11: 61083 | C11: 64834 | D11: 163629 | E11: 373520 | F11: 271997
A12: Net income | B12: 6650 | C12: 18151 | D12: 7028 | E12: 33791 | F12: -27647
A14: Financial position (USD, end of year)
A15: Total assets | B15: 192210 | C15: 210361 | D15: 201719 | E15: 235510 | F15: 207863
A16: Total liabilities | B16: 0 | C16: 0 | D16: 0 | E16: 0 | F16: 0
A17: Net assets | B17: 192210 | C17: 210361 | D17: 201719 | E17: 235510 | F17: 207863
A19: Headline ratios
A20: Operating margin | B20: 0.098179617 | C20: 0.21872628 | D20: 0.04118202 | E20: 0.082961177 | F20: -0.11314508
A21: Revenue growth (YoY) | E21: 1.3867231 | F21: -0.40008986
A22: Return on assets | B22: 0.034597576 | C22: 0.086285005 | D22: 0.034840546 | E22: 0.14348011 | F22: -0.13300587
A24: Figures as reported in source filings (full provenance on the Sources & audit tab). Parentheses denote negatives; ratios are computed upstream in financials_annual.

Sheet Notes
A1: Notes
A2: Human annotations from the versioned store (data/notes/). Annotations only: they never change a reported figure or a confidence tier.
A4: Date | B4: Tag | C4: Author | D4: Note
A5: No notes recorded yet.

Sheet Financial Statements
A1: New Auberry Water Association
A2: Financial Statements - income statement, balance sheet, cash flow, member income test (USD)
A3: Entity ID: cawc_0081 | Fiscal year ends January 31.
A5: INCOME STATEMENT - as reported (USD)
A6: Line item | B6: FY2020 | C6: FY2021 | D6: FY2023 | E6: FY2024 | F6: FY2025
A7: Revenue
A8: Program service revenue
A9: Investment income | E9: 7 | F9: 7
A10: Net rental income | E10: 13300 | F10: 14400
A11: Net gain/(loss) on investment sales
A12: Other revenue
A13: Contributions & grants | E13: 394004 | F13: 229943
A14: Total revenue | E14: 407311 | F14: 244350
A16: Expenses
A17: Depreciation
A18: Interest expense
A19: Total expenses | B19: 61083 | C19: 64834 | D19: 163629 | E19: 373520 | F19: 271997
A21: Net income | B21: 6650 | C21: 18151 | D21: 7028 | E21: 33791 | F21: -27647
A24: BALANCE SHEET - as reported (USD, end of year)
A25: Line item | B25: FY2020 | C25: FY2021 | D25: FY2023 | E25: FY2024 | F25: FY2025
A26: Assets
A27: Cash | B27: 22210 | C27: 40361 | D27: 31719 | E27: 65510 | F27: 74718
A28: Savings & temporary investments | E28: 170000 | F28: 133145
A29: Accounts receivable
A30: Inventories
A31: Prepaid expenses
A32: Property, plant & equipment (gross)
A33: Less: accumulated depreciation
A34: Net property, plant & equipment | B34: 170000 | C34: 170000 | D34: 170000
A35: Total assets | B35: 192210 | C35: 210361 | D35: 201719 | E35: 235510 | F35: 207863
A37: Liabilities
A38: Accounts payable
A39: Mortgages & notes payable
A40: Total liabilities | B40: 0 | C40: 0 | D40: 0 | E40: 0 | F40: 0
A42: Net Assets / Equity
A43: Capital stock
A44: Paid-in capital
A45: Retained earnings
A46: Net assets | B46: 192210 | C46: 210361 | D46: 201719 | E46: 235510 | F46: 207863
A49: CASH FLOW - derived proxy (USD)
...

Sheet Balance Sheet
A1: New Auberry Water Association
A2: Balance Sheet - as reported (USD, end of year)
A3: Entity ID: cawc_0081 | Fiscal year ends January 31.
A5: Line item | B5: FY2020 | C5: FY2021 | D5: FY2023 | E5: FY2024 | F5: FY2025
A6: Assets
A7: Cash | B7: 22210 | C7: 40361 | D7: 31719 | E7: 65510 | F7: 74718
A8: Savings & temporary investments | E8: 170000 | F8: 133145
A9: Accounts receivable
A10: Inventories
A11: Prepaid expenses
A12: Property, plant & equipment (gross)
A13: Less: accumulated depreciation
A14: Net property, plant & equipment | B14: 170000 | C14: 170000 | D14: 170000
A15: Total assets | B15: 192210 | C15: 210361 | D15: 201719 | E15: 235510 | F15: 207863
A17: Liabilities
A18: Accounts payable
A19: Mortgages & notes payable
A20: Total liabilities | B20: 0 | C20: 0 | D20: 0 | E20: 0 | F20: 0
A22: Net Assets / Equity
A23: Capital stock
A24: Paid-in capital
A25: Retained earnings
A26: Net assets | B26: 192210 | C26: 210361 | D26: 201719 | E26: 235510 | F26: 207863
A28: Balance check (assets − liab. − net assets) | B28: 0 | C28: 0 | D28: 0 | E28: 0 | F28: 0
A30: Net PP&E is the reported ppe_net column (gross less accumulated depreciation). The balance check should be ~0 where all three totals are reported; a non-zero value flags a reporting or extraction discrepancy worth reviewing.

Sheet Officers & contractors
A1: New Auberry Water Association
A2: Officers, Directors & Contractors - Form 990 Part VII (FY2025; USD)
A3: Entity ID: cawc_0081 | Fiscal year ends January 31.
A5: Section A - Officers, directors, trustees, key employees
A6: Name | B6: Title | C6: Reportable comp (org) | D6: Reportable comp (related) | E6: Other comp | F6: Total compensation
A7: KELLI DACKAWICH | B7: PRESIDENTTREASURER | C7: 0 | D7: 0 | E7: 0 | F7: 0
A8: MARK OLIVER | B8: VICE PRESIDENT | C8: 0 | D8: 0 | E8: 0 | F8: 0
A9: EVA MALIK | B9: SECRETARY | C9: 0 | D9: 0 | E9: 0 | F9: 0
A10: SUE CHESTERMAN | B10: MEMBER | C10: 0 | D10: 0 | E10: 0 | F10: 0
A11: MINDY SMITH | B11: MEMBER | C11: 0 | D11: 0 | E11: 0 | F11: 0
A13: Section B - Independent contractors (over $100,000)
A14: Contractor | B14: Services | C14: Compensation
A16: Section A lists every officer, director, trustee and key employee filed for the latest year; the two with the highest total compensation are highlighted. Total compensation is computed (reportable org + related + other). Section B lists each independent contractor paid over $100,000; the return reports None such contractor(s). Source and confidence for every figure are on the Sources & audit tab.

Sheet Revenue (detail)
A1: New Auberry Water Association
A2: Revenue - Form 990 Part VIII (USD)
A3: Entity ID: cawc_0081 | Fiscal year ends January 31.
A5: Part VIII line | B5: FY2024 | C5: FY2025
A6: Revenue by category
A7: 1h. Total contributions, gifts, grants | B7: 394004 | C7: 229943
A8: 2g. Total program service revenue | B8: not reported | C8: not reported
A9: 3. Investment income | B9: 7 | C9: 7
A10: 6d. Net rental income | B10: 13300 | C10: 14400
A11: 7d. Net gain/(loss) from investment sales | B11: not reported | C11: not reported
A12: 11e. Other revenue | B12: not reported | C12: not reported
A13: 12. Total revenue | B13: =SUM(B7:B12) | C13: =SUM(C7:C12)
A15: Revenue category subtotals are as filed. Total revenue (line 12) is a live SUM of the category cells above; its tie-out to the filed total is on the Sources & audit tab. Program service revenue detail is shown for the latest year, with its sum-to-line-2g check on that same audit tab.

Sheet Operating expenses (detail)
A1: New Auberry Water Association
A2: Statement of Functional Expenses - Form 990 Part IX (USD)
A3: Entity ID: cawc_0081 | Fiscal year ends January 31.
A5: Part IX line (column A Total) | B5: FY2024 | C5: FY2025
A6: Functional expenses, column A Total - by year
A7: 11b. Fees for services: legal | B7: 385 | C7: 85
A8: 11c. Fees for services: accounting | B8: 9142 | C8: 12980
A9: 13. Office expenses | B9: 1264 | C9: 1192
A10: 16. Occupancy | B10: 24576 | C10: 22303
A11: 23. Insurance | B11: 2289 | C11: 2621
A12: 24. SWRCB WATER SYS CONSTRUCTION | B12: 291600 | C12: 168636
A13: 24. CHISHOLD EXPENSES | B13: 8780 | C13: 9137
A14: 24. REPAIRS SPEC PROJECTS | B14: 19350 | C14: 38893
A15: 24. REPAIRS | B15: 4179 | C15: 4303
A16: 24e. All other expenses | B16: 11955 | C16: 11847
A17: 25. Total functional expenses | B17: =SUM(B7:B16) | C17: =SUM(C7:C16)
A19: Functional column split - FY2025 (col A = B + C + D)
A20: Part IX line | B20: A. Total | C20: B. Program services | D20: C. Management & general | E20: D. Fundraising
A21: 11b. Fees for services: legal | B21: 85 | C21: 85
A22: 11c. Fees for services: accounting | B22: 12980 | C22: 12980
A23: 13. Office expenses | B23: 1192 | C23: 1192
A24: 16. Occupancy | B24: 22303 | C24: 22303
A25: 23. Insurance | B25: 2621 | C25: 2621
A26: 25. Total (filed col A / B / C / D) | B26: 271997 | C26: 271997 | D26: 0 | E26: 0
A28: Top block: each Part IX line, column A (Total), by year, as filed. Total functional expenses (line 25) is a live SUM of the line cells; its tie-out to the filed total is on the Sources & audit tab. Filer-itemized 24a-24d rows show the most recent year's as-filed wording; rows are aligned across years case-insensitively with collapsed spacing, so a line filed only in a different capitalization or spacing shares one row, while genuinely different wording stays a separate row (every as-filed variant is recorded on the Sources & audit tab). Lower block: the program / management / fundraising split for the latest year, with its col A = B + C + D check on the audit tab. Lines this filer does not report are omitted rather than shown empty.

Sheet Balance sheet (detail)
A1: New Auberry Water Association
A2: Balance Sheet - Form 990 Part X (end of year, USD)
A3: Entity ID: cawc_0081 | Fiscal year ends January 31.
A5: Part X line (column B, EOY) | B5: FY2024 | C5: FY2025
A6: Assets
A7: 1. Cash - non-interest-bearing | B7: 65510 | C7: 74718
A8: 2. Savings and temporary cash investments | B8: 170000 | C8: 133145
A9: 16. Total assets | B9: =SUM(B7:B8) | C9: =SUM(C7:C8)
A11: Liabilities
A12: 26. Total liabilities | B12: =SUM(B12:B11) | C12: =SUM(C12:C11)
A14: Net assets / fund balances
A15: 27. Net assets without donor restrictions | B15: 235510 | C15: 207863
A16: 32. Total net assets / fund balances | B16: =SUM(B15:B15) | C16: =SUM(C15:C15)
A18: Every Part X line is end-of-year (column B), as filed. Section totals (lines 16 / 26 / 32) are live SUMs of the lines above; their tie-outs and the balance-sheet identity (16 = 26 + 32) are on the Sources & audit tab. This filer files as a non-FASB mutual, so net assets sit on lines 29-31 (capital stock / paid-in capital / retained earnings); lines this filer does not report are omitted. Lines 10a/10b net into line 10c (shown).

Sheet Net-assets reconciliation
A1: New Auberry Water Association
A2: Reconciliation of Net Assets - Form 990 Part XI (USD)
A3: Entity ID: cawc_0081 | Fiscal year ends January 31.
A5: Part XI line | B5: FY2024 | C5: FY2025
A6: Reconciliation
A7: 4. Net assets, beginning of year | B7: 201719 | C7: 235510
A8: 3. Revenue less expenses | B8: 33791 | C8: -27647
A9: 8. Prior period adjustments | B9: not reported | C9: not reported
A10: 9. Other changes in net assets | B10: 0 | C10: 0
A11: 10. Net assets, end of year | B11: =SUM(B7,B8,B9,B10) | C11: =SUM(C7,C8,C9,C10)
A13: Part XI reconciles beginning to ending net assets. Ending net assets (line 10) is a live formula: beginning balance (line 4) + revenue less expenses (line 3) + prior-period adjustments (8) + other changes (9). Its tie-out to the filed line 10 (and to Part X line 32) is on the Sources & audit tab. Lines 5-7 (unrealized gains, donated services, investment expenses) are not filed by this entity.

Sheet Cash flow proxies
A1: New Auberry Water Association
A2: Cash Flow Proxies - derived (USD)
A3: Entity ID: cawc_0081 | Fiscal year ends January 31.
A5: PROXY ONLY. The source filings contain no statement of cash flows. Lines below are derived from the reported income statement and year-over-year balance-sheet changes; treat as directional estimates, not GAAP cash flows. The earliest year has no prior period, so its delta cells are blank.
A7: Proxy line (USD) | B7: FY2020 | C7: FY2021 | D7: FY2023 | E7: FY2024 | F7: FY2025
A8: Operating
A9: Net income | B9: 6650 | C9: 18151 | D9: 7028 | E9: 33791 | F9: -27647
A10: + Depreciation (reported)
A11: − Δ Accounts receivable
A12: − Δ Inventories
A13: − Δ Prepaid expenses
A14: + Δ Accounts payable
A15: Operating cash flow proxy | C15: 18151 | D15: 7028 | E15: 33791 | F15: -27647
A17: Investing
A18: − Δ PP&E gross (capex proxy)
A20: Financing
A21: Δ Mortgages & notes payable
A23: Reconciliation
A24: Δ Cash + temp. investments (actual) | C24: 18151 | D24: -8642 | E24: 203791 | F24: -27647
A26: The capex proxy assumes gross PP&E rises only via capital spending (it ignores disposals). 'Δ Cash + temp. investments (actual)' is the real reported change in liquid funds and is the most reliable line here; the operating/investing/financing proxies will not perfectly reconcile to it.

Sheet Ratios
A1: New Auberry Water Association
A2: Financial Ratios
A3: Entity ID: cawc_0081 | Fiscal year ends January 31.
A5: Ratio | B5: FY2020 | C5: FY2021 | D5: FY2023 | E5: FY2024 | F5: FY2025
A6: Profitability (computed upstream)
A7: Operating margin (NI / revenue) | B7: 0.098179617 | C7: 0.21872628 | D7: 0.04118202 | E7: 0.082961177 | F7: -0.11314508
A8: Expense ratio (expenses / revenue) | B8: 0.90182038 | C8: 0.78127372 | D8: 0.95881798 | E8: 0.91703882 | F8: 1.1131451
A9: Return on assets (NI / assets) | B9: 0.034597576 | C9: 0.086285005 | D9: 0.034840546 | E9: 0.14348011 | F9: -0.13300587
A10: Revenue growth (YoY) | E10: 1.3867231 | F10: -0.40008986
A12: Leverage & solvency
A13: Debt-to-assets (liab. / assets) | B13: 0 | C13: 0 | D13: 0 | E13: 0 | F13: 0
A14: Equity ratio (net assets / assets) | B14: 1 | C14: 1 | D14: 1 | E14: 1 | F14: 1
A16: Liquidity & asset profile (derived here)
A17: Current ratio (current assets / AP)
A18: Cash ratio ((cash+temp inv.) / total liab.)
A19: Asset age proxy (accum. deprec. / gross PP&E)
A21: Upstream ratios are read from financials_annual; derived ratios are computed only where inputs are reported. Current ratio uses accounts payable as the current-liability proxy (the filings do not split current vs. long-term liabilities). Asset age proxy: a higher % implies older / more depreciated infrastructure.

Sheet Unit economics
A1: New Auberry Water Association
A2: Unit economics - per-customer revenue by category (USD)
A3: Entity ID: cawc_0081 | Fiscal year ends January 31.
A5: Every metric here is PER CUSTOMER (a metered service connection). It is not a per-member figure; the member (shareholder) count is a different denominator, shown in the denominator block. The visible cell shows the value and its classification; the numerator, denominator, formula, and rationale are in each metric's LOGIC popup.
A6: Per-customer denominator (service connections) | C6: State Water Board eAR Section 4
A7: Total annual revenue (eAR Section 8b B1.8) | C7: eAR Section 8b total annual revenue not reported for this system.
A8: Primary source
A10: Revenue categories (value, classification, per customer, share)
A11: Revenue category | B11: Classification | C11: Value (USD) | D11: Per customer | E11: Share of revenue
A12: Water sales revenue | B12: not reported | C12: not reported | D12: not reported | E12: not reported
A13: Assessment revenue (990 program-service revenue not matched to eAR water-rate revenue) | B13: IMPOSSIBLE | C13: IMPOSSIBLE | D13: IMPOSSIBLE | E13: IMPOSSIBLE
A14: Meter revenue | B14: not reported | C14: not reported | D14: not reported | E14: not reported
A15: Overage or tiered penalty revenue | B15: not reported | C15: not reported | D15: not reported | E15: not reported
A17: Water sales revenue - not reported
A18: Not reported: this system filed an eAR but no Section 8b revenue block, so there is no filed water-sales figure. Not fallen back to a different year.
A19: Reason: No filed eAR Section 8b water-rate revenue for this system.
A21: Assessment revenue (990 program-service revenue not matched to eAR water-rate revenue) - IMPOSSIBLE
A22: Not computed. A period-aligned residual is not possible for this filer.
A23: Reason: Not derivable. The eAR Section 8b is reporting year None while the Form 990 fiscal year ends None; the two period ends are not aligned, so a period-aligned residual cannot be computed.
A25: Meter revenue - not reported
A26: Not reported. This category is not built because doing so would double-count.
A27: Reason: The eAR Section 8a reports a base/meter rate PRICE, but the filing carries no meter revenue line and no tier volume, and the base charge is already inside the water-sales revenue (eAR Section 8b water rates). Building a separate meter figure would double-count. Not backed into from a total.
A29: Overage or tiered penalty revenue - not reported
A30: Not reported. This category is not built because doing so would double-count.
A31: Reason: The eAR Section 8a reports tiered/overage rate PRICES, but the filing carries no overage revenue and no tier consumption volume, and any overage billed is already inside the water-sales revenue. Building it would double-count. Not backed into from a total.

Sheet Rate structure
A1: New Auberry Water Association
A2: Rate structure and representative bill - eAR Section 8a
A3: Entity ID: cawc_0081 | Fiscal year ends January 31.
A5: This block is a rate-schedule illustration at defined usage levels. It is NOT billed revenue and not a claim about any real customer's usage. The revenue side of unit economics is the separate Unit Economics block.
A6: No filed eAR Section 8a rate schedule is staged for this system.

Sheet Operational metrics
A1: New Auberry Water Association
A2: Operational metrics - plant per acre, density, terrain
A3: Entity ID: cawc_0081 | Fiscal year ends January 31.
A5: Connections per acre
A6: Connections per acre | B6: 0.18 | C6: 35 connections / 199.1 acres. CA State Water Board SABL SERVICE_CONNECTIONS; Geodesic area (WGS84 spherical excess) of the SABL service-area polygon.

Sheet Supply & weather
A1: New Auberry Water Association
A2: Supply and weather indicators (DWR water year)
A3: Entity ID: cawc_0081 | Fiscal year ends January 31.
A5: Reporting calendar: Different reporting periods. The DWR water year runs October 1 to September 30; this system's fiscal year ends January 31, so the two period ends are four months apart. Read the two side by side with that in mind. Neither series is recast: both are reported as filed. A water year is named for the calendar year it ends in, so WY2024 and FY2024 share a number without covering the same twelve months.
A7: Indicator | B7: WY2020 | C7: WY2021 | D7: WY2023 | E7: WY2024 | F7: WY2025
A8: Water-year type (Sacramento Valley) | B8: Dry | C8: Critical | D8: Wet | E8: Above Normal | F8: not reported
A9: Peak drought, county County | B9: not reported | C9: not reported | D9: not reported | E9: not reported | F9: not reported
A10: Precip, percent of normal (8-Station Index) | B10: 63 | C10: 48 | D10: 133 | E10: 96 | F10: 113
A11: Snowpack, April 1 percent of average | B11: 53% | C11: 59% | D11: 237% | E11: 110% | F11: 96%
A12: State Water Project allocation | B12: 20% | C12: 5% | D12: 100% | E12: 40% | F12: 50%

Sheet How this was built
A1: New Auberry Water Association
A2: How this was built - forensic lineage
A3: Entity ID: cawc_0081 | Fiscal year ends January 31.
A5: A plain account of the forensic lineage behind the hard-to-source metrics: what sources were checked, what was found, what was derived, and what could not be built and why. Every figure marked DERIVED or IMPOSSIBLE above is traceable to a line here.
A7: Water-sales revenue per customer - not reported
A8: Sources checked | B8: State Water Board eAR Section 8b (water-rate revenue B1.1/B1.2); State Water Board eAR Section 4 (connection count, same reporting year); audited financial statement (secondary cross-check, where published)
A9: What was found | B9: The eAR Section 8b reports water-rate revenue for reporting year None, so this is a DIRECT filed figure; per customer it is divided by the eAR Section 4 connection count for the same reporting year, so numerator and denominator share the year.
A11: Assessment revenue (residual) - IMPOSSIBLE
A12: Sources checked | B12: Form 990 Part VIII line 2 (program-service revenue); State Water Board eAR Section 8b (water-rate revenue B1.1/B1.2); eAR Section 8b filer comment (WRRevenueComments)
A13: What was found | B13: A period-aligned residual cannot be computed for this filer, so the metric is rendered IMPOSSIBLE rather than guessed.
A14: Caveat | B14: Not derivable. The eAR Section 8b is reporting year None while the Form 990 fiscal year ends None; the two period ends are not aligned, so a period-aligned residual cannot be computed.
A16: Meter revenue - not reported
A17: Sources checked | B17: State Water Board eAR Section 8a (rate prices); State Water Board eAR Section 8b (revenue lines); audited financial statement
A18: What was found | B18: The rate price exists in Section 8a but no revenue or tier volume is reported, and the base charge is already inside water sales.
A19: Caveat | B19: The eAR Section 8a reports a base/meter rate PRICE, but the filing carries no meter revenue line and no tier volume, and the base charge is already inside the water-sales revenue (eAR Section 8b water rates). Building a separate meter figure would double-count. Not backed into from a total.
A21: Overage / tiered-penalty revenue - not reported
A22: Sources checked | B22: State Water Board eAR Section 8a (rate prices); State Water Board eAR Section 8b (revenue lines); audited financial statement
A23: What was found | B23: The rate price exists in Section 8a but no revenue or tier volume is reported, and the base charge is already inside water sales.
A24: Caveat | B24: The eAR Section 8a reports tiered/overage rate PRICES, but the filing carries no overage revenue and no tier consumption volume, and any overage billed is already inside the water-sales revenue. Building it would double-count. Not backed into from a total.
A26: eAR Section 8b reporting-period basis - sourced
A27: Sources checked | B27: eAR Section 8b B0.1 (WRFinancialReportingPeriod); eAR Section 8b B0.2 (WRFiscalYearStartDate)
A28: What was found | B28: The reporting basis (fiscal vs calendar year) is read from the filer's own B0.1/B0.2 answer and staged verbatim, never hardcoded, so the 990 comparison and the residual are period-aligned.
A30: Member (shareholder) count denominator - not reported
A31: Sources checked | B31: Form 990 (no member count stated); company website
A32: What was found | B32: No filing states a member/shareholder count, so the per-member unit economics read not reported rather than borrowing the connection count.
A34: Water volume delivered (acre-feet) - not reported
A35: Sources checked | B35: Form 990 (not in the filing); Consumer Confidence Report; eAR Section 6 (PRA-gated)
A36: What was found | B36: Volume delivered in acre-feet is not in the Form 990 and the CCR states only a source mix, so the per-acre-foot metrics read not reported; the eAR Section 6 is named as the source still needed.

Sheet Sources & audit
A1: New Auberry Water Association
A2: Sources & audit - full provenance and tie-outs (kept off the statements so they read clean)
A3: Entity ID: cawc_0081 | Fiscal year ends January 31.
A5: Presentation standard: every figure on the statement tabs is verified to its source filing and shown clean. A cell the filing does not report reads "not reported" (never estimated, never guessed).
A6: Citations, confidence tiers, and the filed-vs-computed tie-out checks live on the "Sources & audit" tab, keyed by cell, so every number is fully traceable without cluttering the statements. These pages are ready to use as filed.
A8: A. Filing provenance (one row per staged extraction)
A9: Fiscal year | B9: Period end | C9: Filing type | D9: Confidence | E9: Extraction ID | F9: Object ID | G9: Extracted by | H9: Extracted at | I9: Source URL
A10: FY2020 | B10: 2020-01-31 | C10: 990-EZ | D10: high | E10: e2ee2aac-e25a-4de2-a67a-ddc6245faa46 | F10: 202021879349200502 | G10: claude-opus-5 | H10: 2026-09-21T02:50:01+00:00 | I10: https://apps.irs.gov/pub/epostcard/990/xml/2020/download990xml_2020_4.zip#202021879349200502_public.xml
A11: FY2021 | B11: 2021-01-31 | C11: 990-EZ | D11: high | E11: 117b96e2-e7da-4895-8e92-889a5f3dd0f9 | F11: 202132639349200888 | G11: claude-opus-5 | H11: 2026-09-21T02:50:01+00:00 | I11: https://apps.irs.gov/pub/epostcard/990/xml/2021/2021_TEOS_XML_01A.zip#202132639349200888_public.xml
A12: FY2023 | B12: 2023-01-31 | C12: 990-EZ | D12: high | E12: 064e0720-8c02-4611-b508-9c49d66e84a9 | F12: 202302519349201410 | G12: claude-opus-5 | H12: 2026-09-21T02:50:01+00:00 | I12: https://apps.irs.gov/pub/epostcard/990/xml/2023/2023_TEOS_XML_09A.zip#202302519349201410_public.xml
A13: FY2024 | B13: 2024-01-31 | C13: 990 | D13: high | E13: 273623c1-b7a1-40b4-92b7-851dcf081ef3 | F13: 202401709349301450 | G13: claude-opus-5 | H13: 2026-09-21T02:50:01+00:00 | I13: https://apps.irs.gov/pub/epostcard/990/xml/2024/2024_TEOS_XML_06A.zip#202401709349301450_public.xml
A14: FY2025 | B14: 2025-01-31 | C14: 990 | D14: high | E14: ca45586e-ad9c-46d2-95dc-d6254d6de869 | F14: 202522099349300642 | G14: claude-opus-5 | H14: 2026-09-21T02:50:01+00:00 | I14: https://apps.irs.gov/pub/epostcard/990/xml/2025/2025_TEOS_XML_08A.zip#202522099349300642_public.xml
A16: B. Figure citations (every figure on the statement tabs, keyed by cell)
A17: Tab | B17: Cell | C17: Line item | D17: Form 990 line | E17: Key path | F17: Confidence | G17: As filed
A18: Financial Statements | B18: B73 | C18: 11a. Gross income from members or shareholders | D18: 11a | E18: part_v_other_irs_filings.members_and_shareholders_gross_income | F18: high | G18: 0
A19: Financial Statements | B19: C73 | C19: 11a. Gross income from members or shareholders | D19: 11a | E19: part_v_other_irs_filings.members_and_shareholders_gross_income | F19: high | G19: 0
A20: Financial Statements | B20: B74 | C20: 11b. Gross income from other sources | D20: 11b | E20: part_v_other_irs_filings.other_sources_gross_income | F20: high | G20: 0
A21: Financial Statements | B21: C74 | C21: 11b. Gross income from other sources | D21: 11b | E21: part_v_other_irs_filings.other_sources_gross_income | F21: high | G21: 0
A22: Revenue (detail) | B22: B7 | C22: 1h. Total contributions, gifts, grants | D22: 1h | E22: part_viii_revenue.total_contributions | F22: high | G22: 394004
A23: Revenue (detail) | B23: C7 | C23: 1h. Total contributions, gifts, grants | D23: 1h | E23: part_viii_revenue.total_contributions | F23: high | G23: 229943
A24: Revenue (detail) | B24: B9 | C24: 3. Investment income | D24: 3 | E24: part_viii_revenue.investment_income | F24: high | G24: 7
A25: Revenue (detail) | B25: C9 | C25: 3. Investment income | D25: 3 | E25: part_viii_revenue.investment_income | F25: high | G25: 7
A26: Revenue (detail) | B26: B10 | C26: 6d. Net rental income | D26: 6d | E26: part_viii_revenue.net_rental_income | F26: high | G26: 13300
A27: Revenue (detail) | B27: C10 | C27: 6d. Net rental income | D27: 6d | E27: part_viii_revenue.net_rental_income | F27: high | G27: 14400
A28: Operating expenses (detail) | B28: B7 | C28: 11b. Fees for services: legal | D28: 11b | E28: part_ix_expenses.fees_legal | F28: high | G28: 385
A29: Operating expenses (detail) | B29: C7 | C29: 11b. Fees for services: legal | D29: 11b | E29: part_ix_expenses.fees_legal | F29: high | G29: 85
... A51: Net-assets reconciliation | B51: C10 | C51: 9. Other changes in net assets | D51: Part XI line 9 | E51: part_xi_reconciliation.other_changes_net_assets | F51: high | G51: 0
A53: C. Tie-out checks (filed vs computed; any nonzero variance is flagged red)
A54: Tab | B54: Check | C54: Fiscal year | D54: Filed | E54: Computed | F54: Variance (computed - filed)
A55: Revenue (detail) | B55: 12. Total revenue | C55: FY2024 | D55: 407311 | E55: ='Revenue (detail)'!B13 | F55: =E55-D55
A56: Revenue (detail) | B56: 12. Total revenue | C56: FY2025 | D56: 244350 | E56: ='Revenue (detail)'!C13 | F56: =E56-D56
A57: Operating expenses (detail) | B57: 25. Total functional expenses | C57: FY2024 | D57: 373520 | E57: ='Operating expenses (detail)'!B17 | F57: =E57-D57
A58: Operating expenses (detail) | B58: 25. Total functional expenses | C58: FY2025 | D58: 271997 | E58: ='Operating expenses (detail)'!C17 | F58: =E58-D58
A59: Operating expenses (detail) | B59: Part IX column split: col A = B + C + D (FY2025) | C59: FY2025 | D59: ='Operating expenses (detail)'!B26 | E59: ='Operating expenses (detail)'!C26+'Operating expenses (detail)'!D26+'Operating expenses (detail)'!E26 | F59: =E59-D59
A60: Balance sheet (detail) | B60: 16. Total assets | C60: FY2024 | D60: 235510 | E60: ='Balance sheet (detail)'!B9 | F60: =E60-D60
A61: Balance sheet (detail) | B61: 16. Total assets | C61: FY2025 | D61: 207863 | E61: ='Balance sheet (detail)'!C9 | F61: =E61-D61
A62: Balance sheet (detail) | B62: 26. Total liabilities | C62: FY2024 | D62: 0 | E62: ='Balance sheet (detail)'!B12 | F62: =E62-D62
A63: Balance sheet (detail) | B63: 26. Total liabilities | C63: FY2025 | D63: 0 | E63: ='Balance sheet (detail)'!C12 | F63: =E63-D63
A64: Balance sheet (detail) | B64: 32. Total net assets / fund balances | C64: FY2024 | D64: 235510 | E64: ='Balance sheet (detail)'!B16 | F64: =E64-D64
A65: Balance sheet (detail) | B65: 32. Total net assets / fund balances | C65: FY2025 | D65: 207863 | E65: ='Balance sheet (detail)'!C16 | F65: =E65-D65
...

Sheet Provenance
A1: Build provenance | B1: Built from source commit d418ffb17485 (2026-10-06); source fingerprint a75a8eee82c65cf7; 192 companies (179 retail mutual, 4 irrigation mutual, 3 mutual, no PWSID, purpose not stated, 2 frozen non-mutual (special district), 2 wholesale mutual, 1 frozen non-mutual (investor-owned), 1 frozen non-mutual (municipal)); 91 gates; build id 3d08d6d2a855.
A2: source_commit | B2: d418ffb174855ab78000d391d42f898397b0d8aa
A3: source_commit_date | B3: 2026-10-06
A4: source_fingerprint | B4: a75a8eee82c65cf7096931f06e18affdc28686a02895b46538e7298b57c04d94
A5: gate_count | B5: 91
A6: build_id | B6: 3d08d6d2a855
A7: registry: frozen non-mutual (investor-owned) | B7: 1
A8: registry: frozen non-mutual (municipal) | B8: 1
A9: registry: frozen non-mutual (special district) | B9: 2
A10: registry: irrigation mutual | B10: 4
A11: registry: mutual, no PWSID, purpose not stated | B11: 3
A12: registry: retail mutual | B12: 179
A13: registry: wholesale mutual | B13: 2
