Workbook

Sheet Summary
A1: Cayucos Beach Mutual Water Company
A2: Financial Summary - multi-year overview (USD)
A3: Entity ID: cawc_0043 | Fiscal year ends December 31.
A5: Presentation standard: every figure on the statement tabs is verified to its source filing and shown clean. A cell the filing does not report reads "not reported" (never estimated, never guessed).
A6: Citations, confidence tiers, and the filed-vs-computed tie-out checks live on the "Sources & audit" tab, keyed by cell, so every number is fully traceable without cluttering the statements. These pages are ready to use as filed.
A8: Metric | B8: FY2020 | C8: FY2021 | D8: FY2022 | E8: FY2023 | F8: FY2024
A9: Operating results (USD)
A10: Total revenue | B10: 980610 | C10: 1109551 | D10: 964784 | E10: 1018038 | F10: 1004214
A11: Total expenses | B11: 1189963 | C11: 775589 | D11: 770255 | E11: 997300 | F11: 759232
A12: Net income | B12: -209353 | C12: 333962 | D12: 194529 | E12: 20738 | F12: 244982
A14: Financial position (USD, end of year)
A15: Total assets | B15: 2502828 | C15: 2836051 | D15: 3041964 | E15: 3055112 | F15: 3298366
A16: Total liabilities | B16: 739 | C16: 0 | D16: 11384 | E16: 3794 | F16: 2066
A17: Net assets | B17: 2502089 | C17: 2836051 | D17: 3030580 | E17: 3051318 | F17: 3296300
A19: Headline ratios
A20: Operating margin | B20: -0.21349262 | C20: 0.30098842 | D20: 0.20162959 | E20: 0.020370556 | F20: 0.24395398
A21: Revenue growth (YoY) | B21: 0.045495544 | C21: 0.1314906 | D21: -0.1304735 | E21: 0.055197847 | F21: -0.013579061
A22: Return on assets | B22: -0.083646579 | C22: 0.11775599 | D22: 0.063948489 | E22: 0.0067879672 | F22: 0.074273746
A24: Figures as reported in source filings (full provenance on the Sources & audit tab). Parentheses denote negatives; ratios are computed upstream in financials_annual.

Sheet Notes
A1: Notes
A2: Human annotations from the versioned store (data/notes/). Annotations only: they never change a reported figure or a confidence tier.
A4: Date | B4: Tag | C4: Author | D4: Note
A5: No notes recorded yet.

Sheet Financial Statements
A1: Cayucos Beach Mutual Water Company
A2: Financial Statements - income statement, balance sheet, cash flow, member income test (USD)
A3: Entity ID: cawc_0043 | Fiscal year ends December 31.
A5: INCOME STATEMENT - as reported (USD)
A6: Line item | B6: FY2020 | C6: FY2021 | D6: FY2022 | E6: FY2023 | F6: FY2024
A7: Revenue
A8: Program service revenue | B8: 908135 | C8: 1048347 | D8: 915129 | E8: 925297 | F8: 886656
A9: Investment income | B9: 16600 | C9: 5329 | D9: -1162 | E9: 41141 | F9: 60858
A10: Net rental income | B10: 55875 | C10: 55875 | D10: 50817 | E10: 51600 | F10: 56700
A11: Net gain/(loss) on investment sales | B11: 0 | C11: 0 | D11: 0 | E11: 0 | F11: 0
A12: Other revenue | B12: 0 | C12: 0 | D12: 0 | E12: 0 | F12: 0
A13: Contributions & grants | B13: 0 | C13: 0 | D13: 0 | E13: 0 | F13: 0
A14: Total revenue | B14: 980610 | C14: 1109551 | D14: 964784 | E14: 1018038 | F14: 1004214
A16: Expenses
A17: Depreciation | B17: 158275 | C17: 153869 | D17: 144693 | E17: 136726 | F17: 123516
A18: Interest expense | B18: 0 | C18: 0 | D18: 0 | E18: 0 | F18: 0
A19: Total expenses | B19: 1189963 | C19: 775589 | D19: 770255 | E19: 997300 | F19: 759232
A21: Net income | B21: -209353 | C21: 333962 | D21: 194529 | E21: 20738 | F21: 244982
A24: BALANCE SHEET - as reported (USD, end of year)
A25: Line item | B25: FY2020 | C25: FY2021 | D25: FY2022 | E25: FY2023 | F25: FY2024
A26: Assets
A27: Cash | B27: 1145438 | C27: 1283976 | D27: 516192 | E27: 539461 | F27: 792966
A28: Savings & temporary investments | B28: 0 | C28: 0 | D28: 998838 | E28: 1039979 | F28: 1121328
A29: Accounts receivable | B29: 0 | C29: 0 | D29: 0 | E29: 0 | F29: 0
A30: Inventories | B30: 0 | C30: 0 | D30: 0 | E30: 0 | F30: 0
A31: Prepaid expenses | B31: 0 | C31: 1005 | D31: 1029 | E31: 0 | F31: 0
A32: Property, plant & equipment (gross) | B32: 4122674 | C32: 4470223 | D32: 4589751 | E32: 4676242 | F32: 4708160
A33: Less: accumulated depreciation | B33: -2765922 | C33: -2919791 | D33: -3064484 | E33: -3201209 | F33: -3324726
A34: Net property, plant & equipment | B34: 1356752 | C34: 1550432 | D34: 1525267 | E34: 1475033 | F34: 1383434
A35: Total assets | B35: 2502828 | C35: 2836051 | D35: 3041964 | E35: 3055112 | F35: 3298366
A37: Liabilities
A38: Accounts payable | B38: 739 | E38: 3794 | F38: 2066
A39: Mortgages & notes payable
A40: Total liabilities | B40: 739 | C40: 0 | D40: 11384 | E40: 3794 | F40: 2066
A42: Net Assets / Equity
A43: Capital stock
A44: Paid-in capital | B44: 64744 | C44: 64744 | D44: 64744 | E44: 64744 | F44: 64744
A45: Retained earnings | B45: 2437345 | C45: 2771307 | D45: 2965836 | E45: 2986574 | F45: 3231556
A46: Net assets | B46: 2502089 | C46: 2836051 | D46: 3030580 | E46: 3051318 | F46: 3296300
A49: CASH FLOW - derived proxy (USD)
...

Sheet Balance Sheet
A1: Cayucos Beach Mutual Water Company
A2: Balance Sheet - as reported (USD, end of year)
A3: Entity ID: cawc_0043 | Fiscal year ends December 31.
A5: Line item | B5: FY2020 | C5: FY2021 | D5: FY2022 | E5: FY2023 | F5: FY2024
A6: Assets
A7: Cash | B7: 1145438 | C7: 1283976 | D7: 516192 | E7: 539461 | F7: 792966
A8: Savings & temporary investments | B8: 0 | C8: 0 | D8: 998838 | E8: 1039979 | F8: 1121328
A9: Accounts receivable | B9: 0 | C9: 0 | D9: 0 | E9: 0 | F9: 0
A10: Inventories | B10: 0 | C10: 0 | D10: 0 | E10: 0 | F10: 0
A11: Prepaid expenses | B11: 0 | C11: 1005 | D11: 1029 | E11: 0 | F11: 0
A12: Property, plant & equipment (gross) | B12: 4122674 | C12: 4470223 | D12: 4589751 | E12: 4676242 | F12: 4708160
A13: Less: accumulated depreciation | B13: -2765922 | C13: -2919791 | D13: -3064484 | E13: -3201209 | F13: -3324726
A14: Net property, plant & equipment | B14: 1356752 | C14: 1550432 | D14: 1525267 | E14: 1475033 | F14: 1383434
A15: Total assets | B15: 2502828 | C15: 2836051 | D15: 3041964 | E15: 3055112 | F15: 3298366
A17: Liabilities
A18: Accounts payable | B18: 739 | E18: 3794 | F18: 2066
A19: Mortgages & notes payable
A20: Total liabilities | B20: 739 | C20: 0 | D20: 11384 | E20: 3794 | F20: 2066
A22: Net Assets / Equity
A23: Capital stock
A24: Paid-in capital | B24: 64744 | C24: 64744 | D24: 64744 | E24: 64744 | F24: 64744
A25: Retained earnings | B25: 2437345 | C25: 2771307 | D25: 2965836 | E25: 2986574 | F25: 3231556
A26: Net assets | B26: 2502089 | C26: 2836051 | D26: 3030580 | E26: 3051318 | F26: 3296300
A28: Balance check (assets − liab. − net assets) | B28: 0 | C28: 0 | D28: 0 | E28: 0 | F28: 0
A30: Net PP&E is the reported ppe_net column (gross less accumulated depreciation). The balance check should be ~0 where all three totals are reported; a non-zero value flags a reporting or extraction discrepancy worth reviewing.

Sheet Officers & contractors
A1: Cayucos Beach Mutual Water Company
A2: Officers, Directors & Contractors - Form 990 Part VII (FY2024; USD)
A3: Entity ID: cawc_0043 | Fiscal year ends December 31.
A5: Section A - Officers, directors, trustees, key employees
A6: Name | B6: Title | C6: Reportable comp (org) | D6: Reportable comp (related) | E6: Other comp | F6: Total compensation
A7: JONELLE MCALLISTER | B7: Director | C7: 0 | D7: 0 | E7: 0 | F7: 0
A8: DOUGLAS LAUNCHBAUGH | B8: President | C8: 0 | D8: 0 | E8: 0 | F8: 0
A9: LOUISA SMITH | B9: Director | C9: 0 | D9: 0 | E9: 0 | F9: 0
A10: EDWARD MUSOLFF | B10: Secretary | C10: 0 | D10: 0 | E10: 0 | F10: 0
A11: DOUG HENDRY | B11: Vice President | C11: 0 | D11: 0 | E11: 0 | F11: 0
A13: Section B - Independent contractors (over $100,000)
A14: Contractor | B14: Services | C14: Compensation
A16: Section A lists every officer, director, trustee and key employee filed for the latest year; the two with the highest total compensation are highlighted. Total compensation is computed (reportable org + related + other). Section B lists each independent contractor paid over $100,000; the return reports 0 such contractor(s). Source and confidence for every figure are on the Sources & audit tab.

Sheet Revenue (detail)
A1: Cayucos Beach Mutual Water Company
A2: Revenue - Form 990 Part VIII (USD)
A3: Entity ID: cawc_0043 | Fiscal year ends December 31.
A5: Part VIII line | B5: FY2020 | C5: FY2021 | D5: FY2022 | E5: FY2023 | F5: FY2024
A6: Revenue by category
A7: 1h. Total contributions, gifts, grants | B7: 0 | C7: 0 | D7: 0 | E7: 0 | F7: 0
A8: 2g. Total program service revenue | B8: 908135 | C8: 1048347 | D8: 915129 | E8: 925297 | F8: 886656
A9: 3. Investment income | B9: 16600 | C9: 5329 | D9: -1162 | E9: 41141 | F9: 60858
A10: 6d. Net rental income | B10: 55875 | C10: 55875 | D10: 50817 | E10: 51600 | F10: 56700
A11: 7d. Net gain/(loss) from investment sales | B11: 0 | C11: 0 | D11: 0 | E11: 0 | F11: 0
A12: 11e. Other revenue | B12: 0 | C12: 0 | D12: 0 | E12: 0 | F12: 0
A13: 12. Total revenue | B13: =SUM(B7:B12) | C13: =SUM(C7:C12) | D13: =SUM(D7:D12) | E13: =SUM(E7:E12) | F13: =SUM(F7:F12)
A15: Program service revenue detail - FY2024 (lines 2a-2f)
A16: Description | B16: Business code | C16: Total revenue
A17: MISCELLANEOUS | C17: 3245
A18: PENALTIES | C18: 2959
A19: UPGRADES | C19: 15560
A20: WATER SALES | B20: 221000 | C20: 859681
A21: WILL SERVE APPLICATIONS | C21: 3400
A22: Revenue category subtotals are as filed. Total revenue (line 12) is a live SUM of the category cells above; its tie-out to the filed total is on the Sources & audit tab. Program service revenue detail is shown for the latest year, with its sum-to-line-2g check on that same audit tab.

Sheet Operating expenses (detail)
A1: Cayucos Beach Mutual Water Company
A2: Statement of Functional Expenses - Form 990 Part IX (USD)
A3: Entity ID: cawc_0043 | Fiscal year ends December 31.
A5: Part IX line (column A Total) | B5: FY2020 | C5: FY2021 | D5: FY2022 | E5: FY2023 | F5: FY2024
A6: Functional expenses, column A Total - by year
A7: 1. Grants to domestic organizations and governments | B7: 0 | C7: 0 | D7: 0 | E7: 0 | F7: 0
A8: 2. Grants to domestic individuals | B8: 0 | C8: 0 | D8: 0 | E8: 0 | F8: 0
A9: 3. Grants to foreign organizations and individuals | B9: 0 | C9: 0 | D9: 0 | E9: 0 | F9: 0
A10: 4. Benefits paid to or for members | B10: 0 | C10: 0 | D10: 0 | E10: 0 | F10: 0
A11: 5. Compensation of current officers, directors, trustees | B11: 4700 | C11: 4400 | D11: 3700 | E11: 4150 | F11: 4100
A12: 6. Compensation to disqualified persons | B12: 0 | C12: 0 | D12: 0 | E12: 0 | F12: 0
A13: 7. Other salaries and wages | B13: 0 | C13: 0 | D13: 0 | E13: 0 | F13: 0
A14: 8. Pension plan accruals and contributions | B14: 0 | C14: 0 | D14: 0 | E14: 0 | F14: 0
A15: 9. Other employee benefits | B15: 0 | C15: 0 | D15: 0 | E15: 0 | F15: 0
A16: 10. Payroll taxes | B16: 0 | C16: 0 | D16: 0 | E16: 0 | F16: 0
A17: 11a. Fees for services: management | B17: 0 | C17: 0 | D17: 0 | E17: 0 | F17: 0
A18: 11b. Fees for services: legal | B18: 0 | C18: 0 | D18: 307 | E18: 90 | F18: 2768
... A36: 24. OPERATING LEASE | B36: 828852 | C36: 326067 | D36: 380935 | E36: 374624 | F36: 385255
A37: 24. OVERHEAD | B37: 132338 | C37: not reported | D37: not reported | E37: not reported | F37: not reported
A38: 24. REPAIRS & MAINTENANCE | B38: 10669 | C38: 21418 | D38: 30476 | E38: 255515 | F38: 11616
A39: 24. DUES AND SUBSCRIPTIONS | B39: 7860 | C39: not reported | D39: not reported | E39: not reported | F39: not reported
A40: 24. CONTRACT LABOR | B40: not reported | C40: 175950 | D40: 138740 | E40: 148390 | F40: 149436
A41: 24. MISCELLANEOUS | B41: not reported | C41: 44581 | D41: 20499 | E41: 17354 | F41: 26031
A42: 24e. All other expenses | B42: 28923 | C42: 27757 | D42: 26611 | E42: 33100 | F42: 30333
A43: 25. Total functional expenses | B43: =SUM(B7:B42) | C43: =SUM(C7:C42) | D43: =SUM(D7:D42) | E43: =SUM(E7:E42) | F43: =SUM(F7:F42)
A45: Functional column split - FY2024 (col A = B + C + D)
A46: Part IX line | B46: A. Total | C46: B. Program services | D46: C. Management & general | E46: D. Fundraising
A47: 1. Grants to domestic organizations and governments | B47: 0
A48: 2. Grants to domestic individuals | B48: 0
A49: 3. Grants to foreign organizations and individuals | B49: 0
A50: 4. Benefits paid to or for members | B50: 0
A51: 5. Compensation of current officers, directors, trustees | B51: 4100 | C51: 4100
A52: 6. Compensation to disqualified persons | B52: 0
A53: 7. Other salaries and wages | B53: 0
A54: 8. Pension plan accruals and contributions | B54: 0
A55: 9. Other employee benefits | B55: 0
A56: 10. Payroll taxes | B56: 0
A57: 11a. Fees for services: management | B57: 0
A58: 11b. Fees for services: legal | B58: 2768 | C58: 2768
A59: 11c. Fees for services: accounting | B59: 3975 | C59: 3975
...

Sheet Balance sheet (detail)
A1: Cayucos Beach Mutual Water Company
A2: Balance Sheet - Form 990 Part X (end of year, USD)
A3: Entity ID: cawc_0043 | Fiscal year ends December 31.
A5: Part X line (column B, EOY) | B5: FY2020 | C5: FY2021 | D5: FY2022 | E5: FY2023 | F5: FY2024
A6: Assets
A7: 1. Cash - non-interest-bearing | B7: 1145438 | C7: 1283976 | D7: 516192 | E7: 539461 | F7: 792966
A8: 2. Savings and temporary cash investments | B8: 0 | C8: 0 | D8: 998838 | E8: 1039979 | F8: 1121328
A9: 3. Pledges and grants receivable, net | B9: 0 | C9: 0 | D9: 0 | E9: 0 | F9: 0
A10: 4. Accounts receivable, net | B10: 0 | C10: 0 | D10: 0 | E10: 0 | F10: 0
A11: 5. Receivables from officers/directors/trustees | B11: 0 | C11: 0 | D11: 0 | E11: 0 | F11: 0
A12: 6. Receivables from disqualified persons | B12: 0 | C12: 0 | D12: 0 | E12: 0 | F12: 0
A13: 7. Notes and loans receivable, net | B13: 0 | C13: 0 | D13: 0 | E13: 0 | F13: 0
A14: 8. Inventories for sale or use | B14: 0 | C14: 0 | D14: 0 | E14: 0 | F14: 0
A15: 9. Prepaid expenses and deferred charges | B15: 0 | C15: 1005 | D15: 1029 | E15: 0 | F15: 0
A16: 10c. Land, buildings, and equipment, net | B16: 1356752 | C16: 1550432 | D16: 1525267 | E16: 1475033 | F16: 1383434
A17: 11. Investments - publicly traded securities | B17: 0 | C17: 0 | D17: 0 | E17: 0 | F17: 0
A18: 12. Investments - other securities | B18: 0 | C18: 0 | D18: 0 | E18: 0 | F18: 0
... A21: 15. Other assets | B21: 638 | C21: 638 | D21: 638 | E21: 639 | F21: 638
A22: 16. Total assets | B22: =SUM(B7:B21) | C22: =SUM(C7:C21) | D22: =SUM(D7:D21) | E22: =SUM(E7:E21) | F22: =SUM(F7:F21)
A24: Liabilities
A25: 17. Accounts payable and accrued expenses | B25: 739 | C25: not reported | D25: not reported | E25: 3794 | F25: 2066
A26: 25. Other liabilities | B26: not reported | C26: not reported | D26: 11384 | E26: not reported | F26: not reported
A27: 26. Total liabilities | B27: =SUM(B25:B26) | C27: =SUM(C25:C26) | D27: =SUM(D25:D26) | E27: =SUM(E25:E26) | F27: =SUM(F25:F26)
A29: Net assets / fund balances
A30: 30. Paid-in or capital surplus | B30: 64744 | C30: 64744 | D30: 64744 | E30: 64744 | F30: 64744
A31: 31. Retained earnings / accumulated funds | B31: 2437345 | C31: 2771307 | D31: 2965836 | E31: 2986574 | F31: 3231556
A32: 32. Total net assets / fund balances | B32: =SUM(B30:B31) | C32: =SUM(C30:C31) | D32: =SUM(D30:D31) | E32: =SUM(E30:E31) | F32: =SUM(F30:F31)
A34: Every Part X line is end-of-year (column B), as filed. Section totals (lines 16 / 26 / 32) are live SUMs of the lines above; their tie-outs and the balance-sheet identity (16 = 26 + 32) are on the Sources & audit tab. This filer files as a non-FASB mutual, so net assets sit on lines 29-31 (capital stock / paid-in capital / retained earnings); lines this filer does not report are omitted. Lines 10a/10b net into line 10c (shown).

Sheet Net-assets reconciliation
A1: Cayucos Beach Mutual Water Company
A2: Reconciliation of Net Assets - Form 990 Part XI (USD)
A3: Entity ID: cawc_0043 | Fiscal year ends December 31.
A5: Part XI line | B5: FY2020 | C5: FY2021 | D5: FY2022 | E5: FY2023 | F5: FY2024
A6: Reconciliation
A7: 4. Net assets, beginning of year | B7: 2711442 | C7: 2502089 | D7: 2836051 | E7: 3030580 | F7: 3051318
A8: 3. Revenue less expenses | B8: -209353 | C8: 333962 | D8: 194529 | E8: 20738 | F8: 244982
A9: 8. Prior period adjustments | B9: not reported | C9: not reported | D9: not reported | E9: not reported | F9: not reported
A10: 9. Other changes in net assets | B10: not reported | C10: not reported | D10: not reported | E10: not reported | F10: not reported
A11: 10. Net assets, end of year | B11: =SUM(B7,B8,B9,B10) | C11: =SUM(C7,C8,C9,C10) | D11: =SUM(D7,D8,D9,D10) | E11: =SUM(E7,E8,E9,E10) | F11: =SUM(F7,F8,F9,F10)
A13: Part XI reconciles beginning to ending net assets. Ending net assets (line 10) is a live formula: beginning balance (line 4) + revenue less expenses (line 3) + prior-period adjustments (8) + other changes (9). Its tie-out to the filed line 10 (and to Part X line 32) is on the Sources & audit tab. Lines 5-7 (unrealized gains, donated services, investment expenses) are not filed by this entity.

Sheet Cash flow proxies
A1: Cayucos Beach Mutual Water Company
A2: Cash Flow Proxies - derived (USD)
A3: Entity ID: cawc_0043 | Fiscal year ends December 31.
A5: PROXY ONLY. The source filings contain no statement of cash flows. Lines below are derived from the reported income statement and year-over-year balance-sheet changes; treat as directional estimates, not GAAP cash flows. The earliest year has no prior period, so its delta cells are blank.
A7: Proxy line (USD) | B7: FY2020 | C7: FY2021 | D7: FY2022 | E7: FY2023 | F7: FY2024
A8: Operating
A9: Net income | B9: -209353 | C9: 333962 | D9: 194529 | E9: 20738 | F9: 244982
A10: + Depreciation (reported) | B10: 158275 | C10: 153869 | D10: 144693 | E10: 136726 | F10: 123516
A11: − Δ Accounts receivable | C11: 0 | D11: 0 | E11: 0 | F11: 0
A12: − Δ Inventories | C12: 0 | D12: 0 | E12: 0 | F12: 0
A13: − Δ Prepaid expenses | C13: -1005 | D13: -24 | E13: 1029 | F13: 0
A14: + Δ Accounts payable | F14: -1728
A15: Operating cash flow proxy | C15: 486826 | D15: 339198 | E15: 158493 | F15: 366770
A17: Investing
A18: − Δ PP&E gross (capex proxy) | C18: -347549 | D18: -119528 | E18: -86491 | F18: -31918
A20: Financing
A21: Δ Mortgages & notes payable
A23: Reconciliation
A24: Δ Cash + temp. investments (actual) | C24: 138538 | D24: 231054 | E24: 64410 | F24: 334854
A26: The capex proxy assumes gross PP&E rises only via capital spending (it ignores disposals). 'Δ Cash + temp. investments (actual)' is the real reported change in liquid funds and is the most reliable line here; the operating/investing/financing proxies will not perfectly reconcile to it.

Sheet Ratios
A1: Cayucos Beach Mutual Water Company
A2: Financial Ratios
A3: Entity ID: cawc_0043 | Fiscal year ends December 31.
A5: Ratio | B5: FY2020 | C5: FY2021 | D5: FY2022 | E5: FY2023 | F5: FY2024
A6: Profitability (computed upstream)
A7: Operating margin (NI / revenue) | B7: -0.21349262 | C7: 0.30098842 | D7: 0.20162959 | E7: 0.020370556 | F7: 0.24395398
A8: Expense ratio (expenses / revenue) | B8: 1.2134926 | C8: 0.69901158 | D8: 0.79837041 | E8: 0.97962944 | F8: 0.75604602
A9: Return on assets (NI / assets) | B9: -0.083646579 | C9: 0.11775599 | D9: 0.063948489 | E9: 0.0067879672 | F9: 0.074273746
A10: Revenue growth (YoY) | B10: 0.045495544 | C10: 0.1314906 | D10: -0.1304735 | E10: 0.055197847 | F10: -0.013579061
A12: Leverage & solvency
A13: Debt-to-assets (liab. / assets) | B13: 0.000295266 | C13: 0 | D13: 0.0037423191 | E13: 0.001241853 | F13: 0.00062637075
A14: Equity ratio (net assets / assets) | B14: 0.99970473 | C14: 1 | D14: 0.99625768 | E14: 0.99875815 | F14: 0.99937363
A16: Liquidity & asset profile (derived here)
A17: Current ratio (current assets / AP) | B17: 1549.9838 | E17: 416.29942 | F17: 926.57018
A18: Cash ratio ((cash+temp inv.) / total liab.) | B18: 1549.9838 | D18: 133.08415 | E18: 416.29942 | F18: 926.57018
A19: Asset age proxy (accum. deprec. / gross PP&E) | B19: 0.67090485 | C19: 0.65316451 | D19: 0.66767979 | E19: 0.68456872 | F19: 0.70616249
A21: Upstream ratios are read from financials_annual; derived ratios are computed only where inputs are reported. Current ratio uses accounts payable as the current-liability proxy (the filings do not split current vs. long-term liabilities). Asset age proxy: a higher % implies older / more depreciated infrastructure.

Sheet Unit economics
A1: Cayucos Beach Mutual Water Company
A2: Unit economics - per-customer revenue by category (USD)
A3: Entity ID: cawc_0043 | Fiscal year ends December 31.
A5: Every metric here is PER CUSTOMER (a metered service connection). It is not a per-member figure; the member (shareholder) count is a different denominator, shown in the denominator block. The visible cell shows the value and its classification; the numerator, denominator, formula, and rationale are in each metric's LOGIC popup.
A6: Per-customer denominator (service connections) | B6: 778 | C6: State Water Board eAR Section 4 (CurTotalConnections), reporting year 2024
A7: Total annual revenue (eAR Section 8b B1.8) | B7: 950417 | C7: State Water Board eAR Section 8b, question B1.8 (total annual revenue), reporting year 2024
A8: Primary source | C8: State Water Board eAR Section 8b (revenue by rate/fee), reporting year 2024
A10: Revenue categories (value, classification, per customer, share)
A11: Revenue category | B11: Classification | C11: Value (USD) | D11: Per customer | E11: Share of revenue
A12: Water sales revenue | B12: DIRECT | C12: 859003 | D12: 1104.12 | E12: 0.9038
A13: Assessment revenue (990 program-service revenue not matched to eAR water-rate revenue) | B13: DERIVED | C13: 27653 | D13: 35.54 | E13: 0.0312
A14: Meter revenue | B14: not reported | C14: not reported | D14: not reported | E14: not reported
A15: Overage or tiered penalty revenue | B15: not reported | C15: not reported | D15: not reported | E15: not reported
A17: Water sales revenue - DIRECT
A18: Revenue customers paid for water service, read straight off the filed eAR Section 8b water-rate line. A DIRECT filed figure, not computed by us.
A19: Numerator: Water rate revenue | B19: 859003 | C19: eAR Section 8b field B1.1 (residential water rates) + B1.2 (non-residential water rates). State Water Board eAR Section 8b, question B1.1 + B1.2 (revenue from water rates), reporting year 2024
A20: Denominator: Total service connections | B20: 778 | C20: eAR Section 4 CurTotalConnections, reporting year 2024. State Water Board eAR Section 4 (CurTotalConnections), reporting year 2024
A21: Per customer: water rate revenue $859,003 / 778 connections = $1,104.12 per connection
A22: Share of revenue: water rate revenue $859,003 / total annual revenue (eAR Section 8b B1.8) $950,417 = 90.38%
A23: Period treatment: Numerator (eAR Section 8b, the calendar year 2024) and denominator (eAR Section 4 connections reported in the same eAR filing) are both the eAR reporting year 2024, so the two sides are bound to the same reporting year.
A24: Rationale: Dividing water-rate revenue by the number of metered service connections gives the average revenue per customer; dividing by total annual revenue shows how much of the system's income comes from water rates.
A26: Assessment revenue (990 program-service revenue not matched to eAR water-rate revenue) - DERIVED
A27: A DERIVED residual (medium confidence): the part of the Form 990 program-service revenue that is not matched by the eAR water-rate revenue for the same period. Computed by us, not a filed line.
A28: Input A: Form 990 program-service revenue | B28: 886656 | C28: Form 990 Part VIII line 2 (total program-service revenue), fiscal year 2024 ending December 31, 2024
A29: Input B: eAR water-rate revenue | B29: 859003 | C29: State Water Board eAR Section 8b, question B1.1 + B1.2 (revenue from water rates), reporting year 2024
A30: Residual (A minus B) = assessment revenue | B30: =B28-B29 | C30: $886,656 (990 program-service revenue) minus $859,003 (eAR water-rate revenue) = $27,653
A31: Period alignment: Both inputs cover the same period: the eAR Section 8b is the calendar year 2024 and the Form 990 fiscal year 2024 ends December 31, 2024, so the residual is period-aligned.
A32: What it IS: revenue the system booked as program service on its 990 that is not accounted for by the eAR water-rate line, plausibly member assessments and other service revenue.
A33: This residual is a difference between two sources for the same period; it is not a separately filed assessment line and may include other unmatched revenue.
A34: Denominator: Total service connections | B34: 778 | C34: eAR Section 4 CurTotalConnections, reporting year 2024. State Water Board eAR Section 4 (CurTotalConnections), reporting year 2024
A35: Per customer: residual $27,653 / 778 connections = $35.54 per connection
A36: Share of revenue: residual $27,653 / 990 program-service revenue $886,656 = 3.12%
A38: Meter revenue - not reported
A39: Not reported. This category is not built because doing so would double-count.
A40: Reason: The eAR Section 8a reports a base/meter rate PRICE, but the filing carries no meter revenue line and no tier volume, and the base charge is already inside the water-sales revenue (eAR Section 8b water rates). Building a separate meter figure would double-count. Not backed into from a total.
A42: Overage or tiered penalty revenue - not reported
A43: Not reported. This category is not built because doing so would double-count.
A44: Reason: The eAR Section 8a reports tiered/overage rate PRICES, but the filing carries no overage revenue and no tier consumption volume, and any overage billed is already inside the water-sales revenue. Building it would double-count. Not backed into from a total.

Sheet Rate structure
A1: Cayucos Beach Mutual Water Company
A2: Rate structure and representative bill - eAR Section 8a (RY2024)
A3: Entity ID: cawc_0043 | Fiscal year ends December 31.
A5: This block is a rate-schedule illustration at defined usage levels. It is NOT billed revenue and not a claim about any real customer's usage. The revenue side of unit economics is the separate Unit Economics block.
A6: Structure: Tiered increasing-block with a fixed base, billed bimonthly, priced per Thousand Gallons.
A7: Defined single-family usage levels, identical for every company so the bill is comparable: Low = 5 HCF/month (~125 gallons/day); Median = 10 HCF/month (~249 gallons/day); High = 25 HCF/month (~623 gallons/day). 1 HCF = 748 gallons, and 1 thousand gallons = 1,000 gallons. The usage is converted into the company's own filed unit before the filed tiers are applied, and the bill is stated as a monthly equivalent: a bimonthly structure is computed at twice the monthly usage and divided by two, and any other billing period the same way with its factor stated. These are an illustration, not a measured usage for any real customer.
A9: Defined usage levels (EDITABLE - change a yellow cell to move the bill)
B10: Low | C10: Median | D10: High
A11: Defined usage level (HCF per month) | B11: 5 | C11: 10 | D11: 25
A12: Conversion: one HCF is this many Thousand Gallons | B12: 0.748 | C12: 1 HCF = 748 gallons
A13: Monthly usage (Thousand Gallons) | B13: =B11*$B$12 | C13: =C11*$B$12 | D13: =D11*$B$12
A14: Months per bill (from filed billing frequency) | B14: 2 | C14: bimonthly biller
A16: Filed rate table - single-family residential (as filed, eAR Section 8a)
A17: Base / fixed charge per bimonthly bill ($) | B17: 40
A18: Tier | B18: Range (Thousand Gallons) | C18: Price ($/Thousand Gallons) | D18: Upper limit (Thousand Gallons)
A19: Tier 1 | B19: 0 to 1000 Thousand Gallons | C19: 13.36 | D19: 1000
A20: Tier 2 | B20: over 1000 Thousand Gallons | C20: 13.36 | D20: no limit
A22: Representative monthly bill - LIVE (edit a yellow usage cell to recompute)
B23: Low | C23: Median | D23: High
A24: Usage per bill (Thousand Gallons) | B24: =B13*$B$14 | C24: =C13*$B$14 | D24: =D13*$B$14
A25: Tier 1 charge per bill ($) | B25: =$C$19*MAX(0,MIN(B24,$D$19)-0) | C25: =$C$19*MAX(0,MIN(C24,$D$19)-0) | D25: =$C$19*MAX(0,MIN(D24,$D$19)-0)
A26: Tier 2 charge per bill ($) | B26: =$C$20*MAX(0,B24-$D$19) | C26: =$C$20*MAX(0,C24-$D$19) | D26: =$C$20*MAX(0,D24-$D$19)
A27: Volumetric charge per bill ($) | B27: =SUM(B25,B26) | C27: =SUM(C25,C26) | D27: =SUM(D25,D26)
A28: Base charge per bill ($) | B28: =$B$17 | C28: =$B$17 | D28: =$B$17
A29: Total per bill ($) | B29: =B28+B27 | C29: =C28+C27 | D29: =D28+D27
A30: Total per MONTH ($) | B30: =B29/$B$14 | C30: =C29/$B$14 | D30: =D29/$B$14
A31: Fixed per month ($) | B31: =$B$17/$B$14 | C31: =$B$17/$B$14 | D31: =$B$17/$B$14
A32: Volumetric per month ($) | B32: =B27/$B$14 | C32: =C27/$B$14 | D32: =D27/$B$14
A33: Effective price ($/HCF) | B33: =IF(B11=0,"",B30/B11) | C33: =IF(C11=0,"",C30/C11) | D33: =IF(D11=0,"",D30/D11)
A35: Rate-structure comparison metrics
A36: Fixed share of the bill at median usage | B36: =C31/C30 | C36: fixed / total at 10 HCF/month
A37: Tier price ratio (highest to lowest positive tier) | B37: =$C$19/$C$19 | C37: highest filed tier price divided by lowest filed tier price.
A38: Rate structure (as filed) | B38: tiered (Variable Base)
A40: Flagged (carried as filed, never reconciled)
A41: The single-family base charge or tier thresholds filed for RY2024 differ from RY2023, yet the eAR answer to whether rates changed is "No". Carried exactly as filed; both years are preserved and the difference is surfaced, never reconciled.
A42: RY2023: base $80.00, tier upper thresholds [1.0, None]. RY2024: base $40.00, tier upper thresholds [1000.0, None].
A43: State Water Board eAR Section 8a (Customer Charges), single- and multi-family residential charges grid, reporting year 2024. Rate structure only; no revenue.

Sheet eAR revenue & expenses
A1: Cayucos Beach Mutual Water Company
A2: eAR annual revenue and expenses - State Water Board eAR Section 8b (USD)
A3: Entity ID: cawc_0043 | Fiscal year ends December 31.
A5: The water system's own annual figures from the public eAR Section 8b, on the calendar year 2024 the filer self-reported (B0.1/B0.2). Shown beside the period-aligned Form 990 with the variance flagged: a different source (a State Water Board self-report vs an IRS filing). Preserved as filed, never reconciled.
A6: Reporting period basis (self-reported) | B6: calendar year 2024 | C6: eAR Section 8b B0.1 (WRFinancialReportingPeriod)
A8: Revenue (eAR Section 8b, questions B1.x)
A9: Line | B9: Amount (USD) | C9: Citation
A10: Water rate revenue | B10: 859003 | C10: State Water Board eAR Section 8b, question B1.1 + B1.2 (revenue from water rates), reporting year 2024
A11: Other fees and charges | B11: 35514 | C11: State Water Board eAR Section 8b, question B1.3 + B1.4 (revenue from other fees), reporting year 2024
A12: Non-customer revenue | B12: 55900 | C12: State Water Board eAR Section 8b, question B1.7 (grants, interest, and other non-customer), reporting year 2024
A13: Total annual revenue | B13: 950417 | C13: State Water Board eAR Section 8b, question B1.8 (total annual revenue for the reporting year), reporting year 2024
A15: Expenses (eAR Section 8b, questions B2.x)
A16: Line | B16: Amount (USD) | C16: Citation
A17: Operations and maintenance | B17: 634089 | C17: State Water Board eAR Section 8b, question B2.1 (annual O and M expense), reporting year 2024
A18: Capital | B18: 3355 | C18: State Water Board eAR Section 8b, question B2.2 (annual expenses from investing or capital), reporting year 2024
A19: Financing | B19: 0 | C19: State Water Board eAR Section 8b, question B2.3 (annual expenses from financing), reporting year 2024
A20: Other | B20: 0 | C20: State Water Board eAR Section 8b, question B2.4 (total other annual expenses), reporting year 2024
A21: Total annual expenses | B21: 637444 | C21: State Water Board eAR Section 8b, question B2.5 (total annual expenses), reporting year 2024
A23: Period-aligned Form 990 comparison (variance surfaced, never reconciled)
A24: Measure | B24: eAR Section 8b | C24: Form 990
A25: total revenue | B25: 950417 | C25: 1004214
A26: Variance (eAR minus Form 990) | B26: =B25-C25
A27: The eAR Section 8b total revenue (State Water Board self-report, calendar year 2024) and the Form 990 total revenue (IRS filing) are a different source and cover the same calendar year 2024. Both are carried as filed; the variance is surfaced, never reconciled.
A28: total expenses | B28: 637444 | C28: 759232
A29: Variance (eAR minus Form 990) | B29: =B28-C28
A30: The eAR Section 8b total expenses (State Water Board self-report, calendar year 2024) and the Form 990 total expenses (IRS filing) are a different source and cover the same calendar year 2024. Both are carried as filed; the variance is surfaced, never reconciled.

Sheet Denominators & alignment
A1: Cayucos Beach Mutual Water Company
A2: Denominators and calendar alignment
A3: Entity ID: cawc_0043 | Fiscal year ends December 31.
A5: System size and water use per fiscal year (the operating denominators that per-customer and per-acre metrics divide by), each cited to file and field. The eAR is reported on the calendar year; the 990 fiscal year differs by company. A calendar-year filer's volume is the eAR annual total (fiscal year = calendar year); an offset filer's is recast by a true monthly sum of the covered calendar months, or read not reported naming the missing months. Point-in-time counts (connections, population) are matched to the closest eAR year and never summed. Every derived figure states its formula and accounting rationale.
A6: Member vs customer (two different denominators, both preserved)
A7: Customer (service connection) | B7: 778 | C7: State Water Board eAR Section 4 (CurTotalConnections), reporting year 2024
A8: Member (shareholder) | C8: No published shareholder count
A9: In a mutual water company a MEMBER is a shareholder who owns part of the system; a CUSTOMER is a metered service connection that receives water. The two diverge because one owner can hold several connections, a connection can serve people who are not owners, and some mutuals attach shares to land by acreage rather than counting heads. Per-customer metrics divide by service connections; per-member metrics divide by shareholders; the two counts are never used interchangeably.
A11: Denominator layer by fiscal year
A12: Fiscal year (end) | B12: Connections | C12: Population | D12: Service-area acres | E12: Water produced (AF) | F12: Water delivered (AF) | G12: Alignment method
A13: FY2020 (2020-12-31) | B13: 783 | C13: not reported | D13: 162.3 | E13: not reported | F13: not reported | G13: eAR annual total, calendar filer, equals fiscal year (not a monthly recast)
A14: FY2021 (2021-12-31) | B14: 783 | C14: not reported | D14: 162.3 | E14: not reported | F14: not reported | G14: eAR annual total, calendar filer, equals fiscal year (not a monthly recast)
A15: FY2022 (2022-12-31) | B15: 778 | C15: not reported | D15: 162.3 | E15: not reported | F15: not reported | G15: eAR annual total, calendar filer, equals fiscal year (not a monthly recast)
A16: FY2023 (2023-12-31) | B16: 778 | C16: 2369 | D16: 162.3 | E16: not reported | F16: not reported | G16: eAR annual total, calendar filer, equals fiscal year (not a monthly recast)
A17: FY2024 (2024-12-31) | B17: 778 | C17: 2369 | D17: 162.3 | E17: not reported | F17: not reported | G17: eAR annual total, calendar filer, equals fiscal year (not a monthly recast)
A19: Connections by class - FY2024 (eAR Section 4)
A20: Single-family residential | B20: 632
A21: Multi-family residential | B21: 91
A22: Commercial and institutional | B22: 47
A23: Landscape irrigation | B23: 8
A24: Agricultural | B24: 0
A25: Monthly-volume source: California open-data portal (data.ca.gov): the separate Produced Water (by month and source) and Delivered Water (by month and connection type) resources, which cover every public water system (not only urban suppliers), one resource per reporting year, matched by exact PWSID. This is the aggregate publication of eAR Section 6.

Sheet Operational metrics
A1: Cayucos Beach Mutual Water Company
A2: Operational metrics - plant per acre, density, terrain
A3: Entity ID: cawc_0043 | Fiscal year ends December 31.
A5: Plant assets per acre
A6: Service-area acres | B6: 162.3 | C6: Geodesic area (WGS84 spherical excess) of the SABL service-area polygon.
A7: Fiscal year | B7: Gross plant per acre (primary) | C7: Net plant per acre
A8: FY2020 | B8: 25401.565 | C8: 8359.5317
A9: FY2021 | B9: 27542.964 | C9: 9552.8774
A10: FY2022 | B10: 28279.427 | C10: 9397.825
A11: FY2023 | B11: 28812.335 | C11: 9088.3118
A12: FY2024 | B12: 29008.996 | C12: 8523.931
A13: Infrastructure built per acre of service area. Gross plant per acre is the primary read because it measures how much plant the system has put in the ground per acre, and unlike net plant it does not fall over time purely because the assets depreciate on the books. Net plant per acre is shown alongside as the depreciated book value per acre.
A14: Formula: gross plant per acre = Form 990 Part X line 10a (land, buildings, and equipment, gross) / SABL service-area acres; net plant per acre uses Part X line 10c (net)
A15: Source lines: Form 990 Part X line 10a (gross) and line 10c (net); Geodesic area (WGS84 spherical excess) of the SABL service-area polygon.
A16: Confidence: medium. This is worked out from filed figures (a ratio, or a year-to-year change), so it is one step removed from the raw numbers.. Filed gross/net plant over the measured SABL service-area acreage.
A18: Connections per acre
A19: Connections per acre | B19: 4.79 | C19: 778 connections / 162.3 acres. CA State Water Board SABL SERVICE_CONNECTIONS; Geodesic area (WGS84 spherical excess) of the SABL service-area polygon.

Sheet Supply & weather
A1: Cayucos Beach Mutual Water Company
A2: Supply and weather indicators (DWR water year)
A3: Entity ID: cawc_0043 | Fiscal year ends December 31.
A5: Reporting calendar: Different reporting periods. The DWR water year runs October 1 to September 30; this system's fiscal year ends December 31, so the two period ends are three months apart. Read the two side by side with that in mind. Neither series is recast: both are reported as filed. A water year is named for the calendar year it ends in, so WY2024 and FY2024 share a number without covering the same twelve months.
A7: Indicator | B7: WY2020 | C7: WY2021 | D7: WY2022 | E7: WY2023 | F7: WY2024
A8: Water-year type (Sacramento Valley) | B8: Dry | C8: Critical | D8: Critical | E8: Wet | F8: Above Normal
A9: Peak drought, San Luis Obispo County | B9: D1 | C9: D4 | D9: D4 | E9: D4 | F9: None (no D0-D4 during the fiscal year)
A10: Precip, percent of normal (8-Station Index) | B10: 63 | C10: 48 | D10: 86 | E10: 133 | F10: 96
A11: Snowpack, April 1 percent of average | B11: 53% | C11: 59% | D11: 38% | E11: 237% | F11: 110%
A12: State Water Project allocation | B12: 20% | C12: 5% | D12: 5% | E12: 100% | F12: 40%

Sheet How this was built
A1: Cayucos Beach Mutual Water Company
A2: How this was built - forensic lineage
A3: Entity ID: cawc_0043 | Fiscal year ends December 31.
A5: A plain account of the forensic lineage behind the hard-to-source metrics: what sources were checked, what was found, what was derived, and what could not be built and why. Every figure marked DERIVED or IMPOSSIBLE above is traceable to a line here.
A7: Water-sales revenue per customer - DIRECT
A8: Sources checked | B8: State Water Board eAR Section 8b (water-rate revenue B1.1/B1.2); State Water Board eAR Section 4 (connection count, same reporting year); audited financial statement (secondary cross-check, where published)
A9: What was found | B9: The eAR Section 8b reports water-rate revenue for reporting year 2024, so this is a DIRECT filed figure; per customer it is divided by the eAR Section 4 connection count for the same reporting year, so numerator and denominator share the year.
A11: Assessment revenue (residual) - DERIVED
A12: Sources checked | B12: Form 990 Part VIII line 2 (program-service revenue); State Water Board eAR Section 8b (water-rate revenue B1.1/B1.2)
A13: What was found | B13: No source separately reports a member assessment, so it is DERIVED as a residual: $886,656 (990 program-service revenue) minus $859,003 (eAR water-rate revenue) = $27,653. Period-aligned; medium confidence.
A14: Caveat | B14: This residual is a difference between two sources for the same period; it is not a separately filed assessment line and may include other unmatched revenue.
A16: Meter revenue - not reported
A17: Sources checked | B17: State Water Board eAR Section 8a (rate prices); State Water Board eAR Section 8b (revenue lines); audited financial statement
A18: What was found | B18: The rate price exists in Section 8a but no revenue or tier volume is reported, and the base charge is already inside water sales.
A19: Caveat | B19: The eAR Section 8a reports a base/meter rate PRICE, but the filing carries no meter revenue line and no tier volume, and the base charge is already inside the water-sales revenue (eAR Section 8b water rates). Building a separate meter figure would double-count. Not backed into from a total.
A21: Overage / tiered-penalty revenue - not reported
A22: Sources checked | B22: State Water Board eAR Section 8a (rate prices); State Water Board eAR Section 8b (revenue lines); audited financial statement
A23: What was found | B23: The rate price exists in Section 8a but no revenue or tier volume is reported, and the base charge is already inside water sales.
A24: Caveat | B24: The eAR Section 8a reports tiered/overage rate PRICES, but the filing carries no overage revenue and no tier consumption volume, and any overage billed is already inside the water-sales revenue. Building it would double-count. Not backed into from a total.
A26: eAR Section 8b reporting-period basis - sourced
A27: Sources checked | B27: eAR Section 8b B0.1 (WRFinancialReportingPeriod); eAR Section 8b B0.2 (WRFiscalYearStartDate)
A28: What was found | B28: The reporting basis (fiscal vs calendar year) is read from the filer's own B0.1/B0.2 answer and staged verbatim, never hardcoded, so the 990 comparison and the residual are period-aligned.
A30: Member (shareholder) count denominator - not reported
A31: Sources checked | B31: Form 990 (no member count stated); company website
A32: What was found | B32: No filing states a member/shareholder count, so the per-member unit economics read not reported rather than borrowing the connection count.
A34: Water volume delivered (acre-feet) - not reported
A35: Sources checked | B35: Form 990 (not in the filing); Consumer Confidence Report; eAR Section 6 (PRA-gated)
A36: What was found | B36: Volume delivered in acre-feet is not in the Form 990 and the CCR states only a source mix, so the per-acre-foot metrics read not reported; the eAR Section 6 is named as the source still needed.

Sheet Sources & audit
A1: Cayucos Beach Mutual Water Company
A2: Sources & audit - full provenance and tie-outs (kept off the statements so they read clean)
A3: Entity ID: cawc_0043 | Fiscal year ends December 31.
A5: Presentation standard: every figure on the statement tabs is verified to its source filing and shown clean. A cell the filing does not report reads "not reported" (never estimated, never guessed).
A6: Citations, confidence tiers, and the filed-vs-computed tie-out checks live on the "Sources & audit" tab, keyed by cell, so every number is fully traceable without cluttering the statements. These pages are ready to use as filed.
A8: A. Filing provenance (one row per staged extraction)
A9: Fiscal year | B9: Period end | C9: Filing type | D9: Confidence | E9: Extraction ID | F9: Object ID | G9: Extracted by | H9: Extracted at | I9: Source URL
A10: FY2020 | B10: 2020-12-31 | C10: 990 | D10: high | E10: f6487562-961e-4dfb-8758-7e1d30d4110c | F10: 202142879349301934 | G10: claude-opus-5 | H10: 2026-09-16T21:34:13+00:00 | I10: https://apps.irs.gov/pub/epostcard/990/xml/2021/2021_TEOS_XML_01A.zip#202142879349301934_public.xml
A11: FY2021 | B11: 2021-12-31 | C11: 990 | D11: high | E11: da73e3aa-835f-4dbc-9585-403838f89fcc | F11: 202213199349326901 | G11: claude-opus-5 | H11: 2026-09-16T21:34:13+00:00 | I11: https://apps.irs.gov/pub/epostcard/990/xml/2022/2022_TEOS_XML_02A.zip#202213199349326901_public.xml
A12: FY2022 | B12: 2022-12-31 | C12: 990 | D12: high | E12: 2ec633b7-0e93-4bc7-8503-365e8f052e23 | F12: 202342239349301239 | G12: claude-opus-5 | H12: 2026-09-16T21:34:13+00:00 | I12: https://apps.irs.gov/pub/epostcard/990/xml/2023/2023_TEOS_XML_08A.zip#202342239349301239_public.xml
A13: FY2023 | B13: 2023-12-31 | C13: 990 | D13: high | E13: a1d3aab1-800a-41e7-93bf-479f57b3a005 | F13: 202400939349301625 | G13: claude-opus-5 | H13: 2026-09-16T21:34:13+00:00 | I13: https://apps.irs.gov/pub/epostcard/990/xml/2024/2024_TEOS_XML_04A.zip#202400939349301625_public.xml
A14: FY2024 | B14: 2024-12-31 | C14: 990 | D14: high | E14: ecfcd59f-ffb0-49ef-b1d3-070a9adbc5c7 | F14: 202541269349302079 | G14: claude-opus-5 | H14: 2026-09-16T21:34:13+00:00 | I14: https://apps.irs.gov/pub/epostcard/990/xml/2025/2025_TEOS_XML_05B.zip#202541269349302079_public.xml
A16: B. Figure citations (every figure on the statement tabs, keyed by cell)
A17: Tab | B17: Cell | C17: Line item | D17: Form 990 line | E17: Key path | F17: Confidence | G17: As filed
A18: Financial Statements | B18: C73 | C18: 11a. Gross income from members or shareholders | D18: 11a | E18: part_v_other_irs_filings.members_and_shareholders_gross_income | F18: high | G18: 1048347
A19: Financial Statements | B19: C74 | C19: 11b. Gross income from other sources | D19: 11b | E19: part_v_other_irs_filings.other_sources_gross_income | F19: high | G19: 61204
A20: Revenue (detail) | B20: B7 | C20: 1h. Total contributions, gifts, grants | D20: 1h | E20: part_viii_revenue.total_contributions | F20: high | G20: 0
A21: Revenue (detail) | B21: C7 | C21: 1h. Total contributions, gifts, grants | D21: 1h | E21: part_viii_revenue.total_contributions | F21: high | G21: 0
A22: Revenue (detail) | B22: D7 | C22: 1h. Total contributions, gifts, grants | D22: 1h | E22: part_viii_revenue.total_contributions | F22: high | G22: 0
A23: Revenue (detail) | B23: E7 | C23: 1h. Total contributions, gifts, grants | D23: 1h | E23: part_viii_revenue.total_contributions | F23: high | G23: 0
A24: Revenue (detail) | B24: F7 | C24: 1h. Total contributions, gifts, grants | D24: 1h | E24: part_viii_revenue.total_contributions | F24: high | G24: 0
A25: Revenue (detail) | B25: B8 | C25: 2g. Total program service revenue | D25: 2g | E25: part_viii_revenue.total_program_service_revenue | F25: high | G25: 908135
A26: Revenue (detail) | B26: C8 | C26: 2g. Total program service revenue | D26: 2g | E26: part_viii_revenue.total_program_service_revenue | F26: high | G26: 1048347
A27: Revenue (detail) | B27: D8 | C27: 2g. Total program service revenue | D27: 2g | E27: part_viii_revenue.total_program_service_revenue | F27: high | G27: 915129
A28: Revenue (detail) | B28: E8 | C28: 2g. Total program service revenue | D28: 2g | E28: part_viii_revenue.total_program_service_revenue | F28: high | G28: 925297
A29: Revenue (detail) | B29: F8 | C29: 2g. Total program service revenue | D29: 2g | E29: part_viii_revenue.total_program_service_revenue | F29: high | G29: 886656
... A298: Net-assets reconciliation | B298: F8 | C298: 3. Revenue less expenses | D298: Part XI line 3 | E298: part_xi_reconciliation.reconciliation_revenue_expenses | F298: high | G298: 244982
A300: C. Tie-out checks (filed vs computed; any nonzero variance is flagged red)
A301: Tab | B301: Check | C301: Fiscal year | D301: Filed | E301: Computed | F301: Variance (computed - filed)
A302: Revenue (detail) | B302: 12. Total revenue | C302: FY2020 | D302: 980610 | E302: ='Revenue (detail)'!B13 | F302: =E302-D302
A303: Revenue (detail) | B303: 12. Total revenue | C303: FY2021 | D303: 1109551 | E303: ='Revenue (detail)'!C13 | F303: =E303-D303
A304: Revenue (detail) | B304: 12. Total revenue | C304: FY2022 | D304: 964784 | E304: ='Revenue (detail)'!D13 | F304: =E304-D304
A305: Revenue (detail) | B305: 12. Total revenue | C305: FY2023 | D305: 1018038 | E305: ='Revenue (detail)'!E13 | F305: =E305-D305
A306: Revenue (detail) | B306: 12. Total revenue | C306: FY2024 | D306: 1004214 | E306: ='Revenue (detail)'!F13 | F306: =E306-D306
A307: Revenue (detail) | B307: 2g program service revenue = sum of lines 2a-2f (FY2024) | C307: FY2024 | D307: 886656 | E307: =SUM('Revenue (detail)'!C17:C21) | F307: =E307-D307
A308: Operating expenses (detail) | B308: 25. Total functional expenses | C308: FY2020 | D308: 1189963 | E308: ='Operating expenses (detail)'!B43 | F308: =E308-D308
A309: Operating expenses (detail) | B309: 25. Total functional expenses | C309: FY2021 | D309: 775589 | E309: ='Operating expenses (detail)'!C43 | F309: =E309-D309
A310: Operating expenses (detail) | B310: 25. Total functional expenses | C310: FY2022 | D310: 770255 | E310: ='Operating expenses (detail)'!D43 | F310: =E310-D310
A311: Operating expenses (detail) | B311: 25. Total functional expenses | C311: FY2023 | D311: 997300 | E311: ='Operating expenses (detail)'!E43 | F311: =E311-D311
A312: Operating expenses (detail) | B312: 25. Total functional expenses | C312: FY2024 | D312: 759232 | E312: ='Operating expenses (detail)'!F43 | F312: =E312-D312
...

Sheet Provenance
A1: Build provenance | B1: Built from source commit d418ffb17485 (2026-10-06); source fingerprint a75a8eee82c65cf7; 192 companies (179 retail mutual, 4 irrigation mutual, 3 mutual, no PWSID, purpose not stated, 2 frozen non-mutual (special district), 2 wholesale mutual, 1 frozen non-mutual (investor-owned), 1 frozen non-mutual (municipal)); 91 gates; build id 3d08d6d2a855.
A2: source_commit | B2: d418ffb174855ab78000d391d42f898397b0d8aa
A3: source_commit_date | B3: 2026-10-06
A4: source_fingerprint | B4: a75a8eee82c65cf7096931f06e18affdc28686a02895b46538e7298b57c04d94
A5: gate_count | B5: 91
A6: build_id | B6: 3d08d6d2a855
A7: registry: frozen non-mutual (investor-owned) | B7: 1
A8: registry: frozen non-mutual (municipal) | B8: 1
A9: registry: frozen non-mutual (special district) | B9: 2
A10: registry: irrigation mutual | B10: 4
A11: registry: mutual, no PWSID, purpose not stated | B11: 3
A12: registry: retail mutual | B12: 179
A13: registry: wholesale mutual | B13: 2
