Workbook

Sheet Summary
A1: Caspar South Service Company
A2: Financial Summary - multi-year overview (USD)
A3: Entity ID: cawc_0160 | Fiscal year ends April 30.
A5: Presentation standard: every figure on the statement tabs is verified to its source filing and shown clean. A cell the filing does not report reads "not reported" (never estimated, never guessed).
A6: Citations, confidence tiers, and the filed-vs-computed tie-out checks live on the "Sources & audit" tab, keyed by cell, so every number is fully traceable without cluttering the statements. These pages are ready to use as filed.
A8: Metric | B8: FY2020 | C8: FY2021 | D8: FY2022 | E8: FY2023 | F8: FY2024
A9: Operating results (USD)
A10: Total revenue | B10: 175645 | C10: 185422 | D10: 189237 | E10: 189368 | F10: 176339
A11: Total expenses | B11: 79663 | C11: 99260 | D11: 84884 | E11: 89310 | F11: 94848
A12: Net income | B12: 95982 | C12: 86162 | D12: 104353 | E12: 100058 | F12: 81491
A14: Financial position (USD, end of year)
A15: Total assets | B15: 697447 | C15: 895453 | D15: 905923 | E15: 981280 | F15: 1132187
A16: Total liabilities | B16: 1 | C16: 0 | D16: 1 | E16: 0 | F16: 1
A17: Net assets | B17: 697446 | C17: 895453 | D17: 905922 | E17: 981280 | F17: 1132186
A19: Headline ratios
A20: Operating margin | B20: 0.5464545 | C20: 0.46468057 | D20: 0.55144079 | E20: 0.52837861 | F20: 0.46212693
A21: Revenue growth (YoY) | B21: 0.068198819 | C21: 0.055663412 | D21: 0.020574689 | E21: 0.00069225363 | F21: -0.068802543
A22: Return on assets | B22: 0.13761906 | C22: 0.096221689 | D22: 0.1151897 | E22: 0.10196682 | F22: 0.071976626
A24: Figures as reported in source filings (full provenance on the Sources & audit tab). Parentheses denote negatives; ratios are computed upstream in financials_annual.

Sheet Notes
A1: Notes
A2: Human annotations from the versioned store (data/notes/). Annotations only: they never change a reported figure or a confidence tier.
A4: Date | B4: Tag | C4: Author | D4: Note
A5: No notes recorded yet.

Sheet Financial Statements
A1: Caspar South Service Company
A2: Financial Statements - income statement, balance sheet, cash flow, member income test (USD)
A3: Entity ID: cawc_0160 | Fiscal year ends April 30.
A5: INCOME STATEMENT - as reported (USD)
A6: Line item | B6: FY2020 | C6: FY2021 | D6: FY2022 | E6: FY2023 | F6: FY2024
A7: Revenue
A8: Program service revenue | B8: 154857 | C8: 159131 | D8: 154694 | E8: 156022 | F8: 134908
A9: Investment income | B9: 20788 | C9: 26291 | D9: 34543 | E9: 33346 | F9: 41431
A10: Net rental income | B10: 0 | C10: 0 | D10: 0 | E10: 0 | F10: 0
A11: Net gain/(loss) on investment sales | B11: 0 | C11: 0 | D11: 0 | E11: 0 | F11: 0
A12: Other revenue | B12: 0 | C12: 0 | D12: 0 | E12: 0 | F12: 0
A13: Contributions & grants | B13: 0 | C13: 0 | D13: 0 | E13: 0 | F13: 0
A14: Total revenue | B14: 175645 | C14: 185422 | D14: 189237 | E14: 189368 | F14: 176339
A16: Expenses
A17: Depreciation | B17: 1908 | C17: 1908 | D17: 728 | E17: 728 | F17: 728
A18: Interest expense | B18: 0 | C18: 0 | D18: 0 | E18: 0 | F18: 0
A19: Total expenses | B19: 79663 | C19: 99260 | D19: 84884 | E19: 89310 | F19: 94848
A21: Net income | B21: 95982 | C21: 86162 | D21: 104353 | E21: 100058 | F21: 81491
A24: BALANCE SHEET - as reported (USD, end of year)
A25: Line item | B25: FY2020 | C25: FY2021 | D25: FY2022 | E25: FY2023 | F25: FY2024
A26: Assets
A27: Cash | B27: 14537 | C27: 41773 | D27: 7535 | E27: 24234 | F27: 6743
A28: Savings & temporary investments | B28: 14860 | C28: 14868 | D28: 14875 | E28: 14882 | F28: 7890
A29: Accounts receivable | B29: 11609 | C29: 11609 | D29: 9102 | E29: 0 | F29: 0
A30: Inventories | B30: 0 | C30: 0 | D30: 0 | E30: 0 | F30: 0
A31: Prepaid expenses | B31: 0 | C31: 0 | D31: 0 | E31: 0 | F31: 0
A32: Property, plant & equipment (gross) | B32: 404978 | C32: 404978 | D32: 404978 | E32: 404978 | F32: 404978
A33: Less: accumulated depreciation | B33: -348131 | C33: -350039 | D33: -350767 | E33: -351495 | F33: -352223
A34: Net property, plant & equipment | B34: 56847 | C34: 54939 | D34: 54211 | E34: 53483 | F34: 52755
A35: Total assets | B35: 697447 | C35: 895453 | D35: 905923 | E35: 981280 | F35: 1132187
A37: Liabilities
A38: Accounts payable
A39: Mortgages & notes payable
A40: Total liabilities | B40: 1 | C40: 0 | D40: 1 | E40: 0 | F40: 1
A42: Net Assets / Equity
A43: Capital stock
A44: Paid-in capital
A45: Retained earnings | B45: 697446 | C45: 895453 | D45: 905922 | E45: 981280 | F45: 1132186
A46: Net assets | B46: 697446 | C46: 895453 | D46: 905922 | E46: 981280 | F46: 1132186
A49: CASH FLOW - derived proxy (USD)
...

Sheet Balance Sheet
A1: Caspar South Service Company
A2: Balance Sheet - as reported (USD, end of year)
A3: Entity ID: cawc_0160 | Fiscal year ends April 30.
A5: Line item | B5: FY2020 | C5: FY2021 | D5: FY2022 | E5: FY2023 | F5: FY2024
A6: Assets
A7: Cash | B7: 14537 | C7: 41773 | D7: 7535 | E7: 24234 | F7: 6743
A8: Savings & temporary investments | B8: 14860 | C8: 14868 | D8: 14875 | E8: 14882 | F8: 7890
A9: Accounts receivable | B9: 11609 | C9: 11609 | D9: 9102 | E9: 0 | F9: 0
A10: Inventories | B10: 0 | C10: 0 | D10: 0 | E10: 0 | F10: 0
A11: Prepaid expenses | B11: 0 | C11: 0 | D11: 0 | E11: 0 | F11: 0
A12: Property, plant & equipment (gross) | B12: 404978 | C12: 404978 | D12: 404978 | E12: 404978 | F12: 404978
A13: Less: accumulated depreciation | B13: -348131 | C13: -350039 | D13: -350767 | E13: -351495 | F13: -352223
A14: Net property, plant & equipment | B14: 56847 | C14: 54939 | D14: 54211 | E14: 53483 | F14: 52755
A15: Total assets | B15: 697447 | C15: 895453 | D15: 905923 | E15: 981280 | F15: 1132187
A17: Liabilities
A18: Accounts payable
A19: Mortgages & notes payable
A20: Total liabilities | B20: 1 | C20: 0 | D20: 1 | E20: 0 | F20: 1
A22: Net Assets / Equity
A23: Capital stock
A24: Paid-in capital
A25: Retained earnings | B25: 697446 | C25: 895453 | D25: 905922 | E25: 981280 | F25: 1132186
A26: Net assets | B26: 697446 | C26: 895453 | D26: 905922 | E26: 981280 | F26: 1132186
A28: Balance check (assets − liab. − net assets) | B28: 0 | C28: 0 | D28: 0 | E28: 0 | F28: 0
A30: Net PP&E is the reported ppe_net column (gross less accumulated depreciation). The balance check should be ~0 where all three totals are reported; a non-zero value flags a reporting or extraction discrepancy worth reviewing.

Sheet Officers & contractors
A1: Caspar South Service Company
A2: Officers, Directors & Contractors - Form 990 Part VII (FY2024; USD)
A3: Entity ID: cawc_0160 | Fiscal year ends April 30.
A5: Section A - Officers, directors, trustees, key employees
A6: Name | B6: Title | C6: Reportable comp (org) | D6: Reportable comp (related) | E6: Other comp | F6: Total compensation
A7: Marlene Demery | B7: Receiver | C7: 13694 | D7: 0 | E7: 0 | F7: 13694
A9: Section B - Independent contractors (over $100,000)
A10: Contractor | B10: Services | C10: Compensation
A12: Section A lists every officer, director, trustee and key employee filed for the latest year; the two with the highest total compensation are highlighted. Total compensation is computed (reportable org + related + other). Section B lists each independent contractor paid over $100,000; the return reports 0 such contractor(s). Source and confidence for every figure are on the Sources & audit tab.

Sheet Revenue (detail)
A1: Caspar South Service Company
A2: Revenue - Form 990 Part VIII (USD)
A3: Entity ID: cawc_0160 | Fiscal year ends April 30.
A5: Part VIII line | B5: FY2020 | C5: FY2021 | D5: FY2022 | E5: FY2023 | F5: FY2024
A6: Revenue by category
A7: 1h. Total contributions, gifts, grants | B7: 0 | C7: 0 | D7: 0 | E7: 0 | F7: 0
A8: 2g. Total program service revenue | B8: 154857 | C8: 159131 | D8: 154694 | E8: 156022 | F8: 134908
A9: 3. Investment income | B9: 20788 | C9: 26291 | D9: 34543 | E9: 33346 | F9: 41431
A10: 6d. Net rental income | B10: 0 | C10: 0 | D10: 0 | E10: 0 | F10: 0
A11: 7d. Net gain/(loss) from investment sales | B11: 0 | C11: 0 | D11: 0 | E11: 0 | F11: 0
A12: 11e. Other revenue | B12: 0 | C12: 0 | D12: 0 | E12: 0 | F12: 0
A13: 12. Total revenue | B13: =SUM(B7:B12) | C13: =SUM(C7:C12) | D13: =SUM(D7:D12) | E13: =SUM(E7:E12) | F13: =SUM(F7:F12)
A15: Program service revenue detail - FY2024 (lines 2a-2f)
A16: Description | B16: Business code | C16: Total revenue
A17: Water delivery System | C17: 134908
A18: Revenue category subtotals are as filed. Total revenue (line 12) is a live SUM of the category cells above; its tie-out to the filed total is on the Sources & audit tab. Program service revenue detail is shown for the latest year, with its sum-to-line-2g check on that same audit tab.

Sheet Operating expenses (detail)
A1: Caspar South Service Company
A2: Statement of Functional Expenses - Form 990 Part IX (USD)
A3: Entity ID: cawc_0160 | Fiscal year ends April 30.
A5: Part IX line (column A Total) | B5: FY2020 | C5: FY2021 | D5: FY2022 | E5: FY2023 | F5: FY2024
A6: Functional expenses, column A Total - by year
A7: 1. Grants to domestic organizations and governments | B7: 0 | C7: 0 | D7: 0 | E7: 0 | F7: 0
A8: 2. Grants to domestic individuals | B8: 0 | C8: 0 | D8: 0 | E8: 0 | F8: 0
A9: 3. Grants to foreign organizations and individuals | B9: 0 | C9: 0 | D9: 0 | E9: 0 | F9: 0
A10: 4. Benefits paid to or for members | B10: 0 | C10: 0 | D10: 0 | E10: 0 | F10: 0
A11: 5. Compensation of current officers, directors, trustees | B11: 12503 | C11: 19346 | D11: 14916 | E11: 14049 | F11: 13694
A12: 6. Compensation to disqualified persons | B12: 0 | C12: 0 | D12: 0 | E12: 0 | F12: 0
A13: 7. Other salaries and wages | B13: 0 | C13: 0 | D13: 0 | E13: 0 | F13: 0
A14: 8. Pension plan accruals and contributions | B14: 0 | C14: 0 | D14: 0 | E14: 0 | F14: 0
A15: 9. Other employee benefits | B15: 0 | C15: 0 | D15: 0 | E15: 0 | F15: 0
A16: 10. Payroll taxes | B16: 0 | C16: 0 | D16: 0 | E16: 0 | F16: 0
A17: 11a. Fees for services: management | B17: 0 | C17: 0 | D17: 0 | E17: 0 | F17: 0
A18: 11b. Fees for services: legal | B18: 0 | C18: 0 | D18: 0 | E18: 0 | F18: 0
... A38: 24. Water Testing | B38: 2700 | C38: 2345 | D38: 4035 | E38: 3660 | F38: 2145
A39: 24. Licenses & Permits | B39: 1014 | C39: 1014 | D39: 1710 | E39: 1804 | F39: not reported
A40: 24. Meters | B40: not reported | C40: not reported | D40: not reported | E40: not reported | F40: 3707
A41: 24e. All other expenses | B41: 212 | C41: 702 | D41: 0 | E41: 1492 | F41: 2722
A42: 25. Total functional expenses | B42: =SUM(B7:B41) | C42: =SUM(C7:C41) | D42: =SUM(D7:D41) | E42: =SUM(E7:E41) | F42: =SUM(F7:F41)
A44: Functional column split - FY2024 (col A = B + C + D)
A45: Part IX line | B45: A. Total | C45: B. Program services | D45: C. Management & general | E45: D. Fundraising
A46: 1. Grants to domestic organizations and governments | B46: 0
A47: 2. Grants to domestic individuals | B47: 0
A48: 3. Grants to foreign organizations and individuals | B48: 0
A49: 4. Benefits paid to or for members | B49: 0
A50: 5. Compensation of current officers, directors, trustees | B50: 13694 | C50: 13694
A51: 6. Compensation to disqualified persons | B51: 0
A52: 7. Other salaries and wages | B52: 0
A53: 8. Pension plan accruals and contributions | B53: 0
A54: 9. Other employee benefits | B54: 0
A55: 10. Payroll taxes | B55: 0
A56: 11a. Fees for services: management | B56: 0
A57: 11b. Fees for services: legal | B57: 0
A58: 11c. Fees for services: accounting | B58: 5859 | C58: 5273 | D58: 586
A59: 11d. Fees for services: lobbying | B59: 0
A60: 11e. Fees for services: professional fundraising | B60: 0
A61: 11f. Fees for services: investment management | B61: 14720 | C61: 13248 | D61: 1472
...

Sheet Balance sheet (detail)
A1: Caspar South Service Company
A2: Balance Sheet - Form 990 Part X (end of year, USD)
A3: Entity ID: cawc_0160 | Fiscal year ends April 30.
A5: Part X line (column B, EOY) | B5: FY2020 | C5: FY2021 | D5: FY2022 | E5: FY2023 | F5: FY2024
A6: Assets
A7: 1. Cash - non-interest-bearing | B7: 14537 | C7: 41773 | D7: 7535 | E7: 24234 | F7: 6743
A8: 2. Savings and temporary cash investments | B8: 14860 | C8: 14868 | D8: 14875 | E8: 14882 | F8: 7890
A9: 3. Pledges and grants receivable, net | B9: 0 | C9: 0 | D9: 0 | E9: 0 | F9: 0
A10: 4. Accounts receivable, net | B10: 11609 | C10: 11609 | D10: 9102 | E10: 0 | F10: 0
A11: 5. Receivables from officers/directors/trustees | B11: 0 | C11: 0 | D11: 0 | E11: 0 | F11: 0
A12: 6. Receivables from disqualified persons | B12: 0 | C12: 0 | D12: 0 | E12: 0 | F12: 0
A13: 7. Notes and loans receivable, net | B13: 0 | C13: 0 | D13: 0 | E13: 0 | F13: 0
A14: 8. Inventories for sale or use | B14: 0 | C14: 0 | D14: 0 | E14: 0 | F14: 0
A15: 9. Prepaid expenses and deferred charges | B15: 0 | C15: 0 | D15: 0 | E15: 0 | F15: 0
A16: 10c. Land, buildings, and equipment, net | B16: 56847 | C16: 54939 | D16: 54211 | E16: 53483 | F16: 52755
A17: 11. Investments - publicly traded securities | B17: 599594 | C17: 772264 | D17: 820200 | E17: 888680 | F17: 1064799
A18: 12. Investments - other securities | B18: 0 | C18: 0 | D18: 0 | E18: 0 | F18: 0
... A21: 15. Other assets | B21: 0 | C21: 0 | D21: 0 | E21: 1 | F21: 0
A22: 16. Total assets | B22: =SUM(B7:B21) | C22: =SUM(C7:C21) | D22: =SUM(D7:D21) | E22: =SUM(E7:E21) | F22: =SUM(F7:F21)
A24: Liabilities
A25: 25. Other liabilities | B25: 1 | C25: not reported | D25: 1 | E25: not reported | F25: 1
A26: 26. Total liabilities | B26: =SUM(B25:B25) | C26: =SUM(C25:C25) | D26: =SUM(D25:D25) | E26: =SUM(E25:E25) | F26: =SUM(F25:F25)
A28: Net assets / fund balances
A29: 31. Retained earnings / accumulated funds | B29: 697446 | C29: 895453 | D29: 905922 | E29: 981280 | F29: 1132186
A30: 32. Total net assets / fund balances | B30: =SUM(B29:B29) | C30: =SUM(C29:C29) | D30: =SUM(D29:D29) | E30: =SUM(E29:E29) | F30: =SUM(F29:F29)
A32: Every Part X line is end-of-year (column B), as filed. Section totals (lines 16 / 26 / 32) are live SUMs of the lines above; their tie-outs and the balance-sheet identity (16 = 26 + 32) are on the Sources & audit tab. This filer files as a non-FASB mutual, so net assets sit on lines 29-31 (capital stock / paid-in capital / retained earnings); lines this filer does not report are omitted. Lines 10a/10b net into line 10c (shown).

Sheet Net-assets reconciliation
A1: Caspar South Service Company
A2: Reconciliation of Net Assets - Form 990 Part XI (USD)
A3: Entity ID: cawc_0160 | Fiscal year ends April 30.
A5: Part XI line | B5: FY2020 | C5: FY2021 | D5: FY2022 | E5: FY2023 | F5: FY2024
A6: Reconciliation
A7: 4. Net assets, beginning of year | B7: 602714 | C7: 697446 | D7: 895453 | E7: 905922 | F7: 981280
A8: 3. Revenue less expenses | B8: 95982 | C8: 86162 | D8: 104353 | E8: 100058 | F8: 81491
A9: 8. Prior period adjustments | B9: not reported | C9: not reported | D9: not reported | E9: not reported | F9: not reported
A10: 9. Other changes in net assets | B10: not reported | C10: not reported | D10: not reported | E10: not reported | F10: not reported
A11: 10. Net assets, end of year | B11: =SUM(B7,B8,B9,B10) | C11: =SUM(C7,C8,C9,C10) | D11: =SUM(D7,D8,D9,D10) | E11: =SUM(E7,E8,E9,E10) | F11: =SUM(F7,F8,F9,F10)
A13: Part XI reconciles beginning to ending net assets. Ending net assets (line 10) is a live formula: beginning balance (line 4) + revenue less expenses (line 3) + prior-period adjustments (8) + other changes (9). Its tie-out to the filed line 10 (and to Part X line 32) is on the Sources & audit tab. Lines 5-7 (unrealized gains, donated services, investment expenses) are not filed by this entity.

Sheet Cash flow proxies
A1: Caspar South Service Company
A2: Cash Flow Proxies - derived (USD)
A3: Entity ID: cawc_0160 | Fiscal year ends April 30.
A5: PROXY ONLY. The source filings contain no statement of cash flows. Lines below are derived from the reported income statement and year-over-year balance-sheet changes; treat as directional estimates, not GAAP cash flows. The earliest year has no prior period, so its delta cells are blank.
A7: Proxy line (USD) | B7: FY2020 | C7: FY2021 | D7: FY2022 | E7: FY2023 | F7: FY2024
A8: Operating
A9: Net income | B9: 95982 | C9: 86162 | D9: 104353 | E9: 100058 | F9: 81491
A10: + Depreciation (reported) | B10: 1908 | C10: 1908 | D10: 728 | E10: 728 | F10: 728
A11: − Δ Accounts receivable | C11: 0 | D11: 2507 | E11: 9102 | F11: 0
A12: − Δ Inventories | C12: 0 | D12: 0 | E12: 0 | F12: 0
A13: − Δ Prepaid expenses | C13: 0 | D13: 0 | E13: 0 | F13: 0
A14: + Δ Accounts payable
A15: Operating cash flow proxy | C15: 88070 | D15: 107588 | E15: 109888 | F15: 82219
A17: Investing
A18: − Δ PP&E gross (capex proxy) | C18: 0 | D18: 0 | E18: 0 | F18: 0
A20: Financing
A21: Δ Mortgages & notes payable
A23: Reconciliation
A24: Δ Cash + temp. investments (actual) | C24: 27244 | D24: -34231 | E24: 16706 | F24: -24483
A26: The capex proxy assumes gross PP&E rises only via capital spending (it ignores disposals). 'Δ Cash + temp. investments (actual)' is the real reported change in liquid funds and is the most reliable line here; the operating/investing/financing proxies will not perfectly reconcile to it.

Sheet Ratios
A1: Caspar South Service Company
A2: Financial Ratios
A3: Entity ID: cawc_0160 | Fiscal year ends April 30.
A5: Ratio | B5: FY2020 | C5: FY2021 | D5: FY2022 | E5: FY2023 | F5: FY2024
A6: Profitability (computed upstream)
A7: Operating margin (NI / revenue) | B7: 0.5464545 | C7: 0.46468057 | D7: 0.55144079 | E7: 0.52837861 | F7: 0.46212693
A8: Expense ratio (expenses / revenue) | B8: 0.4535455 | C8: 0.53531943 | D8: 0.44855921 | E8: 0.47162139 | F8: 0.53787307
A9: Return on assets (NI / assets) | B9: 0.13761906 | C9: 0.096221689 | D9: 0.1151897 | E9: 0.10196682 | F9: 0.071976626
A10: Revenue growth (YoY) | B10: 0.068198819 | C10: 0.055663412 | D10: 0.020574689 | E10: 0.00069225363 | F10: -0.068802543
A12: Leverage & solvency
A13: Debt-to-assets (liab. / assets) | B13: 1.4338007e-06 | C13: 0 | D13: 1.1038466e-06 | E13: 0 | F13: 8.8324632e-07
A14: Equity ratio (net assets / assets) | B14: 0.99999857 | C14: 1 | D14: 0.9999989 | E14: 1 | F14: 0.99999912
A16: Liquidity & asset profile (derived here)
A17: Current ratio (current assets / AP)
A18: Cash ratio ((cash+temp inv.) / total liab.) | B18: 29397 | D18: 22410 | F18: 14633
A19: Asset age proxy (accum. deprec. / gross PP&E) | B19: 0.85962941 | C19: 0.86434078 | D19: 0.86613841 | E19: 0.86793604 | F19: 0.86973366
A21: Upstream ratios are read from financials_annual; derived ratios are computed only where inputs are reported. Current ratio uses accounts payable as the current-liability proxy (the filings do not split current vs. long-term liabilities). Asset age proxy: a higher % implies older / more depreciated infrastructure.

Sheet Unit economics
A1: Caspar South Service Company
A2: Unit economics - per-customer revenue by category (USD)
A3: Entity ID: cawc_0160 | Fiscal year ends April 30.
A5: Every metric here is PER CUSTOMER (a metered service connection). It is not a per-member figure; the member (shareholder) count is a different denominator, shown in the denominator block. The visible cell shows the value and its classification; the numerator, denominator, formula, and rationale are in each metric's LOGIC popup.
A6: Per-customer denominator (service connections) | C6: State Water Board eAR Section 4
A7: Total annual revenue (eAR Section 8b B1.8) | C7: eAR Section 8b total annual revenue not reported for this system.
A8: Primary source
A10: Revenue categories (value, classification, per customer, share)
A11: Revenue category | B11: Classification | C11: Value (USD) | D11: Per customer | E11: Share of revenue
A12: Water sales revenue | B12: not reported | C12: not reported | D12: not reported | E12: not reported
A13: Assessment revenue (990 program-service revenue not matched to eAR water-rate revenue) | B13: IMPOSSIBLE | C13: IMPOSSIBLE | D13: IMPOSSIBLE | E13: IMPOSSIBLE
A14: Meter revenue | B14: not reported | C14: not reported | D14: not reported | E14: not reported
A15: Overage or tiered penalty revenue | B15: not reported | C15: not reported | D15: not reported | E15: not reported
A17: Water sales revenue - not reported
A18: Not reported: this system filed an eAR but no Section 8b revenue block, so there is no filed water-sales figure. Not fallen back to a different year.
A19: Reason: No filed eAR Section 8b water-rate revenue for this system.
A21: Assessment revenue (990 program-service revenue not matched to eAR water-rate revenue) - IMPOSSIBLE
A22: Not computed. A period-aligned residual is not possible for this filer.
A23: Reason: Not derivable. The eAR Section 8b is reporting year None while the Form 990 fiscal year ends None; the two period ends are not aligned, so a period-aligned residual cannot be computed.
A25: Meter revenue - not reported
A26: Not reported. This category is not built because doing so would double-count.
A27: Reason: The eAR Section 8a reports a base/meter rate PRICE, but the filing carries no meter revenue line and no tier volume, and the base charge is already inside the water-sales revenue (eAR Section 8b water rates). Building a separate meter figure would double-count. Not backed into from a total.
A29: Overage or tiered penalty revenue - not reported
A30: Not reported. This category is not built because doing so would double-count.
A31: Reason: The eAR Section 8a reports tiered/overage rate PRICES, but the filing carries no overage revenue and no tier consumption volume, and any overage billed is already inside the water-sales revenue. Building it would double-count. Not backed into from a total.

Sheet Rate structure
A1: Caspar South Service Company
A2: Rate structure and representative bill - eAR Section 8a
A3: Entity ID: cawc_0160 | Fiscal year ends April 30.
A5: This block is a rate-schedule illustration at defined usage levels. It is NOT billed revenue and not a claim about any real customer's usage. The revenue side of unit economics is the separate Unit Economics block.
A6: No filed eAR Section 8a rate schedule is staged for this system.

Sheet Operational metrics
A1: Caspar South Service Company
A2: Operational metrics - plant per acre, density, terrain
A3: Entity ID: cawc_0160 | Fiscal year ends April 30.
A5: Plant assets per acre
A6: Service-area acres | B6: 100.9 | C6: Geodesic area (WGS84 spherical excess) of the SABL service-area polygon.
A7: Fiscal year | B7: Gross plant per acre (primary) | C7: Net plant per acre
A8: FY2020 | B8: 4013.6571 | C8: 563.3994
A9: FY2021 | B9: 4013.6571 | C9: 544.4896
A10: FY2022 | B10: 4013.6571 | C10: 537.2745
A11: FY2023 | B11: 4013.6571 | C11: 530.0595
A12: FY2024 | B12: 4013.6571 | C12: 522.8444
A13: Infrastructure built per acre of service area. Gross plant per acre is the primary read because it measures how much plant the system has put in the ground per acre, and unlike net plant it does not fall over time purely because the assets depreciate on the books. Net plant per acre is shown alongside as the depreciated book value per acre.
A14: Formula: gross plant per acre = Form 990 Part X line 10a (land, buildings, and equipment, gross) / SABL service-area acres; net plant per acre uses Part X line 10c (net)
A15: Source lines: Form 990 Part X line 10a (gross) and line 10c (net); Geodesic area (WGS84 spherical excess) of the SABL service-area polygon.
A16: Confidence: medium. This is worked out from filed figures (a ratio, or a year-to-year change), so it is one step removed from the raw numbers.. Filed gross/net plant over the measured SABL service-area acreage.
A18: Connections per acre
A19: Connections per acre | B19: 0.94 | C19: 95 connections / 100.9 acres. CA State Water Board SABL SERVICE_CONNECTIONS; Geodesic area (WGS84 spherical excess) of the SABL service-area polygon.

Sheet Supply & weather
A1: Caspar South Service Company
A2: Supply and weather indicators (DWR water year)
A3: Entity ID: cawc_0160 | Fiscal year ends April 30.
A5: Reporting calendar: Different reporting periods. The DWR water year runs October 1 to September 30; this system's fiscal year ends April 30, so the two period ends are five months apart. Read the two side by side with that in mind. Neither series is recast: both are reported as filed. A water year is named for the calendar year it ends in, so WY2024 and FY2024 share a number without covering the same twelve months.
A7: Indicator | B7: WY2020 | C7: WY2021 | D7: WY2022 | E7: WY2023 | F7: WY2024
A8: Water-year type (Sacramento Valley) | B8: Dry | C8: Critical | D8: Critical | E8: Wet | F8: Above Normal
A9: Peak drought, county County | B9: not reported | C9: not reported | D9: not reported | E9: not reported | F9: not reported
A10: Precip, percent of normal (8-Station Index) | B10: 63 | C10: 48 | D10: 86 | E10: 133 | F10: 96
A11: Snowpack, April 1 percent of average | B11: 53% | C11: 59% | D11: 38% | E11: 237% | F11: 110%
A12: State Water Project allocation | B12: 20% | C12: 5% | D12: 5% | E12: 100% | F12: 40%

Sheet How this was built
A1: Caspar South Service Company
A2: How this was built - forensic lineage
A3: Entity ID: cawc_0160 | Fiscal year ends April 30.
A5: A plain account of the forensic lineage behind the hard-to-source metrics: what sources were checked, what was found, what was derived, and what could not be built and why. Every figure marked DERIVED or IMPOSSIBLE above is traceable to a line here.
A7: Water-sales revenue per customer - not reported
A8: Sources checked | B8: State Water Board eAR Section 8b (water-rate revenue B1.1/B1.2); State Water Board eAR Section 4 (connection count, same reporting year); audited financial statement (secondary cross-check, where published)
A9: What was found | B9: The eAR Section 8b reports water-rate revenue for reporting year None, so this is a DIRECT filed figure; per customer it is divided by the eAR Section 4 connection count for the same reporting year, so numerator and denominator share the year.
A11: Assessment revenue (residual) - IMPOSSIBLE
A12: Sources checked | B12: Form 990 Part VIII line 2 (program-service revenue); State Water Board eAR Section 8b (water-rate revenue B1.1/B1.2); eAR Section 8b filer comment (WRRevenueComments)
A13: What was found | B13: A period-aligned residual cannot be computed for this filer, so the metric is rendered IMPOSSIBLE rather than guessed.
A14: Caveat | B14: Not derivable. The eAR Section 8b is reporting year None while the Form 990 fiscal year ends None; the two period ends are not aligned, so a period-aligned residual cannot be computed.
A16: Meter revenue - not reported
A17: Sources checked | B17: State Water Board eAR Section 8a (rate prices); State Water Board eAR Section 8b (revenue lines); audited financial statement
A18: What was found | B18: The rate price exists in Section 8a but no revenue or tier volume is reported, and the base charge is already inside water sales.
A19: Caveat | B19: The eAR Section 8a reports a base/meter rate PRICE, but the filing carries no meter revenue line and no tier volume, and the base charge is already inside the water-sales revenue (eAR Section 8b water rates). Building a separate meter figure would double-count. Not backed into from a total.
A21: Overage / tiered-penalty revenue - not reported
A22: Sources checked | B22: State Water Board eAR Section 8a (rate prices); State Water Board eAR Section 8b (revenue lines); audited financial statement
A23: What was found | B23: The rate price exists in Section 8a but no revenue or tier volume is reported, and the base charge is already inside water sales.
A24: Caveat | B24: The eAR Section 8a reports tiered/overage rate PRICES, but the filing carries no overage revenue and no tier consumption volume, and any overage billed is already inside the water-sales revenue. Building it would double-count. Not backed into from a total.
A26: eAR Section 8b reporting-period basis - sourced
A27: Sources checked | B27: eAR Section 8b B0.1 (WRFinancialReportingPeriod); eAR Section 8b B0.2 (WRFiscalYearStartDate)
A28: What was found | B28: The reporting basis (fiscal vs calendar year) is read from the filer's own B0.1/B0.2 answer and staged verbatim, never hardcoded, so the 990 comparison and the residual are period-aligned.
A30: Member (shareholder) count denominator - not reported
A31: Sources checked | B31: Form 990 (no member count stated); company website
A32: What was found | B32: No filing states a member/shareholder count, so the per-member unit economics read not reported rather than borrowing the connection count.
A34: Water volume delivered (acre-feet) - not reported
A35: Sources checked | B35: Form 990 (not in the filing); Consumer Confidence Report; eAR Section 6 (PRA-gated)
A36: What was found | B36: Volume delivered in acre-feet is not in the Form 990 and the CCR states only a source mix, so the per-acre-foot metrics read not reported; the eAR Section 6 is named as the source still needed.

Sheet Sources & audit
A1: Caspar South Service Company
A2: Sources & audit - full provenance and tie-outs (kept off the statements so they read clean)
A3: Entity ID: cawc_0160 | Fiscal year ends April 30.
A5: Presentation standard: every figure on the statement tabs is verified to its source filing and shown clean. A cell the filing does not report reads "not reported" (never estimated, never guessed).
A6: Citations, confidence tiers, and the filed-vs-computed tie-out checks live on the "Sources & audit" tab, keyed by cell, so every number is fully traceable without cluttering the statements. These pages are ready to use as filed.
A8: A. Filing provenance (one row per staged extraction)
A9: Fiscal year | B9: Period end | C9: Filing type | D9: Confidence | E9: Extraction ID | F9: Object ID | G9: Extracted by | H9: Extracted at | I9: Source URL
A10: FY2020 | B10: 2020-04-30 | C10: 990 | D10: high | E10: f38a68fb-a714-4032-a3d7-c8371f6aba8a | F10: 202130389349300203 | G10: claude-opus-5 | H10: 2026-10-05T16:06:09+00:00 | I10: https://apps.irs.gov/pub/epostcard/990/xml/2021/2021_TEOS_XML_01A.zip#202130389349300203_public.xml
A11: FY2021 | B11: 2021-04-30 | C11: 990 | D11: high | E11: 1ed1ecdd-bd65-429b-b3c9-fa5f197fdca8 | F11: 202132569349301523 | G11: claude-opus-5 | H11: 2026-10-05T16:06:09+00:00 | I11: https://apps.irs.gov/pub/epostcard/990/xml/2021/2021_TEOS_XML_01A.zip#202132569349301523_public.xml
A12: FY2022 | B12: 2022-04-30 | C12: 990 | D12: high | E12: c3456bf5-4cfc-435d-ae38-3516cecd4a04 | F12: 202330129349303343 | G12: claude-opus-5 | H12: 2026-10-05T16:06:09+00:00 | I12: https://apps.irs.gov/pub/epostcard/990/xml/2023/2023_TEOS_XML_01A.zip#202330129349303343_public.xml
A13: FY2023 | B13: 2023-04-30 | C13: 990 | D13: high | E13: 608eb6ff-6267-433a-958b-5908e40ef8bb | F13: 202302409349301095 | G13: claude-opus-5 | H13: 2026-10-05T16:06:09+00:00 | I13: https://apps.irs.gov/pub/epostcard/990/xml/2023/2023_TEOS_XML_09A.zip#202302409349301095_public.xml
A14: FY2024 | B14: 2024-04-30 | C14: 990 | D14: high | E14: 345cebf2-f8cb-4233-92a8-c03a1d639a36 | F14: 202432609349300798 | G14: claude-opus-5 | H14: 2026-10-05T16:06:09+00:00 | I14: https://apps.irs.gov/pub/epostcard/990/xml/2024/2024_TEOS_XML_09A.zip#202432609349300798_public.xml
A16: B. Figure citations (every figure on the statement tabs, keyed by cell)
A17: Tab | B17: Cell | C17: Line item | D17: Form 990 line | E17: Key path | F17: Confidence | G17: As filed
A18: Financial Statements | B18: B73 | C18: 11a. Gross income from members or shareholders | D18: 11a | E18: part_v_other_irs_filings.members_and_shareholders_gross_income | F18: high | G18: 154857
A19: Financial Statements | B19: B74 | C19: 11b. Gross income from other sources | D19: 11b | E19: part_v_other_irs_filings.other_sources_gross_income | F19: high | G19: 20788
A20: Revenue (detail) | B20: B7 | C20: 1h. Total contributions, gifts, grants | D20: 1h | E20: part_viii_revenue.total_contributions | F20: high | G20: 0
A21: Revenue (detail) | B21: C7 | C21: 1h. Total contributions, gifts, grants | D21: 1h | E21: part_viii_revenue.total_contributions | F21: high | G21: 0
A22: Revenue (detail) | B22: D7 | C22: 1h. Total contributions, gifts, grants | D22: 1h | E22: part_viii_revenue.total_contributions | F22: high | G22: 0
A23: Revenue (detail) | B23: E7 | C23: 1h. Total contributions, gifts, grants | D23: 1h | E23: part_viii_revenue.total_contributions | F23: high | G23: 0
A24: Revenue (detail) | B24: F7 | C24: 1h. Total contributions, gifts, grants | D24: 1h | E24: part_viii_revenue.total_contributions | F24: high | G24: 0
A25: Revenue (detail) | B25: B8 | C25: 2g. Total program service revenue | D25: 2g | E25: part_viii_revenue.total_program_service_revenue | F25: high | G25: 154857
A26: Revenue (detail) | B26: C8 | C26: 2g. Total program service revenue | D26: 2g | E26: part_viii_revenue.total_program_service_revenue | F26: high | G26: 159131
A27: Revenue (detail) | B27: D8 | C27: 2g. Total program service revenue | D27: 2g | E27: part_viii_revenue.total_program_service_revenue | F27: high | G27: 154694
A28: Revenue (detail) | B28: E8 | C28: 2g. Total program service revenue | D28: 2g | E28: part_viii_revenue.total_program_service_revenue | F28: high | G28: 156022
A29: Revenue (detail) | B29: F8 | C29: 2g. Total program service revenue | D29: 2g | E29: part_viii_revenue.total_program_service_revenue | F29: high | G29: 134908
... A292: Net-assets reconciliation | B292: F8 | C292: 3. Revenue less expenses | D292: Part XI line 3 | E292: part_xi_reconciliation.reconciliation_revenue_expenses | F292: high | G292: 81491
A294: C. Tie-out checks (filed vs computed; any nonzero variance is flagged red)
A295: Tab | B295: Check | C295: Fiscal year | D295: Filed | E295: Computed | F295: Variance (computed - filed)
A296: Revenue (detail) | B296: 12. Total revenue | C296: FY2020 | D296: 175645 | E296: ='Revenue (detail)'!B13 | F296: =E296-D296
A297: Revenue (detail) | B297: 12. Total revenue | C297: FY2021 | D297: 185422 | E297: ='Revenue (detail)'!C13 | F297: =E297-D297
A298: Revenue (detail) | B298: 12. Total revenue | C298: FY2022 | D298: 189237 | E298: ='Revenue (detail)'!D13 | F298: =E298-D298
A299: Revenue (detail) | B299: 12. Total revenue | C299: FY2023 | D299: 189368 | E299: ='Revenue (detail)'!E13 | F299: =E299-D299
A300: Revenue (detail) | B300: 12. Total revenue | C300: FY2024 | D300: 176339 | E300: ='Revenue (detail)'!F13 | F300: =E300-D300
A301: Revenue (detail) | B301: 2g program service revenue = sum of lines 2a-2f (FY2024) | C301: FY2024 | D301: 134908 | E301: =SUM('Revenue (detail)'!C17:C17) | F301: =E301-D301
A302: Operating expenses (detail) | B302: 25. Total functional expenses | C302: FY2020 | D302: 79663 | E302: ='Operating expenses (detail)'!B42 | F302: =E302-D302
A303: Operating expenses (detail) | B303: 25. Total functional expenses | C303: FY2021 | D303: 99260 | E303: ='Operating expenses (detail)'!C42 | F303: =E303-D303
A304: Operating expenses (detail) | B304: 25. Total functional expenses | C304: FY2022 | D304: 84884 | E304: ='Operating expenses (detail)'!D42 | F304: =E304-D304
A305: Operating expenses (detail) | B305: 25. Total functional expenses | C305: FY2023 | D305: 89310 | E305: ='Operating expenses (detail)'!E42 | F305: =E305-D305
A306: Operating expenses (detail) | B306: 25. Total functional expenses | C306: FY2024 | D306: 94848 | E306: ='Operating expenses (detail)'!F42 | F306: =E306-D306
...

Sheet Provenance
A1: Build provenance | B1: Built from source commit d418ffb17485 (2026-10-06); source fingerprint a75a8eee82c65cf7; 192 companies (179 retail mutual, 4 irrigation mutual, 3 mutual, no PWSID, purpose not stated, 2 frozen non-mutual (special district), 2 wholesale mutual, 1 frozen non-mutual (investor-owned), 1 frozen non-mutual (municipal)); 91 gates; build id 3d08d6d2a855.
A2: source_commit | B2: d418ffb174855ab78000d391d42f898397b0d8aa
A3: source_commit_date | B3: 2026-10-06
A4: source_fingerprint | B4: a75a8eee82c65cf7096931f06e18affdc28686a02895b46538e7298b57c04d94
A5: gate_count | B5: 91
A6: build_id | B6: 3d08d6d2a855
A7: registry: frozen non-mutual (investor-owned) | B7: 1
A8: registry: frozen non-mutual (municipal) | B8: 1
A9: registry: frozen non-mutual (special district) | B9: 2
A10: registry: irrigation mutual | B10: 4
A11: registry: mutual, no PWSID, purpose not stated | B11: 3
A12: registry: retail mutual | B12: 179
A13: registry: wholesale mutual | B13: 2
