Workbook

Sheet Summary
A1: Krista Mutual Water Company
A2: Financial Summary - multi-year overview (USD)
A3: Entity ID: cawc_0073 | Fiscal year ends December 31.
A5: Presentation standard: every figure on the statement tabs is verified to its source filing and shown clean. A cell the filing does not report reads "not reported" (never estimated, never guessed).
A6: Citations, confidence tiers, and the filed-vs-computed tie-out checks live on the "Sources & audit" tab, keyed by cell, so every number is fully traceable without cluttering the statements. These pages are ready to use as filed.
A8: Metric | B8: FY2020 | C8: FY2021 | D8: FY2022 | E8: FY2023 | F8: FY2024
A9: Operating results (USD)
A10: Total revenue | B10: 190589 | C10: 198238 | D10: 169301 | E10: 695730 | F10: 454170
A11: Total expenses | B11: 160639 | C11: 181828 | D11: 179781 | E11: 678947 | F11: 415151
A12: Net income | B12: 29950 | C12: 16410 | D12: -10480 | E12: 16783 | F12: 39019
A14: Financial position (USD, end of year)
A15: Total assets | B15: 175895 | C15: 187873 | D15: 224523 | E15: 498438 | F15: 243027
A16: Total liabilities | B16: 11129 | C16: 6697 | D16: 96527 | E16: 301287 | F16: 6857
A17: Net assets | B17: 164766 | C17: 181176 | D17: 127996 | E17: 197151 | F17: 236170
A19: Headline ratios
A20: Operating margin | B20: 0.15714443 | C20: 0.082779286 | D20: -0.061901584 | E20: 0.024122864 | F20: 0.085912764
A21: Revenue growth (YoY) | F21: -0.34720366
A22: Return on assets | B22: 0.17027204 | C22: 0.087346239 | D22: -0.046676732 | E22: 0.033671189 | F22: 0.16055418
A24: Figures as reported in source filings (full provenance on the Sources & audit tab). Parentheses denote negatives; ratios are computed upstream in financials_annual.

Sheet Notes
A1: Notes
A2: Human annotations from the versioned store (data/notes/). Annotations only: they never change a reported figure or a confidence tier.
A4: Date | B4: Tag | C4: Author | D4: Note
A5: No notes recorded yet.

Sheet Financial Statements
A1: Krista Mutual Water Company
A2: Financial Statements - income statement, balance sheet, cash flow, member income test (USD)
A3: Entity ID: cawc_0073 | Fiscal year ends December 31.
A5: INCOME STATEMENT - as reported (USD)
A6: Line item | B6: FY2020 | C6: FY2021 | D6: FY2022 | E6: FY2023 | F6: FY2024
A7: Revenue
A8: Program service revenue | E8: 182500 | F8: 453823
A9: Investment income | E9: 575 | F9: 347
A10: Net rental income | E10: 0
A11: Net gain/(loss) on investment sales | E11: 0
A12: Other revenue | E12: 0
A13: Contributions & grants | E13: 512655
A14: Total revenue | E14: 695730 | F14: 454170
A16: Expenses
A17: Depreciation | E17: 1914 | F17: 1903
A18: Interest expense | E18: 0 | F18: 74
A19: Total expenses | B19: 160639 | C19: 181828 | D19: 179781 | E19: 678947 | F19: 415151
A21: Net income | B21: 29950 | C21: 16410 | D21: -10480 | E21: 16783 | F21: 39019
A24: BALANCE SHEET - as reported (USD, end of year)
A25: Line item | B25: FY2020 | C25: FY2021 | D25: FY2022 | E25: FY2023 | F25: FY2024
A26: Assets
A27: Cash | B27: 123966 | C27: 144892 | D27: 158817 | E27: 169486 | F27: 196526
A28: Savings & temporary investments | E28: 0
A29: Accounts receivable | E29: 297116 | F29: 22136
A30: Inventories | E30: 0
A31: Prepaid expenses | E31: 1727 | F31: 735
A32: Property, plant & equipment (gross) | E32: 414658 | F32: 414658
A33: Less: accumulated depreciation | E33: -389125 | F33: -391028
A34: Net property, plant & equipment | E34: 25533 | F34: 23630
A35: Total assets | B35: 175895 | C35: 187873 | D35: 224523 | E35: 498438 | F35: 243027
A37: Liabilities
A38: Accounts payable | E38: 40991
A39: Mortgages & notes payable
A40: Total liabilities | B40: 11129 | C40: 6697 | D40: 96527 | E40: 301287 | F40: 6857
A42: Net Assets / Equity
A43: Capital stock | E43: 107502 | F43: 107502
A44: Paid-in capital | E44: 220469 | F44: 220469
A45: Retained earnings | E45: -130820 | F45: -91801
A46: Net assets | B46: 164766 | C46: 181176 | D46: 127996 | E46: 197151 | F46: 236170
A49: CASH FLOW - derived proxy (USD)
...

Sheet Balance Sheet
A1: Krista Mutual Water Company
A2: Balance Sheet - as reported (USD, end of year)
A3: Entity ID: cawc_0073 | Fiscal year ends December 31.
A5: Line item | B5: FY2020 | C5: FY2021 | D5: FY2022 | E5: FY2023 | F5: FY2024
A6: Assets
A7: Cash | B7: 123966 | C7: 144892 | D7: 158817 | E7: 169486 | F7: 196526
A8: Savings & temporary investments | E8: 0
A9: Accounts receivable | E9: 297116 | F9: 22136
A10: Inventories | E10: 0
A11: Prepaid expenses | E11: 1727 | F11: 735
A12: Property, plant & equipment (gross) | E12: 414658 | F12: 414658
A13: Less: accumulated depreciation | E13: -389125 | F13: -391028
A14: Net property, plant & equipment | E14: 25533 | F14: 23630
A15: Total assets | B15: 175895 | C15: 187873 | D15: 224523 | E15: 498438 | F15: 243027
A17: Liabilities
A18: Accounts payable | E18: 40991
A19: Mortgages & notes payable
A20: Total liabilities | B20: 11129 | C20: 6697 | D20: 96527 | E20: 301287 | F20: 6857
A22: Net Assets / Equity
A23: Capital stock | E23: 107502 | F23: 107502
A24: Paid-in capital | E24: 220469 | F24: 220469
A25: Retained earnings | E25: -130820 | F25: -91801
A26: Net assets | B26: 164766 | C26: 181176 | D26: 127996 | E26: 197151 | F26: 236170
A28: Balance check (assets − liab. − net assets) | B28: 0 | C28: 0 | D28: 0 | E28: 0 | F28: 0
A30: Net PP&E is the reported ppe_net column (gross less accumulated depreciation). The balance check should be ~0 where all three totals are reported; a non-zero value flags a reporting or extraction discrepancy worth reviewing.

Sheet Officers & contractors
A1: Krista Mutual Water Company
A2: Officers, Directors & Contractors - Form 990 Part VII (FY2024; USD)
A3: Entity ID: cawc_0073 | Fiscal year ends December 31.
A5: Section A - Officers, directors, trustees, key employees
A6: Name | B6: Title | C6: Reportable comp (org) | D6: Reportable comp (related) | E6: Other comp | F6: Total compensation
A7: Sandra McElhenney | B7: President | C7: 0 | D7: 0 | E7: 0 | F7: 0
A8: Jonathon Paley | B8: Vice President | C8: 0 | D8: 0 | E8: 0 | F8: 0
A9: Richard Dickerson | B9: Secretary | C9: 0 | D9: 0 | E9: 0 | F9: 0
A11: Section B - Independent contractors (over $100,000)
A12: Contractor | B12: Services | C12: Compensation
A13: Brough Construction Inc | B13: Construction | C13: 103661
A14: Quad Knopf Inc | B14: Engineering | C14: 118263
A16: Section A lists every officer, director, trustee and key employee filed for the latest year; the two with the highest total compensation are highlighted. Total compensation is computed (reportable org + related + other). Section B lists each independent contractor paid over $100,000; the return reports 2 such contractor(s). Source and confidence for every figure are on the Sources & audit tab.

Sheet Revenue (detail)
A1: Krista Mutual Water Company
A2: Revenue - Form 990 Part VIII (USD)
A3: Entity ID: cawc_0073 | Fiscal year ends December 31.
A5: Part VIII line | B5: FY2023 | C5: FY2024
A6: Revenue by category
A7: 1h. Total contributions, gifts, grants | B7: 512655 | C7: not reported
A8: 2g. Total program service revenue | B8: 182500 | C8: 453823
A9: 3. Investment income | B9: 575 | C9: 347
A10: 6d. Net rental income | B10: 0 | C10: not reported
A11: 7d. Net gain/(loss) from investment sales | B11: 0 | C11: not reported
A12: 11e. Other revenue | B12: 0 | C12: not reported
A13: 12. Total revenue | B13: =SUM(B7:B12) | C13: =SUM(C7:C12)
A15: Program service revenue detail - FY2024 (lines 2a-2f)
A16: Description | B16: Business code | C16: Total revenue
A17: Water Assessments | B17: 221000 | C17: 453823
A18: Revenue category subtotals are as filed. Total revenue (line 12) is a live SUM of the category cells above; its tie-out to the filed total is on the Sources & audit tab. Program service revenue detail is shown for the latest year, with its sum-to-line-2g check on that same audit tab.

Sheet Operating expenses (detail)
A1: Krista Mutual Water Company
A2: Statement of Functional Expenses - Form 990 Part IX (USD)
A3: Entity ID: cawc_0073 | Fiscal year ends December 31.
A5: Part IX line (column A Total) | B5: FY2023 | C5: FY2024
A6: Functional expenses, column A Total - by year
A7: 1. Grants to domestic organizations and governments | B7: 0 | C7: not reported
A8: 2. Grants to domestic individuals | B8: 0 | C8: not reported
A9: 3. Grants to foreign organizations and individuals | B9: 0 | C9: not reported
A10: 4. Benefits paid to or for members | B10: 0 | C10: not reported
A11: 5. Compensation of current officers, directors, trustees | B11: 0 | C11: not reported
A12: 6. Compensation to disqualified persons | B12: 0 | C12: not reported
A13: 7. Other salaries and wages | B13: 53841 | C13: 55915
A14: 8. Pension plan accruals and contributions | B14: 0 | C14: not reported
A15: 9. Other employee benefits | B15: 8292 | C15: not reported
A16: 10. Payroll taxes | B16: 4342 | C16: 4543
A17: 11a. Fees for services: management | B17: 0 | C17: not reported
A18: 11b. Fees for services: legal | B18: 2423 | C18: 12660
A19: 11c. Fees for services: accounting | B19: 13605 | C19: 968
A20: 11d. Fees for services: lobbying | B20: 0 | C20: not reported
A21: 11e. Fees for services: professional fundraising | B21: 0 | C21: not reported
A22: 11f. Fees for services: investment management | B22: 0 | C22: not reported
A23: 11g. Fees for services: other | B23: 538521 | C23: not reported
A24: 12. Advertising and promotion | B24: 0 | C24: not reported
A25: 13. Office expenses | B25: 2410 | C25: 3548
A26: 14. Information technology | B26: 0 | C26: not reported
A27: 15. Royalties | B27: 0 | C27: not reported
A28: 16. Occupancy | B28: 3585 | C28: 4470
A29: 17. Travel | B29: 0 | C29: not reported
A30: 18. Payments of travel/entertainment for public officials | B30: 0 | C30: not reported
A31: 19. Conferences, conventions, and meetings | B31: 0 | C31: not reported
A32: 20. Interest | B32: 0 | C32: 74
A33: 21. Payments to affiliates | B33: 0 | C33: not reported
A34: 22. Depreciation, depletion, and amortization | B34: 1914 | C34: 1903
A35: 23. Insurance | B35: 10918 | C35: 18692
A36: 24. POWER | B36: 25425 | C36: not reported
A37: 24. EQUIPMENT RENTAL | B37: 6028 | C37: not reported
A38: 24. Postage and Shipping | B38: 2647 | C38: not reported
A39: 24. TELEPHONE & RELAY | B39: 2595 | C39: not reported
A40: 24. Subcontractors | B40: not reported | C40: 257624
A41: 24. Dues & Subscriptions | B41: not reported | C41: 2299
...

Sheet Balance sheet (detail)
A1: Krista Mutual Water Company
A2: Balance Sheet - Form 990 Part X (end of year, USD)
A3: Entity ID: cawc_0073 | Fiscal year ends December 31.
A5: Part X line (column B, EOY) | B5: FY2023 | C5: FY2024
A6: Assets
A7: 1. Cash - non-interest-bearing | B7: 169486 | C7: 196526
A8: 2. Savings and temporary cash investments | B8: 0 | C8: not reported
A9: 3. Pledges and grants receivable, net | B9: 0 | C9: not reported
A10: 4. Accounts receivable, net | B10: 297116 | C10: 22136
A11: 5. Receivables from officers/directors/trustees | B11: 0 | C11: not reported
A12: 6. Receivables from disqualified persons | B12: 0 | C12: not reported
A13: 7. Notes and loans receivable, net | B13: 0 | C13: not reported
A14: 8. Inventories for sale or use | B14: 0 | C14: not reported
A15: 9. Prepaid expenses and deferred charges | B15: 1727 | C15: 735
A16: 10c. Land, buildings, and equipment, net | B16: 25533 | C16: 23630
A17: 11. Investments - publicly traded securities | B17: 0 | C17: not reported
A18: 12. Investments - other securities | B18: 0 | C18: not reported
A19: 13. Investments - program-related | B19: 0 | C19: not reported
A20: 14. Intangible assets | B20: 0 | C20: not reported
A21: 15. Other assets | B21: 4576 | C21: not reported
A22: 16. Total assets | B22: =SUM(B7:B21) | C22: =SUM(C7:C21)
A24: Liabilities
A25: 17. Accounts payable and accrued expenses | B25: 40991 | C25: not reported
A26: 19. Deferred revenue | B26: 14027 | C26: not reported
A27: 25. Other liabilities | B27: 246269 | C27: 6857
A28: 26. Total liabilities | B28: =SUM(B25:B27) | C28: =SUM(C25:C27)
A30: Net assets / fund balances
A31: 29. Capital stock or trust principal | B31: 107502 | C31: 107502
A32: 30. Paid-in or capital surplus | B32: 220469 | C32: 220469
A33: 31. Retained earnings / accumulated funds | B33: -130820 | C33: -91801
A34: 32. Total net assets / fund balances | B34: =SUM(B31:B33) | C34: =SUM(C31:C33)
A36: Every Part X line is end-of-year (column B), as filed. Section totals (lines 16 / 26 / 32) are live SUMs of the lines above; their tie-outs and the balance-sheet identity (16 = 26 + 32) are on the Sources & audit tab. This filer files as a non-FASB mutual, so net assets sit on lines 29-31 (capital stock / paid-in capital / retained earnings); lines this filer does not report are omitted. Lines 10a/10b net into line 10c (shown).

Sheet Net-assets reconciliation
A1: Krista Mutual Water Company
A2: Reconciliation of Net Assets - Form 990 Part XI (USD)
A3: Entity ID: cawc_0073 | Fiscal year ends December 31.
A5: Part XI line | B5: FY2023 | C5: FY2024
A6: Reconciliation
A7: 4. Net assets, beginning of year | B7: 127997 | C7: 197151
A8: 3. Revenue less expenses | B8: 16783 | C8: 39019
A9: 8. Prior period adjustments | B9: 52371 | C9: not reported
A10: 9. Other changes in net assets | B10: not reported | C10: not reported
A11: 10. Net assets, end of year | B11: =SUM(B7,B8,B9,B10) | C11: =SUM(C7,C8,C9,C10)
A13: Part XI reconciles beginning to ending net assets. Ending net assets (line 10) is a live formula: beginning balance (line 4) + revenue less expenses (line 3) + prior-period adjustments (8) + other changes (9). Its tie-out to the filed line 10 (and to Part X line 32) is on the Sources & audit tab. Lines 5-7 (unrealized gains, donated services, investment expenses) are not filed by this entity.

Sheet Cash flow proxies
A1: Krista Mutual Water Company
A2: Cash Flow Proxies - derived (USD)
A3: Entity ID: cawc_0073 | Fiscal year ends December 31.
A5: PROXY ONLY. The source filings contain no statement of cash flows. Lines below are derived from the reported income statement and year-over-year balance-sheet changes; treat as directional estimates, not GAAP cash flows. The earliest year has no prior period, so its delta cells are blank.
A7: Proxy line (USD) | B7: FY2020 | C7: FY2021 | D7: FY2022 | E7: FY2023 | F7: FY2024
A8: Operating
A9: Net income | B9: 29950 | C9: 16410 | D9: -10480 | E9: 16783 | F9: 39019
A10: + Depreciation (reported) | E10: 1914 | F10: 1903
A11: − Δ Accounts receivable | F11: 274980
A12: − Δ Inventories
A13: − Δ Prepaid expenses | F13: 992
A14: + Δ Accounts payable
A15: Operating cash flow proxy | C15: 16410 | D15: -10480 | E15: 18697 | F15: 316894
A17: Investing
A18: − Δ PP&E gross (capex proxy) | F18: 0
A20: Financing
A21: Δ Mortgages & notes payable
A23: Reconciliation
A24: Δ Cash + temp. investments (actual) | C24: 20926 | D24: 13925 | E24: 10669 | F24: 27040
A26: The capex proxy assumes gross PP&E rises only via capital spending (it ignores disposals). 'Δ Cash + temp. investments (actual)' is the real reported change in liquid funds and is the most reliable line here; the operating/investing/financing proxies will not perfectly reconcile to it.

Sheet Ratios
A1: Krista Mutual Water Company
A2: Financial Ratios
A3: Entity ID: cawc_0073 | Fiscal year ends December 31.
A5: Ratio | B5: FY2020 | C5: FY2021 | D5: FY2022 | E5: FY2023 | F5: FY2024
A6: Profitability (computed upstream)
A7: Operating margin (NI / revenue) | B7: 0.15714443 | C7: 0.082779286 | D7: -0.061901584 | E7: 0.024122864 | F7: 0.085912764
A8: Expense ratio (expenses / revenue) | B8: 0.84285557 | C8: 0.91722071 | D8: 1.0619016 | E8: 0.97587714 | F8: 0.91408724
A9: Return on assets (NI / assets) | B9: 0.17027204 | C9: 0.087346239 | D9: -0.046676732 | E9: 0.033671189 | F9: 0.16055418
A10: Revenue growth (YoY) | F10: -0.34720366
A12: Leverage & solvency
A13: Debt-to-assets (liab. / assets) | B13: 0.063270701 | C13: 0.035646421 | D13: 0.42992032 | E13: 0.60446234 | F13: 0.028214972
A14: Equity ratio (net assets / assets) | B14: 0.9367293 | C14: 0.96435358 | D14: 0.57007968 | E14: 0.39553766 | F14: 0.97178503
A16: Liquidity & asset profile (derived here)
A17: Current ratio (current assets / AP) | E17: 11.425166
A18: Cash ratio ((cash+temp inv.) / total liab.) | B18: 11.139006 | C18: 21.635359 | D18: 1.6453117 | E18: 0.56254004 | F18: 28.660639
A19: Asset age proxy (accum. deprec. / gross PP&E) | E19: 0.93842395 | F19: 0.94301328
A21: Upstream ratios are read from financials_annual; derived ratios are computed only where inputs are reported. Current ratio uses accounts payable as the current-liability proxy (the filings do not split current vs. long-term liabilities). Asset age proxy: a higher % implies older / more depreciated infrastructure.

Sheet Unit economics
A1: Krista Mutual Water Company
A2: Unit economics - per-customer revenue by category (USD)
A3: Entity ID: cawc_0073 | Fiscal year ends December 31.
A5: Every metric here is PER CUSTOMER (a metered service connection). It is not a per-member figure; the member (shareholder) count is a different denominator, shown in the denominator block. The visible cell shows the value and its classification; the numerator, denominator, formula, and rationale are in each metric's LOGIC popup.
A6: Per-customer denominator (service connections) | C6: State Water Board eAR Section 4
A7: Total annual revenue (eAR Section 8b B1.8) | C7: eAR Section 8b total annual revenue not reported for this system.
A8: Primary source
A10: Revenue categories (value, classification, per customer, share)
A11: Revenue category | B11: Classification | C11: Value (USD) | D11: Per customer | E11: Share of revenue
A12: Water sales revenue | B12: not reported | C12: not reported | D12: not reported | E12: not reported
A13: Assessment revenue (990 program-service revenue not matched to eAR water-rate revenue) | B13: IMPOSSIBLE | C13: IMPOSSIBLE | D13: IMPOSSIBLE | E13: IMPOSSIBLE
A14: Meter revenue | B14: not reported | C14: not reported | D14: not reported | E14: not reported
A15: Overage or tiered penalty revenue | B15: not reported | C15: not reported | D15: not reported | E15: not reported
A17: Water sales revenue - not reported
A18: Not reported: this system filed an eAR but no Section 8b revenue block, so there is no filed water-sales figure. Not fallen back to a different year.
A19: Reason: No filed eAR Section 8b water-rate revenue for this system.
A21: Assessment revenue (990 program-service revenue not matched to eAR water-rate revenue) - IMPOSSIBLE
A22: Not computed. A period-aligned residual is not possible for this filer.
A23: Reason: Not derivable. The eAR Section 8b is reporting year None while the Form 990 fiscal year ends None; the two period ends are not aligned, so a period-aligned residual cannot be computed.
A25: Meter revenue - not reported
A26: Not reported. This category is not built because doing so would double-count.
A27: Reason: The eAR Section 8a reports a base/meter rate PRICE, but the filing carries no meter revenue line and no tier volume, and the base charge is already inside the water-sales revenue (eAR Section 8b water rates). Building a separate meter figure would double-count. Not backed into from a total.
A29: Overage or tiered penalty revenue - not reported
A30: Not reported. This category is not built because doing so would double-count.
A31: Reason: The eAR Section 8a reports tiered/overage rate PRICES, but the filing carries no overage revenue and no tier consumption volume, and any overage billed is already inside the water-sales revenue. Building it would double-count. Not backed into from a total.

Sheet Rate structure
A1: Krista Mutual Water Company
A2: Rate structure and representative bill - eAR Section 8a
A3: Entity ID: cawc_0073 | Fiscal year ends December 31.
A5: This block is a rate-schedule illustration at defined usage levels. It is NOT billed revenue and not a claim about any real customer's usage. The revenue side of unit economics is the separate Unit Economics block.
A6: No filed eAR Section 8a rate schedule is staged for this system.

Sheet Operational metrics
A1: Krista Mutual Water Company
A2: Operational metrics - plant per acre, density, terrain
A3: Entity ID: cawc_0073 | Fiscal year ends December 31.
A5: Plant assets per acre
A6: Service-area acres | B6: 89.4 | C6: Geodesic area (WGS84 spherical excess) of the SABL service-area polygon.
A7: Fiscal year | B7: Gross plant per acre (primary) | C7: Net plant per acre
A8: FY2020
A9: FY2021
A10: FY2022
A11: FY2023 | B11: 4638.2327 | C11: 285.604
A12: FY2024 | B12: 4638.2327 | C12: 264.3177
A13: Infrastructure built per acre of service area. Gross plant per acre is the primary read because it measures how much plant the system has put in the ground per acre, and unlike net plant it does not fall over time purely because the assets depreciate on the books. Net plant per acre is shown alongside as the depreciated book value per acre.
A14: Formula: gross plant per acre = Form 990 Part X line 10a (land, buildings, and equipment, gross) / SABL service-area acres; net plant per acre uses Part X line 10c (net)
A15: Source lines: Form 990 Part X line 10a (gross) and line 10c (net); Geodesic area (WGS84 spherical excess) of the SABL service-area polygon.
A16: Confidence: medium. This is worked out from filed figures (a ratio, or a year-to-year change), so it is one step removed from the raw numbers.. Filed gross/net plant over the measured SABL service-area acreage.
A18: Connections per acre
A19: Connections per acre | B19: 2 | C19: 179 connections / 89.4 acres. CA State Water Board SABL SERVICE_CONNECTIONS; Geodesic area (WGS84 spherical excess) of the SABL service-area polygon.

Sheet Supply & weather
A1: Krista Mutual Water Company
A2: Supply and weather indicators (DWR water year)
A3: Entity ID: cawc_0073 | Fiscal year ends December 31.
A5: Reporting calendar: Different reporting periods. The DWR water year runs October 1 to September 30; this system's fiscal year ends December 31, so the two period ends are three months apart. Read the two side by side with that in mind. Neither series is recast: both are reported as filed. A water year is named for the calendar year it ends in, so WY2024 and FY2024 share a number without covering the same twelve months.
A7: Indicator | B7: WY2020 | C7: WY2021 | D7: WY2022 | E7: WY2023 | F7: WY2024
A8: Water-year type (Sacramento Valley) | B8: Dry | C8: Critical | D8: Critical | E8: Wet | F8: Above Normal
A9: Peak drought, county County | B9: not reported | C9: not reported | D9: not reported | E9: not reported | F9: not reported
A10: Precip, percent of normal (8-Station Index) | B10: 63 | C10: 48 | D10: 86 | E10: 133 | F10: 96
A11: Snowpack, April 1 percent of average | B11: 53% | C11: 59% | D11: 38% | E11: 237% | F11: 110%
A12: State Water Project allocation | B12: 20% | C12: 5% | D12: 5% | E12: 100% | F12: 40%

Sheet How this was built
A1: Krista Mutual Water Company
A2: How this was built - forensic lineage
A3: Entity ID: cawc_0073 | Fiscal year ends December 31.
A5: A plain account of the forensic lineage behind the hard-to-source metrics: what sources were checked, what was found, what was derived, and what could not be built and why. Every figure marked DERIVED or IMPOSSIBLE above is traceable to a line here.
A7: Water-sales revenue per customer - not reported
A8: Sources checked | B8: State Water Board eAR Section 8b (water-rate revenue B1.1/B1.2); State Water Board eAR Section 4 (connection count, same reporting year); audited financial statement (secondary cross-check, where published)
A9: What was found | B9: The eAR Section 8b reports water-rate revenue for reporting year None, so this is a DIRECT filed figure; per customer it is divided by the eAR Section 4 connection count for the same reporting year, so numerator and denominator share the year.
A11: Assessment revenue (residual) - IMPOSSIBLE
A12: Sources checked | B12: Form 990 Part VIII line 2 (program-service revenue); State Water Board eAR Section 8b (water-rate revenue B1.1/B1.2); eAR Section 8b filer comment (WRRevenueComments)
A13: What was found | B13: A period-aligned residual cannot be computed for this filer, so the metric is rendered IMPOSSIBLE rather than guessed.
A14: Caveat | B14: Not derivable. The eAR Section 8b is reporting year None while the Form 990 fiscal year ends None; the two period ends are not aligned, so a period-aligned residual cannot be computed.
A16: Meter revenue - not reported
A17: Sources checked | B17: State Water Board eAR Section 8a (rate prices); State Water Board eAR Section 8b (revenue lines); audited financial statement
A18: What was found | B18: The rate price exists in Section 8a but no revenue or tier volume is reported, and the base charge is already inside water sales.
A19: Caveat | B19: The eAR Section 8a reports a base/meter rate PRICE, but the filing carries no meter revenue line and no tier volume, and the base charge is already inside the water-sales revenue (eAR Section 8b water rates). Building a separate meter figure would double-count. Not backed into from a total.
A21: Overage / tiered-penalty revenue - not reported
A22: Sources checked | B22: State Water Board eAR Section 8a (rate prices); State Water Board eAR Section 8b (revenue lines); audited financial statement
A23: What was found | B23: The rate price exists in Section 8a but no revenue or tier volume is reported, and the base charge is already inside water sales.
A24: Caveat | B24: The eAR Section 8a reports tiered/overage rate PRICES, but the filing carries no overage revenue and no tier consumption volume, and any overage billed is already inside the water-sales revenue. Building it would double-count. Not backed into from a total.
A26: eAR Section 8b reporting-period basis - sourced
A27: Sources checked | B27: eAR Section 8b B0.1 (WRFinancialReportingPeriod); eAR Section 8b B0.2 (WRFiscalYearStartDate)
A28: What was found | B28: The reporting basis (fiscal vs calendar year) is read from the filer's own B0.1/B0.2 answer and staged verbatim, never hardcoded, so the 990 comparison and the residual are period-aligned.
A30: Member (shareholder) count denominator - not reported
A31: Sources checked | B31: Form 990 (no member count stated); company website
A32: What was found | B32: No filing states a member/shareholder count, so the per-member unit economics read not reported rather than borrowing the connection count.
A34: Water volume delivered (acre-feet) - not reported
A35: Sources checked | B35: Form 990 (not in the filing); Consumer Confidence Report; eAR Section 6 (PRA-gated)
A36: What was found | B36: Volume delivered in acre-feet is not in the Form 990 and the CCR states only a source mix, so the per-acre-foot metrics read not reported; the eAR Section 6 is named as the source still needed.

Sheet Anomaly Flags
A1: Krista Mutual Water Company
A2: Anomaly Flags (automated; kept separate from the clean statements)
A3: Entity ID: cawc_0073 | Fiscal year ends December 31.
A5: Material irregularities found automatically in the filed financials by the Hydronomics anomaly flagger. Each flag has two clearly separated layers. WHAT is mechanical, certain, and sourced: the exact filed lines, years, and amounts, carried as filed and never reconciled. WHY is attempted: the filing's own narrative is checked first, and when it states no reason a single best-guess hypothesis is shown, clearly labelled as a guess that is not in the filing and is not a verified figure.
A7: Flag: FY2022 opening net assets differ from FY2021 closing
A8: Affected figure | B8: Net assets FY2022
A9: Confidence | B9: high
A10: What happened (filed, sourced) | B10: The company filed $138,476 as its beginning net assets for FY2022 and $181,176 as its ending net assets for FY2021, a difference of $-42,700. Both figures are carried exactly as each year's own filing reports them. Neither is adjusted to match the other.
A11: Source lines | B11: - FY2022 net assets, beginning of year (as filed): $138,476 - FY2021 net assets, end of year (as filed): $181,176 - Difference: $-42,700
A12: Confidence reasoning | B12: Both are direct filed line items read from two different returns, so the difference between them is high confidence as an observation. What caused it is not stated on either form.
A13: Why (not stated in the filing) | B13: The filing does not state a reason.
A14: Possible explanation (guess) | B14: Possible explanation, not stated in filing: a beginning balance that differs from the prior year's ending balance usually means the earlier year was restated, or a balance-sheet line was reclassified between the two filings. This is an educated guess, not something either filing says.
A16: Flag: FY2023 opening net assets differ from FY2022 closing
A17: Affected figure | B17: Net assets FY2023
A18: Confidence | B18: high
A19: What happened (filed, sourced) | B19: The company filed $127,997 as its beginning net assets for FY2023 and $127,996 as its ending net assets for FY2022, a difference of $1. Both figures are carried exactly as each year's own filing reports them. Neither is adjusted to match the other.
A20: Source lines | B20: - FY2023 net assets, beginning of year (as filed): $127,997 - FY2022 net assets, end of year (as filed): $127,996 - Difference: $1
A21: Confidence reasoning | B21: Both are direct filed line items read from two different returns, so the difference between them is high confidence as an observation. What caused it is not stated on either form.
A22: Why (not stated in the filing) | B22: The filing does not state a reason.
A23: Possible explanation (guess) | B23: Possible explanation, not stated in filing: a beginning balance that differs from the prior year's ending balance usually means the earlier year was restated, or a balance-sheet line was reclassified between the two filings. This is an educated guess, not something either filing says.

Sheet Sources & audit
A1: Krista Mutual Water Company
A2: Sources & audit - full provenance and tie-outs (kept off the statements so they read clean)
A3: Entity ID: cawc_0073 | Fiscal year ends December 31.
A5: Presentation standard: every figure on the statement tabs is verified to its source filing and shown clean. A cell the filing does not report reads "not reported" (never estimated, never guessed).
A6: Citations, confidence tiers, and the filed-vs-computed tie-out checks live on the "Sources & audit" tab, keyed by cell, so every number is fully traceable without cluttering the statements. These pages are ready to use as filed.
A8: A. Filing provenance (one row per staged extraction)
A9: Fiscal year | B9: Period end | C9: Filing type | D9: Confidence | E9: Extraction ID | F9: Object ID | G9: Extracted by | H9: Extracted at | I9: Source URL
A10: FY2020 | B10: 2020-12-31 | C10: 990-EZ | D10: high | E10: 51def515-6152-4616-9c3b-c689d9b31084 | F10: 202112879349200936 | G10: claude-opus-5 | H10: 2026-09-21T02:49:59+00:00 | I10: https://apps.irs.gov/pub/epostcard/990/xml/2021/2021_TEOS_XML_01A.zip#202112879349200936_public.xml
A11: FY2021 | B11: 2021-12-31 | C11: 990-EZ | D11: high | E11: 87661124-09d9-4898-98a4-a73c7e4d75c7 | F11: 202242729349200139 | G11: claude-opus-5 | H11: 2026-09-21T02:49:59+00:00 | I11: https://apps.irs.gov/pub/epostcard/990/xml/2022/2022_TEOS_XML_01A.zip#202242729349200139_public.xml
A12: FY2022 | B12: 2022-12-31 | C12: 990-EZ | D12: high | E12: 64b67970-2ed4-4837-b45f-73e820805765 | F12: 202331799349200443 | G12: claude-opus-5 | H12: 2026-09-21T02:49:59+00:00 | I12: https://apps.irs.gov/pub/epostcard/990/xml/2023/2023_TEOS_XML_07A.zip#202331799349200443_public.xml
A13: FY2023 | B13: 2023-12-31 | C13: 990 | D13: high | E13: a192608d-f184-4294-af6f-a2554f1b00c9 | F13: 202432569349301238 | G13: claude-opus-5 | H13: 2026-09-21T02:49:59+00:00 | I13: https://apps.irs.gov/pub/epostcard/990/xml/2024/2024_TEOS_XML_09A.zip#202432569349301238_public.xml
A14: FY2024 | B14: 2024-12-31 | C14: 990 | D14: high | E14: 7985e235-79df-475e-9908-b8036ffc631e | F14: 202511329349305721 | G14: claude-opus-5 | H14: 2026-09-21T02:49:59+00:00 | I14: https://apps.irs.gov/pub/epostcard/990/xml/2025/2025_TEOS_XML_05A.zip#202511329349305721_public.xml
A16: B. Figure citations (every figure on the statement tabs, keyed by cell)
A17: Tab | B17: Cell | C17: Line item | D17: Form 990 line | E17: Key path | F17: Confidence | G17: As filed
A18: Financial Statements | B18: B73 | C18: 11a. Gross income from members or shareholders | D18: 11a | E18: part_v_other_irs_filings.members_and_shareholders_gross_income | F18: high | G18: 182500
A19: Financial Statements | B19: C73 | C19: 11a. Gross income from members or shareholders | D19: 11a | E19: part_v_other_irs_filings.members_and_shareholders_gross_income | F19: high | G19: 453823
A20: Financial Statements | B20: C74 | C20: 11b. Gross income from other sources | D20: 11b | E20: part_v_other_irs_filings.other_sources_gross_income | F20: high | G20: 0
A21: Revenue (detail) | B21: B7 | C21: 1h. Total contributions, gifts, grants | D21: 1h | E21: part_viii_revenue.total_contributions | F21: high | G21: 512655
A22: Revenue (detail) | B22: B8 | C22: 2g. Total program service revenue | D22: 2g | E22: part_viii_revenue.total_program_service_revenue | F22: high | G22: 182500
A23: Revenue (detail) | B23: C8 | C23: 2g. Total program service revenue | D23: 2g | E23: part_viii_revenue.total_program_service_revenue | F23: high | G23: 453823
A24: Revenue (detail) | B24: B9 | C24: 3. Investment income | D24: 3 | E24: part_viii_revenue.investment_income | F24: high | G24: 575
A25: Revenue (detail) | B25: C9 | C25: 3. Investment income | D25: 3 | E25: part_viii_revenue.investment_income | F25: high | G25: 347
A26: Revenue (detail) | B26: B10 | C26: 6d. Net rental income | D26: 6d | E26: part_viii_revenue.net_rental_income | F26: high | G26: 0
A27: Revenue (detail) | B27: B11 | C27: 7d. Net gain/(loss) from investment sales | D27: 7d | E27: part_viii_revenue.net_gain_or_loss_investments | F27: high | G27: 0
A28: Revenue (detail) | B28: B12 | C28: 11e. Other revenue | D28: 11e | E28: part_viii_revenue.other_revenue_total | F28: high | G28: 0
A29: Operating expenses (detail) | B29: B7 | C29: 1. Grants to domestic organizations and governments | D29: 1 | E29: part_ix_expenses.grants_domestic_orgs | F29: high | G29: 0
... A102: Net-assets reconciliation | B102: B9 | C102: 8. Prior period adjustments | D102: Part XI line 8 | E102: part_xi_reconciliation.prior_period_adjustments | F102: high | G102: 52371
A104: C. Tie-out checks (filed vs computed; any nonzero variance is flagged red)
A105: Tab | B105: Check | C105: Fiscal year | D105: Filed | E105: Computed | F105: Variance (computed - filed)
A106: Revenue (detail) | B106: 12. Total revenue | C106: FY2023 | D106: 695730 | E106: ='Revenue (detail)'!B13 | F106: =E106-D106
A107: Revenue (detail) | B107: 12. Total revenue | C107: FY2024 | D107: 454170 | E107: ='Revenue (detail)'!C13 | F107: =E107-D107
A108: Revenue (detail) | B108: 2g program service revenue = sum of lines 2a-2f (FY2024) | C108: FY2024 | D108: 453823 | E108: =SUM('Revenue (detail)'!C17:C17) | F108: =E108-D108
A109: Operating expenses (detail) | B109: 25. Total functional expenses | C109: FY2023 | D109: 678947 | E109: ='Operating expenses (detail)'!B45 | F109: =E109-D109
A110: Operating expenses (detail) | B110: 25. Total functional expenses | C110: FY2024 | D110: 415151 | E110: ='Operating expenses (detail)'!C45 | F110: =E110-D110
A111: Operating expenses (detail) | B111: Part IX column split: col A = B + C + D (FY2024) | C111: FY2024 | D111: ='Operating expenses (detail)'!B58 | E111: ='Operating expenses (detail)'!C58+'Operating expenses (detail)'!D58+'Operating expenses (detail)'!E58 | F111: =E111-D111
A112: Balance sheet (detail) | B112: 16. Total assets | C112: FY2023 | D112: 498438 | E112: ='Balance sheet (detail)'!B22 | F112: =E112-D112
A113: Balance sheet (detail) | B113: 16. Total assets | C113: FY2024 | D113: 243027 | E113: ='Balance sheet (detail)'!C22 | F113: =E113-D113
A114: Balance sheet (detail) | B114: 26. Total liabilities | C114: FY2023 | D114: 301287 | E114: ='Balance sheet (detail)'!B28 | F114: =E114-D114
A115: Balance sheet (detail) | B115: 26. Total liabilities | C115: FY2024 | D115: 6857 | E115: ='Balance sheet (detail)'!C28 | F115: =E115-D115
A116: Balance sheet (detail) | B116: 32. Total net assets / fund balances | C116: FY2023 | D116: 197151 | E116: ='Balance sheet (detail)'!B34 | F116: =E116-D116
...

Sheet Provenance
A1: Build provenance | B1: Built from source commit d418ffb17485 (2026-10-06); source fingerprint a75a8eee82c65cf7; 192 companies (179 retail mutual, 4 irrigation mutual, 3 mutual, no PWSID, purpose not stated, 2 frozen non-mutual (special district), 2 wholesale mutual, 1 frozen non-mutual (investor-owned), 1 frozen non-mutual (municipal)); 91 gates; build id 3d08d6d2a855.
A2: source_commit | B2: d418ffb174855ab78000d391d42f898397b0d8aa
A3: source_commit_date | B3: 2026-10-06
A4: source_fingerprint | B4: a75a8eee82c65cf7096931f06e18affdc28686a02895b46538e7298b57c04d94
A5: gate_count | B5: 91
A6: build_id | B6: 3d08d6d2a855
A7: registry: frozen non-mutual (investor-owned) | B7: 1
A8: registry: frozen non-mutual (municipal) | B8: 1
A9: registry: frozen non-mutual (special district) | B9: 2
A10: registry: irrigation mutual | B10: 4
A11: registry: mutual, no PWSID, purpose not stated | B11: 3
A12: registry: retail mutual | B12: 179
A13: registry: wholesale mutual | B13: 2
