Workbook

Sheet Summary
A1: Santa Ynez Rancho Estates Mutual Water Company
A2: Financial Summary - multi-year overview (USD)
A3: Entity ID: cawc_0021 | Fiscal year ends December 31.
A5: Presentation standard: every figure on the statement tabs is verified to its source filing and shown clean. A cell the filing does not report reads "not reported" (never estimated, never guessed).
A6: Citations, confidence tiers, and the filed-vs-computed tie-out checks live on the "Sources & audit" tab, keyed by cell, so every number is fully traceable without cluttering the statements. These pages are ready to use as filed.
A8: Metric | B8: FY2020 | C8: FY2021 | D8: FY2022 | E8: FY2023 | F8: FY2024 | G8: FY2025
A9: Operating results (USD)
A10: Total revenue | B10: 218111 | C10: 248246 | D10: 213691 | E10: 248919 | F10: 413938 | G10: 546703
A11: Total expenses | B11: 207980 | C11: 224644 | D11: 272676 | E11: 244236 | F11: 277639 | G11: 345598
A12: Net income | B12: 10131 | C12: 23602 | D12: -58985 | E12: 4683 | F12: 136299 | G12: 201105
A14: Financial position (USD, end of year)
A15: Total assets | B15: 555310 | C15: 579212 | D15: 517777 | E15: 522460 | F15: 658759 | G15: 859864
A16: Total liabilities | B16: 0 | C16: 0 | D16: 0 | E16: 0 | F16: 0 | G16: 0
A17: Net assets | B17: 555310 | C17: 579212 | D17: 517777 | E17: 522460 | F17: 658759 | G17: 859864
A19: Headline ratios
A20: Operating margin | B20: 0.046448827 | C20: 0.095075047 | D20: -0.27602941 | E20: 0.018813349 | F20: 0.32927395 | G20: 0.36785055
A21: Revenue growth (YoY) | B21: 0.13213257 | C21: 0.1381636 | D21: -0.1391966 | E21: 0.16485486 | F21: 0.66294256 | G21: 0.32073644
A22: Return on assets | B22: 0.018243864 | C22: 0.040748465 | D22: -0.1139197 | E22: 0.0089633656 | F22: 0.20690268 | G22: 0.23388001
A24: Figures as reported in source filings (full provenance on the Sources & audit tab). Parentheses denote negatives; ratios are computed upstream in financials_annual.

Sheet Notes
A1: Notes
A2: Human annotations from the versioned store (data/notes/). Annotations only: they never change a reported figure or a confidence tier.
A4: Date | B4: Tag | C4: Author | D4: Note
A5: No notes recorded yet.

Sheet Financial Statements
A1: Santa Ynez Rancho Estates Mutual Water Company
A2: Financial Statements - income statement, balance sheet, cash flow, member income test (USD)
A3: Entity ID: cawc_0021 | Fiscal year ends December 31.
A5: INCOME STATEMENT - as reported (USD)
A6: Line item | B6: FY2020 | C6: FY2021 | D6: FY2022 | E6: FY2023 | F6: FY2024 | G6: FY2025
A7: Revenue
A8: Program service revenue | B8: 215819 | C8: 248239 | D8: 213691 | E8: 248215 | F8: 409534 | G8: 540118
A9: Investment income | B9: 2292 | C9: 7 | E9: 704 | G9: 6585
A10: Net rental income
A11: Net gain/(loss) on investment sales
A12: Other revenue | F12: 4404
A13: Contributions & grants
A14: Total revenue | B14: 218111 | C14: 248246 | D14: 213691 | E14: 248919 | F14: 413938 | G14: 546703
A16: Expenses
A17: Depreciation | B17: 26984 | C17: 26305 | D17: 27282 | E17: 29059 | F17: 33327 | G17: 38220
A18: Interest expense
A19: Total expenses | B19: 207980 | C19: 224644 | D19: 272676 | E19: 244236 | F19: 277639 | G19: 345598
A21: Net income | B21: 10131 | C21: 23602 | D21: -58985 | E21: 4683 | F21: 136299 | G21: 201105
A24: BALANCE SHEET - as reported (USD, end of year)
A25: Line item | B25: FY2020 | C25: FY2021 | D25: FY2022 | E25: FY2023 | F25: FY2024 | G25: FY2025
A26: Assets
A27: Cash | B27: 280687 | C27: 330893 | D27: 237139 | E27: 147642 | F27: 198771 | G27: 235656
A28: Savings & temporary investments | E28: 100704 | F28: 105036 | G28: 257721
A29: Accounts receivable
A30: Inventories
A31: Prepaid expenses
A32: Property, plant & equipment (gross) | B32: 828256 | C32: 828256 | D32: 879802 | E32: 902337 | F32: 1016429 | G32: 1066184
A33: Less: accumulated depreciation | B33: -553633 | C33: -579937 | D33: -599164 | E33: -628223 | F33: -661477 | G33: -699697
A34: Net property, plant & equipment | B34: 274623 | C34: 248319 | D34: 280638 | E34: 274114 | F34: 354952 | G34: 366487
A35: Total assets | B35: 555310 | C35: 579212 | D35: 517777 | E35: 522460 | F35: 658759 | G35: 859864
A37: Liabilities
A38: Accounts payable
A39: Mortgages & notes payable
A40: Total liabilities | B40: 0 | C40: 0 | D40: 0 | E40: 0 | F40: 0 | G40: 0
A42: Net Assets / Equity
A43: Capital stock
A44: Paid-in capital
A45: Retained earnings | B45: 555310 | C45: 579212 | D45: 517777 | E45: 522460 | F45: 658759 | G45: 859864
A46: Net assets | B46: 555310 | C46: 579212 | D46: 517777 | E46: 522460 | F46: 658759 | G46: 859864
A49: CASH FLOW - derived proxy (USD)
...

Sheet Balance Sheet
A1: Santa Ynez Rancho Estates Mutual Water Company
A2: Balance Sheet - as reported (USD, end of year)
A3: Entity ID: cawc_0021 | Fiscal year ends December 31.
A5: Line item | B5: FY2020 | C5: FY2021 | D5: FY2022 | E5: FY2023 | F5: FY2024 | G5: FY2025
A6: Assets
A7: Cash | B7: 280687 | C7: 330893 | D7: 237139 | E7: 147642 | F7: 198771 | G7: 235656
A8: Savings & temporary investments | E8: 100704 | F8: 105036 | G8: 257721
A9: Accounts receivable
A10: Inventories
A11: Prepaid expenses
A12: Property, plant & equipment (gross) | B12: 828256 | C12: 828256 | D12: 879802 | E12: 902337 | F12: 1016429 | G12: 1066184
A13: Less: accumulated depreciation | B13: -553633 | C13: -579937 | D13: -599164 | E13: -628223 | F13: -661477 | G13: -699697
A14: Net property, plant & equipment | B14: 274623 | C14: 248319 | D14: 280638 | E14: 274114 | F14: 354952 | G14: 366487
A15: Total assets | B15: 555310 | C15: 579212 | D15: 517777 | E15: 522460 | F15: 658759 | G15: 859864
A17: Liabilities
A18: Accounts payable
A19: Mortgages & notes payable
A20: Total liabilities | B20: 0 | C20: 0 | D20: 0 | E20: 0 | F20: 0 | G20: 0
A22: Net Assets / Equity
A23: Capital stock
A24: Paid-in capital
A25: Retained earnings | B25: 555310 | C25: 579212 | D25: 517777 | E25: 522460 | F25: 658759 | G25: 859864
A26: Net assets | B26: 555310 | C26: 579212 | D26: 517777 | E26: 522460 | F26: 658759 | G26: 859864
A28: Balance check (assets − liab. − net assets) | B28: 0 | C28: 0 | D28: 0 | E28: 0 | F28: 0 | G28: 0
A30: Net PP&E is the reported ppe_net column (gross less accumulated depreciation). The balance check should be ~0 where all three totals are reported; a non-zero value flags a reporting or extraction discrepancy worth reviewing.

Sheet Officers & contractors
A1: Santa Ynez Rancho Estates Mutual Water Company
A2: Officers, Directors & Contractors - Form 990 Part VII (FY2025; USD)
A3: Entity ID: cawc_0021 | Fiscal year ends December 31.
A5: Section A - Officers, directors, trustees, key employees
A6: Name | B6: Title | C6: Reportable comp (org) | D6: Reportable comp (related) | E6: Other comp | F6: Total compensation
A7: KIM SWITZER | B7: PRESIDENT | C7: 0 | D7: 0 | E7: 0 | F7: 0
A8: DAVE CHACKEL | B8: VICE PRESIDENT-OPERATIONS | C8: 0 | D8: 0 | E8: 0 | F8: 0
A9: CRAIG JURATSCH | B9: VICE PRESIDENT-REGULATORY | C9: 0 | D9: 0 | E9: 0 | F9: 0
A10: BRIAN CULACIATI | B10: SECRETARY | C10: 0 | D10: 0 | E10: 0 | F10: 0
A11: HOWARD ERENBERG | B11: TREASURER | C11: 0 | D11: 0 | E11: 0 | F11: 0
A13: Section B - Independent contractors (over $100,000)
A14: Contractor | B14: Services | C14: Compensation
A16: Section A lists every officer, director, trustee and key employee filed for the latest year; the two with the highest total compensation are highlighted. Total compensation is computed (reportable org + related + other). Section B lists each independent contractor paid over $100,000; the return reports None such contractor(s). Source and confidence for every figure are on the Sources & audit tab.

Sheet Revenue (detail)
A1: Santa Ynez Rancho Estates Mutual Water Company
A2: Revenue - Form 990 Part VIII (USD)
A3: Entity ID: cawc_0021 | Fiscal year ends December 31.
A5: Part VIII line | B5: FY2020 | C5: FY2021 | D5: FY2022 | E5: FY2023 | F5: FY2024 | G5: FY2025
A6: Revenue by category
A7: 1h. Total contributions, gifts, grants | B7: not reported | C7: not reported | D7: not reported | E7: not reported | F7: not reported | G7: not reported
A8: 2g. Total program service revenue | B8: 215819 | C8: 248239 | D8: 213691 | E8: 248215 | F8: 409534 | G8: 540118
A9: 3. Investment income | B9: 2292 | C9: 7 | D9: not reported | E9: 704 | F9: not reported | G9: 6585
A10: 6d. Net rental income | B10: not reported | C10: not reported | D10: not reported | E10: not reported | F10: not reported | G10: not reported
A11: 7d. Net gain/(loss) from investment sales | B11: not reported | C11: not reported | D11: not reported | E11: not reported | F11: not reported | G11: not reported
A12: 11e. Other revenue | B12: not reported | C12: not reported | D12: not reported | E12: not reported | F12: 4404 | G12: not reported
A13: 12. Total revenue | B13: =SUM(B7:B12) | C13: =SUM(C7:C12) | D13: =SUM(D7:D12) | E13: =SUM(E7:E12) | F13: =SUM(F7:F12) | G13: =SUM(G7:G12)
A15: Program service revenue detail - FY2025 (lines 2a-2f)
A16: Description | B16: Business code | C16: Total revenue
A17: WATER USAGE | B17: 221000 | C17: 431549
A18: SPEC ASSESMENT WELL 4 | B18: 221000 | C18: 108569
A19: Revenue category subtotals are as filed. Total revenue (line 12) is a live SUM of the category cells above; its tie-out to the filed total is on the Sources & audit tab. Program service revenue detail is shown for the latest year, with its sum-to-line-2g check on that same audit tab.

Sheet Operating expenses (detail)
A1: Santa Ynez Rancho Estates Mutual Water Company
A2: Statement of Functional Expenses - Form 990 Part IX (USD)
A3: Entity ID: cawc_0021 | Fiscal year ends December 31.
A5: Part IX line (column A Total) | B5: FY2020 | C5: FY2021 | D5: FY2022 | E5: FY2023 | F5: FY2024 | G5: FY2025
A6: Functional expenses, column A Total - by year
A7: 11b. Fees for services: legal | B7: not reported | C7: not reported | D7: not reported | E7: not reported | F7: 2783 | G7: 10572
A8: 11c. Fees for services: accounting | B8: 14760 | C8: 16730 | D8: 18650 | E8: 22872 | F8: 26754 | G8: 28310
A9: 13. Office expenses | B9: 1748 | C9: 1206 | D9: 2388 | E9: 3253 | F9: 742 | G9: 2590
A10: 22. Depreciation, depletion, and amortization | B10: 26984 | C10: 26305 | D10: 27282 | E10: 29059 | F10: 33327 | G10: 38220
A11: 23. Insurance | B11: 2073 | C11: 2289 | D11: 2538 | E11: 2775 | F11: 4190 | G11: 5321
A12: 24. UTILITIES | B12: 93356 | C12: 94300 | D12: 107931 | E12: 106673 | F12: 108818 | G12: 110930
A13: 24. REPAIRS & MAINTENANCE | B13: 29453 | C13: 29367 | D13: 29577 | E13: 40468 | F13: 50073 | G13: 54657
A14: 24. WATER TESTING | B14: 18926 | C14: 20030 | D14: 23626 | E14: 23007 | F14: 33288 | G14: 42239
A15: 24. METER READ & BACKFLOW TEST | B15: 10906 | C15: 14380 | D15: 8253 | E15: 7590 | F15: not reported | G15: not reported
A16: 24. SGMA EXPENSESHYDROLOGICAL C | B16: not reported | C16: not reported | D16: not reported | E16: not reported | F16: not reported | G16: 28256
A17: 24e. All other expenses | B17: 9774 | C17: 20037 | D17: 52431 | E17: 8539 | F17: 17664 | G17: 24503
A18: 25. Total functional expenses | B18: =SUM(B7:B17) | C18: =SUM(C7:C17) | D18: =SUM(D7:D17) | E18: =SUM(E7:E17) | F18: =SUM(F7:F17) | G18: =SUM(G7:G17)
A20: Functional column split - FY2025 (col A = B + C + D)
A21: Part IX line | B21: A. Total | C21: B. Program services | D21: C. Management & general | E21: D. Fundraising
A22: 11b. Fees for services: legal | B22: 10572 | C22: 10572
A23: 11c. Fees for services: accounting | B23: 28310 | C23: 25510 | D23: 2800
A24: 13. Office expenses | B24: 2590 | C24: 2590
A25: 22. Depreciation, depletion, and amortization | B25: 38220 | C25: 38220
A26: 23. Insurance | B26: 5321 | C26: 5321
A27: 25. Total (filed col A / B / C / D) | B27: 345598 | C27: 342798 | D27: 2800 | E27: 0
A29: Top block: each Part IX line, column A (Total), by year, as filed. Total functional expenses (line 25) is a live SUM of the line cells; its tie-out to the filed total is on the Sources & audit tab. Filer-itemized 24a-24d rows show the most recent year's as-filed wording; rows are aligned across years case-insensitively with collapsed spacing, so a line filed only in a different capitalization or spacing shares one row, while genuinely different wording stays a separate row (every as-filed variant is recorded on the Sources & audit tab). Lower block: the program / management / fundraising split for the latest year, with its col A = B + C + D check on the audit tab. Lines this filer does not report are omitted rather than shown empty.

Sheet Balance sheet (detail)
A1: Santa Ynez Rancho Estates Mutual Water Company
A2: Balance Sheet - Form 990 Part X (end of year, USD)
A3: Entity ID: cawc_0021 | Fiscal year ends December 31.
A5: Part X line (column B, EOY) | B5: FY2020 | C5: FY2021 | D5: FY2022 | E5: FY2023 | F5: FY2024 | G5: FY2025
A6: Assets
A7: 1. Cash - non-interest-bearing | B7: 280687 | C7: 330893 | D7: 237139 | E7: 147642 | F7: 198771 | G7: 235656
A8: 2. Savings and temporary cash investments | B8: not reported | C8: not reported | D8: not reported | E8: 100704 | F8: 105036 | G8: 257721
A9: 10c. Land, buildings, and equipment, net | B9: 274623 | C9: 248319 | D9: 280638 | E9: 274114 | F9: 354952 | G9: 366487
A10: 16. Total assets | B10: =SUM(B7:B9) | C10: =SUM(C7:C9) | D10: =SUM(D7:D9) | E10: =SUM(E7:E9) | F10: =SUM(F7:F9) | G10: =SUM(G7:G9)
A12: Liabilities
A13: 26. Total liabilities | B13: =SUM(B13:B12) | C13: =SUM(C13:C12) | D13: =SUM(D13:D12) | E13: =SUM(E13:E12) | F13: =SUM(F13:F12) | G13: =SUM(G13:G12)
A15: Net assets / fund balances
A16: 31. Retained earnings / accumulated funds | B16: 555310 | C16: 579212 | D16: 517777 | E16: 522460 | F16: 658759 | G16: 859864
A17: 32. Total net assets / fund balances | B17: =SUM(B16:B16) | C17: =SUM(C16:C16) | D17: =SUM(D16:D16) | E17: =SUM(E16:E16) | F17: =SUM(F16:F16) | G17: =SUM(G16:G16)
A19: Every Part X line is end-of-year (column B), as filed. Section totals (lines 16 / 26 / 32) are live SUMs of the lines above; their tie-outs and the balance-sheet identity (16 = 26 + 32) are on the Sources & audit tab. This filer files as a non-FASB mutual, so net assets sit on lines 29-31 (capital stock / paid-in capital / retained earnings); lines this filer does not report are omitted. Lines 10a/10b net into line 10c (shown).

Sheet Net-assets reconciliation
A1: Santa Ynez Rancho Estates Mutual Water Company
A2: Reconciliation of Net Assets - Form 990 Part XI (USD)
A3: Entity ID: cawc_0021 | Fiscal year ends December 31.
A5: Part XI line | B5: FY2020 | C5: FY2021 | D5: FY2022 | E5: FY2023 | F5: FY2024 | G5: FY2025
A6: Reconciliation
A7: 4. Net assets, beginning of year | B7: 544579 | C7: 555310 | D7: 579212 | E7: 517777 | F7: 522460 | G7: 658759
A8: 3. Revenue less expenses | B8: 10131 | C8: 23602 | D8: -58985 | E8: 4683 | F8: 136299 | G8: 201105
A9: 8. Prior period adjustments | B9: not reported | C9: not reported | D9: not reported | E9: not reported | F9: not reported | G9: not reported
A10: 9. Other changes in net assets | B10: 600 | C10: 300 | D10: -2450 | E10: 0 | F10: 0 | G10: 0
A11: 10. Net assets, end of year | B11: =SUM(B7,B8,B9,B10) | C11: =SUM(C7,C8,C9,C10) | D11: =SUM(D7,D8,D9,D10) | E11: =SUM(E7,E8,E9,E10) | F11: =SUM(F7,F8,F9,F10) | G11: =SUM(G7,G8,G9,G10)
A13: Part XI reconciles beginning to ending net assets. Ending net assets (line 10) is a live formula: beginning balance (line 4) + revenue less expenses (line 3) + prior-period adjustments (8) + other changes (9). Its tie-out to the filed line 10 (and to Part X line 32) is on the Sources & audit tab. Lines 5-7 (unrealized gains, donated services, investment expenses) are not filed by this entity.

Sheet Cash flow proxies
A1: Santa Ynez Rancho Estates Mutual Water Company
A2: Cash Flow Proxies - derived (USD)
A3: Entity ID: cawc_0021 | Fiscal year ends December 31.
A5: PROXY ONLY. The source filings contain no statement of cash flows. Lines below are derived from the reported income statement and year-over-year balance-sheet changes; treat as directional estimates, not GAAP cash flows. The earliest year has no prior period, so its delta cells are blank.
A7: Proxy line (USD) | B7: FY2020 | C7: FY2021 | D7: FY2022 | E7: FY2023 | F7: FY2024 | G7: FY2025
A8: Operating
A9: Net income | B9: 10131 | C9: 23602 | D9: -58985 | E9: 4683 | F9: 136299 | G9: 201105
A10: + Depreciation (reported) | B10: 26984 | C10: 26305 | D10: 27282 | E10: 29059 | F10: 33327 | G10: 38220
A11: − Δ Accounts receivable
A12: − Δ Inventories
A13: − Δ Prepaid expenses
A14: + Δ Accounts payable
A15: Operating cash flow proxy | C15: 49907 | D15: -31703 | E15: 33742 | F15: 169626 | G15: 239325
A17: Investing
A18: − Δ PP&E gross (capex proxy) | C18: 0 | D18: -51546 | E18: -22535 | F18: -114092 | G18: -49755
A20: Financing
A21: Δ Mortgages & notes payable
A23: Reconciliation
A24: Δ Cash + temp. investments (actual) | C24: 50206 | D24: -93754 | E24: 11207 | F24: 55461 | G24: 189570
A26: The capex proxy assumes gross PP&E rises only via capital spending (it ignores disposals). 'Δ Cash + temp. investments (actual)' is the real reported change in liquid funds and is the most reliable line here; the operating/investing/financing proxies will not perfectly reconcile to it.

Sheet Ratios
A1: Santa Ynez Rancho Estates Mutual Water Company
A2: Financial Ratios
A3: Entity ID: cawc_0021 | Fiscal year ends December 31.
A5: Ratio | B5: FY2020 | C5: FY2021 | D5: FY2022 | E5: FY2023 | F5: FY2024 | G5: FY2025
A6: Profitability (computed upstream)
A7: Operating margin (NI / revenue) | B7: 0.046448827 | C7: 0.095075047 | D7: -0.27602941 | E7: 0.018813349 | F7: 0.32927395 | G7: 0.36785055
A8: Expense ratio (expenses / revenue) | B8: 0.95355117 | C8: 0.90492495 | D8: 1.2760294 | E8: 0.98118665 | F8: 0.67072605 | G8: 0.63214945
A9: Return on assets (NI / assets) | B9: 0.018243864 | C9: 0.040748465 | D9: -0.1139197 | E9: 0.0089633656 | F9: 0.20690268 | G9: 0.23388001
A10: Revenue growth (YoY) | B10: 0.13213257 | C10: 0.1381636 | D10: -0.1391966 | E10: 0.16485486 | F10: 0.66294256 | G10: 0.32073644
A12: Leverage & solvency
A13: Debt-to-assets (liab. / assets) | B13: 0 | C13: 0 | D13: 0 | E13: 0 | F13: 0 | G13: 0
A14: Equity ratio (net assets / assets) | B14: 1 | C14: 1 | D14: 1 | E14: 1 | F14: 1 | G14: 1
A16: Liquidity & asset profile (derived here)
A17: Current ratio (current assets / AP)
A18: Cash ratio ((cash+temp inv.) / total liab.)
A19: Asset age proxy (accum. deprec. / gross PP&E) | B19: 0.66843222 | C19: 0.70019052 | D19: 0.68102141 | E19: 0.69621771 | F19: 0.65078525 | G19: 0.6562629
A21: Upstream ratios are read from financials_annual; derived ratios are computed only where inputs are reported. Current ratio uses accounts payable as the current-liability proxy (the filings do not split current vs. long-term liabilities). Asset age proxy: a higher % implies older / more depreciated infrastructure.

Sheet Unit economics
A1: Santa Ynez Rancho Estates Mutual Water Company
A2: Unit economics - per-customer revenue by category (USD)
A3: Entity ID: cawc_0021 | Fiscal year ends December 31.
A5: Every metric here is PER CUSTOMER (a metered service connection). It is not a per-member figure; the member (shareholder) count is a different denominator, shown in the denominator block. The visible cell shows the value and its classification; the numerator, denominator, formula, and rationale are in each metric's LOGIC popup.
A6: Per-customer denominator (service connections) | B6: 92 | C6: State Water Board eAR Section 4 (CurTotalConnections), reporting year 2023
A7: Total annual revenue (eAR Section 8b B1.8) | B7: 213691 | C7: State Water Board eAR Section 8b, question B1.8 (total annual revenue), reporting year 2023
A8: Primary source | C8: State Water Board eAR Section 8b (revenue by rate/fee), reporting year 2023
A10: Revenue categories (value, classification, per customer, share)
A11: Revenue category | B11: Classification | C11: Value (USD) | D11: Per customer | E11: Share of revenue
A12: Water sales revenue | B12: DIRECT | C12: 210201 | D12: 2284.79 | E12: 0.9837
A13: Assessment revenue (990 program-service revenue not matched to eAR water-rate revenue) | B13: DERIVED | C13: 38014 | D13: 413.2 | E13: 0.1531
A14: Meter revenue | B14: not reported | C14: not reported | D14: not reported | E14: not reported
A15: Overage or tiered penalty revenue | B15: not reported | C15: not reported | D15: not reported | E15: not reported
A17: Water sales revenue - DIRECT
A18: Revenue customers paid for water service, read straight off the filed eAR Section 8b water-rate line. A DIRECT filed figure, not computed by us.
A19: Numerator: Water rate revenue | B19: 210201 | C19: eAR Section 8b field B1.1 (residential water rates) only (this filer reported no non-residential water-rate revenue). State Water Board eAR Section 8b, question B1.1 + B1.2 (revenue from water rates), reporting year 2023
A20: Denominator: Total service connections | B20: 92 | C20: eAR Section 4 CurTotalConnections, reporting year 2023. State Water Board eAR Section 4 (CurTotalConnections), reporting year 2023
A21: Per customer: water rate revenue $210,201 / 92 connections = $2,284.79 per connection
A22: Share of revenue: water rate revenue $210,201 / total annual revenue (eAR Section 8b B1.8) $213,691 = 98.37%
A23: Period treatment: Numerator (eAR Section 8b, the calendar year 2023) and denominator (eAR Section 4 connections reported in the same eAR filing) are both the eAR reporting year 2023, so the two sides are bound to the same reporting year.
A24: Rationale: Dividing water-rate revenue by the number of metered service connections gives the average revenue per customer; dividing by total annual revenue shows how much of the system's income comes from water rates.
A26: Assessment revenue (990 program-service revenue not matched to eAR water-rate revenue) - DERIVED
A27: A DERIVED residual (medium confidence): the part of the Form 990 program-service revenue that is not matched by the eAR water-rate revenue for the same period. Computed by us, not a filed line.
A28: Input A: Form 990 program-service revenue | B28: 248215 | C28: Form 990 Part VIII line 2 (total program-service revenue), fiscal year 2023 ending December 31, 2023
A29: Input B: eAR water-rate revenue | B29: 210201 | C29: State Water Board eAR Section 8b, question B1.1 + B1.2 (revenue from water rates), reporting year 2023
A30: Residual (A minus B) = assessment revenue | B30: =B28-B29 | C30: $248,215 (990 program-service revenue) minus $210,201 (eAR water-rate revenue) = $38,014
A31: Period alignment: Both inputs cover the same period: the eAR Section 8b is the calendar year 2023 and the Form 990 fiscal year 2023 ends December 31, 2023, so the residual is period-aligned.
A32: What it IS: revenue the system booked as program service on its 990 that is not accounted for by the eAR water-rate line, plausibly member assessments and other service revenue.
A33: This residual is a difference between two sources for the same period; it is not a separately filed assessment line and may include other unmatched revenue.
A34: Denominator: Total service connections | B34: 92 | C34: eAR Section 4 CurTotalConnections, reporting year 2023. State Water Board eAR Section 4 (CurTotalConnections), reporting year 2023
A35: Per customer: residual $38,014 / 92 connections = $413.20 per connection
A36: Share of revenue: residual $38,014 / 990 program-service revenue $248,215 = 15.31%
A38: Meter revenue - not reported
A39: Not reported. This category is not built because doing so would double-count.
A40: Reason: The eAR Section 8a reports a base/meter rate PRICE, but the filing carries no meter revenue line and no tier volume, and the base charge is already inside the water-sales revenue (eAR Section 8b water rates). Building a separate meter figure would double-count. Not backed into from a total.
A42: Overage or tiered penalty revenue - not reported
A43: Not reported. This category is not built because doing so would double-count.
A44: Reason: The eAR Section 8a reports tiered/overage rate PRICES, but the filing carries no overage revenue and no tier consumption volume, and any overage billed is already inside the water-sales revenue. Building it would double-count. Not backed into from a total.

Sheet Rate structure
A1: Santa Ynez Rancho Estates Mutual Water Company
A2: Rate structure and representative bill - eAR Section 8a (RY2024)
A3: Entity ID: cawc_0021 | Fiscal year ends December 31.
A5: This block is a rate-schedule illustration at defined usage levels. It is NOT billed revenue and not a claim about any real customer's usage. The revenue side of unit economics is the separate Unit Economics block.
A6: A filed eAR Section 8a rate schedule IS staged for this system, reporting year 2024, carrying a residential rate structure filed as "OtherRate", a volumetric unit of Hundred Cubic Feet, a billing frequency of M. It carries no single-family residential charges grid (no base charge and no tier prices), so a representative monthly bill is not computable as a monthly bill for this system. Nothing here is estimated to fill the gap.

Sheet eAR revenue & expenses
A1: Santa Ynez Rancho Estates Mutual Water Company
A2: eAR annual revenue and expenses - State Water Board eAR Section 8b (USD)
A3: Entity ID: cawc_0021 | Fiscal year ends December 31.
A5: The water system's own annual figures from the public eAR Section 8b, on the calendar year 2023 the filer self-reported (B0.1/B0.2). Shown beside the period-aligned Form 990 with the variance flagged: a different source (a State Water Board self-report vs an IRS filing). Preserved as filed, never reconciled.
A6: Reporting period basis (self-reported) | B6: calendar year 2023 | C6: eAR Section 8b B0.1 (WRFinancialReportingPeriod)
A8: Revenue (eAR Section 8b, questions B1.x)
A9: Line | B9: Amount (USD) | C9: Citation
A10: Water rate revenue | B10: 210201 | C10: State Water Board eAR Section 8b, question B1.1 + B1.2 (revenue from water rates), reporting year 2023
A11: Other fees and charges | B11: 3490 | C11: State Water Board eAR Section 8b, question B1.3 + B1.4 (revenue from other fees), reporting year 2023
A12: Non-customer revenue | B12: 0 | C12: State Water Board eAR Section 8b, question B1.7 (grants, interest, and other non-customer), reporting year 2023
A13: Total annual revenue | B13: 213691 | C13: State Water Board eAR Section 8b, question B1.8 (total annual revenue for the reporting year), reporting year 2023
A15: Expenses (eAR Section 8b, questions B2.x)
A16: Line | B16: Amount (USD) | C16: Citation
A17: Operations and maintenance | B17: 243098 | C17: State Water Board eAR Section 8b, question B2.1 (annual O and M expense), reporting year 2023
A18: Capital | B18: 29577 | C18: State Water Board eAR Section 8b, question B2.2 (annual expenses from investing or capital), reporting year 2023
A19: Financing | B19: 0 | C19: State Water Board eAR Section 8b, question B2.3 (annual expenses from financing), reporting year 2023
A20: Other | B20: 0 | C20: State Water Board eAR Section 8b, question B2.4 (total other annual expenses), reporting year 2023
A21: Total annual expenses | B21: 272675 | C21: State Water Board eAR Section 8b, question B2.5 (total annual expenses), reporting year 2023
A23: Period-aligned Form 990 comparison (variance surfaced, never reconciled)
A24: Measure | B24: eAR Section 8b | C24: Form 990
A25: total revenue | B25: 213691 | C25: 248919
A26: Variance (eAR minus Form 990) | B26: =B25-C25
A27: The eAR Section 8b total revenue (State Water Board self-report, calendar year 2023) and the Form 990 total revenue (IRS filing) are a different source and cover the same calendar year 2023. Both are carried as filed; the variance is surfaced, never reconciled.
A28: total expenses | B28: 272675 | C28: 244236
A29: Variance (eAR minus Form 990) | B29: =B28-C28
A30: The eAR Section 8b total expenses (State Water Board self-report, calendar year 2023) and the Form 990 total expenses (IRS filing) are a different source and cover the same calendar year 2023. Both are carried as filed; the variance is surfaced, never reconciled.

Sheet Denominators & alignment
A1: Santa Ynez Rancho Estates Mutual Water Company
A2: Denominators and calendar alignment
A3: Entity ID: cawc_0021 | Fiscal year ends December 31.
A5: System size and water use per fiscal year (the operating denominators that per-customer and per-acre metrics divide by), each cited to file and field. The eAR is reported on the calendar year; the 990 fiscal year differs by company. A calendar-year filer's volume is the eAR annual total (fiscal year = calendar year); an offset filer's is recast by a true monthly sum of the covered calendar months, or read not reported naming the missing months. Point-in-time counts (connections, population) are matched to the closest eAR year and never summed. Every derived figure states its formula and accounting rationale.
A6: Member vs customer (two different denominators, both preserved)
A7: Customer (service connection) | B7: 92 | C7: State Water Board eAR Section 4 (CurTotalConnections), reporting year 2024
A8: SDWIS service-connection count (different registry) | B8: 92
A9: Member (shareholder) | C9: No published shareholder count
A10: In a mutual water company a MEMBER is a shareholder who owns part of the system; a CUSTOMER is a metered service connection that receives water. The two diverge because one owner can hold several connections, a connection can serve people who are not owners, and some mutuals attach shares to land by acreage rather than counting heads. Per-customer metrics divide by service connections; per-member metrics divide by shareholders; the two counts are never used interchangeably.
A12: Denominator layer by fiscal year
A13: Fiscal year (end) | B13: Connections | C13: Population | D13: Service-area acres | E13: Water produced (AF) | F13: Water delivered (AF) | G13: Alignment method
A14: FY2021 (2021-12-31) | B14: 92 | C14: not reported | D14: 534.4 | E14: 373.5 | F14: 350.6 | G14: eAR annual total, calendar filer, equals fiscal year (not a monthly recast)
A15: FY2022 (2022-12-31) | B15: 92 | C15: not reported | D15: 534.4 | E15: 326.6 | F15: 306.3 | G15: eAR annual total, calendar filer, equals fiscal year (not a monthly recast)
A16: FY2023 (2023-12-31) | B16: 92 | C16: 304 | D16: 534.4 | E16: not reported | F16: not reported | G16: eAR annual total, calendar filer, equals fiscal year (not a monthly recast)
A17: FY2024 (2024-12-31) | B17: 92 | C17: 304 | D17: 534.4 | E17: not reported | F17: not reported | G17: eAR annual total, calendar filer, equals fiscal year (not a monthly recast)
A18: FY2025 (2025-12-31) | B18: 92 | C18: 304 | D18: 534.4 | E18: not reported | F18: not reported | G18: eAR annual total, calendar filer, equals fiscal year (not a monthly recast)
A20: Connections by class - FY2025 (eAR Section 4)
A21: Single-family residential | B21: 92
A22: Monthly-volume source: California open-data portal (data.ca.gov): the separate Produced Water (by month and source) and Delivered Water (by month and connection type) resources, which cover every public water system (not only urban suppliers), one resource per reporting year, matched by exact PWSID. This is the aggregate publication of eAR Section 6.

Sheet Governance evidence
A1: Santa Ynez Rancho Estates Mutual Water Company
A2: Governance evidence status - Ostrom's eight design principles
A3: Entity ID: cawc_0021 | Fiscal year ends December 31.
A5: Evidence summary: 5 documented, 1 partial, 2 not documented of eight principles.
A6: A count of how many of Elinor Ostrom's eight design principles have a supporting record on file, not a grade. NOT DOCUMENTED means the supporting record was not found, not that the company governs badly. It marks a gap in the documentary record, an evidence gap to close, never a governance failing.
A7: Each mutual is read against Elinor Ostrom's eight design principles for institutions that govern a shared resource durably. Per principle: a one-line finding, the observable signal, a citation, and an evidence status stating whether the supporting record exists: DOCUMENTED (a cited record supports alignment), PARTIAL (some evidence exists but it is incomplete), or NOT DOCUMENTED (no supporting record was found). This is an evidence-status read, not a grade: the principles are never ranked, weighted, or given a letter, consistent with reporting as filed and not grading companies. NOT DOCUMENTED means the supporting record was not found, not that the company governs badly. It marks a gap in the documentary record, an evidence gap to close, never a governance failing.
A9: Principle | B9: Evidence status | C9: Finding | D9: Signal | E9: Citation
A10: Clearly defined boundaries | B10: DOCUMENTED | C10: The system is a defined public water system: 92 service connections over a State-published service-area boundary. | D10: SDWIS Community water system; SABL service-area boundary (not verified (sabl)); connections defined. | E10: [C][G]
A11: What the record shows: SDWIS defines the membership as a fixed set of service connections and the State Water Board publishes a SABL service-area polygon, so who is inside and outside the system is documented. The boundary is Not Verified (SABL), so its outer edge rests on that State layer.
A12: Rules fit local conditions | B12: DOCUMENTED | C12: Charges are tied to service under a documented rate or share-based allocation rule reported to the State or set in the company's structure. | D12: eAR Section 8a customer charges; documented rate or share-allocation rule. | E12: [E][r1]
A13: What the record shows: The record documents how charges are set, whether a filed metered rate schedule or a share-and-acreage allocation, so cost tracks service. Whether every tier scales precisely with use is only partially visible at this scale, but a real cost-to-service rule is on record.
A14: Collective-choice arrangements | B14: DOCUMENTED | C14: The company is owned by its customer-shareholders and run by a named board they elect, documented in its Form 990 governance section. | D14: Mutual ownership; named elected board of directors (Form 990). | E14: [990][r1]
A15: What the record shows: The record documents a collective-choice mechanism: customers are shareholders who elect a named board that governs the company. Turnout and specific member votes on major decisions are not documented, but the elected-board structure and its membership are on record.
A16: Monitoring | B16: DOCUMENTED | C16: The system is metered and monitored: the State SAFER risk assessment shows it Not Failing, and it files an annual eAR. | D16: SAFER Not Failing; annual eAR reporting; metered connections. | E16: [S][E]
A17: What the record shows: Operational monitoring is documented: the State rates the system Not Failing on its drinking-water risk assessment and the system files an annual eAR. No independent audited financial statement is published, so financial monitoring is weaker, but the operational record is present.
A18: Graduated sanctions | B18: NOT DOCUMENTED | C18: No published shut-off, penalty, or delinquency policy was found for this system. | D18: No sourced sanctions policy. | E18: not reported
A19: What the record shows: No public record of a graduated shut-off or penalty policy was found for a system this small. NOT DOCUMENTED means the supporting record was not found, not that the company governs badly. It marks a gap in the documentary record, an evidence gap to close, never a governance failing.
A20: Conflict-resolution mechanisms | B20: NOT DOCUMENTED | C20: No published bylaws, dispute procedure, or grievance mechanism was found for this system. | D20: No sourced conflict-resolution record. | E20: not reported
A21: What the record shows: No public record of a member dispute or conflict-resolution procedure was found. NOT DOCUMENTED means the supporting record was not found, not that the company governs badly. It marks a gap in the documentary record, an evidence gap to close, never a governance failing.
A22: Recognized right to organize | B22: DOCUMENTED | C22: An incorporated California mutual water company recognized by the IRS (501(c)(12)) and by the State Water Board as a public water system. | D22: IRS 501(c)(12) exempt filer (Form 990); SDWIS public water system. | E22: [990][C][SOS]
A23: What the record shows: Baseline legal standing is documented: the company is an incorporated mutual recognized by the IRS as a tax-exempt filer and by the State Water Board as a regulated water system. This records the right to organize as a member entity, not a documented instance of exercising it. The California Secretary of State holds the company as a registered corporation, entity number 0954249, first registered 03/06/1980, status as filed "Active", with a governing body named in the Statement of Information filed 4/21/2026. That is a direct state record of the right to organize being recognized, so the evidence behind this status is now a filed corporate record rather than an inference from the company's tax form. The status was already DOCUMENTED and does not move.
A24: Nested enterprises | B24: PARTIAL | C24: The system draws on a shared local groundwater basin, embedding it in a larger physical water system, though its role in basin governance is not documented. | D24: SDWIS Primary Water Source Type: groundwater (shared basin). | E24: [C]
A25: What the record shows: The system relies on a shared groundwater basin, so it is physically nested in a larger hydrologic system. Its participation in a groundwater sustainability agency or basin governance is not documented, so the nesting evidence is partial.

Sheet Operational metrics
A1: Santa Ynez Rancho Estates Mutual Water Company
A2: Operational metrics - plant per acre, density, terrain
A3: Entity ID: cawc_0021 | Fiscal year ends December 31.
A5: Plant assets per acre
A6: Service-area acres | B6: 534.4 | C6: Geodesic area (WGS84 spherical excess) of the SABL service-area polygon.
A7: Fiscal year | B7: Gross plant per acre (primary) | C7: Net plant per acre
A8: FY2021 | B8: 1549.8802 | C8: 464.6688
A9: FY2022 | B9: 1646.3361 | C9: 525.146
A10: FY2023 | B10: 1688.5049 | C10: 512.9379
A11: FY2024 | B11: 1902.0004 | C11: 664.2066
A12: FY2025 | B12: 1995.1048 | C12: 685.7915
A13: Infrastructure built per acre of service area. Gross plant per acre is the primary read because it measures how much plant the system has put in the ground per acre, and unlike net plant it does not fall over time purely because the assets depreciate on the books. Net plant per acre is shown alongside as the depreciated book value per acre.
A14: Formula: gross plant per acre = Form 990 Part X line 10a (land, buildings, and equipment, gross) / SABL service-area acres; net plant per acre uses Part X line 10c (net)
A15: Source lines: Form 990 Part X line 10a (gross) and line 10c (net); Geodesic area (WGS84 spherical excess) of the SABL service-area polygon.
A16: Confidence: medium. This is worked out from filed figures (a ratio, or a year-to-year change), so it is one step removed from the raw numbers.. Filed gross/net plant over the measured SABL service-area acreage.
A18: Connections per acre
A19: Connections per acre | B19: 0.17 | C19: 92 connections / 534.4 acres. CA State Water Board SABL SERVICE_CONNECTIONS; Geodesic area (WGS84 spherical excess) of the SABL service-area polygon.
A21: Who they are
A22: Terrain class | B22: flat valley | C22: Company context page (BLUEPRINT 5B)
A23: A California mutual water company (501(c)(12)) serving about 92 service connections and roughly 304 residents in the Santa Ynez Rancho Estates residential subdivision, Santa Ynez Valley, Santa Barbara County.

Sheet Supply & weather
A1: Santa Ynez Rancho Estates Mutual Water Company
A2: Supply and weather indicators (DWR water year)
A3: Entity ID: cawc_0021 | Fiscal year ends December 31.
A5: Reporting calendar: Different reporting periods. The DWR water year runs October 1 to September 30; this system's fiscal year ends December 31, so the two period ends are three months apart. Read the two side by side with that in mind. Neither series is recast: both are reported as filed. A water year is named for the calendar year it ends in, so WY2024 and FY2024 share a number without covering the same twelve months.
A7: Indicator | B7: WY2021 | C7: WY2022 | D7: WY2023 | E7: WY2024 | F7: WY2025
A8: Water-year type (Sacramento Valley) | B8: Critical | C8: Critical | D8: Wet | E8: Above Normal | F8: not reported
A9: Peak drought, Santa Barbara County | B9: D4 | C9: D4 | D9: D3 | E9: None (no D0-D4 during the fiscal year) | F9: D3
A10: Precip, percent of normal (8-Station Index) | B10: 48 | C10: 86 | D10: 133 | E10: 96 | F10: 113
A11: Snowpack, April 1 percent of average | B11: 59% | C11: 38% | D11: 237% | E11: 110% | F11: 96%
A12: State Water Project allocation | B12: 5% | C12: 5% | D12: 100% | E12: 40% | F12: 50%

Sheet How this was built
A1: Santa Ynez Rancho Estates Mutual Water Company
A2: How this was built - forensic lineage
A3: Entity ID: cawc_0021 | Fiscal year ends December 31.
A5: A plain account of the forensic lineage behind the hard-to-source metrics: what sources were checked, what was found, what was derived, and what could not be built and why. Every figure marked DERIVED or IMPOSSIBLE above is traceable to a line here.
A7: Water-sales revenue per customer - DIRECT
A8: Sources checked | B8: State Water Board eAR Section 8b (water-rate revenue B1.1/B1.2); State Water Board eAR Section 4 (connection count, same reporting year); audited financial statement (secondary cross-check, where published)
A9: What was found | B9: The eAR Section 8b reports water-rate revenue for reporting year 2023, so this is a DIRECT filed figure; per customer it is divided by the eAR Section 4 connection count for the same reporting year, so numerator and denominator share the year.
A11: Assessment revenue (residual) - DERIVED
A12: Sources checked | B12: Form 990 Part VIII line 2 (program-service revenue); State Water Board eAR Section 8b (water-rate revenue B1.1/B1.2)
A13: What was found | B13: No source separately reports a member assessment, so it is DERIVED as a residual: $248,215 (990 program-service revenue) minus $210,201 (eAR water-rate revenue) = $38,014. Period-aligned; medium confidence.
A14: Caveat | B14: This residual is a difference between two sources for the same period; it is not a separately filed assessment line and may include other unmatched revenue.
A16: Meter revenue - not reported
A17: Sources checked | B17: State Water Board eAR Section 8a (rate prices); State Water Board eAR Section 8b (revenue lines); audited financial statement
A18: What was found | B18: The rate price exists in Section 8a but no revenue or tier volume is reported, and the base charge is already inside water sales.
A19: Caveat | B19: The eAR Section 8a reports a base/meter rate PRICE, but the filing carries no meter revenue line and no tier volume, and the base charge is already inside the water-sales revenue (eAR Section 8b water rates). Building a separate meter figure would double-count. Not backed into from a total.
A21: Overage / tiered-penalty revenue - not reported
A22: Sources checked | B22: State Water Board eAR Section 8a (rate prices); State Water Board eAR Section 8b (revenue lines); audited financial statement
A23: What was found | B23: The rate price exists in Section 8a but no revenue or tier volume is reported, and the base charge is already inside water sales.
A24: Caveat | B24: The eAR Section 8a reports tiered/overage rate PRICES, but the filing carries no overage revenue and no tier consumption volume, and any overage billed is already inside the water-sales revenue. Building it would double-count. Not backed into from a total.
A26: eAR Section 8b reporting-period basis - sourced
A27: Sources checked | B27: eAR Section 8b B0.1 (WRFinancialReportingPeriod); eAR Section 8b B0.2 (WRFiscalYearStartDate)
A28: What was found | B28: The reporting basis (fiscal vs calendar year) is read from the filer's own B0.1/B0.2 answer and staged verbatim, never hardcoded, so the 990 comparison and the residual are period-aligned.
A30: Member (shareholder) count denominator - not reported
A31: Sources checked | B31: Form 990 (no member count stated); company website
A32: What was found | B32: No filing states a member/shareholder count, so the per-member unit economics read not reported rather than borrowing the connection count.
A34: Water volume delivered (acre-feet) - not reported
A35: Sources checked | B35: Form 990 (not in the filing); Consumer Confidence Report; eAR Section 6 (PRA-gated)
A36: What was found | B36: Volume delivered in acre-feet is not in the Form 990 and the CCR states only a source mix, so the per-acre-foot metrics read not reported; the eAR Section 6 is named as the source still needed.

Sheet Water Operations
A1: Santa Ynez Rancho Estates Mutual Water Company
A2: Water Operations (sourced outside the financial filings)
A3: Entity ID: cawc_0021 | Fiscal year ends December 31.
A5: A separate dialect of data from the financial statements: the system's water supply, from the California State Water Board records (the Consumer Confidence Report served by the eAR portal, and SDWIS Drinking Water Watch). Each field carries its source, year, and confidence the same way a financial line item does; a field the source does not state reads 'not reported' with the source still needed. Figures are as reported, never estimated or reconciled across sources.
A7: Field | B7: Value | C7: Source | D7: Year | E7: Confidence | F7: Source excerpt / cross-source note
A8: Water type | B8: Potable (community drinking water) | C8: SDWIS Drinking Water Watch (State Water Board) | D8: 2024 | E8: high | F8: SANTA YNEZ RANCHO ESTATES: State Water System Type = Community.
A9: Source mix | B9: Primary source: local groundwater wells (SDWIS Primary Water Source Type: Groundwater). SDWIS classifies the primary supply type; it states no acre-foot volume by source. | C9: SDWIS Drinking Water Watch (State Water Board) | D9: 2024 | E9: high | F9: SANTA YNEZ RANCHO ESTATES: Primary Water Source Type = Groundwater.
A10: Service connections (total) | B10: 92 connections | C10: SDWIS Drinking Water Watch (State Water Board) | D10: 2024 | E10: high | F10: SANTA YNEZ RANCHO ESTATES: Total Number of Service Connections = 92. [cross-source: SDWIS connection snapshot; the eAR reports active service connections on its own basis and per reporting year. Both preserved, not reconciled.]
A11: Connections by class | B11: Service connections by type (SDWIS snapshot): Residential 92; Total 92. | C11: SDWIS Drinking Water Watch (State Water Board) | D11: 2024 | E11: high | F11: SANTA YNEZ RANCHO ESTATES: connections by type - Residential 92; Total 92.
A12: Population served | B12: 304 residents | C12: SDWIS Drinking Water Watch (State Water Board) | D12: 2024 | E12: high | F12: SANTA YNEZ RANCHO ESTATES: Total Population = 304.
A13: Treatment and water quality | B13: Operator certification on file: Distribution Operator Level 1. SDWIS states operator grades, not the treatment process detail. | C13: SDWIS Drinking Water Watch (State Water Board) | D13: 2024 | E13: high | F13: SANTA YNEZ RANCHO ESTATES: Treatment Plant Class = not stated; Distribution System Class = Distribution Operator Level 1.
A15: Not reported (source still needed)
A16: Annual volume delivered (acre-feet) | B16: not reported - needs annual volume in acre-feet (State Water Board eAR Section 6 or company production records); the CCR states only a percentage mix
A17: Customer classes served | B17: not reported - needs the State Water Board eAR or the system CCR

Sheet Sources & audit
A1: Santa Ynez Rancho Estates Mutual Water Company
A2: Sources & audit - full provenance and tie-outs (kept off the statements so they read clean)
A3: Entity ID: cawc_0021 | Fiscal year ends December 31.
A5: Presentation standard: every figure on the statement tabs is verified to its source filing and shown clean. A cell the filing does not report reads "not reported" (never estimated, never guessed).
A6: Citations, confidence tiers, and the filed-vs-computed tie-out checks live on the "Sources & audit" tab, keyed by cell, so every number is fully traceable without cluttering the statements. These pages are ready to use as filed.
A8: A. Filing provenance (one row per staged extraction)
A9: Fiscal year | B9: Period end | C9: Filing type | D9: Confidence | E9: Extraction ID | F9: Object ID | G9: Extracted by | H9: Extracted at | I9: Source URL
A10: FY2020 | B10: 2020-12-31 | C10: 990 | D10: high | E10: 7b88840c-f04e-4ccb-a762-b225d21c9cf2 | F10: 202142989349301904 | G10: claude-opus-5 | H10: 2026-09-14T20:40:23+00:00 | I10: https://apps.irs.gov/pub/epostcard/990/xml/2021/2021_TEOS_XML_01A.zip#202142989349301904_public.xml
A11: FY2021 | B11: 2021-12-31 | C11: 990 | D11: high | E11: c6ccc7c5-f563-4477-b46d-2df4bc90b27f | F11: 202201319349303630 | G11: claude-opus-5 | H11: 2026-09-14T20:40:23+00:00 | I11: https://apps.irs.gov/pub/epostcard/990/xml/2022/2022_TEOS_XML_01A.zip#202201319349303630_public.xml
A12: FY2022 | B12: 2022-12-31 | C12: 990 | D12: high | E12: 45229109-8508-4324-9fe1-a3eb43842165 | F12: 202341359349313504 | G12: claude-opus-5 | H12: 2026-09-14T20:40:23+00:00 | I12: https://apps.irs.gov/pub/epostcard/990/xml/2023/2023_TEOS_XML_05A.zip#202341359349313504_public.xml
A13: FY2023 | B13: 2023-12-31 | C13: 990 | D13: high | E13: 9bba56be-6773-4f61-878e-b3ab778dbfad | F13: 202421299349303072 | G13: claude-opus-5 | H13: 2026-09-14T20:40:23+00:00 | I13: https://apps.irs.gov/pub/epostcard/990/xml/2024/2024_TEOS_XML_05A.zip#202421299349303072_public.xml
A14: FY2024 | B14: 2024-12-31 | C14: 990 | D14: high | E14: b86d2f4b-e124-4cf1-a3e1-4060c008a3cf | F14: 202541049349300234 | G14: claude-opus-5 | H14: 2026-09-14T20:40:23+00:00 | I14: https://apps.irs.gov/pub/epostcard/990/xml/2025/2025_TEOS_XML_04A.zip#202541049349300234_public.xml
A15: FY2025 | B15: 2025-12-31 | C15: 990 | D15: high | E15: ab78afa5-dcca-4b5b-be98-0e9c41cb9ea0 | F15: 202641679349300244 | G15: claude-opus-5 | H15: 2026-09-14T20:40:23+00:00 | I15: https://apps.irs.gov/pub/epostcard/990/xml/2026/2026_TEOS_XML_06A.zip#202641679349300244_public.xml
A17: B. Figure citations (every figure on the statement tabs, keyed by cell)
A18: Tab | B18: Cell | C18: Line item | D18: Form 990 line | E18: Key path | F18: Confidence | G18: As filed
A19: Financial Statements | B19: B73 | C19: 11a. Gross income from members or shareholders | D19: 11a | E19: part_v_other_irs_filings.members_and_shareholders_gross_income | F19: high | G19: 215819
A20: Financial Statements | B20: C73 | C20: 11a. Gross income from members or shareholders | D20: 11a | E20: part_v_other_irs_filings.members_and_shareholders_gross_income | F20: high | G20: 248239
A21: Financial Statements | B21: D73 | C21: 11a. Gross income from members or shareholders | D21: 11a | E21: part_v_other_irs_filings.members_and_shareholders_gross_income | F21: high | G21: 213691
A22: Financial Statements | B22: E73 | C22: 11a. Gross income from members or shareholders | D22: 11a | E22: part_v_other_irs_filings.members_and_shareholders_gross_income | F22: high | G22: 248213
A23: Financial Statements | B23: F73 | C23: 11a. Gross income from members or shareholders | D23: 11a | E23: part_v_other_irs_filings.members_and_shareholders_gross_income | F23: high | G23: 409534
A24: Financial Statements | B24: G73 | C24: 11a. Gross income from members or shareholders | D24: 11a | E24: part_v_other_irs_filings.members_and_shareholders_gross_income | F24: high | G24: 540118
A25: Financial Statements | B25: B74 | C25: 11b. Gross income from other sources | D25: 11b | E25: part_v_other_irs_filings.other_sources_gross_income | F25: high | G25: 2292
A26: Financial Statements | B26: C74 | C26: 11b. Gross income from other sources | D26: 11b | E26: part_v_other_irs_filings.other_sources_gross_income | F26: high | G26: 7
A27: Financial Statements | B27: D74 | C27: 11b. Gross income from other sources | D27: 11b | E27: part_v_other_irs_filings.other_sources_gross_income | F27: high | G27: 0
A28: Financial Statements | B28: E74 | C28: 11b. Gross income from other sources | D28: 11b | E28: part_v_other_irs_filings.other_sources_gross_income | F28: high | G28: 704
A29: Financial Statements | B29: F74 | C29: 11b. Gross income from other sources | D29: 11b | E29: part_v_other_irs_filings.other_sources_gross_income | F29: high | G29: 4404
A30: Financial Statements | B30: G74 | C30: 11b. Gross income from other sources | D30: 11b | E30: part_v_other_irs_filings.other_sources_gross_income | F30: high | G30: 6585
... A112: Net-assets reconciliation | B112: G10 | C112: 9. Other changes in net assets | D112: Part XI line 9 | E112: part_xi_reconciliation.other_changes_net_assets | F112: high | G112: 0
A114: C. Tie-out checks (filed vs computed; any nonzero variance is flagged red)
A115: Tab | B115: Check | C115: Fiscal year | D115: Filed | E115: Computed | F115: Variance (computed - filed)
A116: Revenue (detail) | B116: 12. Total revenue | C116: FY2020 | D116: 218111 | E116: ='Revenue (detail)'!B13 | F116: =E116-D116
A117: Revenue (detail) | B117: 12. Total revenue | C117: FY2021 | D117: 248246 | E117: ='Revenue (detail)'!C13 | F117: =E117-D117
A118: Revenue (detail) | B118: 12. Total revenue | C118: FY2022 | D118: 213691 | E118: ='Revenue (detail)'!D13 | F118: =E118-D118
A119: Revenue (detail) | B119: 12. Total revenue | C119: FY2023 | D119: 248919 | E119: ='Revenue (detail)'!E13 | F119: =E119-D119
A120: Revenue (detail) | B120: 12. Total revenue | C120: FY2024 | D120: 413938 | E120: ='Revenue (detail)'!F13 | F120: =E120-D120
A121: Revenue (detail) | B121: 12. Total revenue | C121: FY2025 | D121: 546703 | E121: ='Revenue (detail)'!G13 | F121: =E121-D121
A122: Revenue (detail) | B122: 2g program service revenue = sum of lines 2a-2f (FY2025) | C122: FY2025 | D122: 540118 | E122: =SUM('Revenue (detail)'!C17:C18) | F122: =E122-D122
A123: Operating expenses (detail) | B123: 25. Total functional expenses | C123: FY2020 | D123: 207980 | E123: ='Operating expenses (detail)'!B18 | F123: =E123-D123
A124: Operating expenses (detail) | B124: 25. Total functional expenses | C124: FY2021 | D124: 224644 | E124: ='Operating expenses (detail)'!C18 | F124: =E124-D124
A125: Operating expenses (detail) | B125: 25. Total functional expenses | C125: FY2022 | D125: 272676 | E125: ='Operating expenses (detail)'!D18 | F125: =E125-D125
...

Sheet Provenance
A1: Build provenance | B1: Built from source commit d418ffb17485 (2026-10-06); source fingerprint a75a8eee82c65cf7; 192 companies (179 retail mutual, 4 irrigation mutual, 3 mutual, no PWSID, purpose not stated, 2 frozen non-mutual (special district), 2 wholesale mutual, 1 frozen non-mutual (investor-owned), 1 frozen non-mutual (municipal)); 91 gates; build id 3d08d6d2a855.
A2: source_commit | B2: d418ffb174855ab78000d391d42f898397b0d8aa
A3: source_commit_date | B3: 2026-10-06
A4: source_fingerprint | B4: a75a8eee82c65cf7096931f06e18affdc28686a02895b46538e7298b57c04d94
A5: gate_count | B5: 91
A6: build_id | B6: 3d08d6d2a855
A7: registry: frozen non-mutual (investor-owned) | B7: 1
A8: registry: frozen non-mutual (municipal) | B8: 1
A9: registry: frozen non-mutual (special district) | B9: 2
A10: registry: irrigation mutual | B10: 4
A11: registry: mutual, no PWSID, purpose not stated | B11: 3
A12: registry: retail mutual | B12: 179
A13: registry: wholesale mutual | B13: 2
