Workbook

Sheet Summary
A1: Cascadel Mutual Water Company
A2: Financial Summary - multi-year overview (USD)
A3: Entity ID: cawc_0158 | Fiscal year ends April 30.
A5: Presentation standard: every figure on the statement tabs is verified to its source filing and shown clean. A cell the filing does not report reads "not reported" (never estimated, never guessed).
A6: Citations, confidence tiers, and the filed-vs-computed tie-out checks live on the "Sources & audit" tab, keyed by cell, so every number is fully traceable without cluttering the statements. These pages are ready to use as filed.
A8: Metric | B8: FY2020 | C8: FY2021 | D8: FY2022 | E8: FY2023 | F8: FY2024 | G8: FY2025
A9: Operating results (USD)
A10: Total revenue | B10: 156456 | C10: 159459 | D10: 161287 | E10: 153037 | F10: 151439 | G10: 185375
A11: Total expenses | B11: 134824 | C11: 203525 | D11: 199212 | E11: 219634 | F11: 228243 | G11: 215682
A12: Net income | B12: 21632 | C12: -44066 | D12: -37925 | E12: -66597 | F12: -76804 | G12: -30307
A14: Financial position (USD, end of year)
A15: Total assets | B15: 994246 | C15: 953108 | D15: 902446 | E15: 816506 | F15: 728654 | G15: 682752
A16: Total liabilities | B16: 235846 | C16: 238774 | D16: 225906 | E16: 205726 | F16: 194690 | G16: 179855
A17: Net assets | B17: 758400 | C17: 714334 | D17: 676540 | E17: 610780 | F17: 533964 | G17: 502897
A19: Headline ratios
A20: Operating margin | B20: 0.13826251 | C20: -0.2763469 | D20: -0.23513984 | E20: -0.43516927 | F20: -0.5071613 | G20: -0.16349022
A21: Revenue growth (YoY) | C21: 0.019193895 | D21: 0.011463762 | E21: -0.051151054 | F21: -0.010441919 | G21: 0.22409023
A22: Return on assets | B22: 0.021757191 | C22: -0.046234005 | D22: -0.042024675 | E22: -0.081563393 | F22: -0.10540531 | G22: -0.044389471
A24: Figures as reported in source filings (full provenance on the Sources & audit tab). Parentheses denote negatives; ratios are computed upstream in financials_annual.

Sheet Notes
A1: Notes
A2: Human annotations from the versioned store (data/notes/). Annotations only: they never change a reported figure or a confidence tier.
A4: Date | B4: Tag | C4: Author | D4: Note
A5: No notes recorded yet.

Sheet Financial Statements
A1: Cascadel Mutual Water Company
A2: Financial Statements - income statement, balance sheet, cash flow, member income test (USD)
A3: Entity ID: cawc_0158 | Fiscal year ends April 30.
A5: INCOME STATEMENT - as reported (USD)
A6: Line item | B6: FY2020 | C6: FY2021 | D6: FY2022 | E6: FY2023 | F6: FY2024 | G6: FY2025
A7: Revenue
A8: Program service revenue | B8: 151585 | C8: 136474 | D8: 153547 | E8: 145785 | F8: 143168 | G8: 177169
A9: Investment income | B9: 35 | C9: 11 | D9: 8 | E9: 9 | F9: 111 | G9: 89
A10: Net rental income
A11: Net gain/(loss) on investment sales
A12: Other revenue | B12: 4836 | C12: 20853
A13: Contributions & grants | C13: 2121 | D13: 7732 | E13: 7243 | F13: 8160 | G13: 8117
A14: Total revenue | B14: 156456 | C14: 159459 | D14: 161287 | E14: 153037 | F14: 151439 | G14: 185375
A16: Expenses
A17: Depreciation | B17: 46044 | C17: 49712 | D17: 52261 | E17: 54264 | F17: 56038 | G17: 54396
A18: Interest expense | F18: 19983 | G18: 10223
A19: Total expenses | B19: 134824 | C19: 203525 | D19: 199212 | E19: 219634 | F19: 228243 | G19: 215682
A21: Net income | B21: 21632 | C21: -44066 | D21: -37925 | E21: -66597 | F21: -76804 | G21: -30307
A24: BALANCE SHEET - as reported (USD, end of year)
A25: Line item | B25: FY2020 | C25: FY2021 | D25: FY2022 | E25: FY2023 | F25: FY2024 | G25: FY2025
A26: Assets
A27: Cash | B27: 253470 | C27: 264511 | D27: 211137 | E27: 170450 | F27: 137605 | G27: 139736
A28: Savings & temporary investments | B28: 13232 | C28: 6959 | D28: 6959 | E28: 6959 | F28: 6964 | G28: 6966
A29: Accounts receivable | B29: 5293 | C29: 2077 | D29: 14633 | E29: 1602 | F29: 2160 | G29: 8947
A30: Inventories
A31: Prepaid expenses | G31: 460
A32: Property, plant & equipment (gross) | B32: 1798102 | C32: 1805124 | D32: 1847322 | E32: 1868823 | F32: 1868823 | G32: 1868823
A33: Less: accumulated depreciation | B33: -1075851 | C33: -1125563 | D33: -1177825 | E33: -1231348 | F33: -1287473 | G33: -1341956
A34: Net property, plant & equipment | B34: 722251 | C34: 679561 | D34: 669497 | E34: 637475 | F34: 581350 | G34: 526867
A35: Total assets | B35: 994246 | C35: 953108 | D35: 902446 | E35: 816506 | F35: 728654 | G35: 682752
A37: Liabilities
A38: Accounts payable | B38: 1884 | C38: 1328 | D38: 992 | E38: 5900
A39: Mortgages & notes payable
A40: Total liabilities | B40: 235846 | C40: 238774 | D40: 225906 | E40: 205726 | F40: 194690 | G40: 179855
A42: Net Assets / Equity
A43: Capital stock | B43: 3325 | C43: 3325 | D43: 3325 | E43: 3325 | F43: 3325 | G43: 3325
A44: Paid-in capital | B44: 50000 | C44: 50000 | D44: 50000 | E44: 50000 | F44: 50000 | G44: 50000
A45: Retained earnings | B45: 705075 | C45: 661009 | D45: 623215 | E45: 557455 | F45: 480639 | G45: 449572
A46: Net assets | B46: 758400 | C46: 714334 | D46: 676540 | E46: 610780 | F46: 533964 | G46: 502897
A49: CASH FLOW - derived proxy (USD)
...

Sheet Balance Sheet
A1: Cascadel Mutual Water Company
A2: Balance Sheet - as reported (USD, end of year)
A3: Entity ID: cawc_0158 | Fiscal year ends April 30.
A5: Line item | B5: FY2020 | C5: FY2021 | D5: FY2022 | E5: FY2023 | F5: FY2024 | G5: FY2025
A6: Assets
A7: Cash | B7: 253470 | C7: 264511 | D7: 211137 | E7: 170450 | F7: 137605 | G7: 139736
A8: Savings & temporary investments | B8: 13232 | C8: 6959 | D8: 6959 | E8: 6959 | F8: 6964 | G8: 6966
A9: Accounts receivable | B9: 5293 | C9: 2077 | D9: 14633 | E9: 1602 | F9: 2160 | G9: 8947
A10: Inventories
A11: Prepaid expenses | G11: 460
A12: Property, plant & equipment (gross) | B12: 1798102 | C12: 1805124 | D12: 1847322 | E12: 1868823 | F12: 1868823 | G12: 1868823
A13: Less: accumulated depreciation | B13: -1075851 | C13: -1125563 | D13: -1177825 | E13: -1231348 | F13: -1287473 | G13: -1341956
A14: Net property, plant & equipment | B14: 722251 | C14: 679561 | D14: 669497 | E14: 637475 | F14: 581350 | G14: 526867
A15: Total assets | B15: 994246 | C15: 953108 | D15: 902446 | E15: 816506 | F15: 728654 | G15: 682752
A17: Liabilities
A18: Accounts payable | B18: 1884 | C18: 1328 | D18: 992 | E18: 5900
A19: Mortgages & notes payable
A20: Total liabilities | B20: 235846 | C20: 238774 | D20: 225906 | E20: 205726 | F20: 194690 | G20: 179855
A22: Net Assets / Equity
A23: Capital stock | B23: 3325 | C23: 3325 | D23: 3325 | E23: 3325 | F23: 3325 | G23: 3325
A24: Paid-in capital | B24: 50000 | C24: 50000 | D24: 50000 | E24: 50000 | F24: 50000 | G24: 50000
A25: Retained earnings | B25: 705075 | C25: 661009 | D25: 623215 | E25: 557455 | F25: 480639 | G25: 449572
A26: Net assets | B26: 758400 | C26: 714334 | D26: 676540 | E26: 610780 | F26: 533964 | G26: 502897
A28: Balance check (assets − liab. − net assets) | B28: 0 | C28: 0 | D28: 0 | E28: 0 | F28: 0 | G28: 0
A30: Net PP&E is the reported ppe_net column (gross less accumulated depreciation). The balance check should be ~0 where all three totals are reported; a non-zero value flags a reporting or extraction discrepancy worth reviewing.

Sheet Officers & contractors
A1: Cascadel Mutual Water Company
A2: Officers, Directors & Contractors - Form 990 Part VII (FY2025; USD)
A3: Entity ID: cawc_0158 | Fiscal year ends April 30.
A5: Section A - Officers, directors, trustees, key employees
A6: Name | B6: Title | C6: Reportable comp (org) | D6: Reportable comp (related) | E6: Other comp | F6: Total compensation
A7: MICHAEL DELANEY | B7: VICE PRESIDE | C7: 0 | D7: 0 | E7: 0 | F7: 0
A8: STAN EGGINK | B8: PRESIDENT | C8: 0 | D8: 0 | E8: 0 | F8: 0
A9: STEVE JOHANSEN | B9: TREASURER | C9: 0 | D9: 0 | E9: 0 | F9: 0
A10: ED ROSE | B10: DIRECTOR OF | C10: 0 | D10: 0 | E10: 0 | F10: 0
A11: KEN TRAPP | B11: SECRETARY | C11: 0 | D11: 0 | E11: 0 | F11: 0
A13: Section B - Independent contractors (over $100,000)
A14: Contractor | B14: Services | C14: Compensation
A16: Section A lists every officer, director, trustee and key employee filed for the latest year; the two with the highest total compensation are highlighted. Total compensation is computed (reportable org + related + other). Section B lists each independent contractor paid over $100,000; the return reports None such contractor(s). Source and confidence for every figure are on the Sources & audit tab.

Sheet Revenue (detail)
A1: Cascadel Mutual Water Company
A2: Revenue - Form 990 Part VIII (USD)
A3: Entity ID: cawc_0158 | Fiscal year ends April 30.
A5: Part VIII line | B5: FY2020 | C5: FY2021 | D5: FY2022 | E5: FY2023 | F5: FY2024 | G5: FY2025
A6: Revenue by category
A7: 1h. Total contributions, gifts, grants | B7: not reported | C7: 2121 | D7: 7732 | E7: 7243 | F7: 8160 | G7: 8117
A8: 2g. Total program service revenue | B8: 151585 | C8: 136474 | D8: 153547 | E8: 145785 | F8: 143168 | G8: 177169
A9: 3. Investment income | B9: 35 | C9: 11 | D9: 8 | E9: 9 | F9: 111 | G9: 89
A10: 6d. Net rental income | B10: not reported | C10: not reported | D10: not reported | E10: not reported | F10: not reported | G10: not reported
A11: 7d. Net gain/(loss) from investment sales | B11: not reported | C11: not reported | D11: not reported | E11: not reported | F11: not reported | G11: not reported
A12: 11e. Other revenue | B12: 4836 | C12: 20853 | D12: not reported | E12: not reported | F12: not reported | G12: not reported
A13: 12. Total revenue | B13: =SUM(B7:B12) | C13: =SUM(C7:C12) | D13: =SUM(D7:D12) | E13: =SUM(E7:E12) | F13: =SUM(F7:F12) | G13: =SUM(G7:G12)
A15: Program service revenue detail - FY2025 (lines 2a-2f)
A16: Description | B16: Business code | C16: Total revenue
A17: WATER SYSTEM | C17: 128198
A18: ROAD MAINTENANCE | C18: 46621
A19: SNOW REMOVAL | C19: 2350
A20: Revenue category subtotals are as filed. Total revenue (line 12) is a live SUM of the category cells above; its tie-out to the filed total is on the Sources & audit tab. Program service revenue detail is shown for the latest year, with its sum-to-line-2g check on that same audit tab.

Sheet Operating expenses (detail)
A1: Cascadel Mutual Water Company
A2: Statement of Functional Expenses - Form 990 Part IX (USD)
A3: Entity ID: cawc_0158 | Fiscal year ends April 30.
A5: Part IX line (column A Total) | B5: FY2020 | C5: FY2021 | D5: FY2022 | E5: FY2023 | F5: FY2024 | G5: FY2025
A6: Functional expenses, column A Total - by year
A7: 7. Other salaries and wages | B7: 18135 | C7: 4660 | D7: not reported | E7: not reported | F7: not reported | G7: not reported
A8: 10. Payroll taxes | B8: 1739 | C8: 482 | D8: not reported | E8: not reported | F8: not reported | G8: not reported
A9: 11a. Fees for services: management | B9: not reported | C9: 4048 | D9: 6313 | E9: 9812 | F9: 3842 | G9: not reported
A10: 11b. Fees for services: legal | B10: 5920 | C10: 7450 | D10: not reported | E10: 21207 | F10: 2172 | G10: not reported
A11: 11c. Fees for services: accounting | B11: 10739 | C11: 14188 | D11: 13679 | E11: 15372 | F11: 22706 | G11: 26192
A12: 11f. Fees for services: investment management | B12: not reported | C12: 28573 | D12: 12555 | E12: not reported | F12: not reported | G12: not reported
A13: 11g. Fees for services: other | B13: 4420 | C13: 22408 | D13: 32615 | E13: 81656 | F13: 35539 | G13: not reported
A14: 12. Advertising and promotion | B14: not reported | C14: not reported | D14: 1468 | E14: 150 | F14: not reported | G14: not reported
A15: 13. Office expenses | B15: 8657 | C15: 5788 | D15: 6662 | E15: 7116 | F15: 7482 | G15: 11769
A16: 16. Occupancy | B16: not reported | C16: 57893 | D16: 52287 | E16: 7189 | F16: 48731 | G16: 102106
A17: 17. Travel | B17: not reported | C17: 1100 | D17: 5784 | E17: 7085 | F17: 15239 | G17: not reported
A18: 19. Conferences, conventions, and meetings | B18: 200 | C18: 383 | D18: 813 | E18: 306 | F18: 292 | G18: 32
A19: 20. Interest | B19: not reported | C19: not reported | D19: not reported | E19: not reported | F19: 19983 | G19: 10223
A20: 22. Depreciation, depletion, and amortization | B20: 46044 | C20: 49712 | D20: 52261 | E20: 54264 | F20: 56038 | G20: 54396
A21: 23. Insurance | B21: 6828 | C21: 6447 | D21: 14709 | E21: 15477 | F21: 16219 | G21: 10964
A22: 24. REPAIRS & MAINTENANCE | B22: 14967 | C22: not reported | D22: not reported | E22: not reported | F22: not reported | G22: not reported
A23: 24. AUTO EXPENSES | B23: 6970 | C23: not reported | D23: not reported | E23: not reported | F23: not reported | G23: not reported
A24: 24. UTILITIES | B24: 4761 | C24: not reported | D24: not reported | E24: not reported | F24: not reported | G24: not reported
A25: 24. WATER TESTING | B25: 2593 | C25: not reported | D25: not reported | E25: not reported | F25: not reported | G25: not reported
A26: 24. ADJUSTMENT PER BOOKS | B26: not reported | C26: 393 | D26: 66 | E26: not reported | F26: not reported | G26: not reported
A27: 24e. All other expenses | B27: 2851 | C27: not reported | D27: not reported | E27: not reported | F27: not reported | G27: not reported
A28: 25. Total functional expenses | B28: =SUM(B7:B27) | C28: =SUM(C7:C27) | D28: =SUM(D7:D27) | E28: =SUM(E7:E27) | F28: =SUM(F7:F27) | G28: =SUM(G7:G27)
A30: Functional column split - FY2025 (col A = B + C + D)
A31: Part IX line | B31: A. Total | C31: B. Program services | D31: C. Management & general | E31: D. Fundraising
A32: 11c. Fees for services: accounting | B32: 26192 | C32: 5238 | D32: 20954
A33: 13. Office expenses | B33: 11769 | C33: 9117 | D33: 1904 | E33: 748
A34: 16. Occupancy | B34: 102106 | C34: 102106
A35: 19. Conferences, conventions, and meetings | B35: 32 | C35: 6 | D35: 26
A36: 20. Interest | B36: 10223 | C36: 10223
A37: 22. Depreciation, depletion, and amortization | B37: 54396 | C37: 54396
A38: 23. Insurance | B38: 10964 | C38: 10964
A39: 25. Total (filed col A / B / C / D) | B39: 215682 | C39: 192050 | D39: 22884 | E39: 748
A41: Top block: each Part IX line, column A (Total), by year, as filed. Total functional expenses (line 25) is a live SUM of the line cells; its tie-out to the filed total is on the Sources & audit tab. Filer-itemized 24a-24d rows show the most recent year's as-filed wording; rows are aligned across years case-insensitively with collapsed spacing, so a line filed only in a different capitalization or spacing shares one row, while genuinely different wording stays a separate row (every as-filed variant is recorded on the Sources & audit tab). Lower block: the program / management / fundraising split for the latest year, with its col A = B + C + D check on the audit tab. Lines this filer does not report are omitted rather than shown empty.

Sheet Balance sheet (detail)
A1: Cascadel Mutual Water Company
A2: Balance Sheet - Form 990 Part X (end of year, USD)
A3: Entity ID: cawc_0158 | Fiscal year ends April 30.
A5: Part X line (column B, EOY) | B5: FY2020 | C5: FY2021 | D5: FY2022 | E5: FY2023 | F5: FY2024 | G5: FY2025
A6: Assets
A7: 1. Cash - non-interest-bearing | B7: 253470 | C7: 264511 | D7: 211137 | E7: 170450 | F7: 137605 | G7: 139736
A8: 2. Savings and temporary cash investments | B8: 13232 | C8: 6959 | D8: 6959 | E8: 6959 | F8: 6964 | G8: 6966
A9: 4. Accounts receivable, net | B9: 5293 | C9: 2077 | D9: 14633 | E9: 1602 | F9: 2160 | G9: 8947
A10: 9. Prepaid expenses and deferred charges | B10: not reported | C10: not reported | D10: not reported | E10: not reported | F10: not reported | G10: 460
A11: 10c. Land, buildings, and equipment, net | B11: 722251 | C11: 679561 | D11: 669497 | E11: 637475 | F11: 581350 | G11: 526867
A12: 15. Other assets | B12: not reported | C12: not reported | D12: 220 | E12: 20 | F12: 575 | G12: -224
A13: 16. Total assets | B13: =SUM(B7:B12) | C13: =SUM(C7:C12) | D13: =SUM(D7:D12) | E13: =SUM(E7:E12) | F13: =SUM(F7:F12) | G13: =SUM(G7:G12)
A15: Liabilities
A16: 17. Accounts payable and accrued expenses | B16: 1884 | C16: 1328 | D16: 992 | E16: 5900 | F16: not reported | G16: not reported
A17: 25. Other liabilities | B17: 233962 | C17: 237446 | D17: 224914 | E17: 199826 | F17: 194690 | G17: 179855
A18: 26. Total liabilities | B18: =SUM(B16:B17) | C18: =SUM(C16:C17) | D18: =SUM(D16:D17) | E18: =SUM(E16:E17) | F18: =SUM(F16:F17) | G18: =SUM(G16:G17)
A20: Net assets / fund balances
A21: 29. Capital stock or trust principal | B21: 3325 | C21: 3325 | D21: 3325 | E21: 3325 | F21: 3325 | G21: 3325
A22: 30. Paid-in or capital surplus | B22: 50000 | C22: 50000 | D22: 50000 | E22: 50000 | F22: 50000 | G22: 50000
A23: 31. Retained earnings / accumulated funds | B23: 705075 | C23: 661009 | D23: 623215 | E23: 557455 | F23: 480639 | G23: 449572
A24: 32. Total net assets / fund balances | B24: =SUM(B21:B23) | C24: =SUM(C21:C23) | D24: =SUM(D21:D23) | E24: =SUM(E21:E23) | F24: =SUM(F21:F23) | G24: =SUM(G21:G23)
A26: Every Part X line is end-of-year (column B), as filed. Section totals (lines 16 / 26 / 32) are live SUMs of the lines above; their tie-outs and the balance-sheet identity (16 = 26 + 32) are on the Sources & audit tab. This filer files as a non-FASB mutual, so net assets sit on lines 29-31 (capital stock / paid-in capital / retained earnings); lines this filer does not report are omitted. Lines 10a/10b net into line 10c (shown).

Sheet Net-assets reconciliation
A1: Cascadel Mutual Water Company
A2: Reconciliation of Net Assets - Form 990 Part XI (USD)
A3: Entity ID: cawc_0158 | Fiscal year ends April 30.
A5: Part XI line | B5: FY2020 | C5: FY2021 | D5: FY2022 | E5: FY2023 | F5: FY2024 | G5: FY2025
A6: Reconciliation
A7: 4. Net assets, beginning of year | B7: 736768 | C7: 758400 | D7: 714334 | E7: 676540 | F7: 610780 | G7: 533964
A8: 3. Revenue less expenses | B8: 21632 | C8: -44066 | D8: -37925 | E8: -66597 | F8: -76804 | G8: -30307
A9: 8. Prior period adjustments | B9: not reported | C9: not reported | D9: not reported | E9: 924 | F9: 75 | G9: -673
A10: 9. Other changes in net assets | B10: not reported | C10: not reported | D10: 131 | E10: -87 | F10: -87 | G10: -87
A11: 10. Net assets, end of year | B11: =SUM(B7,B8,B9,B10) | C11: =SUM(C7,C8,C9,C10) | D11: =SUM(D7,D8,D9,D10) | E11: =SUM(E7,E8,E9,E10) | F11: =SUM(F7,F8,F9,F10) | G11: =SUM(G7,G8,G9,G10)
A13: Part XI reconciles beginning to ending net assets. Ending net assets (line 10) is a live formula: beginning balance (line 4) + revenue less expenses (line 3) + prior-period adjustments (8) + other changes (9). Its tie-out to the filed line 10 (and to Part X line 32) is on the Sources & audit tab. Lines 5-7 (unrealized gains, donated services, investment expenses) are not filed by this entity.

Sheet Cash flow proxies
A1: Cascadel Mutual Water Company
A2: Cash Flow Proxies - derived (USD)
A3: Entity ID: cawc_0158 | Fiscal year ends April 30.
A5: PROXY ONLY. The source filings contain no statement of cash flows. Lines below are derived from the reported income statement and year-over-year balance-sheet changes; treat as directional estimates, not GAAP cash flows. The earliest year has no prior period, so its delta cells are blank.
A7: Proxy line (USD) | B7: FY2020 | C7: FY2021 | D7: FY2022 | E7: FY2023 | F7: FY2024 | G7: FY2025
A8: Operating
A9: Net income | B9: 21632 | C9: -44066 | D9: -37925 | E9: -66597 | F9: -76804 | G9: -30307
A10: + Depreciation (reported) | B10: 46044 | C10: 49712 | D10: 52261 | E10: 54264 | F10: 56038 | G10: 54396
A11: − Δ Accounts receivable | C11: 3216 | D11: -12556 | E11: 13031 | F11: -558 | G11: -6787
A12: − Δ Inventories
A13: − Δ Prepaid expenses
A14: + Δ Accounts payable | C14: -556 | D14: -336 | E14: 4908
A15: Operating cash flow proxy | C15: 8306 | D15: 1444 | E15: 5606 | F15: -21324 | G15: 17302
A17: Investing
A18: − Δ PP&E gross (capex proxy) | C18: -7022 | D18: -42198 | E18: -21501 | F18: 0 | G18: 0
A20: Financing
A21: Δ Mortgages & notes payable
A23: Reconciliation
A24: Δ Cash + temp. investments (actual) | C24: 4768 | D24: -53374 | E24: -40687 | F24: -32840 | G24: 2133
A26: The capex proxy assumes gross PP&E rises only via capital spending (it ignores disposals). 'Δ Cash + temp. investments (actual)' is the real reported change in liquid funds and is the most reliable line here; the operating/investing/financing proxies will not perfectly reconcile to it.

Sheet Ratios
A1: Cascadel Mutual Water Company
A2: Financial Ratios
A3: Entity ID: cawc_0158 | Fiscal year ends April 30.
A5: Ratio | B5: FY2020 | C5: FY2021 | D5: FY2022 | E5: FY2023 | F5: FY2024 | G5: FY2025
A6: Profitability (computed upstream)
A7: Operating margin (NI / revenue) | B7: 0.13826251 | C7: -0.2763469 | D7: -0.23513984 | E7: -0.43516927 | F7: -0.5071613 | G7: -0.16349022
A8: Expense ratio (expenses / revenue) | B8: 0.86173749 | C8: 1.2763469 | D8: 1.2351398 | E8: 1.4351693 | F8: 1.5071613 | G8: 1.1634902
A9: Return on assets (NI / assets) | B9: 0.021757191 | C9: -0.046234005 | D9: -0.042024675 | E9: -0.081563393 | F9: -0.10540531 | G9: -0.044389471
A10: Revenue growth (YoY) | C10: 0.019193895 | D10: 0.011463762 | E10: -0.051151054 | F10: -0.010441919 | G10: 0.22409023
A12: Leverage & solvency
A13: Debt-to-assets (liab. / assets) | B13: 0.23721091 | C13: 0.25052145 | D13: 0.25032634 | E13: 0.25195896 | F13: 0.26719129 | G13: 0.26342654
A14: Equity ratio (net assets / assets) | B14: 0.76278909 | C14: 0.74947855 | D14: 0.74967366 | E14: 0.74804104 | F14: 0.73280871 | G14: 0.73657346
A16: Liquidity & asset profile (derived here)
A17: Current ratio (current assets / AP) | B17: 144.37102 | C17: 205.98419 | D17: 234.60585 | E17: 30.340847
A18: Cash ratio ((cash+temp inv.) / total liab.) | B18: 1.1308311 | C18: 1.1369328 | D18: 0.9654281 | E18: 0.86235575 | F18: 0.74255997 | G18: 0.81566818
A19: Asset age proxy (accum. deprec. / gross PP&E) | B19: 0.5983259 | C19: 0.62353777 | D19: 0.63758511 | E19: 0.65888958 | F19: 0.68892185 | G19: 0.71807549
A21: Upstream ratios are read from financials_annual; derived ratios are computed only where inputs are reported. Current ratio uses accounts payable as the current-liability proxy (the filings do not split current vs. long-term liabilities). Asset age proxy: a higher % implies older / more depreciated infrastructure.

Sheet Unit economics
A1: Cascadel Mutual Water Company
A2: Unit economics - per-customer revenue by category (USD)
A3: Entity ID: cawc_0158 | Fiscal year ends April 30.
A5: Every metric here is PER CUSTOMER (a metered service connection). It is not a per-member figure; the member (shareholder) count is a different denominator, shown in the denominator block. The visible cell shows the value and its classification; the numerator, denominator, formula, and rationale are in each metric's LOGIC popup.
A6: Per-customer denominator (service connections) | C6: State Water Board eAR Section 4
A7: Total annual revenue (eAR Section 8b B1.8) | C7: eAR Section 8b total annual revenue not reported for this system.
A8: Primary source
A10: Revenue categories (value, classification, per customer, share)
A11: Revenue category | B11: Classification | C11: Value (USD) | D11: Per customer | E11: Share of revenue
A12: Water sales revenue | B12: not reported | C12: not reported | D12: not reported | E12: not reported
A13: Assessment revenue (990 program-service revenue not matched to eAR water-rate revenue) | B13: IMPOSSIBLE | C13: IMPOSSIBLE | D13: IMPOSSIBLE | E13: IMPOSSIBLE
A14: Meter revenue | B14: not reported | C14: not reported | D14: not reported | E14: not reported
A15: Overage or tiered penalty revenue | B15: not reported | C15: not reported | D15: not reported | E15: not reported
A17: Water sales revenue - not reported
A18: Not reported: this system filed an eAR but no Section 8b revenue block, so there is no filed water-sales figure. Not fallen back to a different year.
A19: Reason: No filed eAR Section 8b water-rate revenue for this system.
A21: Assessment revenue (990 program-service revenue not matched to eAR water-rate revenue) - IMPOSSIBLE
A22: Not computed. A period-aligned residual is not possible for this filer.
A23: Reason: Not derivable. The eAR Section 8b is reporting year None while the Form 990 fiscal year ends None; the two period ends are not aligned, so a period-aligned residual cannot be computed.
A25: Meter revenue - not reported
A26: Not reported. This category is not built because doing so would double-count.
A27: Reason: The eAR Section 8a reports a base/meter rate PRICE, but the filing carries no meter revenue line and no tier volume, and the base charge is already inside the water-sales revenue (eAR Section 8b water rates). Building a separate meter figure would double-count. Not backed into from a total.
A29: Overage or tiered penalty revenue - not reported
A30: Not reported. This category is not built because doing so would double-count.
A31: Reason: The eAR Section 8a reports tiered/overage rate PRICES, but the filing carries no overage revenue and no tier consumption volume, and any overage billed is already inside the water-sales revenue. Building it would double-count. Not backed into from a total.

Sheet Rate structure
A1: Cascadel Mutual Water Company
A2: Rate structure and representative bill - eAR Section 8a
A3: Entity ID: cawc_0158 | Fiscal year ends April 30.
A5: This block is a rate-schedule illustration at defined usage levels. It is NOT billed revenue and not a claim about any real customer's usage. The revenue side of unit economics is the separate Unit Economics block.
A6: No filed eAR Section 8a rate schedule is staged for this system.

Sheet Operational metrics
A1: Cascadel Mutual Water Company
A2: Operational metrics - plant per acre, density, terrain
A3: Entity ID: cawc_0158 | Fiscal year ends April 30.
A5: Plant assets per acre
A6: Service-area acres | B6: 292.3 | C6: Geodesic area (WGS84 spherical excess) of the SABL service-area polygon.
A7: Fiscal year | B7: Gross plant per acre (primary) | C7: Net plant per acre
A8: FY2021 | B8: 6175.5867 | C8: 2324.8751
A9: FY2022 | B9: 6319.9521 | C9: 2290.4447
A10: FY2023 | B10: 6393.5101 | C10: 2180.8929
A11: FY2024 | B11: 6393.5101 | C11: 1988.8813
A12: FY2025 | B12: 6393.5101 | C12: 1802.4872
A13: Infrastructure built per acre of service area. Gross plant per acre is the primary read because it measures how much plant the system has put in the ground per acre, and unlike net plant it does not fall over time purely because the assets depreciate on the books. Net plant per acre is shown alongside as the depreciated book value per acre.
A14: Formula: gross plant per acre = Form 990 Part X line 10a (land, buildings, and equipment, gross) / SABL service-area acres; net plant per acre uses Part X line 10c (net)
A15: Source lines: Form 990 Part X line 10a (gross) and line 10c (net); Geodesic area (WGS84 spherical excess) of the SABL service-area polygon.
A16: Confidence: medium. This is worked out from filed figures (a ratio, or a year-to-year change), so it is one step removed from the raw numbers.. Filed gross/net plant over the measured SABL service-area acreage.
A18: Connections per acre
A19: Connections per acre | B19: 0.41 | C19: 120 connections / 292.3 acres. CA State Water Board SABL SERVICE_CONNECTIONS; Geodesic area (WGS84 spherical excess) of the SABL service-area polygon.

Sheet Supply & weather
A1: Cascadel Mutual Water Company
A2: Supply and weather indicators (DWR water year)
A3: Entity ID: cawc_0158 | Fiscal year ends April 30.
A5: Reporting calendar: Different reporting periods. The DWR water year runs October 1 to September 30; this system's fiscal year ends April 30, so the two period ends are five months apart. Read the two side by side with that in mind. Neither series is recast: both are reported as filed. A water year is named for the calendar year it ends in, so WY2024 and FY2024 share a number without covering the same twelve months.
A7: Indicator | B7: WY2021 | C7: WY2022 | D7: WY2023 | E7: WY2024 | F7: WY2025
A8: Water-year type (Sacramento Valley) | B8: Critical | C8: Critical | D8: Wet | E8: Above Normal | F8: not reported
A9: Peak drought, county County | B9: not reported | C9: not reported | D9: not reported | E9: not reported | F9: not reported
A10: Precip, percent of normal (8-Station Index) | B10: 48 | C10: 86 | D10: 133 | E10: 96 | F10: 113
A11: Snowpack, April 1 percent of average | B11: 59% | C11: 38% | D11: 237% | E11: 110% | F11: 96%
A12: State Water Project allocation | B12: 5% | C12: 5% | D12: 100% | E12: 40% | F12: 50%

Sheet How this was built
A1: Cascadel Mutual Water Company
A2: How this was built - forensic lineage
A3: Entity ID: cawc_0158 | Fiscal year ends April 30.
A5: A plain account of the forensic lineage behind the hard-to-source metrics: what sources were checked, what was found, what was derived, and what could not be built and why. Every figure marked DERIVED or IMPOSSIBLE above is traceable to a line here.
A7: Water-sales revenue per customer - not reported
A8: Sources checked | B8: State Water Board eAR Section 8b (water-rate revenue B1.1/B1.2); State Water Board eAR Section 4 (connection count, same reporting year); audited financial statement (secondary cross-check, where published)
A9: What was found | B9: The eAR Section 8b reports water-rate revenue for reporting year None, so this is a DIRECT filed figure; per customer it is divided by the eAR Section 4 connection count for the same reporting year, so numerator and denominator share the year.
A11: Assessment revenue (residual) - IMPOSSIBLE
A12: Sources checked | B12: Form 990 Part VIII line 2 (program-service revenue); State Water Board eAR Section 8b (water-rate revenue B1.1/B1.2); eAR Section 8b filer comment (WRRevenueComments)
A13: What was found | B13: A period-aligned residual cannot be computed for this filer, so the metric is rendered IMPOSSIBLE rather than guessed.
A14: Caveat | B14: Not derivable. The eAR Section 8b is reporting year None while the Form 990 fiscal year ends None; the two period ends are not aligned, so a period-aligned residual cannot be computed.
A16: Meter revenue - not reported
A17: Sources checked | B17: State Water Board eAR Section 8a (rate prices); State Water Board eAR Section 8b (revenue lines); audited financial statement
A18: What was found | B18: The rate price exists in Section 8a but no revenue or tier volume is reported, and the base charge is already inside water sales.
A19: Caveat | B19: The eAR Section 8a reports a base/meter rate PRICE, but the filing carries no meter revenue line and no tier volume, and the base charge is already inside the water-sales revenue (eAR Section 8b water rates). Building a separate meter figure would double-count. Not backed into from a total.
A21: Overage / tiered-penalty revenue - not reported
A22: Sources checked | B22: State Water Board eAR Section 8a (rate prices); State Water Board eAR Section 8b (revenue lines); audited financial statement
A23: What was found | B23: The rate price exists in Section 8a but no revenue or tier volume is reported, and the base charge is already inside water sales.
A24: Caveat | B24: The eAR Section 8a reports tiered/overage rate PRICES, but the filing carries no overage revenue and no tier consumption volume, and any overage billed is already inside the water-sales revenue. Building it would double-count. Not backed into from a total.
A26: eAR Section 8b reporting-period basis - sourced
A27: Sources checked | B27: eAR Section 8b B0.1 (WRFinancialReportingPeriod); eAR Section 8b B0.2 (WRFiscalYearStartDate)
A28: What was found | B28: The reporting basis (fiscal vs calendar year) is read from the filer's own B0.1/B0.2 answer and staged verbatim, never hardcoded, so the 990 comparison and the residual are period-aligned.
A30: Member (shareholder) count denominator - not reported
A31: Sources checked | B31: Form 990 (no member count stated); company website
A32: What was found | B32: No filing states a member/shareholder count, so the per-member unit economics read not reported rather than borrowing the connection count.
A34: Water volume delivered (acre-feet) - not reported
A35: Sources checked | B35: Form 990 (not in the filing); Consumer Confidence Report; eAR Section 6 (PRA-gated)
A36: What was found | B36: Volume delivered in acre-feet is not in the Form 990 and the CCR states only a source mix, so the per-acre-foot metrics read not reported; the eAR Section 6 is named as the source still needed.

Sheet Sources & audit
A1: Cascadel Mutual Water Company
A2: Sources & audit - full provenance and tie-outs (kept off the statements so they read clean)
A3: Entity ID: cawc_0158 | Fiscal year ends April 30.
A5: Presentation standard: every figure on the statement tabs is verified to its source filing and shown clean. A cell the filing does not report reads "not reported" (never estimated, never guessed).
A6: Citations, confidence tiers, and the filed-vs-computed tie-out checks live on the "Sources & audit" tab, keyed by cell, so every number is fully traceable without cluttering the statements. These pages are ready to use as filed.
A8: A. Filing provenance (one row per staged extraction)
A9: Fiscal year | B9: Period end | C9: Filing type | D9: Confidence | E9: Extraction ID | F9: Object ID | G9: Extracted by | H9: Extracted at | I9: Source URL
A10: FY2020 | B10: 2020-04-30 | C10: 990 | D10: high | E10: d26b650f-ebc1-43f2-90b5-238636958bcb | F10: 202140749349300244 | G10: claude-opus-5 | H10: 2026-10-05T16:06:09+00:00 | I10: https://apps.irs.gov/pub/epostcard/990/xml/2021/2021_TEOS_XML_01A.zip#202140749349300244_public.xml
A11: FY2021 | B11: 2021-04-30 | C11: 990 | D11: high | E11: 47c8a2d1-9bef-42aa-adf4-5a2adfa7dd5e | F11: 202122579349301327 | G11: claude-opus-5 | H11: 2026-10-05T16:06:09+00:00 | I11: https://apps.irs.gov/pub/epostcard/990/xml/2021/2021_TEOS_XML_01A.zip#202122579349301327_public.xml
A12: FY2022 | B12: 2022-04-30 | C12: 990 | D12: high | E12: b7e84db1-0981-4685-8f0b-a54746019fd5 | F12: 202202209349301495 | G12: claude-opus-5 | H12: 2026-10-05T16:06:09+00:00 | I12: https://apps.irs.gov/pub/epostcard/990/xml/2022/2022_TEOS_XML_01A.zip#202202209349301495_public.xml
A13: FY2023 | B13: 2023-04-30 | C13: 990 | D13: high | E13: e79107c8-8274-4faf-9353-4fd0d2953855 | F13: 202323459349300637 | G13: claude-opus-5 | H13: 2026-10-05T16:06:09+00:00 | I13: https://apps.irs.gov/pub/epostcard/990/xml/2023/2023_TEOS_XML_12A.zip#202323459349300637_public.xml
A14: FY2024 | B14: 2024-04-30 | C14: 990 | D14: high | E14: 420cbba2-a9a0-41d0-bce4-a812990a6511 | F14: 202432609349301838 | G14: claude-opus-5 | H14: 2026-10-05T16:06:09+00:00 | I14: https://apps.irs.gov/pub/epostcard/990/xml/2024/2024_TEOS_XML_09A.zip#202432609349301838_public.xml
A15: FY2025 | B15: 2025-04-30 | C15: 990 | D15: high | E15: 4f04603b-b16b-40de-9906-27af2a5f1f45 | F15: 202502519349301455 | G15: claude-opus-5 | H15: 2026-10-05T16:06:09+00:00 | I15: https://apps.irs.gov/pub/epostcard/990/xml/2025/2025_TEOS_XML_09A.zip#202502519349301455_public.xml
A17: B. Figure citations (every figure on the statement tabs, keyed by cell)
A18: Tab | B18: Cell | C18: Line item | D18: Form 990 line | E18: Key path | F18: Confidence | G18: As filed
A19: Financial Statements | B19: B73 | C19: 11a. Gross income from members or shareholders | D19: 11a | E19: part_v_other_irs_filings.members_and_shareholders_gross_income | F19: high | G19: 151585
A20: Revenue (detail) | B20: C7 | C20: 1h. Total contributions, gifts, grants | D20: 1h | E20: part_viii_revenue.total_contributions | F20: high | G20: 2121
A21: Revenue (detail) | B21: D7 | C21: 1h. Total contributions, gifts, grants | D21: 1h | E21: part_viii_revenue.total_contributions | F21: high | G21: 7732
A22: Revenue (detail) | B22: E7 | C22: 1h. Total contributions, gifts, grants | D22: 1h | E22: part_viii_revenue.total_contributions | F22: high | G22: 7243
A23: Revenue (detail) | B23: F7 | C23: 1h. Total contributions, gifts, grants | D23: 1h | E23: part_viii_revenue.total_contributions | F23: high | G23: 8160
A24: Revenue (detail) | B24: G7 | C24: 1h. Total contributions, gifts, grants | D24: 1h | E24: part_viii_revenue.total_contributions | F24: high | G24: 8117
A25: Revenue (detail) | B25: B8 | C25: 2g. Total program service revenue | D25: 2g | E25: part_viii_revenue.total_program_service_revenue | F25: high | G25: 151585
A26: Revenue (detail) | B26: C8 | C26: 2g. Total program service revenue | D26: 2g | E26: part_viii_revenue.total_program_service_revenue | F26: high | G26: 136474
A27: Revenue (detail) | B27: D8 | C27: 2g. Total program service revenue | D27: 2g | E27: part_viii_revenue.total_program_service_revenue | F27: high | G27: 153547
A28: Revenue (detail) | B28: E8 | C28: 2g. Total program service revenue | D28: 2g | E28: part_viii_revenue.total_program_service_revenue | F28: high | G28: 145785
A29: Revenue (detail) | B29: F8 | C29: 2g. Total program service revenue | D29: 2g | E29: part_viii_revenue.total_program_service_revenue | F29: high | G29: 143168
A30: Revenue (detail) | B30: G8 | C30: 2g. Total program service revenue | D30: 2g | E30: part_viii_revenue.total_program_service_revenue | F30: high | G30: 177169
... A177: Net-assets reconciliation | B177: G10 | C177: 9. Other changes in net assets | D177: Part XI line 9 | E177: part_xi_reconciliation.other_changes_net_assets | F177: high | G177: -87
A179: C. Tie-out checks (filed vs computed; any nonzero variance is flagged red)
A180: Tab | B180: Check | C180: Fiscal year | D180: Filed | E180: Computed | F180: Variance (computed - filed)
A181: Revenue (detail) | B181: 12. Total revenue | C181: FY2020 | D181: 156456 | E181: ='Revenue (detail)'!B13 | F181: =E181-D181
A182: Revenue (detail) | B182: 12. Total revenue | C182: FY2021 | D182: 159459 | E182: ='Revenue (detail)'!C13 | F182: =E182-D182
A183: Revenue (detail) | B183: 12. Total revenue | C183: FY2022 | D183: 161287 | E183: ='Revenue (detail)'!D13 | F183: =E183-D183
A184: Revenue (detail) | B184: 12. Total revenue | C184: FY2023 | D184: 153037 | E184: ='Revenue (detail)'!E13 | F184: =E184-D184
A185: Revenue (detail) | B185: 12. Total revenue | C185: FY2024 | D185: 151439 | E185: ='Revenue (detail)'!F13 | F185: =E185-D185
A186: Revenue (detail) | B186: 12. Total revenue | C186: FY2025 | D186: 185375 | E186: ='Revenue (detail)'!G13 | F186: =E186-D186
A187: Revenue (detail) | B187: 2g program service revenue = sum of lines 2a-2f (FY2025) | C187: FY2025 | D187: 177169 | E187: =SUM('Revenue (detail)'!C17:C19) | F187: =E187-D187
A188: Operating expenses (detail) | B188: 25. Total functional expenses | C188: FY2020 | D188: 134824 | E188: ='Operating expenses (detail)'!B28 | F188: =E188-D188
A189: Operating expenses (detail) | B189: 25. Total functional expenses | C189: FY2021 | D189: 203525 | E189: ='Operating expenses (detail)'!C28 | F189: =E189-D189
A190: Operating expenses (detail) | B190: 25. Total functional expenses | C190: FY2022 | D190: 199212 | E190: ='Operating expenses (detail)'!D28 | F190: =E190-D190
...

Sheet Provenance
A1: Build provenance | B1: Built from source commit d418ffb17485 (2026-10-06); source fingerprint a75a8eee82c65cf7; 192 companies (179 retail mutual, 4 irrigation mutual, 3 mutual, no PWSID, purpose not stated, 2 frozen non-mutual (special district), 2 wholesale mutual, 1 frozen non-mutual (investor-owned), 1 frozen non-mutual (municipal)); 91 gates; build id 3d08d6d2a855.
A2: source_commit | B2: d418ffb174855ab78000d391d42f898397b0d8aa
A3: source_commit_date | B3: 2026-10-06
A4: source_fingerprint | B4: a75a8eee82c65cf7096931f06e18affdc28686a02895b46538e7298b57c04d94
A5: gate_count | B5: 91
A6: build_id | B6: 3d08d6d2a855
A7: registry: frozen non-mutual (investor-owned) | B7: 1
A8: registry: frozen non-mutual (municipal) | B8: 1
A9: registry: frozen non-mutual (special district) | B9: 2
A10: registry: irrigation mutual | B10: 4
A11: registry: mutual, no PWSID, purpose not stated | B11: 3
A12: registry: retail mutual | B12: 179
A13: registry: wholesale mutual | B13: 2
