Workbook

Sheet Summary
A1: Lincoln Avenue Water Company
A2: Financial Summary - multi-year overview (USD)
A3: Entity ID: cawc_0026 | Fiscal year ends December 31.
A5: Presentation standard: every figure on the statement tabs is verified to its source filing and shown clean. A cell the filing does not report reads "not reported" (never estimated, never guessed).
A6: Citations, confidence tiers, and the filed-vs-computed tie-out checks live on the "Sources & audit" tab, keyed by cell, so every number is fully traceable without cluttering the statements. These pages are ready to use as filed.
A8: Metric | B8: FY2020 | C8: FY2021 | D8: FY2022 | E8: FY2023 | F8: FY2024
A9: Operating results (USD)
A10: Total revenue | B10: 2769445 | C10: 2974975 | D10: 3134087 | E10: 3533209 | F10: 6225040
A11: Total expenses | B11: 1852566 | C11: 1955097 | D11: 1981011 | E11: 2103504 | F11: 5675518
A12: Net income | B12: 916879 | C12: 1019878 | D12: 1153076 | E12: 1429705 | F12: 549522
A14: Financial position (USD, end of year)
A15: Total assets | B15: 21689529 | C15: 22298610 | D15: 23088687 | E15: 24418088 | F15: 24559739
A16: Total liabilities | B16: 2261448 | C16: 1843451 | D16: 1484052 | E16: 1351348 | F16: 923877
A17: Net assets | B17: 19428081 | C17: 20455159 | D17: 21604635 | E17: 23066740 | F17: 23635862
A19: Headline ratios
A20: Operating margin | B20: 0.33106958 | C20: 0.34281902 | D20: 0.36791448 | E20: 0.40464773 | F20: 0.088276059
A21: Revenue growth (YoY) | B21: -0.067256849 | C21: 0.074213425 | D21: 0.053483475 | E21: 0.12734873 | F21: 0.76186577
A22: Return on assets | B22: 0.042272887 | C22: 0.04573729 | D22: 0.049941168 | E22: 0.058551063 | F22: 0.022374912
A24: Figures as reported in source filings (full provenance on the Sources & audit tab). Parentheses denote negatives; ratios are computed upstream in financials_annual.

Sheet Notes
A1: Notes
A2: Human annotations from the versioned store (data/notes/). Annotations only: they never change a reported figure or a confidence tier.
A4: Date | B4: Tag | C4: Author | D4: Note
A5: No notes recorded yet.

Sheet Financial Statements
A1: Lincoln Avenue Water Company
A2: Financial Statements - income statement, balance sheet, cash flow, member income test (USD)
A3: Entity ID: cawc_0026 | Fiscal year ends December 31.
A5: INCOME STATEMENT - as reported (USD)
A6: Line item | B6: FY2020 | C6: FY2021 | D6: FY2022 | E6: FY2023 | F6: FY2024
A7: Revenue
A8: Program service revenue | F8: 6087629
A9: Investment income | B9: 12146 | C9: 6266 | D9: 16752 | E9: 73752 | F9: 89023
A10: Net rental income
A11: Net gain/(loss) on investment sales
A12: Other revenue | D12: 145710 | E12: 271761 | F12: 48388
A13: Contributions & grants
A14: Total revenue | B14: 2769445 | C14: 2974975 | D14: 3134087 | E14: 3533209 | F14: 6225040
A16: Expenses
A17: Depreciation | B17: 566049 | C17: 588471 | D17: 621280 | E17: 648774 | F17: 701225
A18: Interest expense | B18: 26312 | C18: 37279 | D18: 25742 | E18: 19569 | F18: 13173
A19: Total expenses | B19: 1852566 | C19: 1955097 | D19: 1981011 | E19: 2103504 | F19: 5675518
A21: Net income | B21: 916879 | C21: 1019878 | D21: 1153076 | E21: 1429705 | F21: 549522
A24: BALANCE SHEET - as reported (USD, end of year)
A25: Line item | B25: FY2020 | C25: FY2021 | D25: FY2022 | E25: FY2023 | F25: FY2024
A26: Assets
A27: Cash | B27: 3409433 | C27: 3878249 | D27: 4371783 | E27: 4818195 | F27: 4046571
A28: Savings & temporary investments
A29: Accounts receivable | B29: 641215 | C29: 496861 | D29: 383551 | E29: 553260 | F29: 520235
A30: Inventories | B30: 80829 | C30: 75744 | D30: 66071 | E30: 97207 | F30: 70771
A31: Prepaid expenses | B31: 47334 | C31: 69348 | D31: 87055 | E31: 95504 | F31: 184024
A32: Property, plant & equipment (gross) | B32: 28961796 | C32: 29817957 | D32: 30813831 | E32: 32104419 | F32: 33625886
A33: Less: accumulated depreciation | B33: -11452086 | C33: -12040557 | D33: -12633612 | E33: -13250505 | F33: -13887756
A34: Net property, plant & equipment | B34: 17509710 | C34: 17777400 | D34: 18180219 | E34: 18853914 | F34: 19738130
A35: Total assets | B35: 21689529 | C35: 22298610 | D35: 23088687 | E35: 24418088 | F35: 24559739
A37: Liabilities
A38: Accounts payable | B38: 553124 | C38: 401493 | D38: 319587 | E38: 472094 | F38: 344750
A39: Mortgages & notes payable
A40: Total liabilities | B40: 2261448 | C40: 1843451 | D40: 1484052 | E40: 1351348 | F40: 923877
A42: Net Assets / Equity
A43: Capital stock | B43: 328023 | C43: 335223 | D43: 331623 | E43: 364023 | F43: 383623
A44: Paid-in capital | B44: 0 | C44: 0 | D44: 0 | E44: 0 | F44: 0
A45: Retained earnings | B45: 19100058 | C45: 20119936 | D45: 21273012 | E45: 22702717 | F45: 23252239
A46: Net assets | B46: 19428081 | C46: 20455159 | D46: 21604635 | E46: 23066740 | F46: 23635862
A49: CASH FLOW - derived proxy (USD)
...

Sheet Balance Sheet
A1: Lincoln Avenue Water Company
A2: Balance Sheet - as reported (USD, end of year)
A3: Entity ID: cawc_0026 | Fiscal year ends December 31.
A5: Line item | B5: FY2020 | C5: FY2021 | D5: FY2022 | E5: FY2023 | F5: FY2024
A6: Assets
A7: Cash | B7: 3409433 | C7: 3878249 | D7: 4371783 | E7: 4818195 | F7: 4046571
A8: Savings & temporary investments
A9: Accounts receivable | B9: 641215 | C9: 496861 | D9: 383551 | E9: 553260 | F9: 520235
A10: Inventories | B10: 80829 | C10: 75744 | D10: 66071 | E10: 97207 | F10: 70771
A11: Prepaid expenses | B11: 47334 | C11: 69348 | D11: 87055 | E11: 95504 | F11: 184024
A12: Property, plant & equipment (gross) | B12: 28961796 | C12: 29817957 | D12: 30813831 | E12: 32104419 | F12: 33625886
A13: Less: accumulated depreciation | B13: -11452086 | C13: -12040557 | D13: -12633612 | E13: -13250505 | F13: -13887756
A14: Net property, plant & equipment | B14: 17509710 | C14: 17777400 | D14: 18180219 | E14: 18853914 | F14: 19738130
A15: Total assets | B15: 21689529 | C15: 22298610 | D15: 23088687 | E15: 24418088 | F15: 24559739
A17: Liabilities
A18: Accounts payable | B18: 553124 | C18: 401493 | D18: 319587 | E18: 472094 | F18: 344750
A19: Mortgages & notes payable
A20: Total liabilities | B20: 2261448 | C20: 1843451 | D20: 1484052 | E20: 1351348 | F20: 923877
A22: Net Assets / Equity
A23: Capital stock | B23: 328023 | C23: 335223 | D23: 331623 | E23: 364023 | F23: 383623
A24: Paid-in capital | B24: 0 | C24: 0 | D24: 0 | E24: 0 | F24: 0
A25: Retained earnings | B25: 19100058 | C25: 20119936 | D25: 21273012 | E25: 22702717 | F25: 23252239
A26: Net assets | B26: 19428081 | C26: 20455159 | D26: 21604635 | E26: 23066740 | F26: 23635862
A28: Balance check (assets − liab. − net assets) | B28: 0 | C28: 0 | D28: 0 | E28: 0 | F28: 0
A30: Net PP&E is the reported ppe_net column (gross less accumulated depreciation). The balance check should be ~0 where all three totals are reported; a non-zero value flags a reporting or extraction discrepancy worth reviewing.

Sheet Officers & contractors
A1: Lincoln Avenue Water Company
A2: Officers, Directors & Contractors - Form 990 Part VII (FY2024; USD)
A3: Entity ID: cawc_0026 | Fiscal year ends December 31.
A5: Section A - Officers, directors, trustees, key employees
A6: Name | B6: Title | C6: Reportable comp (org) | D6: Reportable comp (related) | E6: Other comp | F6: Total compensation
A7: J CLAIRDAY | B7: PRESIDENT | C7: 15900 | D7: 0 | E7: 0 | F7: 15900
A8: R GOMPERZ | B8: VP | C8: 9600 | D8: 0 | E8: 0 | F8: 9600
A9: L DUNCAN | B9: 1S VP | C9: 12840 | D9: 0 | E9: 0 | F9: 12840
A10: D FERNANDEZ | B10: TREAS. | C10: 9600 | D10: 0 | E10: 0 | F10: 9600
A11: J BETANCOURT REPORTED ON W-2 | B11: SECRETARY/COO | C11: 178973 | D11: 0 | E11: 0 | F11: 178973
A12: V THOMPSON | B12: ASST. SEC | C12: 9600 | D12: 0 | E12: 0 | F12: 9600
A14: Section B - Independent contractors (over $100,000)
A15: Contractor | B15: Services | C15: Compensation
A17: Section A lists every officer, director, trustee and key employee filed for the latest year; the two with the highest total compensation are highlighted. Total compensation is computed (reportable org + related + other). Section B lists each independent contractor paid over $100,000; the return reports 0 such contractor(s). Source and confidence for every figure are on the Sources & audit tab.

Sheet Revenue (detail)
A1: Lincoln Avenue Water Company
A2: Revenue - Form 990 Part VIII (USD)
A3: Entity ID: cawc_0026 | Fiscal year ends December 31.
A5: Part VIII line | B5: FY2020 | C5: FY2021 | D5: FY2022 | E5: FY2023 | F5: FY2024
A6: Revenue by category
A7: 1h. Total contributions, gifts, grants | B7: not reported | C7: not reported | D7: not reported | E7: not reported | F7: not reported
A8: 2g. Total program service revenue | B8: not reported | C8: not reported | D8: not reported | E8: not reported | F8: 6087629
A9: 3. Investment income | B9: 12146 | C9: 6266 | D9: 16752 | E9: 73752 | F9: 89023
A10: 6d. Net rental income | B10: not reported | C10: not reported | D10: not reported | E10: not reported | F10: not reported
A11: 7d. Net gain/(loss) from investment sales | B11: not reported | C11: not reported | D11: not reported | E11: not reported | F11: not reported
A12: 11e. Other revenue | B12: not reported | C12: not reported | D12: 145710 | E12: 271761 | F12: 48388
A13: 12. Total revenue | B13: =SUM(B7:B12) | C13: =SUM(C7:C12) | D13: =SUM(D7:D12) | E13: =SUM(E7:E12) | F13: =SUM(F7:F12)
A15: Program service revenue detail - FY2024 (lines 2a-2f)
A16: Description | B16: Business code | C16: Total revenue
A17: POTABLE WATER UTILITY | B17: 221000 | C17: 6087629
A18: Revenue category subtotals are as filed. Total revenue (line 12) is a live SUM of the category cells above; its tie-out to the filed total is on the Sources & audit tab. Program service revenue detail is shown for the latest year, with its sum-to-line-2g check on that same audit tab.

Sheet Operating expenses (detail)
A1: Lincoln Avenue Water Company
A2: Statement of Functional Expenses - Form 990 Part IX (USD)
A3: Entity ID: cawc_0026 | Fiscal year ends December 31.
A5: Part IX line (column A Total) | B5: FY2020 | C5: FY2021 | D5: FY2022 | E5: FY2023 | F5: FY2024
A6: Functional expenses, column A Total - by year
A7: 5. Compensation of current officers, directors, trustees | B7: 201820 | C7: 181700 | D7: 215316 | E7: 222430 | F7: 236513
A8: 7. Other salaries and wages | B8: 330604 | C8: 378761 | D8: 290201 | E8: 300606 | F8: 962568
A9: 8. Pension plan accruals and contributions | B9: 65000 | C9: 65000 | D9: 60000 | E9: 65000 | F9: 65000
A10: 9. Other employee benefits | B10: 119170 | C10: 118381 | D10: 210159 | E10: 252574 | F10: not reported
A11: 10. Payroll taxes | B11: 82163 | C11: 79223 | D11: 81823 | E11: 84066 | F11: 89767
A12: 11g. Fees for services: other | B12: 33776 | C12: 34020 | D12: 26120 | E12: 32235 | F12: 192888
A13: 13. Office expenses | B13: 31285 | C13: 38462 | D13: 31280 | E13: 40336 | F13: 63863
A14: 14. Information technology | B14: 28915 | C14: 47718 | D14: 48439 | E14: 48630 | F14: 56881
A15: 20. Interest | B15: 26312 | C15: 37279 | D15: 25742 | E15: 19569 | F15: 13173
A16: 22. Depreciation, depletion, and amortization | B16: 566049 | C16: 588471 | D16: 621280 | E16: 648774 | F16: 701225
A17: 23. Insurance | B17: 214941 | C17: 166720 | D17: 145328 | E17: 170632 | F17: 418385
A18: 24. ALL OTHER | B18: 55389 | C18: 79448 | D18: 93174 | E18: 77009 | F18: 98788
A19: 24. PROPERTY TAXES, LICENSE | B19: 51326 | C19: 40983 | D19: 61602 | E19: 59409 | F19: 80793
A20: 24. UTILITIES | B20: 23440 | C20: 20270 | D20: 22905 | E20: 31154 | F20: 407933
A21: 24. OUTSIDE SERVICE | B21: 16810 | C21: 61551 | D21: 40606 | E21: 43792 | F21: not reported
A22: 24. DISTRIBUTION, PURCHASED | B22: not reported | C22: not reported | D22: not reported | E22: not reported | F22: 2246250
A23: 24e. All other expenses | B23: 5566 | C23: 17110 | D23: 7036 | E23: 7288 | F23: 41491
A24: 25. Total functional expenses | B24: =SUM(B7:B23) | C24: =SUM(C7:C23) | D24: =SUM(D7:D23) | E24: =SUM(E7:E23) | F24: =SUM(F7:F23)
A26: Functional column split - FY2024
A27: Not reported. This filer reports only column A (Total) of Part IX; the program / management / fundraising split (columns B-D) is not filed, so it is left as not reported rather than shown empty or inferred.
A28: Top block: each Part IX line, column A (Total), by year, as filed. Total functional expenses (line 25) is a live SUM of the line cells; its tie-out to the filed total is on the Sources & audit tab. Filer-itemized 24a-24d rows show the most recent year's as-filed wording; rows are aligned across years case-insensitively with collapsed spacing, so a line filed only in a different capitalization or spacing shares one row, while genuinely different wording stays a separate row (every as-filed variant is recorded on the Sources & audit tab). This filer reports only column A (Total); the program / management / fundraising split (columns B-D) is not reported. Lines this filer does not report are omitted rather than shown empty.

Sheet Balance sheet (detail)
A1: Lincoln Avenue Water Company
A2: Balance Sheet - Form 990 Part X (end of year, USD)
A3: Entity ID: cawc_0026 | Fiscal year ends December 31.
A5: Part X line (column B, EOY) | B5: FY2020 | C5: FY2021 | D5: FY2022 | E5: FY2023 | F5: FY2024
A6: Assets
A7: 1. Cash - non-interest-bearing | B7: 3409433 | C7: 3878249 | D7: 4371783 | E7: 4818195 | F7: 4046571
A8: 4. Accounts receivable, net | B8: 641215 | C8: 496861 | D8: 383551 | E8: 553260 | F8: 520235
A9: 8. Inventories for sale or use | B9: 80829 | C9: 75744 | D9: 66071 | E9: 97207 | F9: 70771
A10: 9. Prepaid expenses and deferred charges | B10: 47334 | C10: 69348 | D10: 87055 | E10: 95504 | F10: 184024
A11: 10c. Land, buildings, and equipment, net | B11: 17509710 | C11: 17777400 | D11: 18180219 | E11: 18853914 | F11: 19738130
A12: 15. Other assets | B12: 1008 | C12: 1008 | D12: 8 | E12: 8 | F12: 8
A13: 16. Total assets | B13: =SUM(B7:B12) | C13: =SUM(C7:C12) | D13: =SUM(D7:D12) | E13: =SUM(E7:E12) | F13: =SUM(F7:F12)
A15: Liabilities
A16: 17. Accounts payable and accrued expenses | B16: 553124 | C16: 401493 | D16: 319587 | E16: 472094 | F16: 344750
A17: 24. Unsecured notes and loans payable | B17: 1359806 | C17: 1073280 | D17: 775205 | E17: 470950 | F17: 160277
A18: 25. Other liabilities | B18: 348518 | C18: 368678 | D18: 389260 | E18: 408304 | F18: 418850
A19: 26. Total liabilities | B19: =SUM(B16:B18) | C19: =SUM(C16:C18) | D19: =SUM(D16:D18) | E19: =SUM(E16:E18) | F19: =SUM(F16:F18)
A21: Net assets / fund balances
A22: 29. Capital stock or trust principal | B22: 328023 | C22: 335223 | D22: 331623 | E22: 364023 | F22: 383623
A23: 30. Paid-in or capital surplus | B23: 0 | C23: 0 | D23: 0 | E23: 0 | F23: 0
A24: 31. Retained earnings / accumulated funds | B24: 19100058 | C24: 20119936 | D24: 21273012 | E24: 22702717 | F24: 23252239
A25: 32. Total net assets / fund balances | B25: =SUM(B22:B24) | C25: =SUM(C22:C24) | D25: =SUM(D22:D24) | E25: =SUM(E22:E24) | F25: =SUM(F22:F24)
A27: Every Part X line is end-of-year (column B), as filed. Section totals (lines 16 / 26 / 32) are live SUMs of the lines above; their tie-outs and the balance-sheet identity (16 = 26 + 32) are on the Sources & audit tab. This filer files as a non-FASB mutual, so net assets sit on lines 29-31 (capital stock / paid-in capital / retained earnings); lines this filer does not report are omitted. Lines 10a/10b net into line 10c (shown).

Sheet Net-assets reconciliation
A1: Lincoln Avenue Water Company
A2: Reconciliation of Net Assets - Form 990 Part XI (USD)
A3: Entity ID: cawc_0026 | Fiscal year ends December 31.
A5: Part XI line | B5: FY2020 | C5: FY2021 | D5: FY2022 | E5: FY2023 | F5: FY2024
A6: Reconciliation
A7: 4. Net assets, beginning of year | B7: 18511202 | C7: 19428081 | D7: 20455159 | E7: 21604635 | F7: 23066740
A8: 3. Revenue less expenses | B8: 916879 | C8: 1019878 | D8: 1153076 | E8: 1429705 | F8: 549522
A9: 8. Prior period adjustments | B9: not reported | C9: not reported | D9: not reported | E9: not reported | F9: not reported
A10: 9. Other changes in net assets | B10: 0 | C10: 7200 | D10: -3600 | E10: 32400 | F10: 19600
A11: 10. Net assets, end of year | B11: =SUM(B7,B8,B9,B10) | C11: =SUM(C7,C8,C9,C10) | D11: =SUM(D7,D8,D9,D10) | E11: =SUM(E7,E8,E9,E10) | F11: =SUM(F7,F8,F9,F10)
A13: Part XI reconciles beginning to ending net assets. Ending net assets (line 10) is a live formula: beginning balance (line 4) + revenue less expenses (line 3) + prior-period adjustments (8) + other changes (9). Its tie-out to the filed line 10 (and to Part X line 32) is on the Sources & audit tab. Lines 5-7 (unrealized gains, donated services, investment expenses) are not filed by this entity.

Sheet Cash flow proxies
A1: Lincoln Avenue Water Company
A2: Cash Flow Proxies - derived (USD)
A3: Entity ID: cawc_0026 | Fiscal year ends December 31.
A5: PROXY ONLY. The source filings contain no statement of cash flows. Lines below are derived from the reported income statement and year-over-year balance-sheet changes; treat as directional estimates, not GAAP cash flows. The earliest year has no prior period, so its delta cells are blank.
A7: Proxy line (USD) | B7: FY2020 | C7: FY2021 | D7: FY2022 | E7: FY2023 | F7: FY2024
A8: Operating
A9: Net income | B9: 916879 | C9: 1019878 | D9: 1153076 | E9: 1429705 | F9: 549522
A10: + Depreciation (reported) | B10: 566049 | C10: 588471 | D10: 621280 | E10: 648774 | F10: 701225
A11: − Δ Accounts receivable | C11: 144354 | D11: 113310 | E11: -169709 | F11: 33025
A12: − Δ Inventories | C12: 5085 | D12: 9673 | E12: -31136 | F12: 26436
A13: − Δ Prepaid expenses | C13: -22014 | D13: -17707 | E13: -8449 | F13: -88520
A14: + Δ Accounts payable | C14: -151631 | D14: -81906 | E14: 152507 | F14: -127344
A15: Operating cash flow proxy | C15: 1584143 | D15: 1797726 | E15: 2021692 | F15: 1094344
A17: Investing
A18: − Δ PP&E gross (capex proxy) | C18: -856161 | D18: -995874 | E18: -1290588 | F18: -1521467
A20: Financing
A21: Δ Mortgages & notes payable
A23: Reconciliation
A24: Δ Cash + temp. investments (actual) | C24: 468816 | D24: 493534 | E24: 446412 | F24: -771624
A26: The capex proxy assumes gross PP&E rises only via capital spending (it ignores disposals). 'Δ Cash + temp. investments (actual)' is the real reported change in liquid funds and is the most reliable line here; the operating/investing/financing proxies will not perfectly reconcile to it.

Sheet Ratios
A1: Lincoln Avenue Water Company
A2: Financial Ratios
A3: Entity ID: cawc_0026 | Fiscal year ends December 31.
A5: Ratio | B5: FY2020 | C5: FY2021 | D5: FY2022 | E5: FY2023 | F5: FY2024
A6: Profitability (computed upstream)
A7: Operating margin (NI / revenue) | B7: 0.33106958 | C7: 0.34281902 | D7: 0.36791448 | E7: 0.40464773 | F7: 0.088276059
A8: Expense ratio (expenses / revenue) | B8: 0.66893042 | C8: 0.65718098 | D8: 0.63208552 | E8: 0.59535227 | F8: 0.91172394
A9: Return on assets (NI / assets) | B9: 0.042272887 | C9: 0.04573729 | D9: 0.049941168 | E9: 0.058551063 | F9: 0.022374912
A10: Revenue growth (YoY) | B10: -0.067256849 | C10: 0.074213425 | D10: 0.053483475 | E10: 0.12734873 | F10: 0.76186577
A12: Leverage & solvency
A13: Debt-to-assets (liab. / assets) | B13: 0.1042645 | C13: 0.082671117 | D13: 0.064276154 | E13: 0.055342089 | F13: 0.037617541
A14: Equity ratio (net assets / assets) | B14: 0.8957355 | C14: 0.91732888 | D14: 0.93572385 | E14: 0.94465791 | F14: 0.96238246
A16: Liquidity & asset profile (derived here)
A17: Current ratio (current assets / AP) | B17: 7.5549262 | C17: 11.258483 | D17: 15.35876 | E17: 11.78614 | F17: 13.98579
A18: Cash ratio ((cash+temp inv.) / total liab.) | B18: 1.5076327 | C18: 2.1037983 | D18: 2.9458422 | E18: 3.5654731 | F18: 4.3799889
A19: Asset age proxy (accum. deprec. / gross PP&E) | B19: 0.39542044 | C19: 0.40380221 | D19: 0.40999809 | E19: 0.4127315 | F19: 0.41300788
A21: Upstream ratios are read from financials_annual; derived ratios are computed only where inputs are reported. Current ratio uses accounts payable as the current-liability proxy (the filings do not split current vs. long-term liabilities). Asset age proxy: a higher % implies older / more depreciated infrastructure.

Sheet Unit economics
A1: Lincoln Avenue Water Company
A2: Unit economics - per-customer revenue by category (USD)
A3: Entity ID: cawc_0026 | Fiscal year ends December 31.
A5: Every metric here is PER CUSTOMER (a metered service connection). It is not a per-member figure; the member (shareholder) count is a different denominator, shown in the denominator block. The visible cell shows the value and its classification; the numerator, denominator, formula, and rationale are in each metric's LOGIC popup.
A6: Per-customer denominator (service connections) | B6: 4477 | C6: State Water Board eAR Section 4 (CurTotalConnections), reporting year 2023
A7: Total annual revenue (eAR Section 8b B1.8) | B7: 6191765 | C7: State Water Board eAR Section 8b, question B1.8 (total annual revenue), reporting year 2023
A8: Primary source | C8: State Water Board eAR Section 8b (revenue by rate/fee), reporting year 2023
A10: Revenue categories (value, classification, per customer, share)
A11: Revenue category | B11: Classification | C11: Value (USD) | D11: Per customer | E11: Share of revenue
A12: Water sales revenue | B12: DIRECT | C12: 4758028 | D12: 1062.77 | E12: 0.7684
A13: Assessment revenue (990 program-service revenue not matched to eAR water-rate revenue) | B13: DERIVED | C13: -4486267 | D13: -1002.07 | E13: -16.5081
A14: Meter revenue | B14: not reported | C14: not reported | D14: not reported | E14: not reported
A15: Overage or tiered penalty revenue | B15: not reported | C15: not reported | D15: not reported | E15: not reported
A17: Water sales revenue - DIRECT
A18: Revenue customers paid for water service, read straight off the filed eAR Section 8b water-rate line. A DIRECT filed figure, not computed by us.
A19: Numerator: Water rate revenue | B19: 4758028 | C19: eAR Section 8b field B1.1 (residential water rates) + B1.2 (non-residential water rates). State Water Board eAR Section 8b, question B1.1 + B1.2 (revenue from water rates), reporting year 2023
A20: Denominator: Total service connections | B20: 4477 | C20: eAR Section 4 CurTotalConnections, reporting year 2023. State Water Board eAR Section 4 (CurTotalConnections), reporting year 2023
A21: Per customer: water rate revenue $4,758,028 / 4,477 connections = $1,062.77 per connection
A22: Share of revenue: water rate revenue $4,758,028 / total annual revenue (eAR Section 8b B1.8) $6,191,765 = 76.84%
A23: Period treatment: Numerator (eAR Section 8b, the calendar year 2023) and denominator (eAR Section 4 connections reported in the same eAR filing) are both the eAR reporting year 2023, so the two sides are bound to the same reporting year.
A24: Rationale: Dividing water-rate revenue by the number of metered service connections gives the average revenue per customer; dividing by total annual revenue shows how much of the system's income comes from water rates.
A26: Assessment revenue (990 program-service revenue not matched to eAR water-rate revenue) - DERIVED
A27: A DERIVED residual (medium confidence): the part of the Form 990 program-service revenue that is not matched by the eAR water-rate revenue for the same period. Computed by us, not a filed line.
A28: Input A: Form 990 program-service revenue | B28: 271761 | C28: Form 990 Part VIII line 2 (total program-service revenue), fiscal year 2023 ending December 31, 2023
A29: Input B: eAR water-rate revenue | B29: 4758028 | C29: State Water Board eAR Section 8b, question B1.1 + B1.2 (revenue from water rates), reporting year 2023
A30: Residual (A minus B) = assessment revenue | B30: =B28-B29 | C30: $271,761 (990 program-service revenue) minus $4,758,028 (eAR water-rate revenue) = $-4,486,267
A31: Period alignment: Both inputs cover the same period: the eAR Section 8b is the calendar year 2023 and the Form 990 fiscal year 2023 ends December 31, 2023, so the residual is period-aligned.
A32: What it IS: revenue the system booked as program service on its 990 that is not accounted for by the eAR water-rate line, plausibly member assessments and other service revenue.
A33: This residual is a difference between two sources for the same period; it is not a separately filed assessment line and may include other unmatched revenue.
A34: Denominator: Total service connections | B34: 4477 | C34: eAR Section 4 CurTotalConnections, reporting year 2023. State Water Board eAR Section 4 (CurTotalConnections), reporting year 2023
A35: Per customer: residual $-4,486,267 / 4,477 connections = $-1,002.07 per connection
A36: Share of revenue: residual $-4,486,267 / 990 program-service revenue $271,761 = -1650.81%
A38: Meter revenue - not reported
A39: Not reported. This category is not built because doing so would double-count.
A40: Reason: The eAR Section 8a reports a base/meter rate PRICE, but the filing carries no meter revenue line and no tier volume, and the base charge is already inside the water-sales revenue (eAR Section 8b water rates). Building a separate meter figure would double-count. Not backed into from a total.
A42: Overage or tiered penalty revenue - not reported
A43: Not reported. This category is not built because doing so would double-count.
A44: Reason: The eAR Section 8a reports tiered/overage rate PRICES, but the filing carries no overage revenue and no tier consumption volume, and any overage billed is already inside the water-sales revenue. Building it would double-count. Not backed into from a total.

Sheet Rate structure
A1: Lincoln Avenue Water Company
A2: Rate structure and representative bill - eAR Section 8a (RY2024)
A3: Entity ID: cawc_0026 | Fiscal year ends December 31.
A5: This block is a rate-schedule illustration at defined usage levels. It is NOT billed revenue and not a claim about any real customer's usage. The revenue side of unit economics is the separate Unit Economics block.
A6: Structure: Tiered increasing-block with a fixed base, billed monthly, priced per HCF. Rate schedule last updated 04/30/2010.
A7: Defined single-family usage levels, identical for every company so the bill is comparable: Low = 5 HCF/month (~125 gallons/day); Median = 10 HCF/month (~249 gallons/day); High = 25 HCF/month (~623 gallons/day). 1 HCF = 748 gallons, and 1 thousand gallons = 1,000 gallons. The usage is converted into the company's own filed unit before the filed tiers are applied, and the bill is stated as a monthly equivalent: a bimonthly structure is computed at twice the monthly usage and divided by two, and any other billing period the same way with its factor stated. These are an illustration, not a measured usage for any real customer.
A9: Defined usage levels (EDITABLE - change a yellow cell to move the bill)
B10: Low | C10: Median | D10: High
A11: Monthly usage (HCF) | B11: 5 | C11: 10 | D11: 25
A12: Months per bill (from filed billing frequency) | B12: 1 | C12: monthly biller
A14: Filed rate table - single-family residential (as filed, eAR Section 8a)
A15: Base / fixed charge per monthly bill ($) | B15: 30.5
A16: Tier | B16: Range (HCF) | C16: Price ($/HCF) | D16: Upper limit (HCF)
A17: Tier 1 | B17: 0 to 7 HCF | C17: 4.03 | D17: 7
A18: Tier 2 | B18: 7 to 20 HCF | C18: 4.76 | D18: 20
A19: Tier 3 | B19: 20 to 40 HCF | C19: 5.31 | D19: 40
A20: Tier 4 | B20: over 40 HCF | C20: 5.92 | D20: no limit
A22: Representative monthly bill - LIVE (edit a yellow usage cell to recompute)
B23: Low | C23: Median | D23: High
A24: Usage per bill (HCF) | B24: =B11*$B$12 | C24: =C11*$B$12 | D24: =D11*$B$12
A25: Tier 1 charge per bill ($) | B25: =$C$17*MAX(0,MIN(B24,$D$17)-0) | C25: =$C$17*MAX(0,MIN(C24,$D$17)-0) | D25: =$C$17*MAX(0,MIN(D24,$D$17)-0)
A26: Tier 2 charge per bill ($) | B26: =$C$18*MAX(0,MIN(B24,$D$18)-$D$17) | C26: =$C$18*MAX(0,MIN(C24,$D$18)-$D$17) | D26: =$C$18*MAX(0,MIN(D24,$D$18)-$D$17)
A27: Tier 3 charge per bill ($) | B27: =$C$19*MAX(0,MIN(B24,$D$19)-$D$18) | C27: =$C$19*MAX(0,MIN(C24,$D$19)-$D$18) | D27: =$C$19*MAX(0,MIN(D24,$D$19)-$D$18)
A28: Tier 4 charge per bill ($) | B28: =$C$20*MAX(0,B24-$D$19) | C28: =$C$20*MAX(0,C24-$D$19) | D28: =$C$20*MAX(0,D24-$D$19)
A29: Volumetric charge per bill ($) | B29: =SUM(B25,B26,B27,B28) | C29: =SUM(C25,C26,C27,C28) | D29: =SUM(D25,D26,D27,D28)
A30: Base charge per bill ($) | B30: =$B$15 | C30: =$B$15 | D30: =$B$15
A31: Total per bill ($) | B31: =B30+B29 | C31: =C30+C29 | D31: =D30+D29
A32: Total per MONTH ($) | B32: =B31/$B$12 | C32: =C31/$B$12 | D32: =D31/$B$12
A33: Fixed per month ($) | B33: =$B$15/$B$12 | C33: =$B$15/$B$12 | D33: =$B$15/$B$12
A34: Volumetric per month ($) | B34: =B29/$B$12 | C34: =C29/$B$12 | D34: =D29/$B$12
A35: Effective price ($/HCF) | B35: =IF(B11=0,"",B32/B11) | C35: =IF(C11=0,"",C32/C11) | D35: =IF(D11=0,"",D32/D11)
A37: Rate-structure comparison metrics
A38: Fixed share of the bill at median usage | B38: =C33/C32 | C38: fixed / total at 10 HCF/month
A39: Tier price ratio (highest to lowest positive tier) | B39: =$C$20/$C$17 | C39: highest filed tier price divided by lowest filed tier price.
A40: Rate structure (as filed) | B40: tiered (Variable Base)
A42: State Water Board eAR Section 8a (Customer Charges), single- and multi-family residential charges grid, reporting year 2024. Rate structure only; no revenue.

Sheet eAR revenue & expenses
A1: Lincoln Avenue Water Company
A2: eAR annual revenue and expenses - State Water Board eAR Section 8b (USD)
A3: Entity ID: cawc_0026 | Fiscal year ends December 31.
A5: The water system's own annual figures from the public eAR Section 8b, on the calendar year 2023 the filer self-reported (B0.1/B0.2). Shown beside the period-aligned Form 990 with the variance flagged: a different source (a State Water Board self-report vs an IRS filing). Preserved as filed, never reconciled.
A6: Reporting period basis (self-reported) | B6: calendar year 2023 | C6: eAR Section 8b B0.1 (WRFinancialReportingPeriod)
A8: Revenue (eAR Section 8b, questions B1.x)
A9: Line | B9: Amount (USD) | C9: Citation
A10: Water rate revenue | B10: 4758028 | C10: State Water Board eAR Section 8b, question B1.1 + B1.2 (revenue from water rates), reporting year 2023
A11: Other fees and charges | B11: 115576 | C11: State Water Board eAR Section 8b, question B1.3 + B1.4 (revenue from other fees), reporting year 2023
A12: Non-customer revenue | B12: 1318161 | C12: State Water Board eAR Section 8b, question B1.7 (grants, interest, and other non-customer), reporting year 2023
A13: Total annual revenue | B13: 6191765 | C13: State Water Board eAR Section 8b, question B1.8 (total annual revenue for the reporting year), reporting year 2023
A15: Expenses (eAR Section 8b, questions B2.x)
A16: Line | B16: Amount (USD) | C16: Citation
A17: Operations and maintenance | B17: 4763207 | C17: State Water Board eAR Section 8b, question B2.1 (annual O and M expense), reporting year 2023
A18: Capital | B18: 1339232 | C18: State Water Board eAR Section 8b, question B2.2 (annual expenses from investing or capital), reporting year 2023
A19: Financing | B19: 19569 | C19: State Water Board eAR Section 8b, question B2.3 (annual expenses from financing), reporting year 2023
A20: Other | B20: 0 | C20: State Water Board eAR Section 8b, question B2.4 (total other annual expenses), reporting year 2023
A21: Total annual expenses | B21: 6122008 | C21: State Water Board eAR Section 8b, question B2.5 (total annual expenses), reporting year 2023
A23: Period-aligned Form 990 comparison (variance surfaced, never reconciled)
A24: Measure | B24: eAR Section 8b | C24: Form 990
A25: total revenue | B25: 6191765 | C25: 3533209
A26: Variance (eAR minus Form 990) | B26: =B25-C25
A27: The eAR Section 8b total revenue (State Water Board self-report, calendar year 2023) and the Form 990 total revenue (IRS filing) are a different source and cover the same calendar year 2023. Both are carried as filed; the variance is surfaced, never reconciled.
A28: total expenses | B28: 6122008 | C28: 2103504
A29: Variance (eAR minus Form 990) | B29: =B28-C28
A30: The eAR Section 8b total expenses (State Water Board self-report, calendar year 2023) and the Form 990 total expenses (IRS filing) are a different source and cover the same calendar year 2023. Both are carried as filed; the variance is surfaced, never reconciled.

Sheet Denominators & alignment
A1: Lincoln Avenue Water Company
A2: Denominators and calendar alignment
A3: Entity ID: cawc_0026 | Fiscal year ends December 31.
A5: System size and water use per fiscal year (the operating denominators that per-customer and per-acre metrics divide by), each cited to file and field. The eAR is reported on the calendar year; the 990 fiscal year differs by company. A calendar-year filer's volume is the eAR annual total (fiscal year = calendar year); an offset filer's is recast by a true monthly sum of the covered calendar months, or read not reported naming the missing months. Point-in-time counts (connections, population) are matched to the closest eAR year and never summed. Every derived figure states its formula and accounting rationale.
A6: Member vs customer (two different denominators, both preserved)
A7: Customer (service connection) | B7: 4493 | C7: State Water Board eAR Section 4 (CurTotalConnections), reporting year 2024
A8: SDWIS service-connection count (different registry) | B8: 4493
A9: Member (shareholder) | C9: No published shareholder count
A10: In a mutual water company a MEMBER is a shareholder who owns part of the system; a CUSTOMER is a metered service connection that receives water. The two diverge because one owner can hold several connections, a connection can serve people who are not owners, and some mutuals attach shares to land by acreage rather than counting heads. Per-customer metrics divide by service connections; per-member metrics divide by shareholders; the two counts are never used interchangeably.
A12: Denominator layer by fiscal year
A13: Fiscal year (end) | B13: Connections | C13: Population | D13: Service-area acres | E13: Water produced (AF) | F13: Water delivered (AF) | G13: Alignment method
A14: FY2020 (2020-12-31) | B14: 4476 | C14: not reported | D14: 1693.4 | E14: 2307.9 | F14: 2045.9 | G14: eAR annual total, calendar filer, equals fiscal year (not a monthly recast)
A15: FY2021 (2021-12-31) | B15: 4477 | C15: not reported | D15: 1693.4 | E15: 2177.1 | F15: 889149 | G15: eAR annual total, calendar filer, equals fiscal year (not a monthly recast)
A16: FY2022 (2022-12-31) | B16: 4477 | C16: not reported | D16: 1693.4 | E16: 1896.6 | F16: 782140 | G16: eAR annual total, calendar filer, equals fiscal year (not a monthly recast)
A17: FY2023 (2023-12-31) | B17: 4477 | C17: 16126 | D17: 1693.4 | E17: not reported | F17: not reported | G17: eAR annual total, calendar filer, equals fiscal year (not a monthly recast)
A18: FY2024 (2024-12-31) | B18: 4493 | C18: 16126 | D18: 1693.4 | E18: not reported | F18: not reported | G18: eAR annual total, calendar filer, equals fiscal year (not a monthly recast)
A20: Connections by class - FY2024 (eAR Section 4)
A21: Single-family residential | B21: 4148
A22: Multi-family residential | B22: 218
A23: Commercial and institutional | B23: 133
A24: Industrial | B24: 0
A25: Landscape irrigation | B25: 0
A26: Agricultural | B26: 0
A27: Monthly-volume source: California open-data portal (data.ca.gov): the separate Produced Water (by month and source) and Delivered Water (by month and connection type) resources, which cover every public water system (not only urban suppliers), one resource per reporting year, matched by exact PWSID. This is the aggregate publication of eAR Section 6.

Sheet Governance evidence
A1: Lincoln Avenue Water Company
A2: Governance evidence status - Ostrom's eight design principles
A3: Entity ID: cawc_0026 | Fiscal year ends December 31.
A5: Evidence summary: 5 documented, 1 partial, 2 not documented of eight principles.
A6: A count of how many of Elinor Ostrom's eight design principles have a supporting record on file, not a grade. NOT DOCUMENTED means the supporting record was not found, not that the company governs badly. It marks a gap in the documentary record, an evidence gap to close, never a governance failing.
A7: Each mutual is read against Elinor Ostrom's eight design principles for institutions that govern a shared resource durably. Per principle: a one-line finding, the observable signal, a citation, and an evidence status stating whether the supporting record exists: DOCUMENTED (a cited record supports alignment), PARTIAL (some evidence exists but it is incomplete), or NOT DOCUMENTED (no supporting record was found). This is an evidence-status read, not a grade: the principles are never ranked, weighted, or given a letter, consistent with reporting as filed and not grading companies. NOT DOCUMENTED means the supporting record was not found, not that the company governs badly. It marks a gap in the documentary record, an evidence gap to close, never a governance failing.
A9: Principle | B9: Evidence status | C9: Finding | D9: Signal | E9: Citation
A10: Clearly defined boundaries | B10: DOCUMENTED | C10: The system is a defined public water system: 4,493 service connections over a State-published service-area boundary. | D10: SDWIS Community water system; SABL service-area boundary (not verified (sabl)); connections defined. | E10: [C][G]
A11: What the record shows: SDWIS defines the membership as a fixed set of service connections and the State Water Board publishes a SABL service-area polygon, so who is inside and outside the system is documented. The boundary is Not Verified (SABL), so its outer edge rests on that State layer.
A12: Rules fit local conditions | B12: DOCUMENTED | C12: Charges are tied to service under a documented rate or share-based allocation rule reported to the State or set in the company's structure. | D12: eAR Section 8a customer charges; documented rate or share-allocation rule. | E12: [E][r1]
A13: What the record shows: The record documents how charges are set, whether a filed metered rate schedule or a share-and-acreage allocation, so cost tracks service. Whether every tier scales precisely with use is only partially visible at this scale, but a real cost-to-service rule is on record.
A14: Collective-choice arrangements | B14: DOCUMENTED | C14: The company is owned by its customer-shareholders and run by a named board they elect, documented in its Form 990 governance section. | D14: Mutual ownership; named elected board of directors (Form 990). | E14: [990][r1]
A15: What the record shows: The record documents a collective-choice mechanism: customers are shareholders who elect a named board that governs the company. Turnout and specific member votes on major decisions are not documented, but the elected-board structure and its membership are on record.
A16: Monitoring | B16: DOCUMENTED | C16: The system is metered and monitored: the State SAFER risk assessment shows it Not Failing, and it files an annual eAR. | D16: SAFER Not Failing; annual eAR reporting; metered connections. | E16: [S][E]
A17: What the record shows: Operational monitoring is documented: the State rates the system Not Failing on its drinking-water risk assessment and the system files an annual eAR. No independent audited financial statement is published, so financial monitoring is weaker, but the operational record is present.
A18: Graduated sanctions | B18: NOT DOCUMENTED | C18: No published shut-off, penalty, or delinquency policy was found for this system. | D18: No sourced sanctions policy. | E18: not reported
A19: What the record shows: No public record of a graduated shut-off or penalty policy was found for a system this small. NOT DOCUMENTED means the supporting record was not found, not that the company governs badly. It marks a gap in the documentary record, an evidence gap to close, never a governance failing.
A20: Conflict-resolution mechanisms | B20: NOT DOCUMENTED | C20: No published bylaws, dispute procedure, or grievance mechanism was found for this system. | D20: No sourced conflict-resolution record. | E20: not reported
A21: What the record shows: No public record of a member dispute or conflict-resolution procedure was found. NOT DOCUMENTED means the supporting record was not found, not that the company governs badly. It marks a gap in the documentary record, an evidence gap to close, never a governance failing.
A22: Recognized right to organize | B22: DOCUMENTED | C22: An incorporated California mutual water company recognized by the IRS (501(c)(12)) and by the State Water Board as a public water system. | D22: IRS 501(c)(12) exempt filer (Form 990); SDWIS public water system. | E22: [990][C][SOS]
A23: What the record shows: Baseline legal standing is documented: the company is an incorporated mutual recognized by the IRS as a tax-exempt filer and by the State Water Board as a regulated water system. This records the right to organize as a member entity, not a documented instance of exercising it. The California Secretary of State holds the company as a registered corporation, entity number 0025301, first registered 03/26/1896, status as filed "Active", with a governing body named in the Statement of Information filed 2/25/2026. That is a direct state record of the right to organize being recognized, so the evidence behind this status is now a filed corporate record rather than an inference from the company's tax form. The status was already DOCUMENTED and does not move.
A24: Nested enterprises | B24: PARTIAL | C24: The system draws on a shared local groundwater basin, embedding it in a larger physical water system, though its role in basin governance is not documented. | D24: SDWIS Primary Water Source Type: groundwater (shared basin). | E24: [C]
A25: What the record shows: The system relies on a shared groundwater basin, so it is physically nested in a larger hydrologic system. Its participation in a groundwater sustainability agency or basin governance is not documented, so the nesting evidence is partial.

Sheet Operational metrics
A1: Lincoln Avenue Water Company
A2: Operational metrics - plant per acre, density, terrain
A3: Entity ID: cawc_0026 | Fiscal year ends December 31.
A5: Plant assets per acre
A6: Service-area acres | B6: 1693.4 | C6: Geodesic area (WGS84 spherical excess) of the SABL service-area polygon.
A7: Fiscal year | B7: Gross plant per acre (primary) | C7: Net plant per acre
A8: FY2020 | B8: 17102.75 | C8: 10339.973
A9: FY2021 | B9: 17608.337 | C9: 10498.051
A10: FY2022 | B10: 18196.428 | C10: 10735.927
A11: FY2023 | B11: 18958.556 | C11: 11133.763
A12: FY2024 | B12: 19857.025 | C12: 11655.917
A13: Infrastructure built per acre of service area. Gross plant per acre is the primary read because it measures how much plant the system has put in the ground per acre, and unlike net plant it does not fall over time purely because the assets depreciate on the books. Net plant per acre is shown alongside as the depreciated book value per acre.
A14: Formula: gross plant per acre = Form 990 Part X line 10a (land, buildings, and equipment, gross) / SABL service-area acres; net plant per acre uses Part X line 10c (net)
A15: Source lines: Form 990 Part X line 10a (gross) and line 10c (net); Geodesic area (WGS84 spherical excess) of the SABL service-area polygon.
A16: Confidence: medium. This is worked out from filed figures (a ratio, or a year-to-year change), so it is one step removed from the raw numbers.. Filed gross/net plant over the measured SABL service-area acreage.
A18: Connections per acre
A19: Connections per acre | B19: 2.66 | C19: 4,508 connections / 1,693.4 acres. CA State Water Board SABL SERVICE_CONNECTIONS; Geodesic area (WGS84 spherical excess) of the SABL service-area polygon.
A21: Who they are
A22: Terrain class | B22: canyon | C22: Company context page (BLUEPRINT 5B)
A23: A private not-for-profit mutual water company serving about 4,490 service connections and roughly 16,000 residents in western and northwest Altadena, Los Angeles County, in the San Gabriel Mountain foothills and canyons.

Sheet Supply & weather
A1: Lincoln Avenue Water Company
A2: Supply and weather indicators (DWR water year)
A3: Entity ID: cawc_0026 | Fiscal year ends December 31.
A5: Reporting calendar: Different reporting periods. The DWR water year runs October 1 to September 30; this system's fiscal year ends December 31, so the two period ends are three months apart. Read the two side by side with that in mind. Neither series is recast: both are reported as filed. A water year is named for the calendar year it ends in, so WY2024 and FY2024 share a number without covering the same twelve months.
A7: Indicator | B7: WY2020 | C7: WY2021 | D7: WY2022 | E7: WY2023 | F7: WY2024
A8: Water-year type (Sacramento Valley) | B8: Dry | C8: Critical | D8: Critical | E8: Wet | F8: Above Normal
A9: Peak drought, Los Angeles County | B9: D1 | C9: D4 | D9: D4 | E9: D4 | F9: None (no D0-D4 during the fiscal year)
A10: Precip, percent of normal (8-Station Index) | B10: 63 | C10: 48 | D10: 86 | E10: 133 | F10: 96
A11: Snowpack, April 1 percent of average | B11: 53% | C11: 59% | D11: 38% | E11: 237% | F11: 110%
A12: State Water Project allocation | B12: 20% | C12: 5% | D12: 5% | E12: 100% | F12: 40%

Sheet How this was built
A1: Lincoln Avenue Water Company
A2: How this was built - forensic lineage
A3: Entity ID: cawc_0026 | Fiscal year ends December 31.
A5: A plain account of the forensic lineage behind the hard-to-source metrics: what sources were checked, what was found, what was derived, and what could not be built and why. Every figure marked DERIVED or IMPOSSIBLE above is traceable to a line here.
A7: Water-sales revenue per customer - DIRECT
A8: Sources checked | B8: State Water Board eAR Section 8b (water-rate revenue B1.1/B1.2); State Water Board eAR Section 4 (connection count, same reporting year); audited financial statement (secondary cross-check, where published)
A9: What was found | B9: The eAR Section 8b reports water-rate revenue for reporting year 2023, so this is a DIRECT filed figure; per customer it is divided by the eAR Section 4 connection count for the same reporting year, so numerator and denominator share the year.
A11: Assessment revenue (residual) - DERIVED
A12: Sources checked | B12: Form 990 Part VIII line 2 (program-service revenue); State Water Board eAR Section 8b (water-rate revenue B1.1/B1.2)
A13: What was found | B13: No source separately reports a member assessment, so it is DERIVED as a residual: $271,761 (990 program-service revenue) minus $4,758,028 (eAR water-rate revenue) = $-4,486,267. Period-aligned; medium confidence.
A14: Caveat | B14: This residual is a difference between two sources for the same period; it is not a separately filed assessment line and may include other unmatched revenue.
A16: Meter revenue - not reported
A17: Sources checked | B17: State Water Board eAR Section 8a (rate prices); State Water Board eAR Section 8b (revenue lines); audited financial statement
A18: What was found | B18: The rate price exists in Section 8a but no revenue or tier volume is reported, and the base charge is already inside water sales.
A19: Caveat | B19: The eAR Section 8a reports a base/meter rate PRICE, but the filing carries no meter revenue line and no tier volume, and the base charge is already inside the water-sales revenue (eAR Section 8b water rates). Building a separate meter figure would double-count. Not backed into from a total.
A21: Overage / tiered-penalty revenue - not reported
A22: Sources checked | B22: State Water Board eAR Section 8a (rate prices); State Water Board eAR Section 8b (revenue lines); audited financial statement
A23: What was found | B23: The rate price exists in Section 8a but no revenue or tier volume is reported, and the base charge is already inside water sales.
A24: Caveat | B24: The eAR Section 8a reports tiered/overage rate PRICES, but the filing carries no overage revenue and no tier consumption volume, and any overage billed is already inside the water-sales revenue. Building it would double-count. Not backed into from a total.
A26: eAR Section 8b reporting-period basis - sourced
A27: Sources checked | B27: eAR Section 8b B0.1 (WRFinancialReportingPeriod); eAR Section 8b B0.2 (WRFiscalYearStartDate)
A28: What was found | B28: The reporting basis (fiscal vs calendar year) is read from the filer's own B0.1/B0.2 answer and staged verbatim, never hardcoded, so the 990 comparison and the residual are period-aligned.
A30: Member (shareholder) count denominator - not reported
A31: Sources checked | B31: Form 990 (no member count stated); company website
A32: What was found | B32: No filing states a member/shareholder count, so the per-member unit economics read not reported rather than borrowing the connection count.
A34: Water volume delivered (acre-feet) - not reported
A35: Sources checked | B35: Form 990 (not in the filing); Consumer Confidence Report; eAR Section 6 (PRA-gated)
A36: What was found | B36: Volume delivered in acre-feet is not in the Form 990 and the CCR states only a source mix, so the per-acre-foot metrics read not reported; the eAR Section 6 is named as the source still needed.

Sheet Water Operations
A1: Lincoln Avenue Water Company
A2: Water Operations (sourced outside the financial filings)
A3: Entity ID: cawc_0026 | Fiscal year ends December 31.
A5: A separate dialect of data from the financial statements: the system's water supply, from the California State Water Board records (the Consumer Confidence Report served by the eAR portal, and SDWIS Drinking Water Watch). Each field carries its source, year, and confidence the same way a financial line item does; a field the source does not state reads 'not reported' with the source still needed. Figures are as reported, never estimated or reconciled across sources.
A7: Field | B7: Value | C7: Source | D7: Year | E7: Confidence | F7: Source excerpt / cross-source note
A8: Water type | B8: Potable (community drinking water) | C8: SDWIS Drinking Water Watch (State Water Board) | D8: 2024 | E8: high | F8: LINCOLN AVENUE WATER CO.: State Water System Type = Community.
A9: Source mix | B9: Primary source: surface water (SDWIS Primary Water Source Type: Surface Water). SDWIS classifies the primary supply type; it states no acre-foot volume by source. | C9: SDWIS Drinking Water Watch (State Water Board) | D9: 2024 | E9: high | F9: LINCOLN AVENUE WATER CO.: Primary Water Source Type = Surface Water.
A10: Service connections (total) | B10: 4,493 connections | C10: SDWIS Drinking Water Watch (State Water Board) | D10: 2024 | E10: high | F10: LINCOLN AVENUE WATER CO.: Total Number of Service Connections = 4,493. [cross-source: SDWIS connection snapshot; the eAR reports active service connections on its own basis and per reporting year. Both preserved, not reconciled.]
A11: Connections by class | B11: Service connections by type (SDWIS snapshot): Residential 4,360; Commercial 133; Total 4,493. | C11: SDWIS Drinking Water Watch (State Water Board) | D11: 2024 | E11: high | F11: LINCOLN AVENUE WATER CO.: connections by type - Residential 4,360; Commercial 133; Total 4,493.
A12: Population served | B12: 16,126 residents | C12: SDWIS Drinking Water Watch (State Water Board) | D12: 2024 | E12: high | F12: LINCOLN AVENUE WATER CO.: Total Population = 16,126.
A13: Treatment and water quality | B13: Operator certification on file: Treatment Operator Level 2; Distribution Operator Level 4. SDWIS states operator grades, not the treatment process detail. | C13: SDWIS Drinking Water Watch (State Water Board) | D13: 2024 | E13: high | F13: LINCOLN AVENUE WATER CO.: Treatment Plant Class = Treatment Operator Level 2; Distribution System Class = Distribution Operator Level 4.
A15: Not reported (source still needed)
A16: Annual volume delivered (acre-feet) | B16: not reported - needs annual volume in acre-feet (State Water Board eAR Section 6 or company production records); the CCR states only a percentage mix
A17: Customer classes served | B17: not reported - needs the State Water Board eAR or the system CCR

Sheet Anomaly Flags
A1: Lincoln Avenue Water Company
A2: Anomaly Flags (automated; kept separate from the clean statements)
A3: Entity ID: cawc_0026 | Fiscal year ends December 31.
A5: Material irregularities found automatically in the filed financials by the Hydronomics anomaly flagger. Each flag has two clearly separated layers. WHAT is mechanical, certain, and sourced: the exact filed lines, years, and amounts, carried as filed and never reconciled. WHY is attempted: the filing's own narrative is checked first, and when it states no reason a single best-guess hypothesis is shown, clearly labelled as a guess that is not in the filing and is not a verified figure.
A7: Flag: FY2024 total expenses swing
A8: Affected figure | B8: Total expenses FY2024
A9: Confidence | B9: high
A10: What happened (filed, sourced) | B10: FY2024 total expenses rose to $5,675,518 from $2,103,504 in FY2023, a 170 percent move ($3,572,014 in absolute terms). Carried as filed and flagged as a documented anomaly, not smoothed.
A11: Source lines | B11: - total expenses: $2,103,504 FY2023, $5,675,518 FY2024
A12: Confidence reasoning | B12: A year-over-year move in a filed headline total that exceeds both the percentage and the dollar threshold; carried as filed.
A13: Why (not stated in the filing) | B13: The filing does not state a reason.
A14: Possible explanation (guess) | B14: Possible explanation, not stated in filing: a large one-year move in total expenses may reflect a one-time item or a change in how it was recorded. This is an educated guess, not something the filing actually says.
A16: Flag: FY2024 total revenue swing
A17: Affected figure | B17: Operating revenue FY2024
A18: Confidence | B18: high
A19: What happened (filed, sourced) | B19: FY2024 total revenue rose to $6,225,040 from $3,533,209 in FY2023, a 76 percent move ($2,691,831 in absolute terms). Carried as filed and flagged as a documented anomaly, not smoothed.
A20: Source lines | B20: - total revenue: $3,533,209 FY2023, $6,225,040 FY2024
A21: Confidence reasoning | B21: A year-over-year move in a filed headline total that exceeds both the percentage and the dollar threshold; carried as filed.
A22: Why (not stated in the filing) | B22: The filing does not state a reason.
A23: Possible explanation (guess) | B23: Possible explanation, not stated in filing: a large one-year move in total revenue may reflect a one-time item or a change in how it was recorded. This is an educated guess, not something the filing actually says.

Sheet Sources & audit
A1: Lincoln Avenue Water Company
A2: Sources & audit - full provenance and tie-outs (kept off the statements so they read clean)
A3: Entity ID: cawc_0026 | Fiscal year ends December 31.
A5: Presentation standard: every figure on the statement tabs is verified to its source filing and shown clean. A cell the filing does not report reads "not reported" (never estimated, never guessed).
A6: Citations, confidence tiers, and the filed-vs-computed tie-out checks live on the "Sources & audit" tab, keyed by cell, so every number is fully traceable without cluttering the statements. These pages are ready to use as filed.
A8: A. Filing provenance (one row per staged extraction)
A9: Fiscal year | B9: Period end | C9: Filing type | D9: Confidence | E9: Extraction ID | F9: Object ID | G9: Extracted by | H9: Extracted at | I9: Source URL
A10: FY2020 | B10: 2020-12-31 | C10: 990 | D10: high | E10: 0781502c-3cdd-4bc4-8c4c-99d9898520ae | F10: 202141799349300024 | G10: claude-opus-5 | H10: 2026-09-14T20:40:24+00:00 | I10: https://apps.irs.gov/pub/epostcard/990/xml/2021/2021_TEOS_XML_01A.zip#202141799349300024_public.xml
A11: FY2021 | B11: 2021-12-31 | C11: 990 | D11: high | E11: f92caee2-1153-4080-b118-f9375f2a8a23 | F11: 202242499349300814 | G11: claude-opus-5 | H11: 2026-09-14T20:40:24+00:00 | I11: https://apps.irs.gov/pub/epostcard/990/xml/2022/2022_TEOS_XML_01A.zip#202242499349300814_public.xml
A12: FY2022 | B12: 2022-12-31 | C12: 990 | D12: high | E12: 13c9f3c4-0b9f-4e49-9acc-9a9f53782977 | F12: 202332499349300248 | G12: claude-opus-5 | H12: 2026-09-14T20:40:24+00:00 | I12: https://apps.irs.gov/pub/epostcard/990/xml/2023/2023_TEOS_XML_09A.zip#202332499349300248_public.xml
A13: FY2023 | B13: 2023-12-31 | C13: 990 | D13: high | E13: 5cb25910-d5dd-414d-8ff3-630f5c292ea2 | F13: 202402199349301030 | G13: claude-opus-5 | H13: 2026-09-14T20:40:24+00:00 | I13: https://apps.irs.gov/pub/epostcard/990/xml/2024/2024_TEOS_XML_08A.zip#202402199349301030_public.xml
A14: FY2024 | B14: 2024-12-31 | C14: 990 | D14: high | E14: 127c6671-c869-4487-a61e-5b22c0ec75d6 | F14: 202533149349306653 | G14: claude-opus-5 | H14: 2026-09-14T20:40:24+00:00 | I14: https://apps.irs.gov/pub/epostcard/990/xml/2025/2025_TEOS_XML_11B.zip#202533149349306653_public.xml
A16: B. Figure citations (every figure on the statement tabs, keyed by cell)
A17: Tab | B17: Cell | C17: Line item | D17: Form 990 line | E17: Key path | F17: Confidence | G17: As filed
A18: Financial Statements | B18: B73 | C18: 11a. Gross income from members or shareholders | D18: 11a | E18: part_v_other_irs_filings.members_and_shareholders_gross_income | F18: high | G18: 5740379
A19: Financial Statements | B19: C73 | C19: 11a. Gross income from members or shareholders | D19: 11a | E19: part_v_other_irs_filings.members_and_shareholders_gross_income | F19: high | G19: 6729864
A20: Financial Statements | B20: D73 | C20: 11a. Gross income from members or shareholders | D20: 11a | E20: part_v_other_irs_filings.members_and_shareholders_gross_income | F20: high | G20: 6014623
A21: Financial Statements | B21: E73 | C21: 11a. Gross income from members or shareholders | D21: 11a | E21: part_v_other_irs_filings.members_and_shareholders_gross_income | F21: high | G21: 6138729
A22: Financial Statements | B22: F73 | C22: 11a. Gross income from members or shareholders | D22: 11a | E22: part_v_other_irs_filings.members_and_shareholders_gross_income | F22: high | G22: 6087629
A23: Financial Statements | B23: B74 | C23: 11b. Gross income from other sources | D23: 11b | E23: part_v_other_irs_filings.other_sources_gross_income | F23: high | G23: 12149
A24: Financial Statements | B24: C74 | C24: 11b. Gross income from other sources | D24: 11b | E24: part_v_other_irs_filings.other_sources_gross_income | F24: high | G24: 6266
A25: Financial Statements | B25: D74 | C25: 11b. Gross income from other sources | D25: 11b | E25: part_v_other_irs_filings.other_sources_gross_income | F25: high | G25: 162462
A26: Financial Statements | B26: E74 | C26: 11b. Gross income from other sources | D26: 11b | E26: part_v_other_irs_filings.other_sources_gross_income | F26: high | G26: 73752
A27: Financial Statements | B27: F74 | C27: 11b. Gross income from other sources | D27: 11b | E27: part_v_other_irs_filings.other_sources_gross_income | F27: high | G27: 248851
A28: Revenue (detail) | B28: F8 | C28: 2g. Total program service revenue | D28: 2g | E28: part_viii_revenue.total_program_service_revenue | F28: high | G28: 6087629
A29: Revenue (detail) | B29: B9 | C29: 3. Investment income | D29: 3 | E29: part_viii_revenue.investment_income | F29: high | G29: 12146
... A170: Net-assets reconciliation | B170: F10 | C170: 9. Other changes in net assets | D170: Part XI line 9 | E170: part_xi_reconciliation.other_changes_net_assets | F170: high | G170: 19600
A172: C. Tie-out checks (filed vs computed; any nonzero variance is flagged red)
A173: Tab | B173: Check | C173: Fiscal year | D173: Filed | E173: Computed | F173: Variance (computed - filed)
A174: Revenue (detail) | B174: 12. Total revenue | C174: FY2020 | D174: 2769445 | E174: ='Revenue (detail)'!B13 | F174: =E174-D174
A175: Revenue (detail) | B175: 12. Total revenue | C175: FY2021 | D175: 2974975 | E175: ='Revenue (detail)'!C13 | F175: =E175-D175
