Workbook

Sheet Summary
A1: Montebello Land and Water Company
A2: Financial Summary - multi-year overview (USD)
A3: Entity ID: cawc_0031 | Fiscal year ends June 30.
A5: Presentation standard: every figure on the statement tabs is verified to its source filing and shown clean. A cell the filing does not report reads "not reported" (never estimated, never guessed).
A6: Citations, confidence tiers, and the filed-vs-computed tie-out checks live on the "Sources & audit" tab, keyed by cell, so every number is fully traceable without cluttering the statements. These pages are ready to use as filed.
A8: Metric | B8: FY2021 | C8: FY2022 | D8: FY2023 | E8: FY2024
A9: Operating results (USD)
A10: Total revenue | B10: 6119676 | C10: 6771352 | D10: 10023447 | E10: 10411332
A11: Total expenses | B11: 4983572 | C11: 4810920 | D11: 4786324 | E11: 4760974
A12: Net income | B12: 1136104 | C12: 1960432 | D12: 5237123 | E12: 5650358
A14: Financial position (USD, end of year)
A15: Total assets | B15: 25302243 | C15: 27602664 | D15: 32912596 | E15: 37967556
A16: Total liabilities | B16: 417080 | C16: 936658 | D16: 1391208 | E16: 770353
A17: Net assets | B17: 24885163 | C17: 26666006 | D17: 31521388 | E17: 37197203
A19: Headline ratios
A20: Operating margin | B20: 0.18564774 | C20: 0.28951855 | D20: 0.52248722 | E20: 0.54271231
A21: Revenue growth (YoY) | B21: -0.0017688548 | C21: 0.10648864 | D21: 0.48027263 | E21: 0.038697765
A22: Return on assets | B22: 0.044901316 | C22: 0.07102329 | D22: 0.15912215 | E22: 0.14882069
A24: Figures as reported in source filings (full provenance on the Sources & audit tab). Parentheses denote negatives; ratios are computed upstream in financials_annual.

Sheet Notes
A1: Notes
A2: Human annotations from the versioned store (data/notes/). Annotations only: they never change a reported figure or a confidence tier.
A4: Date | B4: Tag | C4: Author | D4: Note
A5: No notes recorded yet.

Sheet Financial Statements
A1: Montebello Land and Water Company
A2: Financial Statements - income statement, balance sheet, cash flow, member income test (USD)
A3: Entity ID: cawc_0031 | Fiscal year ends June 30.
A5: INCOME STATEMENT - as reported (USD)
A6: Line item | B6: FY2021 | C6: FY2022 | D6: FY2023 | E6: FY2024
A7: Revenue
A8: Program service revenue | B8: 6001213 | C8: 6537460 | D8: 6548139 | E8: 6786362
A9: Investment income | B9: 79468 | C9: 76951 | D9: 175461 | E9: 314633
A10: Net rental income
A11: Net gain/(loss) on investment sales | B11: 1500 | C11: 10000 | E11: 11000
A12: Other revenue | B12: 37495 | C12: 107070 | D12: 369379 | E12: 1001189
A13: Contributions & grants | C13: 39871 | D13: 2930468 | E13: 2298148
A14: Total revenue | B14: 6119676 | C14: 6771352 | D14: 10023447 | E14: 10411332
A16: Expenses
A17: Depreciation | B17: 700696 | C17: 705040 | D17: 701606 | E17: 719217
A18: Interest expense
A19: Total expenses | B19: 4983572 | C19: 4810920 | D19: 4786324 | E19: 4760974
A21: Net income | B21: 1136104 | C21: 1960432 | D21: 5237123 | E21: 5650358
A24: BALANCE SHEET - as reported (USD, end of year)
A25: Line item | B25: FY2021 | C25: FY2022 | D25: FY2023 | E25: FY2024
A26: Assets
A27: Cash | B27: 57818 | C27: 517176 | D27: 543443 | E27: 217947
A28: Savings & temporary investments | B28: 4428799 | C28: 3142076 | D28: 6967537 | E28: 6250170
A29: Accounts receivable | B29: 751576 | C29: 845963 | D29: 1373920 | E29: 2474145
A30: Inventories | B30: 257880 | C30: 484939 | D30: 410183 | E30: 369901
A31: Prepaid expenses | B31: 115546 | C31: 132648 | D31: 135542 | E31: 158416
A32: Property, plant & equipment (gross) | B32: 26912273 | C32: 27184987 | D32: 27816833 | E32: 28532464
A33: Less: accumulated depreciation | B33: -13314739 | C33: -13982616 | D33: -14684223 | E33: -15368858
A34: Net property, plant & equipment | B34: 13597534 | C34: 13202371 | D34: 13132610 | E34: 13163606
A35: Total assets | B35: 25302243 | C35: 27602664 | D35: 32912596 | E35: 37967556
A37: Liabilities
A38: Accounts payable | B38: 42845 | C38: 53260 | D38: 209524 | E38: 482643
A39: Mortgages & notes payable
A40: Total liabilities | B40: 417080 | C40: 936658 | D40: 1391208 | E40: 770353
A42: Net Assets / Equity
A43: Capital stock | B43: 77813 | C43: 77813 | D43: 77813 | E43: 77813
A44: Paid-in capital | B44: 3512 | C44: 3512 | D44: 3512 | E44: 3512
A45: Retained earnings | B45: 24803838 | C45: 26584681 | D45: 31440063 | E45: 37115878
A46: Net assets | B46: 24885163 | C46: 26666006 | D46: 31521388 | E46: 37197203
A49: CASH FLOW - derived proxy (USD)
...

Sheet Balance Sheet
A1: Montebello Land and Water Company
A2: Balance Sheet - as reported (USD, end of year)
A3: Entity ID: cawc_0031 | Fiscal year ends June 30.
A5: Line item | B5: FY2021 | C5: FY2022 | D5: FY2023 | E5: FY2024
A6: Assets
A7: Cash | B7: 57818 | C7: 517176 | D7: 543443 | E7: 217947
A8: Savings & temporary investments | B8: 4428799 | C8: 3142076 | D8: 6967537 | E8: 6250170
A9: Accounts receivable | B9: 751576 | C9: 845963 | D9: 1373920 | E9: 2474145
A10: Inventories | B10: 257880 | C10: 484939 | D10: 410183 | E10: 369901
A11: Prepaid expenses | B11: 115546 | C11: 132648 | D11: 135542 | E11: 158416
A12: Property, plant & equipment (gross) | B12: 26912273 | C12: 27184987 | D12: 27816833 | E12: 28532464
A13: Less: accumulated depreciation | B13: -13314739 | C13: -13982616 | D13: -14684223 | E13: -15368858
A14: Net property, plant & equipment | B14: 13597534 | C14: 13202371 | D14: 13132610 | E14: 13163606
A15: Total assets | B15: 25302243 | C15: 27602664 | D15: 32912596 | E15: 37967556
A17: Liabilities
A18: Accounts payable | B18: 42845 | C18: 53260 | D18: 209524 | E18: 482643
A19: Mortgages & notes payable
A20: Total liabilities | B20: 417080 | C20: 936658 | D20: 1391208 | E20: 770353
A22: Net Assets / Equity
A23: Capital stock | B23: 77813 | C23: 77813 | D23: 77813 | E23: 77813
A24: Paid-in capital | B24: 3512 | C24: 3512 | D24: 3512 | E24: 3512
A25: Retained earnings | B25: 24803838 | C25: 26584681 | D25: 31440063 | E25: 37115878
A26: Net assets | B26: 24885163 | C26: 26666006 | D26: 31521388 | E26: 37197203
A28: Balance check (assets − liab. − net assets) | B28: 0 | C28: 0 | D28: 0 | E28: 0
A30: Net PP&E is the reported ppe_net column (gross less accumulated depreciation). The balance check should be ~0 where all three totals are reported; a non-zero value flags a reporting or extraction discrepancy worth reviewing.

Sheet Officers & contractors
A1: Montebello Land and Water Company
A2: Officers, Directors & Contractors - Form 990 Part VII (FY2024; USD)
A3: Entity ID: cawc_0031 | Fiscal year ends June 30.
A5: Section A - Officers, directors, trustees, key employees
A6: Name | B6: Title | C6: Reportable comp (org) | D6: Reportable comp (related) | E6: Other comp | F6: Total compensation
A7: BRUCE JUGAN | B7: PRESIDENT | C7: 7200 | D7: 0 | E7: 0 | F7: 7200
A8: DAVID R REGO | B8: VICE PRESIDENT | C8: 7200 | D8: 0 | E8: 0 | F8: 7200
A9: OMER ZEKI KAYIRAN | B9: TREASURER | C9: 7200 | D9: 0 | E9: 0 | F9: 7200
A10: DAVID R REGO | B10: SECRETARY | C10: 7200 | D10: 0 | E10: 0 | F10: 7200
A11: NORMAN AKASHI | B11: DIRECTOR | C11: 7200 | D11: 0 | E11: 0 | F11: 7200
A12: KENNETH BRADBURY | B12: DIRECTOR | C12: 7200 | D12: 0 | E12: 0 | F12: 7200
A13: KOREY BRADBURY | B13: GENERAL MANAGER | C13: 184800 | D13: 0 | E13: 27295 | F13: 212095
A14: MARIO GARDEA | B14: SUPERINDENDENT | C14: 130359 | D14: 0 | E14: 45094 | F14: 175453
A16: Section B - Independent contractors (over $100,000)
A17: Contractor | B17: Services | C17: Compensation
A18: DOTY BROTHERS EQUIPMENT CO | B18: CONSTRUCTION SERVICES | C18: 1308391
A19: AQUEOUS VETS | B19: FILTRATION EQUIPMENT | C19: 633083
A20: AKM CONSULTING ENGINEERING | B20: ENGINEERING CONSULTING SERVICES | C20: 266732
A21: ROBERT BRKICH CONSTRUCTION CORP | B21: CONSTRUCTION SERVICES | C21: 182028
A22: HIGHROAD INFORMATION TECHNOLOGY | B22: IT SERVICES | C22: 147677
A24: Section A lists every officer, director, trustee and key employee filed for the latest year; the two with the highest total compensation are highlighted. Total compensation is computed (reportable org + related + other). Section B lists each independent contractor paid over $100,000; the return reports 5 such contractor(s). Source and confidence for every figure are on the Sources & audit tab.

Sheet Revenue (detail)
A1: Montebello Land and Water Company
A2: Revenue - Form 990 Part VIII (USD)
A3: Entity ID: cawc_0031 | Fiscal year ends June 30.
A5: Part VIII line | B5: FY2021 | C5: FY2022 | D5: FY2023 | E5: FY2024
A6: Revenue by category
A7: 1h. Total contributions, gifts, grants | B7: not reported | C7: 39871 | D7: 2930468 | E7: 2298148
A8: 2g. Total program service revenue | B8: 6001213 | C8: 6537460 | D8: 6548139 | E8: 6786362
A9: 3. Investment income | B9: 79468 | C9: 76951 | D9: 175461 | E9: 314633
A10: 6d. Net rental income | B10: not reported | C10: not reported | D10: not reported | E10: not reported
A11: 7d. Net gain/(loss) from investment sales | B11: 1500 | C11: 10000 | D11: not reported | E11: 11000
A12: 11e. Other revenue | B12: 37495 | C12: 107070 | D12: 369379 | E12: 1001189
A13: 12. Total revenue | B13: =SUM(B7:B12) | C13: =SUM(C7:C12) | D13: =SUM(D7:D12) | E13: =SUM(E7:E12)
A15: Program service revenue detail - FY2024 (lines 2a-2f)
A16: Description | B16: Business code | C16: Total revenue
A17: WATER SALES | B17: 221000 | C17: 6733589
A18: DELINQUENT FEES | B18: 221000 | C18: 37540
A19: SHUT OFF FEES | B19: 221000 | C19: 12065
A20: STOCK TRANSFER FEES | B20: 221000 | C20: 3168
A21: Revenue category subtotals are as filed. Total revenue (line 12) is a live SUM of the category cells above; its tie-out to the filed total is on the Sources & audit tab. Program service revenue detail is shown for the latest year, with its sum-to-line-2g check on that same audit tab.

Sheet Operating expenses (detail)
A1: Montebello Land and Water Company
A2: Statement of Functional Expenses - Form 990 Part IX (USD)
A3: Entity ID: cawc_0031 | Fiscal year ends June 30.
A5: Part IX line (column A Total) | B5: FY2021 | C5: FY2022 | D5: FY2023 | E5: FY2024
A6: Functional expenses, column A Total - by year
A7: 5. Compensation of current officers, directors, trustees | B7: 234027 | C7: 339169 | D7: 249738 | E7: 277260
A8: 7. Other salaries and wages | B8: 790543 | C8: 774184 | D8: 693589 | E8: 717376
A9: 8. Pension plan accruals and contributions | B9: 531864 | C9: 146974 | D9: 145502 | E9: 111902
A10: 9. Other employee benefits | B10: 215494 | C10: 195430 | D10: 188176 | E10: 193166
A11: 10. Payroll taxes | B11: 86855 | C11: 83241 | D11: 77323 | E11: 87480
A12: 11b. Fees for services: legal | B12: 47975 | C12: 33287 | D12: 44035 | E12: 31995
A13: 11c. Fees for services: accounting | B13: 34625 | C13: 36875 | D13: 36822 | E13: 38150
A14: 11g. Fees for services: other | B14: 172935 | C14: 216845 | D14: 161754 | E14: 176077
A15: 13. Office expenses | B15: 103493 | C15: 100386 | D15: 110246 | E15: 116548
A16: 16. Occupancy | B16: 18316 | C16: 16171 | D16: 18850 | E16: 18575
A17: 22. Depreciation, depletion, and amortization | B17: 700696 | C17: 705040 | D17: 701606 | E17: 719217
A18: 23. Insurance | B18: 135260 | C18: 145697 | D18: 167126 | E18: 186289
... A21: 24. POWER & GAS | B21: 239515 | C21: 348420 | D21: 398719 | E21: 344318
A22: 24. FEES AND TAXES | B22: 71473 | C22: not reported | D22: not reported | E22: 92998
A23: 24. REPAIRS & MAINTENANCE | B23: not reported | C23: 77252 | D23: 109968 | E23: not reported
A24: 24e. All other expenses | B24: 59064 | C24: 73514 | D24: 96100 | E24: 79601
A25: 25. Total functional expenses | B25: =SUM(B7:B24) | C25: =SUM(C7:C24) | D25: =SUM(D7:D24) | E25: =SUM(E7:E24)
A27: Functional column split - FY2024 (col A = B + C + D)
A28: Part IX line | B28: A. Total | C28: B. Program services | D28: C. Management & general | E28: D. Fundraising
A29: 5. Compensation of current officers, directors, trustees | B29: 277260 | C29: 277260
A30: 7. Other salaries and wages | B30: 717376 | C30: 717376
A31: 8. Pension plan accruals and contributions | B31: 111902 | C31: 111902
A32: 9. Other employee benefits | B32: 193166 | C32: 193166
A33: 10. Payroll taxes | B33: 87480 | C33: 87480
A34: 11b. Fees for services: legal | B34: 31995 | C34: 31995
A35: 11c. Fees for services: accounting | B35: 38150 | C35: 38150
A36: 11g. Fees for services: other | B36: 176077 | C36: 176077
A37: 13. Office expenses | B37: 116548 | C37: 116548
A38: 16. Occupancy | B38: 18575 | C38: 18575
A39: 22. Depreciation, depletion, and amortization | B39: 719217 | C39: 719217
A40: 23. Insurance | B40: 186289 | C40: 186289
A41: 25. Total (filed col A / B / C / D) | B41: 4760974 | C41: 4760974 | D41: 0 | E41: 0
A43: Top block: each Part IX line, column A (Total), by year, as filed. Total functional expenses (line 25) is a live SUM of the line cells; its tie-out to the filed total is on the Sources & audit tab. Filer-itemized 24a-24d rows show the most recent year's as-filed wording; rows are aligned across years case-insensitively with collapsed spacing, so a line filed only in a different capitalization or spacing shares one row, while genuinely different wording stays a separate row (every as-filed variant is recorded on the Sources & audit tab). Lower block: the program / management / fundraising split for the latest year, with its col A = B + C + D check on the audit tab. Lines this filer does not report are omitted rather than shown empty.

Sheet Balance sheet (detail)
A1: Montebello Land and Water Company
A2: Balance Sheet - Form 990 Part X (end of year, USD)
A3: Entity ID: cawc_0031 | Fiscal year ends June 30.
A5: Part X line (column B, EOY) | B5: FY2021 | C5: FY2022 | D5: FY2023 | E5: FY2024
A6: Assets
A7: 1. Cash - non-interest-bearing | B7: 57818 | C7: 517176 | D7: 543443 | E7: 217947
A8: 2. Savings and temporary cash investments | B8: 4428799 | C8: 3142076 | D8: 6967537 | E8: 6250170
A9: 4. Accounts receivable, net | B9: 751576 | C9: 845963 | D9: 1373920 | E9: 2474145
A10: 8. Inventories for sale or use | B10: 257880 | C10: 484939 | D10: 410183 | E10: 369901
A11: 9. Prepaid expenses and deferred charges | B11: 115546 | C11: 132648 | D11: 135542 | E11: 158416
A12: 10c. Land, buildings, and equipment, net | B12: 13597534 | C12: 13202371 | D12: 13132610 | E12: 13163606
A13: 12. Investments - other securities | B13: 1928709 | C13: 1749065 | D13: 1793863 | E13: 1819321
A14: 15. Other assets | B14: 4164381 | C14: 7528426 | D14: 8555498 | E14: 13514050
A15: 16. Total assets | B15: =SUM(B7:B14) | C15: =SUM(C7:C14) | D15: =SUM(D7:D14) | E15: =SUM(E7:E14)
A17: Liabilities
A18: 17. Accounts payable and accrued expenses | B18: 42845 | C18: 53260 | D18: 209524 | E18: 482643
A19: 19. Deferred revenue | B19: 35111 | C19: 57501 | D19: 58326 | E19: 64413
A20: 25. Other liabilities | B20: 339124 | C20: 825897 | D20: 1123358 | E20: 223297
A21: 26. Total liabilities | B21: =SUM(B18:B20) | C21: =SUM(C18:C20) | D21: =SUM(D18:D20) | E21: =SUM(E18:E20)
A23: Net assets / fund balances
A24: 29. Capital stock or trust principal | B24: 77813 | C24: 77813 | D24: 77813 | E24: 77813
A25: 30. Paid-in or capital surplus | B25: 3512 | C25: 3512 | D25: 3512 | E25: 3512
A26: 31. Retained earnings / accumulated funds | B26: 24803838 | C26: 26584681 | D26: 31440063 | E26: 37115878
A27: 32. Total net assets / fund balances | B27: =SUM(B24:B26) | C27: =SUM(C24:C26) | D27: =SUM(D24:D26) | E27: =SUM(E24:E26)
A29: Every Part X line is end-of-year (column B), as filed. Section totals (lines 16 / 26 / 32) are live SUMs of the lines above; their tie-outs and the balance-sheet identity (16 = 26 + 32) are on the Sources & audit tab. This filer files as a non-FASB mutual, so net assets sit on lines 29-31 (capital stock / paid-in capital / retained earnings); lines this filer does not report are omitted. Lines 10a/10b net into line 10c (shown).

Sheet Net-assets reconciliation
A1: Montebello Land and Water Company
A2: Reconciliation of Net Assets - Form 990 Part XI (USD)
A3: Entity ID: cawc_0031 | Fiscal year ends June 30.
A5: Part XI line | B5: FY2021 | C5: FY2022 | D5: FY2023 | E5: FY2024
A6: Reconciliation
A7: 4. Net assets, beginning of year | B7: 22825870 | C7: 24885163 | D7: 26666006 | E7: 31521388
A8: 3. Revenue less expenses | B8: 1136104 | C8: 1960432 | D8: 5237123 | E8: 5650358
A9: 8. Prior period adjustments | B9: not reported | C9: not reported | D9: not reported | E9: not reported
A10: 9. Other changes in net assets | B10: 775988 | C10: 55 | D10: -426539 | E10: 0
A11: 10. Net assets, end of year | B11: =SUM(B7,B8,B9,B10) | C11: =SUM(C7,C8,C9,C10) | D11: =SUM(D7,D8,D9,D10) | E11: =SUM(E7,E8,E9,E10)
A13: Part XI reconciles beginning to ending net assets. Ending net assets (line 10) is a live formula: beginning balance (line 4) + revenue less expenses (line 3) + prior-period adjustments (8) + other changes (9). Its tie-out to the filed line 10 (and to Part X line 32) is on the Sources & audit tab. Lines 5-7 (unrealized gains, donated services, investment expenses) are not filed by this entity.

Sheet Cash flow proxies
A1: Montebello Land and Water Company
A2: Cash Flow Proxies - derived (USD)
A3: Entity ID: cawc_0031 | Fiscal year ends June 30.
A5: PROXY ONLY. The source filings contain no statement of cash flows. Lines below are derived from the reported income statement and year-over-year balance-sheet changes; treat as directional estimates, not GAAP cash flows. The earliest year has no prior period, so its delta cells are blank.
A7: Proxy line (USD) | B7: FY2021 | C7: FY2022 | D7: FY2023 | E7: FY2024
A8: Operating
A9: Net income | B9: 1136104 | C9: 1960432 | D9: 5237123 | E9: 5650358
A10: + Depreciation (reported) | B10: 700696 | C10: 705040 | D10: 701606 | E10: 719217
A11: − Δ Accounts receivable | C11: -94387 | D11: -527957 | E11: -1100225
A12: − Δ Inventories | C12: -227059 | D12: 74756 | E12: 40282
A13: − Δ Prepaid expenses | C13: -17102 | D13: -2894 | E13: -22874
A14: + Δ Accounts payable | C14: 10415 | D14: 156264 | E14: 273119
A15: Operating cash flow proxy | C15: 2337339 | D15: 5638898 | E15: 5559877
A17: Investing
A18: − Δ PP&E gross (capex proxy) | C18: -272714 | D18: -631846 | E18: -715631
A20: Financing
A21: Δ Mortgages & notes payable
A23: Reconciliation
A24: Δ Cash + temp. investments (actual) | C24: -827365 | D24: 3851728 | E24: -1042863
A26: The capex proxy assumes gross PP&E rises only via capital spending (it ignores disposals). 'Δ Cash + temp. investments (actual)' is the real reported change in liquid funds and is the most reliable line here; the operating/investing/financing proxies will not perfectly reconcile to it.

Sheet Ratios
A1: Montebello Land and Water Company
A2: Financial Ratios
A3: Entity ID: cawc_0031 | Fiscal year ends June 30.
A5: Ratio | B5: FY2021 | C5: FY2022 | D5: FY2023 | E5: FY2024
A6: Profitability (computed upstream)
A7: Operating margin (NI / revenue) | B7: 0.18564774 | C7: 0.28951855 | D7: 0.52248722 | E7: 0.54271231
A8: Expense ratio (expenses / revenue) | B8: 0.81435226 | C8: 0.71048145 | D8: 0.47751278 | E8: 0.45728769
A9: Return on assets (NI / assets) | B9: 0.044901316 | C9: 0.07102329 | D9: 0.15912215 | E9: 0.14882069
A10: Revenue growth (YoY) | B10: -0.0017688548 | C10: 0.10648864 | D10: 0.48027263 | E10: 0.038697765
A12: Leverage & solvency
A13: Debt-to-assets (liab. / assets) | B13: 0.016483914 | C13: 0.033933609 | D13: 0.042269774 | E13: 0.020289771
A14: Equity ratio (net assets / assets) | B14: 0.98351609 | C14: 0.96606639 | D14: 0.95773023 | E14: 0.97971023
A16: Liquidity & asset profile (derived here)
A17: Current ratio (current assets / AP) | B17: 130.97489 | C17: 96.184792 | D17: 45.00976 | E17: 19.622327
A18: Cash ratio ((cash+temp inv.) / total liab.) | B18: 10.75721 | C18: 3.9067109 | D18: 5.3988907 | E18: 8.3963027
A19: Asset age proxy (accum. deprec. / gross PP&E) | B19: 0.49474598 | C19: 0.51435066 | D19: 0.52788982 | E19: 0.53864461
A21: Upstream ratios are read from financials_annual; derived ratios are computed only where inputs are reported. Current ratio uses accounts payable as the current-liability proxy (the filings do not split current vs. long-term liabilities). Asset age proxy: a higher % implies older / more depreciated infrastructure.

Sheet Unit economics
A1: Montebello Land and Water Company
A2: Unit economics - per-customer revenue by category (USD)
A3: Entity ID: cawc_0031 | Fiscal year ends June 30.
A5: Every metric here is PER CUSTOMER (a metered service connection). It is not a per-member figure; the member (shareholder) count is a different denominator, shown in the denominator block. The visible cell shows the value and its classification; the numerator, denominator, formula, and rationale are in each metric's LOGIC popup.
A6: Per-customer denominator (service connections) | B6: 3956 | C6: State Water Board eAR Section 4 (CurTotalConnections), reporting year 2024
A7: Total annual revenue (eAR Section 8b B1.8) | B7: 6715191 | C7: State Water Board eAR Section 8b, question B1.8 (total annual revenue), reporting year 2024
A8: Primary source | C8: State Water Board eAR Section 8b (revenue by rate/fee), reporting year 2024
A10: Revenue categories (value, classification, per customer, share)
A11: Revenue category | B11: Classification | C11: Value (USD) | D11: Per customer | E11: Share of revenue
A12: Water sales revenue | B12: DIRECT | C12: 6662418 | D12: 1684.13 | E12: 0.9921
A13: Assessment revenue (990 program-service revenue not matched to eAR water-rate revenue) | B13: DERIVED | C13: 123944 | D13: 31.33 | E13: 0.0183
A14: Meter revenue | B14: not reported | C14: not reported | D14: not reported | E14: not reported
A15: Overage or tiered penalty revenue | B15: not reported | C15: not reported | D15: not reported | E15: not reported
A17: Water sales revenue - DIRECT
A18: Revenue customers paid for water service, read straight off the filed eAR Section 8b water-rate line. A DIRECT filed figure, not computed by us.
A19: Numerator: Water rate revenue | B19: 6662418 | C19: eAR Section 8b field B1.1 (residential water rates) + B1.2 (non-residential water rates). State Water Board eAR Section 8b, question B1.1 + B1.2 (revenue from water rates), reporting year 2024
A20: Denominator: Total service connections | B20: 3956 | C20: eAR Section 4 CurTotalConnections, reporting year 2024. State Water Board eAR Section 4 (CurTotalConnections), reporting year 2024
A21: Per customer: water rate revenue $6,662,418 / 3,956 connections = $1,684.13 per connection
A22: Share of revenue: water rate revenue $6,662,418 / total annual revenue (eAR Section 8b B1.8) $6,715,191 = 99.21%
A23: Period treatment: Numerator (eAR Section 8b, the fiscal year ending June 30, 2024) and denominator (eAR Section 4 connections reported in the same eAR filing) are both the eAR reporting year 2024, so the two sides are bound to the same reporting year.
A24: Rationale: Dividing water-rate revenue by the number of metered service connections gives the average revenue per customer; dividing by total annual revenue shows how much of the system's income comes from water rates.
A26: Assessment revenue (990 program-service revenue not matched to eAR water-rate revenue) - DERIVED
A27: A DERIVED residual (medium confidence): the part of the Form 990 program-service revenue that is not matched by the eAR water-rate revenue for the same period. Computed by us, not a filed line.
A28: Input A: Form 990 program-service revenue | B28: 6786362 | C28: Form 990 Part VIII line 2 (total program-service revenue), fiscal year 2024 ending June 30, 2024
A29: Input B: eAR water-rate revenue | B29: 6662418 | C29: State Water Board eAR Section 8b, question B1.1 + B1.2 (revenue from water rates), reporting year 2024
A30: Residual (A minus B) = assessment revenue | B30: =B28-B29 | C30: $6,786,362 (990 program-service revenue) minus $6,662,418 (eAR water-rate revenue) = $123,944
A31: Period alignment: Both inputs cover the same period: the eAR Section 8b is the fiscal year ending June 30, 2024 and the Form 990 fiscal year 2024 ends June 30, 2024, so the residual is period-aligned.
A32: What it IS: revenue the system booked as program service on its 990 that is not accounted for by the eAR water-rate line, plausibly member assessments and other service revenue.
A33: This residual is a difference between two sources for the same period; it is not a separately filed assessment line and may include other unmatched revenue.
A34: Denominator: Total service connections | B34: 3956 | C34: eAR Section 4 CurTotalConnections, reporting year 2024. State Water Board eAR Section 4 (CurTotalConnections), reporting year 2024
A35: Per customer: residual $123,944 / 3,956 connections = $31.33 per connection
A36: Share of revenue: residual $123,944 / 990 program-service revenue $6,786,362 = 1.83%
A38: Meter revenue - not reported
A39: Not reported. This category is not built because doing so would double-count.
A40: Reason: The eAR Section 8a reports a base/meter rate PRICE, but the filing carries no meter revenue line and no tier volume, and the base charge is already inside the water-sales revenue (eAR Section 8b water rates). Building a separate meter figure would double-count. Not backed into from a total.
A42: Overage or tiered penalty revenue - not reported
A43: Not reported. This category is not built because doing so would double-count.
A44: Reason: The eAR Section 8a reports tiered/overage rate PRICES, but the filing carries no overage revenue and no tier consumption volume, and any overage billed is already inside the water-sales revenue. Building it would double-count. Not backed into from a total.

Sheet Rate structure
A1: Montebello Land and Water Company
A2: Rate structure and representative bill - eAR Section 8a (RY2024)
A3: Entity ID: cawc_0031 | Fiscal year ends June 30.
A5: This block is a rate-schedule illustration at defined usage levels. It is NOT billed revenue and not a claim about any real customer's usage. The revenue side of unit economics is the separate Unit Economics block.
A6: Structure: Tiered increasing-block with a fixed base, billed bimonthly, priced per HCF. Rate schedule last updated 09/01/2024.
A7: Defined single-family usage levels, identical for every company so the bill is comparable: Low = 5 HCF/month (~125 gallons/day); Median = 10 HCF/month (~249 gallons/day); High = 25 HCF/month (~623 gallons/day). 1 HCF = 748 gallons, and 1 thousand gallons = 1,000 gallons. The usage is converted into the company's own filed unit before the filed tiers are applied, and the bill is stated as a monthly equivalent: a bimonthly structure is computed at twice the monthly usage and divided by two, and any other billing period the same way with its factor stated. These are an illustration, not a measured usage for any real customer.
A9: Defined usage levels (EDITABLE - change a yellow cell to move the bill)
B10: Low | C10: Median | D10: High
A11: Monthly usage (HCF) | B11: 5 | C11: 10 | D11: 25
A12: Months per bill (from filed billing frequency) | B12: 2 | C12: bimonthly biller
A14: Filed rate table - single-family residential (as filed, eAR Section 8a)
A15: Base / fixed charge per bimonthly bill ($) | B15: 40.08
A16: Tier | B16: Range (HCF) | C16: Price ($/HCF) | D16: Upper limit (HCF)
A17: Tier 1 | B17: 0 to 18 HCF | C17: 3.31 | D17: 18
A18: Tier 2 | B18: 18 to 35 HCF | C18: 3.69 | D18: 35
A19: Tier 3 | B19: over 35 HCF | C19: 4.93 | D19: no limit
A21: Representative monthly bill - LIVE (edit a yellow usage cell to recompute)
B22: Low | C22: Median | D22: High
A23: Usage per bill (HCF) | B23: =B11*$B$12 | C23: =C11*$B$12 | D23: =D11*$B$12
A24: Tier 1 charge per bill ($) | B24: =$C$17*MAX(0,MIN(B23,$D$17)-0) | C24: =$C$17*MAX(0,MIN(C23,$D$17)-0) | D24: =$C$17*MAX(0,MIN(D23,$D$17)-0)
A25: Tier 2 charge per bill ($) | B25: =$C$18*MAX(0,MIN(B23,$D$18)-$D$17) | C25: =$C$18*MAX(0,MIN(C23,$D$18)-$D$17) | D25: =$C$18*MAX(0,MIN(D23,$D$18)-$D$17)
A26: Tier 3 charge per bill ($) | B26: =$C$19*MAX(0,B23-$D$18) | C26: =$C$19*MAX(0,C23-$D$18) | D26: =$C$19*MAX(0,D23-$D$18)
A27: Volumetric charge per bill ($) | B27: =SUM(B24,B25,B26) | C27: =SUM(C24,C25,C26) | D27: =SUM(D24,D25,D26)
A28: Base charge per bill ($) | B28: =$B$15 | C28: =$B$15 | D28: =$B$15
A29: Total per bill ($) | B29: =B28+B27 | C29: =C28+C27 | D29: =D28+D27
A30: Total per MONTH ($) | B30: =B29/$B$12 | C30: =C29/$B$12 | D30: =D29/$B$12
A31: Fixed per month ($) | B31: =$B$15/$B$12 | C31: =$B$15/$B$12 | D31: =$B$15/$B$12
A32: Volumetric per month ($) | B32: =B27/$B$12 | C32: =C27/$B$12 | D32: =D27/$B$12
A33: Effective price ($/HCF) | B33: =IF(B11=0,"",B30/B11) | C33: =IF(C11=0,"",C30/C11) | D33: =IF(D11=0,"",D30/D11)
A35: Rate-structure comparison metrics
A36: Fixed share of the bill at median usage | B36: =C31/C30 | C36: fixed / total at 10 HCF/month
A37: Tier price ratio (highest to lowest positive tier) | B37: =$C$19/$C$17 | C37: highest filed tier price divided by lowest filed tier price.
A38: Rate structure (as filed) | B38: tiered (Variable Base)
A40: State Water Board eAR Section 8a (Customer Charges), single- and multi-family residential charges grid, reporting year 2024. Rate structure only; no revenue.

Sheet eAR revenue & expenses
A1: Montebello Land and Water Company
A2: eAR annual revenue and expenses - State Water Board eAR Section 8b (USD)
A3: Entity ID: cawc_0031 | Fiscal year ends June 30.
A5: The water system's own annual figures from the public eAR Section 8b, on the fiscal year ending June 30, 2024 the filer self-reported (B0.1/B0.2). Shown beside the period-aligned Form 990 with the variance flagged: a different source (a State Water Board self-report vs an IRS filing). Preserved as filed, never reconciled.
A6: Reporting period basis (self-reported) | B6: fiscal year ending June 30, 2024 | C6: eAR Section 8b B0.1 (WRFinancialReportingPeriod) / B0.2 start 07/01/2023
A8: Revenue (eAR Section 8b, questions B1.x)
A9: Line | B9: Amount (USD) | C9: Citation
A10: Water rate revenue | B10: 6662418 | C10: State Water Board eAR Section 8b, question B1.1 + B1.2 (revenue from water rates), reporting year 2024
A11: Other fees and charges | B11: 52773 | C11: State Water Board eAR Section 8b, question B1.3 + B1.4 (revenue from other fees), reporting year 2024
A12: Non-customer revenue | B12: 0 | C12: State Water Board eAR Section 8b, question B1.7 (grants, interest, and other non-customer), reporting year 2024
A13: Total annual revenue | B13: 6715191 | C13: State Water Board eAR Section 8b, question B1.8 (total annual revenue for the reporting year), reporting year 2024
A15: Expenses (eAR Section 8b, questions B2.x)
A16: Line | B16: Amount (USD) | C16: Citation
A17: Operations and maintenance | B17: 4760974 | C17: State Water Board eAR Section 8b, question B2.1 (annual O and M expense), reporting year 2024
A18: Capital | B18: 999527 | C18: State Water Board eAR Section 8b, question B2.2 (annual expenses from investing or capital), reporting year 2024
A19: Financing | B19: 0 | C19: State Water Board eAR Section 8b, question B2.3 (annual expenses from financing), reporting year 2024
A20: Other | B20: 380068 | C20: State Water Board eAR Section 8b, question B2.4 (total other annual expenses), reporting year 2024
A21: Total annual expenses | B21: 6140569 | C21: State Water Board eAR Section 8b, question B2.5 (total annual expenses), reporting year 2024
A23: Period-aligned Form 990 comparison (variance surfaced, never reconciled)
A24: Measure | B24: eAR Section 8b | C24: Form 990
A25: total revenue | B25: 6715191 | C25: 10411332
A26: Variance (eAR minus Form 990) | B26: =B25-C25
A27: The eAR Section 8b total revenue (State Water Board self-report, fiscal year ending June 30, 2024) and the Form 990 total revenue (IRS filing) are a different source and cover the same fiscal year (July 1, 2023 to June 30, 2024): the water system self-reported the eAR Section 8b on a fiscal year (B0.1 Fiscal, B0.2 start 07/01/2023), which matches the Form 990 fiscal year. Both are carried as filed; the variance is surfaced, never reconciled.
A28: total expenses | B28: 6140569 | C28: 4760974
A29: Variance (eAR minus Form 990) | B29: =B28-C28
A30: The eAR Section 8b total expenses (State Water Board self-report, fiscal year ending June 30, 2024) and the Form 990 total expenses (IRS filing) are a different source and cover the same fiscal year (July 1, 2023 to June 30, 2024): the water system self-reported the eAR Section 8b on a fiscal year (B0.1 Fiscal, B0.2 start 07/01/2023), which matches the Form 990 fiscal year. Both are carried as filed; the variance is surfaced, never reconciled.

Sheet Denominators & alignment
A1: Montebello Land and Water Company
A2: Denominators and calendar alignment
A3: Entity ID: cawc_0031 | Fiscal year ends June 30.
A5: System size and water use per fiscal year (the operating denominators that per-customer and per-acre metrics divide by), each cited to file and field. The eAR is reported on the calendar year; the 990 fiscal year differs by company. A calendar-year filer's volume is the eAR annual total (fiscal year = calendar year); an offset filer's is recast by a true monthly sum of the covered calendar months, or read not reported naming the missing months. Point-in-time counts (connections, population) are matched to the closest eAR year and never summed. Every derived figure states its formula and accounting rationale.
A6: Member vs customer (two different denominators, both preserved)
A7: Customer (service connection) | B7: 3957 | C7: State Water Board eAR Section 4 (CurTotalConnections), reporting year 2023
A8: Member (shareholder) | C8: No published shareholder count
A9: In a mutual water company a MEMBER is a shareholder who owns part of the system; a CUSTOMER is a metered service connection that receives water. The two diverge because one owner can hold several connections, a connection can serve people who are not owners, and some mutuals attach shares to land by acreage rather than counting heads. Per-customer metrics divide by service connections; per-member metrics divide by shareholders; the two counts are never used interchangeably.
A11: Denominator layer by fiscal year
A12: Fiscal year (end) | B12: Connections | C12: Population | D12: Service-area acres | E12: Water produced (AF) | F12: Water delivered (AF) | G12: Alignment method
A13: FY2020 (2020-06-30) | B13: 3932 | C13: not reported | D13: 1190.8 | E13: not reported | F13: not reported | G13: recast from monthly eAR data to fiscal year ending June 30, 2020
A14: FY2021 (2021-06-30) | B14: 3932 | C14: not reported | D14: 1190.8 | E14: not reported | F14: not reported | G14: recast from monthly eAR data to fiscal year ending June 30, 2021
A15: FY2022 (2022-06-30) | B15: 3937 | C15: not reported | D15: 1190.8 | E15: not reported | F15: not reported | G15: recast from monthly eAR data to fiscal year ending June 30, 2022
A16: FY2023 (2023-06-30) | B16: 3957 | C16: not reported | D16: 1190.8 | E16: not reported | F16: not reported | G16: recast from monthly eAR data to fiscal year ending June 30, 2023
A17: FY2024 (2024-06-30) | B17: 3957 | C17: 26554 | D17: 1190.8 | E17: not reported | F17: not reported | G17: recast from monthly eAR data to fiscal year ending June 30, 2024
A19: Connections by class - FY2024 (eAR Section 4)
A20: Single-family residential | B20: 2436
A21: Multi-family residential | B21: 1016
A22: Commercial and institutional | B22: 485
A23: Industrial | B23: 16
A24: Landscape irrigation | B24: 3
A25: Agricultural | B25: 0
A26: Monthly-volume source: California open-data portal (data.ca.gov): the separate Produced Water (by month and source) and Delivered Water (by month and connection type) resources, which cover every public water system (not only urban suppliers), one resource per reporting year, matched by exact PWSID. This is the aggregate publication of eAR Section 6.

Sheet Governance evidence
A1: Montebello Land and Water Company
A2: Governance evidence status - Ostrom's eight design principles
A3: Entity ID: cawc_0031 | Fiscal year ends June 30.
A5: Evidence summary: 3 documented, 2 partial, 3 not documented of eight principles.
A6: A count of how many of Elinor Ostrom's eight design principles have a supporting record on file, not a grade. NOT DOCUMENTED means the supporting record was not found, not that the company governs badly. It marks a gap in the documentary record, an evidence gap to close, never a governance failing.
A7: Each mutual is read against Elinor Ostrom's eight design principles for institutions that govern a shared resource durably. Per principle: a one-line finding, the observable signal, a citation, and an evidence status stating whether the supporting record exists: DOCUMENTED (a cited record supports alignment), PARTIAL (some evidence exists but it is incomplete), or NOT DOCUMENTED (no supporting record was found). This is an evidence-status read, not a grade: the principles are never ranked, weighted, or given a letter, consistent with reporting as filed and not grading companies. NOT DOCUMENTED means the supporting record was not found, not that the company governs badly. It marks a gap in the documentary record, an evidence gap to close, never a governance failing.
A9: Principle | B9: Evidence status | C9: Finding | D9: Signal | E9: Citation
A10: Clearly defined boundaries | B10: DOCUMENTED | C10: The system is a defined public water system: 3,957 service connections over a State-published and field-verified service-area boundary of roughly 1,188.2 acres. | D10: SDWIS Community water system; SABL service-area boundary (Verified); connections defined. | E10: [C][G]
A11: What the record shows: SDWIS defines the membership as a fixed set of service connections and the State Water Board publishes a SABL service-area polygon for it, so who is inside and outside the system is documented. The boundary is FIELD-VERIFIED by the Water Board rather than merely carried.
A12: Rules fit local conditions | B12: NOT DOCUMENTED | C12: No filed rate schedule or metering statement was located for this company. | D12: No eAR Section 8a rate record held. | E12: not reported
A13: What the record shows: This company files no eAR, so the filing that would document metering and rate structure does not exist for it. NOT DOCUMENTED means the supporting record was not found, not that the company governs badly. It marks a gap in the documentary record, an evidence gap to close, never a governance failing.
A14: Collective-choice arrangements | B14: PARTIAL | C14: The company is owned by its customer-shareholders, but the specific board, the election procedure and any record of member votes are not in a source this project holds. | D14: Mutual ownership; Form 990 governance section. | E14: [990]
A15: What the record shows: A collective-choice mechanism is documented in outline: the customers are the shareholders. It stays PARTIAL rather than met because the filed corporate record that would carry the director roster and the election procedure is NOT YET CHECKED for this company, the California Secretary of State being reachable only through a browser session that now answers a CAPTCHA. A stated board is not a filed roster.
A16: Monitoring | B16: DOCUMENTED | C16: The system is monitored and reports on itself: it files an annual eAR, and a Consumer Confidence Report for 2024 was located at the State's own CCR portal, and it holds an emergency response plan dated 8/18/2022. | D16: Annual eAR reporting; located Consumer Confidence Report | E16: [E][CCR]
A17: What the record shows: Operational monitoring is documented from more than one filing. What the federal violation check found is reported separately in the On the record block and is not folded into this tier.
A18: Graduated sanctions | B18: NOT DOCUMENTED | C18: No published shut-off, penalty, or delinquency policy was found for this system. | D18: No sourced graduated sanctions record. | E18: not reported
A19: What the record shows: No public record of a shut-off, penalty, or delinquency policy was located. NOT DOCUMENTED means the supporting record was not found, not that the company governs badly. It marks a gap in the documentary record, an evidence gap to close, never a governance failing.
A20: Conflict-resolution mechanisms | B20: NOT DOCUMENTED | C20: No published bylaws, dispute procedure, or grievance mechanism was found for this system. | D20: No sourced conflict-resolution mechanisms record. | E20: not reported
A21: What the record shows: No public record of a bylaws, dispute procedure, or grievance mechanism was located. NOT DOCUMENTED means the supporting record was not found, not that the company governs badly. It marks a gap in the documentary record, an evidence gap to close, never a governance failing.
A22: Recognized right to organize | B22: DOCUMENTED | C22: An incorporated California mutual water company recognized by the IRS as a 501(c)(12) exempt filer and by the State Water Board as a Community public water system. | D22: IRS 501(c)(12) exempt filer (Form 990); SDWIS Community public water system; eAR ownership type 'Privately owned Mutual Water Company or Association'. | E22: [990][C][E]
A23: What the record shows: Baseline legal standing is documented by two independent regulators: the IRS accepts it as a tax-exempt 501(c)(12) filer and the State Water Board holds it as a Community public water system with a mutual ownership type. This status does NOT rest on a filed corporate record, because the Secretary of State check has not been run for this company.
A24: Nested enterprises | B24: PARTIAL | C24: The system sits inside larger water systems: it pumps from 1 groundwater basin(s) shared with neighbors, and it holds 9 approved emergency intertie(s) with other systems. Its role in governing any of them is not documented. | D24: it pumps from 1 groundwater basin(s) shared with neighbors; it holds 9 approved emergency intertie(s) with other systems | E24: [SG][E]
A25: What the record shows: Physical nesting is documented. What is not documented is any governance role in a wholesaler or in a groundwater sustainability agency, so the tier is PARTIAL rather than met.

Sheet Operational metrics
A1: Montebello Land and Water Company
A2: Operational metrics - plant per acre, density, terrain
A3: Entity ID: cawc_0031 | Fiscal year ends June 30.
A5: Plant assets per acre
A6: Service-area acres | B6: 1190.8 | C6: Geodesic area (WGS84 spherical excess) of the SABL service-area polygon.
A7: Fiscal year | B7: Gross plant per acre (primary) | C7: Net plant per acre
A8: FY2020
A9: FY2021 | B9: 22600.162 | C9: 11418.823
A10: FY2022 | B10: 22829.179 | C10: 11086.976
A11: FY2023 | B11: 23359.786 | C11: 11028.393
A12: FY2024 | B12: 23960.752 | C12: 11054.422
A13: Infrastructure built per acre of service area. Gross plant per acre is the primary read because it measures how much plant the system has put in the ground per acre, and unlike net plant it does not fall over time purely because the assets depreciate on the books. Net plant per acre is shown alongside as the depreciated book value per acre.
A14: Formula: gross plant per acre = Form 990 Part X line 10a (land, buildings, and equipment, gross) / SABL service-area acres; net plant per acre uses Part X line 10c (net)
A15: Source lines: Form 990 Part X line 10a (gross) and line 10c (net); Geodesic area (WGS84 spherical excess) of the SABL service-area polygon.
A16: Confidence: medium. This is worked out from filed figures (a ratio, or a year-to-year change), so it is one step removed from the raw numbers.. Filed gross/net plant over the measured SABL service-area acreage.
A18: Connections per acre
A19: Connections per acre | B19: 3.32 | C19: 3,959 connections / 1,190.8 acres. CA State Water Board SABL SERVICE_CONNECTIONS; Geodesic area (WGS84 spherical excess) of the SABL service-area polygon.

Sheet Supply & weather
A1: Montebello Land and Water Company
A2: Supply and weather indicators (DWR water year)
A3: Entity ID: cawc_0031 | Fiscal year ends June 30.
A5: Reporting calendar: Different reporting periods. The DWR water year runs October 1 to September 30; this system's fiscal year ends June 30, so the two period ends are three months apart. Read the two side by side with that in mind. Neither series is recast: both are reported as filed. A water year is named for the calendar year it ends in, so WY2024 and FY2024 share a number without covering the same twelve months.
A7: Indicator | B7: WY2020 | C7: WY2021 | D7: WY2022 | E7: WY2023 | F7: WY2024
A8: Water-year type (Sacramento Valley) | B8: Dry | C8: Critical | D8: Critical | E8: Wet | F8: Above Normal
A9: Peak drought, Los Angeles County | B9: D1 | C9: D4 | D9: D4 | E9: D4 | F9: None (no D0-D4 during the fiscal year)
A10: Precip, percent of normal (8-Station Index) | B10: 63 | C10: 48 | D10: 86 | E10: 133 | F10: 96
A11: Snowpack, April 1 percent of average | B11: 53% | C11: 59% | D11: 38% | E11: 237% | F11: 110%
A12: State Water Project allocation | B12: 20% | C12: 5% | D12: 5% | E12: 100% | F12: 40%

Sheet How this was built
A1: Montebello Land and Water Company
A2: How this was built - forensic lineage
A3: Entity ID: cawc_0031 | Fiscal year ends June 30.
A5: A plain account of the forensic lineage behind the hard-to-source metrics: what sources were checked, what was found, what was derived, and what could not be built and why. Every figure marked DERIVED or IMPOSSIBLE above is traceable to a line here.
A7: Water-sales revenue per customer - DIRECT
A8: Sources checked | B8: State Water Board eAR Section 8b (water-rate revenue B1.1/B1.2); State Water Board eAR Section 4 (connection count, same reporting year); audited financial statement (secondary cross-check, where published)
A9: What was found | B9: The eAR Section 8b reports water-rate revenue for reporting year 2024, so this is a DIRECT filed figure; per customer it is divided by the eAR Section 4 connection count for the same reporting year, so numerator and denominator share the year.
A11: Assessment revenue (residual) - DERIVED
A12: Sources checked | B12: Form 990 Part VIII line 2 (program-service revenue); State Water Board eAR Section 8b (water-rate revenue B1.1/B1.2)
A13: What was found | B13: No source separately reports a member assessment, so it is DERIVED as a residual: $6,786,362 (990 program-service revenue) minus $6,662,418 (eAR water-rate revenue) = $123,944. Period-aligned; medium confidence.
A14: Caveat | B14: This residual is a difference between two sources for the same period; it is not a separately filed assessment line and may include other unmatched revenue.
A16: Meter revenue - not reported
A17: Sources checked | B17: State Water Board eAR Section 8a (rate prices); State Water Board eAR Section 8b (revenue lines); audited financial statement
A18: What was found | B18: The rate price exists in Section 8a but no revenue or tier volume is reported, and the base charge is already inside water sales.
A19: Caveat | B19: The eAR Section 8a reports a base/meter rate PRICE, but the filing carries no meter revenue line and no tier volume, and the base charge is already inside the water-sales revenue (eAR Section 8b water rates). Building a separate meter figure would double-count. Not backed into from a total.
A21: Overage / tiered-penalty revenue - not reported
A22: Sources checked | B22: State Water Board eAR Section 8a (rate prices); State Water Board eAR Section 8b (revenue lines); audited financial statement
A23: What was found | B23: The rate price exists in Section 8a but no revenue or tier volume is reported, and the base charge is already inside water sales.
A24: Caveat | B24: The eAR Section 8a reports tiered/overage rate PRICES, but the filing carries no overage revenue and no tier consumption volume, and any overage billed is already inside the water-sales revenue. Building it would double-count. Not backed into from a total.
A26: eAR Section 8b reporting-period basis - sourced
A27: Sources checked | B27: eAR Section 8b B0.1 (WRFinancialReportingPeriod); eAR Section 8b B0.2 (WRFiscalYearStartDate)
A28: What was found | B28: The reporting basis (fiscal vs calendar year) is read from the filer's own B0.1/B0.2 answer and staged verbatim, never hardcoded, so the 990 comparison and the residual are period-aligned.
A30: Member (shareholder) count denominator - not reported
A31: Sources checked | B31: Form 990 (no member count stated); company website
A32: What was found | B32: No filing states a member/shareholder count, so the per-member unit economics read not reported rather than borrowing the connection count.
A34: Water volume delivered (acre-feet) - not reported
A35: Sources checked | B35: Form 990 (not in the filing); Consumer Confidence Report; eAR Section 6 (PRA-gated)
A36: What was found | B36: Volume delivered in acre-feet is not in the Form 990 and the CCR states only a source mix, so the per-acre-foot metrics read not reported; the eAR Section 6 is named as the source still needed.

Sheet Sources & audit
A1: Montebello Land and Water Company
A2: Sources & audit - full provenance and tie-outs (kept off the statements so they read clean)
A3: Entity ID: cawc_0031 | Fiscal year ends June 30.
A5: Presentation standard: every figure on the statement tabs is verified to its source filing and shown clean. A cell the filing does not report reads "not reported" (never estimated, never guessed).
A6: Citations, confidence tiers, and the filed-vs-computed tie-out checks live on the "Sources & audit" tab, keyed by cell, so every number is fully traceable without cluttering the statements. These pages are ready to use as filed.
A8: A. Filing provenance (one row per staged extraction)
A9: Fiscal year | B9: Period end | C9: Filing type | D9: Confidence | E9: Extraction ID | F9: Object ID | G9: Extracted by | H9: Extracted at | I9: Source URL
A10: FY2021 | B10: 2021-06-30 | C10: 990 | D10: high | E10: 79364b52-4a38-4134-98ac-9ead29fb8bc3 | F10: 202142719349300909 | G10: claude-opus-5 | H10: 2026-09-14T20:40:24+00:00 | I10: https://apps.irs.gov/pub/epostcard/990/xml/2021/2021_TEOS_XML_01A.zip#202142719349300909_public.xml
A11: FY2022 | B11: 2022-06-30 | C11: 990 | D11: high | E11: 9f127c14-4a0b-4f27-b924-846c3a7aa0dd | F11: 202203129349305215 | G11: claude-opus-5 | H11: 2026-09-14T20:40:24+00:00 | I11: https://apps.irs.gov/pub/epostcard/990/xml/2022/2022_TEOS_XML_02A.zip#202203129349305215_public.xml
A12: FY2023 | B12: 2023-06-30 | C12: 990 | D12: high | E12: c8fae41c-af74-49f0-8a72-dbb4fd84ff36 | F12: 202332869349301668 | G12: claude-opus-5 | H12: 2026-09-14T20:40:24+00:00 | I12: https://apps.irs.gov/pub/epostcard/990/xml/2023/2023_TEOS_XML_10A.zip#202332869349301668_public.xml
A13: FY2024 | B13: 2024-06-30 | C13: 990 | D13: high | E13: 43b75b41-9d5d-4973-8ad0-25d1b9c923a2 | F13: 202422969349301462 | G13: claude-opus-5 | H13: 2026-09-14T20:40:24+00:00 | I13: https://apps.irs.gov/pub/epostcard/990/xml/2024/2024_TEOS_XML_10A.zip#202422969349301462_public.xml
A15: B. Figure citations (every figure on the statement tabs, keyed by cell)
A16: Tab | B16: Cell | C16: Line item | D16: Form 990 line | E16: Key path | F16: Confidence | G16: As filed
A17: Financial Statements | B17: B73 | C17: 11a. Gross income from members or shareholders | D17: 11a | E17: part_v_other_irs_filings.members_and_shareholders_gross_income | F17: high | G17: 6001213
A18: Financial Statements | B18: C73 | C18: 11a. Gross income from members or shareholders | D18: 11a | E18: part_v_other_irs_filings.members_and_shareholders_gross_income | F18: high | G18: 6537460
A19: Financial Statements | B19: D73 | C19: 11a. Gross income from members or shareholders | D19: 11a | E19: part_v_other_irs_filings.members_and_shareholders_gross_income | F19: high | G19: 6548139
A20: Financial Statements | B20: E73 | C20: 11a. Gross income from members or shareholders | D20: 11a | E20: part_v_other_irs_filings.members_and_shareholders_gross_income | F20: high | G20: 6786362
A21: Financial Statements | B21: B74 | C21: 11b. Gross income from other sources | D21: 11b | E21: part_v_other_irs_filings.other_sources_gross_income | F21: high | G21: 118463
A22: Financial Statements | B22: C74 | C22: 11b. Gross income from other sources | D22: 11b | E22: part_v_other_irs_filings.other_sources_gross_income | F22: high | G22: 233892
A23: Financial Statements | B23: D74 | C23: 11b. Gross income from other sources | D23: 11b | E23: part_v_other_irs_filings.other_sources_gross_income | F23: high | G23: 3472684
A24: Financial Statements | B24: E74 | C24: 11b. Gross income from other sources | D24: 11b | E24: part_v_other_irs_filings.other_sources_gross_income | F24: high | G24: 3623308
A25: Revenue (detail) | B25: C7 | C25: 1h. Total contributions, gifts, grants | D25: 1h | E25: part_viii_revenue.total_contributions | F25: high | G25: 39871
A26: Revenue (detail) | B26: D7 | C26: 1h. Total contributions, gifts, grants | D26: 1h | E26: part_viii_revenue.total_contributions | F26: high | G26: 2930468
A27: Revenue (detail) | B27: E7 | C27: 1h. Total contributions, gifts, grants | D27: 1h | E27: part_viii_revenue.total_contributions | F27: high | G27: 2298148
A28: Revenue (detail) | B28: B8 | C28: 2g. Total program service revenue | D28: 2g | E28: part_viii_revenue.total_program_service_revenue | F28: high | G28: 6001213
... A162: Net-assets reconciliation | B162: E10 | C162: 9. Other changes in net assets | D162: Part XI line 9 | E162: part_xi_reconciliation.other_changes_net_assets | F162: high | G162: 0
A164: C. Tie-out checks (filed vs computed; any nonzero variance is flagged red)
A165: Tab | B165: Check | C165: Fiscal year | D165: Filed | E165: Computed | F165: Variance (computed - filed)
A166: Revenue (detail) | B166: 12. Total revenue | C166: FY2021 | D166: 6119676 | E166: ='Revenue (detail)'!B13 | F166: =E166-D166
A167: Revenue (detail) | B167: 12. Total revenue | C167: FY2022 | D167: 6771352 | E167: ='Revenue (detail)'!C13 | F167: =E167-D167
A168: Revenue (detail) | B168: 12. Total revenue | C168: FY2023 | D168: 10023447 | E168: ='Revenue (detail)'!D13 | F168: =E168-D168
A169: Revenue (detail) | B169: 12. Total revenue | C169: FY2024 | D169: 10411332 | E169: ='Revenue (detail)'!E13 | F169: =E169-D169
A170: Revenue (detail) | B170: 2g program service revenue = sum of lines 2a-2f (FY2024) | C170: FY2024 | D170: 6786362 | E170: =SUM('Revenue (detail)'!C17:C20) | F170: =E170-D170
A171: Operating expenses (detail) | B171: 25. Total functional expenses | C171: FY2021 | D171: 4983572 | E171: ='Operating expenses (detail)'!B25 | F171: =E171-D171
A172: Operating expenses (detail) | B172: 25. Total functional expenses | C172: FY2022 | D172: 4810920 | E172: ='Operating expenses (detail)'!C25 | F172: =E172-D172
A173: Operating expenses (detail) | B173: 25. Total functional expenses | C173: FY2023 | D173: 4786324 | E173: ='Operating expenses (detail)'!D25 | F173: =E173-D173
A174: Operating expenses (detail) | B174: 25. Total functional expenses | C174: FY2024 | D174: 4760974 | E174: ='Operating expenses (detail)'!E25 | F174: =E174-D174
A175: Operating expenses (detail) | B175: Part IX column split: col A = B + C + D (FY2024) | C175: FY2024 | D175: ='Operating expenses (detail)'!B41 | E175: ='Operating expenses (detail)'!C41+'Operating expenses (detail)'!D41+'Operating expenses (detail)'!E41 | F175: =E175-D175
A176: Balance sheet (detail) | B176: 16. Total assets | C176: FY2021 | D176: 25302243 | E176: ='Balance sheet (detail)'!B15 | F176: =E176-D176
A177: Balance sheet (detail) | B177: 16. Total assets | C177: FY2022 | D177: 27602664 | E177: ='Balance sheet (detail)'!C15 | F177: =E177-D177
...

Sheet Provenance
A1: Build provenance | B1: Built from source commit d418ffb17485 (2026-10-06); source fingerprint a75a8eee82c65cf7; 192 companies (179 retail mutual, 4 irrigation mutual, 3 mutual, no PWSID, purpose not stated, 2 frozen non-mutual (special district), 2 wholesale mutual, 1 frozen non-mutual (investor-owned), 1 frozen non-mutual (municipal)); 91 gates; build id 3d08d6d2a855.
A2: source_commit | B2: d418ffb174855ab78000d391d42f898397b0d8aa
A3: source_commit_date | B3: 2026-10-06
A4: source_fingerprint | B4: a75a8eee82c65cf7096931f06e18affdc28686a02895b46538e7298b57c04d94
A5: gate_count | B5: 91
A6: build_id | B6: 3d08d6d2a855
A7: registry: frozen non-mutual (investor-owned) | B7: 1
A8: registry: frozen non-mutual (municipal) | B8: 1
A9: registry: frozen non-mutual (special district) | B9: 2
A10: registry: irrigation mutual | B10: 4
A11: registry: mutual, no PWSID, purpose not stated | B11: 3
A12: registry: retail mutual | B12: 179
A13: registry: wholesale mutual | B13: 2
