Workbook

Sheet Summary
A1: Sisar Mutual Water Company
A2: Financial Summary - multi-year overview (USD)
A3: Entity ID: cawc_0014 | Fiscal year ends December 31.
A5: Presentation standard: every figure on the statement tabs is verified to its source filing and shown clean. A cell the filing does not report reads "not reported" (never estimated, never guessed).
A6: Citations, confidence tiers, and the filed-vs-computed tie-out checks live on the "Sources & audit" tab, keyed by cell, so every number is fully traceable without cluttering the statements. These pages are ready to use as filed.
A8: Metric | B8: FY2020 | C8: FY2021 | D8: FY2022 | E8: FY2023 | F8: FY2024 | G8: FY2025
A9: Operating results (USD)
A10: Total revenue | B10: 134980 | C10: 130965 | D10: 131599 | E10: 158846 | F10: 188669 | G10: 131040
A11: Total expenses | B11: 152712 | C11: 114458 | D11: 145865 | E11: 175427 | F11: 190320 | G11: 179283
A12: Net income | B12: -17732 | C12: 16507 | D12: -14266 | E12: -16581 | F12: -1651 | G12: -48243
A14: Financial position (USD, end of year)
A15: Total assets | B15: 638157 | C15: 654664 | D15: 640403 | E15: 902621 | F15: 901259 | G15: 889642
A16: Total liabilities | B16: 0 | C16: 0 | D16: 5 | E16: 0 | F16: 0 | G16: 0
A17: Net assets | B17: 638157 | C17: 654664 | D17: 640398 | E17: 902621 | F17: 901259 | G17: 889642
A19: Headline ratios
A20: Operating margin | B20: -0.13136761 | C20: 0.12604131 | D20: -0.10840508 | E20: -0.10438412 | F20: -0.0087507752 | G20: -0.36815476
A21: Revenue growth (YoY) | C21: -0.029745147 | D21: 0.0048409881 | E21: 0.20704565 | F21: 0.18774788 | G21: -0.30545029
A22: Return on assets | B22: -0.027786266 | C22: 0.025214461 | D22: -0.022276598 | E22: -0.018369836 | F22: -0.0018318818 | G22: -0.054227431
A24: Figures as reported in source filings (full provenance on the Sources & audit tab). Parentheses denote negatives; ratios are computed upstream in financials_annual.

Sheet Notes
A1: Notes
A2: Human annotations from the versioned store (data/notes/). Annotations only: they never change a reported figure or a confidence tier.
A4: Date | B4: Tag | C4: Author | D4: Note
A5: No notes recorded yet.

Sheet Financial Statements
A1: Sisar Mutual Water Company
A2: Financial Statements - income statement, balance sheet, cash flow, member income test (USD)
A3: Entity ID: cawc_0014 | Fiscal year ends December 31.
A5: INCOME STATEMENT - as reported (USD)
A6: Line item | B6: FY2020 | C6: FY2021 | D6: FY2022 | E6: FY2023 | F6: FY2024 | G6: FY2025
A7: Revenue
A8: Program service revenue | B8: 134980 | C8: 130965 | D8: 131599 | E8: 158846 | F8: 188669 | G8: 131040
A9: Investment income | B9: 0 | C9: 0 | D9: 0 | E9: 0 | F9: 0 | G9: 0
A10: Net rental income | B10: 0 | C10: 0 | D10: 0 | E10: 0 | F10: 0 | G10: 0
A11: Net gain/(loss) on investment sales | B11: 0 | C11: 0 | D11: 0 | E11: 0 | F11: 0 | G11: 0
A12: Other revenue | B12: 0 | C12: 0 | D12: 0 | E12: 0 | F12: 0 | G12: 0
A13: Contributions & grants | B13: 0 | C13: 0 | D13: 0 | E13: 0 | F13: 0 | G13: 0
A14: Total revenue | B14: 134980 | C14: 130965 | D14: 131599 | E14: 158846 | F14: 188669 | G14: 131040
A16: Expenses
A17: Depreciation | B17: 29144 | C17: 30551 | D17: 32986 | E17: 55829 | F17: 68791 | G17: 48606
A18: Interest expense | B18: 0 | C18: 0 | D18: 0 | E18: 0 | F18: 0 | G18: 0
A19: Total expenses | B19: 152712 | C19: 114458 | D19: 145865 | E19: 175427 | F19: 190320 | G19: 179283
A21: Net income | B21: -17732 | C21: 16507 | D21: -14266 | E21: -16581 | F21: -1651 | G21: -48243
A24: BALANCE SHEET - as reported (USD, end of year)
A25: Line item | B25: FY2020 | C25: FY2021 | D25: FY2022 | E25: FY2023 | F25: FY2024 | G25: FY2025
A26: Assets
A27: Cash | B27: 198892 | C27: 173388 | D27: 179936 | E27: 58046 | F27: 34738 | G27: 27724
A28: Savings & temporary investments | B28: 0 | C28: 0 | D28: 0 | E28: 0 | F28: 0 | G28: 0
A29: Accounts receivable | B29: 0 | C29: 0 | D29: 0 | E29: 0 | F29: 0 | G29: 7377
A30: Inventories | B30: 0 | C30: 0 | D30: 0 | E30: 0 | F30: 0 | G30: 0
A31: Prepaid expenses | B31: 0 | C31: 0 | D31: 0 | E31: 0 | F31: 0 | G31: 0
A32: Property, plant & equipment (gross) | B32: 1388603 | C32: 1461165 | D32: 1473342 | E32: 1888944 | F32: 1979681 | G32: 2016307
A33: Less: accumulated depreciation | B33: -949338 | C33: -979889 | D33: -1012875 | E33: -1044369 | F33: -1113160 | G33: -1161766
A34: Net property, plant & equipment | B34: 439265 | C34: 481276 | D34: 460467 | E34: 844575 | F34: 866521 | G34: 854541
A35: Total assets | B35: 638157 | C35: 654664 | D35: 640403 | E35: 902621 | F35: 901259 | G35: 889642
A37: Liabilities
A38: Accounts payable
A39: Mortgages & notes payable
A40: Total liabilities | B40: 0 | C40: 0 | D40: 5 | E40: 0 | F40: 0 | G40: 0
A42: Net Assets / Equity
A43: Capital stock
A44: Paid-in capital
A45: Retained earnings | B45: 638157 | C45: 654664 | D45: 640398 | E45: 902621 | F45: 901259 | G45: 889642
A46: Net assets | B46: 638157 | C46: 654664 | D46: 640398 | E46: 902621 | F46: 901259 | G46: 889642
A49: CASH FLOW - derived proxy (USD)
...

Sheet Balance Sheet
A1: Sisar Mutual Water Company
A2: Balance Sheet - as reported (USD, end of year)
A3: Entity ID: cawc_0014 | Fiscal year ends December 31.
A5: Line item | B5: FY2020 | C5: FY2021 | D5: FY2022 | E5: FY2023 | F5: FY2024 | G5: FY2025
A6: Assets
A7: Cash | B7: 198892 | C7: 173388 | D7: 179936 | E7: 58046 | F7: 34738 | G7: 27724
A8: Savings & temporary investments | B8: 0 | C8: 0 | D8: 0 | E8: 0 | F8: 0 | G8: 0
A9: Accounts receivable | B9: 0 | C9: 0 | D9: 0 | E9: 0 | F9: 0 | G9: 7377
A10: Inventories | B10: 0 | C10: 0 | D10: 0 | E10: 0 | F10: 0 | G10: 0
A11: Prepaid expenses | B11: 0 | C11: 0 | D11: 0 | E11: 0 | F11: 0 | G11: 0
A12: Property, plant & equipment (gross) | B12: 1388603 | C12: 1461165 | D12: 1473342 | E12: 1888944 | F12: 1979681 | G12: 2016307
A13: Less: accumulated depreciation | B13: -949338 | C13: -979889 | D13: -1012875 | E13: -1044369 | F13: -1113160 | G13: -1161766
A14: Net property, plant & equipment | B14: 439265 | C14: 481276 | D14: 460467 | E14: 844575 | F14: 866521 | G14: 854541
A15: Total assets | B15: 638157 | C15: 654664 | D15: 640403 | E15: 902621 | F15: 901259 | G15: 889642
A17: Liabilities
A18: Accounts payable
A19: Mortgages & notes payable
A20: Total liabilities | B20: 0 | C20: 0 | D20: 5 | E20: 0 | F20: 0 | G20: 0
A22: Net Assets / Equity
A23: Capital stock
A24: Paid-in capital
A25: Retained earnings | B25: 638157 | C25: 654664 | D25: 640398 | E25: 902621 | F25: 901259 | G25: 889642
A26: Net assets | B26: 638157 | C26: 654664 | D26: 640398 | E26: 902621 | F26: 901259 | G26: 889642
A28: Balance check (assets − liab. − net assets) | B28: 0 | C28: 0 | D28: 0 | E28: 0 | F28: 0 | G28: 0
A30: Net PP&E is the reported ppe_net column (gross less accumulated depreciation). The balance check should be ~0 where all three totals are reported; a non-zero value flags a reporting or extraction discrepancy worth reviewing.

Sheet Officers & contractors
A1: Sisar Mutual Water Company
A2: Officers, Directors & Contractors - Form 990 Part VII (FY2025; USD)
A3: Entity ID: cawc_0014 | Fiscal year ends December 31.
A5: Section A - Officers, directors, trustees, key employees
A6: Name | B6: Title | C6: Reportable comp (org) | D6: Reportable comp (related) | E6: Other comp | F6: Total compensation
A7: JOHN LEMMER | B7: President | C7: 0 | D7: 0 | E7: 0 | F7: 0
A9: Section B - Independent contractors (over $100,000)
A10: Contractor | B10: Services | C10: Compensation
A12: Section A lists every officer, director, trustee and key employee filed for the latest year; the two with the highest total compensation are highlighted. Total compensation is computed (reportable org + related + other). Section B lists each independent contractor paid over $100,000; the return reports 0 such contractor(s). Source and confidence for every figure are on the Sources & audit tab.

Sheet Revenue (detail)
A1: Sisar Mutual Water Company
A2: Revenue - Form 990 Part VIII (USD)
A3: Entity ID: cawc_0014 | Fiscal year ends December 31.
A5: Part VIII line | B5: FY2020 | C5: FY2021 | D5: FY2022 | E5: FY2023 | F5: FY2024 | G5: FY2025
A6: Revenue by category
A7: 1h. Total contributions, gifts, grants | B7: 0 | C7: 0 | D7: 0 | E7: 0 | F7: 0 | G7: 0
A8: 2g. Total program service revenue | B8: 134980 | C8: 130965 | D8: 131599 | E8: 158846 | F8: 188669 | G8: 131040
A9: 3. Investment income | B9: 0 | C9: 0 | D9: 0 | E9: 0 | F9: 0 | G9: 0
A10: 6d. Net rental income | B10: 0 | C10: 0 | D10: 0 | E10: 0 | F10: 0 | G10: 0
A11: 7d. Net gain/(loss) from investment sales | B11: 0 | C11: 0 | D11: 0 | E11: 0 | F11: 0 | G11: 0
A12: 11e. Other revenue | B12: 0 | C12: 0 | D12: 0 | E12: 0 | F12: 0 | G12: 0
A13: 12. Total revenue | B13: =SUM(B7:B12) | C13: =SUM(C7:C12) | D13: =SUM(D7:D12) | E13: =SUM(E7:E12) | F13: =SUM(F7:F12) | G13: =SUM(G7:G12)
A15: Revenue category subtotals are as filed. Total revenue (line 12) is a live SUM of the category cells above; its tie-out to the filed total is on the Sources & audit tab. Program service revenue detail is shown for the latest year, with its sum-to-line-2g check on that same audit tab.

Sheet Operating expenses (detail)
A1: Sisar Mutual Water Company
A2: Statement of Functional Expenses - Form 990 Part IX (USD)
A3: Entity ID: cawc_0014 | Fiscal year ends December 31.
A5: Part IX line (column A Total) | B5: FY2020 | C5: FY2021 | D5: FY2022 | E5: FY2023 | F5: FY2024 | G5: FY2025
A6: Functional expenses, column A Total - by year
A7: 1. Grants to domestic organizations and governments | B7: 0 | C7: 0 | D7: 0 | E7: 0 | F7: 0 | G7: 0
A8: 2. Grants to domestic individuals | B8: 0 | C8: 0 | D8: 0 | E8: 0 | F8: 0 | G8: 0
A9: 3. Grants to foreign organizations and individuals | B9: 0 | C9: 0 | D9: 0 | E9: 0 | F9: 0 | G9: 0
A10: 4. Benefits paid to or for members | B10: 0 | C10: 0 | D10: 0 | E10: 0 | F10: 0 | G10: 0
A11: 5. Compensation of current officers, directors, trustees | B11: 0 | C11: 0 | D11: 0 | E11: 0 | F11: 0 | G11: 0
A12: 6. Compensation to disqualified persons | B12: 0 | C12: 0 | D12: 0 | E12: 0 | F12: 0 | G12: 0
A13: 7. Other salaries and wages | B13: 0 | C13: 0 | D13: 0 | E13: 0 | F13: 0 | G13: 0
A14: 8. Pension plan accruals and contributions | B14: 0 | C14: 0 | D14: 0 | E14: 0 | F14: 0 | G14: 0
A15: 9. Other employee benefits | B15: 0 | C15: 0 | D15: 0 | E15: 0 | F15: 0 | G15: 0
A16: 10. Payroll taxes | B16: 0 | C16: 0 | D16: 0 | E16: 0 | F16: 0 | G16: 0
A17: 11a. Fees for services: management | B17: 0 | C17: 0 | D17: 0 | E17: 0 | F17: 0 | G17: 0
A18: 11b. Fees for services: legal | B18: 0 | C18: 0 | D18: 0 | E18: 0 | F18: 0 | G18: 2133
... A36: 24. UTILITIES | B36: 37526 | C36: 17753 | D36: 17825 | E36: 12618 | F36: 20440 | G36: 22527
A37: 24. CONTRACT WORK | B37: 24605 | C37: 12307 | D37: not reported | E37: 15712 | F37: 17864 | G37: 18160
A38: 24. PROFESSIONAL FEES | B38: 22638 | C38: 13105 | D38: 19168 | E38: 30621 | F38: 34384 | G38: 27228
A39: 24. MATERIALS | B39: 18516 | C39: 13224 | D39: not reported | E39: not reported | F39: not reported | G39: not reported
A40: 24. ADJUSTMENTS | B40: not reported | C40: not reported | D40: 22270 | E40: not reported | F40: not reported | G40: not reported
A41: 24. LEGAL & ACCOUNTING | B41: not reported | C41: not reported | D41: 14718 | E41: not reported | F41: not reported | G41: not reported
A42: 24. REPAIRS & MAINTENANCE | B42: not reported | C42: not reported | D42: not reported | E42: 25777 | F42: 15188 | G42: not reported
A43: 24. MISCELLANEOUS | B43: not reported | C43: not reported | D43: not reported | E43: not reported | F43: not reported | G43: 19720
A44: 24e. All other expenses | B44: 15762 | C44: 18045 | D44: 33040 | E44: 28298 | F44: 25660 | G44: 32552
A45: 25. Total functional expenses | B45: =SUM(B7:B44) | C45: =SUM(C7:C44) | D45: =SUM(D7:D44) | E45: =SUM(E7:E44) | F45: =SUM(F7:F44) | G45: =SUM(G7:G44)
A47: Functional column split - FY2025 (col A = B + C + D)
A48: Part IX line | B48: A. Total | C48: B. Program services | D48: C. Management & general | E48: D. Fundraising
A49: 1. Grants to domestic organizations and governments | B49: 0
A50: 2. Grants to domestic individuals | B50: 0
A51: 3. Grants to foreign organizations and individuals | B51: 0
A52: 4. Benefits paid to or for members | B52: 0
A53: 5. Compensation of current officers, directors, trustees | B53: 0
A54: 6. Compensation to disqualified persons | B54: 0
A55: 7. Other salaries and wages | B55: 0
A56: 8. Pension plan accruals and contributions | B56: 0
A57: 9. Other employee benefits | B57: 0
A58: 10. Payroll taxes | B58: 0
A59: 11a. Fees for services: management | B59: 0
...

Sheet Balance sheet (detail)
A1: Sisar Mutual Water Company
A2: Balance Sheet - Form 990 Part X (end of year, USD)
A3: Entity ID: cawc_0014 | Fiscal year ends December 31.
A5: Part X line (column B, EOY) | B5: FY2020 | C5: FY2021 | D5: FY2022 | E5: FY2023 | F5: FY2024 | G5: FY2025
A6: Assets
A7: 1. Cash - non-interest-bearing | B7: 198892 | C7: 173388 | D7: 179936 | E7: 58046 | F7: 34738 | G7: 27724
A8: 2. Savings and temporary cash investments | B8: 0 | C8: 0 | D8: 0 | E8: 0 | F8: 0 | G8: 0
A9: 3. Pledges and grants receivable, net | B9: 0 | C9: 0 | D9: 0 | E9: 0 | F9: 0 | G9: 0
A10: 4. Accounts receivable, net | B10: 0 | C10: 0 | D10: 0 | E10: 0 | F10: 0 | G10: 7377
A11: 5. Receivables from officers/directors/trustees | B11: 0 | C11: 0 | D11: 0 | E11: 0 | F11: 0 | G11: 0
A12: 6. Receivables from disqualified persons | B12: 0 | C12: 0 | D12: 0 | E12: 0 | F12: 0 | G12: 0
A13: 7. Notes and loans receivable, net | B13: 0 | C13: 0 | D13: 0 | E13: 0 | F13: 0 | G13: 0
A14: 8. Inventories for sale or use | B14: 0 | C14: 0 | D14: 0 | E14: 0 | F14: 0 | G14: 0
A15: 9. Prepaid expenses and deferred charges | B15: 0 | C15: 0 | D15: 0 | E15: 0 | F15: 0 | G15: 0
A16: 10c. Land, buildings, and equipment, net | B16: 439265 | C16: 481276 | D16: 460467 | E16: 844575 | F16: 866521 | G16: 854541
A17: 11. Investments - publicly traded securities | B17: 0 | C17: 0 | D17: 0 | E17: 0 | F17: 0 | G17: 0
A18: 12. Investments - other securities | B18: 0 | C18: 0 | D18: 0 | E18: 0 | F18: 0 | G18: 0
... A21: 15. Other assets | B21: 0 | C21: 0 | D21: 0 | E21: 0 | F21: 0 | G21: 0
A22: 16. Total assets | B22: =SUM(B7:B21) | C22: =SUM(C7:C21) | D22: =SUM(D7:D21) | E22: =SUM(E7:E21) | F22: =SUM(F7:F21) | G22: =SUM(G7:G21)
A24: Liabilities
A25: 25. Other liabilities | B25: not reported | C25: not reported | D25: 5 | E25: not reported | F25: not reported | G25: not reported
A26: 26. Total liabilities | B26: =SUM(B25:B25) | C26: =SUM(C25:C25) | D26: =SUM(D25:D25) | E26: =SUM(E25:E25) | F26: =SUM(F25:F25) | G26: =SUM(G25:G25)
A28: Net assets / fund balances
A29: 31. Retained earnings / accumulated funds | B29: 638157 | C29: 654664 | D29: 640398 | E29: 902621 | F29: 901259 | G29: 889642
A30: 32. Total net assets / fund balances | B30: =SUM(B29:B29) | C30: =SUM(C29:C29) | D30: =SUM(D29:D29) | E30: =SUM(E29:E29) | F30: =SUM(F29:F29) | G30: =SUM(G29:G29)
A32: Every Part X line is end-of-year (column B), as filed. Section totals (lines 16 / 26 / 32) are live SUMs of the lines above; their tie-outs and the balance-sheet identity (16 = 26 + 32) are on the Sources & audit tab. This filer files as a non-FASB mutual, so net assets sit on lines 29-31 (capital stock / paid-in capital / retained earnings); lines this filer does not report are omitted. Lines 10a/10b net into line 10c (shown).

Sheet Net-assets reconciliation
A1: Sisar Mutual Water Company
A2: Reconciliation of Net Assets - Form 990 Part XI (USD)
A3: Entity ID: cawc_0014 | Fiscal year ends December 31.
A5: Part XI line | B5: FY2020 | C5: FY2021 | D5: FY2022 | E5: FY2023 | F5: FY2024 | G5: FY2025
A6: Reconciliation
A7: 4. Net assets, beginning of year | B7: 357341 | C7: 638157 | D7: 654664 | E7: 640398 | F7: 902621 | G7: 901259
A8: 3. Revenue less expenses | B8: -17732 | C8: 16507 | D8: -14266 | E8: -16581 | F8: -1651 | G8: -48243
A9: 8. Prior period adjustments | B9: not reported | C9: not reported | D9: not reported | E9: not reported | F9: not reported | G9: not reported
A10: 9. Other changes in net assets | B10: not reported | C10: not reported | D10: not reported | E10: 278804 | F10: 289 | G10: not reported
A11: 10. Net assets, end of year | B11: =SUM(B7,B8,B9,B10) | C11: =SUM(C7,C8,C9,C10) | D11: =SUM(D7,D8,D9,D10) | E11: =SUM(E7,E8,E9,E10) | F11: =SUM(F7,F8,F9,F10) | G11: =SUM(G7,G8,G9,G10)
A13: Part XI reconciles beginning to ending net assets. Ending net assets (line 10) is a live formula: beginning balance (line 4) + revenue less expenses (line 3) + prior-period adjustments (8) + other changes (9). Its tie-out to the filed line 10 (and to Part X line 32) is on the Sources & audit tab. Lines 5-7 (unrealized gains, donated services, investment expenses) are not filed by this entity.

Sheet Cash flow proxies
A1: Sisar Mutual Water Company
A2: Cash Flow Proxies - derived (USD)
A3: Entity ID: cawc_0014 | Fiscal year ends December 31.
A5: PROXY ONLY. The source filings contain no statement of cash flows. Lines below are derived from the reported income statement and year-over-year balance-sheet changes; treat as directional estimates, not GAAP cash flows. The earliest year has no prior period, so its delta cells are blank.
A7: Proxy line (USD) | B7: FY2020 | C7: FY2021 | D7: FY2022 | E7: FY2023 | F7: FY2024 | G7: FY2025
A8: Operating
A9: Net income | B9: -17732 | C9: 16507 | D9: -14266 | E9: -16581 | F9: -1651 | G9: -48243
A10: + Depreciation (reported) | B10: 29144 | C10: 30551 | D10: 32986 | E10: 55829 | F10: 68791 | G10: 48606
A11: − Δ Accounts receivable | C11: 0 | D11: 0 | E11: 0 | F11: 0 | G11: -7377
A12: − Δ Inventories | C12: 0 | D12: 0 | E12: 0 | F12: 0 | G12: 0
A13: − Δ Prepaid expenses | C13: 0 | D13: 0 | E13: 0 | F13: 0 | G13: 0
A14: + Δ Accounts payable
A15: Operating cash flow proxy | C15: 47058 | D15: 18720 | E15: 39248 | F15: 67140 | G15: -7014
A17: Investing
A18: − Δ PP&E gross (capex proxy) | C18: -72562 | D18: -12177 | E18: -415602 | F18: -90737 | G18: -36626
A20: Financing
A21: Δ Mortgages & notes payable
A23: Reconciliation
A24: Δ Cash + temp. investments (actual) | C24: -25504 | D24: 6548 | E24: -121890 | F24: -23308 | G24: -7014
A26: The capex proxy assumes gross PP&E rises only via capital spending (it ignores disposals). 'Δ Cash + temp. investments (actual)' is the real reported change in liquid funds and is the most reliable line here; the operating/investing/financing proxies will not perfectly reconcile to it.

Sheet Ratios
A1: Sisar Mutual Water Company
A2: Financial Ratios
A3: Entity ID: cawc_0014 | Fiscal year ends December 31.
A5: Ratio | B5: FY2020 | C5: FY2021 | D5: FY2022 | E5: FY2023 | F5: FY2024 | G5: FY2025
A6: Profitability (computed upstream)
A7: Operating margin (NI / revenue) | B7: -0.13136761 | C7: 0.12604131 | D7: -0.10840508 | E7: -0.10438412 | F7: -0.0087507752 | G7: -0.36815476
A8: Expense ratio (expenses / revenue) | B8: 1.1313676 | C8: 0.87395869 | D8: 1.1084051 | E8: 1.1043841 | F8: 1.0087508 | G8: 1.3681548
A9: Return on assets (NI / assets) | B9: -0.027786266 | C9: 0.025214461 | D9: -0.022276598 | E9: -0.018369836 | F9: -0.0018318818 | G9: -0.054227431
A10: Revenue growth (YoY) | C10: -0.029745147 | D10: 0.0048409881 | E10: 0.20704565 | F10: 0.18774788 | G10: -0.30545029
A12: Leverage & solvency
A13: Debt-to-assets (liab. / assets) | B13: 0 | C13: 0 | D13: 7.8075837e-06 | E13: 0 | F13: 0 | G13: 0
A14: Equity ratio (net assets / assets) | B14: 1 | C14: 1 | D14: 0.99999219 | E14: 1 | F14: 1 | G14: 1
A16: Liquidity & asset profile (derived here)
A17: Current ratio (current assets / AP)
A18: Cash ratio ((cash+temp inv.) / total liab.) | D18: 35987.2
A19: Asset age proxy (accum. deprec. / gross PP&E) | B19: 0.68366409 | C19: 0.67062173 | D19: 0.68746768 | E19: 0.5528851 | F19: 0.56229261 | G19: 0.57618507
A21: Upstream ratios are read from financials_annual; derived ratios are computed only where inputs are reported. Current ratio uses accounts payable as the current-liability proxy (the filings do not split current vs. long-term liabilities). Asset age proxy: a higher % implies older / more depreciated infrastructure.

Sheet Unit economics
A1: Sisar Mutual Water Company
A2: Unit economics - per-customer revenue by category (USD)
A3: Entity ID: cawc_0014 | Fiscal year ends December 31.
A5: Every metric here is PER CUSTOMER (a metered service connection). It is not a per-member figure; the member (shareholder) count is a different denominator, shown in the denominator block. The visible cell shows the value and its classification; the numerator, denominator, formula, and rationale are in each metric's LOGIC popup.
A6: Per-customer denominator (service connections) | B6: 106 | C6: State Water Board eAR Section 4 (CurTotalConnections), reporting year 2023
A7: Total annual revenue (eAR Section 8b B1.8) | B7: 158165 | C7: State Water Board eAR Section 8b, question B1.8 (total annual revenue), reporting year 2023
A8: Primary source | C8: State Water Board eAR Section 8b (revenue by rate/fee), reporting year 2023
A10: Revenue categories (value, classification, per customer, share)
A11: Revenue category | B11: Classification | C11: Value (USD) | D11: Per customer | E11: Share of revenue
A12: Water sales revenue | B12: DIRECT | C12: 157665 | D12: 1487.41 | E12: 0.9968
A13: Assessment revenue (990 program-service revenue not matched to eAR water-rate revenue) | B13: DERIVED | C13: 1181 | D13: 11.14 | E13: 0.0074
A14: Meter revenue | B14: not reported | C14: not reported | D14: not reported | E14: not reported
A15: Overage or tiered penalty revenue | B15: not reported | C15: not reported | D15: not reported | E15: not reported
A17: Water sales revenue - DIRECT
A18: Revenue customers paid for water service, read straight off the filed eAR Section 8b water-rate line. A DIRECT filed figure, not computed by us.
A19: Numerator: Water rate revenue | B19: 157665 | C19: eAR Section 8b field B1.1 (residential water rates) + B1.2 (non-residential water rates). State Water Board eAR Section 8b, question B1.1 + B1.2 (revenue from water rates), reporting year 2023
A20: Denominator: Total service connections | B20: 106 | C20: eAR Section 4 CurTotalConnections, reporting year 2023. State Water Board eAR Section 4 (CurTotalConnections), reporting year 2023
A21: Per customer: water rate revenue $157,665 / 106 connections = $1,487.41 per connection
A22: Share of revenue: water rate revenue $157,665 / total annual revenue (eAR Section 8b B1.8) $158,165 = 99.68%
A23: Period treatment: Numerator (eAR Section 8b, the calendar year 2023) and denominator (eAR Section 4 connections reported in the same eAR filing) are both the eAR reporting year 2023, so the two sides are bound to the same reporting year.
A24: Rationale: Dividing water-rate revenue by the number of metered service connections gives the average revenue per customer; dividing by total annual revenue shows how much of the system's income comes from water rates.
A26: Assessment revenue (990 program-service revenue not matched to eAR water-rate revenue) - DERIVED
A27: A DERIVED residual (medium confidence): the part of the Form 990 program-service revenue that is not matched by the eAR water-rate revenue for the same period. Computed by us, not a filed line.
A28: Input A: Form 990 program-service revenue | B28: 158846 | C28: Form 990 Part VIII line 2 (total program-service revenue), fiscal year 2023 ending December 31, 2023
A29: Input B: eAR water-rate revenue | B29: 157665 | C29: State Water Board eAR Section 8b, question B1.1 + B1.2 (revenue from water rates), reporting year 2023
A30: Residual (A minus B) = assessment revenue | B30: =B28-B29 | C30: $158,846 (990 program-service revenue) minus $157,665 (eAR water-rate revenue) = $1,181
A31: Period alignment: Both inputs cover the same period: the eAR Section 8b is the calendar year 2023 and the Form 990 fiscal year 2023 ends December 31, 2023, so the residual is period-aligned.
A32: What it IS: revenue the system booked as program service on its 990 that is not accounted for by the eAR water-rate line, plausibly member assessments and other service revenue.
A33: This residual is a difference between two sources for the same period; it is not a separately filed assessment line and may include other unmatched revenue.
A34: Denominator: Total service connections | B34: 106 | C34: eAR Section 4 CurTotalConnections, reporting year 2023. State Water Board eAR Section 4 (CurTotalConnections), reporting year 2023
A35: Per customer: residual $1,181 / 106 connections = $11.14 per connection
A36: Share of revenue: residual $1,181 / 990 program-service revenue $158,846 = 0.74%
A38: Meter revenue - not reported
A39: Not reported. This category is not built because doing so would double-count.
A40: Reason: The eAR Section 8a reports a base/meter rate PRICE, but the filing carries no meter revenue line and no tier volume, and the base charge is already inside the water-sales revenue (eAR Section 8b water rates). Building a separate meter figure would double-count. Not backed into from a total.
A42: Overage or tiered penalty revenue - not reported
A43: Not reported. This category is not built because doing so would double-count.
A44: Reason: The eAR Section 8a reports tiered/overage rate PRICES, but the filing carries no overage revenue and no tier consumption volume, and any overage billed is already inside the water-sales revenue. Building it would double-count. Not backed into from a total.

Sheet Rate structure
A1: Sisar Mutual Water Company
A2: Rate structure and representative bill - eAR Section 8a (RY2024)
A3: Entity ID: cawc_0014 | Fiscal year ends December 31.
A5: This block is a rate-schedule illustration at defined usage levels. It is NOT billed revenue and not a claim about any real customer's usage. The revenue side of unit economics is the separate Unit Economics block.
A6: Structure: Tiered increasing-block with a fixed base, billed monthly, priced per HCF.
A7: Defined single-family usage levels, identical for every company so the bill is comparable: Low = 5 HCF/month (~125 gallons/day); Median = 10 HCF/month (~249 gallons/day); High = 25 HCF/month (~623 gallons/day). 1 HCF = 748 gallons, and 1 thousand gallons = 1,000 gallons. The usage is converted into the company's own filed unit before the filed tiers are applied, and the bill is stated as a monthly equivalent: a bimonthly structure is computed at twice the monthly usage and divided by two, and any other billing period the same way with its factor stated. These are an illustration, not a measured usage for any real customer.
A9: Defined usage levels (EDITABLE - change a yellow cell to move the bill)
B10: Low | C10: Median | D10: High
A11: Monthly usage (HCF) | B11: 5 | C11: 10 | D11: 25
A12: Months per bill (from filed billing frequency) | B12: 1 | C12: monthly biller
A14: Filed rate table - single-family residential (as filed, eAR Section 8a)
A15: Base / fixed charge per monthly bill ($) | B15: 50
A16: Tier | B16: Range (HCF) | C16: Price ($/HCF) | D16: Upper limit (HCF)
A17: Tier 1 | B17: 0 to 15 HCF | C17: 0 | D17: 15
A18: Tier 2 | B18: 15 to 30 HCF | C18: 0.04 | D18: 30
A19: Tier 3 | B19: 30 to 50 HCF | C19: 0.06 | D19: 50
A20: Tier 4 | B20: 50 to 100 HCF | C20: 0.1 | D20: 100
A21: Tier 5 | B21: 100 to 150 HCF | C21: 0.25 | D21: 150
A22: Tier 6 | B22: over 150 HCF | C22: 0.5 | D22: no limit
A24: Flags on the filed rate table (nothing below is corrected)
A25: Tier 2 price: implausible as filed; checked against source. The filed tier 2 price of $0.04 per unit implies $0.04 per HCF, outside the $0.50 to $50.00 per HCF range a residential water rate plausibly takes. Carried exactly as filed and not corrected. Source: State Water Board eAR Section 8 / WRSFUsageCost2
A26: Tier 3 price: implausible as filed; checked against source. The filed tier 3 price of $0.06 per unit implies $0.06 per HCF, outside the $0.50 to $50.00 per HCF range a residential water rate plausibly takes. Carried exactly as filed and not corrected. Source: State Water Board eAR Section 8 / WRSFUsageCost3
A27: Tier 4 price: implausible as filed; checked against source. The filed tier 4 price of $0.10 per unit implies $0.10 per HCF, outside the $0.50 to $50.00 per HCF range a residential water rate plausibly takes. Carried exactly as filed and not corrected. Source: State Water Board eAR Section 8 / WRSFUsageCost4
A28: Tier 5 price: implausible as filed; checked against source. The filed tier 5 price of $0.25 per unit implies $0.25 per HCF, outside the $0.50 to $50.00 per HCF range a residential water rate plausibly takes. Carried exactly as filed and not corrected. Source: State Water Board eAR Section 8 / WRSFUsageCost5
A30: Representative monthly bill - LIVE (edit a yellow usage cell to recompute)
B31: Low | C31: Median | D31: High
A32: Usage per bill (HCF) | B32: =B11*$B$12 | C32: =C11*$B$12 | D32: =D11*$B$12
A33: Tier 1 charge per bill ($) | B33: =$C$17*MAX(0,MIN(B32,$D$17)-0) | C33: =$C$17*MAX(0,MIN(C32,$D$17)-0) | D33: =$C$17*MAX(0,MIN(D32,$D$17)-0)
A34: Tier 2 charge per bill ($) | B34: =$C$18*MAX(0,MIN(B32,$D$18)-$D$17) | C34: =$C$18*MAX(0,MIN(C32,$D$18)-$D$17) | D34: =$C$18*MAX(0,MIN(D32,$D$18)-$D$17)
A35: Tier 3 charge per bill ($) | B35: =$C$19*MAX(0,MIN(B32,$D$19)-$D$18) | C35: =$C$19*MAX(0,MIN(C32,$D$19)-$D$18) | D35: =$C$19*MAX(0,MIN(D32,$D$19)-$D$18)
A36: Tier 4 charge per bill ($) | B36: =$C$20*MAX(0,MIN(B32,$D$20)-$D$19) | C36: =$C$20*MAX(0,MIN(C32,$D$20)-$D$19) | D36: =$C$20*MAX(0,MIN(D32,$D$20)-$D$19)
A37: Tier 5 charge per bill ($) | B37: =$C$21*MAX(0,MIN(B32,$D$21)-$D$20) | C37: =$C$21*MAX(0,MIN(C32,$D$21)-$D$20) | D37: =$C$21*MAX(0,MIN(D32,$D$21)-$D$20)
A38: Tier 6 charge per bill ($) | B38: =$C$22*MAX(0,B32-$D$21) | C38: =$C$22*MAX(0,C32-$D$21) | D38: =$C$22*MAX(0,D32-$D$21)
A39: Volumetric charge per bill ($) | B39: =SUM(B33,B34,B35,B36,B37,B38) | C39: =SUM(C33,C34,C35,C36,C37,C38) | D39: =SUM(D33,D34,D35,D36,D37,D38)
A40: Base charge per bill ($) | B40: =$B$15 | C40: =$B$15 | D40: =$B$15
A41: Total per bill ($) | B41: =B40+B39 | C41: =C40+C39 | D41: =D40+D39
A42: Total per MONTH ($) | B42: =B41/$B$12 | C42: =C41/$B$12 | D42: =D41/$B$12
A43: Fixed per month ($) | B43: =$B$15/$B$12 | C43: =$B$15/$B$12 | D43: =$B$15/$B$12
A44: Volumetric per month ($) | B44: =B39/$B$12 | C44: =C39/$B$12 | D44: =D39/$B$12
A45: Effective price ($/HCF) | B45: =IF(B11=0,"",B42/B11) | C45: =IF(C11=0,"",C42/C11) | D45: =IF(D11=0,"",D42/D11)
...

Sheet eAR revenue & expenses
A1: Sisar Mutual Water Company
A2: eAR annual revenue and expenses - State Water Board eAR Section 8b (USD)
A3: Entity ID: cawc_0014 | Fiscal year ends December 31.
A5: The water system's own annual figures from the public eAR Section 8b, on the calendar year 2023 the filer self-reported (B0.1/B0.2). Shown beside the period-aligned Form 990 with the variance flagged: a different source (a State Water Board self-report vs an IRS filing). Preserved as filed, never reconciled.
A6: Reporting period basis (self-reported) | B6: calendar year 2023 | C6: eAR Section 8b B0.1 (WRFinancialReportingPeriod)
A8: Revenue (eAR Section 8b, questions B1.x)
A9: Line | B9: Amount (USD) | C9: Citation
A10: Water rate revenue | B10: 157665 | C10: State Water Board eAR Section 8b, question B1.1 + B1.2 (revenue from water rates), reporting year 2023
A11: Other fees and charges | B11: 500 | C11: State Water Board eAR Section 8b, question B1.3 + B1.4 (revenue from other fees), reporting year 2023
A12: Non-customer revenue | B12: 0 | C12: State Water Board eAR Section 8b, question B1.7 (grants, interest, and other non-customer), reporting year 2023
A13: Total annual revenue | B13: 158165 | C13: State Water Board eAR Section 8b, question B1.8 (total annual revenue for the reporting year), reporting year 2023
A15: Expenses (eAR Section 8b, questions B2.x)
A16: Line | B16: Amount (USD) | C16: Citation
A17: Operations and maintenance | B17: 176668 | C17: State Water Board eAR Section 8b, question B2.1 (annual O and M expense), reporting year 2023
A18: Capital | B18: 0 | C18: State Water Board eAR Section 8b, question B2.2 (annual expenses from investing or capital), reporting year 2023
A19: Financing | B19: 0 | C19: State Water Board eAR Section 8b, question B2.3 (annual expenses from financing), reporting year 2023
A20: Other | B20: 0 | C20: State Water Board eAR Section 8b, question B2.4 (total other annual expenses), reporting year 2023
A21: Total annual expenses | B21: 176668 | C21: State Water Board eAR Section 8b, question B2.5 (total annual expenses), reporting year 2023
A23: Period-aligned Form 990 comparison (variance surfaced, never reconciled)
A24: Measure | B24: eAR Section 8b | C24: Form 990
A25: total revenue | B25: 158165 | C25: 158846
A26: Variance (eAR minus Form 990) | B26: =B25-C25
A27: The eAR Section 8b total revenue (State Water Board self-report, calendar year 2023) and the Form 990 total revenue (IRS filing) are a different source and cover the same calendar year 2023. Both are carried as filed; the variance is surfaced, never reconciled.
A28: total expenses | B28: 176668 | C28: 175427
A29: Variance (eAR minus Form 990) | B29: =B28-C28
A30: The eAR Section 8b total expenses (State Water Board self-report, calendar year 2023) and the Form 990 total expenses (IRS filing) are a different source and cover the same calendar year 2023. Both are carried as filed; the variance is surfaced, never reconciled.

Sheet Denominators & alignment
A1: Sisar Mutual Water Company
A2: Denominators and calendar alignment
A3: Entity ID: cawc_0014 | Fiscal year ends December 31.
A5: System size and water use per fiscal year (the operating denominators that per-customer and per-acre metrics divide by), each cited to file and field. The eAR is reported on the calendar year; the 990 fiscal year differs by company. A calendar-year filer's volume is the eAR annual total (fiscal year = calendar year); an offset filer's is recast by a true monthly sum of the covered calendar months, or read not reported naming the missing months. Point-in-time counts (connections, population) are matched to the closest eAR year and never summed. Every derived figure states its formula and accounting rationale.
A6: Member vs customer (two different denominators, both preserved)
A7: Customer (service connection) | B7: 110 | C7: State Water Board eAR Section 4 (CurTotalConnections), reporting year 2024
A8: SDWIS service-connection count (different registry) | B8: 110
A9: Member (shareholder) | C9: No published shareholder count
A10: In a mutual water company a MEMBER is a shareholder who owns part of the system; a CUSTOMER is a metered service connection that receives water. The two diverge because one owner can hold several connections, a connection can serve people who are not owners, and some mutuals attach shares to land by acreage rather than counting heads. Per-customer metrics divide by service connections; per-member metrics divide by shareholders; the two counts are never used interchangeably.
A12: Denominator layer by fiscal year
A13: Fiscal year (end) | B13: Connections | C13: Population | D13: Service-area acres | E13: Water produced (AF) | F13: Water delivered (AF) | G13: Alignment method
A14: FY2021 (2021-12-31) | B14: 106 | C14: not reported | D14: 449.2 | E14: 5900.8 | F14: 5508.9 | G14: eAR annual total, calendar filer, equals fiscal year (not a monthly recast)
A15: FY2022 (2022-12-31) | B15: 106 | C15: not reported | D15: 449.2 | E15: 5723.8 | F15: 5603.8 | G15: eAR annual total, calendar filer, equals fiscal year (not a monthly recast)
A16: FY2023 (2023-12-31) | B16: 106 | C16: 340 | D16: 449.2 | E16: not reported | F16: not reported | G16: eAR annual total, calendar filer, equals fiscal year (not a monthly recast)
A17: FY2024 (2024-12-31) | B17: 110 | C17: 340 | D17: 449.2 | E17: not reported | F17: not reported | G17: eAR annual total, calendar filer, equals fiscal year (not a monthly recast)
A18: FY2025 (2025-12-31) | B18: 110 | C18: 340 | D18: 449.2 | E18: not reported | F18: not reported | G18: eAR annual total, calendar filer, equals fiscal year (not a monthly recast)
A20: Connections by class - FY2025 (eAR Section 4)
A21: Single-family residential | B21: 99
A22: Multi-family residential | B22: 9
A23: Commercial and institutional | B23: 2
A24: Monthly-volume source: California open-data portal (data.ca.gov): the separate Produced Water (by month and source) and Delivered Water (by month and connection type) resources, which cover every public water system (not only urban suppliers), one resource per reporting year, matched by exact PWSID. This is the aggregate publication of eAR Section 6.

Sheet Governance evidence
A1: Sisar Mutual Water Company
A2: Governance evidence status - Ostrom's eight design principles
A3: Entity ID: cawc_0014 | Fiscal year ends December 31.
A5: Evidence summary: 5 documented, 1 partial, 2 not documented of eight principles.
A6: A count of how many of Elinor Ostrom's eight design principles have a supporting record on file, not a grade. NOT DOCUMENTED means the supporting record was not found, not that the company governs badly. It marks a gap in the documentary record, an evidence gap to close, never a governance failing.
A7: Each mutual is read against Elinor Ostrom's eight design principles for institutions that govern a shared resource durably. Per principle: a one-line finding, the observable signal, a citation, and an evidence status stating whether the supporting record exists: DOCUMENTED (a cited record supports alignment), PARTIAL (some evidence exists but it is incomplete), or NOT DOCUMENTED (no supporting record was found). This is an evidence-status read, not a grade: the principles are never ranked, weighted, or given a letter, consistent with reporting as filed and not grading companies. NOT DOCUMENTED means the supporting record was not found, not that the company governs badly. It marks a gap in the documentary record, an evidence gap to close, never a governance failing.
A9: Principle | B9: Evidence status | C9: Finding | D9: Signal | E9: Citation
A10: Clearly defined boundaries | B10: DOCUMENTED | C10: The system is a defined public water system: 110 service connections over a State-published service-area boundary. | D10: SDWIS Community water system; SABL service-area boundary (not verified (sabl)); connections defined. | E10: [C][G]
A11: What the record shows: SDWIS defines the membership as a fixed set of service connections and the State Water Board publishes a SABL service-area polygon, so who is inside and outside the system is documented. The boundary is Not Verified (SABL), so its outer edge rests on that State layer.
A12: Rules fit local conditions | B12: DOCUMENTED | C12: Charges are tied to service under a documented rate or share-based allocation rule reported to the State or set in the company's structure. | D12: eAR Section 8a customer charges; documented rate or share-allocation rule. | E12: [E][r1]
A13: What the record shows: The record documents how charges are set, whether a filed metered rate schedule or a share-and-acreage allocation, so cost tracks service. Whether every tier scales precisely with use is only partially visible at this scale, but a real cost-to-service rule is on record.
A14: Collective-choice arrangements | B14: DOCUMENTED | C14: The company is owned by its customer-shareholders and run by a named board they elect, documented in its Form 990 governance section. | D14: Mutual ownership; named elected board of directors (Form 990). | E14: [990][r1]
A15: What the record shows: The record documents a collective-choice mechanism: customers are shareholders who elect a named board that governs the company. Turnout and specific member votes on major decisions are not documented, but the elected-board structure and its membership are on record.
A16: Monitoring | B16: DOCUMENTED | C16: The system is metered and monitored: the State SAFER risk assessment shows it Not Failing, and it files an annual eAR. | D16: SAFER Not Failing; annual eAR reporting; metered connections. | E16: [S][E]
A17: What the record shows: Operational monitoring is documented: the State rates the system Not Failing on its drinking-water risk assessment and the system files an annual eAR. No independent audited financial statement is published, so financial monitoring is weaker, but the operational record is present.
A18: Graduated sanctions | B18: NOT DOCUMENTED | C18: No published shut-off, penalty, or delinquency policy was found for this system. | D18: No sourced sanctions policy. | E18: not reported
A19: What the record shows: No public record of a graduated shut-off or penalty policy was found for a system this small. NOT DOCUMENTED means the supporting record was not found, not that the company governs badly. It marks a gap in the documentary record, an evidence gap to close, never a governance failing.
A20: Conflict-resolution mechanisms | B20: NOT DOCUMENTED | C20: No published bylaws, dispute procedure, or grievance mechanism was found for this system. | D20: No sourced conflict-resolution record. | E20: not reported
A21: What the record shows: No public record of a member dispute or conflict-resolution procedure was found. NOT DOCUMENTED means the supporting record was not found, not that the company governs badly. It marks a gap in the documentary record, an evidence gap to close, never a governance failing.
A22: Recognized right to organize | B22: DOCUMENTED | C22: An incorporated California mutual water company recognized by the IRS (501(c)(12)) and by the State Water Board as a public water system. | D22: IRS 501(c)(12) exempt filer (Form 990); SDWIS public water system. | E22: [990][C][SOS]
A23: What the record shows: Baseline legal standing is documented: the company is an incorporated mutual recognized by the IRS as a tax-exempt filer and by the State Water Board as a regulated water system. This records the right to organize as a member entity, not a documented instance of exercising it. The California Secretary of State holds the company as a registered corporation, entity number 0235505, first registered 04/14/1949, status as filed "Active", with a governing body named in the Statement of Information filed 2/24/2026. That is a direct state record of the right to organize being recognized, so the evidence behind this status is now a filed corporate record rather than an inference from the company's tax form. The status was already DOCUMENTED and does not move.
A24: Nested enterprises | B24: PARTIAL | C24: The system draws on a shared local groundwater basin, embedding it in a larger physical water system, though its role in basin governance is not documented. | D24: SDWIS Primary Water Source Type: groundwater (shared basin). | E24: [C]
A25: What the record shows: The system relies on a shared groundwater basin, so it is physically nested in a larger hydrologic system. Its participation in a groundwater sustainability agency or basin governance is not documented, so the nesting evidence is partial.

Sheet Operational metrics
A1: Sisar Mutual Water Company
A2: Operational metrics - plant per acre, density, terrain
A3: Entity ID: cawc_0014 | Fiscal year ends December 31.
A5: Plant assets per acre
A6: Service-area acres | B6: 449.2 | C6: Geodesic area (WGS84 spherical excess) of the SABL service-area polygon.
A7: Fiscal year | B7: Gross plant per acre (primary) | C7: Net plant per acre
A8: FY2021 | B8: 3252.8161 | C8: 1071.4069
A9: FY2022 | B9: 3279.9243 | C9: 1025.0824
A10: FY2023 | B10: 4205.1291 | C10: 1880.1759
A11: FY2024 | B11: 4407.126 | C11: 1929.0316
A12: FY2025 | B12: 4488.6621 | C12: 1902.362
A13: Infrastructure built per acre of service area. Gross plant per acre is the primary read because it measures how much plant the system has put in the ground per acre, and unlike net plant it does not fall over time purely because the assets depreciate on the books. Net plant per acre is shown alongside as the depreciated book value per acre.
A14: Formula: gross plant per acre = Form 990 Part X line 10a (land, buildings, and equipment, gross) / SABL service-area acres; net plant per acre uses Part X line 10c (net)
A15: Source lines: Form 990 Part X line 10a (gross) and line 10c (net); Geodesic area (WGS84 spherical excess) of the SABL service-area polygon.
A16: Confidence: medium. This is worked out from filed figures (a ratio, or a year-to-year change), so it is one step removed from the raw numbers.. Filed gross/net plant over the measured SABL service-area acreage.
A18: Connections per acre
A19: Connections per acre | B19: 0.24 | C19: 110 connections / 449.2 acres. CA State Water Board SABL SERVICE_CONNECTIONS; Geodesic area (WGS84 spherical excess) of the SABL service-area polygon.
A21: Who they are
A22: Terrain class | B22: canyon | C22: Company context page (BLUEPRINT 5B)
A23: A California mutual water company (501(c)(12)) serving about 110 service connections and roughly 340 residents in the Sisar Canyon and Upper Ojai area between Ojai and Santa Paula, Ventura County, on canyon and upper-valley terrain.

Sheet Supply & weather
A1: Sisar Mutual Water Company
A2: Supply and weather indicators (DWR water year)
A3: Entity ID: cawc_0014 | Fiscal year ends December 31.
A5: Reporting calendar: Different reporting periods. The DWR water year runs October 1 to September 30; this system's fiscal year ends December 31, so the two period ends are three months apart. Read the two side by side with that in mind. Neither series is recast: both are reported as filed. A water year is named for the calendar year it ends in, so WY2024 and FY2024 share a number without covering the same twelve months.
A7: Indicator | B7: WY2021 | C7: WY2022 | D7: WY2023 | E7: WY2024 | F7: WY2025
A8: Water-year type (Sacramento Valley) | B8: Critical | C8: Critical | D8: Wet | E8: Above Normal | F8: not reported
A9: Peak drought, Ventura County | B9: D4 | C9: D4 | D9: D3 | E9: None (no D0-D4 during the fiscal year) | F9: D3
A10: Precip, percent of normal (8-Station Index) | B10: 48 | C10: 86 | D10: 133 | E10: 96 | F10: 113
A11: Snowpack, April 1 percent of average | B11: 59% | C11: 38% | D11: 237% | E11: 110% | F11: 96%
A12: State Water Project allocation | B12: 5% | C12: 5% | D12: 100% | E12: 40% | F12: 50%

Sheet How this was built
A1: Sisar Mutual Water Company
A2: How this was built - forensic lineage
A3: Entity ID: cawc_0014 | Fiscal year ends December 31.
A5: A plain account of the forensic lineage behind the hard-to-source metrics: what sources were checked, what was found, what was derived, and what could not be built and why. Every figure marked DERIVED or IMPOSSIBLE above is traceable to a line here.
A7: Water-sales revenue per customer - DIRECT
A8: Sources checked | B8: State Water Board eAR Section 8b (water-rate revenue B1.1/B1.2); State Water Board eAR Section 4 (connection count, same reporting year); audited financial statement (secondary cross-check, where published)
A9: What was found | B9: The eAR Section 8b reports water-rate revenue for reporting year 2023, so this is a DIRECT filed figure; per customer it is divided by the eAR Section 4 connection count for the same reporting year, so numerator and denominator share the year.
A11: Assessment revenue (residual) - DERIVED
A12: Sources checked | B12: Form 990 Part VIII line 2 (program-service revenue); State Water Board eAR Section 8b (water-rate revenue B1.1/B1.2)
A13: What was found | B13: No source separately reports a member assessment, so it is DERIVED as a residual: $158,846 (990 program-service revenue) minus $157,665 (eAR water-rate revenue) = $1,181. Period-aligned; medium confidence.
A14: Caveat | B14: This residual is a difference between two sources for the same period; it is not a separately filed assessment line and may include other unmatched revenue.
A16: Meter revenue - not reported
A17: Sources checked | B17: State Water Board eAR Section 8a (rate prices); State Water Board eAR Section 8b (revenue lines); audited financial statement
A18: What was found | B18: The rate price exists in Section 8a but no revenue or tier volume is reported, and the base charge is already inside water sales.
A19: Caveat | B19: The eAR Section 8a reports a base/meter rate PRICE, but the filing carries no meter revenue line and no tier volume, and the base charge is already inside the water-sales revenue (eAR Section 8b water rates). Building a separate meter figure would double-count. Not backed into from a total.
A21: Overage / tiered-penalty revenue - not reported
A22: Sources checked | B22: State Water Board eAR Section 8a (rate prices); State Water Board eAR Section 8b (revenue lines); audited financial statement
A23: What was found | B23: The rate price exists in Section 8a but no revenue or tier volume is reported, and the base charge is already inside water sales.
A24: Caveat | B24: The eAR Section 8a reports tiered/overage rate PRICES, but the filing carries no overage revenue and no tier consumption volume, and any overage billed is already inside the water-sales revenue. Building it would double-count. Not backed into from a total.
A26: eAR Section 8b reporting-period basis - sourced
A27: Sources checked | B27: eAR Section 8b B0.1 (WRFinancialReportingPeriod); eAR Section 8b B0.2 (WRFiscalYearStartDate)
A28: What was found | B28: The reporting basis (fiscal vs calendar year) is read from the filer's own B0.1/B0.2 answer and staged verbatim, never hardcoded, so the 990 comparison and the residual are period-aligned.
A30: Member (shareholder) count denominator - not reported
A31: Sources checked | B31: Form 990 (no member count stated); company website
A32: What was found | B32: No filing states a member/shareholder count, so the per-member unit economics read not reported rather than borrowing the connection count.
A34: Water volume delivered (acre-feet) - not reported
A35: Sources checked | B35: Form 990 (not in the filing); Consumer Confidence Report; eAR Section 6 (PRA-gated)
A36: What was found | B36: Volume delivered in acre-feet is not in the Form 990 and the CCR states only a source mix, so the per-acre-foot metrics read not reported; the eAR Section 6 is named as the source still needed.

Sheet Water Operations
A1: Sisar Mutual Water Company
A2: Water Operations (sourced outside the financial filings)
A3: Entity ID: cawc_0014 | Fiscal year ends December 31.
A5: A separate dialect of data from the financial statements: the system's water supply, from the California State Water Board records (the Consumer Confidence Report served by the eAR portal, and SDWIS Drinking Water Watch). Each field carries its source, year, and confidence the same way a financial line item does; a field the source does not state reads 'not reported' with the source still needed. Figures are as reported, never estimated or reconciled across sources.
A7: Field | B7: Value | C7: Source | D7: Year | E7: Confidence | F7: Source excerpt / cross-source note
A8: Water type | B8: Potable (community drinking water) | C8: SDWIS Drinking Water Watch (State Water Board) | D8: 2024 | E8: high | F8: SISAR MUTUAL WATER CO: State Water System Type = Community.
A9: Source mix | B9: Primary source: local groundwater wells (SDWIS Primary Water Source Type: Groundwater). SDWIS classifies the primary supply type; it states no acre-foot volume by source. | C9: SDWIS Drinking Water Watch (State Water Board) | D9: 2024 | E9: high | F9: SISAR MUTUAL WATER CO: Primary Water Source Type = Groundwater.
A10: Service connections (total) | B10: 110 connections | C10: SDWIS Drinking Water Watch (State Water Board) | D10: 2024 | E10: high | F10: SISAR MUTUAL WATER CO: Total Number of Service Connections = 110. [cross-source: SDWIS connection snapshot; the eAR reports active service connections on its own basis and per reporting year. Both preserved, not reconciled.]
A11: Connections by class | B11: Service connections by type (SDWIS snapshot): Residential 108; Commercial 2; Total 110. | C11: SDWIS Drinking Water Watch (State Water Board) | D11: 2024 | E11: high | F11: SISAR MUTUAL WATER CO: connections by type - Residential 108; Commercial 2; Total 110.
A12: Population served | B12: 340 residents | C12: SDWIS Drinking Water Watch (State Water Board) | D12: 2024 | E12: high | F12: SISAR MUTUAL WATER CO: Total Population = 340.
A13: Treatment and water quality | B13: Operator certification on file: Treatment or distribution operator of any grade; Distribution Operator Level 1. SDWIS states operator grades, not the treatment process detail. | C13: SDWIS Drinking Water Watch (State Water Board) | D13: 2024 | E13: high | F13: SISAR MUTUAL WATER CO: Treatment Plant Class = Treatment or distribution operator of any grade; Distribution System Class = Distribution Operator Level 1.
A15: Not reported (source still needed)
A16: Annual volume delivered (acre-feet) | B16: not reported - needs annual volume in acre-feet (State Water Board eAR Section 6 or company production records); the CCR states only a percentage mix
A17: Customer classes served | B17: not reported - needs the State Water Board eAR or the system CCR

Sheet Sources & audit
A1: Sisar Mutual Water Company
A2: Sources & audit - full provenance and tie-outs (kept off the statements so they read clean)
A3: Entity ID: cawc_0014 | Fiscal year ends December 31.
A5: Presentation standard: every figure on the statement tabs is verified to its source filing and shown clean. A cell the filing does not report reads "not reported" (never estimated, never guessed).
A6: Citations, confidence tiers, and the filed-vs-computed tie-out checks live on the "Sources & audit" tab, keyed by cell, so every number is fully traceable without cluttering the statements. These pages are ready to use as filed.
A8: A. Filing provenance (one row per staged extraction)
A9: Fiscal year | B9: Period end | C9: Filing type | D9: Confidence | E9: Extraction ID | F9: Object ID | G9: Extracted by | H9: Extracted at | I9: Source URL
A10: FY2020 | B10: 2020-12-31 | C10: 990 | D10: high | E10: 7e1eaeeb-6489-40e2-9fbd-31ab9e0bd9e1 | F10: 202100769349300200 | G10: claude-opus-5 | H10: 2026-09-16T21:34:13+00:00 | I10: https://apps.irs.gov/pub/epostcard/990/xml/2021/2021_TEOS_XML_01A.zip#202100769349300200_public.xml
A11: FY2021 | B11: 2021-12-31 | C11: 990 | D11: high | E11: 004aa906-1042-486f-bd5f-a968a1faaa1c | F11: 202200629349300000 | G11: claude-opus-5 | H11: 2026-09-16T21:34:13+00:00 | I11: https://apps.irs.gov/pub/epostcard/990/xml/2022/2022_TEOS_XML_01A.zip#202200629349300000_public.xml
A12: FY2022 | B12: 2022-12-31 | C12: 990 | D12: high | E12: d59a22a0-9204-4881-91c8-928ff76308ed | F12: 202321359349300402 | G12: claude-opus-5 | H12: 2026-09-16T21:34:13+00:00 | I12: https://apps.irs.gov/pub/epostcard/990/xml/2023/2023_TEOS_XML_05A.zip#202321359349300402_public.xml
A13: FY2023 | B13: 2023-12-31 | C13: 990 | D13: high | E13: 55f1b7d4-6735-45f5-a870-b6c53013418f | F13: 202400659349300000 | G13: claude-opus-5 | H13: 2026-09-16T21:34:13+00:00 | I13: https://apps.irs.gov/pub/epostcard/990/xml/2024/2024_TEOS_XML_03A.zip#202400659349300000_public.xml
A14: FY2024 | B14: 2024-12-31 | C14: 990 | D14: high | E14: edb6946f-fa25-4c56-ab32-ecb589094aeb | F14: 202510699349301406 | G14: claude-opus-5 | H14: 2026-09-16T21:34:13+00:00 | I14: https://apps.irs.gov/pub/epostcard/990/xml/2025/2025_TEOS_XML_03A.zip#202510699349301406_public.xml
A15: FY2025 | B15: 2025-12-31 | C15: 990 | D15: high | E15: fd4d2a84-0116-4e50-86ec-e1827b152b0c | F15: 202620699349301132 | G15: claude-opus-5 | H15: 2026-09-16T21:34:13+00:00 | I15: https://apps.irs.gov/pub/epostcard/990/xml/2026/2026_TEOS_XML_03A.zip#202620699349301132_public.xml
A17: B. Figure citations (every figure on the statement tabs, keyed by cell)
A18: Tab | B18: Cell | C18: Line item | D18: Form 990 line | E18: Key path | F18: Confidence | G18: As filed
A19: Revenue (detail) | B19: B7 | C19: 1h. Total contributions, gifts, grants | D19: 1h | E19: part_viii_revenue.total_contributions | F19: high | G19: 0
A20: Revenue (detail) | B20: C7 | C20: 1h. Total contributions, gifts, grants | D20: 1h | E20: part_viii_revenue.total_contributions | F20: high | G20: 0
A21: Revenue (detail) | B21: D7 | C21: 1h. Total contributions, gifts, grants | D21: 1h | E21: part_viii_revenue.total_contributions | F21: high | G21: 0
A22: Revenue (detail) | B22: E7 | C22: 1h. Total contributions, gifts, grants | D22: 1h | E22: part_viii_revenue.total_contributions | F22: high | G22: 0
A23: Revenue (detail) | B23: F7 | C23: 1h. Total contributions, gifts, grants | D23: 1h | E23: part_viii_revenue.total_contributions | F23: high | G23: 0
A24: Revenue (detail) | B24: G7 | C24: 1h. Total contributions, gifts, grants | D24: 1h | E24: part_viii_revenue.total_contributions | F24: high | G24: 0
A25: Revenue (detail) | B25: B8 | C25: 2g. Total program service revenue | D25: 2g | E25: part_viii_revenue.total_program_service_revenue | F25: high | G25: 134980
A26: Revenue (detail) | B26: C8 | C26: 2g. Total program service revenue | D26: 2g | E26: part_viii_revenue.total_program_service_revenue | F26: high | G26: 130965
A27: Revenue (detail) | B27: D8 | C27: 2g. Total program service revenue | D27: 2g | E27: part_viii_revenue.total_program_service_revenue | F27: high | G27: 131599
A28: Revenue (detail) | B28: E8 | C28: 2g. Total program service revenue | D28: 2g | E28: part_viii_revenue.total_program_service_revenue | F28: high | G28: 158846
A29: Revenue (detail) | B29: F8 | C29: 2g. Total program service revenue | D29: 2g | E29: part_viii_revenue.total_program_service_revenue | F29: high | G29: 188669
A30: Revenue (detail) | B30: G8 | C30: 2g. Total program service revenue | D30: 2g | E30: part_viii_revenue.total_program_service_revenue | F30: high | G30: 131040
... A345: Net-assets reconciliation | B345: F10 | C345: 9. Other changes in net assets | D345: Part XI line 9 | E345: part_xi_reconciliation.other_changes_net_assets | F345: high | G345: 289
A347: C. Tie-out checks (filed vs computed; any nonzero variance is flagged red)
A348: Tab | B348: Check | C348: Fiscal year | D348: Filed | E348: Computed | F348: Variance (computed - filed)
A349: Revenue (detail) | B349: 12. Total revenue | C349: FY2020 | D349: 134980 | E349: ='Revenue (detail)'!B13 | F349: =E349-D349
A350: Revenue (detail) | B350: 12. Total revenue | C350: FY2021 | D350: 130965 | E350: ='Revenue (detail)'!C13 | F350: =E350-D350
A351: Revenue (detail) | B351: 12. Total revenue | C351: FY2022 | D351: 131599 | E351: ='Revenue (detail)'!D13 | F351: =E351-D351
A352: Revenue (detail) | B352: 12. Total revenue | C352: FY2023 | D352: 158846 | E352: ='Revenue (detail)'!E13 | F352: =E352-D352
A353: Revenue (detail) | B353: 12. Total revenue | C353: FY2024 | D353: 188669 | E353: ='Revenue (detail)'!F13 | F353: =E353-D353
A354: Revenue (detail) | B354: 12. Total revenue | C354: FY2025 | D354: 131040 | E354: ='Revenue (detail)'!G13 | F354: =E354-D354
A355: Operating expenses (detail) | B355: 25. Total functional expenses | C355: FY2020 | D355: 152712 | E355: ='Operating expenses (detail)'!B45 | F355: =E355-D355
A356: Operating expenses (detail) | B356: 25. Total functional expenses | C356: FY2021 | D356: 114458 | E356: ='Operating expenses (detail)'!C45 | F356: =E356-D356
A357: Operating expenses (detail) | B357: 25. Total functional expenses | C357: FY2022 | D357: 145865 | E357: ='Operating expenses (detail)'!D45 | F357: =E357-D357
A358: Operating expenses (detail) | B358: 25. Total functional expenses | C358: FY2023 | D358: 175427 | E358: ='Operating expenses (detail)'!E45 | F358: =E358-D358
...

Sheet Provenance
