Workbook

Sheet Summary
A1: South Mountain Mutual Water Company
A2: Financial Summary - multi-year overview (USD)
A3: Entity ID: cawc_0017 | Fiscal year ends December 31.
A5: Presentation standard: every figure on the statement tabs is verified to its source filing and shown clean. A cell the filing does not report reads "not reported" (never estimated, never guessed).
A6: Citations, confidence tiers, and the filed-vs-computed tie-out checks live on the "Sources & audit" tab, keyed by cell, so every number is fully traceable without cluttering the statements. These pages are ready to use as filed.
A8: Metric | B8: FY2020 | C8: FY2021 | D8: FY2022 | E8: FY2023 | F8: FY2024
A9: Operating results (USD)
A10: Total revenue | B10: 67866 | C10: 62217 | D10: 76336 | E10: 70723 | F10: 121852
A11: Total expenses | B11: 31431 | C11: 41920 | D11: 32084 | E11: 46371 | F11: 66094
A12: Net income | B12: 36435 | C12: 20297 | D12: 44252 | E12: 24352 | F12: 55758
A14: Financial position (USD, end of year)
A15: Total assets | B15: 98122 | C15: 118419 | D15: 309896 | E15: 334248 | F15: 398778
A16: Total liabilities | B16: 0 | C16: 0 | D16: 0 | E16: 0 | F16: 8772
A17: Net assets | B17: 98122 | C17: 118419 | D17: 309896 | E17: 334248 | F17: 390006
A19: Headline ratios
A20: Operating margin | B20: 0.53686677 | C20: 0.32622917 | D20: 0.57970027 | E20: 0.34432928 | F20: 0.45758789
A21: Revenue growth (YoY)
A22: Return on assets | B22: 0.37132345 | C22: 0.17139986 | D22: 0.14279629 | E22: 0.072856083 | F22: 0.13982216
A24: Figures as reported in source filings (full provenance on the Sources & audit tab). Parentheses denote negatives; ratios are computed upstream in financials_annual.

Sheet Notes
A1: Notes
A2: Human annotations from the versioned store (data/notes/). Annotations only: they never change a reported figure or a confidence tier.
A4: Date | B4: Tag | C4: Author | D4: Note
A5: No notes recorded yet.

Sheet Financial Statements
A1: South Mountain Mutual Water Company
A2: Financial Statements - income statement, balance sheet, cash flow, member income test (USD)
A3: Entity ID: cawc_0017 | Fiscal year ends December 31.
A5: INCOME STATEMENT - as reported (USD)
A6: Line item | B6: FY2020 | C6: FY2021 | D6: FY2022 | E6: FY2023 | F6: FY2024
A7: Revenue
A8: Program service revenue
A9: Investment income
A10: Net rental income
A11: Net gain/(loss) on investment sales
A12: Other revenue
A13: Contributions & grants
A14: Total revenue
A16: Expenses
A17: Depreciation
A18: Interest expense
A19: Total expenses | B19: 31431 | C19: 41920 | D19: 32084 | E19: 46371 | F19: 66094
A21: Net income | B21: 36435 | C21: 20297 | D21: 44252 | E21: 24352 | F21: 55758
A24: BALANCE SHEET - as reported (USD, end of year)
A25: Line item | B25: FY2020 | C25: FY2021 | D25: FY2022 | E25: FY2023 | F25: FY2024
A26: Assets
A27: Cash | B27: 98122 | C27: 118419 | D27: 104455 | E27: 128807 | F27: 140310
A28: Savings & temporary investments
A29: Accounts receivable
A30: Inventories
A31: Prepaid expenses
A32: Property, plant & equipment (gross)
A33: Less: accumulated depreciation
A34: Net property, plant & equipment | B34: 0 | C34: 0 | D34: 205441 | E34: 205441 | F34: 258468
A35: Total assets | B35: 98122 | C35: 118419 | D35: 309896 | E35: 334248 | F35: 398778
A37: Liabilities
A38: Accounts payable
A39: Mortgages & notes payable
A40: Total liabilities | B40: 0 | C40: 0 | D40: 0 | E40: 0 | F40: 8772
A42: Net Assets / Equity
A43: Capital stock
A44: Paid-in capital
A45: Retained earnings
A46: Net assets | B46: 98122 | C46: 118419 | D46: 309896 | E46: 334248 | F46: 390006
A49: CASH FLOW - derived proxy (USD)
...

Sheet Balance Sheet
A1: South Mountain Mutual Water Company
A2: Balance Sheet - as reported (USD, end of year)
A3: Entity ID: cawc_0017 | Fiscal year ends December 31.
A5: Line item | B5: FY2020 | C5: FY2021 | D5: FY2022 | E5: FY2023 | F5: FY2024
A6: Assets
A7: Cash | B7: 98122 | C7: 118419 | D7: 104455 | E7: 128807 | F7: 140310
A8: Savings & temporary investments
A9: Accounts receivable
A10: Inventories
A11: Prepaid expenses
A12: Property, plant & equipment (gross)
A13: Less: accumulated depreciation
A14: Net property, plant & equipment | B14: 0 | C14: 0 | D14: 205441 | E14: 205441 | F14: 258468
A15: Total assets | B15: 98122 | C15: 118419 | D15: 309896 | E15: 334248 | F15: 398778
A17: Liabilities
A18: Accounts payable
A19: Mortgages & notes payable
A20: Total liabilities | B20: 0 | C20: 0 | D20: 0 | E20: 0 | F20: 8772
A22: Net Assets / Equity
A23: Capital stock
A24: Paid-in capital
A25: Retained earnings
A26: Net assets | B26: 98122 | C26: 118419 | D26: 309896 | E26: 334248 | F26: 390006
A28: Balance check (assets − liab. − net assets) | B28: 0 | C28: 0 | D28: 0 | E28: 0 | F28: 0
A30: Net PP&E is the reported ppe_net column (gross less accumulated depreciation). The balance check should be ~0 where all three totals are reported; a non-zero value flags a reporting or extraction discrepancy worth reviewing.

Sheet Form 990-EZ Parts I & II
A1: South Mountain Mutual Water Company
A2: Form 990-EZ - Part I (revenue, expenses, net assets) and Part II (balance sheet), as filed (USD)
A3: Entity ID: cawc_0017 | Fiscal year ends December 31.
A5: Form 990-EZ line | B5: FY2020 | C5: FY2021 | D5: FY2022 | E5: FY2023 | F5: FY2024
A6: Revenue (Part I)
A7: 1. Contributions, gifts, grants | B7: not reported | C7: not reported | D7: not reported | E7: not reported | F7: 48272
A8: 3. Membership dues and assessments | B8: 67824 | C8: 62171 | D8: 76298 | E8: 70685 | F8: 73580
A9: 4. Investment income | B9: 42 | C9: 46 | D9: 38 | E9: 38 | F9: not reported
A10: 9. Total revenue | B10: 67866 | C10: 62217 | D10: 76336 | E10: 70723 | F10: 121852
A12: Expenses (Part I)
A13: 13. Fees for services (independent contractors) | B13: not reported | C13: 7885 | D13: not reported | E13: not reported | F13: not reported
A14: 16. Other expenses | B14: 31431 | C14: 34035 | D14: 32084 | E14: 46371 | F14: 66094
A15: 17. Total expenses | B15: =SUM(B13:B14) | C15: =SUM(C13:C14) | D15: =SUM(D13:D14) | E15: =SUM(E13:E14) | F15: =SUM(F13:F14)
A17: Net-assets reconciliation (Part I)
A18: 19. Net assets or fund balances, beginning of year | B18: 61687 | C18: 98122 | D18: 118419 | E18: 309896 | F18: 334248
A19: 18. Excess or (deficit) for the year | B19: 36435 | C19: 20297 | D19: 44252 | E19: 24352 | F19: 55758
A20: 21. Net assets or fund balances, end of year | B20: =SUM(B18,B19) | C20: =SUM(C18,C19) | D20: =SUM(D18,D19) | E20: =SUM(E18,E19) | F20: =SUM(F18,F19)
A22: Balance sheet (Part II, end of year - column B)
A23: 22. Cash, savings, and investments | B23: 98122 | C23: 118419 | D23: 104455 | E23: 128807 | F23: 140310
A24: 23. Land and buildings | B24: 0 | C24: 0 | D24: 205441 | E24: 205441 | F24: 258468
A25: 24. Other assets | B25: 0 | C25: 0 | D25: 0 | E25: 0 | F25: 0
A26: 25. Total assets | B26: =SUM(B23:B25) | C26: =SUM(C23:C25) | D26: =SUM(D23:D25) | E26: =SUM(E23:E25) | F26: =SUM(F23:F25)
A27: 26. Total liabilities | B27: 0 | C27: 0 | D27: 0 | E27: 0 | F27: 8772
A28: 27. Net assets or fund balances | B28: 98122 | C28: 118419 | D28: 309896 | E28: 334248 | F28: 390006
A30: Form 990-EZ is the short form: revenue and expenses are on Part I and the balance sheet is the six-line Part II (no full-990 Parts VII-XI). Total expenses (line 17) and Total assets (line 25) are live SUMs of the lines above; Total revenue (line 9) is shown as filed because the EZ nets its lines 5-7 (sales of assets, gaming, inventory) into line 9 without itemizing them. Ending net assets (line 21) is recomputed live as beginning net assets (line 19) plus the excess or deficit (line 18); where the filer's own line 21 does not equal that sum, the variance is flagged red on the Sources & audit tab and carried exactly as filed, not reconciled. Every figure's citation and confidence are on the Sources & audit tab.

Sheet Cash flow proxies
A1: South Mountain Mutual Water Company
A2: Cash Flow Proxies - derived (USD)
A3: Entity ID: cawc_0017 | Fiscal year ends December 31.
A5: PROXY ONLY. The source filings contain no statement of cash flows. Lines below are derived from the reported income statement and year-over-year balance-sheet changes; treat as directional estimates, not GAAP cash flows. The earliest year has no prior period, so its delta cells are blank.
A7: Proxy line (USD) | B7: FY2020 | C7: FY2021 | D7: FY2022 | E7: FY2023 | F7: FY2024
A8: Operating
A9: Net income | B9: 36435 | C9: 20297 | D9: 44252 | E9: 24352 | F9: 55758
A10: + Depreciation (reported)
A11: − Δ Accounts receivable
A12: − Δ Inventories
A13: − Δ Prepaid expenses
A14: + Δ Accounts payable
A15: Operating cash flow proxy | C15: 20297 | D15: 44252 | E15: 24352 | F15: 55758
A17: Investing
A18: − Δ PP&E gross (capex proxy)
A20: Financing
A21: Δ Mortgages & notes payable
A23: Reconciliation
A24: Δ Cash + temp. investments (actual) | C24: 20297 | D24: -13964 | E24: 24352 | F24: 11503
A26: The capex proxy assumes gross PP&E rises only via capital spending (it ignores disposals). 'Δ Cash + temp. investments (actual)' is the real reported change in liquid funds and is the most reliable line here; the operating/investing/financing proxies will not perfectly reconcile to it.

Sheet Ratios
A1: South Mountain Mutual Water Company
A2: Financial Ratios
A3: Entity ID: cawc_0017 | Fiscal year ends December 31.
A5: Ratio | B5: FY2020 | C5: FY2021 | D5: FY2022 | E5: FY2023 | F5: FY2024
A6: Profitability (computed upstream)
A7: Operating margin (NI / revenue) | B7: 0.53686677 | C7: 0.32622917 | D7: 0.57970027 | E7: 0.34432928 | F7: 0.45758789
A8: Expense ratio (expenses / revenue) | B8: 0.46313323 | C8: 0.67377083 | D8: 0.42029973 | E8: 0.65567072 | F8: 0.54241211
A9: Return on assets (NI / assets) | B9: 0.37132345 | C9: 0.17139986 | D9: 0.14279629 | E9: 0.072856083 | F9: 0.13982216
A10: Revenue growth (YoY)
A12: Leverage & solvency
A13: Debt-to-assets (liab. / assets) | B13: 0 | C13: 0 | D13: 0 | E13: 0 | F13: 0.021997201
A14: Equity ratio (net assets / assets) | B14: 1 | C14: 1 | D14: 1 | E14: 1 | F14: 0.9780028
A16: Liquidity & asset profile (derived here)
A17: Current ratio (current assets / AP)
A18: Cash ratio ((cash+temp inv.) / total liab.) | F18: 15.995212
A19: Asset age proxy (accum. deprec. / gross PP&E)
A21: Upstream ratios are read from financials_annual; derived ratios are computed only where inputs are reported. Current ratio uses accounts payable as the current-liability proxy (the filings do not split current vs. long-term liabilities). Asset age proxy: a higher % implies older / more depreciated infrastructure.

Sheet Unit economics
A1: South Mountain Mutual Water Company
A2: Unit economics - per-customer revenue by category (USD)
A3: Entity ID: cawc_0017 | Fiscal year ends December 31.
A5: Every metric here is PER CUSTOMER (a metered service connection). It is not a per-member figure; the member (shareholder) count is a different denominator, shown in the denominator block. The visible cell shows the value and its classification; the numerator, denominator, formula, and rationale are in each metric's LOGIC popup.
A6: Per-customer denominator (service connections) | C6: State Water Board eAR Section 4
A7: Total annual revenue (eAR Section 8b B1.8) | C7: eAR Section 8b total annual revenue not reported for this system.
A8: Primary source
A10: Revenue categories (value, classification, per customer, share)
A11: Revenue category | B11: Classification | C11: Value (USD) | D11: Per customer | E11: Share of revenue
A12: Water sales revenue | B12: not reported | C12: not reported | D12: not reported | E12: not reported
A13: Assessment revenue (990 program-service revenue not matched to eAR water-rate revenue) | B13: IMPOSSIBLE | C13: IMPOSSIBLE | D13: IMPOSSIBLE | E13: IMPOSSIBLE
A14: Meter revenue | B14: not reported | C14: not reported | D14: not reported | E14: not reported
A15: Overage or tiered penalty revenue | B15: not reported | C15: not reported | D15: not reported | E15: not reported
A17: Water sales revenue - not reported
A18: Not reported: this system filed an eAR but no Section 8b revenue block, so there is no filed water-sales figure. Not fallen back to a different year.
A19: Reason: No filed eAR Section 8b water-rate revenue for this system.
A21: Assessment revenue (990 program-service revenue not matched to eAR water-rate revenue) - IMPOSSIBLE
A22: Not computed. A period-aligned residual is not possible for this filer.
A23: Reason: Not derivable. The eAR Section 8b is reporting year None while the Form 990 fiscal year ends None; the two period ends are not aligned, so a period-aligned residual cannot be computed.
A25: Meter revenue - not reported
A26: Not reported. This category is not built because doing so would double-count.
A27: Reason: The eAR Section 8a reports a base/meter rate PRICE, but the filing carries no meter revenue line and no tier volume, and the base charge is already inside the water-sales revenue (eAR Section 8b water rates). Building a separate meter figure would double-count. Not backed into from a total.
A29: Overage or tiered penalty revenue - not reported
A30: Not reported. This category is not built because doing so would double-count.
A31: Reason: The eAR Section 8a reports tiered/overage rate PRICES, but the filing carries no overage revenue and no tier consumption volume, and any overage billed is already inside the water-sales revenue. Building it would double-count. Not backed into from a total.

Sheet Rate structure
A1: South Mountain Mutual Water Company
A2: Rate structure and representative bill - eAR Section 8a (RY2024)
A3: Entity ID: cawc_0017 | Fiscal year ends December 31.
A5: This block is a rate-schedule illustration at defined usage levels. It is NOT billed revenue and not a claim about any real customer's usage. The revenue side of unit economics is the separate Unit Economics block.
A6: A filed eAR Section 8a rate schedule IS staged for this system, reporting year 2024, carrying a residential rate structure filed as "OtherRate", a volumetric unit of Gallons, a billing frequency of A. It carries no single-family residential charges grid (no base charge and no tier prices), so a representative monthly bill is not computable as a monthly bill for this system. Nothing here is estimated to fill the gap.

Sheet Denominators & alignment
A1: South Mountain Mutual Water Company
A2: Denominators and calendar alignment
A3: Entity ID: cawc_0017 | Fiscal year ends December 31.
A5: System size and water use per fiscal year (the operating denominators that per-customer and per-acre metrics divide by), each cited to file and field. The eAR is reported on the calendar year; the 990 fiscal year differs by company. A calendar-year filer's volume is the eAR annual total (fiscal year = calendar year); an offset filer's is recast by a true monthly sum of the covered calendar months, or read not reported naming the missing months. Point-in-time counts (connections, population) are matched to the closest eAR year and never summed. Every derived figure states its formula and accounting rationale.
A6: Member vs customer (two different denominators, both preserved)
A7: Customer (service connection) | B7: 27 | C7: State Water Board eAR Section 4 (CurTotalConnections), reporting year 2024
A8: SDWIS service-connection count (different registry) | B8: 27
A9: Member (shareholder) | C9: No published shareholder count
A10: In a mutual water company a MEMBER is a shareholder who owns part of the system; a CUSTOMER is a metered service connection that receives water. The two diverge because one owner can hold several connections, a connection can serve people who are not owners, and some mutuals attach shares to land by acreage rather than counting heads. Per-customer metrics divide by service connections; per-member metrics divide by shareholders; the two counts are never used interchangeably.
A12: Denominator layer by fiscal year
A13: Fiscal year (end) | B13: Connections | C13: Population | D13: Service-area acres | E13: Water produced (AF) | F13: Water delivered (AF) | G13: Alignment method
A14: FY2020 (2020-12-31) | B14: 27 | C14: not reported | D14: 132.1 | E14: 74 | F14: 0 | G14: eAR annual total, calendar filer, equals fiscal year (not a monthly recast)
A15: FY2021 (2021-12-31) | B15: 27 | C15: not reported | D15: 132.1 | E15: 93 | F15: 0 | G15: eAR annual total, calendar filer, equals fiscal year (not a monthly recast)
A16: FY2022 (2022-12-31) | B16: 27 | C16: not reported | D16: 132.1 | E16: 94.9 | F16: 0 | G16: eAR annual total, calendar filer, equals fiscal year (not a monthly recast)
A17: FY2023 (2023-12-31) | B17: 27 | C17: not reported | D17: 132.1 | E17: not reported | F17: not reported | G17: eAR annual total, calendar filer, equals fiscal year (not a monthly recast)
A18: FY2024 (2024-12-31) | B18: 27 | C18: 58 | D18: 132.1 | E18: not reported | F18: not reported | G18: eAR annual total, calendar filer, equals fiscal year (not a monthly recast)
A20: Connections by class - FY2024 (eAR Section 4)
A21: Single-family residential | B21: 27
A22: Monthly-volume source: California open-data portal (data.ca.gov): the separate Produced Water (by month and source) and Delivered Water (by month and connection type) resources, which cover every public water system (not only urban suppliers), one resource per reporting year, matched by exact PWSID. This is the aggregate publication of eAR Section 6.

Sheet Governance evidence
A1: South Mountain Mutual Water Company
A2: Governance evidence status - Ostrom's eight design principles
A3: Entity ID: cawc_0017 | Fiscal year ends December 31.
A5: Evidence summary: 3 documented, 3 partial, 2 not documented of eight principles.
A6: A count of how many of Elinor Ostrom's eight design principles have a supporting record on file, not a grade. NOT DOCUMENTED means the supporting record was not found, not that the company governs badly. It marks a gap in the documentary record, an evidence gap to close, never a governance failing.
A7: Each mutual is read against Elinor Ostrom's eight design principles for institutions that govern a shared resource durably. Per principle: a one-line finding, the observable signal, a citation, and an evidence status stating whether the supporting record exists: DOCUMENTED (a cited record supports alignment), PARTIAL (some evidence exists but it is incomplete), or NOT DOCUMENTED (no supporting record was found). This is an evidence-status read, not a grade: the principles are never ranked, weighted, or given a letter, consistent with reporting as filed and not grading companies. NOT DOCUMENTED means the supporting record was not found, not that the company governs badly. It marks a gap in the documentary record, an evidence gap to close, never a governance failing.
A9: Principle | B9: Evidence status | C9: Finding | D9: Signal | E9: Citation
A10: Clearly defined boundaries | B10: DOCUMENTED | C10: The system is a defined public water system: 27 service connections over a State-published service-area boundary. | D10: SDWIS Community water system; SABL service-area boundary (verified); connections defined. | E10: [C][G]
A11: What the record shows: SDWIS defines the membership as a fixed set of service connections and the State Water Board publishes a SABL service-area polygon, so who is inside and outside the system is documented. The boundary is Verified, so its outer edge rests on that State layer.
A12: Rules fit local conditions | B12: PARTIAL | C12: The system charges customers for water and reports a rate structure to the State, but the detailed basis is only partially documented. | D12: eAR Section 8a customer-charges block. | E12: [E]
A13: What the record shows: The eAR documents that the system charges for water and reports a rate structure, so charges are tied to service. The detailed basis (metered tiers versus shares or parcels) is only partially documented for a system this small, so the proportionality evidence is incomplete.
A14: Collective-choice arrangements | B14: PARTIAL | C14: As a mutual it is owned by its customer-shareholders who elect the board, but specific board membership and votes are not documented. | D14: Mutual (501(c)(12)) ownership structure; Form 990 governance section. | E14: [990][SOS]
A15: What the record shows: The mutual-company form documents that customers are shareholders who elect the directors, so a collective-choice mechanism exists on paper. No record of the specific board, elections, or member votes was found, so the evidence is partial. The specific board is now on the record: the Statement of Information filed 7/2/2026 names 1 director and 3 officers, transcribed as filed. That closes one of the gaps named above. It does NOT close the others: a filed roster shows who governs, not how members choose them, and carries no election, turnout or member vote. The evidence status therefore stays PARTIAL, because what this principle asks about is member participation and that remains undocumented.
A16: Monitoring | B16: DOCUMENTED | C16: The system is metered and monitored: the State SAFER risk assessment shows it Not Failing, and it files an annual eAR. | D16: SAFER Not Failing; annual eAR reporting; metered connections. | E16: [S][E]
A17: What the record shows: Operational monitoring is documented: the State rates the system Not Failing on its drinking-water risk assessment and the system files an annual eAR. No independent audited financial statement is published, so financial monitoring is weaker, but the operational record is present.
A18: Graduated sanctions | B18: NOT DOCUMENTED | C18: No published shut-off, penalty, or delinquency policy was found for this system. | D18: No sourced sanctions policy. | E18: not reported
A19: What the record shows: No public record of a graduated shut-off or penalty policy was found for a system this small. NOT DOCUMENTED means the supporting record was not found, not that the company governs badly. It marks a gap in the documentary record, an evidence gap to close, never a governance failing.
A20: Conflict-resolution mechanisms | B20: NOT DOCUMENTED | C20: No published bylaws, dispute procedure, or grievance mechanism was found for this system. | D20: No sourced conflict-resolution record. | E20: not reported
A21: What the record shows: No public record of a member dispute or conflict-resolution procedure was found. NOT DOCUMENTED means the supporting record was not found, not that the company governs badly. It marks a gap in the documentary record, an evidence gap to close, never a governance failing.
A22: Recognized right to organize | B22: DOCUMENTED | C22: An incorporated California mutual water company recognized by the IRS (501(c)(12)) and by the State Water Board as a public water system. | D22: IRS 501(c)(12) exempt filer (Form 990); SDWIS public water system. | E22: [990][C][SOS]
A23: What the record shows: Baseline legal standing is documented: the company is an incorporated mutual recognized by the IRS as a tax-exempt filer and by the State Water Board as a regulated water system. This records the right to organize as a member entity, not a documented instance of exercising it. The California Secretary of State holds the company as a registered corporation, entity number 0494202, first registered 07/19/1965, status as filed "Active", with a governing body named in the Statement of Information filed 7/2/2026. That is a direct state record of the right to organize being recognized, so the evidence behind this status is now a filed corporate record rather than an inference from the company's tax form. The status was already DOCUMENTED and does not move.
A24: Nested enterprises | B24: PARTIAL | C24: The system draws on a shared local groundwater basin, embedding it in a larger physical water system, though its role in basin governance is not documented. | D24: SDWIS Primary Water Source Type: groundwater (shared basin). | E24: [C]
A25: What the record shows: The system relies on a shared groundwater basin, so it is physically nested in a larger hydrologic system. Its participation in a groundwater sustainability agency or basin governance is not documented, so the nesting evidence is partial.

Sheet Operational metrics
A1: South Mountain Mutual Water Company
A2: Operational metrics - plant per acre, density, terrain
A3: Entity ID: cawc_0017 | Fiscal year ends December 31.
A5: Connections per acre
A6: Connections per acre | B6: 0.2 | C6: 27 connections / 132.1 acres. CA State Water Board SABL SERVICE_CONNECTIONS; Geodesic area (WGS84 spherical excess) of the SABL service-area polygon.
A8: Who they are
A9: Terrain class | B9: other | C9: Company context page (BLUEPRINT 5B)
A10: A small mutual water company (501(c)(12)) serving about 27 service connections and roughly 58 residents on South Mountain Road south of the Santa Clara River near Santa Paula, Ventura County, on ranch and hillside terrain.

Sheet Supply & weather
A1: South Mountain Mutual Water Company
A2: Supply and weather indicators (DWR water year)
A3: Entity ID: cawc_0017 | Fiscal year ends December 31.
A5: Reporting calendar: Different reporting periods. The DWR water year runs October 1 to September 30; this system's fiscal year ends December 31, so the two period ends are three months apart. Read the two side by side with that in mind. Neither series is recast: both are reported as filed. A water year is named for the calendar year it ends in, so WY2024 and FY2024 share a number without covering the same twelve months.
A7: Indicator | B7: WY2020 | C7: WY2021 | D7: WY2022 | E7: WY2023 | F7: WY2024
A8: Water-year type (Sacramento Valley) | B8: Dry | C8: Critical | D8: Critical | E8: Wet | F8: Above Normal
A9: Peak drought, Ventura County | B9: D1 | C9: D4 | D9: D4 | E9: D3 | F9: None (no D0-D4 during the fiscal year)
A10: Precip, percent of normal (8-Station Index) | B10: 63 | C10: 48 | D10: 86 | E10: 133 | F10: 96
A11: Snowpack, April 1 percent of average | B11: 53% | C11: 59% | D11: 38% | E11: 237% | F11: 110%
A12: State Water Project allocation | B12: 20% | C12: 5% | D12: 5% | E12: 100% | F12: 40%

Sheet How this was built
A1: South Mountain Mutual Water Company
A2: How this was built - forensic lineage
A3: Entity ID: cawc_0017 | Fiscal year ends December 31.
A5: A plain account of the forensic lineage behind the hard-to-source metrics: what sources were checked, what was found, what was derived, and what could not be built and why. Every figure marked DERIVED or IMPOSSIBLE above is traceable to a line here.
A7: Water-sales revenue per customer - not reported
A8: Sources checked | B8: State Water Board eAR Section 8b (water-rate revenue B1.1/B1.2); State Water Board eAR Section 4 (connection count, same reporting year); audited financial statement (secondary cross-check, where published)
A9: What was found | B9: The eAR Section 8b reports water-rate revenue for reporting year None, so this is a DIRECT filed figure; per customer it is divided by the eAR Section 4 connection count for the same reporting year, so numerator and denominator share the year.
A11: Assessment revenue (residual) - IMPOSSIBLE
A12: Sources checked | B12: Form 990 Part VIII line 2 (program-service revenue); State Water Board eAR Section 8b (water-rate revenue B1.1/B1.2); eAR Section 8b filer comment (WRRevenueComments)
A13: What was found | B13: A period-aligned residual cannot be computed for this filer, so the metric is rendered IMPOSSIBLE rather than guessed.
A14: Caveat | B14: Not derivable. The eAR Section 8b is reporting year None while the Form 990 fiscal year ends None; the two period ends are not aligned, so a period-aligned residual cannot be computed.
A16: Meter revenue - not reported
A17: Sources checked | B17: State Water Board eAR Section 8a (rate prices); State Water Board eAR Section 8b (revenue lines); audited financial statement
A18: What was found | B18: The rate price exists in Section 8a but no revenue or tier volume is reported, and the base charge is already inside water sales.
A19: Caveat | B19: The eAR Section 8a reports a base/meter rate PRICE, but the filing carries no meter revenue line and no tier volume, and the base charge is already inside the water-sales revenue (eAR Section 8b water rates). Building a separate meter figure would double-count. Not backed into from a total.
A21: Overage / tiered-penalty revenue - not reported
A22: Sources checked | B22: State Water Board eAR Section 8a (rate prices); State Water Board eAR Section 8b (revenue lines); audited financial statement
A23: What was found | B23: The rate price exists in Section 8a but no revenue or tier volume is reported, and the base charge is already inside water sales.
A24: Caveat | B24: The eAR Section 8a reports tiered/overage rate PRICES, but the filing carries no overage revenue and no tier consumption volume, and any overage billed is already inside the water-sales revenue. Building it would double-count. Not backed into from a total.
A26: eAR Section 8b reporting-period basis - sourced
A27: Sources checked | B27: eAR Section 8b B0.1 (WRFinancialReportingPeriod); eAR Section 8b B0.2 (WRFiscalYearStartDate)
A28: What was found | B28: The reporting basis (fiscal vs calendar year) is read from the filer's own B0.1/B0.2 answer and staged verbatim, never hardcoded, so the 990 comparison and the residual are period-aligned.
A30: Member (shareholder) count denominator - not reported
A31: Sources checked | B31: Form 990 (no member count stated); company website
A32: What was found | B32: No filing states a member/shareholder count, so the per-member unit economics read not reported rather than borrowing the connection count.
A34: Water volume delivered (acre-feet) - not reported
A35: Sources checked | B35: Form 990 (not in the filing); Consumer Confidence Report; eAR Section 6 (PRA-gated)
A36: What was found | B36: Volume delivered in acre-feet is not in the Form 990 and the CCR states only a source mix, so the per-acre-foot metrics read not reported; the eAR Section 6 is named as the source still needed.

Sheet Water Operations
A1: South Mountain Mutual Water Company
A2: Water Operations (sourced outside the financial filings)
A3: Entity ID: cawc_0017 | Fiscal year ends December 31.
A5: A separate dialect of data from the financial statements: the system's water supply, from the California State Water Board records (the Consumer Confidence Report served by the eAR portal, and SDWIS Drinking Water Watch). Each field carries its source, year, and confidence the same way a financial line item does; a field the source does not state reads 'not reported' with the source still needed. Figures are as reported, never estimated or reconciled across sources.
A7: Field | B7: Value | C7: Source | D7: Year | E7: Confidence | F7: Source excerpt / cross-source note
A8: Water type | B8: Potable (community drinking water) | C8: SDWIS Drinking Water Watch (State Water Board) | D8: 2024 | E8: high | F8: SOUTH MOUNTAIN MUTUAL WATER CO: State Water System Type = Community.
A9: Source mix | B9: Primary source: local groundwater wells (SDWIS Primary Water Source Type: Groundwater). SDWIS classifies the primary supply type; it states no acre-foot volume by source. | C9: SDWIS Drinking Water Watch (State Water Board) | D9: 2024 | E9: high | F9: SOUTH MOUNTAIN MUTUAL WATER CO: Primary Water Source Type = Groundwater.
A10: Service connections (total) | B10: 27 connections | C10: SDWIS Drinking Water Watch (State Water Board) | D10: 2024 | E10: high | F10: SOUTH MOUNTAIN MUTUAL WATER CO: Total Number of Service Connections = 27. [cross-source: SDWIS connection snapshot; the eAR reports active service connections on its own basis and per reporting year. Both preserved, not reconciled.]
A11: Connections by class | B11: Service connections by type (SDWIS snapshot): Residential 27; Total 27. | C11: SDWIS Drinking Water Watch (State Water Board) | D11: 2024 | E11: high | F11: SOUTH MOUNTAIN MUTUAL WATER CO: connections by type - Residential 27; Total 27.
A12: Population served | B12: 58 residents | C12: SDWIS Drinking Water Watch (State Water Board) | D12: 2024 | E12: high | F12: SOUTH MOUNTAIN MUTUAL WATER CO: Total Population = 58.
A13: Treatment and water quality | B13: Operator certification on file: Treatment or distribution operator of any grade; Distribution Operator Level 1. SDWIS states operator grades, not the treatment process detail. | C13: SDWIS Drinking Water Watch (State Water Board) | D13: 2024 | E13: high | F13: SOUTH MOUNTAIN MUTUAL WATER CO: Treatment Plant Class = Treatment or distribution operator of any grade; Distribution System Class = Distribution Operator Level 1.
A15: Not reported (source still needed)
A16: Annual volume delivered (acre-feet) | B16: not reported - needs annual volume in acre-feet (State Water Board eAR Section 6 or company production records); the CCR states only a percentage mix
A17: Customer classes served | B17: not reported - needs the State Water Board eAR or the system CCR

Sheet Sources & audit
A1: South Mountain Mutual Water Company
A2: Sources & audit - full provenance and tie-outs (kept off the statements so they read clean)
A3: Entity ID: cawc_0017 | Fiscal year ends December 31.
A5: Presentation standard: every figure on the statement tabs is verified to its source filing and shown clean. A cell the filing does not report reads "not reported" (never estimated, never guessed).
A6: Citations, confidence tiers, and the filed-vs-computed tie-out checks live on the "Sources & audit" tab, keyed by cell, so every number is fully traceable without cluttering the statements. These pages are ready to use as filed.
A8: A. Filing provenance (one row per staged extraction)
A9: Fiscal year | B9: Period end | C9: Filing type | D9: Confidence | E9: Extraction ID | F9: Object ID | G9: Extracted by | H9: Extracted at | I9: Source URL
A10: FY2020 | B10: 2020-12-31 | C10: 990-EZ | D10: high | E10: 4727640f-1ec2-4ef0-8914-d777c96c687e | F10: 202140789349200924 | G10: claude-opus-5 | H10: 2026-09-14T20:40:23+00:00 | I10: https://apps.irs.gov/pub/epostcard/990/xml/2021/2021_TEOS_XML_01A.zip#202140789349200924_public.xml
A11: FY2021 | B11: 2021-12-31 | C11: 990-EZ | D11: high | E11: 83d6237b-f606-4a0e-bbf9-fcc7ca2d6599 | F11: 202221059349201677 | G11: claude-opus-5 | H11: 2026-09-14T20:40:23+00:00 | I11: https://apps.irs.gov/pub/epostcard/990/xml/2022/2022_TEOS_XML_01A.zip#202221059349201677_public.xml
A12: FY2022 | B12: 2022-12-31 | C12: 990-EZ | D12: high | E12: 0014eabd-afd0-458f-9cee-29a7df38a4a4 | F12: 202320589349201612 | G12: claude-opus-5 | H12: 2026-09-14T20:40:23+00:00 | I12: https://apps.irs.gov/pub/epostcard/990/xml/2023/2023_TEOS_XML_03A.zip#202320589349201612_public.xml
A13: FY2023 | B13: 2023-12-31 | C13: 990-EZ | D13: high | E13: 236fb461-b472-4c20-817e-28bf9be61bb5 | F13: 202411039349202041 | G13: claude-opus-5 | H13: 2026-09-14T20:40:23+00:00 | I13: https://apps.irs.gov/pub/epostcard/990/xml/2024/2024_TEOS_XML_04A.zip#202411039349202041_public.xml
A14: FY2024 | B14: 2024-12-31 | C14: 990-EZ | D14: high | E14: c26c4b62-143e-4180-9f4d-c43a2fb26624 | F14: 202540939349201104 | G14: claude-opus-5 | H14: 2026-09-14T20:40:23+00:00 | I14: https://apps.irs.gov/pub/epostcard/990/xml/2025/2025_TEOS_XML_04A.zip#202540939349201104_public.xml
A16: B. Figure citations (every figure on the statement tabs, keyed by cell)
A17: Tab | B17: Cell | C17: Line item | D17: Form 990 line | E17: Key path | F17: Confidence | G17: As filed
A18: Form 990-EZ Parts I & II | B18: F7 | C18: 1. Contributions, gifts, grants | D18: Part I line 1 | E18: part_i_revenue_expenses.contributions_grants | F18: high | G18: 48272
A19: Form 990-EZ Parts I & II | B19: B8 | C19: 3. Membership dues and assessments | D19: Part I line 3 | E19: part_i_revenue_expenses.membership_dues | F19: high | G19: 67824
A20: Form 990-EZ Parts I & II | B20: C8 | C20: 3. Membership dues and assessments | D20: Part I line 3 | E20: part_i_revenue_expenses.membership_dues | F20: high | G20: 62171
A21: Form 990-EZ Parts I & II | B21: D8 | C21: 3. Membership dues and assessments | D21: Part I line 3 | E21: part_i_revenue_expenses.membership_dues | F21: high | G21: 76298
A22: Form 990-EZ Parts I & II | B22: E8 | C22: 3. Membership dues and assessments | D22: Part I line 3 | E22: part_i_revenue_expenses.membership_dues | F22: high | G22: 70685
A23: Form 990-EZ Parts I & II | B23: F8 | C23: 3. Membership dues and assessments | D23: Part I line 3 | E23: part_i_revenue_expenses.membership_dues | F23: high | G23: 73580
A24: Form 990-EZ Parts I & II | B24: B9 | C24: 4. Investment income | D24: Part I line 4 | E24: part_i_revenue_expenses.investment_income | F24: high | G24: 42
A25: Form 990-EZ Parts I & II | B25: C9 | C25: 4. Investment income | D25: Part I line 4 | E25: part_i_revenue_expenses.investment_income | F25: high | G25: 46
A26: Form 990-EZ Parts I & II | B26: D9 | C26: 4. Investment income | D26: Part I line 4 | E26: part_i_revenue_expenses.investment_income | F26: high | G26: 38
A27: Form 990-EZ Parts I & II | B27: E9 | C27: 4. Investment income | D27: Part I line 4 | E27: part_i_revenue_expenses.investment_income | F27: high | G27: 38
A28: Form 990-EZ Parts I & II | B28: B10 | C28: 9. Total revenue | D28: Part I line 9 | E28: part_i_revenue_expenses.total_revenue | F28: high | G28: 67866
A29: Form 990-EZ Parts I & II | B29: C10 | C29: 9. Total revenue | D29: Part I line 9 | E29: part_i_revenue_expenses.total_revenue | F29: high | G29: 62217
... A73: Form 990-EZ Parts I & II | B73: F28 | C73: 27. Net assets or fund balances | D73: Part II line 27 col B | E73: part_ii_balance_sheet.net_assets_eoy | F73: high | G73: 390006
A75: C. Tie-out checks (filed vs computed; any nonzero variance is flagged red)
A76: Tab | B76: Check | C76: Fiscal year | D76: Filed | E76: Computed | F76: Variance (computed - filed)
A77: Form 990-EZ Parts I & II | B77: 17. Total expenses | C77: FY2020 | D77: 31431 | E77: ='Form 990-EZ Parts I & II'!B15 | F77: =E77-D77
A78: Form 990-EZ Parts I & II | B78: 17. Total expenses | C78: FY2021 | D78: 41920 | E78: ='Form 990-EZ Parts I & II'!C15 | F78: =E78-D78
A79: Form 990-EZ Parts I & II | B79: 17. Total expenses | C79: FY2022 | D79: 32084 | E79: ='Form 990-EZ Parts I & II'!D15 | F79: =E79-D79
A80: Form 990-EZ Parts I & II | B80: 17. Total expenses | C80: FY2023 | D80: 46371 | E80: ='Form 990-EZ Parts I & II'!E15 | F80: =E80-D80
A81: Form 990-EZ Parts I & II | B81: 17. Total expenses | C81: FY2024 | D81: 66094 | E81: ='Form 990-EZ Parts I & II'!F15 | F81: =E81-D81
A82: Form 990-EZ Parts I & II | B82: 21. Net assets or fund balances, end of year | C82: FY2020 | D82: 98122 | E82: ='Form 990-EZ Parts I & II'!B20 | F82: =E82-D82
A83: Form 990-EZ Parts I & II | B83: 21. Net assets or fund balances, end of year | C83: FY2021 | D83: 118419 | E83: ='Form 990-EZ Parts I & II'!C20 | F83: =E83-D83
A84: Form 990-EZ Parts I & II | B84: 21. Net assets or fund balances, end of year | C84: FY2022 | D84: 309896 | E84: ='Form 990-EZ Parts I & II'!D20 | F84: =E84-D84
A85: Form 990-EZ Parts I & II | B85: 21. Net assets or fund balances, end of year | C85: FY2023 | D85: 334248 | E85: ='Form 990-EZ Parts I & II'!E20 | F85: =E85-D85
A86: Form 990-EZ Parts I & II | B86: 21. Net assets or fund balances, end of year | C86: FY2024 | D86: 390006 | E86: ='Form 990-EZ Parts I & II'!F20 | F86: =E86-D86
A87: Form 990-EZ Parts I & II | B87: 25. Total assets | C87: FY2020 | D87: 98122 | E87: ='Form 990-EZ Parts I & II'!B26 | F87: =E87-D87
...

Sheet Provenance
A1: Build provenance | B1: Built from source commit d418ffb17485 (2026-10-06); source fingerprint a75a8eee82c65cf7; 192 companies (179 retail mutual, 4 irrigation mutual, 3 mutual, no PWSID, purpose not stated, 2 frozen non-mutual (special district), 2 wholesale mutual, 1 frozen non-mutual (investor-owned), 1 frozen non-mutual (municipal)); 91 gates; build id 3d08d6d2a855.
A2: source_commit | B2: d418ffb174855ab78000d391d42f898397b0d8aa
A3: source_commit_date | B3: 2026-10-06
A4: source_fingerprint | B4: a75a8eee82c65cf7096931f06e18affdc28686a02895b46538e7298b57c04d94
A5: gate_count | B5: 91
A6: build_id | B6: 3d08d6d2a855
A7: registry: frozen non-mutual (investor-owned) | B7: 1
A8: registry: frozen non-mutual (municipal) | B8: 1
A9: registry: frozen non-mutual (special district) | B9: 2
A10: registry: irrigation mutual | B10: 4
A11: registry: mutual, no PWSID, purpose not stated | B11: 3
A12: registry: retail mutual | B12: 179
A13: registry: wholesale mutual | B13: 2
