Workbook

Sheet Summary
A1: Riverside Highland Water Company
A2: Financial Summary - multi-year overview (USD)
A3: Entity ID: cawc_0038 | Fiscal year ends December 31.
A5: Presentation standard: every figure on the statement tabs is verified to its source filing and shown clean. A cell the filing does not report reads "not reported" (never estimated, never guessed).
A6: Citations, confidence tiers, and the filed-vs-computed tie-out checks live on the "Sources & audit" tab, keyed by cell, so every number is fully traceable without cluttering the statements. These pages are ready to use as filed.
A8: Metric | B8: FY2020 | C8: FY2022 | D8: FY2023
A9: Operating results (USD)
A10: Total revenue | B10: 4990618 | C10: 26598252 | D10: 5953474
A11: Total expenses | B11: 4042053 | C11: 5120196 | D11: 5535377
A12: Net income | B12: 948565 | C12: 21478056 | D12: 418097
A14: Financial position (USD, end of year)
A15: Total assets | B15: 27142522 | C15: 52588959 | D15: 54491240
A16: Total liabilities | B16: 597827 | C16: 1885129 | D16: 3306931
A17: Net assets | B17: 26544695 | C17: 50703830 | D17: 51184309
A19: Headline ratios
A20: Operating margin | B20: 0.19006965 | C20: 0.80749878 | D20: 0.0702274
A21: Revenue growth (YoY) | B21: 0.25414911 | C21: 1.8573044 | D21: -0.77617048
A22: Return on assets | B22: 0.034947563 | C22: 0.40841379 | D22: 0.0076727379
A24: Figures as reported in source filings (full provenance on the Sources & audit tab). Parentheses denote negatives; ratios are computed upstream in financials_annual.

Sheet Notes
A1: Notes
A2: Human annotations from the versioned store (data/notes/). Annotations only: they never change a reported figure or a confidence tier.
A4: Date | B4: Tag | C4: Author | D4: Note
A5: No notes recorded yet.

Sheet Financial Statements
A1: Riverside Highland Water Company
A2: Financial Statements - income statement, balance sheet, cash flow, member income test (USD)
A3: Entity ID: cawc_0038 | Fiscal year ends December 31.
A5: INCOME STATEMENT - as reported (USD)
A6: Line item | B6: FY2020 | C6: FY2022 | D6: FY2023
A7: Revenue
A8: Program service revenue | B8: 4444005 | C8: 5514562 | D8: 5292585
A9: Investment income | B9: 85370 | C9: 248778 | D9: 320814
A10: Net rental income
A11: Net gain/(loss) on investment sales | B11: -7046 | C11: 28800 | D11: 225
A12: Other revenue | B12: 464364 | C12: 20802412 | D12: 336150
A13: Contributions & grants
A14: Total revenue | B14: 4990618 | C14: 26598252 | D14: 5953474
A16: Expenses
A17: Depreciation | B17: 1104199 | C17: 1167182 | D17: 1556793
A18: Interest expense
A19: Total expenses | B19: 4042053 | C19: 5120196 | D19: 5535377
A21: Net income | B21: 948565 | C21: 21478056 | D21: 418097
A24: BALANCE SHEET - as reported (USD, end of year)
A25: Line item | B25: FY2020 | C25: FY2022 | D25: FY2023
A26: Assets
A27: Cash | B27: 500 | C27: 36034 | D27: 133221
A28: Savings & temporary investments | B28: 2468882 | C28: 813127 | D28: 198493
A29: Accounts receivable | B29: 773398 | C29: 846557 | D29: 806102
A30: Inventories
A31: Prepaid expenses | B31: 17579 | C31: 29662 | D31: 35774
A32: Property, plant & equipment (gross) | B32: 37559754 | C32: 59969280 | D32: 61699476
A33: Less: accumulated depreciation | B33: -16950978 | C33: -19273028 | D33: -20910038
A34: Net property, plant & equipment | B34: 20608776 | C34: 40696252 | D34: 40789438
A35: Total assets | B35: 27142522 | C35: 52588959 | D35: 54491240
A37: Liabilities
A38: Accounts payable | B38: 495540 | C38: 578529 | D38: 707786
A39: Mortgages & notes payable
A40: Total liabilities | B40: 597827 | C40: 1885129 | D40: 3306931
A42: Net Assets / Equity
A43: Capital stock | B43: 190880 | C43: 190260 | D43: 190260
A44: Paid-in capital | B44: 291553 | C44: 292173 | D44: 292173
A45: Retained earnings | B45: 26062262 | C45: 50221397 | D45: 50701876
A46: Net assets | B46: 26544695 | C46: 50703830 | D46: 51184309
A49: CASH FLOW - derived proxy (USD)
...

Sheet Balance Sheet
A1: Riverside Highland Water Company
A2: Balance Sheet - as reported (USD, end of year)
A3: Entity ID: cawc_0038 | Fiscal year ends December 31.
A5: Line item | B5: FY2020 | C5: FY2022 | D5: FY2023
A6: Assets
A7: Cash | B7: 500 | C7: 36034 | D7: 133221
A8: Savings & temporary investments | B8: 2468882 | C8: 813127 | D8: 198493
A9: Accounts receivable | B9: 773398 | C9: 846557 | D9: 806102
A10: Inventories
A11: Prepaid expenses | B11: 17579 | C11: 29662 | D11: 35774
A12: Property, plant & equipment (gross) | B12: 37559754 | C12: 59969280 | D12: 61699476
A13: Less: accumulated depreciation | B13: -16950978 | C13: -19273028 | D13: -20910038
A14: Net property, plant & equipment | B14: 20608776 | C14: 40696252 | D14: 40789438
A15: Total assets | B15: 27142522 | C15: 52588959 | D15: 54491240
A17: Liabilities
A18: Accounts payable | B18: 495540 | C18: 578529 | D18: 707786
A19: Mortgages & notes payable
A20: Total liabilities | B20: 597827 | C20: 1885129 | D20: 3306931
A22: Net Assets / Equity
A23: Capital stock | B23: 190880 | C23: 190260 | D23: 190260
A24: Paid-in capital | B24: 291553 | C24: 292173 | D24: 292173
A25: Retained earnings | B25: 26062262 | C25: 50221397 | D25: 50701876
A26: Net assets | B26: 26544695 | C26: 50703830 | D26: 51184309
A28: Balance check (assets − liab. − net assets) | B28: 0 | C28: 0 | D28: 0
A30: Net PP&E is the reported ppe_net column (gross less accumulated depreciation). The balance check should be ~0 where all three totals are reported; a non-zero value flags a reporting or extraction discrepancy worth reviewing.

Sheet Officers & contractors
A1: Riverside Highland Water Company
A2: Officers, Directors & Contractors - Form 990 Part VII (FY2023; USD)
A3: Entity ID: cawc_0038 | Fiscal year ends December 31.
A5: Section A - Officers, directors, trustees, key employees
A6: Name | B6: Title | C6: Reportable comp (org) | D6: Reportable comp (related) | E6: Other comp | F6: Total compensation
A7: JAMES MCNABOE | B7: PRESIDENT | C7: 3800 | D7: 0 | E7: 0 | F7: 3800
A8: BRYAN HEGARDT | B8: DIRECTOR | C8: 0 | D8: 0 | E8: 0 | F8: 0
A9: DONALD J LARKIN JR | B9: SECRETARY/CFO | C9: 4400 | D9: 0 | E9: 0 | F9: 4400
A10: GILBERT RANGEL | B10: DIRECTOR | C10: 2750 | D10: 0 | E10: 0 | F10: 2750
A11: JENNIFER THOMPSON | B11: VICE PRESIDENT | C11: 3350 | D11: 0 | E11: 0 | F11: 3350
A12: DENIS KIDD | B12: DIRECTOR | C12: 2750 | D12: 0 | E12: 0 | F12: 2750
A13: GEORGE SAUNDERS | B13: DIRECTOR | C13: 2950 | D13: 0 | E13: 0 | F13: 2950
A14: WENDELL BAKER | B14: DIRECTOR | C14: 3200 | D14: 0 | E14: 0 | F14: 3200
A15: BURT SEUYLEMEZIAN | B15: DIRECTOR | C15: 3950 | D15: 0 | E15: 0 | F15: 3950
A16: DONALD HOUGH | B16: GENERAL MANAGER | C16: 230878 | D16: 0 | E16: 26624 | F16: 257502
A17: JENNIFER GIMPEL | B17: ADMINISTRATIVE MANAGER | C17: 134450 | D17: 0 | E17: 20886 | F17: 155336
A18: CRAIG GUDGEON | B18: DISTRIBUTION SUPERINTENDEN | C18: 161056 | D18: 0 | E18: 14022 | F18: 175078
... A21: FERNANDO MONREAL | B21: ROUNDS PERSONNEL | C21: 141863 | D21: 0 | E21: 16746 | F21: 158609
A23: Section B - Independent contractors (over $100,000)
A24: Contractor | B24: Services | C24: Compensation
A25: TRI-COUNTY PUMP COMPANY | B25: PUMP AND WELL SERVICE | C25: 145971
A27: Section A lists every officer, director, trustee and key employee filed for the latest year; the two with the highest total compensation are highlighted. Total compensation is computed (reportable org + related + other). Section B lists each independent contractor paid over $100,000; the return reports 1 such contractor(s). Source and confidence for every figure are on the Sources & audit tab.

Sheet Revenue (detail)
A1: Riverside Highland Water Company
A2: Revenue - Form 990 Part VIII (USD)
A3: Entity ID: cawc_0038 | Fiscal year ends December 31.
A5: Part VIII line | B5: FY2020 | C5: FY2022 | D5: FY2023
A6: Revenue by category
A7: 1h. Total contributions, gifts, grants | B7: not reported | C7: not reported | D7: not reported
A8: 2g. Total program service revenue | B8: 4444005 | C8: 5514562 | D8: 5292585
A9: 3. Investment income | B9: 85370 | C9: 248778 | D9: 320814
A10: 6d. Net rental income | B10: not reported | C10: not reported | D10: not reported
A11: 7d. Net gain/(loss) from investment sales | B11: -7046 | C11: 28800 | D11: 225
A12: 11e. Other revenue | B12: 464364 | C12: 20802412 | D12: 336150
A13: 12. Total revenue | B13: =SUM(B7:B12) | C13: =SUM(C7:C12) | D13: =SUM(D7:D12)
A15: Program service revenue detail - FY2023 (lines 2a-2f)
A16: Description | B16: Business code | C16: Total revenue
A17: WATER SALES | B17: 221000 | C17: 4056047
A18: STOCK ASSESSMENT | B18: 221000 | C18: 987299
A19: FEES AND PENALTIES | B19: 221000 | C19: 249239
A20: Revenue category subtotals are as filed. Total revenue (line 12) is a live SUM of the category cells above; its tie-out to the filed total is on the Sources & audit tab. Program service revenue detail is shown for the latest year, with its sum-to-line-2g check on that same audit tab.

Sheet Operating expenses (detail)
A1: Riverside Highland Water Company
A2: Statement of Functional Expenses - Form 990 Part IX (USD)
A3: Entity ID: cawc_0038 | Fiscal year ends December 31.
A5: Part IX line (column A Total) | B5: FY2020 | C5: FY2022 | D5: FY2023
A6: Functional expenses, column A Total - by year
A7: 5. Compensation of current officers, directors, trustees | B7: 392448 | C7: 1083696 | D7: 1101951
A8: 7. Other salaries and wages | B8: 269529 | C8: 330065 | D8: 343759
A9: 8. Pension plan accruals and contributions | B9: 44204 | C9: 15719 | D9: 90732
A10: 9. Other employee benefits | B10: 206732 | C10: 118465 | D10: 117588
A11: 10. Payroll taxes | B11: 81092 | C11: 56512 | D11: 116837
A12: 11b. Fees for services: legal | B12: 35277 | C12: 55396 | D12: 43820
A13: 11c. Fees for services: accounting | B13: 38300 | C13: 115169 | D13: 130353
A14: 11g. Fees for services: other | B14: 55749 | C14: 6000 | D14: 6500
A15: 13. Office expenses | B15: 46036 | C15: 89897 | D15: 65488
A16: 22. Depreciation, depletion, and amortization | B16: 1104199 | C16: 1167182 | D16: 1556793
A17: 24. OPERATIONS AND MAINTENA | B17: 1446621 | C17: 1642519 | D17: 1505021
A18: 24. PROPERTY TAXES | B18: 106176 | C18: 173534 | D18: 123783
A19: 24. INSURANCE | B19: 72047 | C19: 86040 | D19: 123842
A20: 24. STATE REGULATORY FEES | B20: 55895 | C20: not reported | D20: not reported
A21: 24. BUILDING MAINTENANCE AN | B21: not reported | C21: 58611 | D21: 80136
A22: 24e. All other expenses | B22: 87748 | C22: 121391 | D22: 128774
A23: 25. Total functional expenses | B23: =SUM(B7:B22) | C23: =SUM(C7:C22) | D23: =SUM(D7:D22)
A25: Functional column split - FY2023
A26: Not reported. This filer reports only column A (Total) of Part IX; the program / management / fundraising split (columns B-D) is not filed, so it is left as not reported rather than shown empty or inferred.
A27: Top block: each Part IX line, column A (Total), by year, as filed. Total functional expenses (line 25) is a live SUM of the line cells; its tie-out to the filed total is on the Sources & audit tab. Filer-itemized 24a-24d rows show the most recent year's as-filed wording; rows are aligned across years case-insensitively with collapsed spacing, so a line filed only in a different capitalization or spacing shares one row, while genuinely different wording stays a separate row (every as-filed variant is recorded on the Sources & audit tab). This filer reports only column A (Total); the program / management / fundraising split (columns B-D) is not reported. Lines this filer does not report are omitted rather than shown empty.

Sheet Balance sheet (detail)
A1: Riverside Highland Water Company
A2: Balance Sheet - Form 990 Part X (end of year, USD)
A3: Entity ID: cawc_0038 | Fiscal year ends December 31.
A5: Part X line (column B, EOY) | B5: FY2020 | C5: FY2022 | D5: FY2023
A6: Assets
A7: 1. Cash - non-interest-bearing | B7: 500 | C7: 36034 | D7: 133221
A8: 2. Savings and temporary cash investments | B8: 2468882 | C8: 813127 | D8: 198493
A9: 4. Accounts receivable, net | B9: 773398 | C9: 846557 | D9: 806102
A10: 9. Prepaid expenses and deferred charges | B10: 17579 | C10: 29662 | D10: 35774
A11: 10c. Land, buildings, and equipment, net | B11: 20608776 | C11: 40696252 | D11: 40789438
A12: 12. Investments - other securities | B12: 2135586 | C12: 8974701 | D12: 9838004
A13: 14. Intangible assets | B13: 698151 | C13: 735759 | D13: 1270111
A14: 15. Other assets | B14: 439650 | C14: 456867 | D14: 1420097
A15: 16. Total assets | B15: =SUM(B7:B14) | C15: =SUM(C7:C14) | D15: =SUM(D7:D14)
A17: Liabilities
A18: 17. Accounts payable and accrued expenses | B18: 495540 | C18: 578529 | D18: 707786
A19: 25. Other liabilities | B19: 102287 | C19: 1306600 | D19: 2599145
A20: 26. Total liabilities | B20: =SUM(B18:B19) | C20: =SUM(C18:C19) | D20: =SUM(D18:D19)
A22: Net assets / fund balances
A23: 29. Capital stock or trust principal | B23: 190880 | C23: 190260 | D23: 190260
A24: 30. Paid-in or capital surplus | B24: 291553 | C24: 292173 | D24: 292173
A25: 31. Retained earnings / accumulated funds | B25: 26062262 | C25: 50221397 | D25: 50701876
A26: 32. Total net assets / fund balances | B26: =SUM(B23:B25) | C26: =SUM(C23:C25) | D26: =SUM(D23:D25)
A28: Every Part X line is end-of-year (column B), as filed. Section totals (lines 16 / 26 / 32) are live SUMs of the lines above; their tie-outs and the balance-sheet identity (16 = 26 + 32) are on the Sources & audit tab. This filer files as a non-FASB mutual, so net assets sit on lines 29-31 (capital stock / paid-in capital / retained earnings); lines this filer does not report are omitted. Lines 10a/10b net into line 10c (shown).

Sheet Net-assets reconciliation
A1: Riverside Highland Water Company
A2: Reconciliation of Net Assets - Form 990 Part XI (USD)
A3: Entity ID: cawc_0038 | Fiscal year ends December 31.
A5: Part XI line | B5: FY2020 | C5: FY2022 | D5: FY2023
A6: Reconciliation
A7: 4. Net assets, beginning of year | B7: 25544927 | C7: 29853693 | D7: 50703830
A8: 3. Revenue less expenses | B8: 948565 | C8: 21478056 | D8: 418097
A9: 8. Prior period adjustments | B9: not reported | C9: not reported | D9: not reported
A10: 9. Other changes in net assets | B10: 0 | C10: -79621 | D10: -80217
A11: 10. Net assets, end of year | B11: =SUM(B7,B8,B9,B10) | C11: =SUM(C7,C8,C9,C10) | D11: =SUM(D7,D8,D9,D10)
A13: Part XI reconciles beginning to ending net assets. Ending net assets (line 10) is a live formula: beginning balance (line 4) + revenue less expenses (line 3) + prior-period adjustments (8) + other changes (9). Its tie-out to the filed line 10 (and to Part X line 32) is on the Sources & audit tab. Lines 5-7 (unrealized gains, donated services, investment expenses) are not filed by this entity.

Sheet Cash flow proxies
A1: Riverside Highland Water Company
A2: Cash Flow Proxies - derived (USD)
A3: Entity ID: cawc_0038 | Fiscal year ends December 31.
A5: PROXY ONLY. The source filings contain no statement of cash flows. Lines below are derived from the reported income statement and year-over-year balance-sheet changes; treat as directional estimates, not GAAP cash flows. The earliest year has no prior period, so its delta cells are blank.
A7: Proxy line (USD) | B7: FY2020 | C7: FY2022 | D7: FY2023
A8: Operating
A9: Net income | B9: 948565 | C9: 21478056 | D9: 418097
A10: + Depreciation (reported) | B10: 1104199 | C10: 1167182 | D10: 1556793
A11: − Δ Accounts receivable | C11: -73159 | D11: 40455
A12: − Δ Inventories
A13: − Δ Prepaid expenses | C13: -12083 | D13: -6112
A14: + Δ Accounts payable | C14: 82989 | D14: 129257
A15: Operating cash flow proxy | C15: 22642985 | D15: 2138490
A17: Investing
A18: − Δ PP&E gross (capex proxy) | C18: -22409526 | D18: -1730196
A20: Financing
A21: Δ Mortgages & notes payable
A23: Reconciliation
A24: Δ Cash + temp. investments (actual) | C24: -1620221 | D24: -517447
A26: The capex proxy assumes gross PP&E rises only via capital spending (it ignores disposals). 'Δ Cash + temp. investments (actual)' is the real reported change in liquid funds and is the most reliable line here; the operating/investing/financing proxies will not perfectly reconcile to it.

Sheet Ratios
A1: Riverside Highland Water Company
A2: Financial Ratios
A3: Entity ID: cawc_0038 | Fiscal year ends December 31.
A5: Ratio | B5: FY2020 | C5: FY2022 | D5: FY2023
A6: Profitability (computed upstream)
A7: Operating margin (NI / revenue) | B7: 0.19006965 | C7: 0.80749878 | D7: 0.0702274
A8: Expense ratio (expenses / revenue) | B8: 0.80993035 | C8: 0.19250122 | D8: 0.9297726
A9: Return on assets (NI / assets) | B9: 0.034947563 | C9: 0.40841379 | D9: 0.0076727379
A10: Revenue growth (YoY) | B10: 0.25414911 | C10: 1.8573044 | D10: -0.77617048
A12: Leverage & solvency
A13: Debt-to-assets (liab. / assets) | B13: 0.022025477 | C13: 0.035846479 | D13: 0.060687388
A14: Equity ratio (net assets / assets) | B14: 0.97797452 | C14: 0.96415352 | D14: 0.93931261
A16: Liquidity & asset profile (derived here)
A17: Current ratio (current assets / AP) | B17: 6.5794063 | C17: 2.982357 | D17: 1.6581142
A18: Cash ratio ((cash+temp inv.) / total liab.) | B18: 4.1305963 | C18: 0.45045246 | D18: 0.10030872
A19: Asset age proxy (accum. deprec. / gross PP&E) | B19: 0.45130695 | C19: 0.32138168 | D19: 0.33890139
A21: Upstream ratios are read from financials_annual; derived ratios are computed only where inputs are reported. Current ratio uses accounts payable as the current-liability proxy (the filings do not split current vs. long-term liabilities). Asset age proxy: a higher % implies older / more depreciated infrastructure.

Sheet Unit economics
A1: Riverside Highland Water Company
A2: Unit economics - per-customer revenue by category (USD)
A3: Entity ID: cawc_0038 | Fiscal year ends December 31.
A5: Every metric here is PER CUSTOMER (a metered service connection). It is not a per-member figure; the member (shareholder) count is a different denominator, shown in the denominator block. The visible cell shows the value and its classification; the numerator, denominator, formula, and rationale are in each metric's LOGIC popup.
A6: Per-customer denominator (service connections) | B6: 6217 | C6: State Water Board eAR Section 4 (CurTotalConnections), reporting year 2024
A7: Total annual revenue (eAR Section 8b B1.8) | B7: 5302355 | C7: State Water Board eAR Section 8b, question B1.8 (total annual revenue), reporting year 2024
A8: Primary source | C8: State Water Board eAR Section 8b (revenue by rate/fee), reporting year 2024
A10: Revenue categories (value, classification, per customer, share)
A11: Revenue category | B11: Classification | C11: Value (USD) | D11: Per customer | E11: Share of revenue
A12: Water sales revenue | B12: DIRECT | C12: 4192853 | D12: 674.42 | E12: 0.7908
A13: Assessment revenue (990 program-service revenue not matched to eAR water-rate revenue) | B13: IMPOSSIBLE | C13: IMPOSSIBLE | D13: IMPOSSIBLE | E13: IMPOSSIBLE
A14: Meter revenue | B14: not reported | C14: not reported | D14: not reported | E14: not reported
A15: Overage or tiered penalty revenue | B15: not reported | C15: not reported | D15: not reported | E15: not reported
A17: Water sales revenue - DIRECT
A18: Revenue customers paid for water service, read straight off the filed eAR Section 8b water-rate line. A DIRECT filed figure, not computed by us.
A19: Numerator: Water rate revenue | B19: 4192853 | C19: eAR Section 8b field B1.1 (residential water rates) + B1.2 (non-residential water rates). State Water Board eAR Section 8b, question B1.1 + B1.2 (revenue from water rates), reporting year 2024
A20: Denominator: Total service connections | B20: 6217 | C20: eAR Section 4 CurTotalConnections, reporting year 2024. State Water Board eAR Section 4 (CurTotalConnections), reporting year 2024
A21: Per customer: water rate revenue $4,192,853 / 6,217 connections = $674.42 per connection
A22: Share of revenue: water rate revenue $4,192,853 / total annual revenue (eAR Section 8b B1.8) $5,302,355 = 79.08%
A23: Period treatment: Numerator (eAR Section 8b, the calendar year 2024) and denominator (eAR Section 4 connections reported in the same eAR filing) are both the eAR reporting year 2024, so the two sides are bound to the same reporting year.
A24: Rationale: Dividing water-rate revenue by the number of metered service connections gives the average revenue per customer; dividing by total annual revenue shows how much of the system's income comes from water rates.
A26: Assessment revenue (990 program-service revenue not matched to eAR water-rate revenue) - IMPOSSIBLE
A27: Not computed. A period-aligned residual is not possible for this filer.
A28: Reason: Not derivable. The eAR Section 8b is the calendar year 2024 while the Form 990 fiscal year ends None; the two period ends are not aligned, so a period-aligned residual cannot be computed.
A30: Meter revenue - not reported
A31: Not reported. This category is not built because doing so would double-count.
A32: Reason: The eAR Section 8a reports a base/meter rate PRICE, but the filing carries no meter revenue line and no tier volume, and the base charge is already inside the water-sales revenue (eAR Section 8b water rates). Building a separate meter figure would double-count. Not backed into from a total.
A34: Overage or tiered penalty revenue - not reported
A35: Not reported. This category is not built because doing so would double-count.
A36: Reason: The eAR Section 8a reports tiered/overage rate PRICES, but the filing carries no overage revenue and no tier consumption volume, and any overage billed is already inside the water-sales revenue. Building it would double-count. Not backed into from a total.

Sheet Rate structure
A1: Riverside Highland Water Company
A2: Rate structure and representative bill - eAR Section 8a (RY2024)
A3: Entity ID: cawc_0038 | Fiscal year ends December 31.
A5: This block is a rate-schedule illustration at defined usage levels. It is NOT billed revenue and not a claim about any real customer's usage. The revenue side of unit economics is the separate Unit Economics block.
A6: Structure: Tiered increasing-block with a fixed base, billed bimonthly, priced per HCF.
A7: Defined single-family usage levels, identical for every company so the bill is comparable: Low = 5 HCF/month (~125 gallons/day); Median = 10 HCF/month (~249 gallons/day); High = 25 HCF/month (~623 gallons/day). 1 HCF = 748 gallons, and 1 thousand gallons = 1,000 gallons. The usage is converted into the company's own filed unit before the filed tiers are applied, and the bill is stated as a monthly equivalent: a bimonthly structure is computed at twice the monthly usage and divided by two, and any other billing period the same way with its factor stated. These are an illustration, not a measured usage for any real customer.
A9: Defined usage levels (EDITABLE - change a yellow cell to move the bill)
B10: Low | C10: Median | D10: High
A11: Monthly usage (HCF) | B11: 5 | C11: 10 | D11: 25
A12: Months per bill (from filed billing frequency) | B12: 2 | C12: bimonthly biller
A14: Filed rate table - single-family residential (as filed, eAR Section 8a)
A15: Base / fixed charge per bimonthly bill ($) | B15: 1.16
A16: Tier | B16: Range (HCF) | C16: Price ($/HCF) | D16: Upper limit (HCF)
A17: Tier 1 | B17: 0 to 30 HCF | C17: 1.16 | D17: 30
A18: Tier 2 | B18: 30 to 70 HCF | C18: 1.51 | D18: 70
A19: Tier 3 | B19: 70 to 100 HCF | C19: 1.78 | D19: 100
A20: Tier 4 | B20: 100 to 1e+10 HCF | C20: 2.05 | D20: 9999999999
A22: Flags on the filed rate table (nothing below is corrected)
A23: Fixed charge: implausible as filed; checked against source. The filed base charge of $1.16 per bill is $0.58 per month, outside the $5.00 to $500.00 per month range a residential fixed charge plausibly takes. A filed $0.00 can simply mean the company charges no fixed charge. Carried exactly as filed and not corrected. Source: State Water Board eAR Section 8 / WRSFCostPerUOM1
A25: Representative monthly bill - LIVE (edit a yellow usage cell to recompute)
B26: Low | C26: Median | D26: High
A27: Usage per bill (HCF) | B27: =B11*$B$12 | C27: =C11*$B$12 | D27: =D11*$B$12
A28: Tier 1 charge per bill ($) | B28: =$C$17*MAX(0,MIN(B27,$D$17)-0) | C28: =$C$17*MAX(0,MIN(C27,$D$17)-0) | D28: =$C$17*MAX(0,MIN(D27,$D$17)-0)
A29: Tier 2 charge per bill ($) | B29: =$C$18*MAX(0,MIN(B27,$D$18)-$D$17) | C29: =$C$18*MAX(0,MIN(C27,$D$18)-$D$17) | D29: =$C$18*MAX(0,MIN(D27,$D$18)-$D$17)
A30: Tier 3 charge per bill ($) | B30: =$C$19*MAX(0,MIN(B27,$D$19)-$D$18) | C30: =$C$19*MAX(0,MIN(C27,$D$19)-$D$18) | D30: =$C$19*MAX(0,MIN(D27,$D$19)-$D$18)
A31: Tier 4 charge per bill ($) | B31: =$C$20*MAX(0,MIN(B27,$D$20)-$D$19) | C31: =$C$20*MAX(0,MIN(C27,$D$20)-$D$19) | D31: =$C$20*MAX(0,MIN(D27,$D$20)-$D$19)
A32: Volumetric charge per bill ($) | B32: =SUM(B28,B29,B30,B31) | C32: =SUM(C28,C29,C30,C31) | D32: =SUM(D28,D29,D30,D31)
A33: Base charge per bill ($) | B33: =$B$15 | C33: =$B$15 | D33: =$B$15
A34: Total per bill ($) | B34: =B33+B32 | C34: =C33+C32 | D34: =D33+D32
A35: Total per MONTH ($) | B35: =B34/$B$12 | C35: =C34/$B$12 | D35: =D34/$B$12
A36: Fixed per month ($) | B36: =$B$15/$B$12 | C36: =$B$15/$B$12 | D36: =$B$15/$B$12
A37: Volumetric per month ($) | B37: =B32/$B$12 | C37: =C32/$B$12 | D37: =D32/$B$12
A38: Effective price ($/HCF) | B38: =IF(B11=0,"",B35/B11) | C38: =IF(C11=0,"",C35/C11) | D38: =IF(D11=0,"",D35/D11)
A40: Rate-structure comparison metrics
A41: Fixed share of the bill at median usage | B41: =C36/C35 | C41: fixed / total at 10 HCF/month
A42: Tier price ratio (highest to lowest positive tier) | B42: =$C$20/$C$17 | C42: highest filed tier price divided by lowest filed tier price.
A43: Rate structure (as filed) | B43: tiered (Variable Usage)
A45: Flagged (carried as filed, never reconciled)
A46: The single-family base charge or tier thresholds filed for RY2024 differ from RY2023, yet the eAR answer to whether rates changed is "No". Carried exactly as filed; both years are preserved and the difference is surfaced, never reconciled.
A47: RY2023: base $1.16, tier upper thresholds [4000.0, 7000.0, 11000.0, 110001.0]. RY2024: base $1.16, tier upper thresholds [30.0, 70.0, 100.0, 9999999999.0].
...

Sheet eAR revenue & expenses
A1: Riverside Highland Water Company
A2: eAR annual revenue and expenses - State Water Board eAR Section 8b (USD)
A3: Entity ID: cawc_0038 | Fiscal year ends December 31.
A5: The water system's own annual figures from the public eAR Section 8b, on the calendar year 2024 the filer self-reported (B0.1/B0.2). Shown beside the period-aligned Form 990 with the variance flagged: a different source (a State Water Board self-report vs an IRS filing). Preserved as filed, never reconciled.
A6: Reporting period basis (self-reported) | B6: calendar year 2024 | C6: eAR Section 8b B0.1 (WRFinancialReportingPeriod)
A8: Revenue (eAR Section 8b, questions B1.x)
A9: Line | B9: Amount (USD) | C9: Citation
A10: Water rate revenue | B10: 4192853 | C10: State Water Board eAR Section 8b, question B1.1 + B1.2 (revenue from water rates), reporting year 2024
A11: Other fees and charges | B11: 1109502 | C11: State Water Board eAR Section 8b, question B1.3 + B1.4 (revenue from other fees), reporting year 2024
A12: Non-customer revenue | B12: 0 | C12: State Water Board eAR Section 8b, question B1.7 (grants, interest, and other non-customer), reporting year 2024
A13: Total annual revenue | B13: 5302355 | C13: State Water Board eAR Section 8b, question B1.8 (total annual revenue for the reporting year), reporting year 2024
A15: Expenses (eAR Section 8b, questions B2.x)
A16: Line | B16: Amount (USD) | C16: Citation
A17: Operations and maintenance | B17: 3789594 | C17: State Water Board eAR Section 8b, question B2.1 (annual O and M expense), reporting year 2024
A18: Capital | B18: 1906325 | C18: State Water Board eAR Section 8b, question B2.2 (annual expenses from investing or capital), reporting year 2024
A19: Financing | B19: 0 | C19: State Water Board eAR Section 8b, question B2.3 (annual expenses from financing), reporting year 2024
A20: Other | B20: 0 | C20: State Water Board eAR Section 8b, question B2.4 (total other annual expenses), reporting year 2024
A21: Total annual expenses | B21: 5695919 | C21: State Water Board eAR Section 8b, question B2.5 (total annual expenses), reporting year 2024
A23: Period-aligned Form 990 comparison (variance surfaced, never reconciled)
A24: Measure | B24: eAR Section 8b | C24: Form 990
A25: total revenue | B25: 5302355
A26: Variance (eAR minus Form 990) | B26: =B25-C25
A27: The eAR Section 8b total revenue (State Water Board self-report, calendar year 2024) and the Form 990 total revenue (IRS filing) are a different source and cover a different period (the eAR Section 8b covers the calendar year 2024; the nearest Form 990 fiscal year ends None). Both are carried as filed; the variance is surfaced, never reconciled.
A28: total expenses | B28: 5695919
A29: Variance (eAR minus Form 990) | B29: =B28-C28
A30: The eAR Section 8b total expenses (State Water Board self-report, calendar year 2024) and the Form 990 total expenses (IRS filing) are a different source and cover a different period (the eAR Section 8b covers the calendar year 2024; the nearest Form 990 fiscal year ends None). Both are carried as filed; the variance is surfaced, never reconciled.

Sheet Denominators & alignment
A1: Riverside Highland Water Company
A2: Denominators and calendar alignment
A3: Entity ID: cawc_0038 | Fiscal year ends December 31.
A5: System size and water use per fiscal year (the operating denominators that per-customer and per-acre metrics divide by), each cited to file and field. The eAR is reported on the calendar year; the 990 fiscal year differs by company. A calendar-year filer's volume is the eAR annual total (fiscal year = calendar year); an offset filer's is recast by a true monthly sum of the covered calendar months, or read not reported naming the missing months. Point-in-time counts (connections, population) are matched to the closest eAR year and never summed. Every derived figure states its formula and accounting rationale.
A6: Member vs customer (two different denominators, both preserved)
A7: Customer (service connection) | B7: 5943 | C7: State Water Board eAR Section 4 (CurTotalConnections), reporting year 2023
A8: Member (shareholder) | C8: No published shareholder count
A9: In a mutual water company a MEMBER is a shareholder who owns part of the system; a CUSTOMER is a metered service connection that receives water. The two diverge because one owner can hold several connections, a connection can serve people who are not owners, and some mutuals attach shares to land by acreage rather than counting heads. Per-customer metrics divide by service connections; per-member metrics divide by shareholders; the two counts are never used interchangeably.
A11: Denominator layer by fiscal year
A12: Fiscal year (end) | B12: Connections | C12: Population | D12: Service-area acres | E12: Water produced (AF) | F12: Water delivered (AF) | G12: Alignment method
A13: FY2019 (2019-12-31) | B13: 5335 | C13: not reported | D13: 5430.7 | E13: not reported | F13: not reported | G13: eAR annual total, calendar filer, equals fiscal year (not a monthly recast)
A14: FY2020 (2020-12-31) | B14: 5335 | C14: not reported | D14: 5430.7 | E14: not reported | F14: not reported | G14: eAR annual total, calendar filer, equals fiscal year (not a monthly recast)
A15: FY2021 (2021-12-31) | B15: 5656 | C15: not reported | D15: 5430.7 | E15: not reported | F15: not reported | G15: eAR annual total, calendar filer, equals fiscal year (not a monthly recast)
A16: FY2022 (2022-12-31) | B16: 5943 | C16: not reported | D16: 5430.7 | E16: not reported | F16: not reported | G16: eAR annual total, calendar filer, equals fiscal year (not a monthly recast)
A17: FY2023 (2023-12-31) | B17: 5943 | C17: 19503 | D17: 5430.7 | E17: not reported | F17: not reported | G17: eAR annual total, calendar filer, equals fiscal year (not a monthly recast)
A19: Connections by class - FY2023 (eAR Section 4)
A20: Single-family residential | B20: 5899
A21: Multi-family residential | B21: 71
A22: Commercial and institutional | B22: 83
A23: Industrial | B23: 3
A24: Landscape irrigation | B24: 159
A25: Agricultural | B25: 2
A26: Monthly-volume source: California open-data portal (data.ca.gov): the separate Produced Water (by month and source) and Delivered Water (by month and connection type) resources, which cover every public water system (not only urban suppliers), one resource per reporting year, matched by exact PWSID. This is the aggregate publication of eAR Section 6.

Sheet Governance evidence
A1: Riverside Highland Water Company
A2: Governance evidence status - Ostrom's eight design principles
A3: Entity ID: cawc_0038 | Fiscal year ends December 31.
A5: Evidence summary: 4 documented, 2 partial, 2 not documented of eight principles.
A6: A count of how many of Elinor Ostrom's eight design principles have a supporting record on file, not a grade. NOT DOCUMENTED means the supporting record was not found, not that the company governs badly. It marks a gap in the documentary record, an evidence gap to close, never a governance failing.
A7: Each mutual is read against Elinor Ostrom's eight design principles for institutions that govern a shared resource durably. Per principle: a one-line finding, the observable signal, a citation, and an evidence status stating whether the supporting record exists: DOCUMENTED (a cited record supports alignment), PARTIAL (some evidence exists but it is incomplete), or NOT DOCUMENTED (no supporting record was found). This is an evidence-status read, not a grade: the principles are never ranked, weighted, or given a letter, consistent with reporting as filed and not grading companies. NOT DOCUMENTED means the supporting record was not found, not that the company governs badly. It marks a gap in the documentary record, an evidence gap to close, never a governance failing.
A9: Principle | B9: Evidence status | C9: Finding | D9: Signal | E9: Citation
A10: Clearly defined boundaries | B10: DOCUMENTED | C10: The system is a defined public water system: 6,217 service connections over a State-published and field-verified service-area boundary of roughly 5,418.6 acres. | D10: SDWIS Community water system; SABL service-area boundary (Verified); connections defined. | E10: [C][G]
A11: What the record shows: SDWIS defines the membership as a fixed set of service connections and the State Water Board publishes a SABL service-area polygon for it, so who is inside and outside the system is documented. The boundary is FIELD-VERIFIED by the Water Board rather than merely carried.
A12: Rules fit local conditions | B12: DOCUMENTED | C12: Charges are tied to metered use under a filed rate schedule: a variable usage residential structure billed bm and priced per hundred cubic feet. | D12: eAR Section 8a customer charges; metered service; Variable Usage residential rate structure. | E12: [E]
A13: What the record shows: The record documents how charges are set: the filer reports metered service, a billing frequency, a residential rate structure and a filed rate schedule, so cost tracks service. Whether every tier scales precisely with use is not visible in the filing and is not claimed here.
A14: Collective-choice arrangements | B14: PARTIAL | C14: The company is owned by its customer-shareholders, but the specific board, the election procedure and any record of member votes are not in a source this project holds. | D14: Mutual ownership; Form 990 governance section. | E14: [990]
A15: What the record shows: A collective-choice mechanism is documented in outline: the customers are the shareholders. It stays PARTIAL rather than met because the filed corporate record that would carry the director roster and the election procedure is NOT YET CHECKED for this company, the California Secretary of State being reachable only through a browser session that now answers a CAPTCHA. A stated board is not a filed roster.
A16: Monitoring | B16: DOCUMENTED | C16: The system is monitored and reports on itself: it files an annual eAR, and it reports metered service, and a Consumer Confidence Report for 2024 was located at the State's own CCR portal. | D16: Annual eAR reporting; metered connections; located Consumer Confidence Report | E16: [E][CCR]
A17: What the record shows: Operational monitoring is documented from more than one filing. What the federal violation check found is reported separately in the On the record block and is not folded into this tier.
A18: Graduated sanctions | B18: NOT DOCUMENTED | C18: No published shut-off, penalty, or delinquency policy was found for this system. | D18: No sourced graduated sanctions record. | E18: not reported
A19: What the record shows: No public record of a shut-off, penalty, or delinquency policy was located. NOT DOCUMENTED means the supporting record was not found, not that the company governs badly. It marks a gap in the documentary record, an evidence gap to close, never a governance failing.
A20: Conflict-resolution mechanisms | B20: NOT DOCUMENTED | C20: No published bylaws, dispute procedure, or grievance mechanism was found for this system. | D20: No sourced conflict-resolution mechanisms record. | E20: not reported
A21: What the record shows: No public record of a bylaws, dispute procedure, or grievance mechanism was located. NOT DOCUMENTED means the supporting record was not found, not that the company governs badly. It marks a gap in the documentary record, an evidence gap to close, never a governance failing.
A22: Recognized right to organize | B22: DOCUMENTED | C22: An incorporated California mutual water company recognized by the IRS as a 501(c)(12) exempt filer and by the State Water Board as a Community public water system. | D22: IRS 501(c)(12) exempt filer (Form 990); SDWIS Community public water system; eAR ownership type 'Privately owned Mutual Water Company or Association'. | E22: [990][C][E]
A23: What the record shows: Baseline legal standing is documented by two independent regulators: the IRS accepts it as a tax-exempt 501(c)(12) filer and the State Water Board holds it as a Community public water system with a mutual ownership type. This status does NOT rest on a filed corporate record, because the Secretary of State check has not been run for this company.
A24: Nested enterprises | B24: PARTIAL | C24: The system sits inside larger water systems: it pumps from 2 groundwater basin(s) shared with neighbors, and it holds 4 approved emergency intertie(s) with other systems, and it holds 14 State-recorded surface water right(s) on a shared river system. Its role in governing any of them is not documented. | D24: it pumps from 2 groundwater basin(s) shared with neighbors; it holds 4 approved emergency intertie(s) with other systems; it holds 14 State-recorded surface water right(s) on a shared river system | E24: [SG][E][WR]
A25: What the record shows: Physical nesting is documented. What is not documented is any governance role in a wholesaler or in a groundwater sustainability agency, so the tier is PARTIAL rather than met.

Sheet Operational metrics
A1: Riverside Highland Water Company
A2: Operational metrics - plant per acre, density, terrain
A3: Entity ID: cawc_0038 | Fiscal year ends December 31.
A5: Plant assets per acre
A6: Service-area acres | B6: 5430.7 | C6: Geodesic area (WGS84 spherical excess) of the SABL service-area polygon.
A7: Fiscal year | B7: Gross plant per acre (primary) | C7: Net plant per acre
A8: FY2019
A9: FY2020 | B9: 6916.1902 | C9: 3794.8655
A10: FY2021
A11: FY2022 | B11: 11042.643 | C11: 7493.7397
A12: FY2023 | B12: 11361.238 | C12: 7510.8988
A13: Infrastructure built per acre of service area. Gross plant per acre is the primary read because it measures how much plant the system has put in the ground per acre, and unlike net plant it does not fall over time purely because the assets depreciate on the books. Net plant per acre is shown alongside as the depreciated book value per acre.
A14: Formula: gross plant per acre = Form 990 Part X line 10a (land, buildings, and equipment, gross) / SABL service-area acres; net plant per acre uses Part X line 10c (net)
A15: Source lines: Form 990 Part X line 10a (gross) and line 10c (net); Geodesic area (WGS84 spherical excess) of the SABL service-area polygon.
A16: Confidence: medium. This is worked out from filed figures (a ratio, or a year-to-year change), so it is one step removed from the raw numbers.. Filed gross/net plant over the measured SABL service-area acreage.
A18: Connections per acre
A19: Connections per acre | B19: 1.24 | C19: 6,748 connections / 5,430.7 acres. CA State Water Board SABL SERVICE_CONNECTIONS; Geodesic area (WGS84 spherical excess) of the SABL service-area polygon.

Sheet Supply & weather
A1: Riverside Highland Water Company
A2: Supply and weather indicators (DWR water year)
A3: Entity ID: cawc_0038 | Fiscal year ends December 31.
A5: Reporting calendar: Different reporting periods. The DWR water year runs October 1 to September 30; this system's fiscal year ends December 31, so the two period ends are three months apart. Read the two side by side with that in mind. Neither series is recast: both are reported as filed. A water year is named for the calendar year it ends in, so WY2024 and FY2024 share a number without covering the same twelve months.
A7: Indicator | B7: WY2020 | C7: WY2021 | D7: WY2022 | E7: WY2023
A8: Water-year type (Sacramento Valley) | B8: Dry | C8: Critical | D8: Critical | E8: Wet
A9: Peak drought, San Bernardino County | B9: D2 | C9: D4 | D9: D4 | E9: D4
A10: Precip, percent of normal (8-Station Index) | B10: 63 | C10: 48 | D10: 86 | E10: 133
A11: Snowpack, April 1 percent of average | B11: 53% | C11: 59% | D11: 38% | E11: 237%
A12: State Water Project allocation | B12: 20% | C12: 5% | D12: 5% | E12: 100%

Sheet How this was built
A1: Riverside Highland Water Company
A2: How this was built - forensic lineage
A3: Entity ID: cawc_0038 | Fiscal year ends December 31.
A5: A plain account of the forensic lineage behind the hard-to-source metrics: what sources were checked, what was found, what was derived, and what could not be built and why. Every figure marked DERIVED or IMPOSSIBLE above is traceable to a line here.
A7: Water-sales revenue per customer - DIRECT
A8: Sources checked | B8: State Water Board eAR Section 8b (water-rate revenue B1.1/B1.2); State Water Board eAR Section 4 (connection count, same reporting year); audited financial statement (secondary cross-check, where published)
A9: What was found | B9: The eAR Section 8b reports water-rate revenue for reporting year 2024, so this is a DIRECT filed figure; per customer it is divided by the eAR Section 4 connection count for the same reporting year, so numerator and denominator share the year.
A11: Assessment revenue (residual) - IMPOSSIBLE
A12: Sources checked | B12: Form 990 Part VIII line 2 (program-service revenue); State Water Board eAR Section 8b (water-rate revenue B1.1/B1.2); eAR Section 8b filer comment (WRRevenueComments)
A13: What was found | B13: A period-aligned residual cannot be computed for this filer, so the metric is rendered IMPOSSIBLE rather than guessed.
A14: Caveat | B14: Not derivable. The eAR Section 8b is the calendar year 2024 while the Form 990 fiscal year ends None; the two period ends are not aligned, so a period-aligned residual cannot be computed.
A16: Meter revenue - not reported
A17: Sources checked | B17: State Water Board eAR Section 8a (rate prices); State Water Board eAR Section 8b (revenue lines); audited financial statement
A18: What was found | B18: The rate price exists in Section 8a but no revenue or tier volume is reported, and the base charge is already inside water sales.
A19: Caveat | B19: The eAR Section 8a reports a base/meter rate PRICE, but the filing carries no meter revenue line and no tier volume, and the base charge is already inside the water-sales revenue (eAR Section 8b water rates). Building a separate meter figure would double-count. Not backed into from a total.
A21: Overage / tiered-penalty revenue - not reported
A22: Sources checked | B22: State Water Board eAR Section 8a (rate prices); State Water Board eAR Section 8b (revenue lines); audited financial statement
A23: What was found | B23: The rate price exists in Section 8a but no revenue or tier volume is reported, and the base charge is already inside water sales.
A24: Caveat | B24: The eAR Section 8a reports tiered/overage rate PRICES, but the filing carries no overage revenue and no tier consumption volume, and any overage billed is already inside the water-sales revenue. Building it would double-count. Not backed into from a total.
A26: eAR Section 8b reporting-period basis - sourced
A27: Sources checked | B27: eAR Section 8b B0.1 (WRFinancialReportingPeriod); eAR Section 8b B0.2 (WRFiscalYearStartDate)
A28: What was found | B28: The reporting basis (fiscal vs calendar year) is read from the filer's own B0.1/B0.2 answer and staged verbatim, never hardcoded, so the 990 comparison and the residual are period-aligned.
A30: Member (shareholder) count denominator - not reported
A31: Sources checked | B31: Form 990 (no member count stated); company website
A32: What was found | B32: No filing states a member/shareholder count, so the per-member unit economics read not reported rather than borrowing the connection count.
A34: Water volume delivered (acre-feet) - not reported
A35: Sources checked | B35: Form 990 (not in the filing); Consumer Confidence Report; eAR Section 6 (PRA-gated)
A36: What was found | B36: Volume delivered in acre-feet is not in the Form 990 and the CCR states only a source mix, so the per-acre-foot metrics read not reported; the eAR Section 6 is named as the source still needed.

Sheet Anomaly Flags
A1: Riverside Highland Water Company
A2: Anomaly Flags (automated; kept separate from the clean statements)
A3: Entity ID: cawc_0038 | Fiscal year ends December 31.
A5: Material irregularities found automatically in the filed financials by the Hydronomics anomaly flagger. Each flag has two clearly separated layers. WHAT is mechanical, certain, and sourced: the exact filed lines, years, and amounts, carried as filed and never reconciled. WHY is attempted: the filing's own narrative is checked first, and when it states no reason a single best-guess hypothesis is shown, clearly labelled as a guess that is not in the filing and is not a verified figure.
A7: Flag: FY2023 total revenue swing
A8: Affected figure | B8: Operating revenue FY2023
A9: Confidence | B9: high
A10: What happened (filed, sourced) | B10: FY2023 total revenue fell to $5,953,474 from $26,598,252 in FY2022, a 78 percent move ($20,644,778 in absolute terms). Carried as filed and flagged as a documented anomaly, not smoothed.
A11: Source lines | B11: - total revenue: $26,598,252 FY2022, $5,953,474 FY2023
A12: Confidence reasoning | B12: A year-over-year move in a filed headline total that exceeds both the percentage and the dollar threshold; carried as filed.
A13: Why (not stated in the filing) | B13: The filing does not state a reason.
A14: Possible explanation (guess) | B14: Possible explanation, not stated in filing: a large one-year move in total revenue may reflect a one-time item or a change in how it was recorded. This is an educated guess, not something the filing actually says.

Sheet Sources & audit
A1: Riverside Highland Water Company
A2: Sources & audit - full provenance and tie-outs (kept off the statements so they read clean)
A3: Entity ID: cawc_0038 | Fiscal year ends December 31.
A5: Presentation standard: every figure on the statement tabs is verified to its source filing and shown clean. A cell the filing does not report reads "not reported" (never estimated, never guessed).
A6: Citations, confidence tiers, and the filed-vs-computed tie-out checks live on the "Sources & audit" tab, keyed by cell, so every number is fully traceable without cluttering the statements. These pages are ready to use as filed.
A8: A. Filing provenance (one row per staged extraction)
A9: Fiscal year | B9: Period end | C9: Filing type | D9: Confidence | E9: Extraction ID | F9: Object ID | G9: Extracted by | H9: Extracted at | I9: Source URL
A10: FY2020 | B10: 2020-12-31 | C10: 990 | D10: high | E10: fdb4f3b8-44e6-4efb-8e75-f3b9bf287b8c | F10: 202123149349304172 | G10: claude-opus-5 | H10: 2026-09-14T20:40:25+00:00 | I10: https://apps.irs.gov/pub/epostcard/990/xml/2021/2021_TEOS_XML_01A.zip#202123149349304172_public.xml
A11: FY2022 | B11: 2022-12-31 | C11: 990 | D11: high | E11: 3aa9634c-cfc5-47fc-ac08-75445bc30fc3 | F11: 202312899349301546 | G11: claude-opus-5 | H11: 2026-09-14T20:40:25+00:00 | I11: https://apps.irs.gov/pub/epostcard/990/xml/2023/2023_TEOS_XML_10A.zip#202312899349301546_public.xml
A12: FY2023 | B12: 2023-12-31 | C12: 990 | D12: high | E12: 1453a43b-b3a0-458e-8e8f-a5a7af24c210 | F12: 202442899349302634 | G12: claude-opus-5 | H12: 2026-09-14T20:40:25+00:00 | I12: https://apps.irs.gov/pub/epostcard/990/xml/2024/2024_TEOS_XML_10A.zip#202442899349302634_public.xml
A14: B. Figure citations (every figure on the statement tabs, keyed by cell)
A15: Tab | B15: Cell | C15: Line item | D15: Form 990 line | E15: Key path | F15: Confidence | G15: As filed
A16: Financial Statements | B16: B73 | C16: 11a. Gross income from members or shareholders | D16: 11a | E16: part_v_other_irs_filings.members_and_shareholders_gross_income | F16: high | G16: 4574318
A17: Financial Statements | B17: C73 | C17: 11a. Gross income from members or shareholders | D17: 11a | E17: part_v_other_irs_filings.members_and_shareholders_gross_income | F17: high | G17: 26118170
A18: Financial Statements | B18: D73 | C18: 11a. Gross income from members or shareholders | D18: 11a | E18: part_v_other_irs_filings.members_and_shareholders_gross_income | F18: high | G18: 5628735
A19: Financial Statements | B19: B74 | C19: 11b. Gross income from other sources | D19: 11b | E19: part_v_other_irs_filings.other_sources_gross_income | F19: high | G19: 416300
A20: Financial Statements | B20: C74 | C20: 11b. Gross income from other sources | D20: 11b | E20: part_v_other_irs_filings.other_sources_gross_income | F20: high | G20: 282445
A21: Financial Statements | B21: D74 | C21: 11b. Gross income from other sources | D21: 11b | E21: part_v_other_irs_filings.other_sources_gross_income | F21: high | G21: 324739
A22: Revenue (detail) | B22: B8 | C22: 2g. Total program service revenue | D22: 2g | E22: part_viii_revenue.total_program_service_revenue | F22: high | G22: 4444005
A23: Revenue (detail) | B23: C8 | C23: 2g. Total program service revenue | D23: 2g | E23: part_viii_revenue.total_program_service_revenue | F23: high | G23: 5514562
A24: Revenue (detail) | B24: D8 | C24: 2g. Total program service revenue | D24: 2g | E24: part_viii_revenue.total_program_service_revenue | F24: high | G24: 5292585
A25: Revenue (detail) | B25: B9 | C25: 3. Investment income | D25: 3 | E25: part_viii_revenue.investment_income | F25: high | G25: 85370
A26: Revenue (detail) | B26: C9 | C26: 3. Investment income | D26: 3 | E26: part_viii_revenue.investment_income | F26: high | G26: 248778
A27: Revenue (detail) | B27: D9 | C27: 3. Investment income | D27: 3 | E27: part_viii_revenue.investment_income | F27: high | G27: 320814
... A114: Net-assets reconciliation | B114: D10 | C114: 9. Other changes in net assets | D114: Part XI line 9 | E114: part_xi_reconciliation.other_changes_net_assets | F114: high | G114: -80217
A116: C. Tie-out checks (filed vs computed; any nonzero variance is flagged red)
A117: Tab | B117: Check | C117: Fiscal year | D117: Filed | E117: Computed | F117: Variance (computed - filed)
A118: Revenue (detail) | B118: 12. Total revenue | C118: FY2020 | D118: 4990618 | E118: ='Revenue (detail)'!B13 | F118: =E118-D118
A119: Revenue (detail) | B119: 12. Total revenue | C119: FY2022 | D119: 26598252 | E119: ='Revenue (detail)'!C13 | F119: =E119-D119
A120: Revenue (detail) | B120: 12. Total revenue | C120: FY2023 | D120: 5953474 | E120: ='Revenue (detail)'!D13 | F120: =E120-D120
A121: Revenue (detail) | B121: 2g program service revenue = sum of lines 2a-2f (FY2023) | C121: FY2023 | D121: 5292585 | E121: =SUM('Revenue (detail)'!C17:C19) | F121: =E121-D121
A122: Operating expenses (detail) | B122: 25. Total functional expenses | C122: FY2020 | D122: 4042053 | E122: ='Operating expenses (detail)'!B23 | F122: =E122-D122
A123: Operating expenses (detail) | B123: 25. Total functional expenses | C123: FY2022 | D123: 5120196 | E123: ='Operating expenses (detail)'!C23 | F123: =E123-D123
A124: Operating expenses (detail) | B124: 25. Total functional expenses | C124: FY2023 | D124: 5535377 | E124: ='Operating expenses (detail)'!D23 | F124: =E124-D124
A125: Balance sheet (detail) | B125: 16. Total assets | C125: FY2020 | D125: 27142522 | E125: ='Balance sheet (detail)'!B15 | F125: =E125-D125
A126: Balance sheet (detail) | B126: 16. Total assets | C126: FY2022 | D126: 52588959 | E126: ='Balance sheet (detail)'!C15 | F126: =E126-D126
A127: Balance sheet (detail) | B127: 16. Total assets | C127: FY2023 | D127: 54491240 | E127: ='Balance sheet (detail)'!D15 | F127: =E127-D127
A128: Balance sheet (detail) | B128: 26. Total liabilities | C128: FY2020 | D128: 597827 | E128: ='Balance sheet (detail)'!B20 | F128: =E128-D128
A129: Balance sheet (detail) | B129: 26. Total liabilities | C129: FY2022 | D129: 1885129 | E129: ='Balance sheet (detail)'!C20 | F129: =E129-D129
A130: Balance sheet (detail) | B130: 26. Total liabilities | C130: FY2023 | D130: 3306931 | E130: ='Balance sheet (detail)'!D20 | F130: =E130-D130
...

Sheet Provenance
A1: Build provenance | B1: Built from source commit d418ffb17485 (2026-10-06); source fingerprint a75a8eee82c65cf7; 192 companies (179 retail mutual, 4 irrigation mutual, 3 mutual, no PWSID, purpose not stated, 2 frozen non-mutual (special district), 2 wholesale mutual, 1 frozen non-mutual (investor-owned), 1 frozen non-mutual (municipal)); 91 gates; build id 3d08d6d2a855.
A2: source_commit | B2: d418ffb174855ab78000d391d42f898397b0d8aa
A3: source_commit_date | B3: 2026-10-06
A4: source_fingerprint | B4: a75a8eee82c65cf7096931f06e18affdc28686a02895b46538e7298b57c04d94
A5: gate_count | B5: 91
A6: build_id | B6: 3d08d6d2a855
A7: registry: frozen non-mutual (investor-owned) | B7: 1
A8: registry: frozen non-mutual (municipal) | B8: 1
A9: registry: frozen non-mutual (special district) | B9: 2
A10: registry: irrigation mutual | B10: 4
A11: registry: mutual, no PWSID, purpose not stated | B11: 3
A12: registry: retail mutual | B12: 179
A13: registry: wholesale mutual | B13: 2
