Workbook

Sheet Summary
A1: Painted Cave Mutual Water Company
A2: Financial Summary - multi-year overview (USD)
A3: Entity ID: cawc_0022 | Fiscal year ends March 31.
A5: Presentation standard: every figure on the statement tabs is verified to its source filing and shown clean. A cell the filing does not report reads "not reported" (never estimated, never guessed).
A6: Citations, confidence tiers, and the filed-vs-computed tie-out checks live on the "Sources & audit" tab, keyed by cell, so every number is fully traceable without cluttering the statements. These pages are ready to use as filed.
A8: Metric | B8: FY2021 | C8: FY2022 | D8: FY2023 | E8: FY2024 | F8: FY2025
A9: Operating results (USD)
A10: Total revenue | B10: 23669 | C10: 29727 | D10: 36601 | E10: 36572 | F10: 44152
A11: Total expenses | B11: 36675 | C11: 44594 | D11: 48279 | E11: 45363 | F11: 47167
A12: Net income | B12: -13006 | C12: -14867 | D12: -11678 | E12: -8791 | F12: -3015
A14: Financial position (USD, end of year)
A15: Total assets | B15: 795934 | C15: 821000 | D15: 864579 | E15: 913861 | F15: 399657
A16: Total liabilities | B16: 675 | C16: 675 | D16: 800 | E16: 420 | F16: 625
A17: Net assets | B17: 795259 | C17: 820325 | D17: 863779 | E17: 913441 | F17: 399032
A19: Headline ratios
A20: Operating margin | B20: -0.54949512 | C20: -0.50011774 | D20: -0.31906232 | E20: -0.24037515 | F20: -0.068286827
A21: Revenue growth (YoY) | B21: 0.1527859 | C21: 0.2559466 | D21: 0.2312376 | E21: -0.00079232808 | F21: 0.20726239
A22: Return on assets | B22: -0.016340551 | C22: -0.018108404 | D22: -0.013507152 | E22: -0.0096196249 | F22: -0.007543969
A24: Figures as reported in source filings (full provenance on the Sources & audit tab). Parentheses denote negatives; ratios are computed upstream in financials_annual.

Sheet Notes
A1: Notes
A2: Human annotations from the versioned store (data/notes/). Annotations only: they never change a reported figure or a confidence tier.
A4: Date | B4: Tag | C4: Author | D4: Note
A5: No notes recorded yet.

Sheet Financial Statements
A1: Painted Cave Mutual Water Company
A2: Financial Statements - income statement, balance sheet, cash flow, member income test (USD)
A3: Entity ID: cawc_0022 | Fiscal year ends March 31.
A5: INCOME STATEMENT - as reported (USD)
A6: Line item | B6: FY2021 | C6: FY2022 | D6: FY2023 | E6: FY2024 | F6: FY2025
A7: Revenue
A8: Program service revenue | B8: 19665 | C8: 29721 | D8: 36539 | E8: 35270 | F8: 41793
A9: Investment income | B9: 4 | C9: 6 | D9: 62 | E9: 952 | F9: 809
A10: Net rental income | B10: 0 | C10: 0 | D10: 0 | E10: 0 | F10: 0
A11: Net gain/(loss) on investment sales | B11: 0 | C11: 0 | D11: 0 | E11: 0 | F11: 0
A12: Other revenue | B12: 0 | C12: 0 | D12: 0 | E12: 350 | F12: 1250
A13: Contributions & grants | B13: 4000 | C13: 0 | D13: 0 | E13: 0 | F13: 300
A14: Total revenue | B14: 23669 | C14: 29727 | D14: 36601 | E14: 36572 | F14: 44152
A16: Expenses
A17: Depreciation | B17: 12840 | C17: 12840 | D17: 15447 | E17: 12540 | F17: 12540
A18: Interest expense | B18: 0 | C18: 0 | D18: 0 | E18: 0 | F18: 0
A19: Total expenses | B19: 36675 | C19: 44594 | D19: 48279 | E19: 45363 | F19: 47167
A21: Net income | B21: -13006 | C21: -14867 | D21: -11678 | E21: -8791 | F21: -3015
A24: BALANCE SHEET - as reported (USD, end of year)
A25: Line item | B25: FY2021 | C25: FY2022 | D25: FY2023 | E25: FY2024 | F25: FY2025
A26: Assets
A27: Cash | B27: 193860 | C27: 195736 | D27: 234324 | E27: 264119 | F27: 249501
A28: Savings & temporary investments | B28: 0 | C28: 0 | D28: 0 | E28: 0 | F28: 0
A29: Accounts receivable | B29: 8863 | C29: 6281 | D29: 0 | E29: 0 | F29: 0
A30: Inventories | B30: 0 | C30: 0 | D30: 0 | E30: 0 | F30: 0
A31: Prepaid expenses | B31: 0 | C31: 0 | D31: 0 | E31: 0 | F31: 0
A32: Property, plant & equipment (gross) | B32: 443208 | C32: 443208 | D32: 443208 | E32: 443208 | F32: 443208
A33: Less: accumulated depreciation | B33: -230787 | C33: -243627 | D33: -271466 | E33: -284242 | F33: -296711
A34: Net property, plant & equipment | B34: 212421 | C34: 199581 | D34: 171742 | E34: 158966 | F34: 146497
A35: Total assets | B35: 795934 | C35: 821000 | D35: 864579 | E35: 913861 | F35: 399657
A37: Liabilities
A38: Accounts payable
A39: Mortgages & notes payable
A40: Total liabilities | B40: 675 | C40: 675 | D40: 800 | E40: 420 | F40: 625
A42: Net Assets / Equity
A43: Capital stock
A44: Paid-in capital
A45: Retained earnings
A46: Net assets | B46: 795259 | C46: 820325 | D46: 863779 | E46: 913441 | F46: 399032
A49: CASH FLOW - derived proxy (USD)
...

Sheet Balance Sheet
A1: Painted Cave Mutual Water Company
A2: Balance Sheet - as reported (USD, end of year)
A3: Entity ID: cawc_0022 | Fiscal year ends March 31.
A5: Line item | B5: FY2021 | C5: FY2022 | D5: FY2023 | E5: FY2024 | F5: FY2025
A6: Assets
A7: Cash | B7: 193860 | C7: 195736 | D7: 234324 | E7: 264119 | F7: 249501
A8: Savings & temporary investments | B8: 0 | C8: 0 | D8: 0 | E8: 0 | F8: 0
A9: Accounts receivable | B9: 8863 | C9: 6281 | D9: 0 | E9: 0 | F9: 0
A10: Inventories | B10: 0 | C10: 0 | D10: 0 | E10: 0 | F10: 0
A11: Prepaid expenses | B11: 0 | C11: 0 | D11: 0 | E11: 0 | F11: 0
A12: Property, plant & equipment (gross) | B12: 443208 | C12: 443208 | D12: 443208 | E12: 443208 | F12: 443208
A13: Less: accumulated depreciation | B13: -230787 | C13: -243627 | D13: -271466 | E13: -284242 | F13: -296711
A14: Net property, plant & equipment | B14: 212421 | C14: 199581 | D14: 171742 | E14: 158966 | F14: 146497
A15: Total assets | B15: 795934 | C15: 821000 | D15: 864579 | E15: 913861 | F15: 399657
A17: Liabilities
A18: Accounts payable
A19: Mortgages & notes payable
A20: Total liabilities | B20: 675 | C20: 675 | D20: 800 | E20: 420 | F20: 625
A22: Net Assets / Equity
A23: Capital stock
A24: Paid-in capital
A25: Retained earnings
A26: Net assets | B26: 795259 | C26: 820325 | D26: 863779 | E26: 913441 | F26: 399032
A28: Balance check (assets − liab. − net assets) | B28: 0 | C28: 0 | D28: 0 | E28: 0 | F28: 0
A30: Net PP&E is the reported ppe_net column (gross less accumulated depreciation). The balance check should be ~0 where all three totals are reported; a non-zero value flags a reporting or extraction discrepancy worth reviewing.

Sheet Officers & contractors
A1: Painted Cave Mutual Water Company
A2: Officers, Directors & Contractors - Form 990 Part VII (FY2025; USD)
A3: Entity ID: cawc_0022 | Fiscal year ends March 31.
A5: Section A - Officers, directors, trustees, key employees
A6: Name | B6: Title | C6: Reportable comp (org) | D6: Reportable comp (related) | E6: Other comp | F6: Total compensation
A7: CHLOE KIRK | B7: Treasurer | C7: 0 | D7: 0 | E7: 0 | F7: 0
A8: REX STEPHENS | B8: Director | C8: 0 | D8: 0 | E8: 0 | F8: 0
A9: STUART PHILKILL | B9: Director | C9: 0 | D9: 0 | E9: 0 | F9: 0
A10: PETER HASLER | B10: President & CEO | C10: 0 | D10: 0 | E10: 0 | F10: 0
A11: BUD KINNEY | B11: Secretary | C11: 0 | D11: 0 | E11: 0 | F11: 0
A13: Section B - Independent contractors (over $100,000)
A14: Contractor | B14: Services | C14: Compensation
A16: Section A lists every officer, director, trustee and key employee filed for the latest year; the two with the highest total compensation are highlighted. Total compensation is computed (reportable org + related + other). Section B lists each independent contractor paid over $100,000; the return reports 0 such contractor(s). Source and confidence for every figure are on the Sources & audit tab.

Sheet Revenue (detail)
A1: Painted Cave Mutual Water Company
A2: Revenue - Form 990 Part VIII (USD)
A3: Entity ID: cawc_0022 | Fiscal year ends March 31.
A5: Part VIII line | B5: FY2021 | C5: FY2022 | D5: FY2023 | E5: FY2024 | F5: FY2025
A6: Revenue by category
A7: 1h. Total contributions, gifts, grants | B7: 4000 | C7: 0 | D7: 0 | E7: 0 | F7: 300
A8: 2g. Total program service revenue | B8: 19665 | C8: 29721 | D8: 36539 | E8: 35270 | F8: 41793
A9: 3. Investment income | B9: 4 | C9: 6 | D9: 62 | E9: 952 | F9: 809
A10: 6d. Net rental income | B10: 0 | C10: 0 | D10: 0 | E10: 0 | F10: 0
A11: 7d. Net gain/(loss) from investment sales | B11: 0 | C11: 0 | D11: 0 | E11: 0 | F11: 0
A12: 11e. Other revenue | B12: 0 | C12: 0 | D12: 0 | E12: 350 | F12: 1250
A13: 12. Total revenue | B13: =SUM(B7:B12) | C13: =SUM(C7:C12) | D13: =SUM(D7:D12) | E13: =SUM(E7:E12) | F13: =SUM(F7:F12)
A15: Program service revenue detail - FY2025 (lines 2a-2f)
A16: Description | B16: Business code | C16: Total revenue
A17: MEMBERSHIP DUES & ASSESSM | C17: 35059
A18: MUTUAL WATER COMPANY | C18: 6734
A19: Revenue category subtotals are as filed. Total revenue (line 12) is a live SUM of the category cells above; its tie-out to the filed total is on the Sources & audit tab. Program service revenue detail is shown for the latest year, with its sum-to-line-2g check on that same audit tab.

Sheet Operating expenses (detail)
A1: Painted Cave Mutual Water Company
A2: Statement of Functional Expenses - Form 990 Part IX (USD)
A3: Entity ID: cawc_0022 | Fiscal year ends March 31.
A5: Part IX line (column A Total) | B5: FY2021 | C5: FY2022 | D5: FY2023 | E5: FY2024 | F5: FY2025
A6: Functional expenses, column A Total - by year
A7: 1. Grants to domestic organizations and governments | B7: 0 | C7: 0 | D7: 0 | E7: 0 | F7: 0
A8: 2. Grants to domestic individuals | B8: 0 | C8: 0 | D8: 0 | E8: 0 | F8: 0
A9: 3. Grants to foreign organizations and individuals | B9: 0 | C9: 0 | D9: 0 | E9: 0 | F9: 0
A10: 4. Benefits paid to or for members | B10: 0 | C10: 0 | D10: 0 | E10: 0 | F10: 0
A11: 5. Compensation of current officers, directors, trustees | B11: 0 | C11: 0 | D11: 0 | E11: 0 | F11: 0
A12: 6. Compensation to disqualified persons | B12: 0 | C12: 0 | D12: 0 | E12: 0 | F12: 0
A13: 7. Other salaries and wages | B13: 0 | C13: 0 | D13: 0 | E13: 0 | F13: 0
A14: 8. Pension plan accruals and contributions | B14: 0 | C14: 0 | D14: 0 | E14: 0 | F14: 0
A15: 9. Other employee benefits | B15: 0 | C15: 0 | D15: 0 | E15: 0 | F15: 0
A16: 10. Payroll taxes | B16: 0 | C16: 0 | D16: 0 | E16: 0 | F16: 0
A17: 11a. Fees for services: management | B17: 0 | C17: 0 | D17: 0 | E17: 0 | F17: 0
A18: 11b. Fees for services: legal | B18: 0 | C18: 0 | D18: 2829 | E18: 1225 | F18: 1101
... A35: 23. Insurance | B35: 3349 | C35: 3368 | D35: 3138 | E35: 3690 | F35: 3755
A36: 24. LICENSES & PERMITS | B36: 2267 | C36: 2393 | D36: not reported | E36: not reported | F36: not reported
A37: 24. REPAIRS & MAINTENANCE | B37: 1774 | C37: 1008 | D37: 2183 | E37: not reported | F37: not reported
A38: 24. WATER ANALYSIS | B38: 1420 | C38: not reported | D38: not reported | E38: not reported | F38: not reported
A39: 24. SECRETARIAL | B39: 1050 | C39: 1950 | D39: 1800 | E39: not reported | F39: not reported
A40: 24. WATER MASTER | B40: not reported | C40: 1032 | D40: not reported | E40: 2880 | F40: 2880
A41: 24. UTILITIES | B41: not reported | C41: not reported | D41: 9720 | E41: 4132 | F41: 4764
A42: 24. LICENSE & FEES | B42: not reported | C42: not reported | D42: 2381 | E42: 2500 | F42: 2408
A43: 24. METER READING | B43: not reported | C43: not reported | D43: not reported | E43: 1800 | F43: 1800
A44: 24e. All other expenses | B44: 1032 | C44: 1087 | D44: 3609 | E44: 6362 | F44: 7819
A45: 25. Total functional expenses | B45: =SUM(B7:B44) | C45: =SUM(C7:C44) | D45: =SUM(D7:D44) | E45: =SUM(E7:E44) | F45: =SUM(F7:F44)
A47: Functional column split - FY2025 (col A = B + C + D)
A48: Part IX line | B48: A. Total | C48: B. Program services | D48: C. Management & general | E48: D. Fundraising
A49: 1. Grants to domestic organizations and governments | B49: 0
A50: 2. Grants to domestic individuals | B50: 0
A51: 3. Grants to foreign organizations and individuals | B51: 0
A52: 4. Benefits paid to or for members | B52: 0
A53: 5. Compensation of current officers, directors, trustees | B53: 0
A54: 6. Compensation to disqualified persons | B54: 0
A55: 7. Other salaries and wages | B55: 0
A56: 8. Pension plan accruals and contributions | B56: 0
A57: 9. Other employee benefits | B57: 0
A58: 10. Payroll taxes | B58: 0
...

Sheet Balance sheet (detail)
A1: Painted Cave Mutual Water Company
A2: Balance Sheet - Form 990 Part X (end of year, USD)
A3: Entity ID: cawc_0022 | Fiscal year ends March 31.
A5: Part X line (column B, EOY) | B5: FY2021 | C5: FY2022 | D5: FY2023 | E5: FY2024 | F5: FY2025
A6: Assets
A7: 1. Cash - non-interest-bearing | B7: 193860 | C7: 195736 | D7: 234324 | E7: 264119 | F7: 249501
A8: 2. Savings and temporary cash investments | B8: 0 | C8: 0 | D8: 0 | E8: 0 | F8: 0
A9: 3. Pledges and grants receivable, net | B9: 0 | C9: 0 | D9: 0 | E9: 0 | F9: 0
A10: 4. Accounts receivable, net | B10: 8863 | C10: 6281 | D10: 0 | E10: 0 | F10: 0
A11: 5. Receivables from officers/directors/trustees | B11: 0 | C11: 0 | D11: 0 | E11: 0 | F11: 0
A12: 6. Receivables from disqualified persons | B12: 0 | C12: 0 | D12: 0 | E12: 0 | F12: 0
A13: 7. Notes and loans receivable, net | B13: 0 | C13: 0 | D13: 0 | E13: 0 | F13: 0
A14: 8. Inventories for sale or use | B14: 0 | C14: 0 | D14: 0 | E14: 0 | F14: 0
A15: 9. Prepaid expenses and deferred charges | B15: 0 | C15: 0 | D15: 0 | E15: 0 | F15: 0
A16: 10c. Land, buildings, and equipment, net | B16: 212421 | C16: 199581 | D16: 171742 | E16: 158966 | F16: 146497
A17: 11. Investments - publicly traded securities | B17: 0 | C17: 0 | D17: 0 | E17: 0 | F17: 0
A18: 12. Investments - other securities | B18: 0 | C18: 0 | D18: 0 | E18: 0 | F18: 0
... A21: 15. Other assets | B21: 380790 | C21: 419402 | D21: 458513 | E21: 490776 | F21: 3659
A22: 16. Total assets | B22: =SUM(B7:B21) | C22: =SUM(C7:C21) | D22: =SUM(D7:D21) | E22: =SUM(E7:E21) | F22: =SUM(F7:F21)
A24: Liabilities
A25: 19. Deferred revenue | B25: 375 | C25: 375 | D25: 500 | E25: 120 | F25: not reported
A26: 25. Other liabilities | B26: 300 | C26: 300 | D26: 300 | E26: 300 | F26: 625
A27: 26. Total liabilities | B27: =SUM(B25:B26) | C27: =SUM(C25:C26) | D27: =SUM(D25:D26) | E27: =SUM(E25:E26) | F27: =SUM(F25:F26)
A29: Net assets / fund balances
A30: 27. Net assets without donor restrictions | B30: 795259 | C30: 820325 | D30: 863779 | E30: 913441 | F30: 399032
A31: 32. Total net assets / fund balances | B31: =SUM(B30:B30) | C31: =SUM(C30:C30) | D31: =SUM(D30:D30) | E31: =SUM(E30:E30) | F31: =SUM(F30:F30)
A33: Every Part X line is end-of-year (column B), as filed. Section totals (lines 16 / 26 / 32) are live SUMs of the lines above; their tie-outs and the balance-sheet identity (16 = 26 + 32) are on the Sources & audit tab. This filer files as a non-FASB mutual, so net assets sit on lines 29-31 (capital stock / paid-in capital / retained earnings); lines this filer does not report are omitted. Lines 10a/10b net into line 10c (shown).

Sheet Net-assets reconciliation
A1: Painted Cave Mutual Water Company
A2: Reconciliation of Net Assets - Form 990 Part XI (USD)
A3: Entity ID: cawc_0022 | Fiscal year ends March 31.
A5: Part XI line | B5: FY2021 | C5: FY2022 | D5: FY2023 | E5: FY2024 | F5: FY2025
A6: Reconciliation
A7: 4. Net assets, beginning of year | B7: 732218 | C7: 795259 | D7: 820325 | E7: 863779 | F7: 913441
A8: 3. Revenue less expenses | B8: -13006 | C8: -14867 | D8: -11678 | E8: -8791 | F8: -3015
A9: 8. Prior period adjustments | B9: not reported | C9: not reported | D9: 55132 | E9: not reported | F9: not reported
A10: 9. Other changes in net assets | B10: 76047 | C10: 39933 | D10: not reported | E10: 58453 | F10: -511394
A11: 10. Net assets, end of year | B11: =SUM(B7,B8,B9,B10) | C11: =SUM(C7,C8,C9,C10) | D11: =SUM(D7,D8,D9,D10) | E11: =SUM(E7,E8,E9,E10) | F11: =SUM(F7,F8,F9,F10)
A13: Part XI reconciles beginning to ending net assets. Ending net assets (line 10) is a live formula: beginning balance (line 4) + revenue less expenses (line 3) + prior-period adjustments (8) + other changes (9). Its tie-out to the filed line 10 (and to Part X line 32) is on the Sources & audit tab. Lines 5-7 (unrealized gains, donated services, investment expenses) are not filed by this entity.

Sheet Cash flow proxies
A1: Painted Cave Mutual Water Company
A2: Cash Flow Proxies - derived (USD)
A3: Entity ID: cawc_0022 | Fiscal year ends March 31.
A5: PROXY ONLY. The source filings contain no statement of cash flows. Lines below are derived from the reported income statement and year-over-year balance-sheet changes; treat as directional estimates, not GAAP cash flows. The earliest year has no prior period, so its delta cells are blank.
A7: Proxy line (USD) | B7: FY2021 | C7: FY2022 | D7: FY2023 | E7: FY2024 | F7: FY2025
A8: Operating
A9: Net income | B9: -13006 | C9: -14867 | D9: -11678 | E9: -8791 | F9: -3015
A10: + Depreciation (reported) | B10: 12840 | C10: 12840 | D10: 15447 | E10: 12540 | F10: 12540
A11: − Δ Accounts receivable | C11: 2582 | D11: 6281 | E11: 0 | F11: 0
A12: − Δ Inventories | C12: 0 | D12: 0 | E12: 0 | F12: 0
A13: − Δ Prepaid expenses | C13: 0 | D13: 0 | E13: 0 | F13: 0
A14: + Δ Accounts payable
A15: Operating cash flow proxy | C15: 555 | D15: 10050 | E15: 3749 | F15: 9525
A17: Investing
A18: − Δ PP&E gross (capex proxy) | C18: 0 | D18: 0 | E18: 0 | F18: 0
A20: Financing
A21: Δ Mortgages & notes payable
A23: Reconciliation
A24: Δ Cash + temp. investments (actual) | C24: 1876 | D24: 38588 | E24: 29795 | F24: -14618
A26: The capex proxy assumes gross PP&E rises only via capital spending (it ignores disposals). 'Δ Cash + temp. investments (actual)' is the real reported change in liquid funds and is the most reliable line here; the operating/investing/financing proxies will not perfectly reconcile to it.

Sheet Ratios
A1: Painted Cave Mutual Water Company
A2: Financial Ratios
A3: Entity ID: cawc_0022 | Fiscal year ends March 31.
A5: Ratio | B5: FY2021 | C5: FY2022 | D5: FY2023 | E5: FY2024 | F5: FY2025
A6: Profitability (computed upstream)
A7: Operating margin (NI / revenue) | B7: -0.54949512 | C7: -0.50011774 | D7: -0.31906232 | E7: -0.24037515 | F7: -0.068286827
A8: Expense ratio (expenses / revenue) | B8: 1.5494951 | C8: 1.5001177 | D8: 1.3190623 | E8: 1.2403752 | F8: 1.0682868
A9: Return on assets (NI / assets) | B9: -0.016340551 | C9: -0.018108404 | D9: -0.013507152 | E9: -0.0096196249 | F9: -0.007543969
A10: Revenue growth (YoY) | B10: 0.1527859 | C10: 0.2559466 | D10: 0.2312376 | E10: -0.00079232808 | F10: 0.20726239
A12: Leverage & solvency
A13: Debt-to-assets (liab. / assets) | B13: 0.00084806027 | C13: 0.00082216809 | D13: 0.00092530584 | E13: 0.00045958849 | F13: 0.001563841
A14: Equity ratio (net assets / assets) | B14: 0.99915194 | C14: 0.99917783 | D14: 0.99907469 | E14: 0.99954041 | F14: 0.99843616
A16: Liquidity & asset profile (derived here)
A17: Current ratio (current assets / AP)
A18: Cash ratio ((cash+temp inv.) / total liab.) | B18: 287.2 | C18: 289.97926 | D18: 292.905 | E18: 628.85476 | F18: 399.2016
A19: Asset age proxy (accum. deprec. / gross PP&E) | B19: 0.52071939 | C19: 0.54968999 | D19: 0.61250248 | E19: 0.64132868 | F19: 0.66946219
A21: Upstream ratios are read from financials_annual; derived ratios are computed only where inputs are reported. Current ratio uses accounts payable as the current-liability proxy (the filings do not split current vs. long-term liabilities). Asset age proxy: a higher % implies older / more depreciated infrastructure.

Sheet Unit economics
A1: Painted Cave Mutual Water Company
A2: Unit economics - per-customer revenue by category (USD)
A3: Entity ID: cawc_0022 | Fiscal year ends March 31.
A5: Every metric here is PER CUSTOMER (a metered service connection). It is not a per-member figure; the member (shareholder) count is a different denominator, shown in the denominator block. The visible cell shows the value and its classification; the numerator, denominator, formula, and rationale are in each metric's LOGIC popup.
A6: Per-customer denominator (service connections) | B6: 91 | C6: State Water Board eAR Section 4 (CurTotalConnections), reporting year 2023
A7: Total annual revenue (eAR Section 8b B1.8) | B7: 37270 | C7: State Water Board eAR Section 8b, question B1.8 (total annual revenue), reporting year 2023
A8: Primary source | C8: State Water Board eAR Section 8b (revenue by rate/fee), reporting year 2023
A10: Revenue categories (value, classification, per customer, share)
A11: Revenue category | B11: Classification | C11: Value (USD) | D11: Per customer | E11: Share of revenue
A12: Water sales revenue | B12: DIRECT | C12: 35849 | D12: 393.95 | E12: 0.9619
A13: Assessment revenue (990 program-service revenue not matched to eAR water-rate revenue) | B13: DERIVED | C13: -579 | D13: -6.36 | E13: -0.0164
A14: Meter revenue | B14: not reported | C14: not reported | D14: not reported | E14: not reported
A15: Overage or tiered penalty revenue | B15: not reported | C15: not reported | D15: not reported | E15: not reported
A17: Water sales revenue - DIRECT
A18: Revenue customers paid for water service, read straight off the filed eAR Section 8b water-rate line. A DIRECT filed figure, not computed by us.
A19: Numerator: Water rate revenue | B19: 35849 | C19: eAR Section 8b field B1.1 (residential water rates) only (this filer reported no non-residential water-rate revenue). State Water Board eAR Section 8b, question B1.1 + B1.2 (revenue from water rates), reporting year 2023
A20: Denominator: Total service connections | B20: 91 | C20: eAR Section 4 CurTotalConnections, reporting year 2023. State Water Board eAR Section 4 (CurTotalConnections), reporting year 2023
A21: Per customer: water rate revenue $35,849 / 91 connections = $393.95 per connection
A22: Share of revenue: water rate revenue $35,849 / total annual revenue (eAR Section 8b B1.8) $37,270 = 96.19%
A23: Period treatment: Numerator (eAR Section 8b, the fiscal year ending March 31, 2024) and denominator (eAR Section 4 connections reported in the same eAR filing) are both the eAR reporting year 2023, so the two sides are bound to the same reporting year.
A24: Rationale: Dividing water-rate revenue by the number of metered service connections gives the average revenue per customer; dividing by total annual revenue shows how much of the system's income comes from water rates.
A26: Assessment revenue (990 program-service revenue not matched to eAR water-rate revenue) - DERIVED
A27: A DERIVED residual (medium confidence): the part of the Form 990 program-service revenue that is not matched by the eAR water-rate revenue for the same period. Computed by us, not a filed line.
A28: Input A: Form 990 program-service revenue | B28: 35270 | C28: Form 990 Part VIII line 2 (total program-service revenue), fiscal year 2024 ending March 31, 2024
A29: Input B: eAR water-rate revenue | B29: 35849 | C29: State Water Board eAR Section 8b, question B1.1 + B1.2 (revenue from water rates), reporting year 2023
A30: Residual (A minus B) = assessment revenue | B30: =B28-B29 | C30: $35,270 (990 program-service revenue) minus $35,849 (eAR water-rate revenue) = $-579
A31: Period alignment: Both inputs cover the same period: the eAR Section 8b is the fiscal year ending March 31, 2024 and the Form 990 fiscal year 2024 ends March 31, 2024, so the residual is period-aligned.
A32: What it IS: revenue the system booked as program service on its 990 that is not accounted for by the eAR water-rate line, plausibly member assessments and other service revenue.
A33: This residual is a difference between two sources for the same period; it is not a separately filed assessment line and may include other unmatched revenue.
A34: Denominator: Total service connections | B34: 91 | C34: eAR Section 4 CurTotalConnections, reporting year 2023. State Water Board eAR Section 4 (CurTotalConnections), reporting year 2023
A35: Per customer: residual $-579 / 91 connections = $-6.36 per connection
A36: Share of revenue: residual $-579 / 990 program-service revenue $35,270 = -1.64%
A38: Meter revenue - not reported
A39: Not reported. This category is not built because doing so would double-count.
A40: Reason: The eAR Section 8a reports a base/meter rate PRICE, but the filing carries no meter revenue line and no tier volume, and the base charge is already inside the water-sales revenue (eAR Section 8b water rates). Building a separate meter figure would double-count. Not backed into from a total.
A42: Overage or tiered penalty revenue - not reported
A43: Not reported. This category is not built because doing so would double-count.
A44: Reason: The eAR Section 8a reports tiered/overage rate PRICES, but the filing carries no overage revenue and no tier consumption volume, and any overage billed is already inside the water-sales revenue. Building it would double-count. Not backed into from a total.

Sheet Rate structure
A1: Painted Cave Mutual Water Company
A2: Rate structure and representative bill - eAR Section 8a (RY2024)
A3: Entity ID: cawc_0022 | Fiscal year ends March 31.
A5: This block is a rate-schedule illustration at defined usage levels. It is NOT billed revenue and not a claim about any real customer's usage. The revenue side of unit economics is the separate Unit Economics block.
A6: Structure: Tiered increasing-block with a fixed base, billed monthly, priced per Gallons. Rate schedule last updated 05/01/2024.
A7: Defined single-family usage levels, identical for every company so the bill is comparable: Low = 5 HCF/month (~125 gallons/day); Median = 10 HCF/month (~249 gallons/day); High = 25 HCF/month (~623 gallons/day). 1 HCF = 748 gallons, and 1 thousand gallons = 1,000 gallons. The usage is converted into the company's own filed unit before the filed tiers are applied, and the bill is stated as a monthly equivalent: a bimonthly structure is computed at twice the monthly usage and divided by two, and any other billing period the same way with its factor stated. These are an illustration, not a measured usage for any real customer.
A9: Defined usage levels (EDITABLE - change a yellow cell to move the bill)
B10: Low | C10: Median | D10: High
A11: Defined usage level (HCF per month) | B11: 5 | C11: 10 | D11: 25
A12: Conversion: one HCF is this many Gallons | B12: 748 | C12: 1 HCF = 748 gallons
A13: Monthly usage (Gallons) | B13: =B11*$B$12 | C13: =C11*$B$12 | D13: =D11*$B$12
A14: Months per bill (from filed billing frequency) | B14: 1 | C14: monthly biller
A16: Filed rate table - single-family residential (as filed, eAR Section 8a)
A17: Base / fixed charge per monthly bill ($) | B17: 70
A18: Tier | B18: Range (Gallons) | C18: Price ($/Gallons) | D18: Upper limit (Gallons)
A19: Tier 1 | B19: 0 to 3000 Gallons | C19: 0 | D19: 3000
A20: Tier 2 | B20: 3000 to 7000 Gallons | C20: 0.0015 | D20: 7000
A21: Tier 3 | B21: 7000 to 10000 Gallons | C21: 0.003 | D21: 10000
A22: Tier 4 | B22: over 10000 Gallons | C22: 0.0045 | D22: no limit
A24: Representative monthly bill - LIVE (edit a yellow usage cell to recompute)
B25: Low | C25: Median | D25: High
A26: Usage per bill (Gallons) | B26: =B13*$B$14 | C26: =C13*$B$14 | D26: =D13*$B$14
A27: Tier 1 charge per bill ($) | B27: =$C$19*MAX(0,MIN(B26,$D$19)-0) | C27: =$C$19*MAX(0,MIN(C26,$D$19)-0) | D27: =$C$19*MAX(0,MIN(D26,$D$19)-0)
A28: Tier 2 charge per bill ($) | B28: =$C$20*MAX(0,MIN(B26,$D$20)-$D$19) | C28: =$C$20*MAX(0,MIN(C26,$D$20)-$D$19) | D28: =$C$20*MAX(0,MIN(D26,$D$20)-$D$19)
A29: Tier 3 charge per bill ($) | B29: =$C$21*MAX(0,MIN(B26,$D$21)-$D$20) | C29: =$C$21*MAX(0,MIN(C26,$D$21)-$D$20) | D29: =$C$21*MAX(0,MIN(D26,$D$21)-$D$20)
A30: Tier 4 charge per bill ($) | B30: =$C$22*MAX(0,B26-$D$21) | C30: =$C$22*MAX(0,C26-$D$21) | D30: =$C$22*MAX(0,D26-$D$21)
A31: Volumetric charge per bill ($) | B31: =SUM(B27,B28,B29,B30) | C31: =SUM(C27,C28,C29,C30) | D31: =SUM(D27,D28,D29,D30)
A32: Base charge per bill ($) | B32: =$B$17 | C32: =$B$17 | D32: =$B$17
A33: Total per bill ($) | B33: =B32+B31 | C33: =C32+C31 | D33: =D32+D31
A34: Total per MONTH ($) | B34: =B33/$B$14 | C34: =C33/$B$14 | D34: =D33/$B$14
A35: Fixed per month ($) | B35: =$B$17/$B$14 | C35: =$B$17/$B$14 | D35: =$B$17/$B$14
A36: Volumetric per month ($) | B36: =B31/$B$14 | C36: =C31/$B$14 | D36: =D31/$B$14
A37: Effective price ($/HCF) | B37: =IF(B11=0,"",B34/B11) | C37: =IF(C11=0,"",C34/C11) | D37: =IF(D11=0,"",D34/D11)
A39: Rate-structure comparison metrics
A40: Fixed share of the bill at median usage | B40: =C35/C34 | C40: fixed / total at 10 HCF/month
A41: Tier price ratio (highest to lowest positive tier) | B41: =$C$22/$C$20 | C41: first tier is a $0.00 allowance included in the base charge; the ratio uses the lowest POSITIVE tier price.
A42: Rate structure (as filed) | B42: tiered (Variable Usage)
A44: State Water Board eAR Section 8a (Customer Charges), single- and multi-family residential charges grid, reporting year 2024. Rate structure only; no revenue.

Sheet eAR revenue & expenses
A1: Painted Cave Mutual Water Company
A2: eAR annual revenue and expenses - State Water Board eAR Section 8b (USD)
A3: Entity ID: cawc_0022 | Fiscal year ends March 31.
A5: The water system's own annual figures from the public eAR Section 8b, on the fiscal year ending March 31, 2024 the filer self-reported (B0.1/B0.2). Shown beside the period-aligned Form 990 with the variance flagged: a different source (a State Water Board self-report vs an IRS filing). Preserved as filed, never reconciled.
A6: Reporting period basis (self-reported) | B6: fiscal year ending March 31, 2024 | C6: eAR Section 8b B0.1 (WRFinancialReportingPeriod) / B0.2 start 04/01/2023
A8: Revenue (eAR Section 8b, questions B1.x)
A9: Line | B9: Amount (USD) | C9: Citation
A10: Water rate revenue | B10: 35849 | C10: State Water Board eAR Section 8b, question B1.1 + B1.2 (revenue from water rates), reporting year 2023
A11: Other fees and charges | B11: 1321 | C11: State Water Board eAR Section 8b, question B1.3 + B1.4 (revenue from other fees), reporting year 2023
A12: Non-customer revenue | B12: 100 | C12: State Water Board eAR Section 8b, question B1.7 (grants, interest, and other non-customer), reporting year 2023
A13: Total annual revenue | B13: 37270 | C13: State Water Board eAR Section 8b, question B1.8 (total annual revenue for the reporting year), reporting year 2023
A15: Expenses (eAR Section 8b, questions B2.x)
A16: Line | B16: Amount (USD) | C16: Citation
A17: Operations and maintenance | B17: 32636 | C17: State Water Board eAR Section 8b, question B2.1 (annual O and M expense), reporting year 2023
A18: Capital | B18: 0 | C18: State Water Board eAR Section 8b, question B2.2 (annual expenses from investing or capital), reporting year 2023
A19: Financing | B19: 0 | C19: State Water Board eAR Section 8b, question B2.3 (annual expenses from financing), reporting year 2023
A20: Other | B20: 0 | C20: State Water Board eAR Section 8b, question B2.4 (total other annual expenses), reporting year 2023
A21: Total annual expenses | B21: 32636 | C21: State Water Board eAR Section 8b, question B2.5 (total annual expenses), reporting year 2023
A23: Period-aligned Form 990 comparison (variance surfaced, never reconciled)
A24: Measure | B24: eAR Section 8b | C24: Form 990
A25: total revenue | B25: 37270 | C25: 36572
A26: Variance (eAR minus Form 990) | B26: =B25-C25
A27: The eAR Section 8b total revenue (State Water Board self-report, fiscal year ending March 31, 2024) and the Form 990 total revenue (IRS filing) are a different source and cover the same fiscal year (April 1, 2023 to March 31, 2024): the water system self-reported the eAR Section 8b on a fiscal year (B0.1 Fiscal, B0.2 start 04/01/2023), which matches the Form 990 fiscal year. Both are carried as filed; the variance is surfaced, never reconciled.
A28: total expenses | B28: 32636 | C28: 45363
A29: Variance (eAR minus Form 990) | B29: =B28-C28
A30: The eAR Section 8b total expenses (State Water Board self-report, fiscal year ending March 31, 2024) and the Form 990 total expenses (IRS filing) are a different source and cover the same fiscal year (April 1, 2023 to March 31, 2024): the water system self-reported the eAR Section 8b on a fiscal year (B0.1 Fiscal, B0.2 start 04/01/2023), which matches the Form 990 fiscal year. Both are carried as filed; the variance is surfaced, never reconciled.

Sheet Denominators & alignment
A1: Painted Cave Mutual Water Company
A2: Denominators and calendar alignment
A3: Entity ID: cawc_0022 | Fiscal year ends March 31.
A5: System size and water use per fiscal year (the operating denominators that per-customer and per-acre metrics divide by), each cited to file and field. The eAR is reported on the calendar year; the 990 fiscal year differs by company. A calendar-year filer's volume is the eAR annual total (fiscal year = calendar year); an offset filer's is recast by a true monthly sum of the covered calendar months, or read not reported naming the missing months. Point-in-time counts (connections, population) are matched to the closest eAR year and never summed. Every derived figure states its formula and accounting rationale.
A6: Member vs customer (two different denominators, both preserved)
A7: Customer (service connection) | B7: 91 | C7: State Water Board eAR Section 4 (CurTotalConnections), reporting year 2024
A8: SDWIS service-connection count (different registry) | B8: 91
A9: Member (shareholder) | C9: No published shareholder count
A10: In a mutual water company a MEMBER is a shareholder who owns part of the system; a CUSTOMER is a metered service connection that receives water. The two diverge because one owner can hold several connections, a connection can serve people who are not owners, and some mutuals attach shares to land by acreage rather than counting heads. Per-customer metrics divide by service connections; per-member metrics divide by shareholders; the two counts are never used interchangeably.
A12: Denominator layer by fiscal year
A13: Fiscal year (end) | B13: Connections | C13: Population | D13: Service-area acres | E13: Water produced (AF) | F13: Water delivered (AF) | G13: Alignment method
A14: FY2021 (2021-03-31) | B14: 91 | C14: not reported | D14: 43.4 | E14: 25.9 | F14: 19.8 | G14: recast from monthly eAR data to fiscal year ending March 31, 2021
A15: FY2022 (2022-03-31) | B15: 91 | C15: not reported | D15: 43.4 | E15: 24.7 | F15: 19 | G15: recast from monthly eAR data to fiscal year ending March 31, 2022
A16: FY2023 (2023-03-31) | B16: 91 | C16: not reported | D16: 43.4 | E16: not reported | F16: not reported | G16: recast from monthly eAR data to fiscal year ending March 31, 2023
A17: FY2024 (2024-03-31) | B17: 91 | C17: 160 | D17: 43.4 | E17: not reported | F17: not reported | G17: recast from monthly eAR data to fiscal year ending March 31, 2024
A18: FY2025 (2025-03-31) | B18: 91 | C18: 160 | D18: 43.4 | E18: not reported | F18: not reported | G18: recast from monthly eAR data to fiscal year ending March 31, 2025
A20: Connections by class - FY2025 (eAR Section 4)
A21: Single-family residential | B21: 89
A22: Multi-family residential | B22: 0
A23: Commercial and institutional | B23: 0
A24: Industrial | B24: 0
A25: Landscape irrigation | B25: 0
A26: Agricultural | B26: 0
A27: Monthly-volume source: California open-data portal (data.ca.gov): the separate Produced Water (by month and source) and Delivered Water (by month and connection type) resources, which cover every public water system (not only urban suppliers), one resource per reporting year, matched by exact PWSID. This is the aggregate publication of eAR Section 6.

Sheet Governance evidence
A1: Painted Cave Mutual Water Company
A2: Governance evidence status - Ostrom's eight design principles
A3: Entity ID: cawc_0022 | Fiscal year ends March 31.
A5: Evidence summary: 5 documented, 1 partial, 2 not documented of eight principles.
A6: A count of how many of Elinor Ostrom's eight design principles have a supporting record on file, not a grade. NOT DOCUMENTED means the supporting record was not found, not that the company governs badly. It marks a gap in the documentary record, an evidence gap to close, never a governance failing.
A7: Each mutual is read against Elinor Ostrom's eight design principles for institutions that govern a shared resource durably. Per principle: a one-line finding, the observable signal, a citation, and an evidence status stating whether the supporting record exists: DOCUMENTED (a cited record supports alignment), PARTIAL (some evidence exists but it is incomplete), or NOT DOCUMENTED (no supporting record was found). This is an evidence-status read, not a grade: the principles are never ranked, weighted, or given a letter, consistent with reporting as filed and not grading companies. NOT DOCUMENTED means the supporting record was not found, not that the company governs badly. It marks a gap in the documentary record, an evidence gap to close, never a governance failing.
A9: Principle | B9: Evidence status | C9: Finding | D9: Signal | E9: Citation
A10: Clearly defined boundaries | B10: DOCUMENTED | C10: The system is a defined public water system: 91 service connections over a State-published service-area boundary. | D10: SDWIS Community water system; SABL service-area boundary (not verified (sabl)); connections defined. | E10: [C][G]
A11: What the record shows: SDWIS defines the membership as a fixed set of service connections and the State Water Board publishes a SABL service-area polygon, so who is inside and outside the system is documented. The boundary is Not Verified (SABL), so its outer edge rests on that State layer.
A12: Rules fit local conditions | B12: DOCUMENTED | C12: Charges are tied to service under a documented rate or share-based allocation rule reported to the State or set in the company's structure. | D12: eAR Section 8a customer charges; documented rate or share-allocation rule. | E12: [E][r1]
A13: What the record shows: The record documents how charges are set, whether a filed metered rate schedule or a share-and-acreage allocation, so cost tracks service. Whether every tier scales precisely with use is only partially visible at this scale, but a real cost-to-service rule is on record.
A14: Collective-choice arrangements | B14: DOCUMENTED | C14: The company is owned by its customer-shareholders and run by a named board they elect, documented in its Form 990 governance section. | D14: Mutual ownership; named elected board of directors (Form 990). | E14: [990][r1]
A15: What the record shows: The record documents a collective-choice mechanism: customers are shareholders who elect a named board that governs the company. Turnout and specific member votes on major decisions are not documented, but the elected-board structure and its membership are on record.
A16: Monitoring | B16: DOCUMENTED | C16: The system is metered and monitored: the State SAFER risk assessment shows it Not Failing, and it files an annual eAR. | D16: SAFER Not Failing; annual eAR reporting; metered connections. | E16: [S][E]
A17: What the record shows: Operational monitoring is documented: the State rates the system Not Failing on its drinking-water risk assessment and the system files an annual eAR. No independent audited financial statement is published, so financial monitoring is weaker, but the operational record is present.
A18: Graduated sanctions | B18: NOT DOCUMENTED | C18: No published shut-off, penalty, or delinquency policy was found for this system. | D18: No sourced sanctions policy. | E18: not reported
A19: What the record shows: No public record of a graduated shut-off or penalty policy was found for a system this small. NOT DOCUMENTED means the supporting record was not found, not that the company governs badly. It marks a gap in the documentary record, an evidence gap to close, never a governance failing.
A20: Conflict-resolution mechanisms | B20: NOT DOCUMENTED | C20: No published bylaws, dispute procedure, or grievance mechanism was found for this system. | D20: No sourced conflict-resolution record. | E20: not reported
A21: What the record shows: No public record of a member dispute or conflict-resolution procedure was found. NOT DOCUMENTED means the supporting record was not found, not that the company governs badly. It marks a gap in the documentary record, an evidence gap to close, never a governance failing.
A22: Recognized right to organize | B22: DOCUMENTED | C22: An incorporated California mutual water company recognized by the IRS (501(c)(12)) and by the State Water Board as a public water system. | D22: IRS 501(c)(12) exempt filer (Form 990); SDWIS public water system. | E22: [990][C][SOS]
A23: What the record shows: Baseline legal standing is documented: the company is an incorporated mutual recognized by the IRS as a tax-exempt filer and by the State Water Board as a regulated water system. This records the right to organize as a member entity, not a documented instance of exercising it. The California Secretary of State holds the company as a registered corporation, entity number 0147674, first registered 01/06/1932, status as filed "Active", with a governing body named in the Statement of Information filed 1/22/2026. That is a direct state record of the right to organize being recognized, so the evidence behind this status is now a filed corporate record rather than an inference from the company's tax form. The status was already DOCUMENTED and does not move.
A24: Nested enterprises | B24: PARTIAL | C24: The system draws on a shared local groundwater basin, embedding it in a larger physical water system, though its role in basin governance is not documented. | D24: SDWIS Primary Water Source Type: groundwater (shared basin). | E24: [C]
A25: What the record shows: The system relies on a shared groundwater basin, so it is physically nested in a larger hydrologic system. Its participation in a groundwater sustainability agency or basin governance is not documented, so the nesting evidence is partial.

Sheet Operational metrics
A1: Painted Cave Mutual Water Company
A2: Operational metrics - plant per acre, density, terrain
A3: Entity ID: cawc_0022 | Fiscal year ends March 31.
A5: Plant assets per acre
A6: Service-area acres | B6: 43.4 | C6: Geodesic area (WGS84 spherical excess) of the SABL service-area polygon.
A7: Fiscal year | B7: Gross plant per acre (primary) | C7: Net plant per acre
A8: FY2021 | B8: 10212.166 | C8: 4894.4931
A9: FY2022 | B9: 10212.166 | C9: 4598.6406
A10: FY2023 | B10: 10212.166 | C10: 3957.1889
A11: FY2024 | B11: 10212.166 | C11: 3662.8111
A12: FY2025 | B12: 10212.166 | C12: 3375.5069
A13: Infrastructure built per acre of service area. Gross plant per acre is the primary read because it measures how much plant the system has put in the ground per acre, and unlike net plant it does not fall over time purely because the assets depreciate on the books. Net plant per acre is shown alongside as the depreciated book value per acre.
A14: Formula: gross plant per acre = Form 990 Part X line 10a (land, buildings, and equipment, gross) / SABL service-area acres; net plant per acre uses Part X line 10c (net)
A15: Source lines: Form 990 Part X line 10a (gross) and line 10c (net); Geodesic area (WGS84 spherical excess) of the SABL service-area polygon.
A16: Confidence: medium. This is worked out from filed figures (a ratio, or a year-to-year change), so it is one step removed from the raw numbers.. Filed gross/net plant over the measured SABL service-area acreage.
A18: Connections per acre
A19: Connections per acre | B19: 2.1 | C19: 91 connections / 43.4 acres. CA State Water Board SABL SERVICE_CONNECTIONS; Geodesic area (WGS84 spherical excess) of the SABL service-area polygon.
A21: Who they are
A22: Terrain class | B22: canyon | C22: Company context page (BLUEPRINT 5B)
A23: A residential mountain-community mutual water company (501(c)(12)) serving about 85 to 91 metered single-family connections and roughly 160 residents in Painted Cave, an unincorporated community on San Marcos Pass above Santa Barbara, on steep canyon and mountain terrain zoned very high fire severity.

Sheet Supply & weather
A1: Painted Cave Mutual Water Company
A2: Supply and weather indicators (DWR water year)
A3: Entity ID: cawc_0022 | Fiscal year ends March 31.
A5: Reporting calendar: Different reporting periods. The DWR water year runs October 1 to September 30; this system's fiscal year ends March 31, so the two period ends are six months apart. Read the two side by side with that in mind. Neither series is recast: both are reported as filed. A water year is named for the calendar year it ends in, so WY2024 and FY2024 share a number without covering the same twelve months.
A7: Indicator | B7: WY2021 | C7: WY2022 | D7: WY2023 | E7: WY2024 | F7: WY2025
A8: Water-year type (Sacramento Valley) | B8: Critical | C8: Critical | D8: Wet | E8: Above Normal | F8: not reported
A9: Peak drought, Santa Barbara County | B9: D4 | C9: D4 | D9: D3 | E9: None (no D0-D4 during the fiscal year) | F9: D3
A10: Precip, percent of normal (8-Station Index) | B10: 48 | C10: 86 | D10: 133 | E10: 96 | F10: 113
A11: Snowpack, April 1 percent of average | B11: 59% | C11: 38% | D11: 237% | E11: 110% | F11: 96%
A12: State Water Project allocation | B12: 5% | C12: 5% | D12: 100% | E12: 40% | F12: 50%

Sheet How this was built
A1: Painted Cave Mutual Water Company
A2: How this was built - forensic lineage
A3: Entity ID: cawc_0022 | Fiscal year ends March 31.
A5: A plain account of the forensic lineage behind the hard-to-source metrics: what sources were checked, what was found, what was derived, and what could not be built and why. Every figure marked DERIVED or IMPOSSIBLE above is traceable to a line here.
A7: Water-sales revenue per customer - DIRECT
A8: Sources checked | B8: State Water Board eAR Section 8b (water-rate revenue B1.1/B1.2); State Water Board eAR Section 4 (connection count, same reporting year); audited financial statement (secondary cross-check, where published)
A9: What was found | B9: The eAR Section 8b reports water-rate revenue for reporting year 2023, so this is a DIRECT filed figure; per customer it is divided by the eAR Section 4 connection count for the same reporting year, so numerator and denominator share the year.
A11: Assessment revenue (residual) - DERIVED
A12: Sources checked | B12: Form 990 Part VIII line 2 (program-service revenue); State Water Board eAR Section 8b (water-rate revenue B1.1/B1.2)
A13: What was found | B13: No source separately reports a member assessment, so it is DERIVED as a residual: $35,270 (990 program-service revenue) minus $35,849 (eAR water-rate revenue) = $-579. Period-aligned; medium confidence.
A14: Caveat | B14: This residual is a difference between two sources for the same period; it is not a separately filed assessment line and may include other unmatched revenue.
A16: Meter revenue - not reported
A17: Sources checked | B17: State Water Board eAR Section 8a (rate prices); State Water Board eAR Section 8b (revenue lines); audited financial statement
A18: What was found | B18: The rate price exists in Section 8a but no revenue or tier volume is reported, and the base charge is already inside water sales.
A19: Caveat | B19: The eAR Section 8a reports a base/meter rate PRICE, but the filing carries no meter revenue line and no tier volume, and the base charge is already inside the water-sales revenue (eAR Section 8b water rates). Building a separate meter figure would double-count. Not backed into from a total.
A21: Overage / tiered-penalty revenue - not reported
A22: Sources checked | B22: State Water Board eAR Section 8a (rate prices); State Water Board eAR Section 8b (revenue lines); audited financial statement
A23: What was found | B23: The rate price exists in Section 8a but no revenue or tier volume is reported, and the base charge is already inside water sales.
A24: Caveat | B24: The eAR Section 8a reports tiered/overage rate PRICES, but the filing carries no overage revenue and no tier consumption volume, and any overage billed is already inside the water-sales revenue. Building it would double-count. Not backed into from a total.
A26: eAR Section 8b reporting-period basis - sourced
A27: Sources checked | B27: eAR Section 8b B0.1 (WRFinancialReportingPeriod); eAR Section 8b B0.2 (WRFiscalYearStartDate)
A28: What was found | B28: The reporting basis (fiscal vs calendar year) is read from the filer's own B0.1/B0.2 answer and staged verbatim, never hardcoded, so the 990 comparison and the residual are period-aligned.
A30: Member (shareholder) count denominator - not reported
A31: Sources checked | B31: Form 990 (no member count stated); company website
A32: What was found | B32: No filing states a member/shareholder count, so the per-member unit economics read not reported rather than borrowing the connection count.
A34: Water volume delivered (acre-feet) - not reported
A35: Sources checked | B35: Form 990 (not in the filing); Consumer Confidence Report; eAR Section 6 (PRA-gated)
A36: What was found | B36: Volume delivered in acre-feet is not in the Form 990 and the CCR states only a source mix, so the per-acre-foot metrics read not reported; the eAR Section 6 is named as the source still needed.

Sheet Water Operations
A1: Painted Cave Mutual Water Company
A2: Water Operations (sourced outside the financial filings)
A3: Entity ID: cawc_0022 | Fiscal year ends March 31.
A5: A separate dialect of data from the financial statements: the system's water supply, from the California State Water Board records (the Consumer Confidence Report served by the eAR portal, and SDWIS Drinking Water Watch). Each field carries its source, year, and confidence the same way a financial line item does; a field the source does not state reads 'not reported' with the source still needed. Figures are as reported, never estimated or reconciled across sources.
A7: Field | B7: Value | C7: Source | D7: Year | E7: Confidence | F7: Source excerpt / cross-source note
A8: Water type | B8: Potable (community drinking water) | C8: SDWIS Drinking Water Watch (State Water Board) | D8: 2024 | E8: high | F8: PAINTED CAVE: State Water System Type = Community.
A9: Source mix | B9: Primary source: local groundwater wells (SDWIS Primary Water Source Type: Groundwater). SDWIS classifies the primary supply type; it states no acre-foot volume by source. | C9: SDWIS Drinking Water Watch (State Water Board) | D9: 2024 | E9: high | F9: PAINTED CAVE: Primary Water Source Type = Groundwater.
A10: Service connections (total) | B10: 91 connections | C10: SDWIS Drinking Water Watch (State Water Board) | D10: 2024 | E10: high | F10: PAINTED CAVE: Total Number of Service Connections = 91. [cross-source: SDWIS connection snapshot; the eAR reports active service connections on its own basis and per reporting year. Both preserved, not reconciled.]
A11: Connections by class | B11: Service connections by type (SDWIS snapshot): Residential 91; Total 91. | C11: SDWIS Drinking Water Watch (State Water Board) | D11: 2024 | E11: high | F11: PAINTED CAVE: connections by type - Residential 91; Total 91.
A12: Population served | B12: 160 residents | C12: SDWIS Drinking Water Watch (State Water Board) | D12: 2024 | E12: high | F12: PAINTED CAVE: Total Population = 160.
A13: Treatment and water quality | B13: Operator certification on file: Distribution Operator Level 1. SDWIS states operator grades, not the treatment process detail. | C13: SDWIS Drinking Water Watch (State Water Board) | D13: 2024 | E13: high | F13: PAINTED CAVE: Treatment Plant Class = not stated; Distribution System Class = Distribution Operator Level 1.
A15: Not reported (source still needed)
A16: Annual volume delivered (acre-feet) | B16: not reported - needs annual volume in acre-feet (State Water Board eAR Section 6 or company production records); the CCR states only a percentage mix
A17: Customer classes served | B17: not reported - needs the State Water Board eAR or the system CCR

Sheet Sources & audit
A1: Painted Cave Mutual Water Company
A2: Sources & audit - full provenance and tie-outs (kept off the statements so they read clean)
A3: Entity ID: cawc_0022 | Fiscal year ends March 31.
A5: Presentation standard: every figure on the statement tabs is verified to its source filing and shown clean. A cell the filing does not report reads "not reported" (never estimated, never guessed).
A6: Citations, confidence tiers, and the filed-vs-computed tie-out checks live on the "Sources & audit" tab, keyed by cell, so every number is fully traceable without cluttering the statements. These pages are ready to use as filed.
A8: A. Filing provenance (one row per staged extraction)
A9: Fiscal year | B9: Period end | C9: Filing type | D9: Confidence | E9: Extraction ID | F9: Object ID | G9: Extracted by | H9: Extracted at | I9: Source URL
A10: FY2021 | B10: 2021-03-31 | C10: 990 | D10: high | E10: 122fa633-2aab-485b-8f32-538f3a84b440 | F10: 202103099349302695 | G10: claude-opus-5 | H10: 2026-09-16T21:34:13+00:00 | I10: https://apps.irs.gov/pub/epostcard/990/xml/2021/2021_TEOS_XML_01A.zip#202103099349302695_public.xml
A11: FY2022 | B11: 2022-03-31 | C11: 990 | D11: high | E11: 6d9285d8-c03b-40ee-86bd-af2529e359af | F11: 202201959349300240 | G11: claude-opus-5 | H11: 2026-09-16T21:34:13+00:00 | I11: https://apps.irs.gov/pub/epostcard/990/xml/2022/2022_TEOS_XML_01A.zip#202201959349300240_public.xml
A12: FY2023 | B12: 2023-03-31 | C12: 990 | D12: high | E12: 259206ac-b3a5-4faa-90a6-e64246fd9c92 | F12: 202332719349301558 | G12: claude-opus-5 | H12: 2026-09-16T21:34:13+00:00 | I12: https://apps.irs.gov/pub/epostcard/990/xml/2023/2023_TEOS_XML_10A.zip#202332719349301558_public.xml
A13: FY2024 | B13: 2024-03-31 | C13: 990 | D13: high | E13: 6e19394a-5c60-4427-86ca-a0686116f043 | F13: 202402539349300820 | G13: claude-opus-5 | H13: 2026-09-16T21:34:13+00:00 | I13: https://apps.irs.gov/pub/epostcard/990/xml/2024/2024_TEOS_XML_09A.zip#202402539349300820_public.xml
A14: FY2025 | B14: 2025-03-31 | C14: 990 | D14: high | E14: 67107be3-de5c-4c8b-bde3-796209cff693 | F14: 202512309349301406 | G14: claude-opus-5 | H14: 2026-09-16T21:34:13+00:00 | I14: https://apps.irs.gov/pub/epostcard/990/xml/2025/2025_TEOS_XML_08A.zip#202512309349301406_public.xml
A16: B. Figure citations (every figure on the statement tabs, keyed by cell)
A17: Tab | B17: Cell | C17: Line item | D17: Form 990 line | E17: Key path | F17: Confidence | G17: As filed
A18: Revenue (detail) | B18: B7 | C18: 1h. Total contributions, gifts, grants | D18: 1h | E18: part_viii_revenue.total_contributions | F18: high | G18: 4000
A19: Revenue (detail) | B19: C7 | C19: 1h. Total contributions, gifts, grants | D19: 1h | E19: part_viii_revenue.total_contributions | F19: high | G19: 0
A20: Revenue (detail) | B20: D7 | C20: 1h. Total contributions, gifts, grants | D20: 1h | E20: part_viii_revenue.total_contributions | F20: high | G20: 0
A21: Revenue (detail) | B21: E7 | C21: 1h. Total contributions, gifts, grants | D21: 1h | E21: part_viii_revenue.total_contributions | F21: high | G21: 0
A22: Revenue (detail) | B22: F7 | C22: 1h. Total contributions, gifts, grants | D22: 1h | E22: part_viii_revenue.total_contributions | F22: high | G22: 300
A23: Revenue (detail) | B23: B8 | C23: 2g. Total program service revenue | D23: 2g | E23: part_viii_revenue.total_program_service_revenue | F23: high | G23: 19665
A24: Revenue (detail) | B24: C8 | C24: 2g. Total program service revenue | D24: 2g | E24: part_viii_revenue.total_program_service_revenue | F24: high | G24: 29721
A25: Revenue (detail) | B25: D8 | C25: 2g. Total program service revenue | D25: 2g | E25: part_viii_revenue.total_program_service_revenue | F25: high | G25: 36539
A26: Revenue (detail) | B26: E8 | C26: 2g. Total program service revenue | D26: 2g | E26: part_viii_revenue.total_program_service_revenue | F26: high | G26: 35270
A27: Revenue (detail) | B27: F8 | C27: 2g. Total program service revenue | D27: 2g | E27: part_viii_revenue.total_program_service_revenue | F27: high | G27: 41793
A28: Revenue (detail) | B28: B9 | C28: 3. Investment income | D28: 3 | E28: part_viii_revenue.investment_income | F28: high | G28: 4
A29: Revenue (detail) | B29: C9 | C29: 3. Investment income | D29: 3 | E29: part_viii_revenue.investment_income | F29: high | G29: 6
... A301: Net-assets reconciliation | B301: F10 | C301: 9. Other changes in net assets | D301: Part XI line 9 | E301: part_xi_reconciliation.other_changes_net_assets | F301: high | G301: -511394
A303: C. Tie-out checks (filed vs computed; any nonzero variance is flagged red)
A304: Tab | B304: Check | C304: Fiscal year | D304: Filed | E304: Computed | F304: Variance (computed - filed)
A305: Revenue (detail) | B305: 12. Total revenue | C305: FY2021 | D305: 23669 | E305: ='Revenue (detail)'!B13 | F305: =E305-D305
A306: Revenue (detail) | B306: 12. Total revenue | C306: FY2022 | D306: 29727 | E306: ='Revenue (detail)'!C13 | F306: =E306-D306
A307: Revenue (detail) | B307: 12. Total revenue | C307: FY2023 | D307: 36601 | E307: ='Revenue (detail)'!D13 | F307: =E307-D307
A308: Revenue (detail) | B308: 12. Total revenue | C308: FY2024 | D308: 36572 | E308: ='Revenue (detail)'!E13 | F308: =E308-D308
A309: Revenue (detail) | B309: 12. Total revenue | C309: FY2025 | D309: 44152 | E309: ='Revenue (detail)'!F13 | F309: =E309-D309
A310: Revenue (detail) | B310: 2g program service revenue = sum of lines 2a-2f (FY2025) | C310: FY2025 | D310: 41793 | E310: =SUM('Revenue (detail)'!C17:C18) | F310: =E310-D310
A311: Operating expenses (detail) | B311: 25. Total functional expenses | C311: FY2021 | D311: 36675 | E311: ='Operating expenses (detail)'!B45 | F311: =E311-D311
A312: Operating expenses (detail) | B312: 25. Total functional expenses | C312: FY2022 | D312: 44594 | E312: ='Operating expenses (detail)'!C45 | F312: =E312-D312
A313: Operating expenses (detail) | B313: 25. Total functional expenses | C313: FY2023 | D313: 48279 | E313: ='Operating expenses (detail)'!D45 | F313: =E313-D313
A314: Operating expenses (detail) | B314: 25. Total functional expenses | C314: FY2024 | D314: 45363 | E314: ='Operating expenses (detail)'!E45 | F314: =E314-D314
A315: Operating expenses (detail) | B315: 25. Total functional expenses | C315: FY2025 | D315: 47167 | E315: ='Operating expenses (detail)'!F45 | F315: =E315-D315
...

Sheet Provenance
A1: Build provenance | B1: Built from source commit d418ffb17485 (2026-10-06); source fingerprint a75a8eee82c65cf7; 192 companies (179 retail mutual, 4 irrigation mutual, 3 mutual, no PWSID, purpose not stated, 2 frozen non-mutual (special district), 2 wholesale mutual, 1 frozen non-mutual (investor-owned), 1 frozen non-mutual (municipal)); 91 gates; build id 3d08d6d2a855.
A2: source_commit | B2: d418ffb174855ab78000d391d42f898397b0d8aa
A3: source_commit_date | B3: 2026-10-06
A4: source_fingerprint | B4: a75a8eee82c65cf7096931f06e18affdc28686a02895b46538e7298b57c04d94
A5: gate_count | B5: 91
A6: build_id | B6: 3d08d6d2a855
A7: registry: frozen non-mutual (investor-owned) | B7: 1
A8: registry: frozen non-mutual (municipal) | B8: 1
A9: registry: frozen non-mutual (special district) | B9: 2
A10: registry: irrigation mutual | B10: 4
A11: registry: mutual, no PWSID, purpose not stated | B11: 3
A12: registry: retail mutual | B12: 179
A13: registry: wholesale mutual | B13: 2
