Workbook

Sheet Summary
A1: Anza Vineyard Estates Mutual Water Company
A2: Financial Summary - multi-year overview (USD)
A3: Entity ID: cawc_0079 | Fiscal year ends December 31.
A5: Presentation standard: every figure on the statement tabs is verified to its source filing and shown clean. A cell the filing does not report reads "not reported" (never estimated, never guessed).
A6: Citations, confidence tiers, and the filed-vs-computed tie-out checks live on the "Sources & audit" tab, keyed by cell, so every number is fully traceable without cluttering the statements. These pages are ready to use as filed.
A8: Metric | B8: FY2021 | C8: FY2022 | D8: FY2023 | E8: FY2024
A9: Operating results (USD)
A10: Total revenue | B10: 153838 | C10: 311649 | D10: 223007 | E10: 271878
A11: Total expenses | B11: 153838 | C11: 311649 | D11: 223007 | E11: 271878
A12: Net income | C12: 0 | D12: 0 | E12: 0
A14: Financial position (USD, end of year)
A15: Total assets | B15: 110832 | C15: 118551 | D15: 138234 | E15: 128007
A16: Total liabilities | B16: 2500 | C16: 16380 | D16: 0 | E16: 0
A17: Net assets | B17: 108332 | C17: 102171 | D17: 138234 | E17: 128007
A19: Headline ratios
A20: Operating margin | C20: 0 | D20: 0 | E20: 0
A21: Revenue growth (YoY) | C21: 1.0258259 | D21: -0.28442896 | E21: 0.21914559
A22: Return on assets | C22: 0 | D22: 0 | E22: 0
A24: Figures as reported in source filings (full provenance on the Sources & audit tab). Parentheses denote negatives; ratios are computed upstream in financials_annual.

Sheet Notes
A1: Notes
A2: Human annotations from the versioned store (data/notes/). Annotations only: they never change a reported figure or a confidence tier.
A4: Date | B4: Tag | C4: Author | D4: Note
A5: No notes recorded yet.

Sheet Financial Statements
A1: Anza Vineyard Estates Mutual Water Company
A2: Financial Statements - income statement, balance sheet, cash flow, member income test (USD)
A3: Entity ID: cawc_0079 | Fiscal year ends December 31.
A5: INCOME STATEMENT - as reported (USD)
A6: Line item | B6: FY2021 | C6: FY2022 | D6: FY2023 | E6: FY2024
A7: Revenue
A8: Program service revenue
A9: Investment income
A10: Net rental income
A11: Net gain/(loss) on investment sales
A12: Other revenue | C12: 223161 | D12: 63937 | E12: 114227
A13: Contributions & grants | C13: 88488 | D13: 159070 | E13: 157651
A14: Total revenue | C14: 311649 | D14: 223007 | E14: 271878
A16: Expenses
A17: Depreciation | C17: 9965 | D17: 14552 | E17: 15979
A18: Interest expense
A19: Total expenses | B19: 153838 | C19: 311649 | D19: 223007 | E19: 271878
A21: Net income | C21: 0 | D21: 0 | E21: 0
A24: BALANCE SHEET - as reported (USD, end of year)
A25: Line item | B25: FY2021 | C25: FY2022 | D25: FY2023 | E25: FY2024
A26: Assets
A27: Cash | B27: 24292 | C27: 4369 | D27: 11546 | E27: 17298
A28: Savings & temporary investments
A29: Accounts receivable
A30: Inventories
A31: Prepaid expenses
A32: Property, plant & equipment (gross) | C32: 128661 | D32: 155719 | E32: 155719
A33: Less: accumulated depreciation | C33: -14479 | D33: -29031 | E33: -45010
A34: Net property, plant & equipment | C34: 114182 | D34: 126688 | E34: 110709
A35: Total assets | B35: 110832 | C35: 118551 | D35: 138234 | E35: 128007
A37: Liabilities
A38: Accounts payable
A39: Mortgages & notes payable
A40: Total liabilities | B40: 2500 | C40: 16380 | D40: 0 | E40: 0
A42: Net Assets / Equity
A43: Capital stock | C43: 0 | D43: 0 | E43: 0
A44: Paid-in capital | C44: 0 | D44: 0 | E44: 0
A45: Retained earnings | C45: 102171 | D45: 138234 | E45: 128007
A46: Net assets | B46: 108332 | C46: 102171 | D46: 138234 | E46: 128007
A49: CASH FLOW - derived proxy (USD)
...

Sheet Balance Sheet
A1: Anza Vineyard Estates Mutual Water Company
A2: Balance Sheet - as reported (USD, end of year)
A3: Entity ID: cawc_0079 | Fiscal year ends December 31.
A5: Line item | B5: FY2021 | C5: FY2022 | D5: FY2023 | E5: FY2024
A6: Assets
A7: Cash | B7: 24292 | C7: 4369 | D7: 11546 | E7: 17298
A8: Savings & temporary investments
A9: Accounts receivable
A10: Inventories
A11: Prepaid expenses
A12: Property, plant & equipment (gross) | C12: 128661 | D12: 155719 | E12: 155719
A13: Less: accumulated depreciation | C13: -14479 | D13: -29031 | E13: -45010
A14: Net property, plant & equipment | C14: 114182 | D14: 126688 | E14: 110709
A15: Total assets | B15: 110832 | C15: 118551 | D15: 138234 | E15: 128007
A17: Liabilities
A18: Accounts payable
A19: Mortgages & notes payable
A20: Total liabilities | B20: 2500 | C20: 16380 | D20: 0 | E20: 0
A22: Net Assets / Equity
A23: Capital stock | C23: 0 | D23: 0 | E23: 0
A24: Paid-in capital | C24: 0 | D24: 0 | E24: 0
A25: Retained earnings | C25: 102171 | D25: 138234 | E25: 128007
A26: Net assets | B26: 108332 | C26: 102171 | D26: 138234 | E26: 128007
A28: Balance check (assets − liab. − net assets) | B28: 0 | C28: 0 | D28: 0 | E28: 0
A30: Net PP&E is the reported ppe_net column (gross less accumulated depreciation). The balance check should be ~0 where all three totals are reported; a non-zero value flags a reporting or extraction discrepancy worth reviewing.

Sheet Officers & contractors
A1: Anza Vineyard Estates Mutual Water Company
A2: Officers, Directors & Contractors - Form 990 Part VII (FY2024; USD)
A3: Entity ID: cawc_0079 | Fiscal year ends December 31.
A5: Section A - Officers, directors, trustees, key employees
A6: Name | B6: Title | C6: Reportable comp (org) | D6: Reportable comp (related) | E6: Other comp | F6: Total compensation
A7: HENRY WARSHAW | B7: PRESIDENT | C7: 0 | D7: 0 | E7: 0 | F7: 0
A8: BILL SPRESSER | B8: VICE PRESIDENT | C8: 0 | D8: 0 | E8: 0 | F8: 0
A9: NANCY AHRENS | B9: SECRETARY | C9: 0 | D9: 0 | E9: 0 | F9: 0
A10: JUSTIN WICKERSHAM | B10: CEO | C10: 0 | D10: 0 | E10: 0 | F10: 0
A11: SHANE WOLF | B11: TREASURER, CFO | C11: 0 | D11: 0 | E11: 0 | F11: 0
A13: Section B - Independent contractors (over $100,000)
A14: Contractor | B14: Services | C14: Compensation
A16: Section A lists every officer, director, trustee and key employee filed for the latest year; the two with the highest total compensation are highlighted. Total compensation is computed (reportable org + related + other). Section B lists each independent contractor paid over $100,000; the return reports 0 such contractor(s). Source and confidence for every figure are on the Sources & audit tab.

Sheet Revenue (detail)
A1: Anza Vineyard Estates Mutual Water Company
A2: Revenue - Form 990 Part VIII (USD)
A3: Entity ID: cawc_0079 | Fiscal year ends December 31.
A5: Part VIII line | B5: FY2022 | C5: FY2023 | D5: FY2024
A6: Revenue by category
A7: 1h. Total contributions, gifts, grants | B7: 88488 | C7: 159070 | D7: 157651
A8: 2g. Total program service revenue | B8: not reported | C8: not reported | D8: not reported
A9: 3. Investment income | B9: not reported | C9: not reported | D9: not reported
A10: 6d. Net rental income | B10: not reported | C10: not reported | D10: not reported
A11: 7d. Net gain/(loss) from investment sales | B11: not reported | C11: not reported | D11: not reported
A12: 11e. Other revenue | B12: 223161 | C12: 63937 | D12: 114227
A13: 12. Total revenue | B13: =SUM(B7:B12) | C13: =SUM(C7:C12) | D13: =SUM(D7:D12)
A15: Revenue category subtotals are as filed. Total revenue (line 12) is a live SUM of the category cells above; its tie-out to the filed total is on the Sources & audit tab. Program service revenue detail is shown for the latest year, with its sum-to-line-2g check on that same audit tab.

Sheet Operating expenses (detail)
A1: Anza Vineyard Estates Mutual Water Company
A2: Statement of Functional Expenses - Form 990 Part IX (USD)
A3: Entity ID: cawc_0079 | Fiscal year ends December 31.
A5: Part IX line (column A Total) | B5: FY2022 | C5: FY2023 | D5: FY2024
A6: Functional expenses, column A Total - by year
A7: 16. Occupancy | B7: 90599 | C7: 37266 | D7: 46477
A8: 22. Depreciation, depletion, and amortization | B8: 9965 | C8: 14552 | D8: 15979
A9: 23. Insurance | B9: 23682 | C9: 23834 | D9: 2386
A10: 24. MANAGEMENT | B10: 146055 | C10: 101929 | D10: 132004
A11: 24. UTILITIES | B11: 39952 | C11: 25937 | D11: 37370
A12: 24. TAXES & LICENSES | B12: 800 | C12: not reported | D12: not reported
A13: 24. OFFICE EXPENSE | B13: 481 | C13: not reported | D13: not reported
A14: 24. PROFESSIONAL FEES | B14: not reported | C14: 7725 | D14: 11983
A15: 24. WEED ABATEMENT | B15: not reported | C15: 6815 | D15: 18844
A16: 24e. All other expenses | B16: 115 | C16: 4949 | D16: 6835
A17: 25. Total functional expenses | B17: =SUM(B7:B16) | C17: =SUM(C7:C16) | D17: =SUM(D7:D16)
A19: Functional column split - FY2024
A20: Not reported. This filer reports only column A (Total) of Part IX; the program / management / fundraising split (columns B-D) is not filed, so it is left as not reported rather than shown empty or inferred.
A21: Top block: each Part IX line, column A (Total), by year, as filed. Total functional expenses (line 25) is a live SUM of the line cells; its tie-out to the filed total is on the Sources & audit tab. Filer-itemized 24a-24d rows show the most recent year's as-filed wording; rows are aligned across years case-insensitively with collapsed spacing, so a line filed only in a different capitalization or spacing shares one row, while genuinely different wording stays a separate row (every as-filed variant is recorded on the Sources & audit tab). This filer reports only column A (Total); the program / management / fundraising split (columns B-D) is not reported. Lines this filer does not report are omitted rather than shown empty.

Sheet Balance sheet (detail)
A1: Anza Vineyard Estates Mutual Water Company
A2: Balance Sheet - Form 990 Part X (end of year, USD)
A3: Entity ID: cawc_0079 | Fiscal year ends December 31.
A5: Part X line (column B, EOY) | B5: FY2022 | C5: FY2023 | D5: FY2024
A6: Assets
A7: 1. Cash - non-interest-bearing | B7: 4369 | C7: 11546 | D7: 17298
A8: 10c. Land, buildings, and equipment, net | B8: 114182 | C8: 126688 | D8: 110709
A9: 16. Total assets | B9: =SUM(B7:B8) | C9: =SUM(C7:C8) | D9: =SUM(D7:D8)
A11: Liabilities
A12: 25. Other liabilities | B12: 16380 | C12: 0 | D12: not reported
A13: 26. Total liabilities | B13: =SUM(B12:B12) | C13: =SUM(C12:C12) | D13: =SUM(D12:D12)
A15: Net assets / fund balances
A16: 29. Capital stock or trust principal | B16: 0 | C16: 0 | D16: 0
A17: 30. Paid-in or capital surplus | B17: 0 | C17: 0 | D17: 0
A18: 31. Retained earnings / accumulated funds | B18: 102171 | C18: 138234 | D18: 128007
A19: 32. Total net assets / fund balances | B19: =SUM(B16:B18) | C19: =SUM(C16:C18) | D19: =SUM(D16:D18)
A21: Every Part X line is end-of-year (column B), as filed. Section totals (lines 16 / 26 / 32) are live SUMs of the lines above; their tie-outs and the balance-sheet identity (16 = 26 + 32) are on the Sources & audit tab. This filer files as a non-FASB mutual, so net assets sit on lines 29-31 (capital stock / paid-in capital / retained earnings); lines this filer does not report are omitted. Lines 10a/10b net into line 10c (shown).

Sheet Net-assets reconciliation
A1: Anza Vineyard Estates Mutual Water Company
A2: Reconciliation of Net Assets - Form 990 Part XI (USD)
A3: Entity ID: cawc_0079 | Fiscal year ends December 31.
A5: Part XI line | B5: FY2022 | C5: FY2023 | D5: FY2024
A6: Reconciliation
A7: 4. Net assets, beginning of year | B7: 108332 | C7: 102171 | D7: 138234
A8: 3. Revenue less expenses | B8: 0 | C8: 0 | D8: 0
A9: 8. Prior period adjustments | B9: not reported | C9: not reported | D9: not reported
A10: 9. Other changes in net assets | B10: -6161 | C10: 36063 | D10: -10227
A11: 10. Net assets, end of year | B11: =SUM(B7,B8,B9,B10) | C11: =SUM(C7,C8,C9,C10) | D11: =SUM(D7,D8,D9,D10)
A13: Part XI reconciles beginning to ending net assets. Ending net assets (line 10) is a live formula: beginning balance (line 4) + revenue less expenses (line 3) + prior-period adjustments (8) + other changes (9). Its tie-out to the filed line 10 (and to Part X line 32) is on the Sources & audit tab. Lines 5-7 (unrealized gains, donated services, investment expenses) are not filed by this entity.

Sheet Cash flow proxies
A1: Anza Vineyard Estates Mutual Water Company
A2: Cash Flow Proxies - derived (USD)
A3: Entity ID: cawc_0079 | Fiscal year ends December 31.
A5: PROXY ONLY. The source filings contain no statement of cash flows. Lines below are derived from the reported income statement and year-over-year balance-sheet changes; treat as directional estimates, not GAAP cash flows. The earliest year has no prior period, so its delta cells are blank.
A7: Proxy line (USD) | B7: FY2021 | C7: FY2022 | D7: FY2023 | E7: FY2024
A8: Operating
A9: Net income | C9: 0 | D9: 0 | E9: 0
A10: + Depreciation (reported) | C10: 9965 | D10: 14552 | E10: 15979
A11: − Δ Accounts receivable
A12: − Δ Inventories
A13: − Δ Prepaid expenses
A14: + Δ Accounts payable
A15: Operating cash flow proxy | C15: 9965 | D15: 14552 | E15: 15979
A17: Investing
A18: − Δ PP&E gross (capex proxy) | D18: -27058 | E18: 0
A20: Financing
A21: Δ Mortgages & notes payable
A23: Reconciliation
A24: Δ Cash + temp. investments (actual) | C24: -19923 | D24: 7177 | E24: 5752
A26: The capex proxy assumes gross PP&E rises only via capital spending (it ignores disposals). 'Δ Cash + temp. investments (actual)' is the real reported change in liquid funds and is the most reliable line here; the operating/investing/financing proxies will not perfectly reconcile to it.

Sheet Ratios
A1: Anza Vineyard Estates Mutual Water Company
A2: Financial Ratios
A3: Entity ID: cawc_0079 | Fiscal year ends December 31.
A5: Ratio | B5: FY2021 | C5: FY2022 | D5: FY2023 | E5: FY2024
A6: Profitability (computed upstream)
A7: Operating margin (NI / revenue) | C7: 0 | D7: 0 | E7: 0
A8: Expense ratio (expenses / revenue) | B8: 1 | C8: 1 | D8: 1 | E8: 1
A9: Return on assets (NI / assets) | C9: 0 | D9: 0 | E9: 0
A10: Revenue growth (YoY) | C10: 1.0258259 | D10: -0.28442896 | E10: 0.21914559
A12: Leverage & solvency
A13: Debt-to-assets (liab. / assets) | B13: 0.022556662 | C13: 0.13816838 | D13: 0 | E13: 0
A14: Equity ratio (net assets / assets) | B14: 0.97744334 | C14: 0.86183162 | D14: 1 | E14: 1
A16: Liquidity & asset profile (derived here)
A17: Current ratio (current assets / AP)
A18: Cash ratio ((cash+temp inv.) / total liab.) | B18: 9.7168 | C18: 0.26672772
A19: Asset age proxy (accum. deprec. / gross PP&E) | C19: 0.11253604 | D19: 0.18643197 | E19: 0.28904629
A21: Upstream ratios are read from financials_annual; derived ratios are computed only where inputs are reported. Current ratio uses accounts payable as the current-liability proxy (the filings do not split current vs. long-term liabilities). Asset age proxy: a higher % implies older / more depreciated infrastructure.

Sheet Unit economics
A1: Anza Vineyard Estates Mutual Water Company
A2: Unit economics - per-customer revenue by category (USD)
A3: Entity ID: cawc_0079 | Fiscal year ends December 31.
A5: Every metric here is PER CUSTOMER (a metered service connection). It is not a per-member figure; the member (shareholder) count is a different denominator, shown in the denominator block. The visible cell shows the value and its classification; the numerator, denominator, formula, and rationale are in each metric's LOGIC popup.
A6: Per-customer denominator (service connections) | C6: State Water Board eAR Section 4
A7: Total annual revenue (eAR Section 8b B1.8) | C7: eAR Section 8b total annual revenue not reported for this system.
A8: Primary source
A10: Revenue categories (value, classification, per customer, share)
A11: Revenue category | B11: Classification | C11: Value (USD) | D11: Per customer | E11: Share of revenue
A12: Water sales revenue | B12: not reported | C12: not reported | D12: not reported | E12: not reported
A13: Assessment revenue (990 program-service revenue not matched to eAR water-rate revenue) | B13: IMPOSSIBLE | C13: IMPOSSIBLE | D13: IMPOSSIBLE | E13: IMPOSSIBLE
A14: Meter revenue | B14: not reported | C14: not reported | D14: not reported | E14: not reported
A15: Overage or tiered penalty revenue | B15: not reported | C15: not reported | D15: not reported | E15: not reported
A17: Water sales revenue - not reported
A18: Not reported: this system filed an eAR but no Section 8b revenue block, so there is no filed water-sales figure. Not fallen back to a different year.
A19: Reason: No filed eAR Section 8b water-rate revenue for this system.
A21: Assessment revenue (990 program-service revenue not matched to eAR water-rate revenue) - IMPOSSIBLE
A22: Not computed. A period-aligned residual is not possible for this filer.
A23: Reason: Not derivable. The eAR Section 8b is reporting year None while the Form 990 fiscal year ends None; the two period ends are not aligned, so a period-aligned residual cannot be computed.
A25: Meter revenue - not reported
A26: Not reported. This category is not built because doing so would double-count.
A27: Reason: The eAR Section 8a reports a base/meter rate PRICE, but the filing carries no meter revenue line and no tier volume, and the base charge is already inside the water-sales revenue (eAR Section 8b water rates). Building a separate meter figure would double-count. Not backed into from a total.
A29: Overage or tiered penalty revenue - not reported
A30: Not reported. This category is not built because doing so would double-count.
A31: Reason: The eAR Section 8a reports tiered/overage rate PRICES, but the filing carries no overage revenue and no tier consumption volume, and any overage billed is already inside the water-sales revenue. Building it would double-count. Not backed into from a total.

Sheet Rate structure
A1: Anza Vineyard Estates Mutual Water Company
A2: Rate structure and representative bill - eAR Section 8a
A3: Entity ID: cawc_0079 | Fiscal year ends December 31.
A5: This block is a rate-schedule illustration at defined usage levels. It is NOT billed revenue and not a claim about any real customer's usage. The revenue side of unit economics is the separate Unit Economics block.
A6: No filed eAR Section 8a rate schedule is staged for this system.

Sheet Operational metrics
A1: Anza Vineyard Estates Mutual Water Company
A2: Operational metrics - plant per acre, density, terrain
A3: Entity ID: cawc_0079 | Fiscal year ends December 31.
A5: Plant assets per acre
A6: Service-area acres | B6: 554.5 | C6: Geodesic area (WGS84 spherical excess) of the SABL service-area polygon.
A7: Fiscal year | B7: Gross plant per acre (primary) | C7: Net plant per acre
A8: FY2021
A9: FY2022 | B9: 232.0307 | C9: 205.9188
A10: FY2023 | B10: 280.8278 | C10: 228.4725
A11: FY2024 | B11: 280.8278 | C11: 199.6555
A12: Infrastructure built per acre of service area. Gross plant per acre is the primary read because it measures how much plant the system has put in the ground per acre, and unlike net plant it does not fall over time purely because the assets depreciate on the books. Net plant per acre is shown alongside as the depreciated book value per acre.
A13: Formula: gross plant per acre = Form 990 Part X line 10a (land, buildings, and equipment, gross) / SABL service-area acres; net plant per acre uses Part X line 10c (net)
A14: Source lines: Form 990 Part X line 10a (gross) and line 10c (net); Geodesic area (WGS84 spherical excess) of the SABL service-area polygon.
A15: Confidence: medium. This is worked out from filed figures (a ratio, or a year-to-year change), so it is one step removed from the raw numbers.. Filed gross/net plant over the measured SABL service-area acreage.
A17: Connections per acre
A18: Connections per acre | B18: 0.02 | C18: 13 connections / 554.5 acres. CA State Water Board SABL SERVICE_CONNECTIONS; Geodesic area (WGS84 spherical excess) of the SABL service-area polygon.

Sheet Supply & weather
A1: Anza Vineyard Estates Mutual Water Company
A2: Supply and weather indicators (DWR water year)
A3: Entity ID: cawc_0079 | Fiscal year ends December 31.
A5: Reporting calendar: Different reporting periods. The DWR water year runs October 1 to September 30; this system's fiscal year ends December 31, so the two period ends are three months apart. Read the two side by side with that in mind. Neither series is recast: both are reported as filed. A water year is named for the calendar year it ends in, so WY2024 and FY2024 share a number without covering the same twelve months.
A7: Indicator | B7: WY2021 | C7: WY2022 | D7: WY2023 | E7: WY2024
A8: Water-year type (Sacramento Valley) | B8: Critical | C8: Critical | D8: Wet | E8: Above Normal
A9: Peak drought, county County | B9: not reported | C9: not reported | D9: not reported | E9: not reported
A10: Precip, percent of normal (8-Station Index) | B10: 48 | C10: 86 | D10: 133 | E10: 96
A11: Snowpack, April 1 percent of average | B11: 59% | C11: 38% | D11: 237% | E11: 110%
A12: State Water Project allocation | B12: 5% | C12: 5% | D12: 100% | E12: 40%

Sheet How this was built
A1: Anza Vineyard Estates Mutual Water Company
A2: How this was built - forensic lineage
A3: Entity ID: cawc_0079 | Fiscal year ends December 31.
A5: A plain account of the forensic lineage behind the hard-to-source metrics: what sources were checked, what was found, what was derived, and what could not be built and why. Every figure marked DERIVED or IMPOSSIBLE above is traceable to a line here.
A7: Water-sales revenue per customer - not reported
A8: Sources checked | B8: State Water Board eAR Section 8b (water-rate revenue B1.1/B1.2); State Water Board eAR Section 4 (connection count, same reporting year); audited financial statement (secondary cross-check, where published)
A9: What was found | B9: The eAR Section 8b reports water-rate revenue for reporting year None, so this is a DIRECT filed figure; per customer it is divided by the eAR Section 4 connection count for the same reporting year, so numerator and denominator share the year.
A11: Assessment revenue (residual) - IMPOSSIBLE
A12: Sources checked | B12: Form 990 Part VIII line 2 (program-service revenue); State Water Board eAR Section 8b (water-rate revenue B1.1/B1.2); eAR Section 8b filer comment (WRRevenueComments)
A13: What was found | B13: A period-aligned residual cannot be computed for this filer, so the metric is rendered IMPOSSIBLE rather than guessed.
A14: Caveat | B14: Not derivable. The eAR Section 8b is reporting year None while the Form 990 fiscal year ends None; the two period ends are not aligned, so a period-aligned residual cannot be computed.
A16: Meter revenue - not reported
A17: Sources checked | B17: State Water Board eAR Section 8a (rate prices); State Water Board eAR Section 8b (revenue lines); audited financial statement
A18: What was found | B18: The rate price exists in Section 8a but no revenue or tier volume is reported, and the base charge is already inside water sales.
A19: Caveat | B19: The eAR Section 8a reports a base/meter rate PRICE, but the filing carries no meter revenue line and no tier volume, and the base charge is already inside the water-sales revenue (eAR Section 8b water rates). Building a separate meter figure would double-count. Not backed into from a total.
A21: Overage / tiered-penalty revenue - not reported
A22: Sources checked | B22: State Water Board eAR Section 8a (rate prices); State Water Board eAR Section 8b (revenue lines); audited financial statement
A23: What was found | B23: The rate price exists in Section 8a but no revenue or tier volume is reported, and the base charge is already inside water sales.
A24: Caveat | B24: The eAR Section 8a reports tiered/overage rate PRICES, but the filing carries no overage revenue and no tier consumption volume, and any overage billed is already inside the water-sales revenue. Building it would double-count. Not backed into from a total.
A26: eAR Section 8b reporting-period basis - sourced
A27: Sources checked | B27: eAR Section 8b B0.1 (WRFinancialReportingPeriod); eAR Section 8b B0.2 (WRFiscalYearStartDate)
A28: What was found | B28: The reporting basis (fiscal vs calendar year) is read from the filer's own B0.1/B0.2 answer and staged verbatim, never hardcoded, so the 990 comparison and the residual are period-aligned.
A30: Member (shareholder) count denominator - not reported
A31: Sources checked | B31: Form 990 (no member count stated); company website
A32: What was found | B32: No filing states a member/shareholder count, so the per-member unit economics read not reported rather than borrowing the connection count.
A34: Water volume delivered (acre-feet) - not reported
A35: Sources checked | B35: Form 990 (not in the filing); Consumer Confidence Report; eAR Section 6 (PRA-gated)
A36: What was found | B36: Volume delivered in acre-feet is not in the Form 990 and the CCR states only a source mix, so the per-acre-foot metrics read not reported; the eAR Section 6 is named as the source still needed.

Sheet Sources & audit
A1: Anza Vineyard Estates Mutual Water Company
A2: Sources & audit - full provenance and tie-outs (kept off the statements so they read clean)
A3: Entity ID: cawc_0079 | Fiscal year ends December 31.
A5: Presentation standard: every figure on the statement tabs is verified to its source filing and shown clean. A cell the filing does not report reads "not reported" (never estimated, never guessed).
A6: Citations, confidence tiers, and the filed-vs-computed tie-out checks live on the "Sources & audit" tab, keyed by cell, so every number is fully traceable without cluttering the statements. These pages are ready to use as filed.
A8: A. Filing provenance (one row per staged extraction)
A9: Fiscal year | B9: Period end | C9: Filing type | D9: Confidence | E9: Extraction ID | F9: Object ID | G9: Extracted by | H9: Extracted at | I9: Source URL
A10: FY2021 | B10: 2021-12-31 | C10: 990-EZ | D10: high | E10: aa86d8b2-3c2a-4c0e-8c71-b98a5db50532 | F10: 202233189349208283 | G10: claude-opus-5 | H10: 2026-09-21T02:50:00+00:00 | I10: https://apps.irs.gov/pub/epostcard/990/xml/2022/2022_TEOS_XML_02A.zip#202233189349208283_public.xml
A11: FY2022 | B11: 2022-12-31 | C11: 990 | D11: high | E11: db489f9e-57b2-4b8c-bba7-42057b16cb6a | F11: 202303199349321855 | G11: claude-opus-5 | H11: 2026-09-21T02:50:00+00:00 | I11: https://apps.irs.gov/pub/epostcard/990/xml/2023/2023_TEOS_XML_11A.zip#202303199349321855_public.xml
A12: FY2023 | B12: 2023-12-31 | C12: 990 | D12: high | E12: 9c3335bb-c58c-47cf-94d8-9912aadf2c85 | F12: 202433209349325498 | G12: claude-opus-5 | H12: 2026-09-21T02:50:00+00:00 | I12: https://apps.irs.gov/pub/epostcard/990/xml/2024/2024_TEOS_XML_11A.zip#202433209349325498_public.xml
A13: FY2024 | B13: 2024-12-31 | C13: 990 | D13: high | E13: 2c1c7930-1873-46db-8693-eb3beaa453e8 | F13: 202523199349301677 | G13: claude-opus-5 | H13: 2026-09-21T02:50:00+00:00 | I13: https://apps.irs.gov/pub/epostcard/990/xml/2025/2025_TEOS_XML_11C.zip#202523199349301677_public.xml
A15: B. Figure citations (every figure on the statement tabs, keyed by cell)
A16: Tab | B16: Cell | C16: Line item | D16: Form 990 line | E16: Key path | F16: Confidence | G16: As filed
A17: Financial Statements | B17: B73 | C17: 11a. Gross income from members or shareholders | D17: 11a | E17: part_v_other_irs_filings.members_and_shareholders_gross_income | F17: high | G17: 0
A18: Financial Statements | B18: C73 | C18: 11a. Gross income from members or shareholders | D18: 11a | E18: part_v_other_irs_filings.members_and_shareholders_gross_income | F18: high | G18: 0
A19: Financial Statements | B19: D73 | C19: 11a. Gross income from members or shareholders | D19: 11a | E19: part_v_other_irs_filings.members_and_shareholders_gross_income | F19: high | G19: 157651
A20: Financial Statements | B20: B74 | C20: 11b. Gross income from other sources | D20: 11b | E20: part_v_other_irs_filings.other_sources_gross_income | F20: high | G20: 0
A21: Financial Statements | B21: C74 | C21: 11b. Gross income from other sources | D21: 11b | E21: part_v_other_irs_filings.other_sources_gross_income | F21: high | G21: 0
A22: Financial Statements | B22: D74 | C22: 11b. Gross income from other sources | D22: 11b | E22: part_v_other_irs_filings.other_sources_gross_income | F22: high | G22: 0
A23: Revenue (detail) | B23: B7 | C23: 1h. Total contributions, gifts, grants | D23: 1h | E23: part_viii_revenue.total_contributions | F23: high | G23: 88488
A24: Revenue (detail) | B24: C7 | C24: 1h. Total contributions, gifts, grants | D24: 1h | E24: part_viii_revenue.total_contributions | F24: high | G24: 159070
A25: Revenue (detail) | B25: D7 | C25: 1h. Total contributions, gifts, grants | D25: 1h | E25: part_viii_revenue.total_contributions | F25: high | G25: 157651
A26: Revenue (detail) | B26: B12 | C26: 11e. Other revenue | D26: 11e | E26: part_viii_revenue.other_revenue_total | F26: high | G26: 223161
A27: Revenue (detail) | B27: C12 | C27: 11e. Other revenue | D27: 11e | E27: part_viii_revenue.other_revenue_total | F27: high | G27: 63937
A28: Revenue (detail) | B28: D12 | C28: 11e. Other revenue | D28: 11e | E28: part_viii_revenue.other_revenue_total | F28: high | G28: 114227
... A66: Net-assets reconciliation | B66: D10 | C66: 9. Other changes in net assets | D66: Part XI line 9 | E66: part_xi_reconciliation.other_changes_net_assets | F66: high | G66: -10227
A68: C. Tie-out checks (filed vs computed; any nonzero variance is flagged red)
A69: Tab | B69: Check | C69: Fiscal year | D69: Filed | E69: Computed | F69: Variance (computed - filed)
A70: Revenue (detail) | B70: 12. Total revenue | C70: FY2022 | D70: 311649 | E70: ='Revenue (detail)'!B13 | F70: =E70-D70
A71: Revenue (detail) | B71: 12. Total revenue | C71: FY2023 | D71: 223007 | E71: ='Revenue (detail)'!C13 | F71: =E71-D71
A72: Revenue (detail) | B72: 12. Total revenue | C72: FY2024 | D72: 271878 | E72: ='Revenue (detail)'!D13 | F72: =E72-D72
A73: Operating expenses (detail) | B73: 25. Total functional expenses | C73: FY2022 | D73: 311649 | E73: ='Operating expenses (detail)'!B17 | F73: =E73-D73
A74: Operating expenses (detail) | B74: 25. Total functional expenses | C74: FY2023 | D74: 223007 | E74: ='Operating expenses (detail)'!C17 | F74: =E74-D74
A75: Operating expenses (detail) | B75: 25. Total functional expenses | C75: FY2024 | D75: 271878 | E75: ='Operating expenses (detail)'!D17 | F75: =E75-D75
A76: Balance sheet (detail) | B76: 16. Total assets | C76: FY2022 | D76: 118551 | E76: ='Balance sheet (detail)'!B9 | F76: =E76-D76
A77: Balance sheet (detail) | B77: 16. Total assets | C77: FY2023 | D77: 138234 | E77: ='Balance sheet (detail)'!C9 | F77: =E77-D77
A78: Balance sheet (detail) | B78: 16. Total assets | C78: FY2024 | D78: 128007 | E78: ='Balance sheet (detail)'!D9 | F78: =E78-D78
A79: Balance sheet (detail) | B79: 26. Total liabilities | C79: FY2022 | D79: 16380 | E79: ='Balance sheet (detail)'!B13 | F79: =E79-D79
A80: Balance sheet (detail) | B80: 26. Total liabilities | C80: FY2023 | D80: 0 | E80: ='Balance sheet (detail)'!C13 | F80: =E80-D80
A81: Balance sheet (detail) | B81: 26. Total liabilities | C81: FY2024 | D81: 0 | E81: ='Balance sheet (detail)'!D13 | F81: =E81-D81
...

Sheet Provenance
A1: Build provenance | B1: Built from source commit d418ffb17485 (2026-10-06); source fingerprint a75a8eee82c65cf7; 192 companies (179 retail mutual, 4 irrigation mutual, 3 mutual, no PWSID, purpose not stated, 2 frozen non-mutual (special district), 2 wholesale mutual, 1 frozen non-mutual (investor-owned), 1 frozen non-mutual (municipal)); 91 gates; build id 3d08d6d2a855.
A2: source_commit | B2: d418ffb174855ab78000d391d42f898397b0d8aa
A3: source_commit_date | B3: 2026-10-06
A4: source_fingerprint | B4: a75a8eee82c65cf7096931f06e18affdc28686a02895b46538e7298b57c04d94
A5: gate_count | B5: 91
A6: build_id | B6: 3d08d6d2a855
A7: registry: frozen non-mutual (investor-owned) | B7: 1
A8: registry: frozen non-mutual (municipal) | B8: 1
A9: registry: frozen non-mutual (special district) | B9: 2
A10: registry: irrigation mutual | B10: 4
A11: registry: mutual, no PWSID, purpose not stated | B11: 3
A12: registry: retail mutual | B12: 179
A13: registry: wholesale mutual | B13: 2
