Workbook

Sheet Summary
A1: Prather Water District Inc
A2: Financial Summary - multi-year overview (USD)
A3: Entity ID: cawc_0187 | Fiscal year ends December 31.
A5: Presentation standard: every figure on the statement tabs is verified to its source filing and shown clean. A cell the filing does not report reads "not reported" (never estimated, never guessed).
A6: Citations, confidence tiers, and the filed-vs-computed tie-out checks live on the "Sources & audit" tab, keyed by cell, so every number is fully traceable without cluttering the statements. These pages are ready to use as filed.
A8: Metric | B8: FY2020 | C8: FY2021 | D8: FY2022 | E8: FY2023 | F8: FY2024
A9: Operating results (USD)
A10: Total revenue | B10: 129767 | C10: 106201 | D10: 204198 | E10: 201943 | F10: 99794
A11: Total expenses | B11: 88161 | C11: 85153 | D11: 134097 | E11: 89594 | F11: 91713
A12: Net income | B12: 41606 | C12: 21048 | D12: 70101 | E12: 112349 | F12: 8081
A14: Financial position (USD, end of year)
A15: Total assets | B15: 139308 | C15: 160356 | D15: 416638 | E15: 342806 | F15: 350887
A16: Total liabilities | D16: 186181 | E16: 0 | F16: 0
A17: Net assets | B17: 139308 | C17: 160356 | D17: 230457 | E17: 342806 | F17: 350887
A19: Headline ratios
A20: Operating margin | B20: 0.3206208 | C20: 0.19819022 | D20: 0.34329915 | E20: 0.55634016 | F20: 0.080976812
A21: Revenue growth (YoY) | E21: -0.011043203 | F21: -0.50583085
A22: Return on assets | B22: 0.29866196 | C22: 0.13125795 | D22: 0.16825398 | E22: 0.32773347 | F22: 0.023030206
A24: Figures as reported in source filings (full provenance on the Sources & audit tab). Parentheses denote negatives; ratios are computed upstream in financials_annual.

Sheet Notes
A1: Notes
A2: Human annotations from the versioned store (data/notes/). Annotations only: they never change a reported figure or a confidence tier.
A4: Date | B4: Tag | C4: Author | D4: Note
A5: No notes recorded yet.

Sheet Financial Statements
A1: Prather Water District Inc
A2: Financial Statements - income statement, balance sheet, cash flow, member income test (USD)
A3: Entity ID: cawc_0187 | Fiscal year ends December 31.
A5: INCOME STATEMENT - as reported (USD)
A6: Line item | B6: FY2020 | C6: FY2021 | D6: FY2022 | E6: FY2023 | F6: FY2024
A7: Revenue
A8: Program service revenue | D8: 29454 | E8: 22178
A9: Investment income
A10: Net rental income
A11: Net gain/(loss) on investment sales
A12: Other revenue
A13: Contributions & grants | D13: 174744 | E13: 179765 | F13: 99794
A14: Total revenue | D14: 204198 | E14: 201943 | F14: 99794
A16: Expenses
A17: Depreciation | D17: 43022 | E17: 22603 | F17: 16144
A18: Interest expense | F18: 16
A19: Total expenses | B19: 88161 | C19: 85153 | D19: 134097 | E19: 89594 | F19: 91713
A21: Net income | B21: 41606 | C21: 21048 | D21: 70101 | E21: 112349 | F21: 8081
A24: BALANCE SHEET - as reported (USD, end of year)
A25: Line item | B25: FY2020 | C25: FY2021 | D25: FY2022 | E25: FY2023 | F25: FY2024
A26: Assets
A27: Cash | B27: 57810 | C27: 102145 | D27: 337529 | E27: 286300 | F27: 310525
A28: Savings & temporary investments
A29: Accounts receivable
A30: Inventories
A31: Prepaid expenses
A32: Property, plant & equipment (gross) | D32: 159006 | E32: 159006 | F32: 159006
A33: Less: accumulated depreciation | D33: -79897 | E33: -102500 | F33: -118644
A34: Net property, plant & equipment | B34: 81498 | C34: 58211 | D34: 79109 | E34: 56506 | F34: 40362
A35: Total assets | B35: 139308 | C35: 160356 | D35: 416638 | E35: 342806 | F35: 350887
A37: Liabilities
A38: Accounts payable
A39: Mortgages & notes payable
A40: Total liabilities | D40: 186181 | E40: 0 | F40: 0
A42: Net Assets / Equity
A43: Capital stock
A44: Paid-in capital
A45: Retained earnings | D45: 230457 | E45: 342806 | F45: 350887
A46: Net assets | B46: 139308 | C46: 160356 | D46: 230457 | E46: 342806 | F46: 350887
A49: CASH FLOW - derived proxy (USD)
...

Sheet Balance Sheet
A1: Prather Water District Inc
A2: Balance Sheet - as reported (USD, end of year)
A3: Entity ID: cawc_0187 | Fiscal year ends December 31.
A5: Line item | B5: FY2020 | C5: FY2021 | D5: FY2022 | E5: FY2023 | F5: FY2024
A6: Assets
A7: Cash | B7: 57810 | C7: 102145 | D7: 337529 | E7: 286300 | F7: 310525
A8: Savings & temporary investments
A9: Accounts receivable
A10: Inventories
A11: Prepaid expenses
A12: Property, plant & equipment (gross) | D12: 159006 | E12: 159006 | F12: 159006
A13: Less: accumulated depreciation | D13: -79897 | E13: -102500 | F13: -118644
A14: Net property, plant & equipment | B14: 81498 | C14: 58211 | D14: 79109 | E14: 56506 | F14: 40362
A15: Total assets | B15: 139308 | C15: 160356 | D15: 416638 | E15: 342806 | F15: 350887
A17: Liabilities
A18: Accounts payable
A19: Mortgages & notes payable
A20: Total liabilities | D20: 186181 | E20: 0 | F20: 0
A22: Net Assets / Equity
A23: Capital stock
A24: Paid-in capital
A25: Retained earnings | D25: 230457 | E25: 342806 | F25: 350887
A26: Net assets | B26: 139308 | C26: 160356 | D26: 230457 | E26: 342806 | F26: 350887
A28: Balance check (assets − liab. − net assets) | B28: 0 | C28: 0 | D28: 0 | E28: 0 | F28: 0
A30: Net PP&E is the reported ppe_net column (gross less accumulated depreciation). The balance check should be ~0 where all three totals are reported; a non-zero value flags a reporting or extraction discrepancy worth reviewing.

Sheet Officers & contractors
A1: Prather Water District Inc
A2: Officers, Directors & Contractors - Form 990 Part VII (FY2024; USD)
A3: Entity ID: cawc_0187 | Fiscal year ends December 31.
A5: Section A - Officers, directors, trustees, key employees
A6: Name | B6: Title | C6: Reportable comp (org) | D6: Reportable comp (related) | E6: Other comp | F6: Total compensation
A7: MARTY PAGE | B7: PRESIDENT | C7: 0 | D7: 0 | E7: 0 | F7: 0
A9: Section B - Independent contractors (over $100,000)
A10: Contractor | B10: Services | C10: Compensation
A12: Section A lists every officer, director, trustee and key employee filed for the latest year; the two with the highest total compensation are highlighted. Total compensation is computed (reportable org + related + other). Section B lists each independent contractor paid over $100,000; the return reports None such contractor(s). Source and confidence for every figure are on the Sources & audit tab.

Sheet Revenue (detail)
A1: Prather Water District Inc
A2: Revenue - Form 990 Part VIII (USD)
A3: Entity ID: cawc_0187 | Fiscal year ends December 31.
A5: Part VIII line | B5: FY2022 | C5: FY2023 | D5: FY2024
A6: Revenue by category
A7: 1h. Total contributions, gifts, grants | B7: 174744 | C7: 179765 | D7: 99794
A8: 2g. Total program service revenue | B8: 29454 | C8: 22178 | D8: not reported
A9: 3. Investment income | B9: not reported | C9: not reported | D9: not reported
A10: 6d. Net rental income | B10: not reported | C10: not reported | D10: not reported
A11: 7d. Net gain/(loss) from investment sales | B11: not reported | C11: not reported | D11: not reported
A12: 11e. Other revenue | B12: not reported | C12: not reported | D12: not reported
A13: 12. Total revenue | B13: =SUM(B7:B12) | C13: =SUM(C7:C12) | D13: =SUM(D7:D12)
A15: Revenue category subtotals are as filed. Total revenue (line 12) is a live SUM of the category cells above; its tie-out to the filed total is on the Sources & audit tab. Program service revenue detail is shown for the latest year, with its sum-to-line-2g check on that same audit tab.

Sheet Operating expenses (detail)
A1: Prather Water District Inc
A2: Statement of Functional Expenses - Form 990 Part IX (USD)
A3: Entity ID: cawc_0187 | Fiscal year ends December 31.
A5: Part IX line (column A Total) | B5: FY2022 | C5: FY2023 | D5: FY2024
A6: Functional expenses, column A Total - by year
A7: 11g. Fees for services: other | B7: 55094 | C7: 11808 | D7: 11231
A8: 13. Office expenses | B8: 377 | C8: 299 | D8: 299
A9: 16. Occupancy | B9: 13611 | C9: 14745 | D9: 17002
A10: 20. Interest | B10: not reported | C10: not reported | D10: 16
A11: 22. Depreciation, depletion, and amortization | B11: 43022 | C11: 22603 | D11: 16144
A12: 23. Insurance | B12: 2250 | C12: 2580 | D12: 2952
A13: 24. WATER SYSTEM MAINTENANCE | B13: 14517 | C13: 19045 | D13: 15595
A14: 24. REPAIRS | B14: 2960 | C14: 8850 | D14: 9864
A15: 24. ALARM | B15: 831 | C15: 795 | D15: 902
A16: 24. FTB TAXES | B16: 800 | C16: 8144 | D16: 17708
A17: 24e. All other expenses | B17: 635 | C17: 725 | D17: not reported
A18: 25. Total functional expenses | B18: =SUM(B7:B17) | C18: =SUM(C7:C17) | D18: =SUM(D7:D17)
A20: Functional column split - FY2024 (col A = B + C + D)
A21: Part IX line | B21: A. Total | C21: B. Program services | D21: C. Management & general | E21: D. Fundraising
A22: 11g. Fees for services: other | B22: 11231 | C22: 11231
A23: 13. Office expenses | B23: 299 | C23: 299
A24: 16. Occupancy | B24: 17002 | C24: 17002
A25: 20. Interest | B25: 16 | C25: 16
A26: 22. Depreciation, depletion, and amortization | B26: 16144 | C26: 16144
A27: 23. Insurance | B27: 2952 | C27: 2952
A28: 25. Total (filed col A / B / C / D) | B28: 91713 | C28: 91713 | D28: 0 | E28: 0
A30: Top block: each Part IX line, column A (Total), by year, as filed. Total functional expenses (line 25) is a live SUM of the line cells; its tie-out to the filed total is on the Sources & audit tab. Filer-itemized 24a-24d rows show the most recent year's as-filed wording; rows are aligned across years case-insensitively with collapsed spacing, so a line filed only in a different capitalization or spacing shares one row, while genuinely different wording stays a separate row (every as-filed variant is recorded on the Sources & audit tab). Lower block: the program / management / fundraising split for the latest year, with its col A = B + C + D check on the audit tab. Lines this filer does not report are omitted rather than shown empty.

Sheet Balance sheet (detail)
A1: Prather Water District Inc
A2: Balance Sheet - Form 990 Part X (end of year, USD)
A3: Entity ID: cawc_0187 | Fiscal year ends December 31.
A5: Part X line (column B, EOY) | B5: FY2022 | C5: FY2023 | D5: FY2024
A6: Assets
A7: 1. Cash - non-interest-bearing | B7: 337529 | C7: 286300 | D7: 310525
A8: 10c. Land, buildings, and equipment, net | B8: 79109 | C8: 56506 | D8: 40362
A9: 16. Total assets | B9: =SUM(B7:B8) | C9: =SUM(C7:C8) | D9: =SUM(D7:D8)
A11: Liabilities
A12: 25. Other liabilities | B12: 186181 | C12: not reported | D12: not reported
A13: 26. Total liabilities | B13: =SUM(B12:B12) | C13: =SUM(C12:C12) | D13: =SUM(D12:D12)
A15: Net assets / fund balances
A16: 31. Retained earnings / accumulated funds | B16: 230457 | C16: 342806 | D16: 350887
A17: 32. Total net assets / fund balances | B17: =SUM(B16:B16) | C17: =SUM(C16:C16) | D17: =SUM(D16:D16)
A19: Every Part X line is end-of-year (column B), as filed. Section totals (lines 16 / 26 / 32) are live SUMs of the lines above; their tie-outs and the balance-sheet identity (16 = 26 + 32) are on the Sources & audit tab. This filer files as a non-FASB mutual, so net assets sit on lines 29-31 (capital stock / paid-in capital / retained earnings); lines this filer does not report are omitted. Lines 10a/10b net into line 10c (shown).

Sheet Net-assets reconciliation
A1: Prather Water District Inc
A2: Reconciliation of Net Assets - Form 990 Part XI (USD)
A3: Entity ID: cawc_0187 | Fiscal year ends December 31.
A5: Part XI line | B5: FY2022 | C5: FY2023 | D5: FY2024
A6: Reconciliation
A7: 4. Net assets, beginning of year | B7: 160356 | C7: 230457 | D7: 342806
A8: 3. Revenue less expenses | B8: 70101 | C8: 112349 | D8: 8081
A9: 8. Prior period adjustments | B9: not reported | C9: not reported | D9: not reported
A10: 9. Other changes in net assets | B10: not reported | C10: not reported | D10: not reported
A11: 10. Net assets, end of year | B11: =SUM(B7,B8,B9,B10) | C11: =SUM(C7,C8,C9,C10) | D11: =SUM(D7,D8,D9,D10)
A13: Part XI reconciles beginning to ending net assets. Ending net assets (line 10) is a live formula: beginning balance (line 4) + revenue less expenses (line 3) + prior-period adjustments (8) + other changes (9). Its tie-out to the filed line 10 (and to Part X line 32) is on the Sources & audit tab. Lines 5-7 (unrealized gains, donated services, investment expenses) are not filed by this entity.

Sheet Cash flow proxies
A1: Prather Water District Inc
A2: Cash Flow Proxies - derived (USD)
A3: Entity ID: cawc_0187 | Fiscal year ends December 31.
A5: PROXY ONLY. The source filings contain no statement of cash flows. Lines below are derived from the reported income statement and year-over-year balance-sheet changes; treat as directional estimates, not GAAP cash flows. The earliest year has no prior period, so its delta cells are blank.
A7: Proxy line (USD) | B7: FY2020 | C7: FY2021 | D7: FY2022 | E7: FY2023 | F7: FY2024
A8: Operating
A9: Net income | B9: 41606 | C9: 21048 | D9: 70101 | E9: 112349 | F9: 8081
A10: + Depreciation (reported) | D10: 43022 | E10: 22603 | F10: 16144
A11: − Δ Accounts receivable
A12: − Δ Inventories
A13: − Δ Prepaid expenses
A14: + Δ Accounts payable
A15: Operating cash flow proxy | C15: 21048 | D15: 113123 | E15: 134952 | F15: 24225
A17: Investing
A18: − Δ PP&E gross (capex proxy) | E18: 0 | F18: 0
A20: Financing
A21: Δ Mortgages & notes payable
A23: Reconciliation
A24: Δ Cash + temp. investments (actual) | C24: 44335 | D24: 235384 | E24: -51229 | F24: 24225
A26: The capex proxy assumes gross PP&E rises only via capital spending (it ignores disposals). 'Δ Cash + temp. investments (actual)' is the real reported change in liquid funds and is the most reliable line here; the operating/investing/financing proxies will not perfectly reconcile to it.

Sheet Ratios
A1: Prather Water District Inc
A2: Financial Ratios
A3: Entity ID: cawc_0187 | Fiscal year ends December 31.
A5: Ratio | B5: FY2020 | C5: FY2021 | D5: FY2022 | E5: FY2023 | F5: FY2024
A6: Profitability (computed upstream)
A7: Operating margin (NI / revenue) | B7: 0.3206208 | C7: 0.19819022 | D7: 0.34329915 | E7: 0.55634016 | F7: 0.080976812
A8: Expense ratio (expenses / revenue) | B8: 0.6793792 | C8: 0.80180978 | D8: 0.65670085 | E8: 0.44365984 | F8: 0.91902319
A9: Return on assets (NI / assets) | B9: 0.29866196 | C9: 0.13125795 | D9: 0.16825398 | E9: 0.32773347 | F9: 0.023030206
A10: Revenue growth (YoY) | E10: -0.011043203 | F10: -0.50583085
A12: Leverage & solvency
A13: Debt-to-assets (liab. / assets) | D13: 0.44686514 | E13: 0 | F13: 0
A14: Equity ratio (net assets / assets) | B14: 1 | C14: 1 | D14: 0.55313486 | E14: 1 | F14: 1
A16: Liquidity & asset profile (derived here)
A17: Current ratio (current assets / AP)
A18: Cash ratio ((cash+temp inv.) / total liab.) | D18: 1.8129079
A19: Asset age proxy (accum. deprec. / gross PP&E) | D19: 0.50247789 | E19: 0.64462976 | F19: 0.74616052
A21: Upstream ratios are read from financials_annual; derived ratios are computed only where inputs are reported. Current ratio uses accounts payable as the current-liability proxy (the filings do not split current vs. long-term liabilities). Asset age proxy: a higher % implies older / more depreciated infrastructure.

Sheet Unit economics
A1: Prather Water District Inc
A2: Unit economics - per-customer revenue by category (USD)
A3: Entity ID: cawc_0187 | Fiscal year ends December 31.
A5: Every metric here is PER CUSTOMER (a metered service connection). It is not a per-member figure; the member (shareholder) count is a different denominator, shown in the denominator block. The visible cell shows the value and its classification; the numerator, denominator, formula, and rationale are in each metric's LOGIC popup.
A6: Per-customer denominator (service connections) | C6: State Water Board eAR Section 4
A7: Total annual revenue (eAR Section 8b B1.8) | C7: eAR Section 8b total annual revenue not reported for this system.
A8: Primary source
A10: Revenue categories (value, classification, per customer, share)
A11: Revenue category | B11: Classification | C11: Value (USD) | D11: Per customer | E11: Share of revenue
A12: Water sales revenue | B12: not reported | C12: not reported | D12: not reported | E12: not reported
A13: Assessment revenue (990 program-service revenue not matched to eAR water-rate revenue) | B13: IMPOSSIBLE | C13: IMPOSSIBLE | D13: IMPOSSIBLE | E13: IMPOSSIBLE
A14: Meter revenue | B14: not reported | C14: not reported | D14: not reported | E14: not reported
A15: Overage or tiered penalty revenue | B15: not reported | C15: not reported | D15: not reported | E15: not reported
A17: Water sales revenue - not reported
A18: Not reported: this system filed an eAR but no Section 8b revenue block, so there is no filed water-sales figure. Not fallen back to a different year.
A19: Reason: No filed eAR Section 8b water-rate revenue for this system.
A21: Assessment revenue (990 program-service revenue not matched to eAR water-rate revenue) - IMPOSSIBLE
A22: Not computed. A period-aligned residual is not possible for this filer.
A23: Reason: Not derivable. The eAR Section 8b is reporting year None while the Form 990 fiscal year ends None; the two period ends are not aligned, so a period-aligned residual cannot be computed.
A25: Meter revenue - not reported
A26: Not reported. This category is not built because doing so would double-count.
A27: Reason: The eAR Section 8a reports a base/meter rate PRICE, but the filing carries no meter revenue line and no tier volume, and the base charge is already inside the water-sales revenue (eAR Section 8b water rates). Building a separate meter figure would double-count. Not backed into from a total.
A29: Overage or tiered penalty revenue - not reported
A30: Not reported. This category is not built because doing so would double-count.
A31: Reason: The eAR Section 8a reports tiered/overage rate PRICES, but the filing carries no overage revenue and no tier consumption volume, and any overage billed is already inside the water-sales revenue. Building it would double-count. Not backed into from a total.

Sheet Rate structure
A1: Prather Water District Inc
A2: Rate structure and representative bill - eAR Section 8a
A3: Entity ID: cawc_0187 | Fiscal year ends December 31.
A5: This block is a rate-schedule illustration at defined usage levels. It is NOT billed revenue and not a claim about any real customer's usage. The revenue side of unit economics is the separate Unit Economics block.
A6: No filed eAR Section 8a rate schedule is staged for this system.

Sheet Operational metrics
A1: Prather Water District Inc
A2: Operational metrics - plant per acre, density, terrain
A3: Entity ID: cawc_0187 | Fiscal year ends December 31.
A5: Plant assets per acre
A6: Service-area acres | B6: 127.3 | C6: Geodesic area (WGS84 spherical excess) of the SABL service-area polygon.
A7: Fiscal year | B7: Gross plant per acre (primary) | C7: Net plant per acre
A8: FY2020 | C8: 640.2042
A9: FY2021 | C9: 457.2742
A10: FY2022 | B10: 1249.0652 | C10: 621.4375
A11: FY2023 | B11: 1249.0652 | C11: 443.8806
A12: FY2024 | B12: 1249.0652 | C12: 317.0621
A13: Infrastructure built per acre of service area. Gross plant per acre is the primary read because it measures how much plant the system has put in the ground per acre, and unlike net plant it does not fall over time purely because the assets depreciate on the books. Net plant per acre is shown alongside as the depreciated book value per acre.
A14: Formula: gross plant per acre = Form 990 Part X line 10a (land, buildings, and equipment, gross) / SABL service-area acres; net plant per acre uses Part X line 10c (net)
A15: Source lines: Form 990 Part X line 10a (gross) and line 10c (net); Geodesic area (WGS84 spherical excess) of the SABL service-area polygon.
A16: Confidence: medium. This is worked out from filed figures (a ratio, or a year-to-year change), so it is one step removed from the raw numbers.. Filed gross/net plant over the measured SABL service-area acreage.
A18: Connections per acre
A19: Connections per acre | B19: 0.24 | C19: 30 connections / 127.3 acres. CA State Water Board SABL SERVICE_CONNECTIONS; Geodesic area (WGS84 spherical excess) of the SABL service-area polygon.

Sheet Supply & weather
A1: Prather Water District Inc
A2: Supply and weather indicators (DWR water year)
A3: Entity ID: cawc_0187 | Fiscal year ends December 31.
A5: Reporting calendar: Different reporting periods. The DWR water year runs October 1 to September 30; this system's fiscal year ends December 31, so the two period ends are three months apart. Read the two side by side with that in mind. Neither series is recast: both are reported as filed. A water year is named for the calendar year it ends in, so WY2024 and FY2024 share a number without covering the same twelve months.
A7: Indicator | B7: WY2020 | C7: WY2021 | D7: WY2022 | E7: WY2023 | F7: WY2024
A8: Water-year type (Sacramento Valley) | B8: Dry | C8: Critical | D8: Critical | E8: Wet | F8: Above Normal
A9: Peak drought, county County | B9: not reported | C9: not reported | D9: not reported | E9: not reported | F9: not reported
A10: Precip, percent of normal (8-Station Index) | B10: 63 | C10: 48 | D10: 86 | E10: 133 | F10: 96
A11: Snowpack, April 1 percent of average | B11: 53% | C11: 59% | D11: 38% | E11: 237% | F11: 110%
A12: State Water Project allocation | B12: 20% | C12: 5% | D12: 5% | E12: 100% | F12: 40%

Sheet How this was built
A1: Prather Water District Inc
A2: How this was built - forensic lineage
A3: Entity ID: cawc_0187 | Fiscal year ends December 31.
A5: A plain account of the forensic lineage behind the hard-to-source metrics: what sources were checked, what was found, what was derived, and what could not be built and why. Every figure marked DERIVED or IMPOSSIBLE above is traceable to a line here.
A7: Water-sales revenue per customer - not reported
A8: Sources checked | B8: State Water Board eAR Section 8b (water-rate revenue B1.1/B1.2); State Water Board eAR Section 4 (connection count, same reporting year); audited financial statement (secondary cross-check, where published)
A9: What was found | B9: The eAR Section 8b reports water-rate revenue for reporting year None, so this is a DIRECT filed figure; per customer it is divided by the eAR Section 4 connection count for the same reporting year, so numerator and denominator share the year.
A11: Assessment revenue (residual) - IMPOSSIBLE
A12: Sources checked | B12: Form 990 Part VIII line 2 (program-service revenue); State Water Board eAR Section 8b (water-rate revenue B1.1/B1.2); eAR Section 8b filer comment (WRRevenueComments)
A13: What was found | B13: A period-aligned residual cannot be computed for this filer, so the metric is rendered IMPOSSIBLE rather than guessed.
A14: Caveat | B14: Not derivable. The eAR Section 8b is reporting year None while the Form 990 fiscal year ends None; the two period ends are not aligned, so a period-aligned residual cannot be computed.
A16: Meter revenue - not reported
A17: Sources checked | B17: State Water Board eAR Section 8a (rate prices); State Water Board eAR Section 8b (revenue lines); audited financial statement
A18: What was found | B18: The rate price exists in Section 8a but no revenue or tier volume is reported, and the base charge is already inside water sales.
A19: Caveat | B19: The eAR Section 8a reports a base/meter rate PRICE, but the filing carries no meter revenue line and no tier volume, and the base charge is already inside the water-sales revenue (eAR Section 8b water rates). Building a separate meter figure would double-count. Not backed into from a total.
A21: Overage / tiered-penalty revenue - not reported
A22: Sources checked | B22: State Water Board eAR Section 8a (rate prices); State Water Board eAR Section 8b (revenue lines); audited financial statement
A23: What was found | B23: The rate price exists in Section 8a but no revenue or tier volume is reported, and the base charge is already inside water sales.
A24: Caveat | B24: The eAR Section 8a reports tiered/overage rate PRICES, but the filing carries no overage revenue and no tier consumption volume, and any overage billed is already inside the water-sales revenue. Building it would double-count. Not backed into from a total.
A26: eAR Section 8b reporting-period basis - sourced
A27: Sources checked | B27: eAR Section 8b B0.1 (WRFinancialReportingPeriod); eAR Section 8b B0.2 (WRFiscalYearStartDate)
A28: What was found | B28: The reporting basis (fiscal vs calendar year) is read from the filer's own B0.1/B0.2 answer and staged verbatim, never hardcoded, so the 990 comparison and the residual are period-aligned.
A30: Member (shareholder) count denominator - not reported
A31: Sources checked | B31: Form 990 (no member count stated); company website
A32: What was found | B32: No filing states a member/shareholder count, so the per-member unit economics read not reported rather than borrowing the connection count.
A34: Water volume delivered (acre-feet) - not reported
A35: Sources checked | B35: Form 990 (not in the filing); Consumer Confidence Report; eAR Section 6 (PRA-gated)
A36: What was found | B36: Volume delivered in acre-feet is not in the Form 990 and the CCR states only a source mix, so the per-acre-foot metrics read not reported; the eAR Section 6 is named as the source still needed.

Sheet Sources & audit
A1: Prather Water District Inc
A2: Sources & audit - full provenance and tie-outs (kept off the statements so they read clean)
A3: Entity ID: cawc_0187 | Fiscal year ends December 31.
A5: Presentation standard: every figure on the statement tabs is verified to its source filing and shown clean. A cell the filing does not report reads "not reported" (never estimated, never guessed).
A6: Citations, confidence tiers, and the filed-vs-computed tie-out checks live on the "Sources & audit" tab, keyed by cell, so every number is fully traceable without cluttering the statements. These pages are ready to use as filed.
A8: A. Filing provenance (one row per staged extraction)
A9: Fiscal year | B9: Period end | C9: Filing type | D9: Confidence | E9: Extraction ID | F9: Object ID | G9: Extracted by | H9: Extracted at | I9: Source URL
A10: FY2020 | B10: 2020-12-31 | C10: 990-EZ | D10: high | E10: 07dd755e-10cb-4673-b6a2-ef38f845d0f9 | F10: 202130789349200513 | G10: claude-opus-5 | H10: 2026-10-06T04:30:11+00:00 | I10: https://apps.irs.gov/pub/epostcard/990/xml/2021/2021_TEOS_XML_01A.zip#202130789349200513_public.xml
A11: FY2021 | B11: 2021-12-31 | C11: 990-EZ | D11: high | E11: 74a60c7c-8274-4bf3-8c5e-665bdd9a6acb | F11: 202231729349200968 | G11: claude-opus-5 | H11: 2026-10-06T04:30:12+00:00 | I11: https://apps.irs.gov/pub/epostcard/990/xml/2022/2022_TEOS_XML_01A.zip#202231729349200968_public.xml
A12: FY2022 | B12: 2022-12-31 | C12: 990 | D12: high | E12: 20d693ba-691d-47b8-9496-9f036bfbba6d | F12: 202302859349302205 | G12: claude-opus-5 | H12: 2026-10-06T04:30:13+00:00 | I12: https://apps.irs.gov/pub/epostcard/990/xml/2023/2023_TEOS_XML_10A.zip#202302859349302205_public.xml
A13: FY2023 | B13: 2023-12-31 | C13: 990 | D13: high | E13: 0fb704f4-d387-4fe1-bd33-ece2010f9c9f | F13: 202442849349302019 | G13: claude-opus-5 | H13: 2026-10-06T04:30:14+00:00 | I13: https://apps.irs.gov/pub/epostcard/990/xml/2024/2024_TEOS_XML_10A.zip#202442849349302019_public.xml
A14: FY2024 | B14: 2024-12-31 | C14: 990 | D14: high | E14: a7169f65-a152-4803-b0b2-63c8718f6487 | F14: 202510729349301021 | G14: claude-opus-5 | H14: 2026-10-06T04:30:14+00:00 | I14: https://apps.irs.gov/pub/epostcard/990/xml/2025/2025_TEOS_XML_03A.zip#202510729349301021_public.xml
A16: B. Figure citations (every figure on the statement tabs, keyed by cell)
A17: Tab | B17: Cell | C17: Line item | D17: Form 990 line | E17: Key path | F17: Confidence | G17: As filed
A18: Revenue (detail) | B18: B7 | C18: 1h. Total contributions, gifts, grants | D18: 1h | E18: part_viii_revenue.total_contributions | F18: high | G18: 174744
A19: Revenue (detail) | B19: C7 | C19: 1h. Total contributions, gifts, grants | D19: 1h | E19: part_viii_revenue.total_contributions | F19: high | G19: 179765
A20: Revenue (detail) | B20: D7 | C20: 1h. Total contributions, gifts, grants | D20: 1h | E20: part_viii_revenue.total_contributions | F20: high | G20: 99794
A21: Revenue (detail) | B21: B8 | C21: 2g. Total program service revenue | D21: 2g | E21: part_viii_revenue.total_program_service_revenue | F21: high | G21: 29454
A22: Revenue (detail) | B22: C8 | C22: 2g. Total program service revenue | D22: 2g | E22: part_viii_revenue.total_program_service_revenue | F22: high | G22: 22178
A23: Operating expenses (detail) | B23: B7 | C23: 11g. Fees for services: other | D23: 11g | E23: part_ix_expenses.fees_other | F23: high | G23: 55094
A24: Operating expenses (detail) | B24: C7 | C24: 11g. Fees for services: other | D24: 11g | E24: part_ix_expenses.fees_other | F24: high | G24: 11808
A25: Operating expenses (detail) | B25: D7 | C25: 11g. Fees for services: other | D25: 11g | E25: part_ix_expenses.fees_other | F25: high | G25: 11231
A26: Operating expenses (detail) | B26: B8 | C26: 13. Office expenses | D26: 13 | E26: part_ix_expenses.office_expenses | F26: high | G26: 377
A27: Operating expenses (detail) | B27: C8 | C27: 13. Office expenses | D27: 13 | E27: part_ix_expenses.office_expenses | F27: high | G27: 299
A28: Operating expenses (detail) | B28: D8 | C28: 13. Office expenses | D28: 13 | E28: part_ix_expenses.office_expenses | F28: high | G28: 299
A29: Operating expenses (detail) | B29: B9 | C29: 16. Occupancy | D29: 16 | E29: part_ix_expenses.occupancy | F29: high | G29: 13611
... A56: Net-assets reconciliation | B56: D8 | C56: 3. Revenue less expenses | D56: Part XI line 3 | E56: part_xi_reconciliation.reconciliation_revenue_expenses | F56: high | G56: 8081
A58: C. Tie-out checks (filed vs computed; any nonzero variance is flagged red)
A59: Tab | B59: Check | C59: Fiscal year | D59: Filed | E59: Computed | F59: Variance (computed - filed)
A60: Revenue (detail) | B60: 12. Total revenue | C60: FY2022 | D60: 204198 | E60: ='Revenue (detail)'!B13 | F60: =E60-D60
A61: Revenue (detail) | B61: 12. Total revenue | C61: FY2023 | D61: 201943 | E61: ='Revenue (detail)'!C13 | F61: =E61-D61
A62: Revenue (detail) | B62: 12. Total revenue | C62: FY2024 | D62: 99794 | E62: ='Revenue (detail)'!D13 | F62: =E62-D62
A63: Operating expenses (detail) | B63: 25. Total functional expenses | C63: FY2022 | D63: 134097 | E63: ='Operating expenses (detail)'!B18 | F63: =E63-D63
A64: Operating expenses (detail) | B64: 25. Total functional expenses | C64: FY2023 | D64: 89594 | E64: ='Operating expenses (detail)'!C18 | F64: =E64-D64
A65: Operating expenses (detail) | B65: 25. Total functional expenses | C65: FY2024 | D65: 91713 | E65: ='Operating expenses (detail)'!D18 | F65: =E65-D65
A66: Operating expenses (detail) | B66: Part IX column split: col A = B + C + D (FY2024) | C66: FY2024 | D66: ='Operating expenses (detail)'!B28 | E66: ='Operating expenses (detail)'!C28+'Operating expenses (detail)'!D28+'Operating expenses (detail)'!E28 | F66: =E66-D66
A67: Balance sheet (detail) | B67: 16. Total assets | C67: FY2022 | D67: 416638 | E67: ='Balance sheet (detail)'!B9 | F67: =E67-D67
A68: Balance sheet (detail) | B68: 16. Total assets | C68: FY2023 | D68: 342806 | E68: ='Balance sheet (detail)'!C9 | F68: =E68-D68
A69: Balance sheet (detail) | B69: 16. Total assets | C69: FY2024 | D69: 350887 | E69: ='Balance sheet (detail)'!D9 | F69: =E69-D69
A70: Balance sheet (detail) | B70: 26. Total liabilities | C70: FY2022 | D70: 186181 | E70: ='Balance sheet (detail)'!B13 | F70: =E70-D70
...

Sheet Provenance
A1: Build provenance | B1: Built from source commit d418ffb17485 (2026-10-06); source fingerprint a75a8eee82c65cf7; 192 companies (179 retail mutual, 4 irrigation mutual, 3 mutual, no PWSID, purpose not stated, 2 frozen non-mutual (special district), 2 wholesale mutual, 1 frozen non-mutual (investor-owned), 1 frozen non-mutual (municipal)); 91 gates; build id 3d08d6d2a855.
A2: source_commit | B2: d418ffb174855ab78000d391d42f898397b0d8aa
A3: source_commit_date | B3: 2026-10-06
A4: source_fingerprint | B4: a75a8eee82c65cf7096931f06e18affdc28686a02895b46538e7298b57c04d94
A5: gate_count | B5: 91
A6: build_id | B6: 3d08d6d2a855
A7: registry: frozen non-mutual (investor-owned) | B7: 1
A8: registry: frozen non-mutual (municipal) | B8: 1
A9: registry: frozen non-mutual (special district) | B9: 2
A10: registry: irrigation mutual | B10: 4
A11: registry: mutual, no PWSID, purpose not stated | B11: 3
A12: registry: retail mutual | B12: 179
A13: registry: wholesale mutual | B13: 2
