Workbook

Sheet Summary
A1: Rubio Canon Land & Water Association
A2: Financial Summary - multi-year overview (USD)
A3: Entity ID: cawc_0027 | Fiscal year ends December 31.
A5: Presentation standard: every figure on the statement tabs is verified to its source filing and shown clean. A cell the filing does not report reads "not reported" (never estimated, never guessed).
A6: Citations, confidence tiers, and the filed-vs-computed tie-out checks live on the "Sources & audit" tab, keyed by cell, so every number is fully traceable without cluttering the statements. These pages are ready to use as filed.
A8: Metric | B8: FY2020 | C8: FY2021 | D8: FY2022 | E8: FY2023 | F8: FY2024
A9: Operating results (USD)
A10: Total revenue | B10: 3011124 | C10: 1547156 | D10: 2569729 | E10: 2746190 | F10: 4989018
A11: Total expenses | B11: 1559497 | C11: 1814745 | D11: 2224793 | E11: 1933240 | F11: 3333755
A12: Net income | B12: 1451627 | C12: -267589 | D12: 344936 | E12: 812950 | F12: 1655263
A14: Financial position (USD, end of year)
A15: Total assets | B15: 15995830 | C15: 15860865 | D15: 16051755 | E15: 17189100 | F15: 18520127
A16: Total liabilities | B16: 235037 | C16: 367661 | D16: 213615 | E16: 514773 | F16: 190537
A17: Net assets | B17: 15760793 | C17: 15493204 | D17: 15838140 | E17: 16674327 | F17: 18329590
A19: Headline ratios
A20: Operating margin | B20: 0.48208808 | C20: -0.17295541 | D20: 0.1342305 | E20: 0.29602832 | F20: 0.33178132
A21: Revenue growth (YoY) | B21: 0.22354224 | C21: -0.48618655 | D21: 0.66093723 | E21: 0.068669109 | F21: 0.81670533
A22: Return on assets | B22: 0.090750339 | C22: -0.016871022 | D22: 0.02148899 | E22: 0.047294506 | F22: 0.089376439
A24: Figures as reported in source filings (full provenance on the Sources & audit tab). Parentheses denote negatives; ratios are computed upstream in financials_annual.

Sheet Notes
A1: Notes
A2: Human annotations from the versioned store (data/notes/). Annotations only: they never change a reported figure or a confidence tier.
A4: Date | B4: Tag | C4: Author | D4: Note
A5: No notes recorded yet.

Sheet Financial Statements
A1: Rubio Canon Land & Water Association
A2: Financial Statements - income statement, balance sheet, cash flow, member income test (USD)
A3: Entity ID: cawc_0027 | Fiscal year ends December 31.
A5: INCOME STATEMENT - as reported (USD)
A6: Line item | B6: FY2020 | C6: FY2021 | D6: FY2022 | E6: FY2023 | F6: FY2024
A7: Revenue
A8: Program service revenue | F8: 4662328
A9: Investment income | B9: 238471 | C9: 103061 | D9: 37344 | E9: 100181 | F9: 236534
A10: Net rental income
A11: Net gain/(loss) on investment sales
A12: Other revenue | C12: 759 | E12: 93067 | F12: 90156
A13: Contributions & grants
A14: Total revenue | B14: 3011124 | C14: 1547156 | D14: 2569729 | E14: 2746190 | F14: 4989018
A16: Expenses
A17: Depreciation | B17: 615300 | C17: 584742 | D17: 510970 | E17: 567376 | F17: 609330
A18: Interest expense | B18: 942
A19: Total expenses | B19: 1559497 | C19: 1814745 | D19: 2224793 | E19: 1933240 | F19: 3333755
A21: Net income | B21: 1451627 | C21: -267589 | D21: 344936 | E21: 812950 | F21: 1655263
A24: BALANCE SHEET - as reported (USD, end of year)
A25: Line item | B25: FY2020 | C25: FY2021 | D25: FY2022 | E25: FY2023 | F25: FY2024
A26: Assets
A27: Cash | B27: 2757999 | C27: 2239130 | D27: 2577799 | E27: 3255089 | F27: 3999907
A28: Savings & temporary investments | B28: 2408723 | C28: 2511646 | D28: 2204125 | E28: 2383956 | F28: 2583076
A29: Accounts receivable | B29: 337016 | C29: 210407 | D29: 148765 | E29: 237055 | F29: 311864
A30: Inventories | B30: 84212 | C30: 90781 | D30: 102020 | E30: 128641 | F30: 175264
A31: Prepaid expenses | B31: 40000 | C31: 21426 | D31: 31080 | E31: 26362 | F31: 75909
A32: Property, plant & equipment (gross) | B32: 20265940 | C32: 21270277 | D32: 21981738 | E32: 22719144 | F32: 23544584
A33: Less: accumulated depreciation | B33: -10264810 | C33: -10849552 | D33: -11360522 | E33: -11927897 | F33: -12537227
A34: Net property, plant & equipment | B34: 10001130 | C34: 10420725 | D34: 10621216 | E34: 10791247 | F34: 11007357
A35: Total assets | B35: 15995830 | C35: 15860865 | D35: 16051755 | E35: 17189100 | F35: 18520127
A37: Liabilities
A38: Accounts payable | B38: 223146 | C38: 362752 | D38: 213615 | E38: 514773 | F38: 190537
A39: Mortgages & notes payable | B39: 11891 | C39: 4909
A40: Total liabilities | B40: 235037 | C40: 367661 | D40: 213615 | E40: 514773 | F40: 190537
A42: Net Assets / Equity
A43: Capital stock | B43: 233350 | C43: 233350 | D43: 233350 | E43: 233350 | F43: 233350
A44: Paid-in capital | B44: 537305 | C44: 537305 | D44: 537305 | E44: 560542 | F44: 560542
A45: Retained earnings | B45: 14990138 | C45: 14722549 | D45: 15067485 | E45: 15880435 | F45: 17535698
A46: Net assets | B46: 15760793 | C46: 15493204 | D46: 15838140 | E46: 16674327 | F46: 18329590
A49: CASH FLOW - derived proxy (USD)
...

Sheet Balance Sheet
A1: Rubio Canon Land & Water Association
A2: Balance Sheet - as reported (USD, end of year)
A3: Entity ID: cawc_0027 | Fiscal year ends December 31.
A5: Line item | B5: FY2020 | C5: FY2021 | D5: FY2022 | E5: FY2023 | F5: FY2024
A6: Assets
A7: Cash | B7: 2757999 | C7: 2239130 | D7: 2577799 | E7: 3255089 | F7: 3999907
A8: Savings & temporary investments | B8: 2408723 | C8: 2511646 | D8: 2204125 | E8: 2383956 | F8: 2583076
A9: Accounts receivable | B9: 337016 | C9: 210407 | D9: 148765 | E9: 237055 | F9: 311864
A10: Inventories | B10: 84212 | C10: 90781 | D10: 102020 | E10: 128641 | F10: 175264
A11: Prepaid expenses | B11: 40000 | C11: 21426 | D11: 31080 | E11: 26362 | F11: 75909
A12: Property, plant & equipment (gross) | B12: 20265940 | C12: 21270277 | D12: 21981738 | E12: 22719144 | F12: 23544584
A13: Less: accumulated depreciation | B13: -10264810 | C13: -10849552 | D13: -11360522 | E13: -11927897 | F13: -12537227
A14: Net property, plant & equipment | B14: 10001130 | C14: 10420725 | D14: 10621216 | E14: 10791247 | F14: 11007357
A15: Total assets | B15: 15995830 | C15: 15860865 | D15: 16051755 | E15: 17189100 | F15: 18520127
A17: Liabilities
A18: Accounts payable | B18: 223146 | C18: 362752 | D18: 213615 | E18: 514773 | F18: 190537
A19: Mortgages & notes payable | B19: 11891 | C19: 4909
A20: Total liabilities | B20: 235037 | C20: 367661 | D20: 213615 | E20: 514773 | F20: 190537
A22: Net Assets / Equity
A23: Capital stock | B23: 233350 | C23: 233350 | D23: 233350 | E23: 233350 | F23: 233350
A24: Paid-in capital | B24: 537305 | C24: 537305 | D24: 537305 | E24: 560542 | F24: 560542
A25: Retained earnings | B25: 14990138 | C25: 14722549 | D25: 15067485 | E25: 15880435 | F25: 17535698
A26: Net assets | B26: 15760793 | C26: 15493204 | D26: 15838140 | E26: 16674327 | F26: 18329590
A28: Balance check (assets − liab. − net assets) | B28: 0 | C28: 0 | D28: 0 | E28: 0 | F28: 0
A30: Net PP&E is the reported ppe_net column (gross less accumulated depreciation). The balance check should be ~0 where all three totals are reported; a non-zero value flags a reporting or extraction discrepancy worth reviewing.

Sheet Officers & contractors
A1: Rubio Canon Land & Water Association
A2: Officers, Directors & Contractors - Form 990 Part VII (FY2024; USD)
A3: Entity ID: cawc_0027 | Fiscal year ends December 31.
A5: Section A - Officers, directors, trustees, key employees
A6: Name | B6: Title | C6: Reportable comp (org) | D6: Reportable comp (related) | E6: Other comp | F6: Total compensation
A7: J FAHEY | B7: PRES | C7: 3000 | D7: 0 | E7: 0 | F7: 3000
A8: J GRAUNKE | B8: VP | C8: 3300 | D8: 0 | E8: 0 | F8: 3300
A9: J VRSALOVICH | B9: SECR/TREAS | C9: 3000 | D9: 0 | E9: 0 | F9: 3000
A10: J MOHR | B10: DIR | C10: 2700 | D10: 0 | E10: 0 | F10: 2700
A11: L YAMASHITA-LOPEZ | B11: ASST SECR/GM | C11: 250508 | D11: 0 | E11: 0 | F11: 250508
A12: A DE LA PAZ | B12: ASST GM | C12: 198364 | D12: 0 | E12: 0 | F12: 198364
A14: Section B - Independent contractors (over $100,000)
A15: Contractor | B15: Services | C15: Compensation
A17: Section A lists every officer, director, trustee and key employee filed for the latest year; the two with the highest total compensation are highlighted. Total compensation is computed (reportable org + related + other). Section B lists each independent contractor paid over $100,000; the return reports 0 such contractor(s). Source and confidence for every figure are on the Sources & audit tab.

Sheet Revenue (detail)
A1: Rubio Canon Land & Water Association
A2: Revenue - Form 990 Part VIII (USD)
A3: Entity ID: cawc_0027 | Fiscal year ends December 31.
A5: Part VIII line | B5: FY2020 | C5: FY2021 | D5: FY2022 | E5: FY2023 | F5: FY2024
A6: Revenue by category
A7: 1h. Total contributions, gifts, grants | B7: not reported | C7: not reported | D7: not reported | E7: not reported | F7: not reported
A8: 2g. Total program service revenue | B8: not reported | C8: not reported | D8: not reported | E8: not reported | F8: 4662328
A9: 3. Investment income | B9: 238471 | C9: 103061 | D9: 37344 | E9: 100181 | F9: 236534
A10: 6d. Net rental income | B10: not reported | C10: not reported | D10: not reported | E10: not reported | F10: not reported
A11: 7d. Net gain/(loss) from investment sales | B11: not reported | C11: not reported | D11: not reported | E11: not reported | F11: not reported
A12: 11e. Other revenue | B12: not reported | C12: 759 | D12: not reported | E12: 93067 | F12: 90156
A13: 12. Total revenue | B13: =SUM(B7:B12) | C13: =SUM(C7:C12) | D13: =SUM(D7:D12) | E13: =SUM(E7:E12) | F13: =SUM(F7:F12)
A15: Program service revenue detail - FY2024 (lines 2a-2f)
A16: Description | B16: Business code | C16: Total revenue
A17: POTABLE WATER | B17: 221000 | C17: 4613595
A18: OTHER MEMBER SERVICES | B18: 221000 | C18: 48733
A19: Revenue category subtotals are as filed. Total revenue (line 12) is a live SUM of the category cells above; its tie-out to the filed total is on the Sources & audit tab. Program service revenue detail is shown for the latest year, with its sum-to-line-2g check on that same audit tab.

Sheet Operating expenses (detail)
A1: Rubio Canon Land & Water Association
A2: Statement of Functional Expenses - Form 990 Part IX (USD)
A3: Entity ID: cawc_0027 | Fiscal year ends December 31.
A5: Part IX line (column A Total) | B5: FY2020 | C5: FY2021 | D5: FY2022 | E5: FY2023 | F5: FY2024
A6: Functional expenses, column A Total - by year
A7: 5. Compensation of current officers, directors, trustees | B7: not reported | C7: 348653 | D7: 379348 | E7: not reported | F7: 460872
A8: 7. Other salaries and wages | B8: 274941 | C8: 75975 | D8: 76067 | E8: 242358 | F8: 374907
A9: 8. Pension plan accruals and contributions | B9: 65321 | C9: 68898 | D9: 55827 | E9: 75483 | F9: 79244
A10: 9. Other employee benefits | B10: 96692 | C10: 193053 | D10: 217824 | E10: 285286 | F10: 147486
A11: 10. Payroll taxes | B11: 60041 | C11: 64238 | D11: 76290 | E11: 70113 | F11: 63409
A12: 11g. Fees for services: other | B12: 91293 | C12: 79644 | D12: 125716 | E12: 109828 | F12: 224640
A13: 13. Office expenses | B13: 87842 | C13: 86519 | D13: 95900 | E13: 103148 | F13: 149800
A14: 14. Information technology | B14: not reported | C14: 15836 | D14: 14381 | E14: 13836 | F14: not reported
A15: 16. Occupancy | B15: 37294 | C15: not reported | D15: not reported | E15: not reported | F15: not reported
A16: 20. Interest | B16: 942 | C16: not reported | D16: not reported | E16: not reported | F16: not reported
A17: 22. Depreciation, depletion, and amortization | B17: 615300 | C17: 584742 | D17: 510970 | E17: 567376 | F17: 609330
A18: 23. Insurance | B18: 100191 | C18: 121300 | D18: 137038 | E18: 145045 | F18: 162984
A19: 24. VEHICLES | B19: 57549 | C19: 62934 | D19: 84088 | E19: 175998 | F19: not reported
A20: 24. ALL OTHER | B20: 51812 | C20: 81045 | D20: 81727 | E20: 117910 | F20: not reported
A21: 24. PRINTING AND POSTAGE | B21: 20279 | C21: 31908 | D21: 25415 | E21: 26059 | F21: not reported
A22: 24. UNREALIZED LOSS ON INVE | B22: not reported | C22: not reported | D22: 344202 | E22: not reported | F22: not reported
A23: 24. STATE TAX | B23: not reported | C23: not reported | D23: not reported | E23: 800 | F23: not reported
A24: 24. POWER | B24: not reported | C24: not reported | D24: not reported | E24: not reported | F24: 372033
A25: 24. PUCHASED WATER | B25: not reported | C25: not reported | D25: not reported | E25: not reported | F25: 315525
A26: 24. DISTRIBUTION COSTS | B26: not reported | C26: not reported | D26: not reported | E26: not reported | F26: 196366
A27: 24. VEHICLE MAINTENANCE, FU | B27: not reported | C27: not reported | D27: not reported | E27: not reported | F27: 112138
A28: 24e. All other expenses | B28: not reported | C28: not reported | D28: not reported | E28: not reported | F28: 65021
A29: 25. Total functional expenses | B29: =SUM(B7:B28) | C29: =SUM(C7:C28) | D29: =SUM(D7:D28) | E29: =SUM(E7:E28) | F29: =SUM(F7:F28)
A31: Functional column split - FY2024 (col A = B + C + D)
A32: Part IX line | B32: A. Total | C32: B. Program services | D32: C. Management & general | E32: D. Fundraising
A33: 5. Compensation of current officers, directors, trustees | B33: 460872 | C33: 460872
A34: 7. Other salaries and wages | B34: 374907 | C34: 374907
A35: 8. Pension plan accruals and contributions | B35: 79244 | C35: 79244
A36: 9. Other employee benefits | B36: 147486 | C36: 147486
A37: 10. Payroll taxes | B37: 63409 | C37: 63409
A38: 11g. Fees for services: other | B38: 224640 | C38: 224640
A39: 13. Office expenses | B39: 149800 | C39: 149800
A40: 22. Depreciation, depletion, and amortization | B40: 609330 | C40: 609330
A41: 23. Insurance | B41: 162984 | C41: 162984
A42: 25. Total (filed col A / B / C / D) | B42: 3333755 | C42: 3333755 | D42: 0 | E42: 0
...

Sheet Balance sheet (detail)
A1: Rubio Canon Land & Water Association
A2: Balance Sheet - Form 990 Part X (end of year, USD)
A3: Entity ID: cawc_0027 | Fiscal year ends December 31.
A5: Part X line (column B, EOY) | B5: FY2020 | C5: FY2021 | D5: FY2022 | E5: FY2023 | F5: FY2024
A6: Assets
A7: 1. Cash - non-interest-bearing | B7: 2757999 | C7: 2239130 | D7: 2577799 | E7: 3255089 | F7: 3999907
A8: 2. Savings and temporary cash investments | B8: 2408723 | C8: 2511646 | D8: 2204125 | E8: 2383956 | F8: 2583076
A9: 4. Accounts receivable, net | B9: 337016 | C9: 210407 | D9: 148765 | E9: 237055 | F9: 311864
A10: 8. Inventories for sale or use | B10: 84212 | C10: 90781 | D10: 102020 | E10: 128641 | F10: 175264
A11: 9. Prepaid expenses and deferred charges | B11: 40000 | C11: 21426 | D11: 31080 | E11: 26362 | F11: 75909
A12: 10c. Land, buildings, and equipment, net | B12: 10001130 | C12: 10420725 | D12: 10621216 | E12: 10791247 | F12: 11007357
A13: 15. Other assets | B13: 366750 | C13: 366750 | D13: 366750 | E13: 366750 | F13: 366750
A14: 16. Total assets | B14: =SUM(B7:B13) | C14: =SUM(C7:C13) | D14: =SUM(D7:D13) | E14: =SUM(E7:E13) | F14: =SUM(F7:F13)
A16: Liabilities
A17: 17. Accounts payable and accrued expenses | B17: 223146 | C17: 362752 | D17: 213615 | E17: 514773 | F17: 190537
A18: 23. Secured mortgages and notes payable | B18: 11891 | C18: 4909 | D18: not reported | E18: not reported | F18: not reported
A19: 26. Total liabilities | B19: =SUM(B17:B18) | C19: =SUM(C17:C18) | D19: =SUM(D17:D18) | E19: =SUM(E17:E18) | F19: =SUM(F17:F18)
A21: Net assets / fund balances
A22: 29. Capital stock or trust principal | B22: 233350 | C22: 233350 | D22: 233350 | E22: 233350 | F22: 233350
A23: 30. Paid-in or capital surplus | B23: 537305 | C23: 537305 | D23: 537305 | E23: 560542 | F23: 560542
A24: 31. Retained earnings / accumulated funds | B24: 14990138 | C24: 14722549 | D24: 15067485 | E24: 15880435 | F24: 17535698
A25: 32. Total net assets / fund balances | B25: =SUM(B22:B24) | C25: =SUM(C22:C24) | D25: =SUM(D22:D24) | E25: =SUM(E22:E24) | F25: =SUM(F22:F24)
A27: Every Part X line is end-of-year (column B), as filed. Section totals (lines 16 / 26 / 32) are live SUMs of the lines above; their tie-outs and the balance-sheet identity (16 = 26 + 32) are on the Sources & audit tab. This filer files as a non-FASB mutual, so net assets sit on lines 29-31 (capital stock / paid-in capital / retained earnings); lines this filer does not report are omitted. Lines 10a/10b net into line 10c (shown).

Sheet Net-assets reconciliation
A1: Rubio Canon Land & Water Association
A2: Reconciliation of Net Assets - Form 990 Part XI (USD)
A3: Entity ID: cawc_0027 | Fiscal year ends December 31.
A5: Part XI line | B5: FY2020 | C5: FY2021 | D5: FY2022 | E5: FY2023 | F5: FY2024
A6: Reconciliation
A7: 4. Net assets, beginning of year | B7: 14309166 | C7: 15760793 | D7: 15493204 | E7: 15838140 | F7: 16674327
A8: 3. Revenue less expenses | B8: 1451627 | C8: -267589 | D8: 344936 | E8: 812950 | F8: 1655263
A9: 8. Prior period adjustments | B9: not reported | C9: not reported | D9: not reported | E9: not reported | F9: not reported
A10: 9. Other changes in net assets | B10: 0 | C10: 0 | D10: 0 | E10: 23237 | F10: 0
A11: 10. Net assets, end of year | B11: =SUM(B7,B8,B9,B10) | C11: =SUM(C7,C8,C9,C10) | D11: =SUM(D7,D8,D9,D10) | E11: =SUM(E7,E8,E9,E10) | F11: =SUM(F7,F8,F9,F10)
A13: Part XI reconciles beginning to ending net assets. Ending net assets (line 10) is a live formula: beginning balance (line 4) + revenue less expenses (line 3) + prior-period adjustments (8) + other changes (9). Its tie-out to the filed line 10 (and to Part X line 32) is on the Sources & audit tab. Lines 5-7 (unrealized gains, donated services, investment expenses) are not filed by this entity.

Sheet Cash flow proxies
A1: Rubio Canon Land & Water Association
A2: Cash Flow Proxies - derived (USD)
A3: Entity ID: cawc_0027 | Fiscal year ends December 31.
A5: PROXY ONLY. The source filings contain no statement of cash flows. Lines below are derived from the reported income statement and year-over-year balance-sheet changes; treat as directional estimates, not GAAP cash flows. The earliest year has no prior period, so its delta cells are blank.
A7: Proxy line (USD) | B7: FY2020 | C7: FY2021 | D7: FY2022 | E7: FY2023 | F7: FY2024
A8: Operating
A9: Net income | B9: 1451627 | C9: -267589 | D9: 344936 | E9: 812950 | F9: 1655263
A10: + Depreciation (reported) | B10: 615300 | C10: 584742 | D10: 510970 | E10: 567376 | F10: 609330
A11: − Δ Accounts receivable | C11: 126609 | D11: 61642 | E11: -88290 | F11: -74809
A12: − Δ Inventories | C12: -6569 | D12: -11239 | E12: -26621 | F12: -46623
A13: − Δ Prepaid expenses | C13: 18574 | D13: -9654 | E13: 4718 | F13: -49547
A14: + Δ Accounts payable | C14: 139606 | D14: -149137 | E14: 301158 | F14: -324236
A15: Operating cash flow proxy | C15: 595373 | D15: 747518 | E15: 1571291 | F15: 1769378
A17: Investing
A18: − Δ PP&E gross (capex proxy) | C18: -1004337 | D18: -711461 | E18: -737406 | F18: -825440
A20: Financing
A21: Δ Mortgages & notes payable | C21: -6982
A23: Reconciliation
A24: Δ Cash + temp. investments (actual) | C24: -415946 | D24: 31148 | E24: 857121 | F24: 943938
A26: The capex proxy assumes gross PP&E rises only via capital spending (it ignores disposals). 'Δ Cash + temp. investments (actual)' is the real reported change in liquid funds and is the most reliable line here; the operating/investing/financing proxies will not perfectly reconcile to it.

Sheet Ratios
A1: Rubio Canon Land & Water Association
A2: Financial Ratios
A3: Entity ID: cawc_0027 | Fiscal year ends December 31.
A5: Ratio | B5: FY2020 | C5: FY2021 | D5: FY2022 | E5: FY2023 | F5: FY2024
A6: Profitability (computed upstream)
A7: Operating margin (NI / revenue) | B7: 0.48208808 | C7: -0.17295541 | D7: 0.1342305 | E7: 0.29602832 | F7: 0.33178132
A8: Expense ratio (expenses / revenue) | B8: 0.51791192 | C8: 1.1729554 | D8: 0.8657695 | E8: 0.70397168 | F8: 0.66821868
A9: Return on assets (NI / assets) | B9: 0.090750339 | C9: -0.016871022 | D9: 0.02148899 | E9: 0.047294506 | F9: 0.089376439
A10: Revenue growth (YoY) | B10: 0.22354224 | C10: -0.48618655 | D10: 0.66093723 | E10: 0.068669109 | F10: 0.81670533
A12: Leverage & solvency
A13: Debt-to-assets (liab. / assets) | B13: 0.014693642 | C13: 0.023180388 | D13: 0.013307891 | E13: 0.029947641 | F13: 0.010288104
A14: Equity ratio (net assets / assets) | B14: 0.98530636 | C14: 0.97681961 | D14: 0.98669211 | E14: 0.97005236 | F14: 0.9897119
A16: Liquidity & asset profile (derived here)
A17: Current ratio (current assets / AP) | B17: 25.220932 | C17: 13.985836 | D17: 23.705213 | E17: 11.716044 | F17: 37.504632
A18: Cash ratio ((cash+temp inv.) / total liab.) | B18: 21.98259 | C18: 12.921621 | D18: 22.385713 | E18: 10.95443 | F18: 34.549631
A19: Asset age proxy (accum. deprec. / gross PP&E) | B19: 0.5065055 | C19: 0.51008043 | D19: 0.51681637 | E19: 0.52501525 | F19: 0.53248879
A21: Upstream ratios are read from financials_annual; derived ratios are computed only where inputs are reported. Current ratio uses accounts payable as the current-liability proxy (the filings do not split current vs. long-term liabilities). Asset age proxy: a higher % implies older / more depreciated infrastructure.

Sheet Unit economics
A1: Rubio Canon Land & Water Association
A2: Unit economics - per-customer revenue by category (USD)
A3: Entity ID: cawc_0027 | Fiscal year ends December 31.
A5: Every metric here is PER CUSTOMER (a metered service connection). It is not a per-member figure; the member (shareholder) count is a different denominator, shown in the denominator block. The visible cell shows the value and its classification; the numerator, denominator, formula, and rationale are in each metric's LOGIC popup.
A6: Per-customer denominator (service connections) | B6: 3128 | C6: State Water Board eAR Section 4 (CurTotalConnections), reporting year 2023
A7: Total annual revenue (eAR Section 8b B1.8) | B7: 3994188 | C7: State Water Board eAR Section 8b, question B1.8 (total annual revenue), reporting year 2023
A8: Primary source | C8: State Water Board eAR Section 8b (revenue by rate/fee), reporting year 2023
A10: Revenue categories (value, classification, per customer, share)
A11: Revenue category | B11: Classification | C11: Value (USD) | D11: Per customer | E11: Share of revenue
A12: Water sales revenue | B12: DIRECT | C12: 3945052 | D12: 1261.21 | E12: 0.9877
A13: Assessment revenue (990 program-service revenue not matched to eAR water-rate revenue) | B13: DERIVED | C13: -3851985 | D13: -1231.45 | E13: -41.3894
A14: Meter revenue | B14: not reported | C14: not reported | D14: not reported | E14: not reported
A15: Overage or tiered penalty revenue | B15: not reported | C15: not reported | D15: not reported | E15: not reported
A17: Water sales revenue - DIRECT
A18: Revenue customers paid for water service, read straight off the filed eAR Section 8b water-rate line. A DIRECT filed figure, not computed by us.
A19: Numerator: Water rate revenue | B19: 3945052 | C19: eAR Section 8b field B1.1 (residential water rates) + B1.2 (non-residential water rates). State Water Board eAR Section 8b, question B1.1 + B1.2 (revenue from water rates), reporting year 2023
A20: Denominator: Total service connections | B20: 3128 | C20: eAR Section 4 CurTotalConnections, reporting year 2023. State Water Board eAR Section 4 (CurTotalConnections), reporting year 2023
A21: Per customer: water rate revenue $3,945,052 / 3,128 connections = $1,261.21 per connection
A22: Share of revenue: water rate revenue $3,945,052 / total annual revenue (eAR Section 8b B1.8) $3,994,188 = 98.77%
A23: Period treatment: Numerator (eAR Section 8b, the calendar year 2023) and denominator (eAR Section 4 connections reported in the same eAR filing) are both the eAR reporting year 2023, so the two sides are bound to the same reporting year.
A24: Rationale: Dividing water-rate revenue by the number of metered service connections gives the average revenue per customer; dividing by total annual revenue shows how much of the system's income comes from water rates.
A26: Assessment revenue (990 program-service revenue not matched to eAR water-rate revenue) - DERIVED
A27: A DERIVED residual (medium confidence): the part of the Form 990 program-service revenue that is not matched by the eAR water-rate revenue for the same period. Computed by us, not a filed line.
A28: Input A: Form 990 program-service revenue | B28: 93067 | C28: Form 990 Part VIII line 2 (total program-service revenue), fiscal year 2023 ending December 31, 2023
A29: Input B: eAR water-rate revenue | B29: 3945052 | C29: State Water Board eAR Section 8b, question B1.1 + B1.2 (revenue from water rates), reporting year 2023
A30: Residual (A minus B) = assessment revenue | B30: =B28-B29 | C30: $93,067 (990 program-service revenue) minus $3,945,052 (eAR water-rate revenue) = $-3,851,985
A31: Period alignment: Both inputs cover the same period: the eAR Section 8b is the calendar year 2023 and the Form 990 fiscal year 2023 ends December 31, 2023, so the residual is period-aligned.
A32: What it IS: revenue the system booked as program service on its 990 that is not accounted for by the eAR water-rate line, plausibly member assessments and other service revenue.
A33: This residual is a difference between two sources for the same period; it is not a separately filed assessment line and may include other unmatched revenue.
A34: Denominator: Total service connections | B34: 3128 | C34: eAR Section 4 CurTotalConnections, reporting year 2023. State Water Board eAR Section 4 (CurTotalConnections), reporting year 2023
A35: Per customer: residual $-3,851,985 / 3,128 connections = $-1,231.45 per connection
A36: Share of revenue: residual $-3,851,985 / 990 program-service revenue $93,067 = -4138.94%
A38: Meter revenue - not reported
A39: Not reported. This category is not built because doing so would double-count.
A40: Reason: The eAR Section 8a reports a base/meter rate PRICE, but the filing carries no meter revenue line and no tier volume, and the base charge is already inside the water-sales revenue (eAR Section 8b water rates). Building a separate meter figure would double-count. Not backed into from a total.
A42: Overage or tiered penalty revenue - not reported
A43: Not reported. This category is not built because doing so would double-count.
A44: Reason: The eAR Section 8a reports tiered/overage rate PRICES, but the filing carries no overage revenue and no tier consumption volume, and any overage billed is already inside the water-sales revenue. Building it would double-count. Not backed into from a total.

Sheet Rate structure
A1: Rubio Canon Land & Water Association
A2: Rate structure and representative bill - eAR Section 8a (RY2024)
A3: Entity ID: cawc_0027 | Fiscal year ends December 31.
A5: This block is a rate-schedule illustration at defined usage levels. It is NOT billed revenue and not a claim about any real customer's usage. The revenue side of unit economics is the separate Unit Economics block.
A6: Structure: Tiered increasing-block with a fixed base, billed monthly, priced per HCF. Rate schedule last updated 03/01/2024.
A7: Defined single-family usage levels, identical for every company so the bill is comparable: Low = 5 HCF/month (~125 gallons/day); Median = 10 HCF/month (~249 gallons/day); High = 25 HCF/month (~623 gallons/day). 1 HCF = 748 gallons, and 1 thousand gallons = 1,000 gallons. The usage is converted into the company's own filed unit before the filed tiers are applied, and the bill is stated as a monthly equivalent: a bimonthly structure is computed at twice the monthly usage and divided by two, and any other billing period the same way with its factor stated. These are an illustration, not a measured usage for any real customer.
A9: Defined usage levels (EDITABLE - change a yellow cell to move the bill)
B10: Low | C10: Median | D10: High
A11: Monthly usage (HCF) | B11: 5 | C11: 10 | D11: 25
A12: Months per bill (from filed billing frequency) | B12: 1 | C12: monthly biller
A14: Filed rate table - single-family residential (as filed, eAR Section 8a)
A15: Base / fixed charge per monthly bill ($) | B15: 31.5
A16: Tier | B16: Range (HCF) | C16: Price ($/HCF) | D16: Upper limit (HCF)
A17: Tier 1 | B17: 0 to 12 HCF | C17: 3.75 | D17: 12
A18: Tier 2 | B18: 12 to 14 HCF | C18: 4.75 | D18: 14
A19: Tier 3 | B19: over 14 HCF | C19: 5.15 | D19: no limit
A21: Representative monthly bill - LIVE (edit a yellow usage cell to recompute)
B22: Low | C22: Median | D22: High
A23: Usage per bill (HCF) | B23: =B11*$B$12 | C23: =C11*$B$12 | D23: =D11*$B$12
A24: Tier 1 charge per bill ($) | B24: =$C$17*MAX(0,MIN(B23,$D$17)-0) | C24: =$C$17*MAX(0,MIN(C23,$D$17)-0) | D24: =$C$17*MAX(0,MIN(D23,$D$17)-0)
A25: Tier 2 charge per bill ($) | B25: =$C$18*MAX(0,MIN(B23,$D$18)-$D$17) | C25: =$C$18*MAX(0,MIN(C23,$D$18)-$D$17) | D25: =$C$18*MAX(0,MIN(D23,$D$18)-$D$17)
A26: Tier 3 charge per bill ($) | B26: =$C$19*MAX(0,B23-$D$18) | C26: =$C$19*MAX(0,C23-$D$18) | D26: =$C$19*MAX(0,D23-$D$18)
A27: Volumetric charge per bill ($) | B27: =SUM(B24,B25,B26) | C27: =SUM(C24,C25,C26) | D27: =SUM(D24,D25,D26)
A28: Base charge per bill ($) | B28: =$B$15 | C28: =$B$15 | D28: =$B$15
A29: Total per bill ($) | B29: =B28+B27 | C29: =C28+C27 | D29: =D28+D27
A30: Total per MONTH ($) | B30: =B29/$B$12 | C30: =C29/$B$12 | D30: =D29/$B$12
A31: Fixed per month ($) | B31: =$B$15/$B$12 | C31: =$B$15/$B$12 | D31: =$B$15/$B$12
A32: Volumetric per month ($) | B32: =B27/$B$12 | C32: =C27/$B$12 | D32: =D27/$B$12
A33: Effective price ($/HCF) | B33: =IF(B11=0,"",B30/B11) | C33: =IF(C11=0,"",C30/C11) | D33: =IF(D11=0,"",D30/D11)
A35: Rate-structure comparison metrics
A36: Fixed share of the bill at median usage | B36: =C31/C30 | C36: fixed / total at 10 HCF/month
A37: Tier price ratio (highest to lowest positive tier) | B37: =$C$19/$C$17 | C37: highest filed tier price divided by lowest filed tier price.
A38: Rate structure (as filed) | B38: tiered (Variable Base)
A40: State Water Board eAR Section 8a (Customer Charges), single- and multi-family residential charges grid, reporting year 2024. Rate structure only; no revenue.

Sheet eAR revenue & expenses
A1: Rubio Canon Land & Water Association
A2: eAR annual revenue and expenses - State Water Board eAR Section 8b (USD)
A3: Entity ID: cawc_0027 | Fiscal year ends December 31.
A5: The water system's own annual figures from the public eAR Section 8b, on the calendar year 2023 the filer self-reported (B0.1/B0.2). Shown beside the period-aligned Form 990 with the variance flagged: a different source (a State Water Board self-report vs an IRS filing). Preserved as filed, never reconciled.
A6: Reporting period basis (self-reported) | B6: calendar year 2023 | C6: eAR Section 8b B0.1 (WRFinancialReportingPeriod)
A8: Revenue (eAR Section 8b, questions B1.x)
A9: Line | B9: Amount (USD) | C9: Citation
A10: Water rate revenue | B10: 3945052 | C10: State Water Board eAR Section 8b, question B1.1 + B1.2 (revenue from water rates), reporting year 2023
A11: Other fees and charges | B11: 49136 | C11: State Water Board eAR Section 8b, question B1.3 + B1.4 (revenue from other fees), reporting year 2023
A12: Non-customer revenue | B12: 0 | C12: State Water Board eAR Section 8b, question B1.7 (grants, interest, and other non-customer), reporting year 2023
A13: Total annual revenue | B13: 3994188 | C13: State Water Board eAR Section 8b, question B1.8 (total annual revenue for the reporting year), reporting year 2023
A15: Expenses (eAR Section 8b, questions B2.x)
A16: Line | B16: Amount (USD) | C16: Citation
A17: Operations and maintenance | B17: 3377211 | C17: State Water Board eAR Section 8b, question B2.1 (annual O and M expense), reporting year 2023
A18: Capital | B18: 925508 | C18: State Water Board eAR Section 8b, question B2.2 (annual expenses from investing or capital), reporting year 2023
A19: Financing | B19: 0 | C19: State Water Board eAR Section 8b, question B2.3 (annual expenses from financing), reporting year 2023
A20: Other | B20: 0 | C20: State Water Board eAR Section 8b, question B2.4 (total other annual expenses), reporting year 2023
A21: Total annual expenses | B21: 4302719 | C21: State Water Board eAR Section 8b, question B2.5 (total annual expenses), reporting year 2023
A23: Period-aligned Form 990 comparison (variance surfaced, never reconciled)
A24: Measure | B24: eAR Section 8b | C24: Form 990
A25: total revenue | B25: 3994188 | C25: 2746190
A26: Variance (eAR minus Form 990) | B26: =B25-C25
A27: The eAR Section 8b total revenue (State Water Board self-report, calendar year 2023) and the Form 990 total revenue (IRS filing) are a different source and cover the same calendar year 2023. Both are carried as filed; the variance is surfaced, never reconciled.
A28: total expenses | B28: 4302719 | C28: 1933240
A29: Variance (eAR minus Form 990) | B29: =B28-C28
A30: The eAR Section 8b total expenses (State Water Board self-report, calendar year 2023) and the Form 990 total expenses (IRS filing) are a different source and cover the same calendar year 2023. Both are carried as filed; the variance is surfaced, never reconciled.

Sheet Denominators & alignment
A1: Rubio Canon Land & Water Association
A2: Denominators and calendar alignment
A3: Entity ID: cawc_0027 | Fiscal year ends December 31.
A5: System size and water use per fiscal year (the operating denominators that per-customer and per-acre metrics divide by), each cited to file and field. The eAR is reported on the calendar year; the 990 fiscal year differs by company. A calendar-year filer's volume is the eAR annual total (fiscal year = calendar year); an offset filer's is recast by a true monthly sum of the covered calendar months, or read not reported naming the missing months. Point-in-time counts (connections, population) are matched to the closest eAR year and never summed. Every derived figure states its formula and accounting rationale.
A6: Member vs customer (two different denominators, both preserved)
A7: Customer (service connection) | B7: 3136 | C7: State Water Board eAR Section 4 (CurTotalConnections), reporting year 2024
A8: SDWIS service-connection count (different registry) | B8: 3128 | C8: SDWIS reports 3,128 service connections for the same system; the eAR and SDWIS use different registries, so the two counts differ and are both preserved, not reconciled.
A9: Member (shareholder) | C9: No published shareholder count
A10: In a mutual water company a MEMBER is a shareholder who owns part of the system; a CUSTOMER is a metered service connection that receives water. The two diverge because one owner can hold several connections, a connection can serve people who are not owners, and some mutuals attach shares to land by acreage rather than counting heads. Per-customer metrics divide by service connections; per-member metrics divide by shareholders; the two counts are never used interchangeably.
A12: Denominator layer by fiscal year
A13: Fiscal year (end) | B13: Connections | C13: Population | D13: Service-area acres | E13: Water produced (AF) | F13: Water delivered (AF) | G13: Alignment method
A14: FY2020 (2020-12-31) | B14: 3128 | C14: not reported | D14: 1337.2 | E14: not reported | F14: not reported | G14: eAR annual total, calendar filer, equals fiscal year (not a monthly recast)
A15: FY2021 (2021-12-31) | B15: 3128 | C15: not reported | D15: 1337.2 | E15: not reported | F15: not reported | G15: eAR annual total, calendar filer, equals fiscal year (not a monthly recast)
A16: FY2022 (2022-12-31) | B16: 3128 | C16: not reported | D16: 1337.2 | E16: not reported | F16: not reported | G16: eAR annual total, calendar filer, equals fiscal year (not a monthly recast)
A17: FY2023 (2023-12-31) | B17: 3128 | C17: 9600 | D17: 1337.2 | E17: not reported | F17: not reported | G17: eAR annual total, calendar filer, equals fiscal year (not a monthly recast)
A18: FY2024 (2024-12-31) | B18: 3136 | C18: 9600 | D18: 1337.2 | E18: not reported | F18: not reported | G18: eAR annual total, calendar filer, equals fiscal year (not a monthly recast)
A20: Connections by class - FY2024 (eAR Section 4)
A21: Single-family residential | B21: 2810
A22: Multi-family residential | B22: 211
A23: Commercial and institutional | B23: 117
A24: Industrial | B24: 0
A25: Landscape irrigation | B25: 20
A26: Monthly-volume source: California open-data portal (data.ca.gov): the separate Produced Water (by month and source) and Delivered Water (by month and connection type) resources, which cover every public water system (not only urban suppliers), one resource per reporting year, matched by exact PWSID. This is the aggregate publication of eAR Section 6.

Sheet Governance evidence
A1: Rubio Canon Land & Water Association
A2: Governance evidence status - Ostrom's eight design principles
A3: Entity ID: cawc_0027 | Fiscal year ends December 31.
A5: Evidence summary: 4 documented, 2 partial, 2 not documented of eight principles.
A6: A count of how many of Elinor Ostrom's eight design principles have a supporting record on file, not a grade. NOT DOCUMENTED means the supporting record was not found, not that the company governs badly. It marks a gap in the documentary record, an evidence gap to close, never a governance failing.
A7: Each mutual is read against Elinor Ostrom's eight design principles for institutions that govern a shared resource durably. Per principle: a one-line finding, the observable signal, a citation, and an evidence status stating whether the supporting record exists: DOCUMENTED (a cited record supports alignment), PARTIAL (some evidence exists but it is incomplete), or NOT DOCUMENTED (no supporting record was found). This is an evidence-status read, not a grade: the principles are never ranked, weighted, or given a letter, consistent with reporting as filed and not grading companies. NOT DOCUMENTED means the supporting record was not found, not that the company governs badly. It marks a gap in the documentary record, an evidence gap to close, never a governance failing.
A9: Principle | B9: Evidence status | C9: Finding | D9: Signal | E9: Citation
A10: Clearly defined boundaries | B10: DOCUMENTED | C10: The system is a defined public water system: about 3,128 service connections over a State-published and field-verified service-area boundary of roughly 1,337.2 acres. | D10: SDWIS Community water system; SABL service-area boundary (Verified); connections defined. | E10: [C][G]
A11: What the record shows: SDWIS defines the membership as a fixed set of service connections and the State Water Board publishes a SABL service-area polygon for it, so who is inside and outside the system is documented. The boundary here is FIELD-VERIFIED by the Water Board rather than merely carried, which is stronger than most of this cohort.
A12: Rules fit local conditions | B12: DOCUMENTED | C12: Charges are tied to metered use under a filed rate schedule: a variable base residential structure billed monthly and priced per hundred cubic feet. | D12: eAR Section 8a customer charges; metered service; variable base residential rate structure priced per hundred cubic feet. | E12: [E]
A13: What the record shows: The record documents how charges are set: the filer reports metered service, monthly billing, a variable base residential rate structure and a filed rate schedule, so cost tracks service. Whether every tier scales precisely with use is not visible in the filing and is not claimed here.
A14: Collective-choice arrangements | B14: PARTIAL | C14: The company is owned by its customer-shareholders and states that a five member Board of Directors governs it, but the specific board, the election procedure and member votes are not in a source this project holds. | D14: Mutual ownership; a five member Board of Directors stated by the company; Form 990 governance section. | E14: [990][1]
A15: What the record shows: A collective-choice mechanism is documented in outline: customers are shareholders and the company states a five member board governs it. Three gaps keep this at PARTIAL rather than met, and the corporate registration that would close the first is NOT YET CHECKED for this company: the specific board membership, the election procedure, and any record of member votes. A stated board size is not a filed roster.
A16: Monitoring | B16: DOCUMENTED | C16: The system is metered and monitored: it files an annual eAR, publishes an annual Consumer Confidence Report that states its supply volumes, and holds a dated emergency response plan. | D16: Annual eAR reporting; metered connections; 2024 Consumer Confidence Report with stated volumes; emergency response plan dated 10/24/2023. | E16: [E][CCR][S]
A17: What the record shows: Operational monitoring is documented from more than one filing: the system reports metered service and files an annual eAR, its own Consumer Confidence Report states what it pumped, treated and imported for the year, and it holds a dated emergency response plan. The federal SDWIS violation check returned no violation records.
A18: Graduated sanctions | B18: NOT DOCUMENTED | C18: No published shut-off, penalty, or delinquency policy was found for this system. | D18: No sourced sanctions policy. | E18: not reported
A19: What the record shows: No public record of a graduated shut-off or penalty policy was located. NOT DOCUMENTED means the supporting record was not found, not that the company governs badly. It marks a gap in the documentary record, an evidence gap to close, never a governance failing.
A20: Conflict-resolution mechanisms | B20: NOT DOCUMENTED | C20: No published bylaws, dispute procedure, or grievance mechanism was found for this system. | D20: No sourced conflict-resolution record. | E20: not reported
A21: What the record shows: No public record of a member dispute or conflict-resolution procedure was located. NOT DOCUMENTED means the supporting record was not found, not that the company governs badly. It marks a gap in the documentary record, an evidence gap to close, never a governance failing.
A22: Recognized right to organize | B22: DOCUMENTED | C22: An incorporated California mutual water company recognized by the IRS as a 501(c)(12) exempt filer and by the State Water Board as a Community public water system. | D22: IRS 501(c)(12) exempt filer (Form 990); SDWIS Community public water system; eAR ownership type 'Privately owned Mutual Water Company or Association'. | E22: [990][C][E]
A23: What the record shows: Baseline legal standing is documented by two independent regulators: the IRS accepts it as a tax-exempt 501(c)(12) filer and the State Water Board holds it as a Community public water system with a mutual ownership type. Unlike the 22 mutuals covered by the 2026-08-21 Secretary of State pull, this status does NOT yet rest on a filed corporate record, because that check has not been run; the tier stands on the tax and drinking-water records alone.
A24: Nested enterprises | B24: PARTIAL | C24: The system buys imported water through Foothill Municipal Water District, a member agency of the Metropolitan Water District of Southern California, and pumps from a shared local groundwater basin, so it sits inside two larger systems; its role in governing either is not documented. | D24: eAR one approved purchased surface water source and three approved emergency interties; Consumer Confidence Report naming Foothill MWD and MWD of Southern California; own groundwater wells. | E24: [CCR][E]
A25: What the record shows: Physical nesting is documented twice over: the company holds a purchased connection to a regional wholesaler through Foothill MWD and pumps groundwater from a basin it shares with neighbors, and it holds three approved emergency interties with other systems. What is not documented is any governance role in the wholesaler or in a groundwater sustainability agency, so the tier is PARTIAL rather than met.

Sheet Operational metrics
A1: Rubio Canon Land & Water Association
A2: Operational metrics - plant per acre, density, terrain
A3: Entity ID: cawc_0027 | Fiscal year ends December 31.
A5: Plant assets per acre
A6: Service-area acres | B6: 1337.2 | C6: Geodesic area (WGS84 spherical excess) of the SABL service-area polygon.
A7: Fiscal year | B7: Gross plant per acre (primary) | C7: Net plant per acre
A8: FY2020 | B8: 15155.504 | C8: 7479.1579
A9: FY2021 | B9: 15906.579 | C9: 7792.9442
A10: FY2022 | B10: 16438.631 | C10: 7942.8777
A11: FY2023 | B11: 16990.087 | C11: 8070.0322
A12: FY2024 | B12: 17607.377 | C12: 8231.646
A13: Infrastructure built per acre of service area. Gross plant per acre is the primary read because it measures how much plant the system has put in the ground per acre, and unlike net plant it does not fall over time purely because the assets depreciate on the books. Net plant per acre is shown alongside as the depreciated book value per acre.
A14: Formula: gross plant per acre = Form 990 Part X line 10a (land, buildings, and equipment, gross) / SABL service-area acres; net plant per acre uses Part X line 10c (net)
A15: Source lines: Form 990 Part X line 10a (gross) and line 10c (net); Geodesic area (WGS84 spherical excess) of the SABL service-area polygon.
A16: Confidence: medium. This is worked out from filed figures (a ratio, or a year-to-year change), so it is one step removed from the raw numbers.. Filed gross/net plant over the measured SABL service-area acreage.
A18: Connections per acre
A19: Connections per acre | B19: 1.51 | C19: 2,014 connections / 1,337.2 acres. CA State Water Board SABL SERVICE_CONNECTIONS; Geodesic area (WGS84 spherical excess) of the SABL service-area polygon.
A21: Where the water comes from
A22: Terrain class | B22: canyon | C22: Company context page (BLUEPRINT 5B)
A23: Three channels: groundwater from the company's own wells, local canyon surface water treated at the company's own conventional treatment plant, and imported water bought from Foothill Municipal Water District, a member agency of the Metropolitan Water District of Southern California.

Sheet Supply & weather
A1: Rubio Canon Land & Water Association
A2: Supply and weather indicators (DWR water year)
A3: Entity ID: cawc_0027 | Fiscal year ends December 31.
A5: Reporting calendar: Different reporting periods. The DWR water year runs October 1 to September 30; this system's fiscal year ends December 31, so the two period ends are three months apart. Read the two side by side with that in mind. Neither series is recast: both are reported as filed. A water year is named for the calendar year it ends in, so WY2024 and FY2024 share a number without covering the same twelve months.
A7: Indicator | B7: WY2020 | C7: WY2021 | D7: WY2022 | E7: WY2023 | F7: WY2024
A8: Water-year type (Sacramento Valley) | B8: Dry | C8: Critical | D8: Critical | E8: Wet | F8: Above Normal
A9: Peak drought, Los Angeles County | B9: D1 | C9: D4 | D9: D4 | E9: D4 | F9: None (no D0-D4 during the fiscal year)
A10: Precip, percent of normal (8-Station Index) | B10: 63 | C10: 48 | D10: 86 | E10: 133 | F10: 96
A11: Snowpack, April 1 percent of average | B11: 53% | C11: 59% | D11: 38% | E11: 237% | F11: 110%
A12: State Water Project allocation | B12: 20% | C12: 5% | D12: 5% | E12: 100% | F12: 40%

Sheet How this was built
A1: Rubio Canon Land & Water Association
A2: How this was built - forensic lineage
A3: Entity ID: cawc_0027 | Fiscal year ends December 31.
A5: A plain account of the forensic lineage behind the hard-to-source metrics: what sources were checked, what was found, what was derived, and what could not be built and why. Every figure marked DERIVED or IMPOSSIBLE above is traceable to a line here.
A7: Water-sales revenue per customer - DIRECT
A8: Sources checked | B8: State Water Board eAR Section 8b (water-rate revenue B1.1/B1.2); State Water Board eAR Section 4 (connection count, same reporting year); audited financial statement (secondary cross-check, where published)
A9: What was found | B9: The eAR Section 8b reports water-rate revenue for reporting year 2023, so this is a DIRECT filed figure; per customer it is divided by the eAR Section 4 connection count for the same reporting year, so numerator and denominator share the year.
A11: Assessment revenue (residual) - DERIVED
A12: Sources checked | B12: Form 990 Part VIII line 2 (program-service revenue); State Water Board eAR Section 8b (water-rate revenue B1.1/B1.2)
A13: What was found | B13: No source separately reports a member assessment, so it is DERIVED as a residual: $93,067 (990 program-service revenue) minus $3,945,052 (eAR water-rate revenue) = $-3,851,985. Period-aligned; medium confidence.
A14: Caveat | B14: This residual is a difference between two sources for the same period; it is not a separately filed assessment line and may include other unmatched revenue.
A16: Meter revenue - not reported
A17: Sources checked | B17: State Water Board eAR Section 8a (rate prices); State Water Board eAR Section 8b (revenue lines); audited financial statement
A18: What was found | B18: The rate price exists in Section 8a but no revenue or tier volume is reported, and the base charge is already inside water sales.
A19: Caveat | B19: The eAR Section 8a reports a base/meter rate PRICE, but the filing carries no meter revenue line and no tier volume, and the base charge is already inside the water-sales revenue (eAR Section 8b water rates). Building a separate meter figure would double-count. Not backed into from a total.
A21: Overage / tiered-penalty revenue - not reported
A22: Sources checked | B22: State Water Board eAR Section 8a (rate prices); State Water Board eAR Section 8b (revenue lines); audited financial statement
A23: What was found | B23: The rate price exists in Section 8a but no revenue or tier volume is reported, and the base charge is already inside water sales.
A24: Caveat | B24: The eAR Section 8a reports tiered/overage rate PRICES, but the filing carries no overage revenue and no tier consumption volume, and any overage billed is already inside the water-sales revenue. Building it would double-count. Not backed into from a total.
A26: eAR Section 8b reporting-period basis - sourced
A27: Sources checked | B27: eAR Section 8b B0.1 (WRFinancialReportingPeriod); eAR Section 8b B0.2 (WRFiscalYearStartDate)
A28: What was found | B28: The reporting basis (fiscal vs calendar year) is read from the filer's own B0.1/B0.2 answer and staged verbatim, never hardcoded, so the 990 comparison and the residual are period-aligned.
A30: Member (shareholder) count denominator - not reported
A31: Sources checked | B31: Form 990 (no member count stated); company website
A32: What was found | B32: No filing states a member/shareholder count, so the per-member unit economics read not reported rather than borrowing the connection count.
A34: Water volume delivered (acre-feet) - not reported
A35: Sources checked | B35: Form 990 (not in the filing); Consumer Confidence Report; eAR Section 6 (PRA-gated)
A36: What was found | B36: Volume delivered in acre-feet is not in the Form 990 and the CCR states only a source mix, so the per-acre-foot metrics read not reported; the eAR Section 6 is named as the source still needed.

Sheet Water Operations
A1: Rubio Canon Land & Water Association
A2: Water Operations (sourced outside the financial filings)
A3: Entity ID: cawc_0027 | Fiscal year ends December 31.
A5: A separate dialect of data from the financial statements: the system's water supply, from the California State Water Board records (the Consumer Confidence Report served by the eAR portal, and SDWIS Drinking Water Watch). Each field carries its source, year, and confidence the same way a financial line item does; a field the source does not state reads 'not reported' with the source still needed. Figures are as reported, never estimated or reconciled across sources.
A7: Field | B7: Value | C7: Source | D7: Year | E7: Confidence | F7: Source excerpt / cross-source note
A8: Water type | B8: Potable (community drinking water) | C8: SDWIS Drinking Water Watch (State Water Board) | D8: 2024 | E8: high | F8: RUBIO CANON LAND & WATER ASSOCIATION: State Water System Type = Community.
A9: Source mix | B9: Primary source: surface water (SDWIS Primary Water Source Type: Surface Water). SDWIS classifies the primary supply type and states no acre-foot volume by source. The company's own 2024 Consumer Confidence Report does state volumes and is carried separately in ccr_source_mix: 1,696 acre-feet pumped from its own wells, 194 acre-feet of surface water treated, and no water imported that year. The two records are both kept and neither is reconciled into the other. | C9: SDWIS Drinking Water Watch (State Water Board) | D9: 2024 | E9: high | F9: RUBIO CANON LAND & WATER ASSOCIATION: Primary Water Source Type = Surface Water. [cross-source: SDWIS classifies the primary source as Surface Water, while the company's own 2024 report describes wells supplying the larger share of the year's volume. Both are as published; neither is picked.]
A10: Service connections (total) | B10: 3,128 connections | C10: SDWIS Drinking Water Watch (State Water Board) | D10: 2024 | E10: high | F10: RUBIO CANON LAND & WATER ASSOCIATION: Total Number of Service Connections = 3,128. [cross-source: Three sources count this system's connections and they do not agree: SDWIS 3,128; eAR reporting year 2024 3,136 active and 3,158 total potable; the company's own site more than 3,140. All three are preserved as filed and none is reconciled.]
A11: Connections by class | B11: Service connections by class (eAR Section 4, reporting year 2024): Single family 2,810; Multi family 211; Commercial and institutional 117; Landscape irrigation 20; Industrial 0; Active total 3,136. | C11: ear | D11: 2024 | E11: high | F11: eAR Section 4: single family 2,810; multi family 211; commercial or institutional 117; landscape irrigation 20; industrial 0. [cross-source: Not comparable line for line with the SDWIS by-type snapshot carried for companies onboarded before 2026-08-26, which uses a coarser Residential and Commercial split.]
A12: Population served | B12: 9,600 residents | C12: SDWIS Drinking Water Watch (State Water Board) | D12: 2024 | E12: high | F12: RUBIO CANON LAND & WATER ASSOCIATION: Total Population = 9,600.
A13: Treatment and water quality | B13: The company operates its own conventional treatment plant, which treats surface water acquired from the local foothill area, and separately obtains treated imported water from Foothill Municipal Water District. Process detail beyond this is not stated in the report. | C13: ccr | D13: 2024 | E13: high | F13: RCLWA provides potable drinking water via groundwater wells, a conventional treatment plant, and from an imported source. [cross-source: Describes the treatment process, not the operator-certification grades carried for companies onboarded before 2026-08-26. The two are different facts and are not interchangeable.]
A15: Not reported (source still needed)
A16: Annual volume delivered (acre-feet) | B16: not reported - needs annual volume in acre-feet (State Water Board eAR Section 6 or company production records); the CCR states only a percentage mix
A17: Customer classes served | B17: not reported - needs the State Water Board eAR or the system CCR

Sheet Anomaly Flags
A1: Rubio Canon Land & Water Association
A2: Anomaly Flags (automated; kept separate from the clean statements)
A3: Entity ID: cawc_0027 | Fiscal year ends December 31.
A5: Material irregularities found automatically in the filed financials by the Hydronomics anomaly flagger. Each flag has two clearly separated layers. WHAT is mechanical, certain, and sourced: the exact filed lines, years, and amounts, carried as filed and never reconciled. WHY is attempted: the filing's own narrative is checked first, and when it states no reason a single best-guess hypothesis is shown, clearly labelled as a guess that is not in the filing and is not a verified figure.
A7: Flag: FY2024 total expenses swing
A8: Affected figure | B8: Total expenses FY2024
A9: Confidence | B9: high
A10: What happened (filed, sourced) | B10: FY2024 total expenses rose to $3,333,755 from $1,933,240 in FY2023, a 72 percent move ($1,400,515 in absolute terms). Carried as filed and flagged as a documented anomaly, not smoothed.
A11: Source lines | B11: - total expenses: $1,933,240 FY2023, $3,333,755 FY2024
A12: Confidence reasoning | B12: A year-over-year move in a filed headline total that exceeds both the percentage and the dollar threshold; carried as filed.
A13: Why (not stated in the filing) | B13: The filing does not state a reason.
A14: Possible explanation (guess) | B14: Possible explanation, not stated in filing: a large one-year move in total expenses may reflect a one-time item or a change in how it was recorded. This is an educated guess, not something the filing actually says.
A16: Flag: FY2024 total revenue swing
A17: Affected figure | B17: Operating revenue FY2024
A18: Confidence | B18: high
A19: What happened (filed, sourced) | B19: FY2024 total revenue rose to $4,989,018 from $2,746,190 in FY2023, a 82 percent move ($2,242,828 in absolute terms). Carried as filed and flagged as a documented anomaly, not smoothed.
A20: Source lines | B20: - total revenue: $2,746,190 FY2023, $4,989,018 FY2024
A21: Confidence reasoning | B21: A year-over-year move in a filed headline total that exceeds both the percentage and the dollar threshold; carried as filed.
A22: Why (not stated in the filing) | B22: The filing does not state a reason.
A23: Possible explanation (guess) | B23: Possible explanation, not stated in filing: a large one-year move in total revenue may reflect a one-time item or a change in how it was recorded. This is an educated guess, not something the filing actually says.

Sheet Sources & audit
A1: Rubio Canon Land & Water Association
A2: Sources & audit - full provenance and tie-outs (kept off the statements so they read clean)
A3: Entity ID: cawc_0027 | Fiscal year ends December 31.
A5: Presentation standard: every figure on the statement tabs is verified to its source filing and shown clean. A cell the filing does not report reads "not reported" (never estimated, never guessed).
A6: Citations, confidence tiers, and the filed-vs-computed tie-out checks live on the "Sources & audit" tab, keyed by cell, so every number is fully traceable without cluttering the statements. These pages are ready to use as filed.
A8: A. Filing provenance (one row per staged extraction)
A9: Fiscal year | B9: Period end | C9: Filing type | D9: Confidence | E9: Extraction ID | F9: Object ID | G9: Extracted by | H9: Extracted at | I9: Source URL
A10: FY2020 | B10: 2020-12-31 | C10: 990 | D10: high | E10: ae3f7492-c22f-4be2-9396-d7c579bee61a | F10: 202101319349304135 | G10: claude-opus-5 | H10: 2026-09-14T20:40:24+00:00 | I10: https://apps.irs.gov/pub/epostcard/990/xml/2021/2021_TEOS_XML_01A.zip#202101319349304135_public.xml
A11: FY2021 | B11: 2021-12-31 | C11: 990 | D11: high | E11: 6cfe7a26-0564-4452-a83b-c828ea4c0a9e | F11: 202232119349300108 | G11: claude-opus-5 | H11: 2026-09-14T20:40:24+00:00 | I11: https://apps.irs.gov/pub/epostcard/990/xml/2022/2022_TEOS_XML_01A.zip#202232119349300108_public.xml
A12: FY2022 | B12: 2022-12-31 | C12: 990 | D12: high | E12: 05defe89-d360-4673-9033-da3da0c65399 | F12: 202322689349301617 | G12: claude-opus-5 | H12: 2026-09-14T20:40:24+00:00 | I12: https://apps.irs.gov/pub/epostcard/990/xml/2023/2023_TEOS_XML_10A.zip#202322689349301617_public.xml
A13: FY2023 | B13: 2023-12-31 | C13: 990 | D13: high | E13: fad9ba6e-4671-49fb-88cc-16c27211e266 | F13: 202421709349301237 | G13: claude-opus-5 | H13: 2026-09-14T20:40:24+00:00 | I13: https://apps.irs.gov/pub/epostcard/990/xml/2024/2024_TEOS_XML_06A.zip#202421709349301237_public.xml
A14: FY2024 | B14: 2024-12-31 | C14: 990 | D14: high | E14: 3cd79a51-91dc-422e-8065-ff9c6cdcc770 | F14: 202502669349300735 | G14: claude-opus-5 | H14: 2026-09-14T20:40:24+00:00 | I14: https://apps.irs.gov/pub/epostcard/990/xml/2025/2025_TEOS_XML_09A.zip#202502669349300735_public.xml
A16: B. Figure citations (every figure on the statement tabs, keyed by cell)
