Workbook

Sheet Summary
A1: Hat Creek Highlands Mutual Water Co
A2: Financial Summary - multi-year overview (USD)
A3: Entity ID: cawc_0106 | Fiscal year ends August 31.
A5: Presentation standard: every figure on the statement tabs is verified to its source filing and shown clean. A cell the filing does not report reads "not reported" (never estimated, never guessed).
A6: Citations, confidence tiers, and the filed-vs-computed tie-out checks live on the "Sources & audit" tab, keyed by cell, so every number is fully traceable without cluttering the statements. These pages are ready to use as filed.
A8: Metric | B8: FY2022 | C8: FY2023 | D8: FY2024 | E8: FY2025
A9: Operating results (USD)
A10: Total revenue | B10: 77965 | C10: 80031 | D10: 0 | E10: 90319
A11: Total expenses | B11: 62140 | C11: 87583 | D11: 15063 | E11: 91248
A12: Net income | B12: 15825 | C12: -7552 | D12: -15063 | E12: -929
A14: Financial position (USD, end of year)
A15: Total assets | B15: 392066 | C15: 371086 | D15: 356585 | E15: 367030
A16: Total liabilities | B16: 17440 | C16: 4012 | D16: 4574 | E16: 15948
A17: Net assets | B17: 374626 | C17: 367074 | D17: 352011 | E17: 351082
A19: Headline ratios
A20: Operating margin | B20: 0.20297569 | C20: -0.094363434 | E20: -0.010285765
A21: Revenue growth (YoY) | B21: 0 | C21: 0.02649907 | D21: -1 | E21: -0.011145538
A22: Return on assets | B22: 0.040363102 | C22: -0.020351078 | D22: -0.042242383 | E22: -0.0025311282
A24: Figures as reported in source filings (full provenance on the Sources & audit tab). Parentheses denote negatives; ratios are computed upstream in financials_annual.

Sheet Notes
A1: Notes
A2: Human annotations from the versioned store (data/notes/). Annotations only: they never change a reported figure or a confidence tier.
A4: Date | B4: Tag | C4: Author | D4: Note
A5: No notes recorded yet.

Sheet Financial Statements
A1: Hat Creek Highlands Mutual Water Co
A2: Financial Statements - income statement, balance sheet, cash flow, member income test (USD)
A3: Entity ID: cawc_0106 | Fiscal year ends August 31.
A5: INCOME STATEMENT - as reported (USD)
A6: Line item | B6: FY2022 | C6: FY2023 | D6: FY2024 | E6: FY2025
A7: Revenue
A8: Program service revenue | C8: 80031 | E8: 90319
A9: Investment income
A10: Net rental income
A11: Net gain/(loss) on investment sales
A12: Other revenue
A13: Contributions & grants | B13: 77965
A14: Total revenue | B14: 77965 | C14: 80031 | D14: 0 | E14: 90319
A16: Expenses
A17: Depreciation
A18: Interest expense | B18: 1475 | C18: 610
A19: Total expenses | B19: 62140 | C19: 87583 | D19: 15063 | E19: 91248
A21: Net income | B21: 15825 | C21: -7552 | D21: -15063 | E21: -929
A24: BALANCE SHEET - as reported (USD, end of year)
A25: Line item | B25: FY2022 | C25: FY2023 | D25: FY2024 | E25: FY2025
A26: Assets
A27: Cash | B27: 15594 | C27: 4578
A28: Savings & temporary investments | B28: 12722 | C28: 12722 | D28: 9148 | E28: 12721
A29: Accounts receivable | B29: 5075 | C29: 6349 | E29: 10517
A30: Inventories
A31: Prepaid expenses
A32: Property, plant & equipment (gross) | B32: 514396 | C32: 514396 | D32: 514396 | E32: 514396
A33: Less: accumulated depreciation | B33: -155721 | C33: -166959 | D33: -166959 | E33: -170604
A34: Net property, plant & equipment | B34: 358675 | C34: 347437 | D34: 347437 | E34: 343792
A35: Total assets | B35: 392066 | C35: 371086 | D35: 356585 | E35: 367030
A37: Liabilities
A38: Accounts payable | B38: 6177 | C38: 1995 | D38: 4574 | E38: 15948
A39: Mortgages & notes payable | B39: 11263 | C39: 2017
A40: Total liabilities | B40: 17440 | C40: 4012 | D40: 4574 | E40: 15948
A42: Net Assets / Equity
A43: Capital stock
A44: Paid-in capital
A45: Retained earnings | B45: 374626 | C45: 367074 | D45: 352011 | E45: 351082
A46: Net assets | B46: 374626 | C46: 367074 | D46: 352011 | E46: 351082
A49: CASH FLOW - derived proxy (USD)
...

Sheet Balance Sheet
A1: Hat Creek Highlands Mutual Water Co
A2: Balance Sheet - as reported (USD, end of year)
A3: Entity ID: cawc_0106 | Fiscal year ends August 31.
A5: Line item | B5: FY2022 | C5: FY2023 | D5: FY2024 | E5: FY2025
A6: Assets
A7: Cash | B7: 15594 | C7: 4578
A8: Savings & temporary investments | B8: 12722 | C8: 12722 | D8: 9148 | E8: 12721
A9: Accounts receivable | B9: 5075 | C9: 6349 | E9: 10517
A10: Inventories
A11: Prepaid expenses
A12: Property, plant & equipment (gross) | B12: 514396 | C12: 514396 | D12: 514396 | E12: 514396
A13: Less: accumulated depreciation | B13: -155721 | C13: -166959 | D13: -166959 | E13: -170604
A14: Net property, plant & equipment | B14: 358675 | C14: 347437 | D14: 347437 | E14: 343792
A15: Total assets | B15: 392066 | C15: 371086 | D15: 356585 | E15: 367030
A17: Liabilities
A18: Accounts payable | B18: 6177 | C18: 1995 | D18: 4574 | E18: 15948
A19: Mortgages & notes payable | B19: 11263 | C19: 2017
A20: Total liabilities | B20: 17440 | C20: 4012 | D20: 4574 | E20: 15948
A22: Net Assets / Equity
A23: Capital stock
A24: Paid-in capital
A25: Retained earnings | B25: 374626 | C25: 367074 | D25: 352011 | E25: 351082
A26: Net assets | B26: 374626 | C26: 367074 | D26: 352011 | E26: 351082
A28: Balance check (assets − liab. − net assets) | B28: 0 | C28: 0 | D28: 0 | E28: 0
A30: Net PP&E is the reported ppe_net column (gross less accumulated depreciation). The balance check should be ~0 where all three totals are reported; a non-zero value flags a reporting or extraction discrepancy worth reviewing.

Sheet Officers & contractors
A1: Hat Creek Highlands Mutual Water Co
A2: Officers, Directors & Contractors - Form 990 Part VII (FY2025; USD)
A3: Entity ID: cawc_0106 | Fiscal year ends August 31.
A5: Section A - Officers, directors, trustees, key employees
A6: Name | B6: Title | C6: Reportable comp (org) | D6: Reportable comp (related) | E6: Other comp | F6: Total compensation
A7: JANICE BUCKLE | C7: 0 | D7: 0 | E7: 0 | F7: 0
A8: CONNIE ANDERSON | C8: 0 | D8: 0 | E8: 0 | F8: 0
A9: ASTRID CEBOLLERO | C9: 0 | D9: 0 | E9: 0 | F9: 0
A10: IAN SEARS | B10: CHAIR | C10: 0 | D10: 0 | E10: 0 | F10: 0
A11: ALAN TOCHTERMAN | B11: TREASURER | C11: 0 | D11: 0 | E11: 0 | F11: 0
A12: ROXANNE BULLOCK | B12: SECRETARY | C12: 0 | D12: 0 | E12: 0 | F12: 0
A14: Section B - Independent contractors (over $100,000)
A15: Contractor | B15: Services | C15: Compensation
A17: Section A lists every officer, director, trustee and key employee filed for the latest year; the two with the highest total compensation are highlighted. Total compensation is computed (reportable org + related + other). Section B lists each independent contractor paid over $100,000; the return reports None such contractor(s). Source and confidence for every figure are on the Sources & audit tab.

Sheet Revenue (detail)
A1: Hat Creek Highlands Mutual Water Co
A2: Revenue - Form 990 Part VIII (USD)
A3: Entity ID: cawc_0106 | Fiscal year ends August 31.
A5: Part VIII line | B5: FY2022 | C5: FY2023 | D5: FY2024 | E5: FY2025
A6: Revenue by category
A7: 1h. Total contributions, gifts, grants | B7: 77965 | C7: not reported | D7: not reported | E7: not reported
A8: 2g. Total program service revenue | B8: not reported | C8: 80031 | D8: not reported | E8: 90319
A9: 3. Investment income | B9: not reported | C9: not reported | D9: not reported | E9: not reported
A10: 6d. Net rental income | B10: not reported | C10: not reported | D10: not reported | E10: not reported
A11: 7d. Net gain/(loss) from investment sales | B11: not reported | C11: not reported | D11: not reported | E11: not reported
A12: 11e. Other revenue | B12: not reported | C12: not reported | D12: not reported | E12: not reported
A13: 12. Total revenue | B13: =SUM(B7:B12) | C13: =SUM(C7:C12) | D13: =SUM(D7:D12) | E13: =SUM(E7:E12)
A15: Program service revenue detail - FY2025 (lines 2a-2f)
A16: Description | B16: Business code | C16: Total revenue
A17: WATER SERVICE | B17: 221000 | C17: 90319
A18: Revenue category subtotals are as filed. Total revenue (line 12) is a live SUM of the category cells above; its tie-out to the filed total is on the Sources & audit tab. Program service revenue detail is shown for the latest year, with its sum-to-line-2g check on that same audit tab.

Sheet Operating expenses (detail)
A1: Hat Creek Highlands Mutual Water Co
A2: Statement of Functional Expenses - Form 990 Part IX (USD)
A3: Entity ID: cawc_0106 | Fiscal year ends August 31.
A5: Part IX line (column A Total) | B5: FY2022 | C5: FY2023 | D5: FY2024 | E5: FY2025
A6: Functional expenses, column A Total - by year
A7: 7. Other salaries and wages | B7: not reported | C7: 10370 | D7: not reported | E7: 27540
A8: 10. Payroll taxes | B8: not reported | C8: 1047 | D8: not reported | E8: 2373
A9: 11b. Fees for services: legal | B9: not reported | C9: 850 | D9: not reported | E9: not reported
A10: 11c. Fees for services: accounting | B10: not reported | C10: 9850 | D10: not reported | E10: 8000
A11: 20. Interest | B11: 1475 | C11: 610 | D11: not reported | E11: not reported
A12: 23. Insurance | B12: 3408 | C12: 3736 | D12: not reported | E12: 4372
A13: 24. CPA REVIEW | B13: 3500 | C13: not reported | D13: not reported | E13: not reported
A14: 24. BANK FEES | B14: 20 | C14: 10 | D14: 8 | E14: not reported
A15: 24. R&M | B15: 19694 | C15: 13750 | D15: not reported | E15: not reported
A16: 24. BOOKKEEPING | B16: 4800 | C16: not reported | D16: not reported | E16: not reported
A17: 24. MILEAGE | B17: not reported | C17: 19281 | D17: 15055 | E17: 16820
A18: 24. BOTTLED WATER | B18: not reported | C18: 2857 | D18: not reported | E18: not reported
A19: 24. UTILITIES | B19: not reported | C19: not reported | D19: not reported | E19: 14604
A20: 24. TAXES | B20: not reported | C20: not reported | D20: not reported | E20: 446
A21: 24e. All other expenses | B21: 29243 | C21: 25222 | D21: not reported | E21: 17093
A22: 25. Total functional expenses | B22: =SUM(B7:B21) | C22: =SUM(C7:C21) | D22: =SUM(D7:D21) | E22: =SUM(E7:E21)
A24: Functional column split - FY2025 (col A = B + C + D)
A25: Part IX line | B25: A. Total | C25: B. Program services | D25: C. Management & general | E25: D. Fundraising
A26: 7. Other salaries and wages | B26: 27540 | D26: 27540
A27: 10. Payroll taxes | B27: 2373 | D27: 2373
A28: 11c. Fees for services: accounting | B28: 8000 | D28: 8000
A29: 23. Insurance | B29: 4372 | D29: 4372
A30: 25. Total (filed col A / B / C / D) | B30: 91248 | C30: 0 | D30: 91248 | E30: 0
A32: Top block: each Part IX line, column A (Total), by year, as filed. Total functional expenses (line 25) is a live SUM of the line cells; its tie-out to the filed total is on the Sources & audit tab. Filer-itemized 24a-24d rows show the most recent year's as-filed wording; rows are aligned across years case-insensitively with collapsed spacing, so a line filed only in a different capitalization or spacing shares one row, while genuinely different wording stays a separate row (every as-filed variant is recorded on the Sources & audit tab). Lower block: the program / management / fundraising split for the latest year, with its col A = B + C + D check on the audit tab. Lines this filer does not report are omitted rather than shown empty.

Sheet Balance sheet (detail)
A1: Hat Creek Highlands Mutual Water Co
A2: Balance Sheet - Form 990 Part X (end of year, USD)
A3: Entity ID: cawc_0106 | Fiscal year ends August 31.
A5: Part X line (column B, EOY) | B5: FY2022 | C5: FY2023 | D5: FY2024 | E5: FY2025
A6: Assets
A7: 1. Cash - non-interest-bearing | B7: 15594 | C7: 4578 | D7: not reported | E7: not reported
A8: 2. Savings and temporary cash investments | B8: 12722 | C8: 12722 | D8: 9148 | E8: 12721
A9: 4. Accounts receivable, net | B9: 5075 | C9: 6349 | D9: not reported | E9: 10517
A10: 10c. Land, buildings, and equipment, net | B10: 358675 | C10: 347437 | D10: 347437 | E10: 343792
A11: 16. Total assets | B11: =SUM(B7:B10) | C11: =SUM(C7:C10) | D11: =SUM(D7:D10) | E11: =SUM(E7:E10)
A13: Liabilities
A14: 17. Accounts payable and accrued expenses | B14: 6177 | C14: 1995 | D14: 4574 | E14: 15948
A15: 23. Secured mortgages and notes payable | B15: 11263 | C15: 2017 | D15: not reported | E15: not reported
A16: 26. Total liabilities | B16: =SUM(B14:B15) | C16: =SUM(C14:C15) | D16: =SUM(D14:D15) | E16: =SUM(E14:E15)
A18: Net assets / fund balances
A19: 31. Retained earnings / accumulated funds | B19: 374626 | C19: 367074 | D19: 352011 | E19: 351082
A20: 32. Total net assets / fund balances | B20: =SUM(B19:B19) | C20: =SUM(C19:C19) | D20: =SUM(D19:D19) | E20: =SUM(E19:E19)
A22: Every Part X line is end-of-year (column B), as filed. Section totals (lines 16 / 26 / 32) are live SUMs of the lines above; their tie-outs and the balance-sheet identity (16 = 26 + 32) are on the Sources & audit tab. This filer files as a non-FASB mutual, so net assets sit on lines 29-31 (capital stock / paid-in capital / retained earnings); lines this filer does not report are omitted. Lines 10a/10b net into line 10c (shown).

Sheet Net-assets reconciliation
A1: Hat Creek Highlands Mutual Water Co
A2: Reconciliation of Net Assets - Form 990 Part XI (USD)
A3: Entity ID: cawc_0106 | Fiscal year ends August 31.
A5: Part XI line | B5: FY2022 | C5: FY2023 | D5: FY2024 | E5: FY2025
A6: Reconciliation
A7: 4. Net assets, beginning of year | B7: 358801 | C7: 374626 | D7: 367074 | E7: 352011
A8: 3. Revenue less expenses | B8: 15825 | C8: -7552 | D8: -15063 | E8: -929
A9: 8. Prior period adjustments | B9: not reported | C9: not reported | D9: not reported | E9: not reported
A10: 9. Other changes in net assets | B10: 0 | C10: 0 | D10: 0 | E10: 0
A11: 10. Net assets, end of year | B11: =SUM(B7,B8,B9,B10) | C11: =SUM(C7,C8,C9,C10) | D11: =SUM(D7,D8,D9,D10) | E11: =SUM(E7,E8,E9,E10)
A13: Part XI reconciles beginning to ending net assets. Ending net assets (line 10) is a live formula: beginning balance (line 4) + revenue less expenses (line 3) + prior-period adjustments (8) + other changes (9). Its tie-out to the filed line 10 (and to Part X line 32) is on the Sources & audit tab. Lines 5-7 (unrealized gains, donated services, investment expenses) are not filed by this entity.

Sheet Cash flow proxies
A1: Hat Creek Highlands Mutual Water Co
A2: Cash Flow Proxies - derived (USD)
A3: Entity ID: cawc_0106 | Fiscal year ends August 31.
A5: PROXY ONLY. The source filings contain no statement of cash flows. Lines below are derived from the reported income statement and year-over-year balance-sheet changes; treat as directional estimates, not GAAP cash flows. The earliest year has no prior period, so its delta cells are blank.
A7: Proxy line (USD) | B7: FY2022 | C7: FY2023 | D7: FY2024 | E7: FY2025
A8: Operating
A9: Net income | B9: 15825 | C9: -7552 | D9: -15063 | E9: -929
A10: + Depreciation (reported)
A11: − Δ Accounts receivable | C11: -1274
A12: − Δ Inventories
A13: − Δ Prepaid expenses
A14: + Δ Accounts payable | C14: -4182 | D14: 2579 | E14: 11374
A15: Operating cash flow proxy | C15: -13008 | D15: -12484 | E15: 10445
A17: Investing
A18: − Δ PP&E gross (capex proxy) | C18: 0 | D18: 0 | E18: 0
A20: Financing
A21: Δ Mortgages & notes payable | C21: -9246
A23: Reconciliation
A24: Δ Cash + temp. investments (actual) | C24: -11016 | D24: -8152 | E24: 3573
A26: The capex proxy assumes gross PP&E rises only via capital spending (it ignores disposals). 'Δ Cash + temp. investments (actual)' is the real reported change in liquid funds and is the most reliable line here; the operating/investing/financing proxies will not perfectly reconcile to it.

Sheet Ratios
A1: Hat Creek Highlands Mutual Water Co
A2: Financial Ratios
A3: Entity ID: cawc_0106 | Fiscal year ends August 31.
A5: Ratio | B5: FY2022 | C5: FY2023 | D5: FY2024 | E5: FY2025
A6: Profitability (computed upstream)
A7: Operating margin (NI / revenue) | B7: 0.20297569 | C7: -0.094363434 | E7: -0.010285765
A8: Expense ratio (expenses / revenue) | B8: 0.79702431 | C8: 1.0943634 | E8: 1.0102858
A9: Return on assets (NI / assets) | B9: 0.040363102 | C9: -0.020351078 | D9: -0.042242383 | E9: -0.0025311282
A10: Revenue growth (YoY) | B10: 0 | C10: 0.02649907 | D10: -1 | E10: -0.011145538
A12: Leverage & solvency
A13: Debt-to-assets (liab. / assets) | B13: 0.044482307 | C13: 0.01081151 | D13: 0.012827236 | E13: 0.043451489
A14: Equity ratio (net assets / assets) | B14: 0.95551769 | C14: 0.98918849 | D14: 0.98717276 | E14: 0.95654851
A16: Liquidity & asset profile (derived here)
A17: Current ratio (current assets / AP) | B17: 5.4056986 | C17: 11.854135 | D17: 2 | E17: 1.4571106
A18: Cash ratio ((cash+temp inv.) / total liab.) | B18: 1.6236239 | C18: 4.3120638 | D18: 2 | E18: 0.79765488
A19: Asset age proxy (accum. deprec. / gross PP&E) | B19: 0.30272592 | C19: 0.3245729 | D19: 0.3245729 | E19: 0.33165888
A21: Upstream ratios are read from financials_annual; derived ratios are computed only where inputs are reported. Current ratio uses accounts payable as the current-liability proxy (the filings do not split current vs. long-term liabilities). Asset age proxy: a higher % implies older / more depreciated infrastructure.

Sheet Unit economics
A1: Hat Creek Highlands Mutual Water Co
A2: Unit economics - per-customer revenue by category (USD)
A3: Entity ID: cawc_0106 | Fiscal year ends August 31.
A5: Every metric here is PER CUSTOMER (a metered service connection). It is not a per-member figure; the member (shareholder) count is a different denominator, shown in the denominator block. The visible cell shows the value and its classification; the numerator, denominator, formula, and rationale are in each metric's LOGIC popup.
A6: Per-customer denominator (service connections) | C6: State Water Board eAR Section 4
A7: Total annual revenue (eAR Section 8b B1.8) | C7: eAR Section 8b total annual revenue not reported for this system.
A8: Primary source
A10: Revenue categories (value, classification, per customer, share)
A11: Revenue category | B11: Classification | C11: Value (USD) | D11: Per customer | E11: Share of revenue
A12: Water sales revenue | B12: not reported | C12: not reported | D12: not reported | E12: not reported
A13: Assessment revenue (990 program-service revenue not matched to eAR water-rate revenue) | B13: IMPOSSIBLE | C13: IMPOSSIBLE | D13: IMPOSSIBLE | E13: IMPOSSIBLE
A14: Meter revenue | B14: not reported | C14: not reported | D14: not reported | E14: not reported
A15: Overage or tiered penalty revenue | B15: not reported | C15: not reported | D15: not reported | E15: not reported
A17: Water sales revenue - not reported
A18: Not reported: this system filed an eAR but no Section 8b revenue block, so there is no filed water-sales figure. Not fallen back to a different year.
A19: Reason: No filed eAR Section 8b water-rate revenue for this system.
A21: Assessment revenue (990 program-service revenue not matched to eAR water-rate revenue) - IMPOSSIBLE
A22: Not computed. A period-aligned residual is not possible for this filer.
A23: Reason: Not derivable. The eAR Section 8b is reporting year None while the Form 990 fiscal year ends None; the two period ends are not aligned, so a period-aligned residual cannot be computed.
A25: Meter revenue - not reported
A26: Not reported. This category is not built because doing so would double-count.
A27: Reason: The eAR Section 8a reports a base/meter rate PRICE, but the filing carries no meter revenue line and no tier volume, and the base charge is already inside the water-sales revenue (eAR Section 8b water rates). Building a separate meter figure would double-count. Not backed into from a total.
A29: Overage or tiered penalty revenue - not reported
A30: Not reported. This category is not built because doing so would double-count.
A31: Reason: The eAR Section 8a reports tiered/overage rate PRICES, but the filing carries no overage revenue and no tier consumption volume, and any overage billed is already inside the water-sales revenue. Building it would double-count. Not backed into from a total.

Sheet Rate structure
A1: Hat Creek Highlands Mutual Water Co
A2: Rate structure and representative bill - eAR Section 8a
A3: Entity ID: cawc_0106 | Fiscal year ends August 31.
A5: This block is a rate-schedule illustration at defined usage levels. It is NOT billed revenue and not a claim about any real customer's usage. The revenue side of unit economics is the separate Unit Economics block.
A6: No filed eAR Section 8a rate schedule is staged for this system.

Sheet Operational metrics
A1: Hat Creek Highlands Mutual Water Co
A2: Operational metrics - plant per acre, density, terrain
A3: Entity ID: cawc_0106 | Fiscal year ends August 31.
A5: Plant assets per acre
A6: Service-area acres | B6: 177.1 | C6: Geodesic area (WGS84 spherical excess) of the SABL service-area polygon.
A7: Fiscal year | B7: Gross plant per acre (primary) | C7: Net plant per acre
A8: FY2022 | B8: 2904.5511 | C8: 2025.2682
A9: FY2023 | B9: 2904.5511 | C9: 1961.8125
A10: FY2024 | B10: 2904.5511 | C10: 1961.8125
A11: FY2025 | B11: 2904.5511 | C11: 1941.2309
A12: Infrastructure built per acre of service area. Gross plant per acre is the primary read because it measures how much plant the system has put in the ground per acre, and unlike net plant it does not fall over time purely because the assets depreciate on the books. Net plant per acre is shown alongside as the depreciated book value per acre.
A13: Formula: gross plant per acre = Form 990 Part X line 10a (land, buildings, and equipment, gross) / SABL service-area acres; net plant per acre uses Part X line 10c (net)
A14: Source lines: Form 990 Part X line 10a (gross) and line 10c (net); Geodesic area (WGS84 spherical excess) of the SABL service-area polygon.
A15: Confidence: medium. This is worked out from filed figures (a ratio, or a year-to-year change), so it is one step removed from the raw numbers.. Filed gross/net plant over the measured SABL service-area acreage.
A17: Connections per acre
A18: Connections per acre | B18: 0.28 | C18: 50 connections / 177.1 acres. CA State Water Board SABL SERVICE_CONNECTIONS; Geodesic area (WGS84 spherical excess) of the SABL service-area polygon.

Sheet Supply & weather
A1: Hat Creek Highlands Mutual Water Co
A2: Supply and weather indicators (DWR water year)
A3: Entity ID: cawc_0106 | Fiscal year ends August 31.
A5: Reporting calendar: Different reporting periods. The DWR water year runs October 1 to September 30; this system's fiscal year ends August 31, so the two period ends are one months apart. Read the two side by side with that in mind. Neither series is recast: both are reported as filed. A water year is named for the calendar year it ends in, so WY2024 and FY2024 share a number without covering the same twelve months.
A7: Indicator | B7: WY2022 | C7: WY2023 | D7: WY2024 | E7: WY2025
A8: Water-year type (Sacramento Valley) | B8: Critical | C8: Wet | D8: Above Normal | E8: not reported
A9: Peak drought, county County | B9: not reported | C9: not reported | D9: not reported | E9: not reported
A10: Precip, percent of normal (8-Station Index) | B10: 86 | C10: 133 | D10: 96 | E10: 113
A11: Snowpack, April 1 percent of average | B11: 38% | C11: 237% | D11: 110% | E11: 96%
A12: State Water Project allocation | B12: 5% | C12: 100% | D12: 40% | E12: 50%

Sheet How this was built
A1: Hat Creek Highlands Mutual Water Co
A2: How this was built - forensic lineage
A3: Entity ID: cawc_0106 | Fiscal year ends August 31.
A5: A plain account of the forensic lineage behind the hard-to-source metrics: what sources were checked, what was found, what was derived, and what could not be built and why. Every figure marked DERIVED or IMPOSSIBLE above is traceable to a line here.
A7: Water-sales revenue per customer - not reported
A8: Sources checked | B8: State Water Board eAR Section 8b (water-rate revenue B1.1/B1.2); State Water Board eAR Section 4 (connection count, same reporting year); audited financial statement (secondary cross-check, where published)
A9: What was found | B9: The eAR Section 8b reports water-rate revenue for reporting year None, so this is a DIRECT filed figure; per customer it is divided by the eAR Section 4 connection count for the same reporting year, so numerator and denominator share the year.
A11: Assessment revenue (residual) - IMPOSSIBLE
A12: Sources checked | B12: Form 990 Part VIII line 2 (program-service revenue); State Water Board eAR Section 8b (water-rate revenue B1.1/B1.2); eAR Section 8b filer comment (WRRevenueComments)
A13: What was found | B13: A period-aligned residual cannot be computed for this filer, so the metric is rendered IMPOSSIBLE rather than guessed.
A14: Caveat | B14: Not derivable. The eAR Section 8b is reporting year None while the Form 990 fiscal year ends None; the two period ends are not aligned, so a period-aligned residual cannot be computed.
A16: Meter revenue - not reported
A17: Sources checked | B17: State Water Board eAR Section 8a (rate prices); State Water Board eAR Section 8b (revenue lines); audited financial statement
A18: What was found | B18: The rate price exists in Section 8a but no revenue or tier volume is reported, and the base charge is already inside water sales.
A19: Caveat | B19: The eAR Section 8a reports a base/meter rate PRICE, but the filing carries no meter revenue line and no tier volume, and the base charge is already inside the water-sales revenue (eAR Section 8b water rates). Building a separate meter figure would double-count. Not backed into from a total.
A21: Overage / tiered-penalty revenue - not reported
A22: Sources checked | B22: State Water Board eAR Section 8a (rate prices); State Water Board eAR Section 8b (revenue lines); audited financial statement
A23: What was found | B23: The rate price exists in Section 8a but no revenue or tier volume is reported, and the base charge is already inside water sales.
A24: Caveat | B24: The eAR Section 8a reports tiered/overage rate PRICES, but the filing carries no overage revenue and no tier consumption volume, and any overage billed is already inside the water-sales revenue. Building it would double-count. Not backed into from a total.
A26: eAR Section 8b reporting-period basis - sourced
A27: Sources checked | B27: eAR Section 8b B0.1 (WRFinancialReportingPeriod); eAR Section 8b B0.2 (WRFiscalYearStartDate)
A28: What was found | B28: The reporting basis (fiscal vs calendar year) is read from the filer's own B0.1/B0.2 answer and staged verbatim, never hardcoded, so the 990 comparison and the residual are period-aligned.
A30: Member (shareholder) count denominator - not reported
A31: Sources checked | B31: Form 990 (no member count stated); company website
A32: What was found | B32: No filing states a member/shareholder count, so the per-member unit economics read not reported rather than borrowing the connection count.
A34: Water volume delivered (acre-feet) - not reported
A35: Sources checked | B35: Form 990 (not in the filing); Consumer Confidence Report; eAR Section 6 (PRA-gated)
A36: What was found | B36: Volume delivered in acre-feet is not in the Form 990 and the CCR states only a source mix, so the per-acre-foot metrics read not reported; the eAR Section 6 is named as the source still needed.

Sheet Sources & audit
A1: Hat Creek Highlands Mutual Water Co
A2: Sources & audit - full provenance and tie-outs (kept off the statements so they read clean)
A3: Entity ID: cawc_0106 | Fiscal year ends August 31.
A5: Presentation standard: every figure on the statement tabs is verified to its source filing and shown clean. A cell the filing does not report reads "not reported" (never estimated, never guessed).
A6: Citations, confidence tiers, and the filed-vs-computed tie-out checks live on the "Sources & audit" tab, keyed by cell, so every number is fully traceable without cluttering the statements. These pages are ready to use as filed.
A8: A. Filing provenance (one row per staged extraction)
A9: Fiscal year | B9: Period end | C9: Filing type | D9: Confidence | E9: Extraction ID | F9: Object ID | G9: Extracted by | H9: Extracted at | I9: Source URL
A10: FY2022 | B10: 2022-08-31 | C10: 990 | D10: high | E10: e5eb61bc-c701-43a6-8b4b-df583d963e78 | F10: 202341539349300649 | G10: claude-opus-5 | H10: 2026-09-23T06:31:51+00:00 | I10: https://apps.irs.gov/pub/epostcard/990/xml/2023/2023_TEOS_XML_06A.zip#202341539349300649_public.xml
A11: FY2023 | B11: 2023-08-31 | C11: 990 | D11: high | E11: b4700da2-c1fc-4810-a02c-11d96c0beaf1 | F11: 202433179349304853 | G11: claude-opus-5 | H11: 2026-09-23T06:31:51+00:00 | I11: https://apps.irs.gov/pub/epostcard/990/xml/2024/2024_TEOS_XML_11A.zip#202433179349304853_public.xml
A12: FY2024 | B12: 2024-08-31 | C12: 990 | D12: high | E12: 8bf1675a-6a55-4c29-b378-28dae9cda388 | F12: 202521959349301652 | G12: claude-opus-5 | H12: 2026-09-23T06:31:51+00:00 | I12: https://apps.irs.gov/pub/epostcard/990/xml/2025/2025_TEOS_XML_07A.zip#202521959349301652_public.xml
A13: FY2025 | B13: 2025-08-31 | C13: 990 | D13: high | E13: 6c53b6a6-fe0c-4e03-b998-636f5761222e | F13: 202620479349301797 | G13: claude-opus-5 | H13: 2026-09-23T06:31:51+00:00 | I13: https://apps.irs.gov/pub/epostcard/990/xml/2026/2026_TEOS_XML_02A.zip#202620479349301797_public.xml
A15: B. Figure citations (every figure on the statement tabs, keyed by cell)
A16: Tab | B16: Cell | C16: Line item | D16: Form 990 line | E16: Key path | F16: Confidence | G16: As filed
A17: Financial Statements | B17: B73 | C17: 11a. Gross income from members or shareholders | D17: 11a | E17: part_v_other_irs_filings.members_and_shareholders_gross_income | F17: high | G17: 77965
A18: Financial Statements | B18: C73 | C18: 11a. Gross income from members or shareholders | D18: 11a | E18: part_v_other_irs_filings.members_and_shareholders_gross_income | F18: high | G18: 80031
A19: Financial Statements | B19: D73 | C19: 11a. Gross income from members or shareholders | D19: 11a | E19: part_v_other_irs_filings.members_and_shareholders_gross_income | F19: high | G19: 77200
A20: Financial Statements | B20: E73 | C20: 11a. Gross income from members or shareholders | D20: 11a | E20: part_v_other_irs_filings.members_and_shareholders_gross_income | F20: high | G20: 92379
A21: Financial Statements | B21: B74 | C21: 11b. Gross income from other sources | D21: 11b | E21: part_v_other_irs_filings.other_sources_gross_income | F21: high | G21: 0
A22: Financial Statements | B22: C74 | C22: 11b. Gross income from other sources | D22: 11b | E22: part_v_other_irs_filings.other_sources_gross_income | F22: high | G22: 0
A23: Financial Statements | B23: D74 | C23: 11b. Gross income from other sources | D23: 11b | E23: part_v_other_irs_filings.other_sources_gross_income | F23: high | G23: 89614
A24: Financial Statements | B24: E74 | C24: 11b. Gross income from other sources | D24: 11b | E24: part_v_other_irs_filings.other_sources_gross_income | F24: high | G24: 0
A25: Revenue (detail) | B25: B7 | C25: 1h. Total contributions, gifts, grants | D25: 1h | E25: part_viii_revenue.total_contributions | F25: high | G25: 77965
A26: Revenue (detail) | B26: C8 | C26: 2g. Total program service revenue | D26: 2g | E26: part_viii_revenue.total_program_service_revenue | F26: high | G26: 80031
A27: Revenue (detail) | B27: E8 | C27: 2g. Total program service revenue | D27: 2g | E27: part_viii_revenue.total_program_service_revenue | F27: high | G27: 90319
A28: Operating expenses (detail) | B28: C7 | C28: 7. Other salaries and wages | D28: 7 | E28: part_ix_expenses.other_salaries_and_wages | F28: high | G28: 10370
... A77: Net-assets reconciliation | B77: E10 | C77: 9. Other changes in net assets | D77: Part XI line 9 | E77: part_xi_reconciliation.other_changes_net_assets | F77: high | G77: 0
A79: C. Tie-out checks (filed vs computed; any nonzero variance is flagged red)
A80: Tab | B80: Check | C80: Fiscal year | D80: Filed | E80: Computed | F80: Variance (computed - filed)
A81: Revenue (detail) | B81: 12. Total revenue | C81: FY2022 | D81: 77965 | E81: ='Revenue (detail)'!B13 | F81: =E81-D81
A82: Revenue (detail) | B82: 12. Total revenue | C82: FY2023 | D82: 80031 | E82: ='Revenue (detail)'!C13 | F82: =E82-D82
A83: Revenue (detail) | B83: 12. Total revenue | C83: FY2024 | D83: 0 | E83: ='Revenue (detail)'!D13 | F83: =E83-D83
A84: Revenue (detail) | B84: 12. Total revenue | C84: FY2025 | D84: 90319 | E84: ='Revenue (detail)'!E13 | F84: =E84-D84
A85: Revenue (detail) | B85: 2g program service revenue = sum of lines 2a-2f (FY2025) | C85: FY2025 | D85: 90319 | E85: =SUM('Revenue (detail)'!C17:C17) | F85: =E85-D85
A86: Operating expenses (detail) | B86: 25. Total functional expenses | C86: FY2022 | D86: 62140 | E86: ='Operating expenses (detail)'!B22 | F86: =E86-D86
A87: Operating expenses (detail) | B87: 25. Total functional expenses | C87: FY2023 | D87: 87583 | E87: ='Operating expenses (detail)'!C22 | F87: =E87-D87
A88: Operating expenses (detail) | B88: 25. Total functional expenses | C88: FY2024 | D88: 15063 | E88: ='Operating expenses (detail)'!D22 | F88: =E88-D88
A89: Operating expenses (detail) | B89: 25. Total functional expenses | C89: FY2025 | D89: 91248 | E89: ='Operating expenses (detail)'!E22 | F89: =E89-D89
A90: Operating expenses (detail) | B90: Part IX column split: col A = B + C + D (FY2025) | C90: FY2025 | D90: ='Operating expenses (detail)'!B30 | E90: ='Operating expenses (detail)'!C30+'Operating expenses (detail)'!D30+'Operating expenses (detail)'!E30 | F90: =E90-D90
A91: Balance sheet (detail) | B91: 16. Total assets | C91: FY2022 | D91: 392066 | E91: ='Balance sheet (detail)'!B11 | F91: =E91-D91
A92: Balance sheet (detail) | B92: 16. Total assets | C92: FY2023 | D92: 371086 | E92: ='Balance sheet (detail)'!C11 | F92: =E92-D92
...

Sheet Provenance
A1: Build provenance | B1: Built from source commit d418ffb17485 (2026-10-06); source fingerprint a75a8eee82c65cf7; 192 companies (179 retail mutual, 4 irrigation mutual, 3 mutual, no PWSID, purpose not stated, 2 frozen non-mutual (special district), 2 wholesale mutual, 1 frozen non-mutual (investor-owned), 1 frozen non-mutual (municipal)); 91 gates; build id 3d08d6d2a855.
A2: source_commit | B2: d418ffb174855ab78000d391d42f898397b0d8aa
A3: source_commit_date | B3: 2026-10-06
A4: source_fingerprint | B4: a75a8eee82c65cf7096931f06e18affdc28686a02895b46538e7298b57c04d94
A5: gate_count | B5: 91
A6: build_id | B6: 3d08d6d2a855
A7: registry: frozen non-mutual (investor-owned) | B7: 1
A8: registry: frozen non-mutual (municipal) | B8: 1
A9: registry: frozen non-mutual (special district) | B9: 2
A10: registry: irrigation mutual | B10: 4
A11: registry: mutual, no PWSID, purpose not stated | B11: 3
A12: registry: retail mutual | B12: 179
A13: registry: wholesale mutual | B13: 2
