Workbook

Sheet Summary
A1: Lazy H Mutual Water Company
A2: Financial Summary - multi-year overview (USD)
A3: Entity ID: cawc_0188 | Fiscal year ends June 30.
A5: Presentation standard: every figure on the statement tabs is verified to its source filing and shown clean. A cell the filing does not report reads "not reported" (never estimated, never guessed).
A6: Citations, confidence tiers, and the filed-vs-computed tie-out checks live on the "Sources & audit" tab, keyed by cell, so every number is fully traceable without cluttering the statements. These pages are ready to use as filed.
A8: Metric | B8: FY2022 | C8: FY2023 | D8: FY2024 | E8: FY2025
A9: Operating results (USD)
A10: Total revenue | B10: 78719 | C10: 74420 | D10: 76035 | E10: 97432
A11: Total expenses | B11: 85951 | C11: 111253 | D11: 87379 | E11: 95295
A12: Net income | B12: -7232 | C12: -36833 | D12: -11344 | E12: 2137
A14: Financial position (USD, end of year)
A15: Total assets | B15: 280861 | C15: 245257 | D15: 234013 | E15: 236149
A16: Total liabilities | D16: 100 | E16: 100
A17: Net assets | B17: 280861 | C17: 245257 | D17: 233913 | E17: 236049
A19: Headline ratios
A20: Operating margin | B20: -0.091871086 | C20: -0.49493416 | D20: -0.14919445 | E20: 0.021933246
A21: Revenue growth (YoY)
A22: Return on assets | B22: -0.025749392 | C22: -0.15018124 | D22: -0.048475939 | E22: 0.0090493714
A24: Figures as reported in source filings (full provenance on the Sources & audit tab). Parentheses denote negatives; ratios are computed upstream in financials_annual.

Sheet Notes
A1: Notes
A2: Human annotations from the versioned store (data/notes/). Annotations only: they never change a reported figure or a confidence tier.
A4: Date | B4: Tag | C4: Author | D4: Note
A5: No notes recorded yet.

Sheet Financial Statements
A1: Lazy H Mutual Water Company
A2: Financial Statements - income statement, balance sheet, cash flow, member income test (USD)
A3: Entity ID: cawc_0188 | Fiscal year ends June 30.
A5: INCOME STATEMENT - as reported (USD)
A6: Line item | B6: FY2022 | C6: FY2023 | D6: FY2024 | E6: FY2025
A7: Revenue
A8: Program service revenue
A9: Investment income
A10: Net rental income
A11: Net gain/(loss) on investment sales
A12: Other revenue
A13: Contributions & grants
A14: Total revenue
A16: Expenses
A17: Depreciation
A18: Interest expense
A19: Total expenses | B19: 85951 | C19: 111253 | D19: 87379 | E19: 95295
A21: Net income | B21: -7232 | C21: -36833 | D21: -11344 | E21: 2137
A24: BALANCE SHEET - as reported (USD, end of year)
A25: Line item | B25: FY2022 | C25: FY2023 | D25: FY2024 | E25: FY2025
A26: Assets
A27: Cash | B27: 69753 | C27: 42469 | D27: 47241 | E27: 49439
A28: Savings & temporary investments
A29: Accounts receivable
A30: Inventories
A31: Prepaid expenses
A32: Property, plant & equipment (gross)
A33: Less: accumulated depreciation
A34: Net property, plant & equipment | B34: 7152 | C34: 7152 | D34: 7152 | E34: 7152
A35: Total assets | B35: 280861 | C35: 245257 | D35: 234013 | E35: 236149
A37: Liabilities
A38: Accounts payable
A39: Mortgages & notes payable
A40: Total liabilities | D40: 100 | E40: 100
A42: Net Assets / Equity
A43: Capital stock
A44: Paid-in capital
A45: Retained earnings
A46: Net assets | B46: 280861 | C46: 245257 | D46: 233913 | E46: 236049
A49: CASH FLOW - derived proxy (USD)
...

Sheet Balance Sheet
A1: Lazy H Mutual Water Company
A2: Balance Sheet - as reported (USD, end of year)
A3: Entity ID: cawc_0188 | Fiscal year ends June 30.
A5: Line item | B5: FY2022 | C5: FY2023 | D5: FY2024 | E5: FY2025
A6: Assets
A7: Cash | B7: 69753 | C7: 42469 | D7: 47241 | E7: 49439
A8: Savings & temporary investments
A9: Accounts receivable
A10: Inventories
A11: Prepaid expenses
A12: Property, plant & equipment (gross)
A13: Less: accumulated depreciation
A14: Net property, plant & equipment | B14: 7152 | C14: 7152 | D14: 7152 | E14: 7152
A15: Total assets | B15: 280861 | C15: 245257 | D15: 234013 | E15: 236149
A17: Liabilities
A18: Accounts payable
A19: Mortgages & notes payable
A20: Total liabilities | D20: 100 | E20: 100
A22: Net Assets / Equity
A23: Capital stock
A24: Paid-in capital
A25: Retained earnings
A26: Net assets | B26: 280861 | C26: 245257 | D26: 233913 | E26: 236049
A28: Balance check (assets − liab. − net assets) | B28: 0 | C28: 0 | D28: 0 | E28: 0
A30: Net PP&E is the reported ppe_net column (gross less accumulated depreciation). The balance check should be ~0 where all three totals are reported; a non-zero value flags a reporting or extraction discrepancy worth reviewing.

Sheet Form 990-EZ Parts I & II
A1: Lazy H Mutual Water Company
A2: Form 990-EZ - Part I (revenue, expenses, net assets) and Part II (balance sheet), as filed (USD)
A3: Entity ID: cawc_0188 | Fiscal year ends June 30.
A5: Form 990-EZ line | B5: FY2022 | C5: FY2023 | D5: FY2024 | E5: FY2025
A6: Revenue (Part I)
A7: 1. Contributions, gifts, grants | B7: 0 | C7: 0 | D7: 0 | E7: 0
A8: 2. Program service revenue | B8: 77772 | C8: 72262 | D8: 75053 | E8: 95778
A9: 3. Membership dues and assessments | B9: 0 | C9: 0 | D9: 0 | E9: 0
A10: 4. Investment income | B10: 0 | C10: 0 | D10: 8 | E10: 714
A11: 8. Other revenue | B11: 947 | C11: 2158 | D11: 974 | E11: 940
A12: 9. Total revenue | B12: 78719 | C12: 74420 | D12: 76035 | E12: 97432
A14: Expenses (Part I)
A15: 13. Fees for services (independent contractors) | B15: 34678 | C15: 35801 | D15: 35853 | E15: 37793
A16: 14. Occupancy, rent, utilities, maintenance | B16: 17501 | C16: 40649 | D16: 16041 | E16: 15082
A17: 16. Other expenses | B17: 33772 | C17: 34803 | D17: 35485 | E17: 42420
A18: 17. Total expenses | B18: =SUM(B15:B17) | C18: =SUM(C15:C17) | D18: =SUM(D15:D17) | E18: =SUM(E15:E17)
A20: Net-assets reconciliation (Part I)
A21: 19. Net assets or fund balances, beginning of year | B21: 289320 | C21: 280861 | D21: 245257 | E21: 233913
A22: 18. Excess or (deficit) for the year | B22: -7232 | C22: -36833 | D22: -11344 | E22: 2137
A23: 21. Net assets or fund balances, end of year | B23: =SUM(B21,B22) | C23: =SUM(C21,C22) | D23: =SUM(D21,D22) | E23: =SUM(E21,E22)
A25: Balance sheet (Part II, end of year - column B)
A26: 22. Cash, savings, and investments | B26: 69753 | C26: 42469 | D26: 47241 | E26: 49439
A27: 23. Land and buildings | B27: 7152 | C27: 7152 | D27: 7152 | E27: 7152
A28: 24. Other assets | B28: 203956 | C28: 195636 | D28: 179620 | E28: 179558
A29: 25. Total assets | B29: =SUM(B26:B28) | C29: =SUM(C26:C28) | D29: =SUM(D26:D28) | E29: =SUM(E26:E28)
A30: 26. Total liabilities | B30: not reported | C30: not reported | D30: 100 | E30: 100
A31: 27. Net assets or fund balances | B31: 280861 | C31: 245257 | D31: 233913 | E31: 236049
A33: Form 990-EZ is the short form: revenue and expenses are on Part I and the balance sheet is the six-line Part II (no full-990 Parts VII-XI). Total expenses (line 17) and Total assets (line 25) are live SUMs of the lines above; Total revenue (line 9) is shown as filed because the EZ nets its lines 5-7 (sales of assets, gaming, inventory) into line 9 without itemizing them. Ending net assets (line 21) is recomputed live as beginning net assets (line 19) plus the excess or deficit (line 18); where the filer's own line 21 does not equal that sum, the variance is flagged red on the Sources & audit tab and carried exactly as filed, not reconciled. Every figure's citation and confidence are on the Sources & audit tab.

Sheet Cash flow proxies
A1: Lazy H Mutual Water Company
A2: Cash Flow Proxies - derived (USD)
A3: Entity ID: cawc_0188 | Fiscal year ends June 30.
A5: PROXY ONLY. The source filings contain no statement of cash flows. Lines below are derived from the reported income statement and year-over-year balance-sheet changes; treat as directional estimates, not GAAP cash flows. The earliest year has no prior period, so its delta cells are blank.
A7: Proxy line (USD) | B7: FY2022 | C7: FY2023 | D7: FY2024 | E7: FY2025
A8: Operating
A9: Net income | B9: -7232 | C9: -36833 | D9: -11344 | E9: 2137
A10: + Depreciation (reported)
A11: − Δ Accounts receivable
A12: − Δ Inventories
A13: − Δ Prepaid expenses
A14: + Δ Accounts payable
A15: Operating cash flow proxy | C15: -36833 | D15: -11344 | E15: 2137
A17: Investing
A18: − Δ PP&E gross (capex proxy)
A20: Financing
A21: Δ Mortgages & notes payable
A23: Reconciliation
A24: Δ Cash + temp. investments (actual) | C24: -27284 | D24: 4772 | E24: 2198
A26: The capex proxy assumes gross PP&E rises only via capital spending (it ignores disposals). 'Δ Cash + temp. investments (actual)' is the real reported change in liquid funds and is the most reliable line here; the operating/investing/financing proxies will not perfectly reconcile to it.

Sheet Ratios
A1: Lazy H Mutual Water Company
A2: Financial Ratios
A3: Entity ID: cawc_0188 | Fiscal year ends June 30.
A5: Ratio | B5: FY2022 | C5: FY2023 | D5: FY2024 | E5: FY2025
A6: Profitability (computed upstream)
A7: Operating margin (NI / revenue) | B7: -0.091871086 | C7: -0.49493416 | D7: -0.14919445 | E7: 0.021933246
A8: Expense ratio (expenses / revenue) | B8: 1.0918711 | C8: 1.4949342 | D8: 1.1491944 | E8: 0.97806675
A9: Return on assets (NI / assets) | B9: -0.025749392 | C9: -0.15018124 | D9: -0.048475939 | E9: 0.0090493714
A10: Revenue growth (YoY)
A12: Leverage & solvency
A13: Debt-to-assets (liab. / assets) | D13: 0.00042732669 | E13: 0.00042346146
A14: Equity ratio (net assets / assets) | B14: 1 | C14: 1 | D14: 0.99957267 | E14: 0.99957654
A16: Liquidity & asset profile (derived here)
A17: Current ratio (current assets / AP)
A18: Cash ratio ((cash+temp inv.) / total liab.) | D18: 472.41 | E18: 494.39
A19: Asset age proxy (accum. deprec. / gross PP&E)
A21: Upstream ratios are read from financials_annual; derived ratios are computed only where inputs are reported. Current ratio uses accounts payable as the current-liability proxy (the filings do not split current vs. long-term liabilities). Asset age proxy: a higher % implies older / more depreciated infrastructure.

Sheet Unit economics
A1: Lazy H Mutual Water Company
A2: Unit economics - per-customer revenue by category (USD)
A3: Entity ID: cawc_0188 | Fiscal year ends June 30.
A5: Every metric here is PER CUSTOMER (a metered service connection). It is not a per-member figure; the member (shareholder) count is a different denominator, shown in the denominator block. The visible cell shows the value and its classification; the numerator, denominator, formula, and rationale are in each metric's LOGIC popup.
A6: Per-customer denominator (service connections) | C6: State Water Board eAR Section 4
A7: Total annual revenue (eAR Section 8b B1.8) | C7: eAR Section 8b total annual revenue not reported for this system.
A8: Primary source
A10: Revenue categories (value, classification, per customer, share)
A11: Revenue category | B11: Classification | C11: Value (USD) | D11: Per customer | E11: Share of revenue
A12: Water sales revenue | B12: not reported | C12: not reported | D12: not reported | E12: not reported
A13: Assessment revenue (990 program-service revenue not matched to eAR water-rate revenue) | B13: IMPOSSIBLE | C13: IMPOSSIBLE | D13: IMPOSSIBLE | E13: IMPOSSIBLE
A14: Meter revenue | B14: not reported | C14: not reported | D14: not reported | E14: not reported
A15: Overage or tiered penalty revenue | B15: not reported | C15: not reported | D15: not reported | E15: not reported
A17: Water sales revenue - not reported
A18: Not reported: this system filed an eAR but no Section 8b revenue block, so there is no filed water-sales figure. Not fallen back to a different year.
A19: Reason: No filed eAR Section 8b water-rate revenue for this system.
A21: Assessment revenue (990 program-service revenue not matched to eAR water-rate revenue) - IMPOSSIBLE
A22: Not computed. A period-aligned residual is not possible for this filer.
A23: Reason: Not derivable. The eAR Section 8b is reporting year None while the Form 990 fiscal year ends None; the two period ends are not aligned, so a period-aligned residual cannot be computed.
A25: Meter revenue - not reported
A26: Not reported. This category is not built because doing so would double-count.
A27: Reason: The eAR Section 8a reports a base/meter rate PRICE, but the filing carries no meter revenue line and no tier volume, and the base charge is already inside the water-sales revenue (eAR Section 8b water rates). Building a separate meter figure would double-count. Not backed into from a total.
A29: Overage or tiered penalty revenue - not reported
A30: Not reported. This category is not built because doing so would double-count.
A31: Reason: The eAR Section 8a reports tiered/overage rate PRICES, but the filing carries no overage revenue and no tier consumption volume, and any overage billed is already inside the water-sales revenue. Building it would double-count. Not backed into from a total.

Sheet Rate structure
A1: Lazy H Mutual Water Company
A2: Rate structure and representative bill - eAR Section 8a
A3: Entity ID: cawc_0188 | Fiscal year ends June 30.
A5: This block is a rate-schedule illustration at defined usage levels. It is NOT billed revenue and not a claim about any real customer's usage. The revenue side of unit economics is the separate Unit Economics block.
A6: No filed eAR Section 8a rate schedule is staged for this system.

Sheet Operational metrics
A1: Lazy H Mutual Water Company
A2: Operational metrics - plant per acre, density, terrain
A3: Entity ID: cawc_0188 | Fiscal year ends June 30.
A5: Connections per acre
A6: Connections per acre | B6: 1.11 | C6: 42 connections / 38.0 acres. CA State Water Board SABL SERVICE_CONNECTIONS; Geodesic area (WGS84 spherical excess) of the SABL service-area polygon.

Sheet Supply & weather
A1: Lazy H Mutual Water Company
A2: Supply and weather indicators (DWR water year)
A3: Entity ID: cawc_0188 | Fiscal year ends June 30.
A5: Reporting calendar: Different reporting periods. The DWR water year runs October 1 to September 30; this system's fiscal year ends June 30, so the two period ends are three months apart. Read the two side by side with that in mind. Neither series is recast: both are reported as filed. A water year is named for the calendar year it ends in, so WY2024 and FY2024 share a number without covering the same twelve months.
A7: Indicator | B7: WY2022 | C7: WY2023 | D7: WY2024 | E7: WY2025
A8: Water-year type (Sacramento Valley) | B8: Critical | C8: Wet | D8: Above Normal | E8: not reported
A9: Peak drought, county County | B9: not reported | C9: not reported | D9: not reported | E9: not reported
A10: Precip, percent of normal (8-Station Index) | B10: 86 | C10: 133 | D10: 96 | E10: 113
A11: Snowpack, April 1 percent of average | B11: 38% | C11: 237% | D11: 110% | E11: 96%
A12: State Water Project allocation | B12: 5% | C12: 100% | D12: 40% | E12: 50%

Sheet How this was built
A1: Lazy H Mutual Water Company
A2: How this was built - forensic lineage
A3: Entity ID: cawc_0188 | Fiscal year ends June 30.
A5: A plain account of the forensic lineage behind the hard-to-source metrics: what sources were checked, what was found, what was derived, and what could not be built and why. Every figure marked DERIVED or IMPOSSIBLE above is traceable to a line here.
A7: Water-sales revenue per customer - not reported
A8: Sources checked | B8: State Water Board eAR Section 8b (water-rate revenue B1.1/B1.2); State Water Board eAR Section 4 (connection count, same reporting year); audited financial statement (secondary cross-check, where published)
A9: What was found | B9: The eAR Section 8b reports water-rate revenue for reporting year None, so this is a DIRECT filed figure; per customer it is divided by the eAR Section 4 connection count for the same reporting year, so numerator and denominator share the year.
A11: Assessment revenue (residual) - IMPOSSIBLE
A12: Sources checked | B12: Form 990 Part VIII line 2 (program-service revenue); State Water Board eAR Section 8b (water-rate revenue B1.1/B1.2); eAR Section 8b filer comment (WRRevenueComments)
A13: What was found | B13: A period-aligned residual cannot be computed for this filer, so the metric is rendered IMPOSSIBLE rather than guessed.
A14: Caveat | B14: Not derivable. The eAR Section 8b is reporting year None while the Form 990 fiscal year ends None; the two period ends are not aligned, so a period-aligned residual cannot be computed.
A16: Meter revenue - not reported
A17: Sources checked | B17: State Water Board eAR Section 8a (rate prices); State Water Board eAR Section 8b (revenue lines); audited financial statement
A18: What was found | B18: The rate price exists in Section 8a but no revenue or tier volume is reported, and the base charge is already inside water sales.
A19: Caveat | B19: The eAR Section 8a reports a base/meter rate PRICE, but the filing carries no meter revenue line and no tier volume, and the base charge is already inside the water-sales revenue (eAR Section 8b water rates). Building a separate meter figure would double-count. Not backed into from a total.
A21: Overage / tiered-penalty revenue - not reported
A22: Sources checked | B22: State Water Board eAR Section 8a (rate prices); State Water Board eAR Section 8b (revenue lines); audited financial statement
A23: What was found | B23: The rate price exists in Section 8a but no revenue or tier volume is reported, and the base charge is already inside water sales.
A24: Caveat | B24: The eAR Section 8a reports tiered/overage rate PRICES, but the filing carries no overage revenue and no tier consumption volume, and any overage billed is already inside the water-sales revenue. Building it would double-count. Not backed into from a total.
A26: eAR Section 8b reporting-period basis - sourced
A27: Sources checked | B27: eAR Section 8b B0.1 (WRFinancialReportingPeriod); eAR Section 8b B0.2 (WRFiscalYearStartDate)
A28: What was found | B28: The reporting basis (fiscal vs calendar year) is read from the filer's own B0.1/B0.2 answer and staged verbatim, never hardcoded, so the 990 comparison and the residual are period-aligned.
A30: Member (shareholder) count denominator - not reported
A31: Sources checked | B31: Form 990 (no member count stated); company website
A32: What was found | B32: No filing states a member/shareholder count, so the per-member unit economics read not reported rather than borrowing the connection count.
A34: Water volume delivered (acre-feet) - not reported
A35: Sources checked | B35: Form 990 (not in the filing); Consumer Confidence Report; eAR Section 6 (PRA-gated)
A36: What was found | B36: Volume delivered in acre-feet is not in the Form 990 and the CCR states only a source mix, so the per-acre-foot metrics read not reported; the eAR Section 6 is named as the source still needed.

Sheet Sources & audit
A1: Lazy H Mutual Water Company
A2: Sources & audit - full provenance and tie-outs (kept off the statements so they read clean)
A3: Entity ID: cawc_0188 | Fiscal year ends June 30.
A5: Presentation standard: every figure on the statement tabs is verified to its source filing and shown clean. A cell the filing does not report reads "not reported" (never estimated, never guessed).
A6: Citations, confidence tiers, and the filed-vs-computed tie-out checks live on the "Sources & audit" tab, keyed by cell, so every number is fully traceable without cluttering the statements. These pages are ready to use as filed.
A8: A. Filing provenance (one row per staged extraction)
A9: Fiscal year | B9: Period end | C9: Filing type | D9: Confidence | E9: Extraction ID | F9: Object ID | G9: Extracted by | H9: Extracted at | I9: Source URL
A10: FY2022 | B10: 2022-06-30 | C10: 990-EZ | D10: high | E10: 3df951ed-5452-4f2a-b1ac-d452be243bb9 | F10: 202242309349200424 | G10: claude-opus-5 | H10: 2026-10-06T04:30:16+00:00 | I10: https://apps.irs.gov/pub/epostcard/990/xml/2022/2022_TEOS_XML_01A.zip#202242309349200424_public.xml
A11: FY2023 | B11: 2023-06-30 | C11: 990-EZ | D11: high | E11: 9eb64f00-f93a-4f42-b3ab-cb2305c464dd | F11: 202312349349200731 | G11: claude-opus-5 | H11: 2026-10-06T04:30:17+00:00 | I11: https://apps.irs.gov/pub/epostcard/990/xml/2023/2023_TEOS_XML_08A.zip#202312349349200731_public.xml
A12: FY2024 | B12: 2024-06-30 | C12: 990-EZ | D12: high | E12: 09fafcb3-d14e-48d8-bf53-b420917c847c | F12: 202412419349200136 | G12: claude-opus-5 | H12: 2026-10-06T04:30:18+00:00 | I12: https://apps.irs.gov/pub/epostcard/990/xml/2024/2024_TEOS_XML_09A.zip#202412419349200136_public.xml
A13: FY2025 | B13: 2025-06-30 | C13: 990-EZ | D13: high | E13: ef99bf3d-9329-4601-b698-d7fd6ec145d2 | F13: 202502689349200635 | G13: claude-opus-5 | H13: 2026-10-06T04:30:18+00:00 | I13: https://apps.irs.gov/pub/epostcard/990/xml/2025/2025_TEOS_XML_09A.zip#202502689349200635_public.xml
A15: B. Figure citations (every figure on the statement tabs, keyed by cell)
A16: Tab | B16: Cell | C16: Line item | D16: Form 990 line | E16: Key path | F16: Confidence | G16: As filed
A17: Form 990-EZ Parts I & II | B17: B7 | C17: 1. Contributions, gifts, grants | D17: Part I line 1 | E17: part_i_revenue_expenses.contributions_grants | F17: high | G17: 0
A18: Form 990-EZ Parts I & II | B18: C7 | C18: 1. Contributions, gifts, grants | D18: Part I line 1 | E18: part_i_revenue_expenses.contributions_grants | F18: high | G18: 0
A19: Form 990-EZ Parts I & II | B19: D7 | C19: 1. Contributions, gifts, grants | D19: Part I line 1 | E19: part_i_revenue_expenses.contributions_grants | F19: high | G19: 0
A20: Form 990-EZ Parts I & II | B20: E7 | C20: 1. Contributions, gifts, grants | D20: Part I line 1 | E20: part_i_revenue_expenses.contributions_grants | F20: high | G20: 0
A21: Form 990-EZ Parts I & II | B21: B8 | C21: 2. Program service revenue | D21: Part I line 2 | E21: part_i_revenue_expenses.program_service_revenue | F21: high | G21: 77772
A22: Form 990-EZ Parts I & II | B22: C8 | C22: 2. Program service revenue | D22: Part I line 2 | E22: part_i_revenue_expenses.program_service_revenue | F22: high | G22: 72262
A23: Form 990-EZ Parts I & II | B23: D8 | C23: 2. Program service revenue | D23: Part I line 2 | E23: part_i_revenue_expenses.program_service_revenue | F23: high | G23: 75053
A24: Form 990-EZ Parts I & II | B24: E8 | C24: 2. Program service revenue | D24: Part I line 2 | E24: part_i_revenue_expenses.program_service_revenue | F24: high | G24: 95778
A25: Form 990-EZ Parts I & II | B25: B9 | C25: 3. Membership dues and assessments | D25: Part I line 3 | E25: part_i_revenue_expenses.membership_dues | F25: high | G25: 0
A26: Form 990-EZ Parts I & II | B26: C9 | C26: 3. Membership dues and assessments | D26: Part I line 3 | E26: part_i_revenue_expenses.membership_dues | F26: high | G26: 0
A27: Form 990-EZ Parts I & II | B27: D9 | C27: 3. Membership dues and assessments | D27: Part I line 3 | E27: part_i_revenue_expenses.membership_dues | F27: high | G27: 0
A28: Form 990-EZ Parts I & II | B28: E9 | C28: 3. Membership dues and assessments | D28: Part I line 3 | E28: part_i_revenue_expenses.membership_dues | F28: high | G28: 0
... A78: Form 990-EZ Parts I & II | B78: E31 | C78: 27. Net assets or fund balances | D78: Part II line 27 col B | E78: part_ii_balance_sheet.net_assets_eoy | F78: high | G78: 236049
A80: C. Tie-out checks (filed vs computed; any nonzero variance is flagged red)
A81: Tab | B81: Check | C81: Fiscal year | D81: Filed | E81: Computed | F81: Variance (computed - filed)
A82: Form 990-EZ Parts I & II | B82: 17. Total expenses | C82: FY2022 | D82: 85951 | E82: ='Form 990-EZ Parts I & II'!B18 | F82: =E82-D82
A83: Form 990-EZ Parts I & II | B83: 17. Total expenses | C83: FY2023 | D83: 111253 | E83: ='Form 990-EZ Parts I & II'!C18 | F83: =E83-D83
A84: Form 990-EZ Parts I & II | B84: 17. Total expenses | C84: FY2024 | D84: 87379 | E84: ='Form 990-EZ Parts I & II'!D18 | F84: =E84-D84
A85: Form 990-EZ Parts I & II | B85: 17. Total expenses | C85: FY2025 | D85: 95295 | E85: ='Form 990-EZ Parts I & II'!E18 | F85: =E85-D85
A86: Form 990-EZ Parts I & II | B86: 21. Net assets or fund balances, end of year | C86: FY2022 | D86: 280861 | E86: ='Form 990-EZ Parts I & II'!B23 | F86: =E86-D86
A87: Form 990-EZ Parts I & II | B87: 21. Net assets or fund balances, end of year | C87: FY2023 | D87: 245257 | E87: ='Form 990-EZ Parts I & II'!C23 | F87: =E87-D87
A88: Form 990-EZ Parts I & II | B88: 21. Net assets or fund balances, end of year | C88: FY2024 | D88: 233913 | E88: ='Form 990-EZ Parts I & II'!D23 | F88: =E88-D88
A89: Form 990-EZ Parts I & II | B89: 21. Net assets or fund balances, end of year | C89: FY2025 | D89: 236049 | E89: ='Form 990-EZ Parts I & II'!E23 | F89: =E89-D89
A90: Form 990-EZ Parts I & II | B90: 25. Total assets | C90: FY2022 | D90: 280861 | E90: ='Form 990-EZ Parts I & II'!B29 | F90: =E90-D90
A91: Form 990-EZ Parts I & II | B91: 25. Total assets | C91: FY2023 | D91: 245257 | E91: ='Form 990-EZ Parts I & II'!C29 | F91: =E91-D91
A92: Form 990-EZ Parts I & II | B92: 25. Total assets | C92: FY2024 | D92: 234013 | E92: ='Form 990-EZ Parts I & II'!D29 | F92: =E92-D92
A93: Form 990-EZ Parts I & II | B93: 25. Total assets | C93: FY2025 | D93: 236149 | E93: ='Form 990-EZ Parts I & II'!E29 | F93: =E93-D93
...

Sheet Provenance
A1: Build provenance | B1: Built from source commit d418ffb17485 (2026-10-06); source fingerprint a75a8eee82c65cf7; 192 companies (179 retail mutual, 4 irrigation mutual, 3 mutual, no PWSID, purpose not stated, 2 frozen non-mutual (special district), 2 wholesale mutual, 1 frozen non-mutual (investor-owned), 1 frozen non-mutual (municipal)); 91 gates; build id 3d08d6d2a855.
A2: source_commit | B2: d418ffb174855ab78000d391d42f898397b0d8aa
A3: source_commit_date | B3: 2026-10-06
A4: source_fingerprint | B4: a75a8eee82c65cf7096931f06e18affdc28686a02895b46538e7298b57c04d94
A5: gate_count | B5: 91
A6: build_id | B6: 3d08d6d2a855
A7: registry: frozen non-mutual (investor-owned) | B7: 1
A8: registry: frozen non-mutual (municipal) | B8: 1
A9: registry: frozen non-mutual (special district) | B9: 2
A10: registry: irrigation mutual | B10: 4
A11: registry: mutual, no PWSID, purpose not stated | B11: 3
A12: registry: retail mutual | B12: 179
A13: registry: wholesale mutual | B13: 2
