Workbook

Sheet Summary
A1: Vaughn Water Company Inc
A2: Financial Summary - multi-year overview (USD)
A3: Entity ID: cawc_0030 | Fiscal year ends December 31.
A5: Presentation standard: every figure on the statement tabs is verified to its source filing and shown clean. A cell the filing does not report reads "not reported" (never estimated, never guessed).
A6: Citations, confidence tiers, and the filed-vs-computed tie-out checks live on the "Sources & audit" tab, keyed by cell, so every number is fully traceable without cluttering the statements. These pages are ready to use as filed.
A8: Metric | B8: FY2020 | C8: FY2021 | D8: FY2022 | E8: FY2023 | F8: FY2024
A9: Operating results (USD)
A10: Total revenue | B10: 21208146 | C10: 9299624 | D10: 9179714 | E10: 11703567 | F10: 12086327
A11: Total expenses | B11: 8276666 | C11: 8469920 | D11: 9993756 | E11: 10048407 | F11: 11046499
A12: Net income | B12: 12931480 | C12: 829704 | D12: -814042 | E12: 1655160 | F12: 1039828
A14: Financial position (USD, end of year)
A15: Total assets | B15: 44686700 | C15: 46118386 | D15: 45225883 | E15: 46284722 | F15: 47630829
A16: Total liabilities | B16: 3015331 | C16: 2800936 | D16: 2362370 | E16: 1814666 | F16: 2648730
A17: Net assets | B17: 41671369 | C17: 43317450 | D17: 42863513 | E17: 44470056 | F17: 44982099
A19: Headline ratios
A20: Operating margin | B20: 0.60974118 | C20: 0.089219091 | D20: -0.088678362 | E20: 0.14142355 | F20: 0.086033416
A21: Revenue growth (YoY) | B21: 1.3490603 | C21: -0.56150698 | D21: -0.01289407 | E21: 0.27493809 | F21: 0.032704559
A22: Return on assets | B22: 0.28938096 | C22: 0.017990742 | D22: -0.017999472 | E22: 0.035760396 | F22: 0.021830987
A24: Figures as reported in source filings (full provenance on the Sources & audit tab). Parentheses denote negatives; ratios are computed upstream in financials_annual.

Sheet Notes
A1: Notes
A2: Human annotations from the versioned store (data/notes/). Annotations only: they never change a reported figure or a confidence tier.
A4: Date | B4: Tag | C4: Author | D4: Note
A5: No notes recorded yet.

Sheet Financial Statements
A1: Vaughn Water Company Inc
A2: Financial Statements - income statement, balance sheet, cash flow, member income test (USD)
A3: Entity ID: cawc_0030 | Fiscal year ends December 31.
A5: INCOME STATEMENT - as reported (USD)
A6: Line item | B6: FY2020 | C6: FY2021 | D6: FY2022 | E6: FY2023 | F6: FY2024
A7: Revenue
A8: Program service revenue | B8: 9106619 | C8: 9221448 | D8: 9129183 | E8: 11066242 | F8: 11206435
A9: Investment income | B9: 68235 | C9: 49610 | D9: 48262 | E9: 637325 | F9: 879892
A10: Net rental income
A11: Net gain/(loss) on investment sales
A12: Other revenue | B12: 12033292 | C12: 28566 | D12: 2269
A13: Contributions & grants
A14: Total revenue | B14: 21208146 | C14: 9299624 | D14: 9179714 | E14: 11703567 | F14: 12086327
A16: Expenses
A17: Depreciation | B17: 1055604 | C17: 1023563 | D17: 1133207 | E17: 1137177 | F17: 707913
A18: Interest expense | B18: 72812 | C18: 42282 | D18: 30981 | E18: 27309
A19: Total expenses | B19: 8276666 | C19: 8469920 | D19: 9993756 | E19: 10048407 | F19: 11046499
A21: Net income | B21: 12931480 | C21: 829704 | D21: -814042 | E21: 1655160 | F21: 1039828
A24: BALANCE SHEET - as reported (USD, end of year)
A25: Line item | B25: FY2020 | C25: FY2021 | D25: FY2022 | E25: FY2023 | F25: FY2024
A26: Assets
A27: Cash | B27: 380719 | C27: 1130043 | D27: 1132372 | E27: 961256 | F27: 2159708
A28: Savings & temporary investments | B28: 21147024 | C28: 20661963 | D28: 20779294 | E28: 21471514 | F28: 22054340
A29: Accounts receivable | B29: 387938 | C29: 616502 | D29: 357391 | E29: 507733 | F29: 411362
A30: Inventories | B30: 118825 | C30: 1808 | D30: 1808 | E30: 1808 | F30: 1808
A31: Prepaid expenses | B31: 1808 | C31: 1691 | F31: 25331
A32: Property, plant & equipment (gross) | B32: 42307578 | C32: 44387134 | D32: 44768980 | E32: 45915296 | F32: 46705214
A33: Less: accumulated depreciation | B33: -19657192 | C33: -20680755 | D33: -21813962 | E33: -22999756 | F33: -24235455
A34: Net property, plant & equipment | B34: 22650386 | C34: 23706379 | D34: 22955018 | E34: 22915540 | F34: 22469759
A35: Total assets | B35: 44686700 | C35: 46118386 | D35: 45225883 | E35: 46284722 | F35: 47630829
A37: Liabilities
A38: Accounts payable | B38: 798098 | C38: 651222 | D38: 735153 | E38: 798381 | F38: 1073723
A39: Mortgages & notes payable
A40: Total liabilities | B40: 3015331 | C40: 2800936 | D40: 2362370 | E40: 1814666 | F40: 2648730
A42: Net Assets / Equity
A43: Capital stock | B43: 12860939 | C43: 12912185 | D43: 13031473 | E43: 13043732 | F43: 13043732
A44: Paid-in capital | B44: 15306952 | C44: 16072083 | D44: 16351684 | E44: 16339425 | F44: 16339425
A45: Retained earnings | B45: 13503478 | C45: 14333182 | D45: 13480356 | E45: 15086899 | F45: 15598942
A46: Net assets | B46: 41671369 | C46: 43317450 | D46: 42863513 | E46: 44470056 | F46: 44982099
A49: CASH FLOW - derived proxy (USD)
...

Sheet Balance Sheet
A1: Vaughn Water Company Inc
A2: Balance Sheet - as reported (USD, end of year)
A3: Entity ID: cawc_0030 | Fiscal year ends December 31.
A5: Line item | B5: FY2020 | C5: FY2021 | D5: FY2022 | E5: FY2023 | F5: FY2024
A6: Assets
A7: Cash | B7: 380719 | C7: 1130043 | D7: 1132372 | E7: 961256 | F7: 2159708
A8: Savings & temporary investments | B8: 21147024 | C8: 20661963 | D8: 20779294 | E8: 21471514 | F8: 22054340
A9: Accounts receivable | B9: 387938 | C9: 616502 | D9: 357391 | E9: 507733 | F9: 411362
A10: Inventories | B10: 118825 | C10: 1808 | D10: 1808 | E10: 1808 | F10: 1808
A11: Prepaid expenses | B11: 1808 | C11: 1691 | F11: 25331
A12: Property, plant & equipment (gross) | B12: 42307578 | C12: 44387134 | D12: 44768980 | E12: 45915296 | F12: 46705214
A13: Less: accumulated depreciation | B13: -19657192 | C13: -20680755 | D13: -21813962 | E13: -22999756 | F13: -24235455
A14: Net property, plant & equipment | B14: 22650386 | C14: 23706379 | D14: 22955018 | E14: 22915540 | F14: 22469759
A15: Total assets | B15: 44686700 | C15: 46118386 | D15: 45225883 | E15: 46284722 | F15: 47630829
A17: Liabilities
A18: Accounts payable | B18: 798098 | C18: 651222 | D18: 735153 | E18: 798381 | F18: 1073723
A19: Mortgages & notes payable
A20: Total liabilities | B20: 3015331 | C20: 2800936 | D20: 2362370 | E20: 1814666 | F20: 2648730
A22: Net Assets / Equity
A23: Capital stock | B23: 12860939 | C23: 12912185 | D23: 13031473 | E23: 13043732 | F23: 13043732
A24: Paid-in capital | B24: 15306952 | C24: 16072083 | D24: 16351684 | E24: 16339425 | F24: 16339425
A25: Retained earnings | B25: 13503478 | C25: 14333182 | D25: 13480356 | E25: 15086899 | F25: 15598942
A26: Net assets | B26: 41671369 | C26: 43317450 | D26: 42863513 | E26: 44470056 | F26: 44982099
A28: Balance check (assets − liab. − net assets) | B28: 0 | C28: 0 | D28: 0 | E28: 0 | F28: 0
A30: Net PP&E is the reported ppe_net column (gross less accumulated depreciation). The balance check should be ~0 where all three totals are reported; a non-zero value flags a reporting or extraction discrepancy worth reviewing.

Sheet Officers & contractors
A1: Vaughn Water Company Inc
A2: Officers, Directors & Contractors - Form 990 Part VII (FY2024; USD)
A3: Entity ID: cawc_0030 | Fiscal year ends December 31.
A5: Section A - Officers, directors, trustees, key employees
A6: Name | B6: Title | C6: Reportable comp (org) | D6: Reportable comp (related) | E6: Other comp | F6: Total compensation
A7: BOB BURDETTE | B7: SECRETARY | C7: 0 | D7: 0 | E7: 0 | F7: 0
A8: JOSHUA DIVILBISS | B8: DIRECTOR | C8: 0 | D8: 0 | E8: 0 | F8: 0
A9: SHAWN KELLY | B9: PRESIDENT | C9: 0 | D9: 0 | E9: 0 | F9: 0
A10: DANA MARTIN | B10: VICE PRESIDENT | C10: 0 | D10: 0 | E10: 0 | F10: 0
A11: PHILLIP WRIGHT | B11: DIRECTOR | C11: 0 | D11: 0 | E11: 0 | F11: 0
A12: LARRY F PENNELL | B12: DIRECTOR | C12: 900 | D12: 0 | E12: 0 | F12: 900
A13: VAN GRAYER | B13: GENERAL MANAGER | C13: 211527 | D13: 0 | E13: 0 | F13: 211527
A14: DENNY ARMSTRONG | B14: OPERATIONS SUPERVISOR | C14: 140911 | D14: 0 | E14: 0 | F14: 140911
A15: THOMAS WEBB | B15: DISTRIBUTION SYSTEM SUPERV | C15: 126330 | D15: 0 | E15: 0 | F15: 126330
A16: JAIME ACEVEDO | B16: SPECIAL PROJECTS COORDINAT | C16: 130071 | D16: 0 | E16: 0 | F16: 130071
A18: Section B - Independent contractors (over $100,000)
A19: Contractor | B19: Services | C19: Compensation
A21: Section A lists every officer, director, trustee and key employee filed for the latest year; the two with the highest total compensation are highlighted. Total compensation is computed (reportable org + related + other). Section B lists each independent contractor paid over $100,000; the return reports 0 such contractor(s). Source and confidence for every figure are on the Sources & audit tab.

Sheet Revenue (detail)
A1: Vaughn Water Company Inc
A2: Revenue - Form 990 Part VIII (USD)
A3: Entity ID: cawc_0030 | Fiscal year ends December 31.
A5: Part VIII line | B5: FY2020 | C5: FY2021 | D5: FY2022 | E5: FY2023 | F5: FY2024
A6: Revenue by category
A7: 1h. Total contributions, gifts, grants | B7: not reported | C7: not reported | D7: not reported | E7: not reported | F7: not reported
A8: 2g. Total program service revenue | B8: 9106619 | C8: 9221448 | D8: 9129183 | E8: 11066242 | F8: 11206435
A9: 3. Investment income | B9: 68235 | C9: 49610 | D9: 48262 | E9: 637325 | F9: 879892
A10: 6d. Net rental income | B10: not reported | C10: not reported | D10: not reported | E10: not reported | F10: not reported
A11: 7d. Net gain/(loss) from investment sales | B11: not reported | C11: not reported | D11: not reported | E11: not reported | F11: not reported
A12: 11e. Other revenue | B12: 12033292 | C12: 28566 | D12: 2269 | E12: not reported | F12: not reported
A13: 12. Total revenue | B13: =SUM(B7:B12) | C13: =SUM(C7:C12) | D13: =SUM(D7:D12) | E13: =SUM(E7:E12) | F13: =SUM(F7:F12)
A15: Program service revenue detail - FY2024 (lines 2a-2f)
A16: Description | B16: Business code | C16: Total revenue
A17: WATER SALES | C17: 11037215
A18: WATER AVAILABILITY CHARGES | C18: 161992
A19: OTHER INCOME | C19: 7228
A20: Revenue category subtotals are as filed. Total revenue (line 12) is a live SUM of the category cells above; its tie-out to the filed total is on the Sources & audit tab. Program service revenue detail is shown for the latest year, with its sum-to-line-2g check on that same audit tab.

Sheet Operating expenses (detail)
A1: Vaughn Water Company Inc
A2: Statement of Functional Expenses - Form 990 Part IX (USD)
A3: Entity ID: cawc_0030 | Fiscal year ends December 31.
A5: Part IX line (column A Total) | B5: FY2020 | C5: FY2021 | D5: FY2022 | E5: FY2023 | F5: FY2024
A6: Functional expenses, column A Total - by year
A7: 5. Compensation of current officers, directors, trustees | B7: not reported | C7: 368449 | D7: 400151 | E7: 203391 | F7: 609739
A8: 7. Other salaries and wages | B8: 1661049 | C8: 1334154 | D8: 1164722 | E8: 1542002 | F8: 1288011
A9: 8. Pension plan accruals and contributions | B9: 141242 | C9: 153634 | D9: 160815 | E9: not reported | F9: not reported
A10: 9. Other employee benefits | B10: not reported | C10: not reported | D10: 190398 | E10: 164419 | F10: not reported
A11: 10. Payroll taxes | B11: 112594 | C11: 124820 | D11: 117050 | E11: 130298 | F11: 140798
A12: 11b. Fees for services: legal | B12: not reported | C12: not reported | D12: 441 | E12: not reported | F12: not reported
A13: 11c. Fees for services: accounting | B13: not reported | C13: not reported | D13: 37400 | E13: not reported | F13: not reported
A14: 11g. Fees for services: other | B14: 157240 | C14: 80003 | D14: 217608 | E14: 488016 | F14: 595804
A15: 13. Office expenses | B15: 62615 | C15: 60368 | D15: 147001 | E15: 52543 | F15: not reported
A16: 14. Information technology | B16: 84324 | C16: 84910 | D16: 129430 | E16: 60632 | F16: 62985
A17: 16. Occupancy | B17: 163771 | C17: 188746 | D17: 6145 | E17: not reported | F17: not reported
A18: 17. Travel | B18: not reported | C18: not reported | D18: 6972 | E18: not reported | F18: not reported
A19: 20. Interest | B19: 72812 | C19: 42282 | D19: 30981 | E19: 27309 | F19: not reported
A20: 22. Depreciation, depletion, and amortization | B20: 1055604 | C20: 1023563 | D20: 1133207 | E20: 1137177 | F20: 707913
A21: 23. Insurance | B21: 94477 | C21: 109873 | D21: 127869 | E21: 308801 | F21: 429408
A22: 24. POWER | B22: 2802677 | C22: 2833639 | D22: 3479640 | E22: 3749838 | F22: 4364148
A23: 24. SITE REPAIRS & MAINTENANC | B23: 1166163 | C23: 1319019 | D23: 1075869 | E23: not reported | F23: not reported
A24: 24. WATER | B24: 223288 | C24: 234375 | D24: 237912 | E24: not reported | F24: not reported
A25: 24. WATER ANALYSIS | B25: 126320 | C25: not reported | D25: not reported | E25: not reported | F25: not reported
A26: 24. OPERATING LEASE EXP | B26: not reported | C26: 137714 | D26: not reported | E26: not reported | F26: not reported
A27: 24. CARBON MEDIA | B27: not reported | C27: not reported | D27: 791761 | E27: not reported | F27: not reported
A28: 24. REPAIRS & MAINTENANCE | B28: not reported | C28: not reported | D28: not reported | E28: 1188948 | F28: 1063600
A29: 24. CARBON MEDIA REPLACEMEN | B29: not reported | C29: not reported | D29: not reported | E29: 367023 | F29: 704247
A30: 24. POSTAGE | B30: not reported | C30: not reported | D30: not reported | E30: 136624 | F30: not reported
A31: 24. BAD DEBT EXPENSE | B31: not reported | C31: not reported | D31: not reported | E31: not reported | F31: 200000
A32: 24e. All other expenses | B32: 352490 | C32: 374371 | D32: 538384 | E32: 491386 | F32: 879846
A33: 25. Total functional expenses | B33: =SUM(B7:B32) | C33: =SUM(C7:C32) | D33: =SUM(D7:D32) | E33: =SUM(E7:E32) | F33: =SUM(F7:F32)
A35: Functional column split - FY2024
A36: Not reported. This filer reports only column A (Total) of Part IX; the program / management / fundraising split (columns B-D) is not filed, so it is left as not reported rather than shown empty or inferred.
A37: Top block: each Part IX line, column A (Total), by year, as filed. Total functional expenses (line 25) is a live SUM of the line cells; its tie-out to the filed total is on the Sources & audit tab. Filer-itemized 24a-24d rows show the most recent year's as-filed wording; rows are aligned across years case-insensitively with collapsed spacing, so a line filed only in a different capitalization or spacing shares one row, while genuinely different wording stays a separate row (every as-filed variant is recorded on the Sources & audit tab). This filer reports only column A (Total); the program / management / fundraising split (columns B-D) is not reported. Lines this filer does not report are omitted rather than shown empty.

Sheet Balance sheet (detail)
A1: Vaughn Water Company Inc
A2: Balance Sheet - Form 990 Part X (end of year, USD)
A3: Entity ID: cawc_0030 | Fiscal year ends December 31.
A5: Part X line (column B, EOY) | B5: FY2020 | C5: FY2021 | D5: FY2022 | E5: FY2023 | F5: FY2024
A6: Assets
A7: 1. Cash - non-interest-bearing | B7: 380719 | C7: 1130043 | D7: 1132372 | E7: 961256 | F7: 2159708
A8: 2. Savings and temporary cash investments | B8: 21147024 | C8: 20661963 | D8: 20779294 | E8: 21471514 | F8: 22054340
A9: 4. Accounts receivable, net | B9: 387938 | C9: 616502 | D9: 357391 | E9: 507733 | F9: 411362
A10: 8. Inventories for sale or use | B10: 118825 | C10: 1808 | D10: 1808 | E10: 1808 | F10: 1808
A11: 9. Prepaid expenses and deferred charges | B11: 1808 | C11: 1691 | D11: not reported | E11: not reported | F11: 25331
A12: 10c. Land, buildings, and equipment, net | B12: 22650386 | C12: 23706379 | D12: 22955018 | E12: 22915540 | F12: 22469759
A13: 15. Other assets | B13: not reported | C13: not reported | D13: not reported | E13: 426871 | F13: 508521
A14: 16. Total assets | B14: =SUM(B7:B13) | C14: =SUM(C7:C13) | D14: =SUM(D7:D13) | E14: =SUM(E7:E13) | F14: =SUM(F7:F13)
A16: Liabilities
A17: 17. Accounts payable and accrued expenses | B17: 798098 | C17: 651222 | D17: 735153 | E17: 798381 | F17: 1073723
A18: 25. Other liabilities | B18: 2217233 | C18: 2149714 | D18: 1627217 | E18: 1016285 | F18: 1575007
A19: 26. Total liabilities | B19: =SUM(B17:B18) | C19: =SUM(C17:C18) | D19: =SUM(D17:D18) | E19: =SUM(E17:E18) | F19: =SUM(F17:F18)
A21: Net assets / fund balances
A22: 29. Capital stock or trust principal | B22: 12860939 | C22: 12912185 | D22: 13031473 | E22: 13043732 | F22: 13043732
A23: 30. Paid-in or capital surplus | B23: 15306952 | C23: 16072083 | D23: 16351684 | E23: 16339425 | F23: 16339425
A24: 31. Retained earnings / accumulated funds | B24: 13503478 | C24: 14333182 | D24: 13480356 | E24: 15086899 | F24: 15598942
A25: 32. Total net assets / fund balances | B25: =SUM(B22:B24) | C25: =SUM(C22:C24) | D25: =SUM(D22:D24) | E25: =SUM(E22:E24) | F25: =SUM(F22:F24)
A27: Every Part X line is end-of-year (column B), as filed. Section totals (lines 16 / 26 / 32) are live SUMs of the lines above; their tie-outs and the balance-sheet identity (16 = 26 + 32) are on the Sources & audit tab. This filer files as a non-FASB mutual, so net assets sit on lines 29-31 (capital stock / paid-in capital / retained earnings); lines this filer does not report are omitted. Lines 10a/10b net into line 10c (shown).

Sheet Net-assets reconciliation
A1: Vaughn Water Company Inc
A2: Reconciliation of Net Assets - Form 990 Part XI (USD)
A3: Entity ID: cawc_0030 | Fiscal year ends December 31.
A5: Part XI line | B5: FY2020 | C5: FY2021 | D5: FY2022 | E5: FY2023 | F5: FY2024
A6: Reconciliation
A7: 4. Net assets, beginning of year | B7: 28732921 | C7: 41671369 | D7: 43317450 | E7: 42863513 | F7: 44470056
A8: 3. Revenue less expenses | B8: 12931480 | C8: 829704 | D8: -814042 | E8: 1655160 | F8: 1039828
A9: 8. Prior period adjustments | B9: not reported | C9: not reported | D9: not reported | E9: not reported | F9: not reported
A10: 9. Other changes in net assets | B10: 6968 | C10: 816377 | D10: 360105 | E10: -48617 | F10: -527785
A11: 10. Net assets, end of year | B11: =SUM(B7,B8,B9,B10) | C11: =SUM(C7,C8,C9,C10) | D11: =SUM(D7,D8,D9,D10) | E11: =SUM(E7,E8,E9,E10) | F11: =SUM(F7,F8,F9,F10)
A13: Part XI reconciles beginning to ending net assets. Ending net assets (line 10) is a live formula: beginning balance (line 4) + revenue less expenses (line 3) + prior-period adjustments (8) + other changes (9). Its tie-out to the filed line 10 (and to Part X line 32) is on the Sources & audit tab. Lines 5-7 (unrealized gains, donated services, investment expenses) are not filed by this entity.

Sheet Cash flow proxies
A1: Vaughn Water Company Inc
A2: Cash Flow Proxies - derived (USD)
A3: Entity ID: cawc_0030 | Fiscal year ends December 31.
A5: PROXY ONLY. The source filings contain no statement of cash flows. Lines below are derived from the reported income statement and year-over-year balance-sheet changes; treat as directional estimates, not GAAP cash flows. The earliest year has no prior period, so its delta cells are blank.
A7: Proxy line (USD) | B7: FY2020 | C7: FY2021 | D7: FY2022 | E7: FY2023 | F7: FY2024
A8: Operating
A9: Net income | B9: 12931480 | C9: 829704 | D9: -814042 | E9: 1655160 | F9: 1039828
A10: + Depreciation (reported) | B10: 1055604 | C10: 1023563 | D10: 1133207 | E10: 1137177 | F10: 707913
A11: − Δ Accounts receivable | C11: -228564 | D11: 259111 | E11: -150342 | F11: 96371
A12: − Δ Inventories | C12: 117017 | D12: 0 | E12: 0 | F12: 0
A13: − Δ Prepaid expenses | C13: 117
A14: + Δ Accounts payable | C14: -146876 | D14: 83931 | E14: 63228 | F14: 275342
A15: Operating cash flow proxy | C15: 1594961 | D15: 662207 | E15: 2705223 | F15: 2119454
A17: Investing
A18: − Δ PP&E gross (capex proxy) | C18: -2079556 | D18: -381846 | E18: -1146316 | F18: -789918
A20: Financing
A21: Δ Mortgages & notes payable
A23: Reconciliation
A24: Δ Cash + temp. investments (actual) | C24: 264263 | D24: 119660 | E24: 521104 | F24: 1781278
A26: The capex proxy assumes gross PP&E rises only via capital spending (it ignores disposals). 'Δ Cash + temp. investments (actual)' is the real reported change in liquid funds and is the most reliable line here; the operating/investing/financing proxies will not perfectly reconcile to it.

Sheet Ratios
A1: Vaughn Water Company Inc
A2: Financial Ratios
A3: Entity ID: cawc_0030 | Fiscal year ends December 31.
A5: Ratio | B5: FY2020 | C5: FY2021 | D5: FY2022 | E5: FY2023 | F5: FY2024
A6: Profitability (computed upstream)
A7: Operating margin (NI / revenue) | B7: 0.60974118 | C7: 0.089219091 | D7: -0.088678362 | E7: 0.14142355 | F7: 0.086033416
A8: Expense ratio (expenses / revenue) | B8: 0.39025882 | C8: 0.91078091 | D8: 1.0886784 | E8: 0.85857645 | F8: 0.91396658
A9: Return on assets (NI / assets) | B9: 0.28938096 | C9: 0.017990742 | D9: -0.017999472 | E9: 0.035760396 | F9: 0.021830987
A10: Revenue growth (YoY) | B10: 1.3490603 | C10: -0.56150698 | D10: -0.01289407 | E10: 0.27493809 | F10: 0.032704559
A12: Leverage & solvency
A13: Debt-to-assets (liab. / assets) | B13: 0.067477146 | C13: 0.060733609 | D13: 0.052234912 | E13: 0.039206587 | F13: 0.055609572
A14: Equity ratio (net assets / assets) | B14: 0.93252285 | C14: 0.93926639 | D14: 0.94776509 | E14: 0.96079341 | F14: 0.94439043
A16: Liquidity & asset profile (derived here)
A17: Current ratio (current assets / AP) | B17: 27.611038 | C17: 34.41531 | D17: 30.29419 | E17: 28.736043 | F17: 22.959878
A18: Cash ratio ((cash+temp inv.) / total liab.) | B18: 7.1394295 | C18: 7.7802585 | D18: 9.2752896 | E18: 12.361928 | F18: 9.1417577
A19: Asset age proxy (accum. deprec. / gross PP&E) | B19: 0.46462579 | C19: 0.46591778 | D19: 0.48725618 | E19: 0.50091708 | F19: 0.51890256
A21: Upstream ratios are read from financials_annual; derived ratios are computed only where inputs are reported. Current ratio uses accounts payable as the current-liability proxy (the filings do not split current vs. long-term liabilities). Asset age proxy: a higher % implies older / more depreciated infrastructure.

Sheet Unit economics
A1: Vaughn Water Company Inc
A2: Unit economics - per-customer revenue by category (USD)
A3: Entity ID: cawc_0030 | Fiscal year ends December 31.
A5: Every metric here is PER CUSTOMER (a metered service connection). It is not a per-member figure; the member (shareholder) count is a different denominator, shown in the denominator block. The visible cell shows the value and its classification; the numerator, denominator, formula, and rationale are in each metric's LOGIC popup.
A6: Per-customer denominator (service connections) | B6: 11448 | C6: State Water Board eAR Section 4 (CurTotalConnections), reporting year 2024
A7: Total annual revenue (eAR Section 8b B1.8) | B7: 11028563 | C7: State Water Board eAR Section 8b, question B1.8 (total annual revenue), reporting year 2024
A8: Primary source | C8: State Water Board eAR Section 8b (revenue by rate/fee), reporting year 2024
A10: Revenue categories (value, classification, per customer, share)
A11: Revenue category | B11: Classification | C11: Value (USD) | D11: Per customer | E11: Share of revenue
A12: Water sales revenue | B12: DIRECT | C12: 10997261 | D12: 960.63 | E12: 0.9972
A13: Assessment revenue (990 program-service revenue not matched to eAR water-rate revenue) | B13: DERIVED | C13: 209174 | D13: 18.27 | E13: 0.0187
A14: Meter revenue | B14: not reported | C14: not reported | D14: not reported | E14: not reported
A15: Overage or tiered penalty revenue | B15: not reported | C15: not reported | D15: not reported | E15: not reported
A17: Water sales revenue - DIRECT
A18: Revenue customers paid for water service, read straight off the filed eAR Section 8b water-rate line. A DIRECT filed figure, not computed by us.
A19: Numerator: Water rate revenue | B19: 10997261 | C19: eAR Section 8b field B1.1 (residential water rates) + B1.2 (non-residential water rates). State Water Board eAR Section 8b, question B1.1 + B1.2 (revenue from water rates), reporting year 2024
A20: Denominator: Total service connections | B20: 11448 | C20: eAR Section 4 CurTotalConnections, reporting year 2024. State Water Board eAR Section 4 (CurTotalConnections), reporting year 2024
A21: Per customer: water rate revenue $10,997,261 / 11,448 connections = $960.63 per connection
A22: Share of revenue: water rate revenue $10,997,261 / total annual revenue (eAR Section 8b B1.8) $11,028,563 = 99.72%
A23: Period treatment: Numerator (eAR Section 8b, the calendar year 2024) and denominator (eAR Section 4 connections reported in the same eAR filing) are both the eAR reporting year 2024, so the two sides are bound to the same reporting year.
A24: Rationale: Dividing water-rate revenue by the number of metered service connections gives the average revenue per customer; dividing by total annual revenue shows how much of the system's income comes from water rates.
A26: Assessment revenue (990 program-service revenue not matched to eAR water-rate revenue) - DERIVED
A27: A DERIVED residual (medium confidence): the part of the Form 990 program-service revenue that is not matched by the eAR water-rate revenue for the same period. Computed by us, not a filed line.
A28: Input A: Form 990 program-service revenue | B28: 11206435 | C28: Form 990 Part VIII line 2 (total program-service revenue), fiscal year 2024 ending December 31, 2024
A29: Input B: eAR water-rate revenue | B29: 10997261 | C29: State Water Board eAR Section 8b, question B1.1 + B1.2 (revenue from water rates), reporting year 2024
A30: Residual (A minus B) = assessment revenue | B30: =B28-B29 | C30: $11,206,435 (990 program-service revenue) minus $10,997,261 (eAR water-rate revenue) = $209,174
A31: Period alignment: Both inputs cover the same period: the eAR Section 8b is the calendar year 2024 and the Form 990 fiscal year 2024 ends December 31, 2024, so the residual is period-aligned.
A32: What it IS: revenue the system booked as program service on its 990 that is not accounted for by the eAR water-rate line, plausibly member assessments and other service revenue.
A33: This residual is a difference between two sources for the same period; it is not a separately filed assessment line and may include other unmatched revenue.
A34: Denominator: Total service connections | B34: 11448 | C34: eAR Section 4 CurTotalConnections, reporting year 2024. State Water Board eAR Section 4 (CurTotalConnections), reporting year 2024
A35: Per customer: residual $209,174 / 11,448 connections = $18.27 per connection
A36: Share of revenue: residual $209,174 / 990 program-service revenue $11,206,435 = 1.87%
A38: Meter revenue - not reported
A39: Not reported. This category is not built because doing so would double-count.
A40: Reason: The eAR Section 8a reports a base/meter rate PRICE, but the filing carries no meter revenue line and no tier volume, and the base charge is already inside the water-sales revenue (eAR Section 8b water rates). Building a separate meter figure would double-count. Not backed into from a total.
A42: Overage or tiered penalty revenue - not reported
A43: Not reported. This category is not built because doing so would double-count.
A44: Reason: The eAR Section 8a reports tiered/overage rate PRICES, but the filing carries no overage revenue and no tier consumption volume, and any overage billed is already inside the water-sales revenue. Building it would double-count. Not backed into from a total.

Sheet Rate structure
A1: Vaughn Water Company Inc
A2: Rate structure and representative bill - eAR Section 8a (RY2024)
A3: Entity ID: cawc_0030 | Fiscal year ends December 31.
A5: This block is a rate-schedule illustration at defined usage levels. It is NOT billed revenue and not a claim about any real customer's usage. The revenue side of unit economics is the separate Unit Economics block.
A6: Structure: Tiered increasing-block with a fixed base, billed monthly, priced per HCF. Rate schedule last updated 04/01/2023.
A7: Defined single-family usage levels, identical for every company so the bill is comparable: Low = 5 HCF/month (~125 gallons/day); Median = 10 HCF/month (~249 gallons/day); High = 25 HCF/month (~623 gallons/day). 1 HCF = 748 gallons, and 1 thousand gallons = 1,000 gallons. The usage is converted into the company's own filed unit before the filed tiers are applied, and the bill is stated as a monthly equivalent: a bimonthly structure is computed at twice the monthly usage and divided by two, and any other billing period the same way with its factor stated. These are an illustration, not a measured usage for any real customer.
A9: Defined usage levels (EDITABLE - change a yellow cell to move the bill)
B10: Low | C10: Median | D10: High
A11: Monthly usage (HCF) | B11: 5 | C11: 10 | D11: 25
A12: Months per bill (from filed billing frequency) | B12: 1 | C12: monthly biller
A14: Filed rate table - single-family residential (as filed, eAR Section 8a)
A15: Base / fixed charge per monthly bill ($) | B15: 60.42
A16: Tier | B16: Range (HCF) | C16: Price ($/HCF) | D16: Upper limit (HCF)
A17: Tier 1 | B17: 0 to 4860 HCF | C17: 0.42 | D17: 4860
A18: Tier 2 | B18: 4860 to 9720 HCF | C18: 0.48 | D18: 9720
A19: Tier 3 | B19: over 9720 HCF | C19: 1.15 | D19: no limit
A21: Flags on the filed rate table (nothing below is corrected)
A22: Tier 1 price: implausible as filed; checked against source. The filed tier 1 price of $0.42 per unit implies $0.42 per HCF, outside the $0.50 to $50.00 per HCF range a residential water rate plausibly takes. Carried exactly as filed and not corrected. Source: State Water Board eAR Section 8 / WRSFUsageCost1
A23: Tier 2 price: implausible as filed; checked against source. The filed tier 2 price of $0.48 per unit implies $0.48 per HCF, outside the $0.50 to $50.00 per HCF range a residential water rate plausibly takes. Carried exactly as filed and not corrected. Source: State Water Board eAR Section 8 / WRSFUsageCost2
A25: Representative monthly bill - LIVE (edit a yellow usage cell to recompute)
B26: Low | C26: Median | D26: High
A27: Usage per bill (HCF) | B27: =B11*$B$12 | C27: =C11*$B$12 | D27: =D11*$B$12
A28: Tier 1 charge per bill ($) | B28: =$C$17*MAX(0,MIN(B27,$D$17)-0) | C28: =$C$17*MAX(0,MIN(C27,$D$17)-0) | D28: =$C$17*MAX(0,MIN(D27,$D$17)-0)
A29: Tier 2 charge per bill ($) | B29: =$C$18*MAX(0,MIN(B27,$D$18)-$D$17) | C29: =$C$18*MAX(0,MIN(C27,$D$18)-$D$17) | D29: =$C$18*MAX(0,MIN(D27,$D$18)-$D$17)
A30: Tier 3 charge per bill ($) | B30: =$C$19*MAX(0,B27-$D$18) | C30: =$C$19*MAX(0,C27-$D$18) | D30: =$C$19*MAX(0,D27-$D$18)
A31: Volumetric charge per bill ($) | B31: =SUM(B28,B29,B30) | C31: =SUM(C28,C29,C30) | D31: =SUM(D28,D29,D30)
A32: Base charge per bill ($) | B32: =$B$15 | C32: =$B$15 | D32: =$B$15
A33: Total per bill ($) | B33: =B32+B31 | C33: =C32+C31 | D33: =D32+D31
A34: Total per MONTH ($) | B34: =B33/$B$12 | C34: =C33/$B$12 | D34: =D33/$B$12
A35: Fixed per month ($) | B35: =$B$15/$B$12 | C35: =$B$15/$B$12 | D35: =$B$15/$B$12
A36: Volumetric per month ($) | B36: =B31/$B$12 | C36: =C31/$B$12 | D36: =D31/$B$12
A37: Effective price ($/HCF) | B37: =IF(B11=0,"",B34/B11) | C37: =IF(C11=0,"",C34/C11) | D37: =IF(D11=0,"",D34/D11)
A39: Rate-structure comparison metrics
A40: Fixed share of the bill at median usage | B40: =C35/C34 | C40: fixed / total at 10 HCF/month
A41: Tier price ratio (highest to lowest positive tier) | B41: =$C$19/$C$17 | C41: highest filed tier price divided by lowest filed tier price.
A42: Rate structure (as filed) | B42: tiered (Variable Base)
A44: State Water Board eAR Section 8a (Customer Charges), single- and multi-family residential charges grid, reporting year 2024. Rate structure only; no revenue.

Sheet eAR revenue & expenses
A1: Vaughn Water Company Inc
A2: eAR annual revenue and expenses - State Water Board eAR Section 8b (USD)
A3: Entity ID: cawc_0030 | Fiscal year ends December 31.
A5: The water system's own annual figures from the public eAR Section 8b, on the calendar year 2024 the filer self-reported (B0.1/B0.2). Shown beside the period-aligned Form 990 with the variance flagged: a different source (a State Water Board self-report vs an IRS filing). Preserved as filed, never reconciled.
A6: Reporting period basis (self-reported) | B6: calendar year 2024 | C6: eAR Section 8b B0.1 (WRFinancialReportingPeriod)
A8: Revenue (eAR Section 8b, questions B1.x)
A9: Line | B9: Amount (USD) | C9: Citation
A10: Water rate revenue | B10: 10997261 | C10: State Water Board eAR Section 8b, question B1.1 + B1.2 (revenue from water rates), reporting year 2024
A11: Other fees and charges | B11: 31302 | C11: State Water Board eAR Section 8b, question B1.3 + B1.4 (revenue from other fees), reporting year 2024
A12: Non-customer revenue | B12: 0 | C12: State Water Board eAR Section 8b, question B1.7 (grants, interest, and other non-customer), reporting year 2024
A13: Total annual revenue | B13: 11028563 | C13: State Water Board eAR Section 8b, question B1.8 (total annual revenue for the reporting year), reporting year 2024
A15: Expenses (eAR Section 8b, questions B2.x)
A16: Line | B16: Amount (USD) | C16: Citation
A17: Operations and maintenance | B17: 11520496 | C17: State Water Board eAR Section 8b, question B2.1 (annual O and M expense), reporting year 2024
A18: Capital | B18: 1285167 | C18: State Water Board eAR Section 8b, question B2.2 (annual expenses from investing or capital), reporting year 2024
A19: Financing | B19: 285511 | C19: State Water Board eAR Section 8b, question B2.3 (annual expenses from financing), reporting year 2024
A20: Other | B20: 0 | C20: State Water Board eAR Section 8b, question B2.4 (total other annual expenses), reporting year 2024
A21: Total annual expenses | B21: 13091174 | C21: State Water Board eAR Section 8b, question B2.5 (total annual expenses), reporting year 2024
A23: Period-aligned Form 990 comparison (variance surfaced, never reconciled)
A24: Measure | B24: eAR Section 8b | C24: Form 990
A25: total revenue | B25: 11028563 | C25: 12086327
A26: Variance (eAR minus Form 990) | B26: =B25-C25
A27: The eAR Section 8b total revenue (State Water Board self-report, calendar year 2024) and the Form 990 total revenue (IRS filing) are a different source and cover the same calendar year 2024. Both are carried as filed; the variance is surfaced, never reconciled.
A28: total expenses | B28: 13091174 | C28: 11046499
A29: Variance (eAR minus Form 990) | B29: =B28-C28
A30: The eAR Section 8b total expenses (State Water Board self-report, calendar year 2024) and the Form 990 total expenses (IRS filing) are a different source and cover the same calendar year 2024. Both are carried as filed; the variance is surfaced, never reconciled.

Sheet Denominators & alignment
A1: Vaughn Water Company Inc
A2: Denominators and calendar alignment
A3: Entity ID: cawc_0030 | Fiscal year ends December 31.
A5: System size and water use per fiscal year (the operating denominators that per-customer and per-acre metrics divide by), each cited to file and field. The eAR is reported on the calendar year; the 990 fiscal year differs by company. A calendar-year filer's volume is the eAR annual total (fiscal year = calendar year); an offset filer's is recast by a true monthly sum of the covered calendar months, or read not reported naming the missing months. Point-in-time counts (connections, population) are matched to the closest eAR year and never summed. Every derived figure states its formula and accounting rationale.
A6: Member vs customer (two different denominators, both preserved)
A7: Customer (service connection) | B7: 11448 | C7: State Water Board eAR Section 4 (CurTotalConnections), reporting year 2024
A8: Member (shareholder) | C8: No published shareholder count
A9: In a mutual water company a MEMBER is a shareholder who owns part of the system; a CUSTOMER is a metered service connection that receives water. The two diverge because one owner can hold several connections, a connection can serve people who are not owners, and some mutuals attach shares to land by acreage rather than counting heads. Per-customer metrics divide by service connections; per-member metrics divide by shareholders; the two counts are never used interchangeably.
A11: Denominator layer by fiscal year
A12: Fiscal year (end) | B12: Connections | C12: Population | D12: Service-area acres | E12: Water produced (AF) | F12: Water delivered (AF) | G12: Alignment method
A13: FY2020 (2020-12-31) | B13: 11099 | C13: not reported | D13: 19204.8 | E13: not reported | F13: not reported | G13: eAR annual total, calendar filer, equals fiscal year (not a monthly recast)
A14: FY2021 (2021-12-31) | B14: 11213 | C14: not reported | D14: 19204.8 | E14: not reported | F14: not reported | G14: eAR annual total, calendar filer, equals fiscal year (not a monthly recast)
A15: FY2022 (2022-12-31) | B15: 11306 | C15: not reported | D15: 19204.8 | E15: not reported | F15: not reported | G15: eAR annual total, calendar filer, equals fiscal year (not a monthly recast)
A16: FY2023 (2023-12-31) | B16: 11306 | C16: not reported | D16: 19204.8 | E16: not reported | F16: not reported | G16: eAR annual total, calendar filer, equals fiscal year (not a monthly recast)
A17: FY2024 (2024-12-31) | B17: 11448 | C17: 37075 | D17: 19204.8 | E17: not reported | F17: not reported | G17: eAR annual total, calendar filer, equals fiscal year (not a monthly recast)
A19: Connections by class - FY2024 (eAR Section 4)
A20: Single-family residential | B20: 11017
A21: Multi-family residential | B21: 44
A22: Commercial and institutional | B22: 260
A23: Industrial | B23: 25
A24: Landscape irrigation | B24: 137
A25: Monthly-volume source: California open-data portal (data.ca.gov): the separate Produced Water (by month and source) and Delivered Water (by month and connection type) resources, which cover every public water system (not only urban suppliers), one resource per reporting year, matched by exact PWSID. This is the aggregate publication of eAR Section 6.

Sheet Governance evidence
A1: Vaughn Water Company Inc
A2: Governance evidence status - Ostrom's eight design principles
A3: Entity ID: cawc_0030 | Fiscal year ends December 31.
A5: Evidence summary: 3 documented, 3 partial, 2 not documented of eight principles.
A6: A count of how many of Elinor Ostrom's eight design principles have a supporting record on file, not a grade. NOT DOCUMENTED means the supporting record was not found, not that the company governs badly. It marks a gap in the documentary record, an evidence gap to close, never a governance failing.
A7: Each mutual is read against Elinor Ostrom's eight design principles for institutions that govern a shared resource durably. Per principle: a one-line finding, the observable signal, a citation, and an evidence status stating whether the supporting record exists: DOCUMENTED (a cited record supports alignment), PARTIAL (some evidence exists but it is incomplete), or NOT DOCUMENTED (no supporting record was found). This is an evidence-status read, not a grade: the principles are never ranked, weighted, or given a letter, consistent with reporting as filed and not grading companies. NOT DOCUMENTED means the supporting record was not found, not that the company governs badly. It marks a gap in the documentary record, an evidence gap to close, never a governance failing.
A9: Principle | B9: Evidence status | C9: Finding | D9: Signal | E9: Citation
A10: Clearly defined boundaries | B10: PARTIAL | C10: The system is a defined public water system with 11,448 service connections and a State-published service area of roughly 19,161.9 acres, but the State Water Board has NOT verified that boundary. | D10: SDWIS Community water system; SABL service-area boundary (Not Verified); connections defined. | E10: [C][G]
A11: What the record shows: Membership is documented as a fixed set of service connections, so the social boundary is clear. The physical boundary is published but carries the State's Not Verified flag, so it is drawn dashed and every figure derived from its acreage is held at lower confidence.
A12: Rules fit local conditions | B12: DOCUMENTED | C12: Charges are tied to metered use under a filed rate schedule: a variable base residential structure billed m and priced per hundred cubic feet. | D12: eAR Section 8a customer charges; metered service; Variable Base residential rate structure. | E12: [E]
A13: What the record shows: The record documents how charges are set: the filer reports metered service, a billing frequency, a residential rate structure and a filed rate schedule, so cost tracks service. Whether every tier scales precisely with use is not visible in the filing and is not claimed here.
A14: Collective-choice arrangements | B14: PARTIAL | C14: The company is owned by its shareholders and publishes the time and place of its regular monthly board meeting. | D14: Mutual ownership; published monthly board meeting; Form 990 governance section. | E14: [990][1]
A15: What the record shows: A collective-choice mechanism is documented in outline: the customers are the shareholders. It stays PARTIAL rather than met because the filed corporate record that would carry the director roster and the election procedure is NOT YET CHECKED for this company, the California Secretary of State being reachable only through a browser session that now answers a CAPTCHA. A stated board is not a filed roster.
A16: Monitoring | B16: DOCUMENTED | C16: The system is monitored and reports on itself: it files an annual eAR, and it reports metered service, and a Consumer Confidence Report for 2024 was located at the State's own CCR portal, and it holds an emergency response plan dated 7/1/2024. | D16: Annual eAR reporting; metered connections; located Consumer Confidence Report | E16: [E][CCR]
A17: What the record shows: Operational monitoring is documented from more than one filing. What the federal violation check found is reported separately in the On the record block and is not folded into this tier.
A18: Graduated sanctions | B18: NOT DOCUMENTED | C18: No published shut-off, penalty, or delinquency policy was found for this system. | D18: No sourced graduated sanctions record. | E18: not reported
A19: What the record shows: No public record of a shut-off, penalty, or delinquency policy was located. NOT DOCUMENTED means the supporting record was not found, not that the company governs badly. It marks a gap in the documentary record, an evidence gap to close, never a governance failing.
A20: Conflict-resolution mechanisms | B20: NOT DOCUMENTED | C20: No published bylaws, dispute procedure, or grievance mechanism was found for this system. | D20: No sourced conflict-resolution mechanisms record. | E20: not reported
A21: What the record shows: No public record of a bylaws, dispute procedure, or grievance mechanism was located. NOT DOCUMENTED means the supporting record was not found, not that the company governs badly. It marks a gap in the documentary record, an evidence gap to close, never a governance failing.
A22: Recognized right to organize | B22: DOCUMENTED | C22: An incorporated California mutual water company recognized by the IRS as a 501(c)(12) exempt filer and by the State Water Board as a Community public water system. | D22: IRS 501(c)(12) exempt filer (Form 990); SDWIS Community public water system; eAR ownership type 'Privately owned Mutual Water Company or Association'. | E22: [990][C][E]
A23: What the record shows: Baseline legal standing is documented by two independent regulators: the IRS accepts it as a tax-exempt 501(c)(12) filer and the State Water Board holds it as a Community public water system with a mutual ownership type. This status does NOT rest on a filed corporate record, because the Secretary of State check has not been run for this company.
A24: Nested enterprises | B24: PARTIAL | C24: The system sits inside larger water systems: it pumps from 1 groundwater basin(s) shared with neighbors. Its role in governing any of them is not documented. | D24: it pumps from 1 groundwater basin(s) shared with neighbors | E24: [SG]
A25: What the record shows: Physical nesting is documented. What is not documented is any governance role in a wholesaler or in a groundwater sustainability agency, so the tier is PARTIAL rather than met.

Sheet Operational metrics
A1: Vaughn Water Company Inc
A2: Operational metrics - plant per acre, density, terrain
A3: Entity ID: cawc_0030 | Fiscal year ends December 31.
A5: Plant assets per acre
A6: Service-area acres | B6: 19204.8 | C6: Geodesic area (WGS84 spherical excess) of the SABL service-area polygon.
A7: Fiscal year | B7: Gross plant per acre (primary) | C7: Net plant per acre
A8: FY2020 | B8: 2202.9689 | C8: 1179.4128
A9: FY2021 | B9: 2311.2521 | C9: 1234.3986
A10: FY2022 | B10: 2331.1349 | C10: 1195.275
A11: FY2023 | B11: 2390.824 | C11: 1193.2194
A12: FY2024 | B12: 2431.9552 | C12: 1170.0074
A13: Infrastructure built per acre of service area. Gross plant per acre is the primary read because it measures how much plant the system has put in the ground per acre, and unlike net plant it does not fall over time purely because the assets depreciate on the books. Net plant per acre is shown alongside as the depreciated book value per acre.
A14: Formula: gross plant per acre = Form 990 Part X line 10a (land, buildings, and equipment, gross) / SABL service-area acres; net plant per acre uses Part X line 10c (net)
A15: Source lines: Form 990 Part X line 10a (gross) and line 10c (net); Geodesic area (WGS84 spherical excess) of the SABL service-area polygon.
A16: Confidence: medium. This is worked out from filed figures (a ratio, or a year-to-year change), so it is one step removed from the raw numbers.. Filed gross/net plant over the measured SABL service-area acreage.
A18: Connections per acre
A19: Connections per acre | B19: 0.6 | C19: 11,483 connections / 19,204.8 acres. CA State Water Board SABL SERVICE_CONNECTIONS; Geodesic area (WGS84 spherical excess) of the SABL service-area polygon.

Sheet Supply & weather
A1: Vaughn Water Company Inc
A2: Supply and weather indicators (DWR water year)
A3: Entity ID: cawc_0030 | Fiscal year ends December 31.
A5: Reporting calendar: Different reporting periods. The DWR water year runs October 1 to September 30; this system's fiscal year ends December 31, so the two period ends are three months apart. Read the two side by side with that in mind. Neither series is recast: both are reported as filed. A water year is named for the calendar year it ends in, so WY2024 and FY2024 share a number without covering the same twelve months.
A7: Indicator | B7: WY2020 | C7: WY2021 | D7: WY2022 | E7: WY2023 | F7: WY2024
A8: Water-year type (Sacramento Valley) | B8: Dry | C8: Critical | D8: Critical | E8: Wet | F8: Above Normal
A9: Peak drought, Kern County | B9: D1 | C9: D4 | D9: D4 | E9: D4 | F9: None (no D0-D4 during the fiscal year)
A10: Precip, percent of normal (8-Station Index) | B10: 63 | C10: 48 | D10: 86 | E10: 133 | F10: 96
A11: Snowpack, April 1 percent of average | B11: 53% | C11: 59% | D11: 38% | E11: 237% | F11: 110%
A12: State Water Project allocation | B12: 20% | C12: 5% | D12: 5% | E12: 100% | F12: 40%

Sheet How this was built
A1: Vaughn Water Company Inc
A2: How this was built - forensic lineage
A3: Entity ID: cawc_0030 | Fiscal year ends December 31.
A5: A plain account of the forensic lineage behind the hard-to-source metrics: what sources were checked, what was found, what was derived, and what could not be built and why. Every figure marked DERIVED or IMPOSSIBLE above is traceable to a line here.
A7: Water-sales revenue per customer - DIRECT
A8: Sources checked | B8: State Water Board eAR Section 8b (water-rate revenue B1.1/B1.2); State Water Board eAR Section 4 (connection count, same reporting year); audited financial statement (secondary cross-check, where published)
A9: What was found | B9: The eAR Section 8b reports water-rate revenue for reporting year 2024, so this is a DIRECT filed figure; per customer it is divided by the eAR Section 4 connection count for the same reporting year, so numerator and denominator share the year.
A11: Assessment revenue (residual) - DERIVED
A12: Sources checked | B12: Form 990 Part VIII line 2 (program-service revenue); State Water Board eAR Section 8b (water-rate revenue B1.1/B1.2)
A13: What was found | B13: No source separately reports a member assessment, so it is DERIVED as a residual: $11,206,435 (990 program-service revenue) minus $10,997,261 (eAR water-rate revenue) = $209,174. Period-aligned; medium confidence.
A14: Caveat | B14: This residual is a difference between two sources for the same period; it is not a separately filed assessment line and may include other unmatched revenue.
A16: Meter revenue - not reported
A17: Sources checked | B17: State Water Board eAR Section 8a (rate prices); State Water Board eAR Section 8b (revenue lines); audited financial statement
A18: What was found | B18: The rate price exists in Section 8a but no revenue or tier volume is reported, and the base charge is already inside water sales.
A19: Caveat | B19: The eAR Section 8a reports a base/meter rate PRICE, but the filing carries no meter revenue line and no tier volume, and the base charge is already inside the water-sales revenue (eAR Section 8b water rates). Building a separate meter figure would double-count. Not backed into from a total.
A21: Overage / tiered-penalty revenue - not reported
A22: Sources checked | B22: State Water Board eAR Section 8a (rate prices); State Water Board eAR Section 8b (revenue lines); audited financial statement
A23: What was found | B23: The rate price exists in Section 8a but no revenue or tier volume is reported, and the base charge is already inside water sales.
A24: Caveat | B24: The eAR Section 8a reports tiered/overage rate PRICES, but the filing carries no overage revenue and no tier consumption volume, and any overage billed is already inside the water-sales revenue. Building it would double-count. Not backed into from a total.
A26: eAR Section 8b reporting-period basis - sourced
A27: Sources checked | B27: eAR Section 8b B0.1 (WRFinancialReportingPeriod); eAR Section 8b B0.2 (WRFiscalYearStartDate)
A28: What was found | B28: The reporting basis (fiscal vs calendar year) is read from the filer's own B0.1/B0.2 answer and staged verbatim, never hardcoded, so the 990 comparison and the residual are period-aligned.
A30: Member (shareholder) count denominator - not reported
A31: Sources checked | B31: Form 990 (no member count stated); company website
A32: What was found | B32: No filing states a member/shareholder count, so the per-member unit economics read not reported rather than borrowing the connection count.
A34: Water volume delivered (acre-feet) - not reported
A35: Sources checked | B35: Form 990 (not in the filing); Consumer Confidence Report; eAR Section 6 (PRA-gated)
A36: What was found | B36: Volume delivered in acre-feet is not in the Form 990 and the CCR states only a source mix, so the per-acre-foot metrics read not reported; the eAR Section 6 is named as the source still needed.

Sheet Sources & audit
A1: Vaughn Water Company Inc
A2: Sources & audit - full provenance and tie-outs (kept off the statements so they read clean)
A3: Entity ID: cawc_0030 | Fiscal year ends December 31.
A5: Presentation standard: every figure on the statement tabs is verified to its source filing and shown clean. A cell the filing does not report reads "not reported" (never estimated, never guessed).
A6: Citations, confidence tiers, and the filed-vs-computed tie-out checks live on the "Sources & audit" tab, keyed by cell, so every number is fully traceable without cluttering the statements. These pages are ready to use as filed.
A8: A. Filing provenance (one row per staged extraction)
A9: Fiscal year | B9: Period end | C9: Filing type | D9: Confidence | E9: Extraction ID | F9: Object ID | G9: Extracted by | H9: Extracted at | I9: Source URL
A10: FY2020 | B10: 2020-12-31 | C10: 990 | D10: high | E10: 80101c1b-f6fc-4fd6-a60c-fa2094db718c | F10: 202133189349300548 | G10: claude-opus-5 | H10: 2026-09-14T20:40:24+00:00 | I10: https://apps.irs.gov/pub/epostcard/990/xml/2021/2021_TEOS_XML_01A.zip#202133189349300548_public.xml
A11: FY2021 | B11: 2021-12-31 | C11: 990 | D11: high | E11: e1aae327-7ef8-4987-9aa3-b5c18cece5c2 | F11: 202223199349327042 | G11: claude-opus-5 | H11: 2026-09-14T20:40:24+00:00 | I11: https://apps.irs.gov/pub/epostcard/990/xml/2022/2022_TEOS_XML_02A.zip#202223199349327042_public.xml
A12: FY2022 | B12: 2022-12-31 | C12: 990 | D12: high | E12: 491cf22b-8d19-480b-8f65-350f6f7b8cf0 | F12: 202303199349316770 | G12: claude-opus-5 | H12: 2026-09-14T20:40:24+00:00 | I12: https://apps.irs.gov/pub/epostcard/990/xml/2023/2023_TEOS_XML_11A.zip#202303199349316770_public.xml
A13: FY2023 | B13: 2023-12-31 | C13: 990 | D13: high | E13: 37f5a46f-0030-4c33-b66c-fb5ab6b3a6f2 | F13: 202403199349315915 | G13: claude-opus-5 | H13: 2026-09-14T20:40:24+00:00 | I13: https://apps.irs.gov/pub/epostcard/990/xml/2024/2024_TEOS_XML_11A.zip#202403199349315915_public.xml
A14: FY2024 | B14: 2024-12-31 | C14: 990 | D14: high | E14: 3ff75d23-5a5a-48a4-bca5-3ecbe6f9da33 | F14: 202513189349306131 | G14: claude-opus-5 | H14: 2026-09-14T20:40:24+00:00 | I14: https://apps.irs.gov/pub/epostcard/990/xml/2025/2025_TEOS_XML_11D.zip#202513189349306131_public.xml
A16: B. Figure citations (every figure on the statement tabs, keyed by cell)
A17: Tab | B17: Cell | C17: Line item | D17: Form 990 line | E17: Key path | F17: Confidence | G17: As filed
A18: Financial Statements | B18: E73 | C18: 11a. Gross income from members or shareholders | D18: 11a | E18: part_v_other_irs_filings.members_and_shareholders_gross_income | F18: high | G18: 11010811
A19: Financial Statements | B19: F73 | C19: 11a. Gross income from members or shareholders | D19: 11a | E19: part_v_other_irs_filings.members_and_shareholders_gross_income | F19: high | G19: 11199206
A20: Financial Statements | B20: E74 | C20: 11b. Gross income from other sources | D20: 11b | E20: part_v_other_irs_filings.other_sources_gross_income | F20: high | G20: 0
A21: Financial Statements | B21: F74 | C21: 11b. Gross income from other sources | D21: 11b | E21: part_v_other_irs_filings.other_sources_gross_income | F21: high | G21: 0
A22: Revenue (detail) | B22: B8 | C22: 2g. Total program service revenue | D22: 2g | E22: part_viii_revenue.total_program_service_revenue | F22: high | G22: 9106619
A23: Revenue (detail) | B23: C8 | C23: 2g. Total program service revenue | D23: 2g | E23: part_viii_revenue.total_program_service_revenue | F23: high | G23: 9221448
A24: Revenue (detail) | B24: D8 | C24: 2g. Total program service revenue | D24: 2g | E24: part_viii_revenue.total_program_service_revenue | F24: high | G24: 9129183
A25: Revenue (detail) | B25: E8 | C25: 2g. Total program service revenue | D25: 2g | E25: part_viii_revenue.total_program_service_revenue | F25: high | G25: 11066242
A26: Revenue (detail) | B26: F8 | C26: 2g. Total program service revenue | D26: 2g | E26: part_viii_revenue.total_program_service_revenue | F26: high | G26: 11206435
A27: Revenue (detail) | B27: B9 | C27: 3. Investment income | D27: 3 | E27: part_viii_revenue.investment_income | F27: high | G27: 68235
A28: Revenue (detail) | B28: C9 | C28: 3. Investment income | D28: 3 | E28: part_viii_revenue.investment_income | F28: high | G28: 49610
A29: Revenue (detail) | B29: D9 | C29: 3. Investment income | D29: 3 | E29: part_viii_revenue.investment_income | F29: high | G29: 48262
... A162: Net-assets reconciliation | B162: F10 | C162: 9. Other changes in net assets | D162: Part XI line 9 | E162: part_xi_reconciliation.other_changes_net_assets | F162: high | G162: -527785
A164: C. Tie-out checks (filed vs computed; any nonzero variance is flagged red)
A165: Tab | B165: Check | C165: Fiscal year | D165: Filed | E165: Computed | F165: Variance (computed - filed)
A166: Revenue (detail) | B166: 12. Total revenue | C166: FY2020 | D166: 21208146 | E166: ='Revenue (detail)'!B13 | F166: =E166-D166
A167: Revenue (detail) | B167: 12. Total revenue | C167: FY2021 | D167: 9299624 | E167: ='Revenue (detail)'!C13 | F167: =E167-D167
A168: Revenue (detail) | B168: 12. Total revenue | C168: FY2022 | D168: 9179714 | E168: ='Revenue (detail)'!D13 | F168: =E168-D168
A169: Revenue (detail) | B169: 12. Total revenue | C169: FY2023 | D169: 11703567 | E169: ='Revenue (detail)'!E13 | F169: =E169-D169
A170: Revenue (detail) | B170: 12. Total revenue | C170: FY2024 | D170: 12086327 | E170: ='Revenue (detail)'!F13 | F170: =E170-D170
A171: Revenue (detail) | B171: 2g program service revenue = sum of lines 2a-2f (FY2024) | C171: FY2024 | D171: 11206435 | E171: =SUM('Revenue (detail)'!C17:C19) | F171: =E171-D171
A172: Operating expenses (detail) | B172: 25. Total functional expenses | C172: FY2020 | D172: 8276666 | E172: ='Operating expenses (detail)'!B33 | F172: =E172-D172
A173: Operating expenses (detail) | B173: 25. Total functional expenses | C173: FY2021 | D173: 8469920 | E173: ='Operating expenses (detail)'!C33 | F173: =E173-D173
A174: Operating expenses (detail) | B174: 25. Total functional expenses | C174: FY2022 | D174: 9993756 | E174: ='Operating expenses (detail)'!D33 | F174: =E174-D174
A175: Operating expenses (detail) | B175: 25. Total functional expenses | C175: FY2023 | D175: 10048407 | E175: ='Operating expenses (detail)'!E33 | F175: =E175-D175
A176: Operating expenses (detail) | B176: 25. Total functional expenses | C176: FY2024 | D176: 11046499 | E176: ='Operating expenses (detail)'!F33 | F176: =E176-D176
...

Sheet Provenance
A1: Build provenance | B1: Built from source commit d418ffb17485 (2026-10-06); source fingerprint a75a8eee82c65cf7; 192 companies (179 retail mutual, 4 irrigation mutual, 3 mutual, no PWSID, purpose not stated, 2 frozen non-mutual (special district), 2 wholesale mutual, 1 frozen non-mutual (investor-owned), 1 frozen non-mutual (municipal)); 91 gates; build id 3d08d6d2a855.
A2: source_commit | B2: d418ffb174855ab78000d391d42f898397b0d8aa
A3: source_commit_date | B3: 2026-10-06
A4: source_fingerprint | B4: a75a8eee82c65cf7096931f06e18affdc28686a02895b46538e7298b57c04d94
A5: gate_count | B5: 91
A6: build_id | B6: 3d08d6d2a855
A7: registry: frozen non-mutual (investor-owned) | B7: 1
A8: registry: frozen non-mutual (municipal) | B8: 1
A9: registry: frozen non-mutual (special district) | B9: 2
A10: registry: irrigation mutual | B10: 4
A11: registry: mutual, no PWSID, purpose not stated | B11: 3
A12: registry: retail mutual | B12: 179
A13: registry: wholesale mutual | B13: 2
