Workbook

Sheet Summary
A1: Santa Anita Mutual Water Company
A2: Financial Summary - multi-year overview (USD)
A3: Entity ID: cawc_0024 | Fiscal year ends January 31.
A5: Presentation standard: every figure on the statement tabs is verified to its source filing and shown clean. A cell the filing does not report reads "not reported" (never estimated, never guessed).
A6: Citations, confidence tiers, and the filed-vs-computed tie-out checks live on the "Sources & audit" tab, keyed by cell, so every number is fully traceable without cluttering the statements. These pages are ready to use as filed.
A8: Metric | B8: FY2021 | C8: FY2022 | D8: FY2023 | E8: FY2024 | F8: FY2025
A9: Operating results (USD)
A10: Total revenue | B10: 110639 | C10: 95375 | D10: 85351 | E10: 89157 | F10: 81469
A11: Total expenses | B11: 91653 | C11: 84338 | D11: 100365 | E11: 93691 | F11: 92466
A12: Net income | B12: 18986 | C12: 11037 | D12: -15014 | E12: -4534 | F12: -10997
A14: Financial position (USD, end of year)
A15: Total assets | B15: 79748 | C15: 90785 | D15: 75771 | E15: 71237 | F15: 60240
A16: Total liabilities | F16: 0
A17: Net assets | B17: 79748 | C17: 90785 | D17: 75771 | E17: 71237 | F17: 60240
A19: Headline ratios
A20: Operating margin | B20: 0.17160314 | C20: 0.11572215 | D20: -0.17590889 | E20: -0.050854111 | F20: -0.13498386
A21: Revenue growth (YoY)
A22: Return on assets | B22: 0.23807494 | C22: 0.12157295 | D22: -0.19814969 | E22: -0.0636467 | F22: -0.18255312
A24: Figures as reported in source filings (full provenance on the Sources & audit tab). Parentheses denote negatives; ratios are computed upstream in financials_annual.

Sheet Notes
A1: Notes
A2: Human annotations from the versioned store (data/notes/). Annotations only: they never change a reported figure or a confidence tier.
A4: Date | B4: Tag | C4: Author | D4: Note
A5: No notes recorded yet.

Sheet Financial Statements
A1: Santa Anita Mutual Water Company
A2: Financial Statements - income statement, balance sheet, cash flow, member income test (USD)
A3: Entity ID: cawc_0024 | Fiscal year ends January 31.
A5: INCOME STATEMENT - as reported (USD)
A6: Line item | B6: FY2021 | C6: FY2022 | D6: FY2023 | E6: FY2024 | F6: FY2025
A7: Revenue
A8: Program service revenue
A9: Investment income
A10: Net rental income
A11: Net gain/(loss) on investment sales
A12: Other revenue
A13: Contributions & grants
A14: Total revenue
A16: Expenses
A17: Depreciation
A18: Interest expense
A19: Total expenses | B19: 91653 | C19: 84338 | D19: 100365 | E19: 93691 | F19: 92466
A21: Net income | B21: 18986 | C21: 11037 | D21: -15014 | E21: -4534 | F21: -10997
A24: BALANCE SHEET - as reported (USD, end of year)
A25: Line item | B25: FY2021 | C25: FY2022 | D25: FY2023 | E25: FY2024 | F25: FY2025
A26: Assets
A27: Cash | B27: 32163 | C27: 39645 | D27: 23798 | E27: 24490 | F27: 17791
A28: Savings & temporary investments
A29: Accounts receivable
A30: Inventories
A31: Prepaid expenses
A32: Property, plant & equipment (gross)
A33: Less: accumulated depreciation
A34: Net property, plant & equipment
A35: Total assets | B35: 79748 | C35: 90785 | D35: 75771 | E35: 71237 | F35: 60240
A37: Liabilities
A38: Accounts payable
A39: Mortgages & notes payable
A40: Total liabilities | F40: 0
A42: Net Assets / Equity
A43: Capital stock
A44: Paid-in capital
A45: Retained earnings
A46: Net assets | B46: 79748 | C46: 90785 | D46: 75771 | E46: 71237 | F46: 60240
A49: CASH FLOW - derived proxy (USD)
...

Sheet Balance Sheet
A1: Santa Anita Mutual Water Company
A2: Balance Sheet - as reported (USD, end of year)
A3: Entity ID: cawc_0024 | Fiscal year ends January 31.
A5: Line item | B5: FY2021 | C5: FY2022 | D5: FY2023 | E5: FY2024 | F5: FY2025
A6: Assets
A7: Cash | B7: 32163 | C7: 39645 | D7: 23798 | E7: 24490 | F7: 17791
A8: Savings & temporary investments
A9: Accounts receivable
A10: Inventories
A11: Prepaid expenses
A12: Property, plant & equipment (gross)
A13: Less: accumulated depreciation
A14: Net property, plant & equipment
A15: Total assets | B15: 79748 | C15: 90785 | D15: 75771 | E15: 71237 | F15: 60240
A17: Liabilities
A18: Accounts payable
A19: Mortgages & notes payable
A20: Total liabilities | F20: 0
A22: Net Assets / Equity
A23: Capital stock
A24: Paid-in capital
A25: Retained earnings
A26: Net assets | B26: 79748 | C26: 90785 | D26: 75771 | E26: 71237 | F26: 60240
A28: Balance check (assets − liab. − net assets) | B28: 0 | C28: 0 | D28: 0 | E28: 0 | F28: 0
A30: Net PP&E is the reported ppe_net column (gross less accumulated depreciation). The balance check should be ~0 where all three totals are reported; a non-zero value flags a reporting or extraction discrepancy worth reviewing.

Sheet Form 990-EZ Parts I & II
A1: Santa Anita Mutual Water Company
A2: Form 990-EZ - Part I (revenue, expenses, net assets) and Part II (balance sheet), as filed (USD)
A3: Entity ID: cawc_0024 | Fiscal year ends January 31.
A5: Form 990-EZ line | B5: FY2021 | C5: FY2022 | D5: FY2023 | E5: FY2024 | F5: FY2025
A6: Revenue (Part I)
A7: 2. Program service revenue | B7: 108926 | C7: 98277 | D7: 85341 | E7: 89148 | F7: not reported
A8: 3. Membership dues and assessments | B8: not reported | C8: not reported | D8: not reported | E8: not reported | F8: 81460
A9: 4. Investment income | B9: 27 | C9: 15 | D9: 10 | E9: 9 | F9: not reported
A10: 8. Other revenue | B10: 1686 | C10: 225 | D10: not reported | E10: not reported | F10: 9
A11: 9. Total revenue | B11: 110639 | C11: 95375 | D11: 85351 | E11: 89157 | F11: 81469
A13: Expenses (Part I)
A14: 12. Salaries, other compensation, benefits | B14: 50983 | C14: 43491 | D14: 41944 | E14: 39779 | F14: 48229
A15: 13. Fees for services (independent contractors) | B15: 2235 | C15: 2298 | D15: 2400 | E15: 2508 | F15: 2540
A16: 16. Other expenses | B16: 38435 | C16: 38549 | D16: 56021 | E16: 51404 | F16: 41697
A17: 17. Total expenses | B17: =SUM(B14:B16) | C17: =SUM(C14:C16) | D17: =SUM(D14:D16) | E17: =SUM(E14:E16) | F17: =SUM(F14:F16)
A19: Net-assets reconciliation (Part I)
A20: 19. Net assets or fund balances, beginning of year | B20: 60762 | C20: 79748 | D20: 90785 | E20: 75771 | F20: 71237
A21: 18. Excess or (deficit) for the year | B21: 18986 | C21: 11037 | D21: -15014 | E21: -4534 | F21: -10997
A22: 21. Net assets or fund balances, end of year | B22: =SUM(B20,B21) | C22: =SUM(C20,C21) | D22: =SUM(D20,D21) | E22: =SUM(E20,E21) | F22: =SUM(F20,F21)
A24: Balance sheet (Part II, end of year - column B)
A25: 22. Cash, savings, and investments | B25: 32163 | C25: 39645 | D25: 23798 | E25: 24490 | F25: 17791
A26: 24. Other assets | B26: 47585 | C26: 51140 | D26: 51973 | E26: 46747 | F26: 42449
A27: 25. Total assets | B27: =SUM(B25:B26) | C27: =SUM(C25:C26) | D27: =SUM(D25:D26) | E27: =SUM(E25:E26) | F27: =SUM(F25:F26)
A28: 26. Total liabilities | B28: not reported | C28: not reported | D28: not reported | E28: not reported | F28: 0
A29: 27. Net assets or fund balances | B29: 79748 | C29: 90785 | D29: 75771 | E29: 71237 | F29: 60240
A31: Form 990-EZ is the short form: revenue and expenses are on Part I and the balance sheet is the six-line Part II (no full-990 Parts VII-XI). Total expenses (line 17) and Total assets (line 25) are live SUMs of the lines above; Total revenue (line 9) is shown as filed because the EZ nets its lines 5-7 (sales of assets, gaming, inventory) into line 9 without itemizing them. Ending net assets (line 21) is recomputed live as beginning net assets (line 19) plus the excess or deficit (line 18); where the filer's own line 21 does not equal that sum, the variance is flagged red on the Sources & audit tab and carried exactly as filed, not reconciled. Every figure's citation and confidence are on the Sources & audit tab.

Sheet Cash flow proxies
A1: Santa Anita Mutual Water Company
A2: Cash Flow Proxies - derived (USD)
A3: Entity ID: cawc_0024 | Fiscal year ends January 31.
A5: PROXY ONLY. The source filings contain no statement of cash flows. Lines below are derived from the reported income statement and year-over-year balance-sheet changes; treat as directional estimates, not GAAP cash flows. The earliest year has no prior period, so its delta cells are blank.
A7: Proxy line (USD) | B7: FY2021 | C7: FY2022 | D7: FY2023 | E7: FY2024 | F7: FY2025
A8: Operating
A9: Net income | B9: 18986 | C9: 11037 | D9: -15014 | E9: -4534 | F9: -10997
A10: + Depreciation (reported)
A11: − Δ Accounts receivable
A12: − Δ Inventories
A13: − Δ Prepaid expenses
A14: + Δ Accounts payable
A15: Operating cash flow proxy | C15: 11037 | D15: -15014 | E15: -4534 | F15: -10997
A17: Investing
A18: − Δ PP&E gross (capex proxy)
A20: Financing
A21: Δ Mortgages & notes payable
A23: Reconciliation
A24: Δ Cash + temp. investments (actual) | C24: 7482 | D24: -15847 | E24: 692 | F24: -6699
A26: The capex proxy assumes gross PP&E rises only via capital spending (it ignores disposals). 'Δ Cash + temp. investments (actual)' is the real reported change in liquid funds and is the most reliable line here; the operating/investing/financing proxies will not perfectly reconcile to it.

Sheet Ratios
A1: Santa Anita Mutual Water Company
A2: Financial Ratios
A3: Entity ID: cawc_0024 | Fiscal year ends January 31.
A5: Ratio | B5: FY2021 | C5: FY2022 | D5: FY2023 | E5: FY2024 | F5: FY2025
A6: Profitability (computed upstream)
A7: Operating margin (NI / revenue) | B7: 0.17160314 | C7: 0.11572215 | D7: -0.17590889 | E7: -0.050854111 | F7: -0.13498386
A8: Expense ratio (expenses / revenue) | B8: 0.82839686 | C8: 0.88427785 | D8: 1.1759089 | E8: 1.0508541 | F8: 1.1349839
A9: Return on assets (NI / assets) | B9: 0.23807494 | C9: 0.12157295 | D9: -0.19814969 | E9: -0.0636467 | F9: -0.18255312
A10: Revenue growth (YoY)
A12: Leverage & solvency
A13: Debt-to-assets (liab. / assets) | F13: 0
A14: Equity ratio (net assets / assets) | B14: 1 | C14: 1 | D14: 1 | E14: 1 | F14: 1
A16: Liquidity & asset profile (derived here)
A17: Current ratio (current assets / AP)
A18: Cash ratio ((cash+temp inv.) / total liab.)
A19: Asset age proxy (accum. deprec. / gross PP&E)
A21: Upstream ratios are read from financials_annual; derived ratios are computed only where inputs are reported. Current ratio uses accounts payable as the current-liability proxy (the filings do not split current vs. long-term liabilities). Asset age proxy: a higher % implies older / more depreciated infrastructure.

Sheet Unit economics
A1: Santa Anita Mutual Water Company
A2: Unit economics - per-customer revenue by category (USD)
A3: Entity ID: cawc_0024 | Fiscal year ends January 31.
A5: Every metric here is PER CUSTOMER (a metered service connection). It is not a per-member figure; the member (shareholder) count is a different denominator, shown in the denominator block. The visible cell shows the value and its classification; the numerator, denominator, formula, and rationale are in each metric's LOGIC popup.
A6: Per-customer denominator (service connections) | B6: 19 | C6: State Water Board eAR Section 4 (CurTotalConnections), reporting year 2023
A7: Total annual revenue (eAR Section 8b B1.8) | B7: 89148 | C7: State Water Board eAR Section 8b, question B1.8 (total annual revenue), reporting year 2023
A8: Primary source | C8: State Water Board eAR Section 8b (revenue by rate/fee), reporting year 2023
A10: Revenue categories (value, classification, per customer, share)
A11: Revenue category | B11: Classification | C11: Value (USD) | D11: Per customer | E11: Share of revenue
A12: Water sales revenue | B12: DIRECT | C12: 56443 | D12: 2970.68 | E12: 0.6331
A13: Assessment revenue (990 program-service revenue not matched to eAR water-rate revenue) | B13: DERIVED | C13: 32705 | D13: 1721.32 | E13: 0.3669
A14: Meter revenue | B14: not reported | C14: not reported | D14: not reported | E14: not reported
A15: Overage or tiered penalty revenue | B15: not reported | C15: not reported | D15: not reported | E15: not reported
A17: Water sales revenue - DIRECT
A18: Revenue customers paid for water service, read straight off the filed eAR Section 8b water-rate line. A DIRECT filed figure, not computed by us.
A19: Numerator: Water rate revenue | B19: 56443 | C19: eAR Section 8b field B1.1 (residential water rates) only (this filer reported no non-residential water-rate revenue). State Water Board eAR Section 8b, question B1.1 + B1.2 (revenue from water rates), reporting year 2023
A20: Denominator: Total service connections | B20: 19 | C20: eAR Section 4 CurTotalConnections, reporting year 2023. State Water Board eAR Section 4 (CurTotalConnections), reporting year 2023
A21: Per customer: water rate revenue $56,443 / 19 connections = $2,970.68 per connection
A22: Share of revenue: water rate revenue $56,443 / total annual revenue (eAR Section 8b B1.8) $89,148 = 63.31%
A23: Period treatment: Numerator (eAR Section 8b, the fiscal year ending January 31, 2024) and denominator (eAR Section 4 connections reported in the same eAR filing) are both the eAR reporting year 2023, so the two sides are bound to the same reporting year.
A24: Rationale: Dividing water-rate revenue by the number of metered service connections gives the average revenue per customer; dividing by total annual revenue shows how much of the system's income comes from water rates.
A26: Assessment revenue (990 program-service revenue not matched to eAR water-rate revenue) - DERIVED
A27: A DERIVED residual (medium confidence): the part of the Form 990 program-service revenue that is not matched by the eAR water-rate revenue for the same period. Computed by us, not a filed line.
A28: Input A: Form 990 program-service revenue | B28: 89148 | C28: Form 990 Part VIII line 2 (total program-service revenue), fiscal year 2024 ending January 31, 2024
A29: Input B: eAR water-rate revenue | B29: 56443 | C29: State Water Board eAR Section 8b, question B1.1 + B1.2 (revenue from water rates), reporting year 2023
A30: Residual (A minus B) = assessment revenue | B30: =B28-B29 | C30: $89,148 (990 program-service revenue) minus $56,443 (eAR water-rate revenue) = $32,705
A31: Period alignment: Both inputs cover the same period: the eAR Section 8b is the fiscal year ending January 31, 2024 and the Form 990 fiscal year 2024 ends January 31, 2024, so the residual is period-aligned.
A32: What it IS: revenue the system booked as program service on its 990 that is not accounted for by the eAR water-rate line, plausibly member assessments and other service revenue.
A33: This residual is a difference between two sources for the same period; it is not a separately filed assessment line and may include other unmatched revenue.
A34: Denominator: Total service connections | B34: 19 | C34: eAR Section 4 CurTotalConnections, reporting year 2023. State Water Board eAR Section 4 (CurTotalConnections), reporting year 2023
A35: Per customer: residual $32,705 / 19 connections = $1,721.32 per connection
A36: Share of revenue: residual $32,705 / 990 program-service revenue $89,148 = 36.69%
A38: Meter revenue - not reported
A39: Not reported. This category is not built because doing so would double-count.
A40: Reason: The eAR Section 8a reports a base/meter rate PRICE, but the filing carries no meter revenue line and no tier volume, and the base charge is already inside the water-sales revenue (eAR Section 8b water rates). Building a separate meter figure would double-count. Not backed into from a total.
A42: Overage or tiered penalty revenue - not reported
A43: Not reported. This category is not built because doing so would double-count.
A44: Reason: The eAR Section 8a reports tiered/overage rate PRICES, but the filing carries no overage revenue and no tier consumption volume, and any overage billed is already inside the water-sales revenue. Building it would double-count. Not backed into from a total.

Sheet Rate structure
A1: Santa Anita Mutual Water Company
A2: Rate structure and representative bill - eAR Section 8a (RY2024)
A3: Entity ID: cawc_0024 | Fiscal year ends January 31.
A5: This block is a rate-schedule illustration at defined usage levels. It is NOT billed revenue and not a claim about any real customer's usage. The revenue side of unit economics is the separate Unit Economics block.
A6: Structure: Tiered increasing-block with a fixed base, billed monthly, priced per Gallons. Rate schedule last updated 09/07/2024.
A7: Defined single-family usage levels, identical for every company so the bill is comparable: Low = 5 HCF/month (~125 gallons/day); Median = 10 HCF/month (~249 gallons/day); High = 25 HCF/month (~623 gallons/day). 1 HCF = 748 gallons, and 1 thousand gallons = 1,000 gallons. The usage is converted into the company's own filed unit before the filed tiers are applied, and the bill is stated as a monthly equivalent: a bimonthly structure is computed at twice the monthly usage and divided by two, and any other billing period the same way with its factor stated. These are an illustration, not a measured usage for any real customer.
A9: Defined usage levels (EDITABLE - change a yellow cell to move the bill)
B10: Low | C10: Median | D10: High
A11: Defined usage level (HCF per month) | B11: 5 | C11: 10 | D11: 25
A12: Conversion: one HCF is this many Gallons | B12: 748 | C12: 1 HCF = 748 gallons
A13: Monthly usage (Gallons) | B13: =B11*$B$12 | C13: =C11*$B$12 | D13: =D11*$B$12
A14: Months per bill (from filed billing frequency) | B14: 1 | C14: monthly biller
A16: Filed rate table - single-family residential (as filed, eAR Section 8a)
A17: Base / fixed charge per monthly bill ($) | B17: 0
A18: Tier | B18: Range (Gallons) | C18: Price ($/Gallons) | D18: Upper limit (Gallons)
A19: Tier 1 | B19: 0 to 650 Gallons | C19: 0.015 | D19: 650
A20: Tier 2 | B20: 650 to 1150 Gallons | C20: 0.045 | D20: 1150
A21: Tier 3 | B21: 1150 to 1650 Gallons | C21: 0.0675 | D21: 1650
A22: Tier 4 | B22: over 1650 Gallons | C22: 0.09 | D22: no limit
A24: Flags on the filed rate table (nothing below is corrected)
A25: Tier 3 price: implausible as filed; checked against source. The filed tier 3 price of $0.07 per unit implies $50.49 per HCF, outside the $0.50 to $50.00 per HCF range a residential water rate plausibly takes. Carried exactly as filed and not corrected. Source: State Water Board eAR Section 8 / WRSFUsageCost3
A26: Tier 4 price: implausible as filed; checked against source. The filed tier 4 price of $0.09 per unit implies $67.32 per HCF, outside the $0.50 to $50.00 per HCF range a residential water rate plausibly takes. Carried exactly as filed and not corrected. Source: State Water Board eAR Section 8 / WRSFUsageCost4
A27: Fixed charge: implausible as filed; checked against source. The filed base charge of $0.00 per bill is $0.00 per month, outside the $5.00 to $500.00 per month range a residential fixed charge plausibly takes. A filed $0.00 can simply mean the company charges no fixed charge. Carried exactly as filed and not corrected. Source: State Water Board eAR Section 8 / WRSFCostPerUOM1
A29: Representative monthly bill - LIVE (edit a yellow usage cell to recompute)
B30: Low | C30: Median | D30: High
A31: Usage per bill (Gallons) | B31: =B13*$B$14 | C31: =C13*$B$14 | D31: =D13*$B$14
A32: Tier 1 charge per bill ($) | B32: =$C$19*MAX(0,MIN(B31,$D$19)-0) | C32: =$C$19*MAX(0,MIN(C31,$D$19)-0) | D32: =$C$19*MAX(0,MIN(D31,$D$19)-0)
A33: Tier 2 charge per bill ($) | B33: =$C$20*MAX(0,MIN(B31,$D$20)-$D$19) | C33: =$C$20*MAX(0,MIN(C31,$D$20)-$D$19) | D33: =$C$20*MAX(0,MIN(D31,$D$20)-$D$19)
A34: Tier 3 charge per bill ($) | B34: =$C$21*MAX(0,MIN(B31,$D$21)-$D$20) | C34: =$C$21*MAX(0,MIN(C31,$D$21)-$D$20) | D34: =$C$21*MAX(0,MIN(D31,$D$21)-$D$20)
A35: Tier 4 charge per bill ($) | B35: =$C$22*MAX(0,B31-$D$21) | C35: =$C$22*MAX(0,C31-$D$21) | D35: =$C$22*MAX(0,D31-$D$21)
A36: Volumetric charge per bill ($) | B36: =SUM(B32,B33,B34,B35) | C36: =SUM(C32,C33,C34,C35) | D36: =SUM(D32,D33,D34,D35)
A37: Base charge per bill ($) | B37: =$B$17 | C37: =$B$17 | D37: =$B$17
A38: Total per bill ($) | B38: =B37+B36 | C38: =C37+C36 | D38: =D37+D36
A39: Total per MONTH ($) | B39: =B38/$B$14 | C39: =C38/$B$14 | D39: =D38/$B$14
A40: Fixed per month ($) | B40: =$B$17/$B$14 | C40: =$B$17/$B$14 | D40: =$B$17/$B$14
A41: Volumetric per month ($) | B41: =B36/$B$14 | C41: =C36/$B$14 | D41: =D36/$B$14
A42: Effective price ($/HCF) | B42: =IF(B11=0,"",B39/B11) | C42: =IF(C11=0,"",C39/C11) | D42: =IF(D11=0,"",D39/D11)
A44: Rate-structure comparison metrics
A45: Fixed share of the bill at median usage | B45: =C40/C39 | C45: fixed / total at 10 HCF/month
A46: Tier price ratio (highest to lowest positive tier) | B46: =$C$22/$C$19 | C46: highest filed tier price divided by lowest filed tier price.
...

Sheet eAR revenue & expenses
A1: Santa Anita Mutual Water Company
A2: eAR annual revenue and expenses - State Water Board eAR Section 8b (USD)
A3: Entity ID: cawc_0024 | Fiscal year ends January 31.
A5: The water system's own annual figures from the public eAR Section 8b, on the fiscal year ending January 31, 2024 the filer self-reported (B0.1/B0.2). Shown beside the period-aligned Form 990 with the variance flagged: a different source (a State Water Board self-report vs an IRS filing). Preserved as filed, never reconciled.
A6: Reporting period basis (self-reported) | B6: fiscal year ending January 31, 2024 | C6: eAR Section 8b B0.1 (WRFinancialReportingPeriod) / B0.2 start 02/01/2023
A8: Revenue (eAR Section 8b, questions B1.x)
A9: Line | B9: Amount (USD) | C9: Citation
A10: Water rate revenue | B10: 56443 | C10: State Water Board eAR Section 8b, question B1.1 + B1.2 (revenue from water rates), reporting year 2023
A11: Other fees and charges | B11: 32705 | C11: State Water Board eAR Section 8b, question B1.3 + B1.4 (revenue from other fees), reporting year 2023
A12: Non-customer revenue | B12: 0 | C12: State Water Board eAR Section 8b, question B1.7 (grants, interest, and other non-customer), reporting year 2023
A13: Total annual revenue | B13: 89148 | C13: State Water Board eAR Section 8b, question B1.8 (total annual revenue for the reporting year), reporting year 2023
A15: Expenses (eAR Section 8b, questions B2.x)
A16: Line | B16: Amount (USD) | C16: Citation
A17: Operations and maintenance | B17: 93362 | C17: State Water Board eAR Section 8b, question B2.1 (annual O and M expense), reporting year 2023
A18: Capital | B18: 0 | C18: State Water Board eAR Section 8b, question B2.2 (annual expenses from investing or capital), reporting year 2023
A19: Financing | B19: 0 | C19: State Water Board eAR Section 8b, question B2.3 (annual expenses from financing), reporting year 2023
A20: Other | B20: 0 | C20: State Water Board eAR Section 8b, question B2.4 (total other annual expenses), reporting year 2023
A21: Total annual expenses | B21: 93362 | C21: State Water Board eAR Section 8b, question B2.5 (total annual expenses), reporting year 2023
A23: Period-aligned Form 990 comparison (variance surfaced, never reconciled)
A24: Measure | B24: eAR Section 8b | C24: Form 990
A25: total revenue | B25: 89148 | C25: 89157
A26: Variance (eAR minus Form 990) | B26: =B25-C25
A27: The eAR Section 8b total revenue (State Water Board self-report, fiscal year ending January 31, 2024) and the Form 990 total revenue (IRS filing) are a different source and cover the same fiscal year (February 1, 2023 to January 31, 2024): the water system self-reported the eAR Section 8b on a fiscal year (B0.1 Fiscal, B0.2 start 02/01/2023), which matches the Form 990 fiscal year. Both are carried as filed; the variance is surfaced, never reconciled.
A28: total expenses | B28: 93362 | C28: 93691
A29: Variance (eAR minus Form 990) | B29: =B28-C28
A30: The eAR Section 8b total expenses (State Water Board self-report, fiscal year ending January 31, 2024) and the Form 990 total expenses (IRS filing) are a different source and cover the same fiscal year (February 1, 2023 to January 31, 2024): the water system self-reported the eAR Section 8b on a fiscal year (B0.1 Fiscal, B0.2 start 02/01/2023), which matches the Form 990 fiscal year. Both are carried as filed; the variance is surfaced, never reconciled.

Sheet Denominators & alignment
A1: Santa Anita Mutual Water Company
A2: Denominators and calendar alignment
A3: Entity ID: cawc_0024 | Fiscal year ends January 31.
A5: System size and water use per fiscal year (the operating denominators that per-customer and per-acre metrics divide by), each cited to file and field. The eAR is reported on the calendar year; the 990 fiscal year differs by company. A calendar-year filer's volume is the eAR annual total (fiscal year = calendar year); an offset filer's is recast by a true monthly sum of the covered calendar months, or read not reported naming the missing months. Point-in-time counts (connections, population) are matched to the closest eAR year and never summed. Every derived figure states its formula and accounting rationale.
A6: Member vs customer (two different denominators, both preserved)
A7: Customer (service connection) | B7: 19 | C7: State Water Board eAR Section 4 (CurTotalConnections), reporting year 2024
A8: SDWIS service-connection count (different registry) | B8: 19
A9: Member (shareholder) | C9: No published shareholder count
A10: In a mutual water company a MEMBER is a shareholder who owns part of the system; a CUSTOMER is a metered service connection that receives water. The two diverge because one owner can hold several connections, a connection can serve people who are not owners, and some mutuals attach shares to land by acreage rather than counting heads. Per-customer metrics divide by service connections; per-member metrics divide by shareholders; the two counts are never used interchangeably.
A12: Denominator layer by fiscal year
A13: Fiscal year (end) | B13: Connections | C13: Population | D13: Service-area acres | E13: Water produced (AF) | F13: Water delivered (AF) | G13: Alignment method
A14: FY2021 (2021-01-31) | B14: 19 | C14: not reported | D14: 1242.2 | E14: 11.9 | F14: 8.9 | G14: recast from monthly eAR data to fiscal year ending January 31, 2021
A15: FY2022 (2022-01-31) | B15: 19 | C15: not reported | D15: 1242.2 | E15: 16.8 | F15: 7.1 | G15: recast from monthly eAR data to fiscal year ending January 31, 2022
A16: FY2023 (2023-01-31) | B16: 19 | C16: not reported | D16: 1242.2 | E16: not reported | F16: not reported | G16: recast from monthly eAR data to fiscal year ending January 31, 2023
A17: FY2024 (2024-01-31) | B17: 19 | C17: 38 | D17: 1242.2 | E17: not reported | F17: not reported | G17: recast from monthly eAR data to fiscal year ending January 31, 2024
A18: FY2025 (2025-01-31) | B18: 19 | C18: 38 | D18: 1242.2 | E18: not reported | F18: not reported | G18: recast from monthly eAR data to fiscal year ending January 31, 2025
A20: Connections by class - FY2025 (eAR Section 4)
A21: Single-family residential | B21: 19
A22: Monthly-volume source: California open-data portal (data.ca.gov): the separate Produced Water (by month and source) and Delivered Water (by month and connection type) resources, which cover every public water system (not only urban suppliers), one resource per reporting year, matched by exact PWSID. This is the aggregate publication of eAR Section 6.

Sheet Governance evidence
A1: Santa Anita Mutual Water Company
A2: Governance evidence status - Ostrom's eight design principles
A3: Entity ID: cawc_0024 | Fiscal year ends January 31.
A5: Evidence summary: 4 documented, 2 partial, 2 not documented of eight principles.
A6: A count of how many of Elinor Ostrom's eight design principles have a supporting record on file, not a grade. NOT DOCUMENTED means the supporting record was not found, not that the company governs badly. It marks a gap in the documentary record, an evidence gap to close, never a governance failing.
A7: Each mutual is read against Elinor Ostrom's eight design principles for institutions that govern a shared resource durably. Per principle: a one-line finding, the observable signal, a citation, and an evidence status stating whether the supporting record exists: DOCUMENTED (a cited record supports alignment), PARTIAL (some evidence exists but it is incomplete), or NOT DOCUMENTED (no supporting record was found). This is an evidence-status read, not a grade: the principles are never ranked, weighted, or given a letter, consistent with reporting as filed and not grading companies. NOT DOCUMENTED means the supporting record was not found, not that the company governs badly. It marks a gap in the documentary record, an evidence gap to close, never a governance failing.
A9: Principle | B9: Evidence status | C9: Finding | D9: Signal | E9: Citation
A10: Clearly defined boundaries | B10: DOCUMENTED | C10: The system is a defined public water system: 19 service connections over a State-published service-area boundary. | D10: SDWIS Community water system; SABL service-area boundary (not verified (sabl)); connections defined. | E10: [C][G]
A11: What the record shows: SDWIS defines the membership as a fixed set of service connections and the State Water Board publishes a SABL service-area polygon, so who is inside and outside the system is documented. The boundary is Not Verified (SABL), so its outer edge rests on that State layer.
A12: Rules fit local conditions | B12: DOCUMENTED | C12: Charges are tied to service under a documented rate or share-based allocation rule reported to the State or set in the company's structure. | D12: eAR Section 8a customer charges; documented rate or share-allocation rule. | E12: [E][r1]
A13: What the record shows: The record documents how charges are set, whether a filed metered rate schedule or a share-and-acreage allocation, so cost tracks service. Whether every tier scales precisely with use is only partially visible at this scale, but a real cost-to-service rule is on record.
A14: Collective-choice arrangements | B14: PARTIAL | C14: As a mutual it is owned by its customer-shareholders who elect the board, but specific board membership and votes are not documented. | D14: Mutual (501(c)(12)) ownership structure; Form 990 governance section. | E14: [990][SOS]
A15: What the record shows: The mutual-company form documents that customers are shareholders who elect the directors, so a collective-choice mechanism exists on paper. No record of the specific board, elections, or member votes was found, so the evidence is partial. The specific board is now on the record: the Statement of Information filed 5/12/2026 names 8 directors and 4 officers, transcribed as filed. That closes one of the gaps named above. It does NOT close the others: a filed roster shows who governs, not how members choose them, and carries no election, turnout or member vote. The evidence status therefore stays PARTIAL, because what this principle asks about is member participation and that remains undocumented.
A16: Monitoring | B16: DOCUMENTED | C16: The system is metered and monitored: the State SAFER risk assessment shows it Not Failing, and it files an annual eAR. | D16: SAFER Not Failing; annual eAR reporting; metered connections. | E16: [S][E]
A17: What the record shows: Operational monitoring is documented: the State rates the system Not Failing on its drinking-water risk assessment and the system files an annual eAR. No independent audited financial statement is published, so financial monitoring is weaker, but the operational record is present.
A18: Graduated sanctions | B18: NOT DOCUMENTED | C18: No published shut-off, penalty, or delinquency policy was found for this system. | D18: No sourced sanctions policy. | E18: not reported
A19: What the record shows: No public record of a graduated shut-off or penalty policy was found for a system this small. NOT DOCUMENTED means the supporting record was not found, not that the company governs badly. It marks a gap in the documentary record, an evidence gap to close, never a governance failing.
A20: Conflict-resolution mechanisms | B20: NOT DOCUMENTED | C20: No published bylaws, dispute procedure, or grievance mechanism was found for this system. | D20: No sourced conflict-resolution record. | E20: not reported
A21: What the record shows: No public record of a member dispute or conflict-resolution procedure was found. NOT DOCUMENTED means the supporting record was not found, not that the company governs badly. It marks a gap in the documentary record, an evidence gap to close, never a governance failing.
A22: Recognized right to organize | B22: DOCUMENTED | C22: An incorporated California mutual water company recognized by the IRS (501(c)(12)) and by the State Water Board as a public water system. | D22: IRS 501(c)(12) exempt filer (Form 990); SDWIS public water system. | E22: [990][C][SOS]
A23: What the record shows: Baseline legal standing is documented: the company is an incorporated mutual recognized by the IRS as a tax-exempt filer and by the State Water Board as a regulated water system. This records the right to organize as a member entity, not a documented instance of exercising it. The California Secretary of State holds the company as a registered corporation, entity number 0981449, first registered 04/25/1980, status as filed "Active", with a governing body named in the Statement of Information filed 5/12/2026. That is a direct state record of the right to organize being recognized, so the evidence behind this status is now a filed corporate record rather than an inference from the company's tax form. The status was already DOCUMENTED and does not move.
A24: Nested enterprises | B24: PARTIAL | C24: The system draws on a shared local groundwater basin, embedding it in a larger physical water system, though its role in basin governance is not documented. | D24: SDWIS Primary Water Source Type: groundwater (shared basin). | E24: [C]
A25: What the record shows: The system relies on a shared groundwater basin, so it is physically nested in a larger hydrologic system. Its participation in a groundwater sustainability agency or basin governance is not documented, so the nesting evidence is partial.

Sheet Operational metrics
A1: Santa Anita Mutual Water Company
A2: Operational metrics - plant per acre, density, terrain
A3: Entity ID: cawc_0024 | Fiscal year ends January 31.
A5: Connections per acre
A6: Connections per acre | B6: 0.02 | C6: 20 connections / 1,242.2 acres. CA State Water Board SABL SERVICE_CONNECTIONS; Geodesic area (WGS84 spherical excess) of the SABL service-area polygon.
A8: Who they are
A9: Terrain class | B9: coastal terrace | C9: Company context page (BLUEPRINT 5B)
A10: A small domestic mutual water company (501(c)(12)) serving about 19 service connections and roughly 38 residents in the Hollister Ranch and Gaviota coast area of Santa Barbara County, on coastal terrace and rural ranch terrain.

Sheet Supply & weather
A1: Santa Anita Mutual Water Company
A2: Supply and weather indicators (DWR water year)
A3: Entity ID: cawc_0024 | Fiscal year ends January 31.
A5: Reporting calendar: Different reporting periods. The DWR water year runs October 1 to September 30; this system's fiscal year ends January 31, so the two period ends are four months apart. Read the two side by side with that in mind. Neither series is recast: both are reported as filed. A water year is named for the calendar year it ends in, so WY2024 and FY2024 share a number without covering the same twelve months.
A7: Indicator | B7: WY2021 | C7: WY2022 | D7: WY2023 | E7: WY2024 | F7: WY2025
A8: Water-year type (Sacramento Valley) | B8: Critical | C8: Critical | D8: Wet | E8: Above Normal | F8: not reported
A9: Peak drought, Santa Barbara County | B9: D4 | C9: D4 | D9: D3 | E9: None (no D0-D4 during the fiscal year) | F9: D3
A10: Precip, percent of normal (8-Station Index) | B10: 48 | C10: 86 | D10: 133 | E10: 96 | F10: 113
A11: Snowpack, April 1 percent of average | B11: 59% | C11: 38% | D11: 237% | E11: 110% | F11: 96%
A12: State Water Project allocation | B12: 5% | C12: 5% | D12: 100% | E12: 40% | F12: 50%

Sheet How this was built
A1: Santa Anita Mutual Water Company
A2: How this was built - forensic lineage
A3: Entity ID: cawc_0024 | Fiscal year ends January 31.
A5: A plain account of the forensic lineage behind the hard-to-source metrics: what sources were checked, what was found, what was derived, and what could not be built and why. Every figure marked DERIVED or IMPOSSIBLE above is traceable to a line here.
A7: Water-sales revenue per customer - DIRECT
A8: Sources checked | B8: State Water Board eAR Section 8b (water-rate revenue B1.1/B1.2); State Water Board eAR Section 4 (connection count, same reporting year); audited financial statement (secondary cross-check, where published)
A9: What was found | B9: The eAR Section 8b reports water-rate revenue for reporting year 2023, so this is a DIRECT filed figure; per customer it is divided by the eAR Section 4 connection count for the same reporting year, so numerator and denominator share the year.
A11: Assessment revenue (residual) - DERIVED
A12: Sources checked | B12: Form 990 Part VIII line 2 (program-service revenue); State Water Board eAR Section 8b (water-rate revenue B1.1/B1.2)
A13: What was found | B13: No source separately reports a member assessment, so it is DERIVED as a residual: $89,148 (990 program-service revenue) minus $56,443 (eAR water-rate revenue) = $32,705. Period-aligned; medium confidence.
A14: Caveat | B14: This residual is a difference between two sources for the same period; it is not a separately filed assessment line and may include other unmatched revenue.
A16: Meter revenue - not reported
A17: Sources checked | B17: State Water Board eAR Section 8a (rate prices); State Water Board eAR Section 8b (revenue lines); audited financial statement
A18: What was found | B18: The rate price exists in Section 8a but no revenue or tier volume is reported, and the base charge is already inside water sales.
A19: Caveat | B19: The eAR Section 8a reports a base/meter rate PRICE, but the filing carries no meter revenue line and no tier volume, and the base charge is already inside the water-sales revenue (eAR Section 8b water rates). Building a separate meter figure would double-count. Not backed into from a total.
A21: Overage / tiered-penalty revenue - not reported
A22: Sources checked | B22: State Water Board eAR Section 8a (rate prices); State Water Board eAR Section 8b (revenue lines); audited financial statement
A23: What was found | B23: The rate price exists in Section 8a but no revenue or tier volume is reported, and the base charge is already inside water sales.
A24: Caveat | B24: The eAR Section 8a reports tiered/overage rate PRICES, but the filing carries no overage revenue and no tier consumption volume, and any overage billed is already inside the water-sales revenue. Building it would double-count. Not backed into from a total.
A26: eAR Section 8b reporting-period basis - sourced
A27: Sources checked | B27: eAR Section 8b B0.1 (WRFinancialReportingPeriod); eAR Section 8b B0.2 (WRFiscalYearStartDate)
A28: What was found | B28: The reporting basis (fiscal vs calendar year) is read from the filer's own B0.1/B0.2 answer and staged verbatim, never hardcoded, so the 990 comparison and the residual are period-aligned.
A30: Member (shareholder) count denominator - not reported
A31: Sources checked | B31: Form 990 (no member count stated); company website
A32: What was found | B32: No filing states a member/shareholder count, so the per-member unit economics read not reported rather than borrowing the connection count.
A34: Water volume delivered (acre-feet) - not reported
A35: Sources checked | B35: Form 990 (not in the filing); Consumer Confidence Report; eAR Section 6 (PRA-gated)
A36: What was found | B36: Volume delivered in acre-feet is not in the Form 990 and the CCR states only a source mix, so the per-acre-foot metrics read not reported; the eAR Section 6 is named as the source still needed.

Sheet Water Operations
A1: Santa Anita Mutual Water Company
A2: Water Operations (sourced outside the financial filings)
A3: Entity ID: cawc_0024 | Fiscal year ends January 31.
A5: A separate dialect of data from the financial statements: the system's water supply, from the California State Water Board records (the Consumer Confidence Report served by the eAR portal, and SDWIS Drinking Water Watch). Each field carries its source, year, and confidence the same way a financial line item does; a field the source does not state reads 'not reported' with the source still needed. Figures are as reported, never estimated or reconciled across sources.
A7: Field | B7: Value | C7: Source | D7: Year | E7: Confidence | F7: Source excerpt / cross-source note
A8: Water type | B8: Potable (community drinking water) | C8: SDWIS Drinking Water Watch (State Water Board) | D8: 2024 | E8: high | F8: SANTA ANITA MUTUAL WATER COMPANY: State Water System Type = Community.
A9: Source mix | B9: Primary source: local groundwater wells (SDWIS Primary Water Source Type: Groundwater). SDWIS classifies the primary supply type; it states no acre-foot volume by source. | C9: SDWIS Drinking Water Watch (State Water Board) | D9: 2024 | E9: high | F9: SANTA ANITA MUTUAL WATER COMPANY: Primary Water Source Type = Groundwater.
A10: Service connections (total) | B10: 19 connections | C10: SDWIS Drinking Water Watch (State Water Board) | D10: 2024 | E10: high | F10: SANTA ANITA MUTUAL WATER COMPANY: Total Number of Service Connections = 19. [cross-source: SDWIS connection snapshot; the eAR reports active service connections on its own basis and per reporting year. Both preserved, not reconciled.]
A11: Connections by class | B11: Service connections by type (SDWIS snapshot): Residential 19; Total 19. | C11: SDWIS Drinking Water Watch (State Water Board) | D11: 2024 | E11: high | F11: SANTA ANITA MUTUAL WATER COMPANY: connections by type - Residential 19; Total 19.
A12: Population served | B12: 38 residents | C12: SDWIS Drinking Water Watch (State Water Board) | D12: 2024 | E12: high | F12: SANTA ANITA MUTUAL WATER COMPANY: Total Population = 38.
A13: Treatment and water quality | B13: Operator certification on file: Treatment or distribution operator of any grade; Distribution Operator Level 1. SDWIS states operator grades, not the treatment process detail. | C13: SDWIS Drinking Water Watch (State Water Board) | D13: 2024 | E13: high | F13: SANTA ANITA MUTUAL WATER COMPANY: Treatment Plant Class = Treatment or distribution operator of any grade; Distribution System Class = Distribution Operator Level 1.
A15: Not reported (source still needed)
A16: Annual volume delivered (acre-feet) | B16: not reported - needs annual volume in acre-feet (State Water Board eAR Section 6 or company production records); the CCR states only a percentage mix
A17: Customer classes served | B17: not reported - needs the State Water Board eAR or the system CCR

Sheet Sources & audit
A1: Santa Anita Mutual Water Company
A2: Sources & audit - full provenance and tie-outs (kept off the statements so they read clean)
A3: Entity ID: cawc_0024 | Fiscal year ends January 31.
A5: Presentation standard: every figure on the statement tabs is verified to its source filing and shown clean. A cell the filing does not report reads "not reported" (never estimated, never guessed).
A6: Citations, confidence tiers, and the filed-vs-computed tie-out checks live on the "Sources & audit" tab, keyed by cell, so every number is fully traceable without cluttering the statements. These pages are ready to use as filed.
A8: A. Filing provenance (one row per staged extraction)
A9: Fiscal year | B9: Period end | C9: Filing type | D9: Confidence | E9: Extraction ID | F9: Object ID | G9: Extracted by | H9: Extracted at | I9: Source URL
A10: FY2021 | B10: 2021-01-31 | C10: 990-EZ | D10: high | E10: f0ae169b-26ab-4132-bc10-f68bd6eb5c50 | F10: 202111399349200631 | G10: claude-opus-5 | H10: 2026-09-14T20:40:24+00:00 | I10: https://apps.irs.gov/pub/epostcard/990/xml/2021/2021_TEOS_XML_01A.zip#202111399349200631_public.xml
A11: FY2022 | B11: 2022-01-31 | C11: 990-EZ | D11: high | E11: 606b2fd5-df0b-42ff-b8a0-4f2dcd504c18 | F11: 202201239349201580 | G11: claude-opus-5 | H11: 2026-09-14T20:40:24+00:00 | I11: https://apps.irs.gov/pub/epostcard/990/xml/2022/2022_TEOS_XML_01A.zip#202201239349201580_public.xml
A12: FY2023 | B12: 2023-01-31 | C12: 990-EZ | D12: high | E12: 62f502be-48a7-440a-838a-958d5c873a19 | F12: 202301359349205400 | G12: claude-opus-5 | H12: 2026-09-14T20:40:24+00:00 | I12: https://apps.irs.gov/pub/epostcard/990/xml/2023/2023_TEOS_XML_05A.zip#202301359349205400_public.xml
A13: FY2024 | B13: 2024-01-31 | C13: 990-EZ | D13: high | E13: f7bf6d9c-9094-4f1a-8e46-73544e02b28a | F13: 202400889349200335 | G13: claude-opus-5 | H13: 2026-09-14T20:40:24+00:00 | I13: https://apps.irs.gov/pub/epostcard/990/xml/2024/2024_TEOS_XML_04A.zip#202400889349200335_public.xml
A14: FY2025 | B14: 2025-01-31 | C14: 990-EZ | D14: high | E14: fcf68488-69c6-474e-9639-f95bf646abef | F14: 202501349349202495 | G14: claude-opus-5 | H14: 2026-09-14T20:40:24+00:00 | I14: https://apps.irs.gov/pub/epostcard/990/xml/2025/2025_TEOS_XML_05A.zip#202501349349202495_public.xml
A16: B. Figure citations (every figure on the statement tabs, keyed by cell)
A17: Tab | B17: Cell | C17: Line item | D17: Form 990 line | E17: Key path | F17: Confidence | G17: As filed
A18: Form 990-EZ Parts I & II | B18: B7 | C18: 2. Program service revenue | D18: Part I line 2 | E18: part_i_revenue_expenses.program_service_revenue | F18: high | G18: 108926
A19: Form 990-EZ Parts I & II | B19: C7 | C19: 2. Program service revenue | D19: Part I line 2 | E19: part_i_revenue_expenses.program_service_revenue | F19: high | G19: 98277
A20: Form 990-EZ Parts I & II | B20: D7 | C20: 2. Program service revenue | D20: Part I line 2 | E20: part_i_revenue_expenses.program_service_revenue | F20: high | G20: 85341
A21: Form 990-EZ Parts I & II | B21: E7 | C21: 2. Program service revenue | D21: Part I line 2 | E21: part_i_revenue_expenses.program_service_revenue | F21: high | G21: 89148
A22: Form 990-EZ Parts I & II | B22: F8 | C22: 3. Membership dues and assessments | D22: Part I line 3 | E22: part_i_revenue_expenses.membership_dues | F22: high | G22: 81460
A23: Form 990-EZ Parts I & II | B23: B9 | C23: 4. Investment income | D23: Part I line 4 | E23: part_i_revenue_expenses.investment_income | F23: high | G23: 27
A24: Form 990-EZ Parts I & II | B24: C9 | C24: 4. Investment income | D24: Part I line 4 | E24: part_i_revenue_expenses.investment_income | F24: high | G24: 15
A25: Form 990-EZ Parts I & II | B25: D9 | C25: 4. Investment income | D25: Part I line 4 | E25: part_i_revenue_expenses.investment_income | F25: high | G25: 10
A26: Form 990-EZ Parts I & II | B26: E9 | C26: 4. Investment income | D26: Part I line 4 | E26: part_i_revenue_expenses.investment_income | F26: high | G26: 9
A27: Form 990-EZ Parts I & II | B27: B10 | C27: 8. Other revenue | D27: Part I line 8 | E27: part_i_revenue_expenses.other_revenue_total | F27: high | G27: 1686
A28: Form 990-EZ Parts I & II | B28: C10 | C28: 8. Other revenue | D28: Part I line 8 | E28: part_i_revenue_expenses.other_revenue_total | F28: high | G28: 225
A29: Form 990-EZ Parts I & II | B29: F10 | C29: 8. Other revenue | D29: Part I line 8 | E29: part_i_revenue_expenses.other_revenue_total | F29: high | G29: 9
... A75: Form 990-EZ Parts I & II | B75: F29 | C75: 27. Net assets or fund balances | D75: Part II line 27 col B | E75: part_ii_balance_sheet.net_assets_eoy | F75: high | G75: 60240
A77: C. Tie-out checks (filed vs computed; any nonzero variance is flagged red)
A78: Tab | B78: Check | C78: Fiscal year | D78: Filed | E78: Computed | F78: Variance (computed - filed)
A79: Form 990-EZ Parts I & II | B79: 17. Total expenses | C79: FY2021 | D79: 91653 | E79: ='Form 990-EZ Parts I & II'!B17 | F79: =E79-D79
A80: Form 990-EZ Parts I & II | B80: 17. Total expenses | C80: FY2022 | D80: 84338 | E80: ='Form 990-EZ Parts I & II'!C17 | F80: =E80-D80
A81: Form 990-EZ Parts I & II | B81: 17. Total expenses | C81: FY2023 | D81: 100365 | E81: ='Form 990-EZ Parts I & II'!D17 | F81: =E81-D81
A82: Form 990-EZ Parts I & II | B82: 17. Total expenses | C82: FY2024 | D82: 93691 | E82: ='Form 990-EZ Parts I & II'!E17 | F82: =E82-D82
A83: Form 990-EZ Parts I & II | B83: 17. Total expenses | C83: FY2025 | D83: 92466 | E83: ='Form 990-EZ Parts I & II'!F17 | F83: =E83-D83
A84: Form 990-EZ Parts I & II | B84: 21. Net assets or fund balances, end of year | C84: FY2021 | D84: 79748 | E84: ='Form 990-EZ Parts I & II'!B22 | F84: =E84-D84
A85: Form 990-EZ Parts I & II | B85: 21. Net assets or fund balances, end of year | C85: FY2022 | D85: 90785 | E85: ='Form 990-EZ Parts I & II'!C22 | F85: =E85-D85
A86: Form 990-EZ Parts I & II | B86: 21. Net assets or fund balances, end of year | C86: FY2023 | D86: 75771 | E86: ='Form 990-EZ Parts I & II'!D22 | F86: =E86-D86
A87: Form 990-EZ Parts I & II | B87: 21. Net assets or fund balances, end of year | C87: FY2024 | D87: 71237 | E87: ='Form 990-EZ Parts I & II'!E22 | F87: =E87-D87
A88: Form 990-EZ Parts I & II | B88: 21. Net assets or fund balances, end of year | C88: FY2025 | D88: 60240 | E88: ='Form 990-EZ Parts I & II'!F22 | F88: =E88-D88
A89: Form 990-EZ Parts I & II | B89: 25. Total assets | C89: FY2021 | D89: 79748 | E89: ='Form 990-EZ Parts I & II'!B27 | F89: =E89-D89
...

Sheet Provenance
A1: Build provenance | B1: Built from source commit d418ffb17485 (2026-10-06); source fingerprint a75a8eee82c65cf7; 192 companies (179 retail mutual, 4 irrigation mutual, 3 mutual, no PWSID, purpose not stated, 2 frozen non-mutual (special district), 2 wholesale mutual, 1 frozen non-mutual (investor-owned), 1 frozen non-mutual (municipal)); 91 gates; build id 3d08d6d2a855.
A2: source_commit | B2: d418ffb174855ab78000d391d42f898397b0d8aa
A3: source_commit_date | B3: 2026-10-06
A4: source_fingerprint | B4: a75a8eee82c65cf7096931f06e18affdc28686a02895b46538e7298b57c04d94
A5: gate_count | B5: 91
A6: build_id | B6: 3d08d6d2a855
A7: registry: frozen non-mutual (investor-owned) | B7: 1
A8: registry: frozen non-mutual (municipal) | B8: 1
A9: registry: frozen non-mutual (special district) | B9: 2
A10: registry: irrigation mutual | B10: 4
A11: registry: mutual, no PWSID, purpose not stated | B11: 3
A12: registry: retail mutual | B12: 179
A13: registry: wholesale mutual | B13: 2
