Workbook

Sheet Summary
A1: Sunny Slope Water Company
A2: Financial Summary - multi-year overview (USD)
A3: Entity ID: cawc_0033 | Fiscal year ends December 31.
A5: Presentation standard: every figure on the statement tabs is verified to its source filing and shown clean. A cell the filing does not report reads "not reported" (never estimated, never guessed).
A6: Citations, confidence tiers, and the filed-vs-computed tie-out checks live on the "Sources & audit" tab, keyed by cell, so every number is fully traceable without cluttering the statements. These pages are ready to use as filed.
A8: Metric | B8: FY2020 | C8: FY2021 | D8: FY2022 | E8: FY2023 | F8: FY2024
A9: Operating results (USD)
A10: Total revenue | B10: 5950902 | C10: 10112414 | D10: 6811105 | E10: 6585472 | F10: 7117630
A11: Total expenses | B11: 4749900 | C11: 5116557 | D11: 5116592 | E11: 5094873 | F11: 5197001
A12: Net income | B12: 1201002 | C12: 4995857 | D12: 1694513 | E12: 1490599 | F12: 1920629
A14: Financial position (USD, end of year)
A15: Total assets | B15: 25694945 | C15: 31584980 | D15: 32249066 | E15: 33745190 | F15: 35866460
A16: Total liabilities | B16: 755923 | C16: 1482563 | D16: 2271389 | E16: 1772893 | F16: 1627427
A17: Net assets | B17: 24939022 | C17: 30102417 | D17: 29977677 | E17: 31972297 | F17: 34239033
A19: Headline ratios
A20: Operating margin | B20: 0.20181848 | C20: 0.49403209 | D20: 0.2487868 | E20: 0.22634657 | F20: 0.26984108
A21: Revenue growth (YoY) | B21: 0.054597917 | C21: 0.69930777 | D21: -0.32646102 | E21: -0.033127224 | F21: 0.080807875
A22: Return on assets | B22: 0.046740789 | C22: 0.15817192 | D22: 0.052544561 | E22: 0.044172192 | F22: 0.053549444
A24: Figures as reported in source filings (full provenance on the Sources & audit tab). Parentheses denote negatives; ratios are computed upstream in financials_annual.

Sheet Notes
A1: Notes
A2: Human annotations from the versioned store (data/notes/). Annotations only: they never change a reported figure or a confidence tier.
A4: Date | B4: Tag | C4: Author | D4: Note
A5: No notes recorded yet.

Sheet Financial Statements
A1: Sunny Slope Water Company
A2: Financial Statements - income statement, balance sheet, cash flow, member income test (USD)
A3: Entity ID: cawc_0033 | Fiscal year ends December 31.
A5: INCOME STATEMENT - as reported (USD)
A6: Line item | B6: FY2020 | C6: FY2021 | D6: FY2022 | E6: FY2023 | F6: FY2024
A7: Revenue
A8: Program service revenue | B8: 5572638 | C8: 6055746 | D8: 6044091 | E8: 6034077 | F8: 6503705
A9: Investment income | B9: 150813 | C9: 277195 | D9: 322028 | E9: 349489 | F9: 356537
A10: Net rental income | B10: 25169 | C10: 21050 | D10: 22390 | E10: 20713 | F10: 12524
A11: Net gain/(loss) on investment sales | B11: 0 | C11: 0 | D11: 0 | E11: 0 | F11: 0
A12: Other revenue | B12: 0 | C12: 3614268 | D12: 1440 | E12: 0 | F12: 0
A13: Contributions & grants | B13: 202282 | C13: 144155 | D13: 421156 | E13: 181193 | F13: 244864
A14: Total revenue | B14: 5950902 | C14: 10112414 | D14: 6811105 | E14: 6585472 | F14: 7117630
A16: Expenses
A17: Depreciation | B17: 814040 | C17: 811593 | D17: 881236 | E17: 994003 | F17: 992344
A18: Interest expense | B18: 0 | C18: 0 | D18: 19871 | E18: 90575 | F18: 52204
A19: Total expenses | B19: 4749900 | C19: 5116557 | D19: 5116592 | E19: 5094873 | F19: 5197001
A21: Net income | B21: 1201002 | C21: 4995857 | D21: 1694513 | E21: 1490599 | F21: 1920629
A24: BALANCE SHEET - as reported (USD, end of year)
A25: Line item | B25: FY2020 | C25: FY2021 | D25: FY2022 | E25: FY2023 | F25: FY2024
A26: Assets
A27: Cash | B27: 0 | C27: 0 | D27: 0 | E27: 0 | F27: 0
A28: Savings & temporary investments | B28: 7362093 | C28: 12094085 | D28: 8538549 | E28: 9602070 | F28: 11385262
A29: Accounts receivable | B29: 695780 | C29: 763711 | D29: 843646 | E29: 885008 | F29: 897819
A30: Inventories | B30: 127331 | C30: 127884 | D30: 134215 | E30: 139531 | F30: 141813
A31: Prepaid expenses | B31: 106209 | C31: 120518 | D31: 124986 | E31: 142230 | F31: 155316
A32: Property, plant & equipment (gross) | B32: 23777034 | C32: 24533624 | D32: 31067930 | E32: 32593392 | F32: 33950492
A33: Less: accumulated depreciation | B33: -9485897 | C33: -10297490 | D33: -11133000 | E33: -12119593 | F33: -13106997
A34: Net property, plant & equipment | B34: 14291137 | C34: 14236134 | D34: 19934930 | E34: 20473799 | F34: 20843495
A35: Total assets | B35: 25694945 | C35: 31584980 | D35: 32249066 | E35: 33745190 | F35: 35866460
A37: Liabilities
A38: Accounts payable | B38: 546240 | C38: 1248168 | D38: 648797 | E38: 622103 | F38: 1390503
A39: Mortgages & notes payable
A40: Total liabilities | B40: 755923 | C40: 1482563 | D40: 2271389 | E40: 1772893 | F40: 1627427
A42: Net Assets / Equity
A43: Capital stock | B43: 130000 | C43: 130000 | D43: 130000 | E43: 130000 | F43: 130000
A44: Paid-in capital
A45: Retained earnings | B45: 24809022 | C45: 29972417 | D45: 29847677 | E45: 31842297 | F45: 34109033
A46: Net assets | B46: 24939022 | C46: 30102417 | D46: 29977677 | E46: 31972297 | F46: 34239033
A49: CASH FLOW - derived proxy (USD)
...

Sheet Balance Sheet
A1: Sunny Slope Water Company
A2: Balance Sheet - as reported (USD, end of year)
A3: Entity ID: cawc_0033 | Fiscal year ends December 31.
A5: Line item | B5: FY2020 | C5: FY2021 | D5: FY2022 | E5: FY2023 | F5: FY2024
A6: Assets
A7: Cash | B7: 0 | C7: 0 | D7: 0 | E7: 0 | F7: 0
A8: Savings & temporary investments | B8: 7362093 | C8: 12094085 | D8: 8538549 | E8: 9602070 | F8: 11385262
A9: Accounts receivable | B9: 695780 | C9: 763711 | D9: 843646 | E9: 885008 | F9: 897819
A10: Inventories | B10: 127331 | C10: 127884 | D10: 134215 | E10: 139531 | F10: 141813
A11: Prepaid expenses | B11: 106209 | C11: 120518 | D11: 124986 | E11: 142230 | F11: 155316
A12: Property, plant & equipment (gross) | B12: 23777034 | C12: 24533624 | D12: 31067930 | E12: 32593392 | F12: 33950492
A13: Less: accumulated depreciation | B13: -9485897 | C13: -10297490 | D13: -11133000 | E13: -12119593 | F13: -13106997
A14: Net property, plant & equipment | B14: 14291137 | C14: 14236134 | D14: 19934930 | E14: 20473799 | F14: 20843495
A15: Total assets | B15: 25694945 | C15: 31584980 | D15: 32249066 | E15: 33745190 | F15: 35866460
A17: Liabilities
A18: Accounts payable | B18: 546240 | C18: 1248168 | D18: 648797 | E18: 622103 | F18: 1390503
A19: Mortgages & notes payable
A20: Total liabilities | B20: 755923 | C20: 1482563 | D20: 2271389 | E20: 1772893 | F20: 1627427
A22: Net Assets / Equity
A23: Capital stock | B23: 130000 | C23: 130000 | D23: 130000 | E23: 130000 | F23: 130000
A24: Paid-in capital
A25: Retained earnings | B25: 24809022 | C25: 29972417 | D25: 29847677 | E25: 31842297 | F25: 34109033
A26: Net assets | B26: 24939022 | C26: 30102417 | D26: 29977677 | E26: 31972297 | F26: 34239033
A28: Balance check (assets − liab. − net assets) | B28: 0 | C28: 0 | D28: 0 | E28: 0 | F28: 0
A30: Net PP&E is the reported ppe_net column (gross less accumulated depreciation). The balance check should be ~0 where all three totals are reported; a non-zero value flags a reporting or extraction discrepancy worth reviewing.

Sheet Officers & contractors
A1: Sunny Slope Water Company
A2: Officers, Directors & Contractors - Form 990 Part VII (FY2024; USD)
A3: Entity ID: cawc_0033 | Fiscal year ends December 31.
A5: Section A - Officers, directors, trustees, key employees
A6: Name | B6: Title | C6: Reportable comp (org) | D6: Reportable comp (related) | E6: Other comp | F6: Total compensation
A7: KENNETH TCHENG | B7: GENERAL MANEGER | C7: 255922 | D7: 0 | E7: 15473 | F7: 271395
A8: TROY HOLLAND | B8: SUPERINTENDENT | C8: 130809 | D8: 0 | E8: 0 | F8: 130809
A9: JOHN L SHAW | B9: Treasurer | C9: 15000 | D9: 0 | E9: 0 | F9: 15000
A10: PETER C JEONG | B10: Secretary | C10: 10900 | D10: 0 | E10: 0 | F10: 10900
A11: LAP T NG | B11: President | C11: 10300 | D11: 0 | E11: 0 | F11: 10300
A12: STEVEN R SEILER | B12: Director | C12: 10000 | D12: 0 | E12: 0 | F12: 10000
A13: MARK J SEDLACEK | B13: Vice President | C13: 4800 | D13: 0 | E13: 0 | F13: 4800
A15: Section B - Independent contractors (over $100,000)
A16: Contractor | B16: Services | C16: Compensation
A18: Section A lists every officer, director, trustee and key employee filed for the latest year; the two with the highest total compensation are highlighted. Total compensation is computed (reportable org + related + other). Section B lists each independent contractor paid over $100,000; the return reports 0 such contractor(s). Source and confidence for every figure are on the Sources & audit tab.

Sheet Revenue (detail)
A1: Sunny Slope Water Company
A2: Revenue - Form 990 Part VIII (USD)
A3: Entity ID: cawc_0033 | Fiscal year ends December 31.
A5: Part VIII line | B5: FY2020 | C5: FY2021 | D5: FY2022 | E5: FY2023 | F5: FY2024
A6: Revenue by category
A7: 1h. Total contributions, gifts, grants | B7: 202282 | C7: 144155 | D7: 421156 | E7: 181193 | F7: 244864
A8: 2g. Total program service revenue | B8: 5572638 | C8: 6055746 | D8: 6044091 | E8: 6034077 | F8: 6503705
A9: 3. Investment income | B9: 150813 | C9: 277195 | D9: 322028 | E9: 349489 | F9: 356537
A10: 6d. Net rental income | B10: 25169 | C10: 21050 | D10: 22390 | E10: 20713 | F10: 12524
A11: 7d. Net gain/(loss) from investment sales | B11: 0 | C11: 0 | D11: 0 | E11: 0 | F11: 0
A12: 11e. Other revenue | B12: 0 | C12: 3614268 | D12: 1440 | E12: 0 | F12: 0
A13: 12. Total revenue | B13: =SUM(B7:B12) | C13: =SUM(C7:C12) | D13: =SUM(D7:D12) | E13: =SUM(E7:E12) | F13: =SUM(F7:F12)
A15: Program service revenue detail - FY2024 (lines 2a-2f)
A16: Description | B16: Business code | C16: Total revenue
A17: COMMERCIAL RATE NON STCK | B17: 221000 | C17: 648436
A18: MINIMUM RATE | B18: 221000 | C18: 2026073
A19: RESIDENTIAL - NON STOCK | B19: 221000 | C19: 1527130
A20: RESIDENTIAL - STOCK | B20: 221000 | C20: 1375222
A21: SPECIAL SURCHARGE | B21: 221000 | C21: 458699
A22: Revenue category subtotals are as filed. Total revenue (line 12) is a live SUM of the category cells above; its tie-out to the filed total is on the Sources & audit tab. Program service revenue detail is shown for the latest year, with its sum-to-line-2g check on that same audit tab.

Sheet Operating expenses (detail)
A1: Sunny Slope Water Company
A2: Statement of Functional Expenses - Form 990 Part IX (USD)
A3: Entity ID: cawc_0033 | Fiscal year ends December 31.
A5: Part IX line (column A Total) | B5: FY2020 | C5: FY2021 | D5: FY2022 | E5: FY2023 | F5: FY2024
A6: Functional expenses, column A Total - by year
A7: 1. Grants to domestic organizations and governments | B7: 0 | C7: 0 | D7: 0 | E7: 0 | F7: 0
A8: 2. Grants to domestic individuals | B8: 0 | C8: 0 | D8: 0 | E8: 0 | F8: 0
A9: 3. Grants to foreign organizations and individuals | B9: 0 | C9: 0 | D9: 0 | E9: 0 | F9: 0
A10: 4. Benefits paid to or for members | B10: 0 | C10: 0 | D10: 0 | E10: 0 | F10: 0
A11: 5. Compensation of current officers, directors, trustees | B11: 380702 | C11: 371733 | D11: 393211 | E11: 408170 | F11: 306922
A12: 6. Compensation to disqualified persons | B12: 0 | C12: 0 | D12: 0 | E12: 0 | F12: 0
A13: 7. Other salaries and wages | B13: 767871 | C13: 776422 | D13: 628128 | E13: 589908 | F13: 731922
A14: 8. Pension plan accruals and contributions | B14: 0 | C14: 0 | D14: 0 | E14: 0 | F14: 0
A15: 9. Other employee benefits | B15: 241833 | C15: 241146 | D15: 221564 | E15: 208301 | F15: 220866
A16: 10. Payroll taxes | B16: 89183 | C16: 90046 | D16: 92332 | E16: 89135 | F16: 89471
A17: 11a. Fees for services: management | B17: 0 | C17: 0 | D17: 0 | E17: 0 | F17: 0
A18: 11b. Fees for services: legal | B18: 15020 | C18: 25225 | D18: 15075 | E18: 15000 | F18: 15000
... A36: 24. SOURCE OF SUPPLY | B36: 1064200 | C36: 1263581 | D36: 961309 | E36: 607523 | F36: 705572
A37: 24. PURCHASED POWER | B37: 480322 | C37: 555812 | D37: not reported | E37: not reported | F37: not reported
A38: 24. MATERIALS AND SERVICES | B38: 376708 | C38: 377642 | D38: not reported | E38: not reported | F38: 179659
A39: 24. REPAIRS AND MAINTENANCE | B39: 92733 | C39: 73098 | D39: not reported | E39: not reported | F39: not reported
A40: 24. PUMPING AND POWER | B40: not reported | C40: not reported | D40: 641005 | E40: 682755 | F40: 800925
A41: 24. TRANSMISSION AND DISTRIBUTION | B41: not reported | C41: not reported | D41: 402082 | E41: 502413 | F41: 423199
A42: 24. PURIFICATION | B42: not reported | C42: not reported | D42: 220203 | E42: 206395 | F42: not reported
A43: 24e. All other expenses | B43: 239319 | C43: 290942 | D43: 398509 | E43: 399466 | F43: 427886
A44: 25. Total functional expenses | B44: =SUM(B7:B43) | C44: =SUM(C7:C43) | D44: =SUM(D7:D43) | E44: =SUM(E7:E43) | F44: =SUM(F7:F43)
A46: Functional column split - FY2024 (col A = B + C + D)
A47: Part IX line | B47: A. Total | C47: B. Program services | D47: C. Management & general | E47: D. Fundraising
A48: 1. Grants to domestic organizations and governments | B48: 0
A49: 2. Grants to domestic individuals | B49: 0
A50: 3. Grants to foreign organizations and individuals | B50: 0
A51: 4. Benefits paid to or for members | B51: 0
A52: 5. Compensation of current officers, directors, trustees | B52: 306922 | C52: 306922
A53: 6. Compensation to disqualified persons | B53: 0
A54: 7. Other salaries and wages | B54: 731922 | C54: 731922
A55: 8. Pension plan accruals and contributions | B55: 0
A56: 9. Other employee benefits | B56: 220866 | C56: 220866
A57: 10. Payroll taxes | B57: 89471 | C57: 89471
A58: 11a. Fees for services: management | B58: 0
A59: 11b. Fees for services: legal | B59: 15000 | C59: 15000
...

Sheet Balance sheet (detail)
A1: Sunny Slope Water Company
A2: Balance Sheet - Form 990 Part X (end of year, USD)
A3: Entity ID: cawc_0033 | Fiscal year ends December 31.
A5: Part X line (column B, EOY) | B5: FY2020 | C5: FY2021 | D5: FY2022 | E5: FY2023 | F5: FY2024
A6: Assets
A7: 1. Cash - non-interest-bearing | B7: 0 | C7: 0 | D7: 0 | E7: 0 | F7: 0
A8: 2. Savings and temporary cash investments | B8: 7362093 | C8: 12094085 | D8: 8538549 | E8: 9602070 | F8: 11385262
A9: 3. Pledges and grants receivable, net | B9: 0 | C9: 0 | D9: 0 | E9: 0 | F9: 0
A10: 4. Accounts receivable, net | B10: 695780 | C10: 763711 | D10: 843646 | E10: 885008 | F10: 897819
A11: 5. Receivables from officers/directors/trustees | B11: 0 | C11: 0 | D11: 0 | E11: 0 | F11: 0
A12: 6. Receivables from disqualified persons | B12: 0 | C12: 0 | D12: 0 | E12: 0 | F12: 0
A13: 7. Notes and loans receivable, net | B13: 0 | C13: 0 | D13: 0 | E13: 0 | F13: 0
A14: 8. Inventories for sale or use | B14: 127331 | C14: 127884 | D14: 134215 | E14: 139531 | F14: 141813
A15: 9. Prepaid expenses and deferred charges | B15: 106209 | C15: 120518 | D15: 124986 | E15: 142230 | F15: 155316
A16: 10c. Land, buildings, and equipment, net | B16: 14291137 | C16: 14236134 | D16: 19934930 | E16: 20473799 | F16: 20843495
A17: 11. Investments - publicly traded securities | B17: 0 | C17: 0 | D17: 0 | E17: 0 | F17: 0
A18: 12. Investments - other securities | B18: 0 | C18: 0 | D18: 0 | E18: 0 | F18: 0
... A21: 15. Other assets | B21: 3079315 | C21: 4209568 | D21: 2639660 | E21: 2469472 | F21: 2409675
A22: 16. Total assets | B22: =SUM(B7:B21) | C22: =SUM(C7:C21) | D22: =SUM(D7:D21) | E22: =SUM(E7:E21) | F22: =SUM(F7:F21)
A24: Liabilities
A25: 17. Accounts payable and accrued expenses | B25: 546240 | C25: 1248168 | D25: 648797 | E25: 622103 | F25: 1390503
A26: 19. Deferred revenue | B26: 32472 | C26: 53184 | D26: 24762 | E26: 41456 | F26: 28924
A27: 24. Unsecured notes and loans payable | B27: not reported | C27: not reported | D27: 1400000 | E27: 900000 | F27: not reported
A28: 25. Other liabilities | B28: 177211 | C28: 181211 | D28: 197830 | E28: 209334 | F28: 208000
A29: 26. Total liabilities | B29: =SUM(B25:B28) | C29: =SUM(C25:C28) | D29: =SUM(D25:D28) | E29: =SUM(E25:E28) | F29: =SUM(F25:F28)
A31: Net assets / fund balances
A32: 29. Capital stock or trust principal | B32: 130000 | C32: 130000 | D32: 130000 | E32: 130000 | F32: 130000
A33: 31. Retained earnings / accumulated funds | B33: 24809022 | C33: 29972417 | D33: 29847677 | E33: 31842297 | F33: 34109033
A34: 32. Total net assets / fund balances | B34: =SUM(B32:B33) | C34: =SUM(C32:C33) | D34: =SUM(D32:D33) | E34: =SUM(E32:E33) | F34: =SUM(F32:F33)
A36: Every Part X line is end-of-year (column B), as filed. Section totals (lines 16 / 26 / 32) are live SUMs of the lines above; their tie-outs and the balance-sheet identity (16 = 26 + 32) are on the Sources & audit tab. This filer files as a non-FASB mutual, so net assets sit on lines 29-31 (capital stock / paid-in capital / retained earnings); lines this filer does not report are omitted. Lines 10a/10b net into line 10c (shown).

Sheet Net-assets reconciliation
A1: Sunny Slope Water Company
A2: Reconciliation of Net Assets - Form 990 Part XI (USD)
A3: Entity ID: cawc_0033 | Fiscal year ends December 31.
A5: Part XI line | B5: FY2020 | C5: FY2021 | D5: FY2022 | E5: FY2023 | F5: FY2024
A6: Reconciliation
A7: 4. Net assets, beginning of year | B7: 23426788 | C7: 24939022 | D7: 30102417 | E7: 29977677 | F7: 31972297
A8: 3. Revenue less expenses | B8: 1201002 | C8: 4995857 | D8: 1694513 | E8: 1490599 | F8: 1920629
A9: 8. Prior period adjustments | B9: not reported | C9: not reported | D9: not reported | E9: not reported | F9: not reported
A10: 9. Other changes in net assets | B10: not reported | C10: not reported | D10: not reported | E10: not reported | F10: not reported
A11: 10. Net assets, end of year | B11: =SUM(B7,B8,B9,B10) | C11: =SUM(C7,C8,C9,C10) | D11: =SUM(D7,D8,D9,D10) | E11: =SUM(E7,E8,E9,E10) | F11: =SUM(F7,F8,F9,F10)
A13: Part XI reconciles beginning to ending net assets. Ending net assets (line 10) is a live formula: beginning balance (line 4) + revenue less expenses (line 3) + prior-period adjustments (8) + other changes (9). Its tie-out to the filed line 10 (and to Part X line 32) is on the Sources & audit tab. Lines 5-7 (unrealized gains, donated services, investment expenses) are not filed by this entity.

Sheet Cash flow proxies
A1: Sunny Slope Water Company
A2: Cash Flow Proxies - derived (USD)
A3: Entity ID: cawc_0033 | Fiscal year ends December 31.
A5: PROXY ONLY. The source filings contain no statement of cash flows. Lines below are derived from the reported income statement and year-over-year balance-sheet changes; treat as directional estimates, not GAAP cash flows. The earliest year has no prior period, so its delta cells are blank.
A7: Proxy line (USD) | B7: FY2020 | C7: FY2021 | D7: FY2022 | E7: FY2023 | F7: FY2024
A8: Operating
A9: Net income | B9: 1201002 | C9: 4995857 | D9: 1694513 | E9: 1490599 | F9: 1920629
A10: + Depreciation (reported) | B10: 814040 | C10: 811593 | D10: 881236 | E10: 994003 | F10: 992344
A11: − Δ Accounts receivable | C11: -67931 | D11: -79935 | E11: -41362 | F11: -12811
A12: − Δ Inventories | C12: -553 | D12: -6331 | E12: -5316 | F12: -2282
A13: − Δ Prepaid expenses | C13: -14309 | D13: -4468 | E13: -17244 | F13: -13086
A14: + Δ Accounts payable | C14: 701928 | D14: -599371 | E14: -26694 | F14: 768400
A15: Operating cash flow proxy | C15: 6426585 | D15: 1885644 | E15: 2393986 | F15: 3653194
A17: Investing
A18: − Δ PP&E gross (capex proxy) | C18: -756590 | D18: -6534306 | E18: -1525462 | F18: -1357100
A20: Financing
A21: Δ Mortgages & notes payable
A23: Reconciliation
A24: Δ Cash + temp. investments (actual) | C24: 4731992 | D24: -3555536 | E24: 1063521 | F24: 1783192
A26: The capex proxy assumes gross PP&E rises only via capital spending (it ignores disposals). 'Δ Cash + temp. investments (actual)' is the real reported change in liquid funds and is the most reliable line here; the operating/investing/financing proxies will not perfectly reconcile to it.

Sheet Ratios
A1: Sunny Slope Water Company
A2: Financial Ratios
A3: Entity ID: cawc_0033 | Fiscal year ends December 31.
A5: Ratio | B5: FY2020 | C5: FY2021 | D5: FY2022 | E5: FY2023 | F5: FY2024
A6: Profitability (computed upstream)
A7: Operating margin (NI / revenue) | B7: 0.20181848 | C7: 0.49403209 | D7: 0.2487868 | E7: 0.22634657 | F7: 0.26984108
A8: Expense ratio (expenses / revenue) | B8: 0.79818152 | C8: 0.50596791 | D8: 0.7512132 | E8: 0.77365343 | F8: 0.73015892
A9: Return on assets (NI / assets) | B9: 0.046740789 | C9: 0.15817192 | D9: 0.052544561 | E9: 0.044172192 | F9: 0.053549444
A10: Revenue growth (YoY) | B10: 0.054597917 | C10: 0.69930777 | D10: -0.32646102 | E10: -0.033127224 | F10: 0.080807875
A12: Leverage & solvency
A13: Debt-to-assets (liab. / assets) | B13: 0.029419133 | C13: 0.046938861 | D13: 0.070432706 | E13: 0.052537651 | F13: 0.04537462
A14: Equity ratio (net assets / assets) | B14: 0.97058087 | C14: 0.95306114 | D14: 0.92956729 | E14: 0.94746235 | F14: 0.95462538
A16: Liquidity & asset profile (derived here)
A17: Current ratio (current assets / AP) | B17: 15.179066 | C17: 10.500348 | D17: 14.86042 | E17: 17.310379 | F17: 9.0472369
A18: Cash ratio ((cash+temp inv.) / total liab.) | B18: 9.7392102 | C18: 8.1575522 | D18: 3.7591751 | E18: 5.416046 | F18: 6.9958665
A19: Asset age proxy (accum. deprec. / gross PP&E) | B19: 0.39895207 | C19: 0.41972967 | D19: 0.3583438 | E19: 0.37184203 | F19: 0.38606206
A21: Upstream ratios are read from financials_annual; derived ratios are computed only where inputs are reported. Current ratio uses accounts payable as the current-liability proxy (the filings do not split current vs. long-term liabilities). Asset age proxy: a higher % implies older / more depreciated infrastructure.

Sheet Unit economics
A1: Sunny Slope Water Company
A2: Unit economics - per-customer revenue by category (USD)
A3: Entity ID: cawc_0033 | Fiscal year ends December 31.
A5: Every metric here is PER CUSTOMER (a metered service connection). It is not a per-member figure; the member (shareholder) count is a different denominator, shown in the denominator block. The visible cell shows the value and its classification; the numerator, denominator, formula, and rationale are in each metric's LOGIC popup.
A6: Per-customer denominator (service connections) | C6: State Water Board eAR Section 4
A7: Total annual revenue (eAR Section 8b B1.8) | C7: eAR Section 8b total annual revenue not reported for this system.
A8: Primary source
A10: Revenue categories (value, classification, per customer, share)
A11: Revenue category | B11: Classification | C11: Value (USD) | D11: Per customer | E11: Share of revenue
A12: Water sales revenue | B12: not reported | C12: not reported | D12: not reported | E12: not reported
A13: Assessment revenue (990 program-service revenue not matched to eAR water-rate revenue) | B13: IMPOSSIBLE | C13: IMPOSSIBLE | D13: IMPOSSIBLE | E13: IMPOSSIBLE
A14: Meter revenue | B14: not reported | C14: not reported | D14: not reported | E14: not reported
A15: Overage or tiered penalty revenue | B15: not reported | C15: not reported | D15: not reported | E15: not reported
A17: Water sales revenue - not reported
A18: Not reported: this system filed an eAR but no Section 8b revenue block, so there is no filed water-sales figure. Not fallen back to a different year.
A19: Reason: No filed eAR Section 8b water-rate revenue for this system.
A21: Assessment revenue (990 program-service revenue not matched to eAR water-rate revenue) - IMPOSSIBLE
A22: Not computed. A period-aligned residual is not possible for this filer.
A23: Reason: Not derivable. The eAR Section 8b is reporting year None while the Form 990 fiscal year ends None; the two period ends are not aligned, so a period-aligned residual cannot be computed.
A25: Meter revenue - not reported
A26: Not reported. This category is not built because doing so would double-count.
A27: Reason: The eAR Section 8a reports a base/meter rate PRICE, but the filing carries no meter revenue line and no tier volume, and the base charge is already inside the water-sales revenue (eAR Section 8b water rates). Building a separate meter figure would double-count. Not backed into from a total.
A29: Overage or tiered penalty revenue - not reported
A30: Not reported. This category is not built because doing so would double-count.
A31: Reason: The eAR Section 8a reports tiered/overage rate PRICES, but the filing carries no overage revenue and no tier consumption volume, and any overage billed is already inside the water-sales revenue. Building it would double-count. Not backed into from a total.

Sheet Rate structure
A1: Sunny Slope Water Company
A2: Rate structure and representative bill - eAR Section 8a
A3: Entity ID: cawc_0033 | Fiscal year ends December 31.
A5: This block is a rate-schedule illustration at defined usage levels. It is NOT billed revenue and not a claim about any real customer's usage. The revenue side of unit economics is the separate Unit Economics block.
A6: No filed eAR Section 8a rate schedule is staged for this system.

Sheet Denominators & alignment
A1: Sunny Slope Water Company
A2: Denominators and calendar alignment
A3: Entity ID: cawc_0033 | Fiscal year ends December 31.
A5: System size and water use per fiscal year (the operating denominators that per-customer and per-acre metrics divide by), each cited to file and field. The eAR is reported on the calendar year; the 990 fiscal year differs by company. A calendar-year filer's volume is the eAR annual total (fiscal year = calendar year); an offset filer's is recast by a true monthly sum of the covered calendar months, or read not reported naming the missing months. Point-in-time counts (connections, population) are matched to the closest eAR year and never summed. Every derived figure states its formula and accounting rationale.
A6: Member vs customer (two different denominators, both preserved)
A7: Customer (service connection) | C7: State Water Board eAR Section 4
A8: Member (shareholder) | C8: No published shareholder count
A9: In a mutual water company a MEMBER is a shareholder who owns part of the system; a CUSTOMER is a metered service connection that receives water. The two diverge because one owner can hold several connections, a connection can serve people who are not owners, and some mutuals attach shares to land by acreage rather than counting heads. Per-customer metrics divide by service connections; per-member metrics divide by shareholders; the two counts are never used interchangeably.
A11: Denominator layer by fiscal year
A12: Fiscal year (end) | B12: Connections | C12: Population | D12: Service-area acres | E12: Water produced (AF) | F12: Water delivered (AF) | G12: Alignment method
A13: FY2020 (2020-12-31) | B13: 6325 | C13: not reported | D13: 1857.7 | E13: not reported | F13: not reported | G13: eAR annual total, calendar filer, equals fiscal year (not a monthly recast)
A14: FY2021 (2021-12-31) | B14: 6334 | C14: not reported | D14: 1857.7 | E14: not reported | F14: not reported | G14: eAR annual total, calendar filer, equals fiscal year (not a monthly recast)
A15: FY2022 (2022-12-31) | B15: 6337 | C15: not reported | D15: 1857.7 | E15: not reported | F15: not reported | G15: eAR annual total, calendar filer, equals fiscal year (not a monthly recast)
A16: FY2023 (2023-12-31) | B16: 6337 | C16: not reported | D16: 1857.7 | E16: not reported | F16: not reported | G16: eAR annual total, calendar filer, equals fiscal year (not a monthly recast)
A17: FY2024 (2024-12-31) | B17: not reported | C17: not reported | D17: 1857.7 | E17: not reported | F17: not reported | G17: eAR annual total, calendar filer, equals fiscal year (not a monthly recast)
A19: Connections by class - FY2023 (eAR Section 4)
A20: Single-family residential | B20: 5700
A21: Multi-family residential | B21: 140
A22: Commercial and institutional | B22: 497
A23: Industrial | B23: 0
A24: Landscape irrigation | B24: 0
A25: Agricultural | B25: 0
A26: Monthly-volume source: California open-data portal (data.ca.gov): the separate Produced Water (by month and source) and Delivered Water (by month and connection type) resources, which cover every public water system (not only urban suppliers), one resource per reporting year, matched by exact PWSID. This is the aggregate publication of eAR Section 6.

Sheet Governance evidence
A1: Sunny Slope Water Company
A2: Governance evidence status - Ostrom's eight design principles
A3: Entity ID: cawc_0033 | Fiscal year ends December 31.
A5: Evidence summary: 3 documented, 2 partial, 3 not documented of eight principles.
A6: A count of how many of Elinor Ostrom's eight design principles have a supporting record on file, not a grade. NOT DOCUMENTED means the supporting record was not found, not that the company governs badly. It marks a gap in the documentary record, an evidence gap to close, never a governance failing.
A7: Each mutual is read against Elinor Ostrom's eight design principles for institutions that govern a shared resource durably. Per principle: a one-line finding, the observable signal, a citation, and an evidence status stating whether the supporting record exists: DOCUMENTED (a cited record supports alignment), PARTIAL (some evidence exists but it is incomplete), or NOT DOCUMENTED (no supporting record was found). This is an evidence-status read, not a grade: the principles are never ranked, weighted, or given a letter, consistent with reporting as filed and not grading companies. NOT DOCUMENTED means the supporting record was not found, not that the company governs badly. It marks a gap in the documentary record, an evidence gap to close, never a governance failing.
A9: Principle | B9: Evidence status | C9: Finding | D9: Signal | E9: Citation
A10: Clearly defined boundaries | B10: DOCUMENTED | C10: The system is a defined public water system: 6,326 service connections over a State-published and field-verified service-area boundary of roughly 1,853.5 acres. | D10: SDWIS Community water system; SABL service-area boundary (Verified); connections defined. | E10: [C][G]
A11: What the record shows: SDWIS defines the membership as a fixed set of service connections and the State Water Board publishes a SABL service-area polygon for it, so who is inside and outside the system is documented. The boundary is FIELD-VERIFIED by the Water Board rather than merely carried.
A12: Rules fit local conditions | B12: NOT DOCUMENTED | C12: No filed rate schedule or metering statement was located for this company. | D12: No eAR Section 8a rate record held. | E12: not reported
A13: What the record shows: This company files no eAR, so the filing that would document metering and rate structure does not exist for it. NOT DOCUMENTED means the supporting record was not found, not that the company governs badly. It marks a gap in the documentary record, an evidence gap to close, never a governance failing.
A14: Collective-choice arrangements | B14: PARTIAL | C14: The company is owned by its customer-shareholders, but the specific board, the election procedure and any record of member votes are not in a source this project holds. | D14: Mutual ownership; Form 990 governance section. | E14: [990]
A15: What the record shows: A collective-choice mechanism is documented in outline: the customers are the shareholders. It stays PARTIAL rather than met because the filed corporate record that would carry the director roster and the election procedure is NOT YET CHECKED for this company, the California Secretary of State being reachable only through a browser session that now answers a CAPTCHA. A stated board is not a filed roster.
A16: Monitoring | B16: DOCUMENTED | C16: The system is monitored and reports on itself: it files an annual eAR, and a Consumer Confidence Report for 2022 was located at the State's own CCR portal. | D16: Annual eAR reporting; located Consumer Confidence Report | E16: [E][CCR]
A17: What the record shows: Operational monitoring is documented from more than one filing. What the federal violation check found is reported separately in the On the record block and is not folded into this tier.
A18: Graduated sanctions | B18: NOT DOCUMENTED | C18: No published shut-off, penalty, or delinquency policy was found for this system. | D18: No sourced graduated sanctions record. | E18: not reported
A19: What the record shows: No public record of a shut-off, penalty, or delinquency policy was located. NOT DOCUMENTED means the supporting record was not found, not that the company governs badly. It marks a gap in the documentary record, an evidence gap to close, never a governance failing.
A20: Conflict-resolution mechanisms | B20: NOT DOCUMENTED | C20: No published bylaws, dispute procedure, or grievance mechanism was found for this system. | D20: No sourced conflict-resolution mechanisms record. | E20: not reported
A21: What the record shows: No public record of a bylaws, dispute procedure, or grievance mechanism was located. NOT DOCUMENTED means the supporting record was not found, not that the company governs badly. It marks a gap in the documentary record, an evidence gap to close, never a governance failing.
A22: Recognized right to organize | B22: DOCUMENTED | C22: An incorporated California mutual water company recognized by the IRS as a 501(c)(12) exempt filer and by the State Water Board as a Community public water system. | D22: IRS 501(c)(12) exempt filer (Form 990); SDWIS Community public water system; eAR ownership type 'Privately owned Mutual Water Company or Association'. | E22: [990][C][E]
A23: What the record shows: Baseline legal standing is documented by two independent regulators: the IRS accepts it as a tax-exempt 501(c)(12) filer and the State Water Board holds it as a Community public water system with a mutual ownership type. This status does NOT rest on a filed corporate record, because the Secretary of State check has not been run for this company.
A24: Nested enterprises | B24: PARTIAL | C24: The system sits inside larger water systems: it pumps from 2 groundwater basin(s) shared with neighbors. Its role in governing any of them is not documented. | D24: it pumps from 2 groundwater basin(s) shared with neighbors | E24: [SG]
A25: What the record shows: Physical nesting is documented. What is not documented is any governance role in a wholesaler or in a groundwater sustainability agency, so the tier is PARTIAL rather than met.

Sheet Operational metrics
A1: Sunny Slope Water Company
A2: Operational metrics - plant per acre, density, terrain
A3: Entity ID: cawc_0033 | Fiscal year ends December 31.
A5: Plant assets per acre
A6: Service-area acres | B6: 1857.7 | C6: Geodesic area (WGS84 spherical excess) of the SABL service-area polygon.
A7: Fiscal year | B7: Gross plant per acre (primary) | C7: Net plant per acre
A8: FY2020 | B8: 12799.179 | C8: 7692.9197
A9: FY2021 | B9: 13206.451 | C9: 7663.3116
A10: FY2022 | B10: 16723.868 | C10: 10730.974
A11: FY2023 | B11: 17545.024 | C11: 11021.047
A12: FY2024 | B12: 18275.552 | C12: 11220.054
A13: Infrastructure built per acre of service area. Gross plant per acre is the primary read because it measures how much plant the system has put in the ground per acre, and unlike net plant it does not fall over time purely because the assets depreciate on the books. Net plant per acre is shown alongside as the depreciated book value per acre.
A14: Formula: gross plant per acre = Form 990 Part X line 10a (land, buildings, and equipment, gross) / SABL service-area acres; net plant per acre uses Part X line 10c (net)
A15: Source lines: Form 990 Part X line 10a (gross) and line 10c (net); Geodesic area (WGS84 spherical excess) of the SABL service-area polygon.
A16: Confidence: medium. This is worked out from filed figures (a ratio, or a year-to-year change), so it is one step removed from the raw numbers.. Filed gross/net plant over the measured SABL service-area acreage.
A18: Connections per acre
A19: Connections per acre | B19: 3.41 | C19: 6,343 connections / 1,857.7 acres. CA State Water Board SABL SERVICE_CONNECTIONS; Geodesic area (WGS84 spherical excess) of the SABL service-area polygon.

Sheet Supply & weather
A1: Sunny Slope Water Company
A2: Supply and weather indicators (DWR water year)
A3: Entity ID: cawc_0033 | Fiscal year ends December 31.
A5: Reporting calendar: Different reporting periods. The DWR water year runs October 1 to September 30; this system's fiscal year ends December 31, so the two period ends are three months apart. Read the two side by side with that in mind. Neither series is recast: both are reported as filed. A water year is named for the calendar year it ends in, so WY2024 and FY2024 share a number without covering the same twelve months.
A7: Indicator | B7: WY2020 | C7: WY2021 | D7: WY2022 | E7: WY2023 | F7: WY2024
A8: Water-year type (Sacramento Valley) | B8: Dry | C8: Critical | D8: Critical | E8: Wet | F8: Above Normal
A9: Peak drought, Los Angeles County | B9: D1 | C9: D4 | D9: D4 | E9: D4 | F9: None (no D0-D4 during the fiscal year)
A10: Precip, percent of normal (8-Station Index) | B10: 63 | C10: 48 | D10: 86 | E10: 133 | F10: 96
A11: Snowpack, April 1 percent of average | B11: 53% | C11: 59% | D11: 38% | E11: 237% | F11: 110%
A12: State Water Project allocation | B12: 20% | C12: 5% | D12: 5% | E12: 100% | F12: 40%

Sheet How this was built
A1: Sunny Slope Water Company
A2: How this was built - forensic lineage
A3: Entity ID: cawc_0033 | Fiscal year ends December 31.
A5: A plain account of the forensic lineage behind the hard-to-source metrics: what sources were checked, what was found, what was derived, and what could not be built and why. Every figure marked DERIVED or IMPOSSIBLE above is traceable to a line here.
A7: Water-sales revenue per customer - not reported
A8: Sources checked | B8: State Water Board eAR Section 8b (water-rate revenue B1.1/B1.2); State Water Board eAR Section 4 (connection count, same reporting year); audited financial statement (secondary cross-check, where published)
A9: What was found | B9: The eAR Section 8b reports water-rate revenue for reporting year None, so this is a DIRECT filed figure; per customer it is divided by the eAR Section 4 connection count for the same reporting year, so numerator and denominator share the year.
A11: Assessment revenue (residual) - IMPOSSIBLE
A12: Sources checked | B12: Form 990 Part VIII line 2 (program-service revenue); State Water Board eAR Section 8b (water-rate revenue B1.1/B1.2); eAR Section 8b filer comment (WRRevenueComments)
A13: What was found | B13: A period-aligned residual cannot be computed for this filer, so the metric is rendered IMPOSSIBLE rather than guessed.
A14: Caveat | B14: Not derivable. The eAR Section 8b is reporting year None while the Form 990 fiscal year ends None; the two period ends are not aligned, so a period-aligned residual cannot be computed.
A16: Meter revenue - not reported
A17: Sources checked | B17: State Water Board eAR Section 8a (rate prices); State Water Board eAR Section 8b (revenue lines); audited financial statement
A18: What was found | B18: The rate price exists in Section 8a but no revenue or tier volume is reported, and the base charge is already inside water sales.
A19: Caveat | B19: The eAR Section 8a reports a base/meter rate PRICE, but the filing carries no meter revenue line and no tier volume, and the base charge is already inside the water-sales revenue (eAR Section 8b water rates). Building a separate meter figure would double-count. Not backed into from a total.
A21: Overage / tiered-penalty revenue - not reported
A22: Sources checked | B22: State Water Board eAR Section 8a (rate prices); State Water Board eAR Section 8b (revenue lines); audited financial statement
A23: What was found | B23: The rate price exists in Section 8a but no revenue or tier volume is reported, and the base charge is already inside water sales.
A24: Caveat | B24: The eAR Section 8a reports tiered/overage rate PRICES, but the filing carries no overage revenue and no tier consumption volume, and any overage billed is already inside the water-sales revenue. Building it would double-count. Not backed into from a total.
A26: eAR Section 8b reporting-period basis - sourced
A27: Sources checked | B27: eAR Section 8b B0.1 (WRFinancialReportingPeriod); eAR Section 8b B0.2 (WRFiscalYearStartDate)
A28: What was found | B28: The reporting basis (fiscal vs calendar year) is read from the filer's own B0.1/B0.2 answer and staged verbatim, never hardcoded, so the 990 comparison and the residual are period-aligned.
A30: Member (shareholder) count denominator - not reported
A31: Sources checked | B31: Form 990 (no member count stated); company website
A32: What was found | B32: No filing states a member/shareholder count, so the per-member unit economics read not reported rather than borrowing the connection count.
A34: Water volume delivered (acre-feet) - not reported
A35: Sources checked | B35: Form 990 (not in the filing); Consumer Confidence Report; eAR Section 6 (PRA-gated)
A36: What was found | B36: Volume delivered in acre-feet is not in the Form 990 and the CCR states only a source mix, so the per-acre-foot metrics read not reported; the eAR Section 6 is named as the source still needed.

Sheet Sources & audit
A1: Sunny Slope Water Company
A2: Sources & audit - full provenance and tie-outs (kept off the statements so they read clean)
A3: Entity ID: cawc_0033 | Fiscal year ends December 31.
A5: Presentation standard: every figure on the statement tabs is verified to its source filing and shown clean. A cell the filing does not report reads "not reported" (never estimated, never guessed).
A6: Citations, confidence tiers, and the filed-vs-computed tie-out checks live on the "Sources & audit" tab, keyed by cell, so every number is fully traceable without cluttering the statements. These pages are ready to use as filed.
A8: A. Filing provenance (one row per staged extraction)
A9: Fiscal year | B9: Period end | C9: Filing type | D9: Confidence | E9: Extraction ID | F9: Object ID | G9: Extracted by | H9: Extracted at | I9: Source URL
A10: FY2020 | B10: 2020-12-31 | C10: 990 | D10: high | E10: b54848aa-7e96-4a58-a1b9-1b2841ccec95 | F10: 202120629349300912 | G10: claude-opus-5 | H10: 2026-09-16T21:34:13+00:00 | I10: https://apps.irs.gov/pub/epostcard/990/xml/2021/2021_TEOS_XML_01A.zip#202120629349300912_public.xml
A11: FY2021 | B11: 2021-12-31 | C11: 990 | D11: high | E11: 37461b61-9105-4c1c-9317-b81d6f27d821 | F11: 202200829349301670 | G11: claude-opus-5 | H11: 2026-09-16T21:34:13+00:00 | I11: https://apps.irs.gov/pub/epostcard/990/xml/2022/2022_TEOS_XML_01A.zip#202200829349301670_public.xml
A12: FY2022 | B12: 2022-12-31 | C12: 990 | D12: high | E12: 4aed9bff-1d70-47c1-81bf-e65da3de9bb7 | F12: 202311119349301616 | G12: claude-opus-5 | H12: 2026-09-16T21:34:13+00:00 | I12: https://apps.irs.gov/pub/epostcard/990/xml/2023/2023_TEOS_XML_05A.zip#202311119349301616_public.xml
A13: FY2023 | B13: 2023-12-31 | C13: 990 | D13: high | E13: 7623a9d2-61b4-43f5-bf29-240e07bc9792 | F13: 202401069349300525 | G13: claude-opus-5 | H13: 2026-09-16T21:34:13+00:00 | I13: https://apps.irs.gov/pub/epostcard/990/xml/2024/2024_TEOS_XML_04A.zip#202401069349300525_public.xml
A14: FY2024 | B14: 2024-12-31 | C14: 990 | D14: high | E14: 817db4dc-65c4-4ff8-86bd-c28038a25647 | F14: 202540799349301909 | G14: claude-opus-5 | H14: 2026-09-16T21:34:13+00:00 | I14: https://apps.irs.gov/pub/epostcard/990/xml/2025/2025_TEOS_XML_03A.zip#202540799349301909_public.xml
A16: B. Figure citations (every figure on the statement tabs, keyed by cell)
A17: Tab | B17: Cell | C17: Line item | D17: Form 990 line | E17: Key path | F17: Confidence | G17: As filed
A18: Revenue (detail) | B18: B7 | C18: 1h. Total contributions, gifts, grants | D18: 1h | E18: part_viii_revenue.total_contributions | F18: high | G18: 202282
A19: Revenue (detail) | B19: C7 | C19: 1h. Total contributions, gifts, grants | D19: 1h | E19: part_viii_revenue.total_contributions | F19: high | G19: 144155
A20: Revenue (detail) | B20: D7 | C20: 1h. Total contributions, gifts, grants | D20: 1h | E20: part_viii_revenue.total_contributions | F20: high | G20: 421156
A21: Revenue (detail) | B21: E7 | C21: 1h. Total contributions, gifts, grants | D21: 1h | E21: part_viii_revenue.total_contributions | F21: high | G21: 181193
A22: Revenue (detail) | B22: F7 | C22: 1h. Total contributions, gifts, grants | D22: 1h | E22: part_viii_revenue.total_contributions | F22: high | G22: 244864
A23: Revenue (detail) | B23: B8 | C23: 2g. Total program service revenue | D23: 2g | E23: part_viii_revenue.total_program_service_revenue | F23: high | G23: 5572638
A24: Revenue (detail) | B24: C8 | C24: 2g. Total program service revenue | D24: 2g | E24: part_viii_revenue.total_program_service_revenue | F24: high | G24: 6055746
A25: Revenue (detail) | B25: D8 | C25: 2g. Total program service revenue | D25: 2g | E25: part_viii_revenue.total_program_service_revenue | F25: high | G25: 6044091
A26: Revenue (detail) | B26: E8 | C26: 2g. Total program service revenue | D26: 2g | E26: part_viii_revenue.total_program_service_revenue | F26: high | G26: 6034077
A27: Revenue (detail) | B27: F8 | C27: 2g. Total program service revenue | D27: 2g | E27: part_viii_revenue.total_program_service_revenue | F27: high | G27: 6503705
A28: Revenue (detail) | B28: B9 | C28: 3. Investment income | D28: 3 | E28: part_viii_revenue.investment_income | F28: high | G28: 150813
A29: Revenue (detail) | B29: C9 | C29: 3. Investment income | D29: 3 | E29: part_viii_revenue.investment_income | F29: high | G29: 277195
... A309: Net-assets reconciliation | B309: F8 | C309: 3. Revenue less expenses | D309: Part XI line 3 | E309: part_xi_reconciliation.reconciliation_revenue_expenses | F309: high | G309: 1920629
A311: C. Tie-out checks (filed vs computed; any nonzero variance is flagged red)
A312: Tab | B312: Check | C312: Fiscal year | D312: Filed | E312: Computed | F312: Variance (computed - filed)
A313: Revenue (detail) | B313: 12. Total revenue | C313: FY2020 | D313: 5950902 | E313: ='Revenue (detail)'!B13 | F313: =E313-D313
A314: Revenue (detail) | B314: 12. Total revenue | C314: FY2021 | D314: 10112414 | E314: ='Revenue (detail)'!C13 | F314: =E314-D314
A315: Revenue (detail) | B315: 12. Total revenue | C315: FY2022 | D315: 6811105 | E315: ='Revenue (detail)'!D13 | F315: =E315-D315
A316: Revenue (detail) | B316: 12. Total revenue | C316: FY2023 | D316: 6585472 | E316: ='Revenue (detail)'!E13 | F316: =E316-D316
A317: Revenue (detail) | B317: 12. Total revenue | C317: FY2024 | D317: 7117630 | E317: ='Revenue (detail)'!F13 | F317: =E317-D317
A318: Revenue (detail) | B318: 2g program service revenue = sum of lines 2a-2f (FY2024) | C318: FY2024 | D318: 6503705 | E318: =SUM('Revenue (detail)'!C17:C21) | F318: =E318-D318
A319: Operating expenses (detail) | B319: 25. Total functional expenses | C319: FY2020 | D319: 4749900 | E319: ='Operating expenses (detail)'!B44 | F319: =E319-D319
A320: Operating expenses (detail) | B320: 25. Total functional expenses | C320: FY2021 | D320: 5116557 | E320: ='Operating expenses (detail)'!C44 | F320: =E320-D320
A321: Operating expenses (detail) | B321: 25. Total functional expenses | C321: FY2022 | D321: 5116592 | E321: ='Operating expenses (detail)'!D44 | F321: =E321-D321
A322: Operating expenses (detail) | B322: 25. Total functional expenses | C322: FY2023 | D322: 5094873 | E322: ='Operating expenses (detail)'!E44 | F322: =E322-D322
A323: Operating expenses (detail) | B323: 25. Total functional expenses | C323: FY2024 | D323: 5197001 | E323: ='Operating expenses (detail)'!F44 | F323: =E323-D323
...

Sheet Provenance
A1: Build provenance | B1: Built from source commit d418ffb17485 (2026-10-06); source fingerprint a75a8eee82c65cf7; 192 companies (179 retail mutual, 4 irrigation mutual, 3 mutual, no PWSID, purpose not stated, 2 frozen non-mutual (special district), 2 wholesale mutual, 1 frozen non-mutual (investor-owned), 1 frozen non-mutual (municipal)); 91 gates; build id 3d08d6d2a855.
A2: source_commit | B2: d418ffb174855ab78000d391d42f898397b0d8aa
A3: source_commit_date | B3: 2026-10-06
A4: source_fingerprint | B4: a75a8eee82c65cf7096931f06e18affdc28686a02895b46538e7298b57c04d94
A5: gate_count | B5: 91
A6: build_id | B6: 3d08d6d2a855
A7: registry: frozen non-mutual (investor-owned) | B7: 1
A8: registry: frozen non-mutual (municipal) | B8: 1
A9: registry: frozen non-mutual (special district) | B9: 2
A10: registry: irrigation mutual | B10: 4
A11: registry: mutual, no PWSID, purpose not stated | B11: 3
A12: registry: retail mutual | B12: 179
A13: registry: wholesale mutual | B13: 2
