Workbook

Sheet Summary
A1: Markleeville Water Company
A2: Financial Summary - multi-year overview (USD)
A3: Entity ID: cawc_0050 | Fiscal year ends June 30.
A5: Presentation standard: every figure on the statement tabs is verified to its source filing and shown clean. A cell the filing does not report reads "not reported" (never estimated, never guessed).
A6: Citations, confidence tiers, and the filed-vs-computed tie-out checks live on the "Sources & audit" tab, keyed by cell, so every number is fully traceable without cluttering the statements. These pages are ready to use as filed.
A8: Metric | B8: FY2020 | C8: FY2021 | D8: FY2022 | E8: FY2023 | F8: FY2024 | G8: FY2025
A9: Operating results (USD)
A10: Total revenue | B10: 224021 | C10: 577618 | D10: 217874 | E10: 181164 | F10: 659047 | G10: 3152090
A11: Total expenses | B11: 195428 | C11: 433901 | D11: 246934 | E11: 184145 | F11: 178796 | G11: 168981
A12: Net income | B12: 28593 | C12: 143717 | D12: -29060 | E12: -2981 | F12: 480251 | G12: 2983109
A14: Financial position (USD, end of year)
A15: Total assets | B15: 400231 | C15: 540139 | D15: 511079 | E15: 509602 | F15: 988349 | G15: 3974874
A16: Total liabilities | B16: 3809 | C16: 0 | D16: 0 | E16: 1504 | F16: 0 | G16: 3416
A17: Net assets | B17: 396422 | C17: 540139 | D17: 511079 | E17: 508098 | F17: 988349 | G17: 3971458
A19: Headline ratios
A20: Operating margin | B20: 0.12763536 | C20: 0.24880977 | D20: -0.13337984 | E20: -0.016454704 | F20: 0.72870524 | G20: 0.94639081
A21: Revenue growth (YoY) | B21: 0.31426074 | C21: 1.5784101 | D21: -0.62280608 | E21: -0.16849188 | F21: 2.6378475 | G21: 3.7828
A22: Return on assets | B22: 0.071441243 | C22: 0.2660741 | D22: -0.056860094 | E22: -0.0058496631 | F22: 0.48591236 | G22: 0.75049146
A24: Figures as reported in source filings (full provenance on the Sources & audit tab). Parentheses denote negatives; ratios are computed upstream in financials_annual.

Sheet Notes
A1: Notes
A2: Human annotations from the versioned store (data/notes/). Annotations only: they never change a reported figure or a confidence tier.
A4: Date | B4: Tag | C4: Author | D4: Note
A5: 2026-08-31 | B5: conflict | C5: Claude | D5: The State publishes 167 service connections against a served population of 25, fewer people than connections, which no retail distribution system produces. Both figures are carried exactly as SDWIS publishes them. Any per-connection or per-capita figure derived from this pair will be an extreme and is not smoothed, adjusted or excluded.

Sheet Financial Statements
A1: Markleeville Water Company
A2: Financial Statements - income statement, balance sheet, cash flow, member income test (USD)
A3: Entity ID: cawc_0050 | Fiscal year ends June 30.
A5: INCOME STATEMENT - as reported (USD)
A6: Line item | B6: FY2020 | C6: FY2021 | D6: FY2022 | E6: FY2023 | F6: FY2024 | G6: FY2025
A7: Revenue
A8: Program service revenue | B8: 175707 | C8: 263321 | D8: 141899 | E8: 181146 | F8: 191253 | G8: 180603
A9: Investment income | B9: 35 | C9: 12 | D9: 12 | E9: 18 | F9: 47 | G9: 46
A10: Net rental income
A11: Net gain/(loss) on investment sales
A12: Other revenue
A13: Contributions & grants | B13: 48279 | C13: 314285 | D13: 75963 | F13: 467747 | G13: 2971441
A14: Total revenue | B14: 224021 | C14: 577618 | D14: 217874 | E14: 181164 | F14: 659047 | G14: 3152090
A16: Expenses
A17: Depreciation | B17: 7576 | C17: 7576 | D17: 7576 | E17: 7576 | F17: 7576 | G17: 7576
A18: Interest expense
A19: Total expenses | B19: 195428 | C19: 433901 | D19: 246934 | E19: 184145 | F19: 178796 | G19: 168981
A21: Net income | B21: 28593 | C21: 143717 | D21: -29060 | E21: -2981 | F21: 480251 | G21: 2983109
A24: BALANCE SHEET - as reported (USD, end of year)
A25: Line item | B25: FY2020 | C25: FY2021 | D25: FY2022 | E25: FY2023 | F25: FY2024 | G25: FY2025
A26: Assets
A27: Cash | B27: 226155 | C27: 288508 | D27: 341205 | E27: 357025 | F27: 365152 | G27: 359674
A28: Savings & temporary investments
A29: Accounts receivable | B29: 99 | C29: 84664 | D29: 10082 | F29: 7740
A30: Inventories
A31: Prepaid expenses | B31: 2956 | C31: 3522 | D31: 3923 | E31: 4284 | F31: 3942 | G31: 5678
A32: Property, plant & equipment (gross) | B32: 483581 | C32: 483581 | D32: 483581 | E32: 483581 | F32: 954379 | G32: 3959962
A33: Less: accumulated depreciation | B33: -312560 | C33: -320136 | D33: -327712 | E33: -335288 | F33: -342864 | G33: -350440
A34: Net property, plant & equipment | B34: 171021 | C34: 163445 | D34: 155869 | E34: 148293 | F34: 611515 | G34: 3609522
A35: Total assets | B35: 400231 | C35: 540139 | D35: 511079 | E35: 509602 | F35: 988349 | G35: 3974874
A37: Liabilities
A38: Accounts payable | B38: 3809 | C38: 0 | E38: 1504 | G38: 3416
A39: Mortgages & notes payable
A40: Total liabilities | B40: 3809 | C40: 0 | D40: 0 | E40: 1504 | F40: 0 | G40: 3416
A42: Net Assets / Equity
A43: Capital stock | B43: 0 | C43: 0 | D43: 0 | E43: 0 | F43: 0 | G43: 0
A44: Paid-in capital | B44: 0 | C44: 0 | D44: 0 | E44: 0 | F44: 0 | G44: 0
A45: Retained earnings | B45: 396422 | C45: 540139 | D45: 511079 | E45: 508098 | F45: 988349 | G45: 3971458
A46: Net assets | B46: 396422 | C46: 540139 | D46: 511079 | E46: 508098 | F46: 988349 | G46: 3971458
A49: CASH FLOW - derived proxy (USD)
...

Sheet Balance Sheet
A1: Markleeville Water Company
A2: Balance Sheet - as reported (USD, end of year)
A3: Entity ID: cawc_0050 | Fiscal year ends June 30.
A5: Line item | B5: FY2020 | C5: FY2021 | D5: FY2022 | E5: FY2023 | F5: FY2024 | G5: FY2025
A6: Assets
A7: Cash | B7: 226155 | C7: 288508 | D7: 341205 | E7: 357025 | F7: 365152 | G7: 359674
A8: Savings & temporary investments
A9: Accounts receivable | B9: 99 | C9: 84664 | D9: 10082 | F9: 7740
A10: Inventories
A11: Prepaid expenses | B11: 2956 | C11: 3522 | D11: 3923 | E11: 4284 | F11: 3942 | G11: 5678
A12: Property, plant & equipment (gross) | B12: 483581 | C12: 483581 | D12: 483581 | E12: 483581 | F12: 954379 | G12: 3959962
A13: Less: accumulated depreciation | B13: -312560 | C13: -320136 | D13: -327712 | E13: -335288 | F13: -342864 | G13: -350440
A14: Net property, plant & equipment | B14: 171021 | C14: 163445 | D14: 155869 | E14: 148293 | F14: 611515 | G14: 3609522
A15: Total assets | B15: 400231 | C15: 540139 | D15: 511079 | E15: 509602 | F15: 988349 | G15: 3974874
A17: Liabilities
A18: Accounts payable | B18: 3809 | C18: 0 | E18: 1504 | G18: 3416
A19: Mortgages & notes payable
A20: Total liabilities | B20: 3809 | C20: 0 | D20: 0 | E20: 1504 | F20: 0 | G20: 3416
A22: Net Assets / Equity
A23: Capital stock | B23: 0 | C23: 0 | D23: 0 | E23: 0 | F23: 0 | G23: 0
A24: Paid-in capital | B24: 0 | C24: 0 | D24: 0 | E24: 0 | F24: 0 | G24: 0
A25: Retained earnings | B25: 396422 | C25: 540139 | D25: 511079 | E25: 508098 | F25: 988349 | G25: 3971458
A26: Net assets | B26: 396422 | C26: 540139 | D26: 511079 | E26: 508098 | F26: 988349 | G26: 3971458
A28: Balance check (assets − liab. − net assets) | B28: 0 | C28: 0 | D28: 0 | E28: 0 | F28: 0 | G28: 0
A30: Net PP&E is the reported ppe_net column (gross less accumulated depreciation). The balance check should be ~0 where all three totals are reported; a non-zero value flags a reporting or extraction discrepancy worth reviewing.

Sheet Officers & contractors
A1: Markleeville Water Company
A2: Officers, Directors & Contractors - Form 990 Part VII (FY2025; USD)
A3: Entity ID: cawc_0050 | Fiscal year ends June 30.
A5: Section A - Officers, directors, trustees, key employees
A6: Name | B6: Title | C6: Reportable comp (org) | D6: Reportable comp (related) | E6: Other comp | F6: Total compensation
A7: MARY YOUNG | B7: PRESIDENT | C7: 0 | D7: 0 | E7: 0 | F7: 0
A8: BECKY THORNBURG | B8: VICE PRESIDENT | C8: 0 | D8: 0 | E8: 0 | F8: 0
A9: RICHARD HARVEY | B9: DIRECTOR | C9: 0 | D9: 0 | E9: 0 | F9: 0
A10: KRIS HARTNETT | B10: DIRECTOR | C10: 12827 | D10: 0 | E10: 0 | F10: 12827
A11: MARK SCHWARTZ | B11: DIRECTOR | C11: 0 | D11: 0 | E11: 0 | F11: 0
A12: JOANNE OEHLERKING | B12: TREASURER/SECRETARY | C12: 12285 | D12: 0 | E12: 0 | F12: 12285
A14: Section B - Independent contractors (over $100,000)
A15: Contractor | B15: Services | C15: Compensation
A17: Section A lists every officer, director, trustee and key employee filed for the latest year; the two with the highest total compensation are highlighted. Total compensation is computed (reportable org + related + other). Section B lists each independent contractor paid over $100,000; the return reports 0 such contractor(s). Source and confidence for every figure are on the Sources & audit tab.

Sheet Revenue (detail)
A1: Markleeville Water Company
A2: Revenue - Form 990 Part VIII (USD)
A3: Entity ID: cawc_0050 | Fiscal year ends June 30.
A5: Part VIII line | B5: FY2020 | C5: FY2021 | D5: FY2022 | E5: FY2023 | F5: FY2024 | G5: FY2025
A6: Revenue by category
A7: 1h. Total contributions, gifts, grants | B7: 48279 | C7: 314285 | D7: 75963 | E7: not reported | F7: 467747 | G7: 2971441
A8: 2g. Total program service revenue | B8: 175707 | C8: 263321 | D8: 141899 | E8: 181146 | F8: 191253 | G8: 180603
A9: 3. Investment income | B9: 35 | C9: 12 | D9: 12 | E9: 18 | F9: 47 | G9: 46
A10: 6d. Net rental income | B10: not reported | C10: not reported | D10: not reported | E10: not reported | F10: not reported | G10: not reported
A11: 7d. Net gain/(loss) from investment sales | B11: not reported | C11: not reported | D11: not reported | E11: not reported | F11: not reported | G11: not reported
A12: 11e. Other revenue | B12: not reported | C12: not reported | D12: not reported | E12: not reported | F12: not reported | G12: not reported
A13: 12. Total revenue | B13: =SUM(B7:B12) | C13: =SUM(C7:C12) | D13: =SUM(D7:D12) | E13: =SUM(E7:E12) | F13: =SUM(F7:F12) | G13: =SUM(G7:G12)
A15: Program service revenue detail - FY2025 (lines 2a-2f)
A16: Description | B16: Business code | C16: Total revenue
A17: MEMBER REVENUE | B17: 541900 | C17: 180603
A18: Revenue category subtotals are as filed. Total revenue (line 12) is a live SUM of the category cells above; its tie-out to the filed total is on the Sources & audit tab. Program service revenue detail is shown for the latest year, with its sum-to-line-2g check on that same audit tab.

Sheet Operating expenses (detail)
A1: Markleeville Water Company
A2: Statement of Functional Expenses - Form 990 Part IX (USD)
A3: Entity ID: cawc_0050 | Fiscal year ends June 30.
A5: Part IX line (column A Total) | B5: FY2020 | C5: FY2021 | D5: FY2022 | E5: FY2023 | F5: FY2024 | G5: FY2025
A6: Functional expenses, column A Total - by year
A7: 5. Compensation of current officers, directors, trustees | B7: 13500 | C7: 26059 | D7: 13365 | E7: 22370 | F7: 24968 | G7: 27319
A8: 7. Other salaries and wages | B8: 36379 | C8: 15466 | D8: 12105 | E8: not reported | F8: not reported | G8: not reported
A9: 10. Payroll taxes | B9: 4438 | C9: 4261 | D9: 2713 | E9: 1966 | F9: 2313 | G9: 2527
A10: 11b. Fees for services: legal | B10: 3273 | C10: 2635 | D10: not reported | E10: not reported | F10: 1000 | G10: not reported
A11: 11c. Fees for services: accounting | B11: 2100 | C11: 2100 | D11: 2258 | E11: 2678 | F11: 3413 | G11: 3654
A12: 13. Office expenses | B12: 1927 | C12: 5910 | D12: 3525 | E12: 3160 | F12: 3282 | G12: 4115
A13: 16. Occupancy | B13: 52339 | C13: 25816 | D13: 55663 | E13: 38966 | F13: 68415 | G13: 70506
A14: 17. Travel | B14: 1519 | C14: 1001 | D14: 752 | E14: 286 | F14: 658 | G14: 705
A15: 22. Depreciation, depletion, and amortization | B15: 7576 | C15: 7576 | D15: 7576 | E15: 7576 | F15: 7576 | G15: 7576
A16: 23. Insurance | B16: 3952 | C16: 1989 | D16: 6802 | E16: 7261 | F16: 6525 | G16: 6997
A17: 24. GRANT FUNDED WATER SYST | B17: 48279 | C17: 314284 | D17: 70963 | E17: not reported | F17: not reported | G17: not reported
A18: 24. OPERATING SUPPLIES | B18: 9889 | C18: 7290 | D18: 6060 | E18: 5779 | F18: 10258 | G18: 3911
A19: 24. WATER ANALYSIS FEE | B19: 4810 | C19: 5880 | D19: not reported | E19: 4176 | F19: 14044 | G19: 4718
A20: 24. LICENSE, PERMITS, FEES | B20: 2870 | C20: not reported | D20: not reported | E20: not reported | F20: not reported | G20: not reported
A21: 24. MISCELLANEOUS | B21: not reported | C21: 6652 | D21: not reported | E21: not reported | F21: not reported | G21: not reported
A22: 24. SIERRA WATER OPERATORS | B22: not reported | C22: not reported | D22: 34359 | E22: 30586 | F22: 30543 | G22: 27900
A23: 24. SUBMAIN PIPELINE PROJEC | B23: not reported | C23: not reported | D23: 20795 | E23: 54600 | F23: not reported | G23: not reported
A24: 24. LICENSES, PERMITS, FEES | B24: not reported | C24: not reported | D24: not reported | E24: not reported | F24: 3812 | G24: 4925
A25: 24e. All other expenses | B25: 2577 | C25: 6982 | D25: 9998 | E25: 4741 | F25: 1989 | G25: 4128
A26: 25. Total functional expenses | B26: =SUM(B7:B25) | C26: =SUM(C7:C25) | D26: =SUM(D7:D25) | E26: =SUM(E7:E25) | F26: =SUM(F7:F25) | G26: =SUM(G7:G25)
A28: Functional column split - FY2025
A29: Not reported. This filer reports only column A (Total) of Part IX; the program / management / fundraising split (columns B-D) is not filed, so it is left as not reported rather than shown empty or inferred.
A30: Top block: each Part IX line, column A (Total), by year, as filed. Total functional expenses (line 25) is a live SUM of the line cells; its tie-out to the filed total is on the Sources & audit tab. Filer-itemized 24a-24d rows show the most recent year's as-filed wording; rows are aligned across years case-insensitively with collapsed spacing, so a line filed only in a different capitalization or spacing shares one row, while genuinely different wording stays a separate row (every as-filed variant is recorded on the Sources & audit tab). This filer reports only column A (Total); the program / management / fundraising split (columns B-D) is not reported. Lines this filer does not report are omitted rather than shown empty.

Sheet Balance sheet (detail)
A1: Markleeville Water Company
A2: Balance Sheet - Form 990 Part X (end of year, USD)
A3: Entity ID: cawc_0050 | Fiscal year ends June 30.
A5: Part X line (column B, EOY) | B5: FY2020 | C5: FY2021 | D5: FY2022 | E5: FY2023 | F5: FY2024 | G5: FY2025
A6: Assets
A7: 1. Cash - non-interest-bearing | B7: 226155 | C7: 288508 | D7: 341205 | E7: 357025 | F7: 365152 | G7: 359674
A8: 4. Accounts receivable, net | B8: 99 | C8: 84664 | D8: 10082 | E8: not reported | F8: 7740 | G8: not reported
A9: 9. Prepaid expenses and deferred charges | B9: 2956 | C9: 3522 | D9: 3923 | E9: 4284 | F9: 3942 | G9: 5678
A10: 10c. Land, buildings, and equipment, net | B10: 171021 | C10: 163445 | D10: 155869 | E10: 148293 | F10: 611515 | G10: 3609522
A11: 16. Total assets | B11: =SUM(B7:B10) | C11: =SUM(C7:C10) | D11: =SUM(D7:D10) | E11: =SUM(E7:E10) | F11: =SUM(F7:F10) | G11: =SUM(G7:G10)
A13: Liabilities
A14: 17. Accounts payable and accrued expenses | B14: 3809 | C14: 0 | D14: not reported | E14: 1504 | F14: not reported | G14: 3416
A15: 26. Total liabilities | B15: =SUM(B14:B14) | C15: =SUM(C14:C14) | D15: =SUM(D14:D14) | E15: =SUM(E14:E14) | F15: =SUM(F14:F14) | G15: =SUM(G14:G14)
A17: Net assets / fund balances
A18: 29. Capital stock or trust principal | B18: 0 | C18: 0 | D18: 0 | E18: 0 | F18: 0 | G18: 0
A19: 30. Paid-in or capital surplus | B19: 0 | C19: 0 | D19: 0 | E19: 0 | F19: 0 | G19: 0
A20: 31. Retained earnings / accumulated funds | B20: 396422 | C20: 540139 | D20: 511079 | E20: 508098 | F20: 988349 | G20: 3971458
A21: 32. Total net assets / fund balances | B21: =SUM(B18:B20) | C21: =SUM(C18:C20) | D21: =SUM(D18:D20) | E21: =SUM(E18:E20) | F21: =SUM(F18:F20) | G21: =SUM(G18:G20)
A23: Every Part X line is end-of-year (column B), as filed. Section totals (lines 16 / 26 / 32) are live SUMs of the lines above; their tie-outs and the balance-sheet identity (16 = 26 + 32) are on the Sources & audit tab. This filer files as a non-FASB mutual, so net assets sit on lines 29-31 (capital stock / paid-in capital / retained earnings); lines this filer does not report are omitted. Lines 10a/10b net into line 10c (shown).

Sheet Net-assets reconciliation
A1: Markleeville Water Company
A2: Reconciliation of Net Assets - Form 990 Part XI (USD)
A3: Entity ID: cawc_0050 | Fiscal year ends June 30.
A5: Part XI line | B5: FY2020 | C5: FY2021 | D5: FY2022 | E5: FY2023 | F5: FY2024 | G5: FY2025
A6: Reconciliation
A7: 4. Net assets, beginning of year | B7: 367829 | C7: 396422 | D7: 540139 | E7: 511079 | F7: 508098 | G7: 988349
A8: 3. Revenue less expenses | B8: 28593 | C8: 143717 | D8: -29060 | E8: -2981 | F8: 480251 | G8: 2983109
A9: 8. Prior period adjustments | B9: not reported | C9: not reported | D9: not reported | E9: not reported | F9: not reported | G9: not reported
A10: 9. Other changes in net assets | B10: 0 | C10: 0 | D10: 0 | E10: 0 | F10: 0 | G10: 0
A11: 10. Net assets, end of year | B11: =SUM(B7,B8,B9,B10) | C11: =SUM(C7,C8,C9,C10) | D11: =SUM(D7,D8,D9,D10) | E11: =SUM(E7,E8,E9,E10) | F11: =SUM(F7,F8,F9,F10) | G11: =SUM(G7,G8,G9,G10)
A13: Part XI reconciles beginning to ending net assets. Ending net assets (line 10) is a live formula: beginning balance (line 4) + revenue less expenses (line 3) + prior-period adjustments (8) + other changes (9). Its tie-out to the filed line 10 (and to Part X line 32) is on the Sources & audit tab. Lines 5-7 (unrealized gains, donated services, investment expenses) are not filed by this entity.

Sheet Cash flow proxies
A1: Markleeville Water Company
A2: Cash Flow Proxies - derived (USD)
A3: Entity ID: cawc_0050 | Fiscal year ends June 30.
A5: PROXY ONLY. The source filings contain no statement of cash flows. Lines below are derived from the reported income statement and year-over-year balance-sheet changes; treat as directional estimates, not GAAP cash flows. The earliest year has no prior period, so its delta cells are blank.
A7: Proxy line (USD) | B7: FY2020 | C7: FY2021 | D7: FY2022 | E7: FY2023 | F7: FY2024 | G7: FY2025
A8: Operating
A9: Net income | B9: 28593 | C9: 143717 | D9: -29060 | E9: -2981 | F9: 480251 | G9: 2983109
A10: + Depreciation (reported) | B10: 7576 | C10: 7576 | D10: 7576 | E10: 7576 | F10: 7576 | G10: 7576
A11: − Δ Accounts receivable | C11: -84565 | D11: 74582
A12: − Δ Inventories
A13: − Δ Prepaid expenses | C13: -566 | D13: -401 | E13: -361 | F13: 342 | G13: -1736
A14: + Δ Accounts payable | C14: -3809
A15: Operating cash flow proxy | C15: 62353 | D15: 52697 | E15: 4234 | F15: 488169 | G15: 2988949
A17: Investing
A18: − Δ PP&E gross (capex proxy) | C18: 0 | D18: 0 | E18: 0 | F18: -470798 | G18: -3005583
A20: Financing
A21: Δ Mortgages & notes payable
A23: Reconciliation
A24: Δ Cash + temp. investments (actual) | C24: 62353 | D24: 52697 | E24: 15820 | F24: 8127 | G24: -5478
A26: The capex proxy assumes gross PP&E rises only via capital spending (it ignores disposals). 'Δ Cash + temp. investments (actual)' is the real reported change in liquid funds and is the most reliable line here; the operating/investing/financing proxies will not perfectly reconcile to it.

Sheet Ratios
A1: Markleeville Water Company
A2: Financial Ratios
A3: Entity ID: cawc_0050 | Fiscal year ends June 30.
A5: Ratio | B5: FY2020 | C5: FY2021 | D5: FY2022 | E5: FY2023 | F5: FY2024 | G5: FY2025
A6: Profitability (computed upstream)
A7: Operating margin (NI / revenue) | B7: 0.12763536 | C7: 0.24880977 | D7: -0.13337984 | E7: -0.016454704 | F7: 0.72870524 | G7: 0.94639081
A8: Expense ratio (expenses / revenue) | B8: 0.87236464 | C8: 0.75119023 | D8: 1.1333798 | E8: 1.0164547 | F8: 0.27129476 | G8: 0.053609193
A9: Return on assets (NI / assets) | B9: 0.071441243 | C9: 0.2660741 | D9: -0.056860094 | E9: -0.0058496631 | F9: 0.48591236 | G9: 0.75049146
A10: Revenue growth (YoY) | B10: 0.31426074 | C10: 1.5784101 | D10: -0.62280608 | E10: -0.16849188 | F10: 2.6378475 | G10: 3.7828
A12: Leverage & solvency
A13: Debt-to-assets (liab. / assets) | B13: 0.0095170039 | C13: 0 | D13: 0 | E13: 0.0029513228 | F13: 0 | G13: 0.00085939831
A14: Equity ratio (net assets / assets) | B14: 0.990483 | C14: 1 | D14: 1 | E14: 0.99704868 | F14: 1 | G14: 0.9991406
A16: Liquidity & asset profile (derived here)
A17: Current ratio (current assets / AP) | B17: 60.175899 | E17: 240.23205 | G17: 106.95316
A18: Cash ratio ((cash+temp inv.) / total liab.) | B18: 59.373851 | E18: 237.38364 | G18: 105.29098
A19: Asset age proxy (accum. deprec. / gross PP&E) | B19: 0.64634467 | C19: 0.66201112 | D19: 0.67767758 | E19: 0.69334403 | F19: 0.3592535 | G19: 0.088495799
A21: Upstream ratios are read from financials_annual; derived ratios are computed only where inputs are reported. Current ratio uses accounts payable as the current-liability proxy (the filings do not split current vs. long-term liabilities). Asset age proxy: a higher % implies older / more depreciated infrastructure.

Sheet Unit economics
A1: Markleeville Water Company
A2: Unit economics - per-customer revenue by category (USD)
A3: Entity ID: cawc_0050 | Fiscal year ends June 30.
A5: Every metric here is PER CUSTOMER (a metered service connection). It is not a per-member figure; the member (shareholder) count is a different denominator, shown in the denominator block. The visible cell shows the value and its classification; the numerator, denominator, formula, and rationale are in each metric's LOGIC popup.
A6: Per-customer denominator (service connections) | C6: State Water Board eAR Section 4
A7: Total annual revenue (eAR Section 8b B1.8) | C7: eAR Section 8b total annual revenue not reported for this system.
A8: Primary source
A10: Revenue categories (value, classification, per customer, share)
A11: Revenue category | B11: Classification | C11: Value (USD) | D11: Per customer | E11: Share of revenue
A12: Water sales revenue | B12: not reported | C12: not reported | D12: not reported | E12: not reported
A13: Assessment revenue (990 program-service revenue not matched to eAR water-rate revenue) | B13: IMPOSSIBLE | C13: IMPOSSIBLE | D13: IMPOSSIBLE | E13: IMPOSSIBLE
A14: Meter revenue | B14: not reported | C14: not reported | D14: not reported | E14: not reported
A15: Overage or tiered penalty revenue | B15: not reported | C15: not reported | D15: not reported | E15: not reported
A17: Water sales revenue - not reported
A18: Not reported: this system filed an eAR but no Section 8b revenue block, so there is no filed water-sales figure. Not fallen back to a different year.
A19: Reason: No filed eAR Section 8b water-rate revenue for this system.
A21: Assessment revenue (990 program-service revenue not matched to eAR water-rate revenue) - IMPOSSIBLE
A22: Not computed. A period-aligned residual is not possible for this filer.
A23: Reason: Not derivable. The eAR Section 8b is reporting year None while the Form 990 fiscal year ends None; the two period ends are not aligned, so a period-aligned residual cannot be computed.
A25: Meter revenue - not reported
A26: Not reported. This category is not built because doing so would double-count.
A27: Reason: The eAR Section 8a reports a base/meter rate PRICE, but the filing carries no meter revenue line and no tier volume, and the base charge is already inside the water-sales revenue (eAR Section 8b water rates). Building a separate meter figure would double-count. Not backed into from a total.
A29: Overage or tiered penalty revenue - not reported
A30: Not reported. This category is not built because doing so would double-count.
A31: Reason: The eAR Section 8a reports tiered/overage rate PRICES, but the filing carries no overage revenue and no tier consumption volume, and any overage billed is already inside the water-sales revenue. Building it would double-count. Not backed into from a total.

Sheet Rate structure
A1: Markleeville Water Company
A2: Rate structure and representative bill - eAR Section 8a
A3: Entity ID: cawc_0050 | Fiscal year ends June 30.
A5: This block is a rate-schedule illustration at defined usage levels. It is NOT billed revenue and not a claim about any real customer's usage. The revenue side of unit economics is the separate Unit Economics block.
A6: No filed eAR Section 8a rate schedule is staged for this system.

Sheet Operational metrics
A1: Markleeville Water Company
A2: Operational metrics - plant per acre, density, terrain
A3: Entity ID: cawc_0050 | Fiscal year ends June 30.
A5: Plant assets per acre
A6: Service-area acres | B6: 27.5 | C6: Geodesic area (WGS84 spherical excess) of the SABL service-area polygon.
A7: Fiscal year | B7: Gross plant per acre (primary) | C7: Net plant per acre
A8: FY2021 | B8: 17584.764 | C8: 5943.4545
A9: FY2022 | B9: 17584.764 | C9: 5667.9636
A10: FY2023 | B10: 17584.764 | C10: 5392.4727
A11: FY2024 | B11: 34704.691 | C11: 22236.909
A12: FY2025 | B12: 143998.62 | C12: 131255.35
A13: Infrastructure built per acre of service area. Gross plant per acre is the primary read because it measures how much plant the system has put in the ground per acre, and unlike net plant it does not fall over time purely because the assets depreciate on the books. Net plant per acre is shown alongside as the depreciated book value per acre.
A14: Formula: gross plant per acre = Form 990 Part X line 10a (land, buildings, and equipment, gross) / SABL service-area acres; net plant per acre uses Part X line 10c (net)
A15: Source lines: Form 990 Part X line 10a (gross) and line 10c (net); Geodesic area (WGS84 spherical excess) of the SABL service-area polygon.
A16: Confidence: medium. This is worked out from filed figures (a ratio, or a year-to-year change), so it is one step removed from the raw numbers.. Filed gross/net plant over the measured SABL service-area acreage.
A18: Connections per acre
A19: Connections per acre | B19: 6.07 | C19: 167 connections / 27.5 acres. CA State Water Board SABL SERVICE_CONNECTIONS; Geodesic area (WGS84 spherical excess) of the SABL service-area polygon.

Sheet Supply & weather
A1: Markleeville Water Company
A2: Supply and weather indicators (DWR water year)
A3: Entity ID: cawc_0050 | Fiscal year ends June 30.
A5: Reporting calendar: Different reporting periods. The DWR water year runs October 1 to September 30; this system's fiscal year ends June 30, so the two period ends are three months apart. Read the two side by side with that in mind. Neither series is recast: both are reported as filed. A water year is named for the calendar year it ends in, so WY2024 and FY2024 share a number without covering the same twelve months.
A7: Indicator | B7: WY2021 | C7: WY2022 | D7: WY2023 | E7: WY2024 | F7: WY2025
A8: Water-year type (Sacramento Valley) | B8: Critical | C8: Critical | D8: Wet | E8: Above Normal | F8: not reported
A9: Peak drought, Alpine County | B9: D3 | C9: D3 | D9: D3 | E9: D0 | F9: D0
A10: Precip, percent of normal (8-Station Index) | B10: 48 | C10: 86 | D10: 133 | E10: 96 | F10: 113
A11: Snowpack, April 1 percent of average | B11: 59% | C11: 38% | D11: 237% | E11: 110% | F11: 96%
A12: State Water Project allocation | B12: 5% | C12: 5% | D12: 100% | E12: 40% | F12: 50%

Sheet How this was built
A1: Markleeville Water Company
A2: How this was built - forensic lineage
A3: Entity ID: cawc_0050 | Fiscal year ends June 30.
A5: A plain account of the forensic lineage behind the hard-to-source metrics: what sources were checked, what was found, what was derived, and what could not be built and why. Every figure marked DERIVED or IMPOSSIBLE above is traceable to a line here.
A7: Water-sales revenue per customer - not reported
A8: Sources checked | B8: State Water Board eAR Section 8b (water-rate revenue B1.1/B1.2); State Water Board eAR Section 4 (connection count, same reporting year); audited financial statement (secondary cross-check, where published)
A9: What was found | B9: The eAR Section 8b reports water-rate revenue for reporting year None, so this is a DIRECT filed figure; per customer it is divided by the eAR Section 4 connection count for the same reporting year, so numerator and denominator share the year.
A11: Assessment revenue (residual) - IMPOSSIBLE
A12: Sources checked | B12: Form 990 Part VIII line 2 (program-service revenue); State Water Board eAR Section 8b (water-rate revenue B1.1/B1.2); eAR Section 8b filer comment (WRRevenueComments)
A13: What was found | B13: A period-aligned residual cannot be computed for this filer, so the metric is rendered IMPOSSIBLE rather than guessed.
A14: Caveat | B14: Not derivable. The eAR Section 8b is reporting year None while the Form 990 fiscal year ends None; the two period ends are not aligned, so a period-aligned residual cannot be computed.
A16: Meter revenue - not reported
A17: Sources checked | B17: State Water Board eAR Section 8a (rate prices); State Water Board eAR Section 8b (revenue lines); audited financial statement
A18: What was found | B18: The rate price exists in Section 8a but no revenue or tier volume is reported, and the base charge is already inside water sales.
A19: Caveat | B19: The eAR Section 8a reports a base/meter rate PRICE, but the filing carries no meter revenue line and no tier volume, and the base charge is already inside the water-sales revenue (eAR Section 8b water rates). Building a separate meter figure would double-count. Not backed into from a total.
A21: Overage / tiered-penalty revenue - not reported
A22: Sources checked | B22: State Water Board eAR Section 8a (rate prices); State Water Board eAR Section 8b (revenue lines); audited financial statement
A23: What was found | B23: The rate price exists in Section 8a but no revenue or tier volume is reported, and the base charge is already inside water sales.
A24: Caveat | B24: The eAR Section 8a reports tiered/overage rate PRICES, but the filing carries no overage revenue and no tier consumption volume, and any overage billed is already inside the water-sales revenue. Building it would double-count. Not backed into from a total.
A26: eAR Section 8b reporting-period basis - sourced
A27: Sources checked | B27: eAR Section 8b B0.1 (WRFinancialReportingPeriod); eAR Section 8b B0.2 (WRFiscalYearStartDate)
A28: What was found | B28: The reporting basis (fiscal vs calendar year) is read from the filer's own B0.1/B0.2 answer and staged verbatim, never hardcoded, so the 990 comparison and the residual are period-aligned.
A30: Member (shareholder) count denominator - not reported
A31: Sources checked | B31: Form 990 (no member count stated); company website
A32: What was found | B32: No filing states a member/shareholder count, so the per-member unit economics read not reported rather than borrowing the connection count.
A34: Water volume delivered (acre-feet) - not reported
A35: Sources checked | B35: Form 990 (not in the filing); Consumer Confidence Report; eAR Section 6 (PRA-gated)
A36: What was found | B36: Volume delivered in acre-feet is not in the Form 990 and the CCR states only a source mix, so the per-acre-foot metrics read not reported; the eAR Section 6 is named as the source still needed.

Sheet Anomaly Flags
A1: Markleeville Water Company
A2: Anomaly Flags (automated; kept separate from the clean statements)
A3: Entity ID: cawc_0050 | Fiscal year ends June 30.
A5: Material irregularities found automatically in the filed financials by the Hydronomics anomaly flagger. Each flag has two clearly separated layers. WHAT is mechanical, certain, and sourced: the exact filed lines, years, and amounts, carried as filed and never reconciled. WHY is attempted: the filing's own narrative is checked first, and when it states no reason a single best-guess hypothesis is shown, clearly labelled as a guess that is not in the filing and is not a verified figure.
A7: Flag: FY2025 total revenue swing
A8: Affected figure | B8: Operating revenue FY2025
A9: Confidence | B9: high
A10: What happened (filed, sourced) | B10: FY2025 total revenue rose to $3,152,090 from $659,047 in FY2024, a 378 percent move ($2,493,043 in absolute terms). Carried as filed and flagged as a documented anomaly, not smoothed.
A11: Source lines | B11: - total revenue: $659,047 FY2024, $3,152,090 FY2025
A12: Confidence reasoning | B12: A year-over-year move in a filed headline total that exceeds both the percentage and the dollar threshold; carried as filed.
A13: Why (not stated in the filing) | B13: The filing does not state a reason.
A14: Possible explanation (guess) | B14: Possible explanation, not stated in filing: a large one-year move in total revenue may reflect a one-time item or a change in how it was recorded. This is an educated guess, not something the filing actually says.

Sheet Sources & audit
A1: Markleeville Water Company
A2: Sources & audit - full provenance and tie-outs (kept off the statements so they read clean)
A3: Entity ID: cawc_0050 | Fiscal year ends June 30.
A5: Presentation standard: every figure on the statement tabs is verified to its source filing and shown clean. A cell the filing does not report reads "not reported" (never estimated, never guessed).
A6: Citations, confidence tiers, and the filed-vs-computed tie-out checks live on the "Sources & audit" tab, keyed by cell, so every number is fully traceable without cluttering the statements. These pages are ready to use as filed.
A8: A. Filing provenance (one row per staged extraction)
A9: Fiscal year | B9: Period end | C9: Filing type | D9: Confidence | E9: Extraction ID | F9: Object ID | G9: Extracted by | H9: Extracted at | I9: Source URL
A10: FY2020 | B10: 2020-06-30 | C10: 990 | D10: high | E10: 5d7c3dfe-e723-4c9d-8cea-0f8f21134787 | F10: 202110509349301606 | G10: claude-opus-5 | H10: 2026-09-14T20:40:27+00:00 | I10: https://apps.irs.gov/pub/epostcard/990/xml/2021/2021_TEOS_XML_01A.zip#202110509349301606_public.xml
A11: FY2021 | B11: 2021-06-30 | C11: 990 | D11: high | E11: 5feed0d8-6de4-4be5-ab7a-1c4ae553c2c4 | F11: 202123199349308122 | G11: claude-opus-5 | H11: 2026-09-14T20:40:27+00:00 | I11: https://apps.irs.gov/pub/epostcard/990/xml/2021/2021_TEOS_XML_01A.zip#202123199349308122_public.xml
A12: FY2022 | B12: 2022-06-30 | C12: 990 | D12: high | E12: bebf469d-51d5-46d9-aa71-216659373237 | F12: 202202699349301405 | G12: claude-opus-5 | H12: 2026-09-14T20:40:27+00:00 | I12: https://apps.irs.gov/pub/epostcard/990/xml/2022/2022_TEOS_XML_01A.zip#202202699349301405_public.xml
A13: FY2023 | B13: 2023-06-30 | C13: 990 | D13: high | E13: 060aac89-9584-4be4-b9b4-3dca3cbd0958 | F13: 202342829349301264 | G13: claude-opus-5 | H13: 2026-09-14T20:40:27+00:00 | I13: https://apps.irs.gov/pub/epostcard/990/xml/2023/2023_TEOS_XML_10A.zip#202342829349301264_public.xml
A14: FY2024 | B14: 2024-06-30 | C14: 990 | D14: high | E14: cc16819b-ea4a-4cec-ae3c-35095d0612e8 | F14: 202403239349301300 | G14: claude-opus-5 | H14: 2026-09-14T20:40:27+00:00 | I14: https://apps.irs.gov/pub/epostcard/990/xml/2024/2024_TEOS_XML_11A.zip#202403239349301300_public.xml
A15: FY2025 | B15: 2025-06-30 | C15: 990 | D15: high | E15: 00562668-0800-45fe-9c57-a5731b1afc7e | F15: 202503179349306750 | G15: claude-opus-5 | H15: 2026-09-14T20:40:27+00:00 | I15: https://apps.irs.gov/pub/epostcard/990/xml/2025/2025_TEOS_XML_11A.zip#202503179349306750_public.xml
A17: B. Figure citations (every figure on the statement tabs, keyed by cell)
A18: Tab | B18: Cell | C18: Line item | D18: Form 990 line | E18: Key path | F18: Confidence | G18: As filed
A19: Financial Statements | B19: B73 | C19: 11a. Gross income from members or shareholders | D19: 11a | E19: part_v_other_irs_filings.members_and_shareholders_gross_income | F19: high | G19: 175707
A20: Financial Statements | B20: C73 | C20: 11a. Gross income from members or shareholders | D20: 11a | E20: part_v_other_irs_filings.members_and_shareholders_gross_income | F20: high | G20: 263321
A21: Financial Statements | B21: D73 | C21: 11a. Gross income from members or shareholders | D21: 11a | E21: part_v_other_irs_filings.members_and_shareholders_gross_income | F21: high | G21: 141899
A22: Financial Statements | B22: E73 | C22: 11a. Gross income from members or shareholders | D22: 11a | E22: part_v_other_irs_filings.members_and_shareholders_gross_income | F22: high | G22: 181146
A23: Financial Statements | B23: F73 | C23: 11a. Gross income from members or shareholders | D23: 11a | E23: part_v_other_irs_filings.members_and_shareholders_gross_income | F23: high | G23: 191253
A24: Financial Statements | B24: G73 | C24: 11a. Gross income from members or shareholders | D24: 11a | E24: part_v_other_irs_filings.members_and_shareholders_gross_income | F24: high | G24: 180603
A25: Financial Statements | B25: B74 | C25: 11b. Gross income from other sources | D25: 11b | E25: part_v_other_irs_filings.other_sources_gross_income | F25: high | G25: 48314
A26: Financial Statements | B26: C74 | C26: 11b. Gross income from other sources | D26: 11b | E26: part_v_other_irs_filings.other_sources_gross_income | F26: high | G26: 314285
A27: Financial Statements | B27: D74 | C27: 11b. Gross income from other sources | D27: 11b | E27: part_v_other_irs_filings.other_sources_gross_income | F27: high | G27: 75974
A28: Financial Statements | B28: E74 | C28: 11b. Gross income from other sources | D28: 11b | E28: part_v_other_irs_filings.other_sources_gross_income | F28: high | G28: 18
A29: Financial Statements | B29: F74 | C29: 11b. Gross income from other sources | D29: 11b | E29: part_v_other_irs_filings.other_sources_gross_income | F29: high | G29: 467794
A30: Financial Statements | B30: G74 | C30: 11b. Gross income from other sources | D30: 11b | E30: part_v_other_irs_filings.other_sources_gross_income | F30: high | G30: 2971441
... A169: Net-assets reconciliation | B169: G10 | C169: 9. Other changes in net assets | D169: Part XI line 9 | E169: part_xi_reconciliation.other_changes_net_assets | F169: high | G169: 0
A171: C. Tie-out checks (filed vs computed; any nonzero variance is flagged red)
A172: Tab | B172: Check | C172: Fiscal year | D172: Filed | E172: Computed | F172: Variance (computed - filed)
A173: Revenue (detail) | B173: 12. Total revenue | C173: FY2020 | D173: 224021 | E173: ='Revenue (detail)'!B13 | F173: =E173-D173
A174: Revenue (detail) | B174: 12. Total revenue | C174: FY2021 | D174: 577618 | E174: ='Revenue (detail)'!C13 | F174: =E174-D174
A175: Revenue (detail) | B175: 12. Total revenue | C175: FY2022 | D175: 217874 | E175: ='Revenue (detail)'!D13 | F175: =E175-D175
A176: Revenue (detail) | B176: 12. Total revenue | C176: FY2023 | D176: 181164 | E176: ='Revenue (detail)'!E13 | F176: =E176-D176
A177: Revenue (detail) | B177: 12. Total revenue | C177: FY2024 | D177: 659047 | E177: ='Revenue (detail)'!F13 | F177: =E177-D177
A178: Revenue (detail) | B178: 12. Total revenue | C178: FY2025 | D178: 3152090 | E178: ='Revenue (detail)'!G13 | F178: =E178-D178
A179: Revenue (detail) | B179: 2g program service revenue = sum of lines 2a-2f (FY2025) | C179: FY2025 | D179: 180603 | E179: =SUM('Revenue (detail)'!C17:C17) | F179: =E179-D179
A180: Operating expenses (detail) | B180: 25. Total functional expenses | C180: FY2020 | D180: 195428 | E180: ='Operating expenses (detail)'!B26 | F180: =E180-D180
A181: Operating expenses (detail) | B181: 25. Total functional expenses | C181: FY2021 | D181: 433901 | E181: ='Operating expenses (detail)'!C26 | F181: =E181-D181
A182: Operating expenses (detail) | B182: 25. Total functional expenses | C182: FY2022 | D182: 246934 | E182: ='Operating expenses (detail)'!D26 | F182: =E182-D182
...

Sheet Provenance
A1: Build provenance | B1: Built from source commit d418ffb17485 (2026-10-06); source fingerprint a75a8eee82c65cf7; 192 companies (179 retail mutual, 4 irrigation mutual, 3 mutual, no PWSID, purpose not stated, 2 frozen non-mutual (special district), 2 wholesale mutual, 1 frozen non-mutual (investor-owned), 1 frozen non-mutual (municipal)); 91 gates; build id 3d08d6d2a855.
A2: source_commit | B2: d418ffb174855ab78000d391d42f898397b0d8aa
A3: source_commit_date | B3: 2026-10-06
A4: source_fingerprint | B4: a75a8eee82c65cf7096931f06e18affdc28686a02895b46538e7298b57c04d94
A5: gate_count | B5: 91
A6: build_id | B6: 3d08d6d2a855
A7: registry: frozen non-mutual (investor-owned) | B7: 1
A8: registry: frozen non-mutual (municipal) | B8: 1
A9: registry: frozen non-mutual (special district) | B9: 2
A10: registry: irrigation mutual | B10: 4
A11: registry: mutual, no PWSID, purpose not stated | B11: 3
A12: registry: retail mutual | B12: 179
A13: registry: wholesale mutual | B13: 2
