Workbook

Sheet Summary
A1: Lundy Mutual Water Co
A2: Financial Summary - multi-year overview (USD)
A3: Entity ID: cawc_0180 | Fiscal year ends December 31.
A5: Presentation standard: every figure on the statement tabs is verified to its source filing and shown clean. A cell the filing does not report reads "not reported" (never estimated, never guessed).
A6: Citations, confidence tiers, and the filed-vs-computed tie-out checks live on the "Sources & audit" tab, keyed by cell, so every number is fully traceable without cluttering the statements. These pages are ready to use as filed.
A8: Metric | B8: FY2021 | C8: FY2022 | D8: FY2023 | E8: FY2024
A9: Operating results (USD)
A10: Total revenue | B10: 81522 | C10: 81328 | D10: 76944 | E10: 107522
A11: Total expenses | B11: 50826 | C11: 90696 | D11: 72245 | E11: 121879
A12: Net income | B12: 30696 | C12: -9368 | D12: 4699 | E12: -14357
A14: Financial position (USD, end of year)
A15: Total assets | B15: 304221 | C15: 291135 | D15: 278527 | E15: 567259
A16: Total liabilities | B16: 0 | C16: 20601 | D16: 3293 | E16: 306382
A17: Net assets | B17: 304221 | C17: 270534 | D17: 275234 | E17: 260877
A19: Headline ratios
A20: Operating margin | B20: 0.3765364 | C20: -0.11518788 | D20: 0.061070389 | E20: -0.13352616
A21: Revenue growth (YoY) | E21: 0.39740591
A22: Return on assets | B22: 0.10090033 | C22: -0.032177512 | D22: 0.016870896 | E22: -0.025309427
A24: Figures as reported in source filings (full provenance on the Sources & audit tab). Parentheses denote negatives; ratios are computed upstream in financials_annual.

Sheet Notes
A1: Notes
A2: Human annotations from the versioned store (data/notes/). Annotations only: they never change a reported figure or a confidence tier.
A4: Date | B4: Tag | C4: Author | D4: Note
A5: No notes recorded yet.

Sheet Financial Statements
A1: Lundy Mutual Water Co
A2: Financial Statements - income statement, balance sheet, cash flow, member income test (USD)
A3: Entity ID: cawc_0180 | Fiscal year ends December 31.
A5: INCOME STATEMENT - as reported (USD)
A6: Line item | B6: FY2021 | C6: FY2022 | D6: FY2023 | E6: FY2024
A7: Revenue
A8: Program service revenue | E8: 105951
A9: Investment income | E9: 1571
A10: Net rental income
A11: Net gain/(loss) on investment sales
A12: Other revenue
A13: Contributions & grants
A14: Total revenue | E14: 107522
A16: Expenses
A17: Depreciation | E17: 11271
A18: Interest expense
A19: Total expenses | B19: 50826 | C19: 90696 | D19: 72245 | E19: 121879
A21: Net income | B21: 30696 | C21: -9368 | D21: 4699 | E21: -14357
A24: BALANCE SHEET - as reported (USD, end of year)
A25: Line item | B25: FY2021 | C25: FY2022 | D25: FY2023 | E25: FY2024
A26: Assets
A27: Cash | B27: 246454 | C27: 248174 | D27: 241752 | E27: 540947
A28: Savings & temporary investments
A29: Accounts receivable | E29: 3251
A30: Inventories | E30: 5402
A31: Prepaid expenses
A32: Property, plant & equipment (gross) | E32: 329863
A33: Less: accumulated depreciation | E33: -312204
A34: Net property, plant & equipment | B34: 46729 | C34: 33502 | D34: 8318 | E34: 17659
A35: Total assets | B35: 304221 | C35: 291135 | D35: 278527 | E35: 567259
A37: Liabilities
A38: Accounts payable | E38: 15266
A39: Mortgages & notes payable
A40: Total liabilities | B40: 0 | C40: 20601 | D40: 3293 | E40: 306382
A42: Net Assets / Equity
A43: Capital stock | E43: 1210
A44: Paid-in capital | E44: 0
A45: Retained earnings | E45: 259667
A46: Net assets | B46: 304221 | C46: 270534 | D46: 275234 | E46: 260877
A49: CASH FLOW - derived proxy (USD)
...

Sheet Balance Sheet
A1: Lundy Mutual Water Co
A2: Balance Sheet - as reported (USD, end of year)
A3: Entity ID: cawc_0180 | Fiscal year ends December 31.
A5: Line item | B5: FY2021 | C5: FY2022 | D5: FY2023 | E5: FY2024
A6: Assets
A7: Cash | B7: 246454 | C7: 248174 | D7: 241752 | E7: 540947
A8: Savings & temporary investments
A9: Accounts receivable | E9: 3251
A10: Inventories | E10: 5402
A11: Prepaid expenses
A12: Property, plant & equipment (gross) | E12: 329863
A13: Less: accumulated depreciation | E13: -312204
A14: Net property, plant & equipment | B14: 46729 | C14: 33502 | D14: 8318 | E14: 17659
A15: Total assets | B15: 304221 | C15: 291135 | D15: 278527 | E15: 567259
A17: Liabilities
A18: Accounts payable | E18: 15266
A19: Mortgages & notes payable
A20: Total liabilities | B20: 0 | C20: 20601 | D20: 3293 | E20: 306382
A22: Net Assets / Equity
A23: Capital stock | E23: 1210
A24: Paid-in capital | E24: 0
A25: Retained earnings | E25: 259667
A26: Net assets | B26: 304221 | C26: 270534 | D26: 275234 | E26: 260877
A28: Balance check (assets − liab. − net assets) | B28: 0 | C28: 0 | D28: 0 | E28: 0
A30: Net PP&E is the reported ppe_net column (gross less accumulated depreciation). The balance check should be ~0 where all three totals are reported; a non-zero value flags a reporting or extraction discrepancy worth reviewing.

Sheet Officers & contractors
A1: Lundy Mutual Water Co
A2: Officers, Directors & Contractors - Form 990 Part VII (FY2024; USD)
A3: Entity ID: cawc_0180 | Fiscal year ends December 31.
A5: Section A - Officers, directors, trustees, key employees
A6: Name | B6: Title | C6: Reportable comp (org) | D6: Reportable comp (related) | E6: Other comp | F6: Total compensation
A7: D DULEN | B7: DIR | C7: 0 | D7: 0 | E7: 0 | F7: 0
A8: K SEIBERLING | B8: VP | C8: 0 | D8: 0 | E8: 0 | F8: 0
A9: M VERBA | B9: TREAS | C9: 0 | D9: 0 | E9: 0 | F9: 0
A10: T DUBLINO | B10: PRES | C10: 0 | D10: 0 | E10: 0 | F10: 0
A11: D CARLE | B11: DIR | C11: 0 | D11: 0 | E11: 0 | F11: 0
A13: Section B - Independent contractors (over $100,000)
A14: Contractor | B14: Services | C14: Compensation
A16: Section A lists every officer, director, trustee and key employee filed for the latest year; the two with the highest total compensation are highlighted. Total compensation is computed (reportable org + related + other). Section B lists each independent contractor paid over $100,000; the return reports 0 such contractor(s). Source and confidence for every figure are on the Sources & audit tab.

Sheet Revenue (detail)
A1: Lundy Mutual Water Co
A2: Revenue - Form 990 Part VIII (USD)
A3: Entity ID: cawc_0180 | Fiscal year ends December 31.
A5: Part VIII line | B5: FY2024
A6: Revenue by category
A7: 1h. Total contributions, gifts, grants | B7: not reported
A8: 2g. Total program service revenue | B8: 105951
A9: 3. Investment income | B9: 1571
A10: 6d. Net rental income | B10: not reported
A11: 7d. Net gain/(loss) from investment sales | B11: not reported
A12: 11e. Other revenue | B12: not reported
A13: 12. Total revenue | B13: =SUM(B7:B12)
A15: Program service revenue detail - FY2024 (lines 2a-2f)
A16: Description | B16: Business code | C16: Total revenue
A17: WATER RELATED REVENUES | B17: 221000 | C17: 76232
A18: WATER GRABT | B18: 221000 | C18: 29119
A19: OTHER | B19: 221000 | C19: 600
A20: Revenue category subtotals are as filed. Total revenue (line 12) is a live SUM of the category cells above; its tie-out to the filed total is on the Sources & audit tab. Program service revenue detail is shown for the latest year, with its sum-to-line-2g check on that same audit tab.

Sheet Operating expenses (detail)
A1: Lundy Mutual Water Co
A2: Statement of Functional Expenses - Form 990 Part IX (USD)
A3: Entity ID: cawc_0180 | Fiscal year ends December 31.
A5: Part IX line (column A Total) | B5: FY2024
A6: Functional expenses, column A Total - by year
A7: 7. Other salaries and wages | B7: 13711
A8: 11g. Fees for services: other | B8: 12580
A9: 13. Office expenses | B9: 1152
A10: 14. Information technology | B10: 1648
A11: 16. Occupancy | B11: 14451
A12: 17. Travel | B12: 952
A13: 22. Depreciation, depletion, and amortization | B13: 11271
A14: 23. Insurance | B14: 5073
A15: 24. WATER RELATED | B15: 31122
A16: 24. GRANT COST | B16: 29119
A17: 24. FRANCHISE TAX | B17: 800
A18: 24e. All other expenses | B18: not reported
A19: 25. Total functional expenses | B19: =SUM(B7:B18)
A21: Functional column split - FY2024
A22: Not reported. This filer reports only column A (Total) of Part IX; the program / management / fundraising split (columns B-D) is not filed, so it is left as not reported rather than shown empty or inferred.
A23: Top block: each Part IX line, column A (Total), by year, as filed. Total functional expenses (line 25) is a live SUM of the line cells; its tie-out to the filed total is on the Sources & audit tab. Filer-itemized 24a-24d rows show the most recent year's as-filed wording; rows are aligned across years case-insensitively with collapsed spacing, so a line filed only in a different capitalization or spacing shares one row, while genuinely different wording stays a separate row (every as-filed variant is recorded on the Sources & audit tab). This filer reports only column A (Total); the program / management / fundraising split (columns B-D) is not reported. Lines this filer does not report are omitted rather than shown empty.

Sheet Balance sheet (detail)
A1: Lundy Mutual Water Co
A2: Balance Sheet - Form 990 Part X (end of year, USD)
A3: Entity ID: cawc_0180 | Fiscal year ends December 31.
A5: Part X line (column B, EOY) | B5: FY2024
A6: Assets
A7: 1. Cash - non-interest-bearing | B7: 540947
A8: 4. Accounts receivable, net | B8: 3251
A9: 8. Inventories for sale or use | B9: 5402
A10: 10c. Land, buildings, and equipment, net | B10: 17659
A11: 16. Total assets | B11: =SUM(B7:B10)
A13: Liabilities
A14: 17. Accounts payable and accrued expenses | B14: 15266
A15: 19. Deferred revenue | B15: 291116
A16: 26. Total liabilities | B16: =SUM(B14:B15)
A18: Net assets / fund balances
A19: 29. Capital stock or trust principal | B19: 1210
A20: 30. Paid-in or capital surplus | B20: 0
A21: 31. Retained earnings / accumulated funds | B21: 259667
A22: 32. Total net assets / fund balances | B22: =SUM(B19:B21)
A24: Every Part X line is end-of-year (column B), as filed. Section totals (lines 16 / 26 / 32) are live SUMs of the lines above; their tie-outs and the balance-sheet identity (16 = 26 + 32) are on the Sources & audit tab. This filer files as a non-FASB mutual, so net assets sit on lines 29-31 (capital stock / paid-in capital / retained earnings); lines this filer does not report are omitted. Lines 10a/10b net into line 10c (shown).

Sheet Net-assets reconciliation
A1: Lundy Mutual Water Co
A2: Reconciliation of Net Assets - Form 990 Part XI (USD)
A3: Entity ID: cawc_0180 | Fiscal year ends December 31.
A5: Part XI line | B5: FY2024
A6: Reconciliation
A7: 4. Net assets, beginning of year | B7: 275234
A8: 3. Revenue less expenses | B8: -14357
A9: 8. Prior period adjustments | B9: not reported
A10: 9. Other changes in net assets | B10: 0
A11: 10. Net assets, end of year | B11: =SUM(B7,B8,B9,B10)
A13: Part XI reconciles beginning to ending net assets. Ending net assets (line 10) is a live formula: beginning balance (line 4) + revenue less expenses (line 3) + prior-period adjustments (8) + other changes (9). Its tie-out to the filed line 10 (and to Part X line 32) is on the Sources & audit tab. Lines 5-7 (unrealized gains, donated services, investment expenses) are not filed by this entity.

Sheet Cash flow proxies
A1: Lundy Mutual Water Co
A2: Cash Flow Proxies - derived (USD)
A3: Entity ID: cawc_0180 | Fiscal year ends December 31.
A5: PROXY ONLY. The source filings contain no statement of cash flows. Lines below are derived from the reported income statement and year-over-year balance-sheet changes; treat as directional estimates, not GAAP cash flows. The earliest year has no prior period, so its delta cells are blank.
A7: Proxy line (USD) | B7: FY2021 | C7: FY2022 | D7: FY2023 | E7: FY2024
A8: Operating
A9: Net income | B9: 30696 | C9: -9368 | D9: 4699 | E9: -14357
A10: + Depreciation (reported) | E10: 11271
A11: − Δ Accounts receivable
A12: − Δ Inventories
A13: − Δ Prepaid expenses
A14: + Δ Accounts payable
A15: Operating cash flow proxy | C15: -9368 | D15: 4699 | E15: -3086
A17: Investing
A18: − Δ PP&E gross (capex proxy)
A20: Financing
A21: Δ Mortgages & notes payable
A23: Reconciliation
A24: Δ Cash + temp. investments (actual) | C24: 1720 | D24: -6422 | E24: 299195
A26: The capex proxy assumes gross PP&E rises only via capital spending (it ignores disposals). 'Δ Cash + temp. investments (actual)' is the real reported change in liquid funds and is the most reliable line here; the operating/investing/financing proxies will not perfectly reconcile to it.

Sheet Ratios
A1: Lundy Mutual Water Co
A2: Financial Ratios
A3: Entity ID: cawc_0180 | Fiscal year ends December 31.
A5: Ratio | B5: FY2021 | C5: FY2022 | D5: FY2023 | E5: FY2024
A6: Profitability (computed upstream)
A7: Operating margin (NI / revenue) | B7: 0.3765364 | C7: -0.11518788 | D7: 0.061070389 | E7: -0.13352616
A8: Expense ratio (expenses / revenue) | B8: 0.6234636 | C8: 1.1151879 | D8: 0.93892961 | E8: 1.1335262
A9: Return on assets (NI / assets) | B9: 0.10090033 | C9: -0.032177512 | D9: 0.016870896 | E9: -0.025309427
A10: Revenue growth (YoY) | E10: 0.39740591
A12: Leverage & solvency
A13: Debt-to-assets (liab. / assets) | B13: 0 | C13: 0.070760987 | D13: 0.011822911 | E13: 0.54010954
A14: Equity ratio (net assets / assets) | B14: 1 | C14: 0.92923901 | D14: 0.98817709 | E14: 0.45989046
A16: Liquidity & asset profile (derived here)
A17: Current ratio (current assets / AP) | E17: 36.001572
A18: Cash ratio ((cash+temp inv.) / total liab.) | C18: 12.046697 | D18: 73.413908 | E18: 1.7655965
A19: Asset age proxy (accum. deprec. / gross PP&E) | E19: 0.94646565
A21: Upstream ratios are read from financials_annual; derived ratios are computed only where inputs are reported. Current ratio uses accounts payable as the current-liability proxy (the filings do not split current vs. long-term liabilities). Asset age proxy: a higher % implies older / more depreciated infrastructure.

Sheet Unit economics
A1: Lundy Mutual Water Co
A2: Unit economics - per-customer revenue by category (USD)
A3: Entity ID: cawc_0180 | Fiscal year ends December 31.
A5: Every metric here is PER CUSTOMER (a metered service connection). It is not a per-member figure; the member (shareholder) count is a different denominator, shown in the denominator block. The visible cell shows the value and its classification; the numerator, denominator, formula, and rationale are in each metric's LOGIC popup.
A6: Per-customer denominator (service connections) | C6: State Water Board eAR Section 4
A7: Total annual revenue (eAR Section 8b B1.8) | C7: eAR Section 8b total annual revenue not reported for this system.
A8: Primary source
A10: Revenue categories (value, classification, per customer, share)
A11: Revenue category | B11: Classification | C11: Value (USD) | D11: Per customer | E11: Share of revenue
A12: Water sales revenue | B12: not reported | C12: not reported | D12: not reported | E12: not reported
A13: Assessment revenue (990 program-service revenue not matched to eAR water-rate revenue) | B13: IMPOSSIBLE | C13: IMPOSSIBLE | D13: IMPOSSIBLE | E13: IMPOSSIBLE
A14: Meter revenue | B14: not reported | C14: not reported | D14: not reported | E14: not reported
A15: Overage or tiered penalty revenue | B15: not reported | C15: not reported | D15: not reported | E15: not reported
A17: Water sales revenue - not reported
A18: Not reported: this system filed an eAR but no Section 8b revenue block, so there is no filed water-sales figure. Not fallen back to a different year.
A19: Reason: No filed eAR Section 8b water-rate revenue for this system.
A21: Assessment revenue (990 program-service revenue not matched to eAR water-rate revenue) - IMPOSSIBLE
A22: Not computed. A period-aligned residual is not possible for this filer.
A23: Reason: Not derivable. The eAR Section 8b is reporting year None while the Form 990 fiscal year ends None; the two period ends are not aligned, so a period-aligned residual cannot be computed.
A25: Meter revenue - not reported
A26: Not reported. This category is not built because doing so would double-count.
A27: Reason: The eAR Section 8a reports a base/meter rate PRICE, but the filing carries no meter revenue line and no tier volume, and the base charge is already inside the water-sales revenue (eAR Section 8b water rates). Building a separate meter figure would double-count. Not backed into from a total.
A29: Overage or tiered penalty revenue - not reported
A30: Not reported. This category is not built because doing so would double-count.
A31: Reason: The eAR Section 8a reports tiered/overage rate PRICES, but the filing carries no overage revenue and no tier consumption volume, and any overage billed is already inside the water-sales revenue. Building it would double-count. Not backed into from a total.

Sheet Rate structure
A1: Lundy Mutual Water Co
A2: Rate structure and representative bill - eAR Section 8a
A3: Entity ID: cawc_0180 | Fiscal year ends December 31.
A5: This block is a rate-schedule illustration at defined usage levels. It is NOT billed revenue and not a claim about any real customer's usage. The revenue side of unit economics is the separate Unit Economics block.
A6: No filed eAR Section 8a rate schedule is staged for this system.

Sheet Operational metrics
A1: Lundy Mutual Water Co
A2: Operational metrics - plant per acre, density, terrain
A3: Entity ID: cawc_0180 | Fiscal year ends December 31.
A5: Plant assets per acre
A6: Service-area acres | B6: 45 | C6: Geodesic area (WGS84 spherical excess) of the SABL service-area polygon.
A7: Fiscal year | B7: Gross plant per acre (primary) | C7: Net plant per acre
A8: FY2021 | C8: 1038.4222
A9: FY2022 | C9: 744.4889
A10: FY2023 | C10: 184.8444
A11: FY2024 | B11: 7330.2889 | C11: 392.4222
A12: Infrastructure built per acre of service area. Gross plant per acre is the primary read because it measures how much plant the system has put in the ground per acre, and unlike net plant it does not fall over time purely because the assets depreciate on the books. Net plant per acre is shown alongside as the depreciated book value per acre.
A13: Formula: gross plant per acre = Form 990 Part X line 10a (land, buildings, and equipment, gross) / SABL service-area acres; net plant per acre uses Part X line 10c (net)
A14: Source lines: Form 990 Part X line 10a (gross) and line 10c (net); Geodesic area (WGS84 spherical excess) of the SABL service-area polygon.
A15: Confidence: medium. This is worked out from filed figures (a ratio, or a year-to-year change), so it is one step removed from the raw numbers.. Filed gross/net plant over the measured SABL service-area acreage.
A17: Connections per acre
A18: Connections per acre | B18: 2.16 | C18: 97 connections / 45.0 acres. CA State Water Board SABL SERVICE_CONNECTIONS; Geodesic area (WGS84 spherical excess) of the SABL service-area polygon.

Sheet Supply & weather
A1: Lundy Mutual Water Co
A2: Supply and weather indicators (DWR water year)
A3: Entity ID: cawc_0180 | Fiscal year ends December 31.
A5: Reporting calendar: Different reporting periods. The DWR water year runs October 1 to September 30; this system's fiscal year ends December 31, so the two period ends are three months apart. Read the two side by side with that in mind. Neither series is recast: both are reported as filed. A water year is named for the calendar year it ends in, so WY2024 and FY2024 share a number without covering the same twelve months.
A7: Indicator | B7: WY2021 | C7: WY2022 | D7: WY2023 | E7: WY2024
A8: Water-year type (Sacramento Valley) | B8: Critical | C8: Critical | D8: Wet | E8: Above Normal
A9: Peak drought, county County | B9: not reported | C9: not reported | D9: not reported | E9: not reported
A10: Precip, percent of normal (8-Station Index) | B10: 48 | C10: 86 | D10: 133 | E10: 96
A11: Snowpack, April 1 percent of average | B11: 59% | C11: 38% | D11: 237% | E11: 110%
A12: State Water Project allocation | B12: 5% | C12: 5% | D12: 100% | E12: 40%

Sheet How this was built
A1: Lundy Mutual Water Co
A2: How this was built - forensic lineage
A3: Entity ID: cawc_0180 | Fiscal year ends December 31.
A5: A plain account of the forensic lineage behind the hard-to-source metrics: what sources were checked, what was found, what was derived, and what could not be built and why. Every figure marked DERIVED or IMPOSSIBLE above is traceable to a line here.
A7: Water-sales revenue per customer - not reported
A8: Sources checked | B8: State Water Board eAR Section 8b (water-rate revenue B1.1/B1.2); State Water Board eAR Section 4 (connection count, same reporting year); audited financial statement (secondary cross-check, where published)
A9: What was found | B9: The eAR Section 8b reports water-rate revenue for reporting year None, so this is a DIRECT filed figure; per customer it is divided by the eAR Section 4 connection count for the same reporting year, so numerator and denominator share the year.
A11: Assessment revenue (residual) - IMPOSSIBLE
A12: Sources checked | B12: Form 990 Part VIII line 2 (program-service revenue); State Water Board eAR Section 8b (water-rate revenue B1.1/B1.2); eAR Section 8b filer comment (WRRevenueComments)
A13: What was found | B13: A period-aligned residual cannot be computed for this filer, so the metric is rendered IMPOSSIBLE rather than guessed.
A14: Caveat | B14: Not derivable. The eAR Section 8b is reporting year None while the Form 990 fiscal year ends None; the two period ends are not aligned, so a period-aligned residual cannot be computed.
A16: Meter revenue - not reported
A17: Sources checked | B17: State Water Board eAR Section 8a (rate prices); State Water Board eAR Section 8b (revenue lines); audited financial statement
A18: What was found | B18: The rate price exists in Section 8a but no revenue or tier volume is reported, and the base charge is already inside water sales.
A19: Caveat | B19: The eAR Section 8a reports a base/meter rate PRICE, but the filing carries no meter revenue line and no tier volume, and the base charge is already inside the water-sales revenue (eAR Section 8b water rates). Building a separate meter figure would double-count. Not backed into from a total.
A21: Overage / tiered-penalty revenue - not reported
A22: Sources checked | B22: State Water Board eAR Section 8a (rate prices); State Water Board eAR Section 8b (revenue lines); audited financial statement
A23: What was found | B23: The rate price exists in Section 8a but no revenue or tier volume is reported, and the base charge is already inside water sales.
A24: Caveat | B24: The eAR Section 8a reports tiered/overage rate PRICES, but the filing carries no overage revenue and no tier consumption volume, and any overage billed is already inside the water-sales revenue. Building it would double-count. Not backed into from a total.
A26: eAR Section 8b reporting-period basis - sourced
A27: Sources checked | B27: eAR Section 8b B0.1 (WRFinancialReportingPeriod); eAR Section 8b B0.2 (WRFiscalYearStartDate)
A28: What was found | B28: The reporting basis (fiscal vs calendar year) is read from the filer's own B0.1/B0.2 answer and staged verbatim, never hardcoded, so the 990 comparison and the residual are period-aligned.
A30: Member (shareholder) count denominator - not reported
A31: Sources checked | B31: Form 990 (no member count stated); company website
A32: What was found | B32: No filing states a member/shareholder count, so the per-member unit economics read not reported rather than borrowing the connection count.
A34: Water volume delivered (acre-feet) - not reported
A35: Sources checked | B35: Form 990 (not in the filing); Consumer Confidence Report; eAR Section 6 (PRA-gated)
A36: What was found | B36: Volume delivered in acre-feet is not in the Form 990 and the CCR states only a source mix, so the per-acre-foot metrics read not reported; the eAR Section 6 is named as the source still needed.

Sheet Anomaly Flags
A1: Lundy Mutual Water Co
A2: Anomaly Flags (automated; kept separate from the clean statements)
A3: Entity ID: cawc_0180 | Fiscal year ends December 31.
A5: Material irregularities found automatically in the filed financials by the Hydronomics anomaly flagger. Each flag has two clearly separated layers. WHAT is mechanical, certain, and sourced: the exact filed lines, years, and amounts, carried as filed and never reconciled. WHY is attempted: the filing's own narrative is checked first, and when it states no reason a single best-guess hypothesis is shown, clearly labelled as a guess that is not in the filing and is not a verified figure.
A7: Flag: FY2022 opening net assets differ from FY2021 closing
A8: Affected figure | B8: Net assets FY2022
A9: Confidence | B9: high
A10: What happened (filed, sourced) | B10: The company filed $279,902 as its beginning net assets for FY2022 and $304,221 as its ending net assets for FY2021, a difference of $-24,319. Both figures are carried exactly as each year's own filing reports them. Neither is adjusted to match the other.
A11: Source lines | B11: - FY2022 net assets, beginning of year (as filed): $279,902 - FY2021 net assets, end of year (as filed): $304,221 - Difference: $-24,319
A12: Confidence reasoning | B12: Both are direct filed line items read from two different returns, so the difference between them is high confidence as an observation. What caused it is not stated on either form.
A13: Why (not stated in the filing) | B13: The filing does not state a reason.
A14: Possible explanation (guess) | B14: Possible explanation, not stated in filing: a beginning balance that differs from the prior year's ending balance usually means the earlier year was restated, or a balance-sheet line was reclassified between the two filings. This is an educated guess, not something either filing says.
A16: Flag: FY2023 opening net assets differ from FY2022 closing
A17: Affected figure | B17: Net assets FY2023
A18: Confidence | B18: high
A19: What happened (filed, sourced) | B19: The company filed $270,535 as its beginning net assets for FY2023 and $270,534 as its ending net assets for FY2022, a difference of $1. Both figures are carried exactly as each year's own filing reports them. Neither is adjusted to match the other.
A20: Source lines | B20: - FY2023 net assets, beginning of year (as filed): $270,535 - FY2022 net assets, end of year (as filed): $270,534 - Difference: $1
A21: Confidence reasoning | B21: Both are direct filed line items read from two different returns, so the difference between them is high confidence as an observation. What caused it is not stated on either form.
A22: Why (not stated in the filing) | B22: The filing does not state a reason.
A23: Possible explanation (guess) | B23: Possible explanation, not stated in filing: a beginning balance that differs from the prior year's ending balance usually means the earlier year was restated, or a balance-sheet line was reclassified between the two filings. This is an educated guess, not something either filing says.

Sheet Sources & audit
A1: Lundy Mutual Water Co
A2: Sources & audit - full provenance and tie-outs (kept off the statements so they read clean)
A3: Entity ID: cawc_0180 | Fiscal year ends December 31.
A5: Presentation standard: every figure on the statement tabs is verified to its source filing and shown clean. A cell the filing does not report reads "not reported" (never estimated, never guessed).
A6: Citations, confidence tiers, and the filed-vs-computed tie-out checks live on the "Sources & audit" tab, keyed by cell, so every number is fully traceable without cluttering the statements. These pages are ready to use as filed.
A8: A. Filing provenance (one row per staged extraction)
A9: Fiscal year | B9: Period end | C9: Filing type | D9: Confidence | E9: Extraction ID | F9: Object ID | G9: Extracted by | H9: Extracted at | I9: Source URL
A10: FY2021 | B10: 2021-12-31 | C10: 990-EZ | D10: high | E10: 1aad8a19-096c-4298-9f72-9f36bd1cefed | F10: 202231309349200613 | G10: claude-opus-5 | H10: 2026-10-06T04:29:14+00:00 | I10: https://apps.irs.gov/pub/epostcard/990/xml/2022/2022_TEOS_XML_01A.zip#202231309349200613_public.xml
A11: FY2022 | B11: 2022-12-31 | C11: 990-EZ | D11: high | E11: 99aa9ab4-8bac-4b2c-80e9-790c755f860e | F11: 202322129349200832 | G11: claude-opus-5 | H11: 2026-10-06T04:29:15+00:00 | I11: https://apps.irs.gov/pub/epostcard/990/xml/2023/2023_TEOS_XML_08A.zip#202322129349200832_public.xml
A12: FY2023 | B12: 2023-12-31 | C12: 990-EZ | D12: high | E12: a5ed0426-dc15-4f35-845a-4a6d18bcfe90 | F12: 202422569349201507 | G12: claude-opus-5 | H12: 2026-10-06T04:29:15+00:00 | I12: https://apps.irs.gov/pub/epostcard/990/xml/2024/2024_TEOS_XML_09A.zip#202422569349201507_public.xml
A13: FY2024 | B13: 2024-12-31 | C13: 990 | D13: high | E13: 2a61973d-5834-4571-862d-29996ed96463 | F13: 202502669349301400 | G13: claude-opus-5 | H13: 2026-10-06T04:29:16+00:00 | I13: https://apps.irs.gov/pub/epostcard/990/xml/2025/2025_TEOS_XML_09A.zip#202502669349301400_public.xml
A15: B. Figure citations (every figure on the statement tabs, keyed by cell)
A16: Tab | B16: Cell | C16: Line item | D16: Form 990 line | E16: Key path | F16: Confidence | G16: As filed
A17: Financial Statements | B17: B73 | C17: 11a. Gross income from members or shareholders | D17: 11a | E17: part_v_other_irs_filings.members_and_shareholders_gross_income | F17: high | G17: 77544
A18: Financial Statements | B18: B74 | C18: 11b. Gross income from other sources | D18: 11b | E18: part_v_other_irs_filings.other_sources_gross_income | F18: high | G18: 29119
A19: Revenue (detail) | B19: B8 | C19: 2g. Total program service revenue | D19: 2g | E19: part_viii_revenue.total_program_service_revenue | F19: high | G19: 105951
A20: Revenue (detail) | B20: B9 | C20: 3. Investment income | D20: 3 | E20: part_viii_revenue.investment_income | F20: high | G20: 1571
A21: Operating expenses (detail) | B21: B7 | C21: 7. Other salaries and wages | D21: 7 | E21: part_ix_expenses.other_salaries_and_wages | F21: high | G21: 13711
A22: Operating expenses (detail) | B22: B8 | C22: 11g. Fees for services: other | D22: 11g | E22: part_ix_expenses.fees_other | F22: high | G22: 12580
A23: Operating expenses (detail) | B23: B9 | C23: 13. Office expenses | D23: 13 | E23: part_ix_expenses.office_expenses | F23: high | G23: 1152
A24: Operating expenses (detail) | B24: B10 | C24: 14. Information technology | D24: 14 | E24: part_ix_expenses.information_technology | F24: high | G24: 1648
A25: Operating expenses (detail) | B25: B11 | C25: 16. Occupancy | D25: 16 | E25: part_ix_expenses.occupancy | F25: high | G25: 14451
A26: Operating expenses (detail) | B26: B12 | C26: 17. Travel | D26: 17 | E26: part_ix_expenses.travel | F26: high | G26: 952
A27: Operating expenses (detail) | B27: B13 | C27: 22. Depreciation, depletion, and amortization | D27: 22 | E27: part_ix_expenses.depreciation | F27: high | G27: 11271
A28: Operating expenses (detail) | B28: B14 | C28: 23. Insurance | D28: 23 | E28: part_ix_expenses.insurance | F28: high | G28: 5073
... A40: Net-assets reconciliation | B40: B10 | C40: 9. Other changes in net assets | D40: Part XI line 9 | E40: part_xi_reconciliation.other_changes_net_assets | F40: high | G40: 0
A42: C. Tie-out checks (filed vs computed; any nonzero variance is flagged red)
A43: Tab | B43: Check | C43: Fiscal year | D43: Filed | E43: Computed | F43: Variance (computed - filed)
A44: Revenue (detail) | B44: 12. Total revenue | C44: FY2024 | D44: 107522 | E44: ='Revenue (detail)'!B13 | F44: =E44-D44
A45: Revenue (detail) | B45: 2g program service revenue = sum of lines 2a-2f (FY2024) | C45: FY2024 | D45: 105951 | E45: =SUM('Revenue (detail)'!C17:C19) | F45: =E45-D45
A46: Operating expenses (detail) | B46: 25. Total functional expenses | C46: FY2024 | D46: 121879 | E46: ='Operating expenses (detail)'!B19 | F46: =E46-D46
A47: Balance sheet (detail) | B47: 16. Total assets | C47: FY2024 | D47: 567259 | E47: ='Balance sheet (detail)'!B11 | F47: =E47-D47
A48: Balance sheet (detail) | B48: 26. Total liabilities | C48: FY2024 | D48: 306382 | E48: ='Balance sheet (detail)'!B16 | F48: =E48-D48
A49: Balance sheet (detail) | B49: 32. Total net assets / fund balances | C49: FY2024 | D49: 260877 | E49: ='Balance sheet (detail)'!B22 | F49: =E49-D49
A50: Balance sheet (detail) | B50: Balance sheet identity: line 16 = line 26 + line 32 (EOY) | C50: FY2024 | D50: ='Balance sheet (detail)'!B11 | E50: =SUM('Balance sheet (detail)'!B16,'Balance sheet (detail)'!B22) | F50: =E50-D50
A51: Net-assets reconciliation | B51: 10. Net assets, end of year | C51: FY2024 | D51: 260877 | E51: ='Net-assets reconciliation'!B11 | F51: =E51-D51
A53: D. Preparer / auditor trail (one row per fiscal year, as filed)
A54: Fiscal year | B54: Paid preparer | C54: Preparer firm | D54: Independent auditor | E54: Citation
A55: FY2024 | B55: Gail N Egan | C55: EGAN CPAs LP | D55: not reported | E55: Form 990 Return Header, Paid Preparer block (return_header.preparer_person_name / preparer_firm_name); auditor: Part XII line 2 reports audited financial statements but does not name the firm.
A57: Section B lists every figure on the statement tabs by its cell, so any number can be traced to its Form 990 line, key path, and confidence without cluttering the statements. Section C recomputes each statutory total live from the statement cells and compares it with the as-filed value; a nonzero variance turns red. A red row is a filer-internal inconsistency (e.g. an ending net-assets figure that does not equal the beginning balance plus the year's surplus or deficit), carried exactly as filed and never reconciled; the statutory totals otherwise tie to zero. Section D records the paid preparer and (where named) the auditor for each year, as filed; the 990 names the preparer but not the auditing firm, so the auditor reads "not reported". Section E lists every as-filed wording variant for Part IX line-24 rows that were consolidated across years because they differed only by capitalization or spacing. IRS efile XML has no page numbers, so 990 figures cite by Part and line (the key path), not a page.

Sheet Provenance
A1: Build provenance | B1: Built from source commit d418ffb17485 (2026-10-06); source fingerprint a75a8eee82c65cf7; 192 companies (179 retail mutual, 4 irrigation mutual, 3 mutual, no PWSID, purpose not stated, 2 frozen non-mutual (special district), 2 wholesale mutual, 1 frozen non-mutual (investor-owned), 1 frozen non-mutual (municipal)); 91 gates; build id 3d08d6d2a855.
A2: source_commit | B2: d418ffb174855ab78000d391d42f898397b0d8aa
A3: source_commit_date | B3: 2026-10-06
A4: source_fingerprint | B4: a75a8eee82c65cf7096931f06e18affdc28686a02895b46538e7298b57c04d94
A5: gate_count | B5: 91
A6: build_id | B6: 3d08d6d2a855
A7: registry: frozen non-mutual (investor-owned) | B7: 1
A8: registry: frozen non-mutual (municipal) | B8: 1
A9: registry: frozen non-mutual (special district) | B9: 2
A10: registry: irrigation mutual | B10: 4
A11: registry: mutual, no PWSID, purpose not stated | B11: 3
A12: registry: retail mutual | B12: 179
A13: registry: wholesale mutual | B13: 2
