Workbook

Sheet Summary
A1: Stockdale Annex Mutual Water Co
A2: Financial Summary - multi-year overview (USD)
A3: Entity ID: cawc_0143 | Fiscal year ends December 31.
A5: Presentation standard: every figure on the statement tabs is verified to its source filing and shown clean. A cell the filing does not report reads "not reported" (never estimated, never guessed).
A6: Citations, confidence tiers, and the filed-vs-computed tie-out checks live on the "Sources & audit" tab, keyed by cell, so every number is fully traceable without cluttering the statements. These pages are ready to use as filed.
A8: Metric | B8: FY2020 | C8: FY2021 | D8: FY2022 | E8: FY2023 | F8: FY2024
A9: Operating results (USD)
A10: Total revenue | B10: 144481 | C10: 226637 | D10: 253840 | E10: 1458158 | F10: 269819
A11: Total expenses | B11: 132991 | C11: 155974 | D11: 147019 | E11: 193687 | F11: 238905
A12: Net income | B12: 11490 | C12: 70663 | D12: 106821 | E12: 1264471 | F12: 30914
A14: Financial position (USD, end of year)
A15: Total assets | B15: 731640 | C15: 806217 | D15: 930149 | E15: 2190801 | F15: 2219500
A16: Total liabilities | B16: 35968 | C16: 39877 | D16: 56988 | E16: 53175 | F16: 50956
A17: Net assets | B17: 695672 | C17: 766340 | D17: 873161 | E17: 2137626 | F17: 2168544
A19: Headline ratios
A20: Operating margin | B20: 0.079526028 | C20: 0.31178934 | D20: 0.4208202 | E20: 0.86717009 | F20: 0.1145731
A21: Revenue growth (YoY) | B21: 0.097738134 | C21: 0.5686284 | D21: 0.12002894 | E21: 4.744398 | F21: -0.81495901
A22: Return on assets | B22: 0.015704445 | C22: 0.087647618 | D22: 0.11484289 | E22: 0.57717292 | F22: 0.013928362
A24: Figures as reported in source filings (full provenance on the Sources & audit tab). Parentheses denote negatives; ratios are computed upstream in financials_annual.

Sheet Notes
A1: Notes
A2: Human annotations from the versioned store (data/notes/). Annotations only: they never change a reported figure or a confidence tier.
A4: Date | B4: Tag | C4: Author | D4: Note
A5: No notes recorded yet.

Sheet Financial Statements
A1: Stockdale Annex Mutual Water Co
A2: Financial Statements - income statement, balance sheet, cash flow, member income test (USD)
A3: Entity ID: cawc_0143 | Fiscal year ends December 31.
A5: INCOME STATEMENT - as reported (USD)
A6: Line item | B6: FY2020 | C6: FY2021 | D6: FY2022 | E6: FY2023 | F6: FY2024
A7: Revenue
A8: Program service revenue | B8: 143360 | C8: 225770 | D8: 251735 | E8: 1450503 | F8: 251967
A9: Investment income | B9: 141 | C9: 92 | D9: 214 | E9: 5805 | F9: 13986
A10: Net rental income
A11: Net gain/(loss) on investment sales
A12: Other revenue | B12: 980 | C12: 775 | D12: 1891 | E12: 1850 | F12: 3866
A13: Contributions & grants
A14: Total revenue | B14: 144481 | C14: 226637 | D14: 253840 | E14: 1458158 | F14: 269819
A16: Expenses
A17: Depreciation | B17: 8683 | C17: 16199 | D17: 23301 | E17: 26584 | F17: 75874
A18: Interest expense
A19: Total expenses | B19: 132991 | C19: 155974 | D19: 147019 | E19: 193687 | F19: 238905
A21: Net income | B21: 11490 | C21: 70663 | D21: 106821 | E21: 1264471 | F21: 30914
A24: BALANCE SHEET - as reported (USD, end of year)
A25: Line item | B25: FY2020 | C25: FY2021 | D25: FY2022 | E25: FY2023 | F25: FY2024
A26: Assets
A27: Cash | B27: 150977 | C27: 20509 | D27: 140393 | E27: 389241 | F27: 62889
A28: Savings & temporary investments | B28: 18418 | C28: 495956 | D28: 496169 | E28: 465754 | F28: 478980
A29: Accounts receivable | B29: 4903 | C29: 5101 | D29: 4098 | E29: 837575 | F29: 2658
A30: Inventories
A31: Prepaid expenses
A32: Property, plant & equipment (gross) | B32: 339951 | C32: 531205 | D32: 559344 | E32: 641512 | F32: 2047286
A33: Less: accumulated depreciation | B33: -238082 | C33: -254014 | D33: -277315 | E33: -303899 | F33: -379773
A34: Net property, plant & equipment | B34: 101869 | C34: 277191 | D34: 282029 | E34: 337613 | F34: 1667513
A35: Total assets | B35: 731640 | C35: 806217 | D35: 930149 | E35: 2190801 | F35: 2219500
A37: Liabilities
A38: Accounts payable | B38: 16507 | C38: 13576 | D38: 32186 | E38: 34254 | F38: 33394
A39: Mortgages & notes payable
A40: Total liabilities | B40: 35968 | C40: 39877 | D40: 56988 | E40: 53175 | F40: 50956
A42: Net Assets / Equity
A43: Capital stock | B43: 28756
A44: Paid-in capital | B44: 487329
A45: Retained earnings | B45: 179587 | C45: 766340 | D45: 873161 | E45: 2137626 | F45: 2168544
A46: Net assets | B46: 695672 | C46: 766340 | D46: 873161 | E46: 2137626 | F46: 2168544
A49: CASH FLOW - derived proxy (USD)
...

Sheet Balance Sheet
A1: Stockdale Annex Mutual Water Co
A2: Balance Sheet - as reported (USD, end of year)
A3: Entity ID: cawc_0143 | Fiscal year ends December 31.
A5: Line item | B5: FY2020 | C5: FY2021 | D5: FY2022 | E5: FY2023 | F5: FY2024
A6: Assets
A7: Cash | B7: 150977 | C7: 20509 | D7: 140393 | E7: 389241 | F7: 62889
A8: Savings & temporary investments | B8: 18418 | C8: 495956 | D8: 496169 | E8: 465754 | F8: 478980
A9: Accounts receivable | B9: 4903 | C9: 5101 | D9: 4098 | E9: 837575 | F9: 2658
A10: Inventories
A11: Prepaid expenses
A12: Property, plant & equipment (gross) | B12: 339951 | C12: 531205 | D12: 559344 | E12: 641512 | F12: 2047286
A13: Less: accumulated depreciation | B13: -238082 | C13: -254014 | D13: -277315 | E13: -303899 | F13: -379773
A14: Net property, plant & equipment | B14: 101869 | C14: 277191 | D14: 282029 | E14: 337613 | F14: 1667513
A15: Total assets | B15: 731640 | C15: 806217 | D15: 930149 | E15: 2190801 | F15: 2219500
A17: Liabilities
A18: Accounts payable | B18: 16507 | C18: 13576 | D18: 32186 | E18: 34254 | F18: 33394
A19: Mortgages & notes payable
A20: Total liabilities | B20: 35968 | C20: 39877 | D20: 56988 | E20: 53175 | F20: 50956
A22: Net Assets / Equity
A23: Capital stock | B23: 28756
A24: Paid-in capital | B24: 487329
A25: Retained earnings | B25: 179587 | C25: 766340 | D25: 873161 | E25: 2137626 | F25: 2168544
A26: Net assets | B26: 695672 | C26: 766340 | D26: 873161 | E26: 2137626 | F26: 2168544
A28: Balance check (assets − liab. − net assets) | B28: 0 | C28: 0 | D28: 0 | E28: 0 | F28: 0
A30: Net PP&E is the reported ppe_net column (gross less accumulated depreciation). The balance check should be ~0 where all three totals are reported; a non-zero value flags a reporting or extraction discrepancy worth reviewing.

Sheet Officers & contractors
A1: Stockdale Annex Mutual Water Co
A2: Officers, Directors & Contractors - Form 990 Part VII (FY2024; USD)
A3: Entity ID: cawc_0143 | Fiscal year ends December 31.
A5: Section A - Officers, directors, trustees, key employees
A6: Name | B6: Title | C6: Reportable comp (org) | D6: Reportable comp (related) | E6: Other comp | F6: Total compensation
A7: Scott Spitzer | B7: Director | C7: 0 | D7: 0 | E7: 0 | F7: 0
A8: Chad Brock | B8: Director | C8: 0 | D8: 0 | E8: 0 | F8: 0
A9: Christopher D Jacobs | B9: PresidentCEO | C9: 0 | D9: 0 | E9: 0 | F9: 0
A10: Michael Ming | B10: Vice President | C10: 0 | D10: 0 | E10: 0 | F10: 0
A11: Brian Grant | B11: SecretaryCFO | C11: 0 | D11: 0 | E11: 0 | F11: 0
A13: Section B - Independent contractors (over $100,000)
A14: Contractor | B14: Services | C14: Compensation
A16: Section A lists every officer, director, trustee and key employee filed for the latest year; the two with the highest total compensation are highlighted. Total compensation is computed (reportable org + related + other). Section B lists each independent contractor paid over $100,000; the return reports None such contractor(s). Source and confidence for every figure are on the Sources & audit tab.

Sheet Revenue (detail)
A1: Stockdale Annex Mutual Water Co
A2: Revenue - Form 990 Part VIII (USD)
A3: Entity ID: cawc_0143 | Fiscal year ends December 31.
A5: Part VIII line | B5: FY2020 | C5: FY2021 | D5: FY2022 | E5: FY2023 | F5: FY2024
A6: Revenue by category
A7: 1h. Total contributions, gifts, grants | B7: not reported | C7: not reported | D7: not reported | E7: not reported | F7: not reported
A8: 2g. Total program service revenue | B8: 143360 | C8: 225770 | D8: 251735 | E8: 1450503 | F8: 251967
A9: 3. Investment income | B9: 141 | C9: 92 | D9: 214 | E9: 5805 | F9: 13986
A10: 6d. Net rental income | B10: not reported | C10: not reported | D10: not reported | E10: not reported | F10: not reported
A11: 7d. Net gain/(loss) from investment sales | B11: not reported | C11: not reported | D11: not reported | E11: not reported | F11: not reported
A12: 11e. Other revenue | B12: 980 | C12: 775 | D12: 1891 | E12: 1850 | F12: 3866
A13: 12. Total revenue | B13: =SUM(B7:B12) | C13: =SUM(C7:C12) | D13: =SUM(D7:D12) | E13: =SUM(E7:E12) | F13: =SUM(F7:F12)
A15: Program service revenue detail - FY2024 (lines 2a-2f)
A16: Description | B16: Business code | C16: Total revenue
A17: Water Service | B17: 221000 | C17: 152290
A18: Member Assessment | B18: 221000 | C18: 99677
A19: Revenue category subtotals are as filed. Total revenue (line 12) is a live SUM of the category cells above; its tie-out to the filed total is on the Sources & audit tab. Program service revenue detail is shown for the latest year, with its sum-to-line-2g check on that same audit tab.

Sheet Operating expenses (detail)
A1: Stockdale Annex Mutual Water Co
A2: Statement of Functional Expenses - Form 990 Part IX (USD)
A3: Entity ID: cawc_0143 | Fiscal year ends December 31.
A5: Part IX line (column A Total) | B5: FY2020 | C5: FY2021 | D5: FY2022 | E5: FY2023 | F5: FY2024
A6: Functional expenses, column A Total - by year
A7: 11a. Fees for services: management | B7: 12000 | C7: 12000 | D7: 12000 | E7: 14300 | F7: 13200
A8: 11b. Fees for services: legal | B8: 7434 | C8: 880 | D8: 4703 | E8: 4386 | F8: 20582
A9: 11c. Fees for services: accounting | B9: 4495 | C9: 5286 | D9: 4646 | E9: 3733 | F9: 3672
A10: 11g. Fees for services: other | B10: 3415 | C10: 10747 | D10: 4945 | E10: 15879 | F10: not reported
A11: 22. Depreciation, depletion, and amortization | B11: 8683 | C11: 16199 | D11: 23301 | E11: 26584 | F11: 75874
A12: 23. Insurance | B12: 4346 | C12: 4527 | D12: 4912 | E12: 5345 | F12: 6029
A13: 24. Repairs & Maintenance | B13: 37456 | C13: 50383 | D13: 27132 | E13: 52502 | F13: 44615
A14: 24. Utilities | B14: 40652 | C14: 41145 | D14: 49287 | E14: 48571 | F14: 60981
A15: 24. Goverment Assessments | B15: 9612 | C15: 9800 | D15: 12163 | E15: 17701 | F15: 7115
A16: 24. Permits Licenses & Fees | B16: 1087 | C16: 1883 | D16: 1336 | E16: 1529 | F16: 626
A17: 24e. All other expenses | B17: 3811 | C17: 3124 | D17: 2594 | E17: 3157 | F17: 6211
A18: 25. Total functional expenses | B18: =SUM(B7:B17) | C18: =SUM(C7:C17) | D18: =SUM(D7:D17) | E18: =SUM(E7:E17) | F18: =SUM(F7:F17)
A20: Functional column split - FY2024 (col A = B + C + D)
A21: Part IX line | B21: A. Total | C21: B. Program services | D21: C. Management & general | E21: D. Fundraising
A22: 11a. Fees for services: management | B22: 13200 | C22: 13200
A23: 11b. Fees for services: legal | B23: 20582 | C23: 20582
A24: 11c. Fees for services: accounting | B24: 3672 | C24: 3672
A25: 22. Depreciation, depletion, and amortization | B25: 75874 | C25: 75874
A26: 23. Insurance | B26: 6029 | C26: 6029
A27: 25. Total (filed col A / B / C / D) | B27: 238905 | C27: 238905 | D27: 0 | E27: 0
A29: Top block: each Part IX line, column A (Total), by year, as filed. Total functional expenses (line 25) is a live SUM of the line cells; its tie-out to the filed total is on the Sources & audit tab. Filer-itemized 24a-24d rows show the most recent year's as-filed wording; rows are aligned across years case-insensitively with collapsed spacing, so a line filed only in a different capitalization or spacing shares one row, while genuinely different wording stays a separate row (every as-filed variant is recorded on the Sources & audit tab). Lower block: the program / management / fundraising split for the latest year, with its col A = B + C + D check on the audit tab. Lines this filer does not report are omitted rather than shown empty.

Sheet Balance sheet (detail)
A1: Stockdale Annex Mutual Water Co
A2: Balance Sheet - Form 990 Part X (end of year, USD)
A3: Entity ID: cawc_0143 | Fiscal year ends December 31.
A5: Part X line (column B, EOY) | B5: FY2020 | C5: FY2021 | D5: FY2022 | E5: FY2023 | F5: FY2024
A6: Assets
A7: 1. Cash - non-interest-bearing | B7: 150977 | C7: 20509 | D7: 140393 | E7: 389241 | F7: 62889
A8: 2. Savings and temporary cash investments | B8: 18418 | C8: 495956 | D8: 496169 | E8: 465754 | F8: 478980
A9: 4. Accounts receivable, net | B9: 4903 | C9: 5101 | D9: 4098 | E9: 837575 | F9: 2658
A10: 10c. Land, buildings, and equipment, net | B10: 101869 | C10: 277191 | D10: 282029 | E10: 337613 | F10: 1667513
A11: 15. Other assets | B11: 455473 | C11: 7460 | D11: 7460 | E11: 160618 | F11: 7460
A12: 16. Total assets | B12: =SUM(B7:B11) | C12: =SUM(C7:C11) | D12: =SUM(D7:D11) | E12: =SUM(E7:E11) | F12: =SUM(F7:F11)
A14: Liabilities
A15: 17. Accounts payable and accrued expenses | B15: 16507 | C15: 13576 | D15: 32186 | E15: 34254 | F15: 33394
A16: 19. Deferred revenue | B16: 19461 | C16: 26301 | D16: 24802 | E16: 18921 | F16: 17562
A17: 26. Total liabilities | B17: =SUM(B15:B16) | C17: =SUM(C15:C16) | D17: =SUM(D15:D16) | E17: =SUM(E15:E16) | F17: =SUM(F15:F16)
A19: Net assets / fund balances
A20: 29. Capital stock or trust principal | B20: 28756 | C20: not reported | D20: not reported | E20: not reported | F20: not reported
A21: 30. Paid-in or capital surplus | B21: 487329 | C21: not reported | D21: not reported | E21: not reported | F21: not reported
A22: 31. Retained earnings / accumulated funds | B22: 179587 | C22: 766340 | D22: 873161 | E22: 2137626 | F22: 2168544
A23: 32. Total net assets / fund balances | B23: =SUM(B20:B22) | C23: =SUM(C20:C22) | D23: =SUM(D20:D22) | E23: =SUM(E20:E22) | F23: =SUM(F20:F22)
A25: Every Part X line is end-of-year (column B), as filed. Section totals (lines 16 / 26 / 32) are live SUMs of the lines above; their tie-outs and the balance-sheet identity (16 = 26 + 32) are on the Sources & audit tab. This filer files as a non-FASB mutual, so net assets sit on lines 29-31 (capital stock / paid-in capital / retained earnings); lines this filer does not report are omitted. Lines 10a/10b net into line 10c (shown).

Sheet Net-assets reconciliation
A1: Stockdale Annex Mutual Water Co
A2: Reconciliation of Net Assets - Form 990 Part XI (USD)
A3: Entity ID: cawc_0143 | Fiscal year ends December 31.
A5: Part XI line | B5: FY2020 | C5: FY2021 | D5: FY2022 | E5: FY2023 | F5: FY2024
A6: Reconciliation
A7: 4. Net assets, beginning of year | B7: 602991 | C7: 695672 | D7: 766340 | E7: 873159 | F7: 2137626
A8: 3. Revenue less expenses | B8: 11490 | C8: 70663 | D8: 106821 | E8: 1264471 | F8: 30914
A9: 8. Prior period adjustments | B9: not reported | C9: not reported | D9: not reported | E9: not reported | F9: not reported
A10: 9. Other changes in net assets | B10: 81191 | C10: 5 | D10: 0 | E10: -4 | F10: 4
A11: 10. Net assets, end of year | B11: =SUM(B7,B8,B9,B10) | C11: =SUM(C7,C8,C9,C10) | D11: =SUM(D7,D8,D9,D10) | E11: =SUM(E7,E8,E9,E10) | F11: =SUM(F7,F8,F9,F10)
A13: Part XI reconciles beginning to ending net assets. Ending net assets (line 10) is a live formula: beginning balance (line 4) + revenue less expenses (line 3) + prior-period adjustments (8) + other changes (9). Its tie-out to the filed line 10 (and to Part X line 32) is on the Sources & audit tab. Lines 5-7 (unrealized gains, donated services, investment expenses) are not filed by this entity.

Sheet Cash flow proxies
A1: Stockdale Annex Mutual Water Co
A2: Cash Flow Proxies - derived (USD)
A3: Entity ID: cawc_0143 | Fiscal year ends December 31.
A5: PROXY ONLY. The source filings contain no statement of cash flows. Lines below are derived from the reported income statement and year-over-year balance-sheet changes; treat as directional estimates, not GAAP cash flows. The earliest year has no prior period, so its delta cells are blank.
A7: Proxy line (USD) | B7: FY2020 | C7: FY2021 | D7: FY2022 | E7: FY2023 | F7: FY2024
A8: Operating
A9: Net income | B9: 11490 | C9: 70663 | D9: 106821 | E9: 1264471 | F9: 30914
A10: + Depreciation (reported) | B10: 8683 | C10: 16199 | D10: 23301 | E10: 26584 | F10: 75874
A11: − Δ Accounts receivable | C11: -198 | D11: 1003 | E11: -833477 | F11: 834917
A12: − Δ Inventories
A13: − Δ Prepaid expenses
A14: + Δ Accounts payable | C14: -2931 | D14: 18610 | E14: 2068 | F14: -860
A15: Operating cash flow proxy | C15: 83733 | D15: 149735 | E15: 459646 | F15: 940845
A17: Investing
A18: − Δ PP&E gross (capex proxy) | C18: -191254 | D18: -28139 | E18: -82168 | F18: -1405774
A20: Financing
A21: Δ Mortgages & notes payable
A23: Reconciliation
A24: Δ Cash + temp. investments (actual) | C24: 347070 | D24: 120097 | E24: 218433 | F24: -313126
A26: The capex proxy assumes gross PP&E rises only via capital spending (it ignores disposals). 'Δ Cash + temp. investments (actual)' is the real reported change in liquid funds and is the most reliable line here; the operating/investing/financing proxies will not perfectly reconcile to it.

Sheet Ratios
A1: Stockdale Annex Mutual Water Co
A2: Financial Ratios
A3: Entity ID: cawc_0143 | Fiscal year ends December 31.
A5: Ratio | B5: FY2020 | C5: FY2021 | D5: FY2022 | E5: FY2023 | F5: FY2024
A6: Profitability (computed upstream)
A7: Operating margin (NI / revenue) | B7: 0.079526028 | C7: 0.31178934 | D7: 0.4208202 | E7: 0.86717009 | F7: 0.1145731
A8: Expense ratio (expenses / revenue) | B8: 0.92047397 | C8: 0.68821066 | D8: 0.5791798 | E8: 0.13282991 | F8: 0.8854269
A9: Return on assets (NI / assets) | B9: 0.015704445 | C9: 0.087647618 | D9: 0.11484289 | E9: 0.57717292 | F9: 0.013928362
A10: Revenue growth (YoY) | B10: 0.097738134 | C10: 0.5686284 | D10: 0.12002894 | E10: 4.744398 | F10: -0.81495901
A12: Leverage & solvency
A13: Debt-to-assets (liab. / assets) | B13: 0.049160789 | C13: 0.049461869 | D13: 0.061267603 | E13: 0.024271944 | F13: 0.022958324
A14: Equity ratio (net assets / assets) | B14: 0.95083921 | C14: 0.95053813 | D14: 0.9387324 | E14: 0.97572806 | F14: 0.97704168
A16: Liquidity & asset profile (derived here)
A17: Current ratio (current assets / AP) | B17: 10.559036 | C17: 38.418238 | D17: 19.904928 | E17: 49.412331 | F17: 16.306133
A18: Cash ratio ((cash+temp inv.) / total liab.) | B18: 4.709603 | C18: 12.951451 | D18: 11.170106 | E18: 16.07889 | F18: 10.634057
A19: Asset age proxy (accum. deprec. / gross PP&E) | B19: 0.70034211 | C19: 0.47818451 | D19: 0.49578614 | E19: 0.47372302 | F19: 0.18550071
A21: Upstream ratios are read from financials_annual; derived ratios are computed only where inputs are reported. Current ratio uses accounts payable as the current-liability proxy (the filings do not split current vs. long-term liabilities). Asset age proxy: a higher % implies older / more depreciated infrastructure.

Sheet Unit economics
A1: Stockdale Annex Mutual Water Co
A2: Unit economics - per-customer revenue by category (USD)
A3: Entity ID: cawc_0143 | Fiscal year ends December 31.
A5: Every metric here is PER CUSTOMER (a metered service connection). It is not a per-member figure; the member (shareholder) count is a different denominator, shown in the denominator block. The visible cell shows the value and its classification; the numerator, denominator, formula, and rationale are in each metric's LOGIC popup.
A6: Per-customer denominator (service connections) | C6: State Water Board eAR Section 4
A7: Total annual revenue (eAR Section 8b B1.8) | C7: eAR Section 8b total annual revenue not reported for this system.
A8: Primary source
A10: Revenue categories (value, classification, per customer, share)
A11: Revenue category | B11: Classification | C11: Value (USD) | D11: Per customer | E11: Share of revenue
A12: Water sales revenue | B12: not reported | C12: not reported | D12: not reported | E12: not reported
A13: Assessment revenue (990 program-service revenue not matched to eAR water-rate revenue) | B13: IMPOSSIBLE | C13: IMPOSSIBLE | D13: IMPOSSIBLE | E13: IMPOSSIBLE
A14: Meter revenue | B14: not reported | C14: not reported | D14: not reported | E14: not reported
A15: Overage or tiered penalty revenue | B15: not reported | C15: not reported | D15: not reported | E15: not reported
A17: Water sales revenue - not reported
A18: Not reported: this system filed an eAR but no Section 8b revenue block, so there is no filed water-sales figure. Not fallen back to a different year.
A19: Reason: No filed eAR Section 8b water-rate revenue for this system.
A21: Assessment revenue (990 program-service revenue not matched to eAR water-rate revenue) - IMPOSSIBLE
A22: Not computed. A period-aligned residual is not possible for this filer.
A23: Reason: Not derivable. The eAR Section 8b is reporting year None while the Form 990 fiscal year ends None; the two period ends are not aligned, so a period-aligned residual cannot be computed.
A25: Meter revenue - not reported
A26: Not reported. This category is not built because doing so would double-count.
A27: Reason: The eAR Section 8a reports a base/meter rate PRICE, but the filing carries no meter revenue line and no tier volume, and the base charge is already inside the water-sales revenue (eAR Section 8b water rates). Building a separate meter figure would double-count. Not backed into from a total.
A29: Overage or tiered penalty revenue - not reported
A30: Not reported. This category is not built because doing so would double-count.
A31: Reason: The eAR Section 8a reports tiered/overage rate PRICES, but the filing carries no overage revenue and no tier consumption volume, and any overage billed is already inside the water-sales revenue. Building it would double-count. Not backed into from a total.

Sheet Rate structure
A1: Stockdale Annex Mutual Water Co
A2: Rate structure and representative bill - eAR Section 8a
A3: Entity ID: cawc_0143 | Fiscal year ends December 31.
A5: This block is a rate-schedule illustration at defined usage levels. It is NOT billed revenue and not a claim about any real customer's usage. The revenue side of unit economics is the separate Unit Economics block.
A6: No filed eAR Section 8a rate schedule is staged for this system.

Sheet Operational metrics
A1: Stockdale Annex Mutual Water Co
A2: Operational metrics - plant per acre, density, terrain
A3: Entity ID: cawc_0143 | Fiscal year ends December 31.
A5: Plant assets per acre
A6: Service-area acres | B6: 445.6 | C6: Geodesic area (WGS84 spherical excess) of the SABL service-area polygon.
A7: Fiscal year | B7: Gross plant per acre (primary) | C7: Net plant per acre
A8: FY2020 | B8: 762.9062 | C8: 228.6109
A9: FY2021 | B9: 1192.1118 | C9: 622.0624
A10: FY2022 | B10: 1255.2603 | C10: 632.9197
A11: FY2023 | B11: 1439.6589 | C11: 757.6593
A12: FY2024 | B12: 4594.4479 | C12: 3742.1746
A13: Infrastructure built per acre of service area. Gross plant per acre is the primary read because it measures how much plant the system has put in the ground per acre, and unlike net plant it does not fall over time purely because the assets depreciate on the books. Net plant per acre is shown alongside as the depreciated book value per acre.
A14: Formula: gross plant per acre = Form 990 Part X line 10a (land, buildings, and equipment, gross) / SABL service-area acres; net plant per acre uses Part X line 10c (net)
A15: Source lines: Form 990 Part X line 10a (gross) and line 10c (net); Geodesic area (WGS84 spherical excess) of the SABL service-area polygon.
A16: Confidence: medium. This is worked out from filed figures (a ratio, or a year-to-year change), so it is one step removed from the raw numbers.. Filed gross/net plant over the measured SABL service-area acreage.
A18: Connections per acre
A19: Connections per acre | B19: 0.32 | C19: 141 connections / 445.6 acres. CA State Water Board SABL SERVICE_CONNECTIONS; Geodesic area (WGS84 spherical excess) of the SABL service-area polygon.

Sheet Supply & weather
A1: Stockdale Annex Mutual Water Co
A2: Supply and weather indicators (DWR water year)
A3: Entity ID: cawc_0143 | Fiscal year ends December 31.
A5: Reporting calendar: Different reporting periods. The DWR water year runs October 1 to September 30; this system's fiscal year ends December 31, so the two period ends are three months apart. Read the two side by side with that in mind. Neither series is recast: both are reported as filed. A water year is named for the calendar year it ends in, so WY2024 and FY2024 share a number without covering the same twelve months.
A7: Indicator | B7: WY2020 | C7: WY2021 | D7: WY2022 | E7: WY2023 | F7: WY2024
A8: Water-year type (Sacramento Valley) | B8: Dry | C8: Critical | D8: Critical | E8: Wet | F8: Above Normal
A9: Peak drought, county County | B9: not reported | C9: not reported | D9: not reported | E9: not reported | F9: not reported
A10: Precip, percent of normal (8-Station Index) | B10: 63 | C10: 48 | D10: 86 | E10: 133 | F10: 96
A11: Snowpack, April 1 percent of average | B11: 53% | C11: 59% | D11: 38% | E11: 237% | F11: 110%
A12: State Water Project allocation | B12: 20% | C12: 5% | D12: 5% | E12: 100% | F12: 40%

Sheet How this was built
A1: Stockdale Annex Mutual Water Co
A2: How this was built - forensic lineage
A3: Entity ID: cawc_0143 | Fiscal year ends December 31.
A5: A plain account of the forensic lineage behind the hard-to-source metrics: what sources were checked, what was found, what was derived, and what could not be built and why. Every figure marked DERIVED or IMPOSSIBLE above is traceable to a line here.
A7: Water-sales revenue per customer - not reported
A8: Sources checked | B8: State Water Board eAR Section 8b (water-rate revenue B1.1/B1.2); State Water Board eAR Section 4 (connection count, same reporting year); audited financial statement (secondary cross-check, where published)
A9: What was found | B9: The eAR Section 8b reports water-rate revenue for reporting year None, so this is a DIRECT filed figure; per customer it is divided by the eAR Section 4 connection count for the same reporting year, so numerator and denominator share the year.
A11: Assessment revenue (residual) - IMPOSSIBLE
A12: Sources checked | B12: Form 990 Part VIII line 2 (program-service revenue); State Water Board eAR Section 8b (water-rate revenue B1.1/B1.2); eAR Section 8b filer comment (WRRevenueComments)
A13: What was found | B13: A period-aligned residual cannot be computed for this filer, so the metric is rendered IMPOSSIBLE rather than guessed.
A14: Caveat | B14: Not derivable. The eAR Section 8b is reporting year None while the Form 990 fiscal year ends None; the two period ends are not aligned, so a period-aligned residual cannot be computed.
A16: Meter revenue - not reported
A17: Sources checked | B17: State Water Board eAR Section 8a (rate prices); State Water Board eAR Section 8b (revenue lines); audited financial statement
A18: What was found | B18: The rate price exists in Section 8a but no revenue or tier volume is reported, and the base charge is already inside water sales.
A19: Caveat | B19: The eAR Section 8a reports a base/meter rate PRICE, but the filing carries no meter revenue line and no tier volume, and the base charge is already inside the water-sales revenue (eAR Section 8b water rates). Building a separate meter figure would double-count. Not backed into from a total.
A21: Overage / tiered-penalty revenue - not reported
A22: Sources checked | B22: State Water Board eAR Section 8a (rate prices); State Water Board eAR Section 8b (revenue lines); audited financial statement
A23: What was found | B23: The rate price exists in Section 8a but no revenue or tier volume is reported, and the base charge is already inside water sales.
A24: Caveat | B24: The eAR Section 8a reports tiered/overage rate PRICES, but the filing carries no overage revenue and no tier consumption volume, and any overage billed is already inside the water-sales revenue. Building it would double-count. Not backed into from a total.
A26: eAR Section 8b reporting-period basis - sourced
A27: Sources checked | B27: eAR Section 8b B0.1 (WRFinancialReportingPeriod); eAR Section 8b B0.2 (WRFiscalYearStartDate)
A28: What was found | B28: The reporting basis (fiscal vs calendar year) is read from the filer's own B0.1/B0.2 answer and staged verbatim, never hardcoded, so the 990 comparison and the residual are period-aligned.
A30: Member (shareholder) count denominator - not reported
A31: Sources checked | B31: Form 990 (no member count stated); company website
A32: What was found | B32: No filing states a member/shareholder count, so the per-member unit economics read not reported rather than borrowing the connection count.
A34: Water volume delivered (acre-feet) - not reported
A35: Sources checked | B35: Form 990 (not in the filing); Consumer Confidence Report; eAR Section 6 (PRA-gated)
A36: What was found | B36: Volume delivered in acre-feet is not in the Form 990 and the CCR states only a source mix, so the per-acre-foot metrics read not reported; the eAR Section 6 is named as the source still needed.

Sheet Anomaly Flags
A1: Stockdale Annex Mutual Water Co
A2: Anomaly Flags (automated; kept separate from the clean statements)
A3: Entity ID: cawc_0143 | Fiscal year ends December 31.
A5: Material irregularities found automatically in the filed financials by the Hydronomics anomaly flagger. Each flag has two clearly separated layers. WHAT is mechanical, certain, and sourced: the exact filed lines, years, and amounts, carried as filed and never reconciled. WHY is attempted: the filing's own narrative is checked first, and when it states no reason a single best-guess hypothesis is shown, clearly labelled as a guess that is not in the filing and is not a verified figure.
A7: Flag: FY2024 total revenue swing
A8: Affected figure | B8: Operating revenue FY2024
A9: Confidence | B9: high
A10: What happened (filed, sourced) | B10: FY2024 total revenue fell to $269,819 from $1,458,158 in FY2023, a 81 percent move ($1,188,339 in absolute terms). Carried as filed and flagged as a documented anomaly, not smoothed.
A11: Source lines | B11: - total revenue: $1,458,158 FY2023, $269,819 FY2024
A12: Confidence reasoning | B12: A year-over-year move in a filed headline total that exceeds both the percentage and the dollar threshold; carried as filed.
A13: Why (not stated in the filing) | B13: The filing does not state a reason.
A14: Possible explanation (guess) | B14: Possible explanation, not stated in filing: a large one-year move in total revenue may reflect a one-time item or a change in how it was recorded. This is an educated guess, not something the filing actually says.
A16: Flag: FY2023 opening net assets differ from FY2022 closing
A17: Affected figure | B17: Net assets FY2023
A18: Confidence | B18: high
A19: What happened (filed, sourced) | B19: The company filed $873,159 as its beginning net assets for FY2023 and $873,161 as its ending net assets for FY2022, a difference of $-2. Both figures are carried exactly as each year's own filing reports them. Neither is adjusted to match the other.
A20: Source lines | B20: - FY2023 net assets, beginning of year (as filed): $873,159 - FY2022 net assets, end of year (as filed): $873,161 - Difference: $-2
A21: Confidence reasoning | B21: Both are direct filed line items read from two different returns, so the difference between them is high confidence as an observation. What caused it is not stated on either form.
A22: Why (not stated in the filing) | B22: The filing does not state a reason.
A23: Possible explanation (guess) | B23: Possible explanation, not stated in filing: a beginning balance that differs from the prior year's ending balance usually means the earlier year was restated, or a balance-sheet line was reclassified between the two filings. This is an educated guess, not something either filing says.

Sheet Sources & audit
A1: Stockdale Annex Mutual Water Co
A2: Sources & audit - full provenance and tie-outs (kept off the statements so they read clean)
A3: Entity ID: cawc_0143 | Fiscal year ends December 31.
A5: Presentation standard: every figure on the statement tabs is verified to its source filing and shown clean. A cell the filing does not report reads "not reported" (never estimated, never guessed).
A6: Citations, confidence tiers, and the filed-vs-computed tie-out checks live on the "Sources & audit" tab, keyed by cell, so every number is fully traceable without cluttering the statements. These pages are ready to use as filed.
A8: A. Filing provenance (one row per staged extraction)
A9: Fiscal year | B9: Period end | C9: Filing type | D9: Confidence | E9: Extraction ID | F9: Object ID | G9: Extracted by | H9: Extracted at | I9: Source URL
A10: FY2020 | B10: 2020-12-31 | C10: 990 | D10: high | E10: bd197e5f-187d-49b6-b57d-631200938bb1 | F10: 202111489349301011 | G10: claude-opus-5 | H10: 2026-10-03T23:10:03+00:00 | I10: https://apps.irs.gov/pub/epostcard/990/xml/2021/2021_TEOS_XML_01A.zip#202111489349301011_public.xml
A11: FY2021 | B11: 2021-12-31 | C11: 990 | D11: high | E11: 86f786d0-7b81-4e3c-96c4-2726a832daad | F11: 202201319349303700 | G11: claude-opus-5 | H11: 2026-10-03T23:10:03+00:00 | I11: https://apps.irs.gov/pub/epostcard/990/xml/2022/2022_TEOS_XML_01A.zip#202201319349303700_public.xml
A12: FY2022 | B12: 2022-12-31 | C12: 990 | D12: high | E12: 5fb3c3ea-76cd-4f1c-adba-d954ab0674b5 | F12: 202331659349300843 | G12: claude-opus-5 | H12: 2026-10-03T23:10:03+00:00 | I12: https://apps.irs.gov/pub/epostcard/990/xml/2023/2023_TEOS_XML_06A.zip#202331659349300843_public.xml
A13: FY2023 | B13: 2023-12-31 | C13: 990 | D13: high | E13: 595d1db7-1735-4625-b4a9-4e5b2046950c | F13: 202442299349301239 | G13: claude-opus-5 | H13: 2026-10-03T23:10:03+00:00 | I13: https://apps.irs.gov/pub/epostcard/990/xml/2024/2024_TEOS_XML_08A.zip#202442299349301239_public.xml
A14: FY2024 | B14: 2024-12-31 | C14: 990 | D14: high | E14: 6ee9da0e-fb95-4523-8406-13d3bb1248a3 | F14: 202512529349300446 | G14: claude-opus-5 | H14: 2026-10-03T23:10:03+00:00 | I14: https://apps.irs.gov/pub/epostcard/990/xml/2025/2025_TEOS_XML_09A.zip#202512529349300446_public.xml
A16: B. Figure citations (every figure on the statement tabs, keyed by cell)
A17: Tab | B17: Cell | C17: Line item | D17: Form 990 line | E17: Key path | F17: Confidence | G17: As filed
A18: Financial Statements | B18: B73 | C18: 11a. Gross income from members or shareholders | D18: 11a | E18: part_v_other_irs_filings.members_and_shareholders_gross_income | F18: high | G18: 144340
A19: Financial Statements | B19: C73 | C19: 11a. Gross income from members or shareholders | D19: 11a | E19: part_v_other_irs_filings.members_and_shareholders_gross_income | F19: high | G19: 226545
A20: Financial Statements | B20: D73 | C20: 11a. Gross income from members or shareholders | D20: 11a | E20: part_v_other_irs_filings.members_and_shareholders_gross_income | F20: high | G20: 253626
A21: Financial Statements | B21: E73 | C21: 11a. Gross income from members or shareholders | D21: 11a | E21: part_v_other_irs_filings.members_and_shareholders_gross_income | F21: high | G21: 1454070
A22: Financial Statements | B22: F73 | C22: 11a. Gross income from members or shareholders | D22: 11a | E22: part_v_other_irs_filings.members_and_shareholders_gross_income | F22: high | G22: 255834
A23: Financial Statements | B23: B74 | C23: 11b. Gross income from other sources | D23: 11b | E23: part_v_other_irs_filings.other_sources_gross_income | F23: high | G23: 141
A24: Financial Statements | B24: C74 | C24: 11b. Gross income from other sources | D24: 11b | E24: part_v_other_irs_filings.other_sources_gross_income | F24: high | G24: 92
A25: Financial Statements | B25: D74 | C25: 11b. Gross income from other sources | D25: 11b | E25: part_v_other_irs_filings.other_sources_gross_income | F25: high | G25: 214
A26: Financial Statements | B26: E74 | C26: 11b. Gross income from other sources | D26: 11b | E26: part_v_other_irs_filings.other_sources_gross_income | F26: high | G26: 5805
A27: Financial Statements | B27: F74 | C27: 11b. Gross income from other sources | D27: 11b | E27: part_v_other_irs_filings.other_sources_gross_income | F27: high | G27: 13986
A28: Revenue (detail) | B28: B8 | C28: 2g. Total program service revenue | D28: 2g | E28: part_viii_revenue.total_program_service_revenue | F28: high | G28: 143360
A29: Revenue (detail) | B29: C8 | C29: 2g. Total program service revenue | D29: 2g | E29: part_viii_revenue.total_program_service_revenue | F29: high | G29: 225770
... A133: Net-assets reconciliation | B133: F10 | C133: 9. Other changes in net assets | D133: Part XI line 9 | E133: part_xi_reconciliation.other_changes_net_assets | F133: high | G133: 4
A135: C. Tie-out checks (filed vs computed; any nonzero variance is flagged red)
A136: Tab | B136: Check | C136: Fiscal year | D136: Filed | E136: Computed | F136: Variance (computed - filed)
A137: Revenue (detail) | B137: 12. Total revenue | C137: FY2020 | D137: 144481 | E137: ='Revenue (detail)'!B13 | F137: =E137-D137
A138: Revenue (detail) | B138: 12. Total revenue | C138: FY2021 | D138: 226637 | E138: ='Revenue (detail)'!C13 | F138: =E138-D138
A139: Revenue (detail) | B139: 12. Total revenue | C139: FY2022 | D139: 253840 | E139: ='Revenue (detail)'!D13 | F139: =E139-D139
A140: Revenue (detail) | B140: 12. Total revenue | C140: FY2023 | D140: 1458158 | E140: ='Revenue (detail)'!E13 | F140: =E140-D140
A141: Revenue (detail) | B141: 12. Total revenue | C141: FY2024 | D141: 269819 | E141: ='Revenue (detail)'!F13 | F141: =E141-D141
A142: Revenue (detail) | B142: 2g program service revenue = sum of lines 2a-2f (FY2024) | C142: FY2024 | D142: 251967 | E142: =SUM('Revenue (detail)'!C17:C18) | F142: =E142-D142
A143: Operating expenses (detail) | B143: 25. Total functional expenses | C143: FY2020 | D143: 132991 | E143: ='Operating expenses (detail)'!B18 | F143: =E143-D143
A144: Operating expenses (detail) | B144: 25. Total functional expenses | C144: FY2021 | D144: 155974 | E144: ='Operating expenses (detail)'!C18 | F144: =E144-D144
A145: Operating expenses (detail) | B145: 25. Total functional expenses | C145: FY2022 | D145: 147019 | E145: ='Operating expenses (detail)'!D18 | F145: =E145-D145
A146: Operating expenses (detail) | B146: 25. Total functional expenses | C146: FY2023 | D146: 193687 | E146: ='Operating expenses (detail)'!E18 | F146: =E146-D146
A147: Operating expenses (detail) | B147: 25. Total functional expenses | C147: FY2024 | D147: 238905 | E147: ='Operating expenses (detail)'!F18 | F147: =E147-D147
...

Sheet Provenance
A1: Build provenance | B1: Built from source commit d418ffb17485 (2026-10-06); source fingerprint a75a8eee82c65cf7; 192 companies (179 retail mutual, 4 irrigation mutual, 3 mutual, no PWSID, purpose not stated, 2 frozen non-mutual (special district), 2 wholesale mutual, 1 frozen non-mutual (investor-owned), 1 frozen non-mutual (municipal)); 91 gates; build id 3d08d6d2a855.
A2: source_commit | B2: d418ffb174855ab78000d391d42f898397b0d8aa
A3: source_commit_date | B3: 2026-10-06
A4: source_fingerprint | B4: a75a8eee82c65cf7096931f06e18affdc28686a02895b46538e7298b57c04d94
A5: gate_count | B5: 91
A6: build_id | B6: 3d08d6d2a855
A7: registry: frozen non-mutual (investor-owned) | B7: 1
A8: registry: frozen non-mutual (municipal) | B8: 1
A9: registry: frozen non-mutual (special district) | B9: 2
A10: registry: irrigation mutual | B10: 4
A11: registry: mutual, no PWSID, purpose not stated | B11: 3
A12: registry: retail mutual | B12: 179
A13: registry: wholesale mutual | B13: 2
