Workbook

Sheet Summary
A1: Clear Water Mutual Water Company
A2: Financial Summary - multi-year overview (USD)
A3: Entity ID: cawc_0165 | Fiscal year ends March 31.
A5: Presentation standard: every figure on the statement tabs is verified to its source filing and shown clean. A cell the filing does not report reads "not reported" (never estimated, never guessed).
A6: Citations, confidence tiers, and the filed-vs-computed tie-out checks live on the "Sources & audit" tab, keyed by cell, so every number is fully traceable without cluttering the statements. These pages are ready to use as filed.
A8: Metric | B8: FY2020 | C8: FY2021 | D8: FY2022 | E8: FY2023
A9: Operating results (USD)
A10: Total revenue | B10: 218417 | C10: 94582 | D10: 165552 | E10: 148330
A11: Total expenses | B11: 132205 | C11: 124898 | D11: 157244 | E11: 186592
A12: Net income | B12: 86212 | C12: -30316 | D12: 8308 | E12: -38262
A14: Financial position (USD, end of year)
A15: Total assets | B15: 450771 | C15: 423841 | D15: 432149 | E15: 417305
A16: Total liabilities | B16: 258747 | C16: 262133 | D16: 262133 | E16: 286745
A17: Net assets | B17: 192024 | C17: 161708 | D17: 170016 | E17: 130560
A19: Headline ratios
A20: Operating margin | B20: 0.39471287 | C20: -0.3205261 | D20: 0.050183628 | E20: -0.25795186
A21: Revenue growth (YoY) | B21: 0.7966209 | C21: -0.56696594 | D21: 0.75035419
A22: Return on assets | B22: 0.19125454 | C22: -0.071526823 | D22: 0.019224851 | E22: -0.091688333
A24: Figures as reported in source filings (full provenance on the Sources & audit tab). Parentheses denote negatives; ratios are computed upstream in financials_annual.

Sheet Notes
A1: Notes
A2: Human annotations from the versioned store (data/notes/). Annotations only: they never change a reported figure or a confidence tier.
A4: Date | B4: Tag | C4: Author | D4: Note
A5: No notes recorded yet.

Sheet Financial Statements
A1: Clear Water Mutual Water Company
A2: Financial Statements - income statement, balance sheet, cash flow, member income test (USD)
A3: Entity ID: cawc_0165 | Fiscal year ends March 31.
A5: INCOME STATEMENT - as reported (USD)
A6: Line item | B6: FY2020 | C6: FY2021 | D6: FY2022 | E6: FY2023
A7: Revenue
A8: Program service revenue | B8: 218417 | C8: 94582 | D8: 165552
A9: Investment income | B9: 0
A10: Net rental income | B10: 0
A11: Net gain/(loss) on investment sales | B11: 0
A12: Other revenue | B12: 0
A13: Contributions & grants | B13: 0
A14: Total revenue | B14: 218417 | C14: 94582 | D14: 165552
A16: Expenses
A17: Depreciation | B17: 7770 | C17: 8899 | D17: 9756
A18: Interest expense | B18: 4011 | C18: 3987 | D18: 7974
A19: Total expenses | B19: 132205 | C19: 124898 | D19: 157244 | E19: 186592
A21: Net income | B21: 86212 | C21: -30316 | D21: 8308 | E21: -38262
A24: BALANCE SHEET - as reported (USD, end of year)
A25: Line item | B25: FY2020 | C25: FY2021 | D25: FY2022 | E25: FY2023
A26: Assets
A27: Cash | B27: 30398 | C27: 11978 | D27: 23386 | E27: 1967
A28: Savings & temporary investments | B28: 0
A29: Accounts receivable | B29: 0
A30: Inventories | B30: 0
A31: Prepaid expenses | B31: 0
A32: Property, plant & equipment (gross) | B32: 329460 | C32: 428903 | D32: 428903
A33: Less: accumulated depreciation | B33: -184570 | C33: -193469 | D33: -203225
A34: Net property, plant & equipment | B34: 144890 | C34: 235434 | D34: 225678 | E34: 17359
A35: Total assets | B35: 450771 | C35: 423841 | D35: 432149 | E35: 417305
A37: Liabilities
A38: Accounts payable
A39: Mortgages & notes payable
A40: Total liabilities | B40: 258747 | C40: 262133 | D40: 262133 | E40: 286745
A42: Net Assets / Equity
A43: Capital stock
A44: Paid-in capital
A45: Retained earnings
A46: Net assets | B46: 192024 | C46: 161708 | D46: 170016 | E46: 130560
A49: CASH FLOW - derived proxy (USD)
...

Sheet Balance Sheet
A1: Clear Water Mutual Water Company
A2: Balance Sheet - as reported (USD, end of year)
A3: Entity ID: cawc_0165 | Fiscal year ends March 31.
A5: Line item | B5: FY2020 | C5: FY2021 | D5: FY2022 | E5: FY2023
A6: Assets
A7: Cash | B7: 30398 | C7: 11978 | D7: 23386 | E7: 1967
A8: Savings & temporary investments | B8: 0
A9: Accounts receivable | B9: 0
A10: Inventories | B10: 0
A11: Prepaid expenses | B11: 0
A12: Property, plant & equipment (gross) | B12: 329460 | C12: 428903 | D12: 428903
A13: Less: accumulated depreciation | B13: -184570 | C13: -193469 | D13: -203225
A14: Net property, plant & equipment | B14: 144890 | C14: 235434 | D14: 225678 | E14: 17359
A15: Total assets | B15: 450771 | C15: 423841 | D15: 432149 | E15: 417305
A17: Liabilities
A18: Accounts payable
A19: Mortgages & notes payable
A20: Total liabilities | B20: 258747 | C20: 262133 | D20: 262133 | E20: 286745
A22: Net Assets / Equity
A23: Capital stock
A24: Paid-in capital
A25: Retained earnings
A26: Net assets | B26: 192024 | C26: 161708 | D26: 170016 | E26: 130560
A28: Balance check (assets − liab. − net assets) | B28: 0 | C28: 0 | D28: 0 | E28: 0
A30: Net PP&E is the reported ppe_net column (gross less accumulated depreciation). The balance check should be ~0 where all three totals are reported; a non-zero value flags a reporting or extraction discrepancy worth reviewing.

Sheet Officers & contractors
A1: Clear Water Mutual Water Company
A2: Officers, Directors & Contractors - Form 990 Part VII (FY2022; USD)
A3: Entity ID: cawc_0165 | Fiscal year ends March 31.
A5: Section A - Officers, directors, trustees, key employees
A6: Name | B6: Title | C6: Reportable comp (org) | D6: Reportable comp (related) | E6: Other comp | F6: Total compensation
A7: Tom Hopkins | B7: Board President | C7: 0 | D7: 0 | E7: 0 | F7: 0
A8: Dan Dougherty | B8: Board Member | C8: 0 | D8: 0 | E8: 0 | F8: 0
A9: Betty Humes | B9: Treasurer | C9: 0 | D9: 0 | E9: 0 | F9: 0
A10: Leslie Olson | B10: Secretary | C10: 0 | D10: 0 | E10: 0 | F10: 0
A12: Section B - Independent contractors (over $100,000)
A13: Contractor | B13: Services | C13: Compensation
A15: Section A lists every officer, director, trustee and key employee filed for the latest year; the two with the highest total compensation are highlighted. Total compensation is computed (reportable org + related + other). Section B lists each independent contractor paid over $100,000; the return reports None such contractor(s). Source and confidence for every figure are on the Sources & audit tab.

Sheet Revenue (detail)
A1: Clear Water Mutual Water Company
A2: Revenue - Form 990 Part VIII (USD)
A3: Entity ID: cawc_0165 | Fiscal year ends March 31.
A5: Part VIII line | B5: FY2020 | C5: FY2021 | D5: FY2022
A6: Revenue by category
A7: 1h. Total contributions, gifts, grants | B7: 0 | C7: not reported | D7: not reported
A8: 2g. Total program service revenue | B8: 218417 | C8: 94582 | D8: 165552
A9: 3. Investment income | B9: 0 | C9: not reported | D9: not reported
A10: 6d. Net rental income | B10: 0 | C10: not reported | D10: not reported
A11: 7d. Net gain/(loss) from investment sales | B11: 0 | C11: not reported | D11: not reported
A12: 11e. Other revenue | B12: 0 | C12: not reported | D12: not reported
A13: 12. Total revenue | B13: =SUM(B7:B12) | C13: =SUM(C7:C12) | D13: =SUM(D7:D12)
A15: Program service revenue detail - FY2022 (lines 2a-2f)
A16: Description | B16: Business code | C16: Total revenue
A17: Membership Dues & Assessments | B17: 999000 | C17: 164105
A18: Administrative Fees Reimb | B18: 999000 | C18: 1447
A19: Revenue category subtotals are as filed. Total revenue (line 12) is a live SUM of the category cells above; its tie-out to the filed total is on the Sources & audit tab. Program service revenue detail is shown for the latest year, with its sum-to-line-2g check on that same audit tab.

Sheet Operating expenses (detail)
A1: Clear Water Mutual Water Company
A2: Statement of Functional Expenses - Form 990 Part IX (USD)
A3: Entity ID: cawc_0165 | Fiscal year ends March 31.
A5: Part IX line (column A Total) | B5: FY2020 | C5: FY2021 | D5: FY2022
A6: Functional expenses, column A Total - by year
A7: 1. Grants to domestic organizations and governments | B7: 0 | C7: not reported | D7: not reported
A8: 2. Grants to domestic individuals | B8: 0 | C8: not reported | D8: not reported
A9: 3. Grants to foreign organizations and individuals | B9: 0 | C9: not reported | D9: not reported
A10: 4. Benefits paid to or for members | B10: 0 | C10: not reported | D10: not reported
A11: 5. Compensation of current officers, directors, trustees | B11: 0 | C11: not reported | D11: not reported
A12: 6. Compensation to disqualified persons | B12: 0 | C12: not reported | D12: not reported
A13: 7. Other salaries and wages | B13: 0 | C13: not reported | D13: not reported
A14: 8. Pension plan accruals and contributions | B14: 0 | C14: not reported | D14: not reported
A15: 9. Other employee benefits | B15: 0 | C15: not reported | D15: not reported
A16: 10. Payroll taxes | B16: 0 | C16: not reported | D16: not reported
A17: 11a. Fees for services: management | B17: 0 | C17: not reported | D17: not reported
A18: 11b. Fees for services: legal | B18: 0 | C18: not reported | D18: not reported
A19: 11c. Fees for services: accounting | B19: 16340 | C19: 1227 | D19: 23946
A20: 11d. Fees for services: lobbying | B20: 0 | C20: not reported | D20: not reported
A21: 11e. Fees for services: professional fundraising | B21: 0 | C21: not reported | D21: not reported
A22: 11f. Fees for services: investment management | B22: 0 | C22: not reported | D22: not reported
A23: 11g. Fees for services: other | B23: 0 | C23: not reported | D23: 68049
A24: 12. Advertising and promotion | B24: 0 | C24: not reported | D24: not reported
A25: 13. Office expenses | B25: 1464 | C25: 3969 | D25: 1977
A26: 14. Information technology | B26: 0 | C26: not reported | D26: not reported
A27: 15. Royalties | B27: 0 | C27: not reported | D27: not reported
A28: 16. Occupancy | B28: 0 | C28: not reported | D28: not reported
A29: 17. Travel | B29: 0 | C29: 1500 | D29: not reported
A30: 18. Payments of travel/entertainment for public officials | B30: 0 | C30: not reported | D30: not reported
A31: 19. Conferences, conventions, and meetings | B31: 0 | C31: not reported | D31: not reported
A32: 20. Interest | B32: 4011 | C32: 3987 | D32: 7974
A33: 21. Payments to affiliates | B33: 0 | C33: not reported | D33: not reported
A34: 22. Depreciation, depletion, and amortization | B34: 7770 | C34: 8899 | D34: 9756
A35: 23. Insurance | B35: 3269 | C35: 6334 | D35: not reported
A36: 24. Independent Contractors | B36: 62948 | C36: 68228 | D36: 750
A37: 24. Plant Supplies | B37: 8293 | C37: 2918 | D37: 11276
A38: 24. Plant Hardware | B38: 6003 | C38: 2651 | D38: 2405
A39: 24. Lab Fees | B39: 3652 | C39: 4874 | D39: 7758
A40: 24e. All other expenses | B40: 18455 | C40: 20311 | D40: 23353
A41: 25. Total functional expenses | B41: =SUM(B7:B40) | C41: =SUM(C7:C40) | D41: =SUM(D7:D40)
...

Sheet Balance sheet (detail)
A1: Clear Water Mutual Water Company
A2: Balance Sheet - Form 990 Part X (end of year, USD)
A3: Entity ID: cawc_0165 | Fiscal year ends March 31.
A5: Part X line (column B, EOY) | B5: FY2020 | C5: FY2021 | D5: FY2022
A6: Assets
A7: 1. Cash - non-interest-bearing | B7: 30398 | C7: 11978 | D7: 23386
A8: 2. Savings and temporary cash investments | B8: 0 | C8: not reported | D8: not reported
A9: 3. Pledges and grants receivable, net | B9: 0 | C9: not reported | D9: not reported
A10: 4. Accounts receivable, net | B10: 0 | C10: not reported | D10: not reported
A11: 5. Receivables from officers/directors/trustees | B11: 0 | C11: not reported | D11: not reported
A12: 6. Receivables from disqualified persons | B12: 0 | C12: not reported | D12: not reported
A13: 7. Notes and loans receivable, net | B13: 0 | C13: not reported | D13: not reported
A14: 8. Inventories for sale or use | B14: 0 | C14: not reported | D14: not reported
A15: 9. Prepaid expenses and deferred charges | B15: 0 | C15: not reported | D15: not reported
A16: 10c. Land, buildings, and equipment, net | B16: 144890 | C16: 235434 | D16: 225678
A17: 11. Investments - publicly traded securities | B17: 0 | C17: not reported | D17: not reported
A18: 12. Investments - other securities | B18: 0 | C18: not reported | D18: not reported
A19: 13. Investments - program-related | B19: 0 | C19: not reported | D19: not reported
A20: 14. Intangible assets | B20: 0 | C20: not reported | D20: not reported
A21: 15. Other assets | B21: 275483 | C21: 176429 | D21: 183085
A22: 16. Total assets | B22: =SUM(B7:B21) | C22: =SUM(C7:C21) | D22: =SUM(D7:D21)
A24: Liabilities
A25: 25. Other liabilities | B25: 258747 | C25: 262133 | D25: 262133
A26: 26. Total liabilities | B26: =SUM(B25:B25) | C26: =SUM(C25:C25) | D26: =SUM(D25:D25)
A28: Net assets / fund balances
A29: 27. Net assets without donor restrictions | B29: 192024 | C29: 161708 | D29: 170016
A30: 32. Total net assets / fund balances | B30: =SUM(B29:B29) | C30: =SUM(C29:C29) | D30: =SUM(D29:D29)
A32: Every Part X line is end-of-year (column B), as filed. Section totals (lines 16 / 26 / 32) are live SUMs of the lines above; their tie-outs and the balance-sheet identity (16 = 26 + 32) are on the Sources & audit tab. This filer files as a non-FASB mutual, so net assets sit on lines 29-31 (capital stock / paid-in capital / retained earnings); lines this filer does not report are omitted. Lines 10a/10b net into line 10c (shown).

Sheet Net-assets reconciliation
A1: Clear Water Mutual Water Company
A2: Reconciliation of Net Assets - Form 990 Part XI (USD)
A3: Entity ID: cawc_0165 | Fiscal year ends March 31.
A5: Part XI line | B5: FY2020 | C5: FY2021 | D5: FY2022
A6: Reconciliation
A7: 4. Net assets, beginning of year | B7: 105812 | C7: 192024 | D7: 161708
A8: 3. Revenue less expenses | B8: 86212 | C8: -30316 | D8: 8308
A9: 8. Prior period adjustments | B9: not reported | C9: not reported | D9: not reported
A10: 9. Other changes in net assets | B10: not reported | C10: not reported | D10: not reported
A11: 10. Net assets, end of year | B11: =SUM(B7,B8,B9,B10) | C11: =SUM(C7,C8,C9,C10) | D11: =SUM(D7,D8,D9,D10)
A13: Part XI reconciles beginning to ending net assets. Ending net assets (line 10) is a live formula: beginning balance (line 4) + revenue less expenses (line 3) + prior-period adjustments (8) + other changes (9). Its tie-out to the filed line 10 (and to Part X line 32) is on the Sources & audit tab. Lines 5-7 (unrealized gains, donated services, investment expenses) are not filed by this entity.

Sheet Cash flow proxies
A1: Clear Water Mutual Water Company
A2: Cash Flow Proxies - derived (USD)
A3: Entity ID: cawc_0165 | Fiscal year ends March 31.
A5: PROXY ONLY. The source filings contain no statement of cash flows. Lines below are derived from the reported income statement and year-over-year balance-sheet changes; treat as directional estimates, not GAAP cash flows. The earliest year has no prior period, so its delta cells are blank.
A7: Proxy line (USD) | B7: FY2020 | C7: FY2021 | D7: FY2022 | E7: FY2023
A8: Operating
A9: Net income | B9: 86212 | C9: -30316 | D9: 8308 | E9: -38262
A10: + Depreciation (reported) | B10: 7770 | C10: 8899 | D10: 9756
A11: − Δ Accounts receivable
A12: − Δ Inventories
A13: − Δ Prepaid expenses
A14: + Δ Accounts payable
A15: Operating cash flow proxy | C15: -21417 | D15: 18064 | E15: -38262
A17: Investing
A18: − Δ PP&E gross (capex proxy) | C18: -99443 | D18: 0
A20: Financing
A21: Δ Mortgages & notes payable
A23: Reconciliation
A24: Δ Cash + temp. investments (actual) | C24: -18420 | D24: 11408 | E24: -21419
A26: The capex proxy assumes gross PP&E rises only via capital spending (it ignores disposals). 'Δ Cash + temp. investments (actual)' is the real reported change in liquid funds and is the most reliable line here; the operating/investing/financing proxies will not perfectly reconcile to it.

Sheet Ratios
A1: Clear Water Mutual Water Company
A2: Financial Ratios
A3: Entity ID: cawc_0165 | Fiscal year ends March 31.
A5: Ratio | B5: FY2020 | C5: FY2021 | D5: FY2022 | E5: FY2023
A6: Profitability (computed upstream)
A7: Operating margin (NI / revenue) | B7: 0.39471287 | C7: -0.3205261 | D7: 0.050183628 | E7: -0.25795186
A8: Expense ratio (expenses / revenue) | B8: 0.60528713 | C8: 1.3205261 | D8: 0.94981637 | E8: 1.2579519
A9: Return on assets (NI / assets) | B9: 0.19125454 | C9: -0.071526823 | D9: 0.019224851 | E9: -0.091688333
A10: Revenue growth (YoY) | B10: 0.7966209 | C10: -0.56696594 | D10: 0.75035419
A12: Leverage & solvency
A13: Debt-to-assets (liab. / assets) | B13: 0.57400986 | C13: 0.61847013 | D13: 0.60658014 | E13: 0.68713531
A14: Equity ratio (net assets / assets) | B14: 0.42599014 | C14: 0.38152987 | D14: 0.39341986 | E14: 0.31286469
A16: Liquidity & asset profile (derived here)
A17: Current ratio (current assets / AP)
A18: Cash ratio ((cash+temp inv.) / total liab.) | B18: 0.11748156 | C18: 0.045694361 | D18: 0.089214254 | E18: 0.0068597534
A19: Asset age proxy (accum. deprec. / gross PP&E) | B19: 0.56021975 | C19: 0.45107868 | D19: 0.47382508
A21: Upstream ratios are read from financials_annual; derived ratios are computed only where inputs are reported. Current ratio uses accounts payable as the current-liability proxy (the filings do not split current vs. long-term liabilities). Asset age proxy: a higher % implies older / more depreciated infrastructure.

Sheet Unit economics
A1: Clear Water Mutual Water Company
A2: Unit economics - per-customer revenue by category (USD)
A3: Entity ID: cawc_0165 | Fiscal year ends March 31.
A5: Every metric here is PER CUSTOMER (a metered service connection). It is not a per-member figure; the member (shareholder) count is a different denominator, shown in the denominator block. The visible cell shows the value and its classification; the numerator, denominator, formula, and rationale are in each metric's LOGIC popup.
A6: Per-customer denominator (service connections) | C6: State Water Board eAR Section 4
A7: Total annual revenue (eAR Section 8b B1.8) | C7: eAR Section 8b total annual revenue not reported for this system.
A8: Primary source
A10: Revenue categories (value, classification, per customer, share)
A11: Revenue category | B11: Classification | C11: Value (USD) | D11: Per customer | E11: Share of revenue
A12: Water sales revenue | B12: not reported | C12: not reported | D12: not reported | E12: not reported
A13: Assessment revenue (990 program-service revenue not matched to eAR water-rate revenue) | B13: IMPOSSIBLE | C13: IMPOSSIBLE | D13: IMPOSSIBLE | E13: IMPOSSIBLE
A14: Meter revenue | B14: not reported | C14: not reported | D14: not reported | E14: not reported
A15: Overage or tiered penalty revenue | B15: not reported | C15: not reported | D15: not reported | E15: not reported
A17: Water sales revenue - not reported
A18: Not reported: this system filed an eAR but no Section 8b revenue block, so there is no filed water-sales figure. Not fallen back to a different year.
A19: Reason: No filed eAR Section 8b water-rate revenue for this system.
A21: Assessment revenue (990 program-service revenue not matched to eAR water-rate revenue) - IMPOSSIBLE
A22: Not computed. A period-aligned residual is not possible for this filer.
A23: Reason: Not derivable. The eAR Section 8b is reporting year None while the Form 990 fiscal year ends None; the two period ends are not aligned, so a period-aligned residual cannot be computed.
A25: Meter revenue - not reported
A26: Not reported. This category is not built because doing so would double-count.
A27: Reason: The eAR Section 8a reports a base/meter rate PRICE, but the filing carries no meter revenue line and no tier volume, and the base charge is already inside the water-sales revenue (eAR Section 8b water rates). Building a separate meter figure would double-count. Not backed into from a total.
A29: Overage or tiered penalty revenue - not reported
A30: Not reported. This category is not built because doing so would double-count.
A31: Reason: The eAR Section 8a reports tiered/overage rate PRICES, but the filing carries no overage revenue and no tier consumption volume, and any overage billed is already inside the water-sales revenue. Building it would double-count. Not backed into from a total.

Sheet Rate structure
A1: Clear Water Mutual Water Company
A2: Rate structure and representative bill - eAR Section 8a
A3: Entity ID: cawc_0165 | Fiscal year ends March 31.
A5: This block is a rate-schedule illustration at defined usage levels. It is NOT billed revenue and not a claim about any real customer's usage. The revenue side of unit economics is the separate Unit Economics block.
A6: No filed eAR Section 8a rate schedule is staged for this system.

Sheet Operational metrics
A1: Clear Water Mutual Water Company
A2: Operational metrics - plant per acre, density, terrain
A3: Entity ID: cawc_0165 | Fiscal year ends March 31.
A5: Plant assets per acre
A6: Service-area acres | B6: 20.6 | C6: Geodesic area (WGS84 spherical excess) of the SABL service-area polygon.
A7: Fiscal year | B7: Gross plant per acre (primary) | C7: Net plant per acre
A8: FY2020 | B8: 15993.204 | C8: 7033.4951
A9: FY2021 | B9: 20820.534 | C9: 11428.835
A10: FY2022 | B10: 20820.534 | C10: 10955.243
A11: FY2023 | C11: 842.6699
A12: Infrastructure built per acre of service area. Gross plant per acre is the primary read because it measures how much plant the system has put in the ground per acre, and unlike net plant it does not fall over time purely because the assets depreciate on the books. Net plant per acre is shown alongside as the depreciated book value per acre.
A13: Formula: gross plant per acre = Form 990 Part X line 10a (land, buildings, and equipment, gross) / SABL service-area acres; net plant per acre uses Part X line 10c (net)
A14: Source lines: Form 990 Part X line 10a (gross) and line 10c (net); Geodesic area (WGS84 spherical excess) of the SABL service-area polygon.
A15: Confidence: medium. This is worked out from filed figures (a ratio, or a year-to-year change), so it is one step removed from the raw numbers.. Filed gross/net plant over the measured SABL service-area acreage.
A17: Connections per acre
A18: Connections per acre | B18: 4.32 | C18: 89 connections / 20.6 acres. CA State Water Board SABL SERVICE_CONNECTIONS; Geodesic area (WGS84 spherical excess) of the SABL service-area polygon.

Sheet Supply & weather
A1: Clear Water Mutual Water Company
A2: Supply and weather indicators (DWR water year)
A3: Entity ID: cawc_0165 | Fiscal year ends March 31.
A5: Reporting calendar: Different reporting periods. The DWR water year runs October 1 to September 30; this system's fiscal year ends March 31, so the two period ends are six months apart. Read the two side by side with that in mind. Neither series is recast: both are reported as filed. A water year is named for the calendar year it ends in, so WY2024 and FY2024 share a number without covering the same twelve months.
A7: Indicator | B7: WY2020 | C7: WY2021 | D7: WY2022 | E7: WY2023
A8: Water-year type (Sacramento Valley) | B8: Dry | C8: Critical | D8: Critical | E8: Wet
A9: Peak drought, county County | B9: not reported | C9: not reported | D9: not reported | E9: not reported
A10: Precip, percent of normal (8-Station Index) | B10: 63 | C10: 48 | D10: 86 | E10: 133
A11: Snowpack, April 1 percent of average | B11: 53% | C11: 59% | D11: 38% | E11: 237%
A12: State Water Project allocation | B12: 20% | C12: 5% | D12: 5% | E12: 100%

Sheet How this was built
A1: Clear Water Mutual Water Company
A2: How this was built - forensic lineage
A3: Entity ID: cawc_0165 | Fiscal year ends March 31.
A5: A plain account of the forensic lineage behind the hard-to-source metrics: what sources were checked, what was found, what was derived, and what could not be built and why. Every figure marked DERIVED or IMPOSSIBLE above is traceable to a line here.
A7: Water-sales revenue per customer - not reported
A8: Sources checked | B8: State Water Board eAR Section 8b (water-rate revenue B1.1/B1.2); State Water Board eAR Section 4 (connection count, same reporting year); audited financial statement (secondary cross-check, where published)
A9: What was found | B9: The eAR Section 8b reports water-rate revenue for reporting year None, so this is a DIRECT filed figure; per customer it is divided by the eAR Section 4 connection count for the same reporting year, so numerator and denominator share the year.
A11: Assessment revenue (residual) - IMPOSSIBLE
A12: Sources checked | B12: Form 990 Part VIII line 2 (program-service revenue); State Water Board eAR Section 8b (water-rate revenue B1.1/B1.2); eAR Section 8b filer comment (WRRevenueComments)
A13: What was found | B13: A period-aligned residual cannot be computed for this filer, so the metric is rendered IMPOSSIBLE rather than guessed.
A14: Caveat | B14: Not derivable. The eAR Section 8b is reporting year None while the Form 990 fiscal year ends None; the two period ends are not aligned, so a period-aligned residual cannot be computed.
A16: Meter revenue - not reported
A17: Sources checked | B17: State Water Board eAR Section 8a (rate prices); State Water Board eAR Section 8b (revenue lines); audited financial statement
A18: What was found | B18: The rate price exists in Section 8a but no revenue or tier volume is reported, and the base charge is already inside water sales.
A19: Caveat | B19: The eAR Section 8a reports a base/meter rate PRICE, but the filing carries no meter revenue line and no tier volume, and the base charge is already inside the water-sales revenue (eAR Section 8b water rates). Building a separate meter figure would double-count. Not backed into from a total.
A21: Overage / tiered-penalty revenue - not reported
A22: Sources checked | B22: State Water Board eAR Section 8a (rate prices); State Water Board eAR Section 8b (revenue lines); audited financial statement
A23: What was found | B23: The rate price exists in Section 8a but no revenue or tier volume is reported, and the base charge is already inside water sales.
A24: Caveat | B24: The eAR Section 8a reports tiered/overage rate PRICES, but the filing carries no overage revenue and no tier consumption volume, and any overage billed is already inside the water-sales revenue. Building it would double-count. Not backed into from a total.
A26: eAR Section 8b reporting-period basis - sourced
A27: Sources checked | B27: eAR Section 8b B0.1 (WRFinancialReportingPeriod); eAR Section 8b B0.2 (WRFiscalYearStartDate)
A28: What was found | B28: The reporting basis (fiscal vs calendar year) is read from the filer's own B0.1/B0.2 answer and staged verbatim, never hardcoded, so the 990 comparison and the residual are period-aligned.
A30: Member (shareholder) count denominator - not reported
A31: Sources checked | B31: Form 990 (no member count stated); company website
A32: What was found | B32: No filing states a member/shareholder count, so the per-member unit economics read not reported rather than borrowing the connection count.
A34: Water volume delivered (acre-feet) - not reported
A35: Sources checked | B35: Form 990 (not in the filing); Consumer Confidence Report; eAR Section 6 (PRA-gated)
A36: What was found | B36: Volume delivered in acre-feet is not in the Form 990 and the CCR states only a source mix, so the per-acre-foot metrics read not reported; the eAR Section 6 is named as the source still needed.

Sheet Sources & audit
A1: Clear Water Mutual Water Company
A2: Sources & audit - full provenance and tie-outs (kept off the statements so they read clean)
A3: Entity ID: cawc_0165 | Fiscal year ends March 31.
A5: Presentation standard: every figure on the statement tabs is verified to its source filing and shown clean. A cell the filing does not report reads "not reported" (never estimated, never guessed).
A6: Citations, confidence tiers, and the filed-vs-computed tie-out checks live on the "Sources & audit" tab, keyed by cell, so every number is fully traceable without cluttering the statements. These pages are ready to use as filed.
A8: A. Filing provenance (one row per staged extraction)
A9: Fiscal year | B9: Period end | C9: Filing type | D9: Confidence | E9: Extraction ID | F9: Object ID | G9: Extracted by | H9: Extracted at | I9: Source URL
A10: FY2020 | B10: 2020-03-31 | C10: 990 | D10: high | E10: 74d5f471-b7ab-41c8-84ea-fcde72057aba | F10: 202110089349301766 | G10: claude-opus-5 | H10: 2026-10-05T16:06:10+00:00 | I10: https://apps.irs.gov/pub/epostcard/990/xml/2021/2021_TEOS_XML_01A.zip#202110089349301766_public.xml
A11: FY2021 | B11: 2021-03-31 | C11: 990 | D11: high | E11: d0f8211b-40b6-4fa4-bdcb-1e8e61026ba0 | F11: 202240449349300404 | G11: claude-opus-5 | H11: 2026-10-05T16:06:10+00:00 | I11: https://apps.irs.gov/pub/epostcard/990/xml/2022/2022_TEOS_XML_01A.zip#202240449349300404_public.xml
A12: FY2022 | B12: 2022-03-31 | C12: 990 | D12: high | E12: 77853a76-f136-487f-b5a0-c6498885afa3 | F12: 202340319349300424 | G12: claude-opus-5 | H12: 2026-10-05T16:06:10+00:00 | I12: https://apps.irs.gov/pub/epostcard/990/xml/2023/2023_TEOS_XML_02A.zip#202340319349300424_public.xml
A13: FY2023 | B13: 2023-03-31 | C13: 990-EZ | D13: high | E13: aaf58993-0c9d-424a-90c5-8cb14cd3cc11 | F13: 202400469349201910 | G13: claude-opus-5 | H13: 2026-10-05T16:06:10+00:00 | I13: https://apps.irs.gov/pub/epostcard/990/xml/2024/2024_TEOS_XML_02A.zip#202400469349201910_public.xml
A15: B. Figure citations (every figure on the statement tabs, keyed by cell)
A16: Tab | B16: Cell | C16: Line item | D16: Form 990 line | E16: Key path | F16: Confidence | G16: As filed
A17: Financial Statements | B17: C73 | C17: 11a. Gross income from members or shareholders | D17: 11a | E17: part_v_other_irs_filings.members_and_shareholders_gross_income | F17: high | G17: 94617
A18: Financial Statements | B18: D73 | C18: 11a. Gross income from members or shareholders | D18: 11a | E18: part_v_other_irs_filings.members_and_shareholders_gross_income | F18: high | G18: 164105
A19: Financial Statements | B19: C74 | C19: 11b. Gross income from other sources | D19: 11b | E19: part_v_other_irs_filings.other_sources_gross_income | F19: high | G19: 0
A20: Financial Statements | B20: D74 | C20: 11b. Gross income from other sources | D20: 11b | E20: part_v_other_irs_filings.other_sources_gross_income | F20: high | G20: 1447
A21: Revenue (detail) | B21: B7 | C21: 1h. Total contributions, gifts, grants | D21: 1h | E21: part_viii_revenue.total_contributions | F21: high | G21: 0
A22: Revenue (detail) | B22: B8 | C22: 2g. Total program service revenue | D22: 2g | E22: part_viii_revenue.total_program_service_revenue | F22: high | G22: 218417
A23: Revenue (detail) | B23: C8 | C23: 2g. Total program service revenue | D23: 2g | E23: part_viii_revenue.total_program_service_revenue | F23: high | G23: 94582
A24: Revenue (detail) | B24: D8 | C24: 2g. Total program service revenue | D24: 2g | E24: part_viii_revenue.total_program_service_revenue | F24: high | G24: 165552
A25: Revenue (detail) | B25: B9 | C25: 3. Investment income | D25: 3 | E25: part_viii_revenue.investment_income | F25: high | G25: 0
A26: Revenue (detail) | B26: B10 | C26: 6d. Net rental income | D26: 6d | E26: part_viii_revenue.net_rental_income | F26: high | G26: 0
A27: Revenue (detail) | B27: B11 | C27: 7d. Net gain/(loss) from investment sales | D27: 7d | E27: part_viii_revenue.net_gain_or_loss_investments | F27: high | G27: 0
A28: Revenue (detail) | B28: B12 | C28: 11e. Other revenue | D28: 11e | E28: part_viii_revenue.other_revenue_total | F28: high | G28: 0
... A104: Net-assets reconciliation | B104: D8 | C104: 3. Revenue less expenses | D104: Part XI line 3 | E104: part_xi_reconciliation.reconciliation_revenue_expenses | F104: high | G104: 8308
A106: C. Tie-out checks (filed vs computed; any nonzero variance is flagged red)
A107: Tab | B107: Check | C107: Fiscal year | D107: Filed | E107: Computed | F107: Variance (computed - filed)
A108: Revenue (detail) | B108: 12. Total revenue | C108: FY2020 | D108: 218417 | E108: ='Revenue (detail)'!B13 | F108: =E108-D108
A109: Revenue (detail) | B109: 12. Total revenue | C109: FY2021 | D109: 94582 | E109: ='Revenue (detail)'!C13 | F109: =E109-D109
A110: Revenue (detail) | B110: 12. Total revenue | C110: FY2022 | D110: 165552 | E110: ='Revenue (detail)'!D13 | F110: =E110-D110
A111: Revenue (detail) | B111: 2g program service revenue = sum of lines 2a-2f (FY2022) | C111: FY2022 | D111: 165552 | E111: =SUM('Revenue (detail)'!C17:C18) | F111: =E111-D111
A112: Operating expenses (detail) | B112: 25. Total functional expenses | C112: FY2020 | D112: 132205 | E112: ='Operating expenses (detail)'!B41 | F112: =E112-D112
A113: Operating expenses (detail) | B113: 25. Total functional expenses | C113: FY2021 | D113: 124898 | E113: ='Operating expenses (detail)'!C41 | F113: =E113-D113
A114: Operating expenses (detail) | B114: 25. Total functional expenses | C114: FY2022 | D114: 157244 | E114: ='Operating expenses (detail)'!D41 | F114: =E114-D114
A115: Operating expenses (detail) | B115: Part IX column split: col A = B + C + D (FY2022) | C115: FY2022 | D115: ='Operating expenses (detail)'!B50 | E115: ='Operating expenses (detail)'!C50+'Operating expenses (detail)'!D50+'Operating expenses (detail)'!E50 | F115: =E115-D115
A116: Balance sheet (detail) | B116: 16. Total assets | C116: FY2020 | D116: 450771 | E116: ='Balance sheet (detail)'!B22 | F116: =E116-D116
A117: Balance sheet (detail) | B117: 16. Total assets | C117: FY2021 | D117: 423841 | E117: ='Balance sheet (detail)'!C22 | F117: =E117-D117
A118: Balance sheet (detail) | B118: 16. Total assets | C118: FY2022 | D118: 432149 | E118: ='Balance sheet (detail)'!D22 | F118: =E118-D118
A119: Balance sheet (detail) | B119: 26. Total liabilities | C119: FY2020 | D119: 258747 | E119: ='Balance sheet (detail)'!B26 | F119: =E119-D119
...

Sheet Provenance
A1: Build provenance | B1: Built from source commit d418ffb17485 (2026-10-06); source fingerprint a75a8eee82c65cf7; 192 companies (179 retail mutual, 4 irrigation mutual, 3 mutual, no PWSID, purpose not stated, 2 frozen non-mutual (special district), 2 wholesale mutual, 1 frozen non-mutual (investor-owned), 1 frozen non-mutual (municipal)); 91 gates; build id 3d08d6d2a855.
A2: source_commit | B2: d418ffb174855ab78000d391d42f898397b0d8aa
A3: source_commit_date | B3: 2026-10-06
A4: source_fingerprint | B4: a75a8eee82c65cf7096931f06e18affdc28686a02895b46538e7298b57c04d94
A5: gate_count | B5: 91
A6: build_id | B6: 3d08d6d2a855
A7: registry: frozen non-mutual (investor-owned) | B7: 1
A8: registry: frozen non-mutual (municipal) | B8: 1
A9: registry: frozen non-mutual (special district) | B9: 2
A10: registry: irrigation mutual | B10: 4
A11: registry: mutual, no PWSID, purpose not stated | B11: 3
A12: registry: retail mutual | B12: 179
A13: registry: wholesale mutual | B13: 2
