Workbook

Sheet Summary
A1: Triple R Mutual Water Company
A2: Financial Summary - multi-year overview (USD)
A3: Entity ID: cawc_0093 | Fiscal year ends December 31.
A5: Presentation standard: every figure on the statement tabs is verified to its source filing and shown clean. A cell the filing does not report reads "not reported" (never estimated, never guessed).
A6: Citations, confidence tiers, and the filed-vs-computed tie-out checks live on the "Sources & audit" tab, keyed by cell, so every number is fully traceable without cluttering the statements. These pages are ready to use as filed.
A8: Metric | B8: FY2020 | C8: FY2021 | D8: FY2022 | E8: FY2023 | F8: FY2024 | G8: FY2025
A9: Operating results (USD)
A10: Total revenue | B10: 108545 | C10: 114629 | D10: 103998 | E10: 113096 | F10: 129555 | G10: 143451
A11: Total expenses | B11: 90271 | C11: 98842 | D11: 101948 | E11: 124319 | F11: 135631 | G11: 134952
A12: Net income | B12: 18274 | C12: 15787 | D12: 2050 | E12: -11223 | F12: -6076 | G12: 8499
A14: Financial position (USD, end of year)
A15: Total assets | B15: 295776 | C15: 311563 | D15: 313613 | E15: 330355 | F15: 321733 | G15: 304014
A16: Total liabilities | E16: 27965 | F16: 26218
A17: Net assets | B17: 295776 | C17: 311563 | D17: 313613 | E17: 302390 | F17: 295515 | G17: 304014
A19: Headline ratios
A20: Operating margin | B20: 0.16835414 | C20: 0.13772257 | D20: 0.019711918 | E20: -0.099234279 | F20: -0.046899 | G20: 0.059246711
A21: Revenue growth (YoY)
A22: Return on assets | B22: 0.061783241 | C22: 0.05067033 | D22: 0.0065367188 | E22: -0.033972545 | F22: -0.018885225 | G22: 0.027955949
A24: Figures as reported in source filings (full provenance on the Sources & audit tab). Parentheses denote negatives; ratios are computed upstream in financials_annual.

Sheet Notes
A1: Notes
A2: Human annotations from the versioned store (data/notes/). Annotations only: they never change a reported figure or a confidence tier.
A4: Date | B4: Tag | C4: Author | D4: Note
A5: 2026-09-23 | B5: clarification | C5: Brendan | D5: triplerwater.com was this company's own website. An archived 2024 snapshot reads 'Triple R Mutual Water Co.', serving 'Triple R Estates of Springville California', with its own board members, FAQ and bill pay pages. The domain now returns NXDOMAIN and whois returns no match, so the registration has lapsed. The contact record therefore states that there is no current website, and the lapsed domain is deliberately not recorded as one: a high confidence address that does not resolve would be worse for a reader than an honest absence.

Sheet Financial Statements
A1: Triple R Mutual Water Company
A2: Financial Statements - income statement, balance sheet, cash flow, member income test (USD)
A3: Entity ID: cawc_0093 | Fiscal year ends December 31.
A5: INCOME STATEMENT - as reported (USD)
A6: Line item | B6: FY2020 | C6: FY2021 | D6: FY2022 | E6: FY2023 | F6: FY2024 | G6: FY2025
A7: Revenue
A8: Program service revenue
A9: Investment income
A10: Net rental income
A11: Net gain/(loss) on investment sales
A12: Other revenue
A13: Contributions & grants
A14: Total revenue
A16: Expenses
A17: Depreciation
A18: Interest expense
A19: Total expenses | B19: 90271 | C19: 98842 | D19: 101948 | E19: 124319 | F19: 135631 | G19: 134952
A21: Net income | B21: 18274 | C21: 15787 | D21: 2050 | E21: -11223 | F21: -6076 | G21: 8499
A24: BALANCE SHEET - as reported (USD, end of year)
A25: Line item | B25: FY2020 | C25: FY2021 | D25: FY2022 | E25: FY2023 | F25: FY2024 | G25: FY2025
A26: Assets
A27: Cash | B27: 295776 | C27: 311563 | D27: 313613 | E27: 330355 | F27: 321733 | G27: 164010
A28: Savings & temporary investments
A29: Accounts receivable
A30: Inventories
A31: Prepaid expenses
A32: Property, plant & equipment (gross)
A33: Less: accumulated depreciation
A34: Net property, plant & equipment | G34: 128207
A35: Total assets | B35: 295776 | C35: 311563 | D35: 313613 | E35: 330355 | F35: 321733 | G35: 304014
A37: Liabilities
A38: Accounts payable
A39: Mortgages & notes payable
A40: Total liabilities | E40: 27965 | F40: 26218
A42: Net Assets / Equity
A43: Capital stock
A44: Paid-in capital
A45: Retained earnings
A46: Net assets | B46: 295776 | C46: 311563 | D46: 313613 | E46: 302390 | F46: 295515 | G46: 304014
A49: CASH FLOW - derived proxy (USD)
...

Sheet Balance Sheet
A1: Triple R Mutual Water Company
A2: Balance Sheet - as reported (USD, end of year)
A3: Entity ID: cawc_0093 | Fiscal year ends December 31.
A5: Line item | B5: FY2020 | C5: FY2021 | D5: FY2022 | E5: FY2023 | F5: FY2024 | G5: FY2025
A6: Assets
A7: Cash | B7: 295776 | C7: 311563 | D7: 313613 | E7: 330355 | F7: 321733 | G7: 164010
A8: Savings & temporary investments
A9: Accounts receivable
A10: Inventories
A11: Prepaid expenses
A12: Property, plant & equipment (gross)
A13: Less: accumulated depreciation
A14: Net property, plant & equipment | G14: 128207
A15: Total assets | B15: 295776 | C15: 311563 | D15: 313613 | E15: 330355 | F15: 321733 | G15: 304014
A17: Liabilities
A18: Accounts payable
A19: Mortgages & notes payable
A20: Total liabilities | E20: 27965 | F20: 26218
A22: Net Assets / Equity
A23: Capital stock
A24: Paid-in capital
A25: Retained earnings
A26: Net assets | B26: 295776 | C26: 311563 | D26: 313613 | E26: 302390 | F26: 295515 | G26: 304014
A28: Balance check (assets − liab. − net assets) | B28: 0 | C28: 0 | D28: 0 | E28: 0 | F28: 0 | G28: 0
A30: Net PP&E is the reported ppe_net column (gross less accumulated depreciation). The balance check should be ~0 where all three totals are reported; a non-zero value flags a reporting or extraction discrepancy worth reviewing.

Sheet Form 990-EZ Parts I & II
A1: Triple R Mutual Water Company
A2: Form 990-EZ - Part I (revenue, expenses, net assets) and Part II (balance sheet), as filed (USD)
A3: Entity ID: cawc_0093 | Fiscal year ends December 31.
A5: Form 990-EZ line | B5: FY2020 | C5: FY2021 | D5: FY2022 | E5: FY2023 | F5: FY2024 | G5: FY2025
A6: Revenue (Part I)
A7: 3. Membership dues and assessments | B7: 108539 | C7: 114600 | D7: 103994 | E7: 113092 | F7: 129550 | G7: 139445
A8: 4. Investment income | B8: 6 | C8: 29 | D8: 4 | E8: 4 | F8: 5 | G8: 275
A9: 9. Total revenue | B9: 108545 | C9: 114629 | D9: 103998 | E9: 113096 | F9: 129555 | G9: 143451
A11: Expenses (Part I)
A12: 13. Fees for services (independent contractors) | B12: 750 | C12: 750 | D12: 700 | E12: 85 | F12: 1300 | G12: 1400
A13: 16. Other expenses | B13: 89521 | C13: 98092 | D13: 101248 | E13: 124234 | F13: 134331 | G13: 133552
A14: 17. Total expenses | B14: =SUM(B12:B13) | C14: =SUM(C12:C13) | D14: =SUM(D12:D13) | E14: =SUM(E12:E13) | F14: =SUM(F12:F13) | G14: =SUM(G12:G13)
A16: Net-assets reconciliation (Part I)
A17: 19. Net assets or fund balances, beginning of year | B17: 277502 | C17: 295776 | D17: 311563 | E17: 313613 | F17: 301591 | G17: 295515
A18: 18. Excess or (deficit) for the year | B18: 18274 | C18: 15787 | D18: 2050 | E18: -11223 | F18: -6076 | G18: 8499
A19: 21. Net assets or fund balances, end of year | B19: =SUM(B17,B18) | C19: =SUM(C17,C18) | D19: =SUM(D17,D18) | E19: =SUM(E17,E18) | F19: =SUM(F17,F18) | G19: =SUM(G17,G18)
A21: Balance sheet (Part II, end of year - column B)
A22: 22. Cash, savings, and investments | B22: 295776 | C22: 311563 | D22: 313613 | E22: 330355 | F22: 321733 | G22: 164010
A23: 23. Land and buildings | B23: not reported | C23: not reported | D23: not reported | E23: not reported | F23: not reported | G23: 128207
A24: 24. Other assets | B24: not reported | C24: not reported | D24: not reported | E24: not reported | F24: not reported | G24: 11797
A25: 25. Total assets | B25: =SUM(B22:B24) | C25: =SUM(C22:C24) | D25: =SUM(D22:D24) | E25: =SUM(E22:E24) | F25: =SUM(F22:F24) | G25: =SUM(G22:G24)
A26: 26. Total liabilities | B26: not reported | C26: not reported | D26: not reported | E26: 27965 | F26: 26218 | G26: not reported
A27: 27. Net assets or fund balances | B27: 295776 | C27: 311563 | D27: 313613 | E27: 302390 | F27: 295515 | G27: 304014
A29: Form 990-EZ is the short form: revenue and expenses are on Part I and the balance sheet is the six-line Part II (no full-990 Parts VII-XI). Total expenses (line 17) and Total assets (line 25) are live SUMs of the lines above; Total revenue (line 9) is shown as filed because the EZ nets its lines 5-7 (sales of assets, gaming, inventory) into line 9 without itemizing them. Ending net assets (line 21) is recomputed live as beginning net assets (line 19) plus the excess or deficit (line 18); where the filer's own line 21 does not equal that sum, the variance is flagged red on the Sources & audit tab and carried exactly as filed, not reconciled. Every figure's citation and confidence are on the Sources & audit tab.

Sheet Cash flow proxies
A1: Triple R Mutual Water Company
A2: Cash Flow Proxies - derived (USD)
A3: Entity ID: cawc_0093 | Fiscal year ends December 31.
A5: PROXY ONLY. The source filings contain no statement of cash flows. Lines below are derived from the reported income statement and year-over-year balance-sheet changes; treat as directional estimates, not GAAP cash flows. The earliest year has no prior period, so its delta cells are blank.
A7: Proxy line (USD) | B7: FY2020 | C7: FY2021 | D7: FY2022 | E7: FY2023 | F7: FY2024 | G7: FY2025
A8: Operating
A9: Net income | B9: 18274 | C9: 15787 | D9: 2050 | E9: -11223 | F9: -6076 | G9: 8499
A10: + Depreciation (reported)
A11: − Δ Accounts receivable
A12: − Δ Inventories
A13: − Δ Prepaid expenses
A14: + Δ Accounts payable
A15: Operating cash flow proxy | C15: 15787 | D15: 2050 | E15: -11223 | F15: -6076 | G15: 8499
A17: Investing
A18: − Δ PP&E gross (capex proxy)
A20: Financing
A21: Δ Mortgages & notes payable
A23: Reconciliation
A24: Δ Cash + temp. investments (actual) | C24: 15787 | D24: 2050 | E24: 16742 | F24: -8622 | G24: -157723
A26: The capex proxy assumes gross PP&E rises only via capital spending (it ignores disposals). 'Δ Cash + temp. investments (actual)' is the real reported change in liquid funds and is the most reliable line here; the operating/investing/financing proxies will not perfectly reconcile to it.

Sheet Ratios
A1: Triple R Mutual Water Company
A2: Financial Ratios
A3: Entity ID: cawc_0093 | Fiscal year ends December 31.
A5: Ratio | B5: FY2020 | C5: FY2021 | D5: FY2022 | E5: FY2023 | F5: FY2024 | G5: FY2025
A6: Profitability (computed upstream)
A7: Operating margin (NI / revenue) | B7: 0.16835414 | C7: 0.13772257 | D7: 0.019711918 | E7: -0.099234279 | F7: -0.046899 | G7: 0.059246711
A8: Expense ratio (expenses / revenue) | B8: 0.83164586 | C8: 0.86227743 | D8: 0.98028808 | E8: 1.0992343 | F8: 1.046899 | G8: 0.94075329
A9: Return on assets (NI / assets) | B9: 0.061783241 | C9: 0.05067033 | D9: 0.0065367188 | E9: -0.033972545 | F9: -0.018885225 | G9: 0.027955949
A10: Revenue growth (YoY)
A12: Leverage & solvency
A13: Debt-to-assets (liab. / assets) | E13: 0.08465136 | F13: 0.081489931
A14: Equity ratio (net assets / assets) | B14: 1 | C14: 1 | D14: 1 | E14: 0.91534864 | F14: 0.91851007 | G14: 1
A16: Liquidity & asset profile (derived here)
A17: Current ratio (current assets / AP)
A18: Cash ratio ((cash+temp inv.) / total liab.) | E18: 11.813159 | F18: 12.271455
A19: Asset age proxy (accum. deprec. / gross PP&E)
A21: Upstream ratios are read from financials_annual; derived ratios are computed only where inputs are reported. Current ratio uses accounts payable as the current-liability proxy (the filings do not split current vs. long-term liabilities). Asset age proxy: a higher % implies older / more depreciated infrastructure.

Sheet Unit economics
A1: Triple R Mutual Water Company
A2: Unit economics - per-customer revenue by category (USD)
A3: Entity ID: cawc_0093 | Fiscal year ends December 31.
A5: Every metric here is PER CUSTOMER (a metered service connection). It is not a per-member figure; the member (shareholder) count is a different denominator, shown in the denominator block. The visible cell shows the value and its classification; the numerator, denominator, formula, and rationale are in each metric's LOGIC popup.
A6: Per-customer denominator (service connections) | C6: State Water Board eAR Section 4
A7: Total annual revenue (eAR Section 8b B1.8) | C7: eAR Section 8b total annual revenue not reported for this system.
A8: Primary source
A10: Revenue categories (value, classification, per customer, share)
A11: Revenue category | B11: Classification | C11: Value (USD) | D11: Per customer | E11: Share of revenue
A12: Water sales revenue | B12: not reported | C12: not reported | D12: not reported | E12: not reported
A13: Assessment revenue (990 program-service revenue not matched to eAR water-rate revenue) | B13: IMPOSSIBLE | C13: IMPOSSIBLE | D13: IMPOSSIBLE | E13: IMPOSSIBLE
A14: Meter revenue | B14: not reported | C14: not reported | D14: not reported | E14: not reported
A15: Overage or tiered penalty revenue | B15: not reported | C15: not reported | D15: not reported | E15: not reported
A17: Water sales revenue - not reported
A18: Not reported: this system filed an eAR but no Section 8b revenue block, so there is no filed water-sales figure. Not fallen back to a different year.
A19: Reason: No filed eAR Section 8b water-rate revenue for this system.
A21: Assessment revenue (990 program-service revenue not matched to eAR water-rate revenue) - IMPOSSIBLE
A22: Not computed. A period-aligned residual is not possible for this filer.
A23: Reason: Not derivable. The eAR Section 8b is reporting year None while the Form 990 fiscal year ends None; the two period ends are not aligned, so a period-aligned residual cannot be computed.
A25: Meter revenue - not reported
A26: Not reported. This category is not built because doing so would double-count.
A27: Reason: The eAR Section 8a reports a base/meter rate PRICE, but the filing carries no meter revenue line and no tier volume, and the base charge is already inside the water-sales revenue (eAR Section 8b water rates). Building a separate meter figure would double-count. Not backed into from a total.
A29: Overage or tiered penalty revenue - not reported
A30: Not reported. This category is not built because doing so would double-count.
A31: Reason: The eAR Section 8a reports tiered/overage rate PRICES, but the filing carries no overage revenue and no tier consumption volume, and any overage billed is already inside the water-sales revenue. Building it would double-count. Not backed into from a total.

Sheet Rate structure
A1: Triple R Mutual Water Company
A2: Rate structure and representative bill - eAR Section 8a
A3: Entity ID: cawc_0093 | Fiscal year ends December 31.
A5: This block is a rate-schedule illustration at defined usage levels. It is NOT billed revenue and not a claim about any real customer's usage. The revenue side of unit economics is the separate Unit Economics block.
A6: No filed eAR Section 8a rate schedule is staged for this system.

Sheet Operational metrics
A1: Triple R Mutual Water Company
A2: Operational metrics - plant per acre, density, terrain
A3: Entity ID: cawc_0093 | Fiscal year ends December 31.
A5: Connections per acre
A6: Connections per acre | B6: 0.35 | C6: 154 connections / 440.6 acres. CA State Water Board SABL SERVICE_CONNECTIONS; Geodesic area (WGS84 spherical excess) of the SABL service-area polygon.

Sheet Supply & weather
A1: Triple R Mutual Water Company
A2: Supply and weather indicators (DWR water year)
A3: Entity ID: cawc_0093 | Fiscal year ends December 31.
A5: Reporting calendar: Different reporting periods. The DWR water year runs October 1 to September 30; this system's fiscal year ends December 31, so the two period ends are three months apart. Read the two side by side with that in mind. Neither series is recast: both are reported as filed. A water year is named for the calendar year it ends in, so WY2024 and FY2024 share a number without covering the same twelve months.
A7: Indicator | B7: WY2021 | C7: WY2022 | D7: WY2023 | E7: WY2024 | F7: WY2025
A8: Water-year type (Sacramento Valley) | B8: Critical | C8: Critical | D8: Wet | E8: Above Normal | F8: not reported
A9: Peak drought, county County | B9: not reported | C9: not reported | D9: not reported | E9: not reported | F9: not reported
A10: Precip, percent of normal (8-Station Index) | B10: 48 | C10: 86 | D10: 133 | E10: 96 | F10: 113
A11: Snowpack, April 1 percent of average | B11: 59% | C11: 38% | D11: 237% | E11: 110% | F11: 96%
A12: State Water Project allocation | B12: 5% | C12: 5% | D12: 100% | E12: 40% | F12: 50%

Sheet How this was built
A1: Triple R Mutual Water Company
A2: How this was built - forensic lineage
A3: Entity ID: cawc_0093 | Fiscal year ends December 31.
A5: A plain account of the forensic lineage behind the hard-to-source metrics: what sources were checked, what was found, what was derived, and what could not be built and why. Every figure marked DERIVED or IMPOSSIBLE above is traceable to a line here.
A7: Water-sales revenue per customer - not reported
A8: Sources checked | B8: State Water Board eAR Section 8b (water-rate revenue B1.1/B1.2); State Water Board eAR Section 4 (connection count, same reporting year); audited financial statement (secondary cross-check, where published)
A9: What was found | B9: The eAR Section 8b reports water-rate revenue for reporting year None, so this is a DIRECT filed figure; per customer it is divided by the eAR Section 4 connection count for the same reporting year, so numerator and denominator share the year.
A11: Assessment revenue (residual) - IMPOSSIBLE
A12: Sources checked | B12: Form 990 Part VIII line 2 (program-service revenue); State Water Board eAR Section 8b (water-rate revenue B1.1/B1.2); eAR Section 8b filer comment (WRRevenueComments)
A13: What was found | B13: A period-aligned residual cannot be computed for this filer, so the metric is rendered IMPOSSIBLE rather than guessed.
A14: Caveat | B14: Not derivable. The eAR Section 8b is reporting year None while the Form 990 fiscal year ends None; the two period ends are not aligned, so a period-aligned residual cannot be computed.
A16: Meter revenue - not reported
A17: Sources checked | B17: State Water Board eAR Section 8a (rate prices); State Water Board eAR Section 8b (revenue lines); audited financial statement
A18: What was found | B18: The rate price exists in Section 8a but no revenue or tier volume is reported, and the base charge is already inside water sales.
A19: Caveat | B19: The eAR Section 8a reports a base/meter rate PRICE, but the filing carries no meter revenue line and no tier volume, and the base charge is already inside the water-sales revenue (eAR Section 8b water rates). Building a separate meter figure would double-count. Not backed into from a total.
A21: Overage / tiered-penalty revenue - not reported
A22: Sources checked | B22: State Water Board eAR Section 8a (rate prices); State Water Board eAR Section 8b (revenue lines); audited financial statement
A23: What was found | B23: The rate price exists in Section 8a but no revenue or tier volume is reported, and the base charge is already inside water sales.
A24: Caveat | B24: The eAR Section 8a reports tiered/overage rate PRICES, but the filing carries no overage revenue and no tier consumption volume, and any overage billed is already inside the water-sales revenue. Building it would double-count. Not backed into from a total.
A26: eAR Section 8b reporting-period basis - sourced
A27: Sources checked | B27: eAR Section 8b B0.1 (WRFinancialReportingPeriod); eAR Section 8b B0.2 (WRFiscalYearStartDate)
A28: What was found | B28: The reporting basis (fiscal vs calendar year) is read from the filer's own B0.1/B0.2 answer and staged verbatim, never hardcoded, so the 990 comparison and the residual are period-aligned.
A30: Member (shareholder) count denominator - not reported
A31: Sources checked | B31: Form 990 (no member count stated); company website
A32: What was found | B32: No filing states a member/shareholder count, so the per-member unit economics read not reported rather than borrowing the connection count.
A34: Water volume delivered (acre-feet) - not reported
A35: Sources checked | B35: Form 990 (not in the filing); Consumer Confidence Report; eAR Section 6 (PRA-gated)
A36: What was found | B36: Volume delivered in acre-feet is not in the Form 990 and the CCR states only a source mix, so the per-acre-foot metrics read not reported; the eAR Section 6 is named as the source still needed.

Sheet Anomaly Flags
A1: Triple R Mutual Water Company
A2: Anomaly Flags (automated; kept separate from the clean statements)
A3: Entity ID: cawc_0093 | Fiscal year ends December 31.
A5: Material irregularities found automatically in the filed financials by the Hydronomics anomaly flagger. Each flag has two clearly separated layers. WHAT is mechanical, certain, and sourced: the exact filed lines, years, and amounts, carried as filed and never reconciled. WHY is attempted: the filing's own narrative is checked first, and when it states no reason a single best-guess hypothesis is shown, clearly labelled as a guess that is not in the filing and is not a verified figure.
A7: Flag: FY2024 opening net assets differ from FY2023 closing
A8: Affected figure | B8: Net assets FY2024
A9: Confidence | B9: high
A10: What happened (filed, sourced) | B10: The company filed $301,591 as its beginning net assets for FY2024 and $302,390 as its ending net assets for FY2023, a difference of $-799. Both figures are carried exactly as each year's own filing reports them. Neither is adjusted to match the other.
A11: Source lines | B11: - FY2024 net assets, beginning of year (as filed): $301,591 - FY2023 net assets, end of year (as filed): $302,390 - Difference: $-799
A12: Confidence reasoning | B12: Both are direct filed line items read from two different returns, so the difference between them is high confidence as an observation. What caused it is not stated on either form.
A13: Why (not stated in the filing) | B13: The filing does not state a reason.
A14: Possible explanation (guess) | B14: Possible explanation, not stated in filing: a beginning balance that differs from the prior year's ending balance usually means the earlier year was restated, or a balance-sheet line was reclassified between the two filings. This is an educated guess, not something either filing says.

Sheet Sources & audit
A1: Triple R Mutual Water Company
A2: Sources & audit - full provenance and tie-outs (kept off the statements so they read clean)
A3: Entity ID: cawc_0093 | Fiscal year ends December 31.
A5: Presentation standard: every figure on the statement tabs is verified to its source filing and shown clean. A cell the filing does not report reads "not reported" (never estimated, never guessed).
A6: Citations, confidence tiers, and the filed-vs-computed tie-out checks live on the "Sources & audit" tab, keyed by cell, so every number is fully traceable without cluttering the statements. These pages are ready to use as filed.
A8: A. Filing provenance (one row per staged extraction)
A9: Fiscal year | B9: Period end | C9: Filing type | D9: Confidence | E9: Extraction ID | F9: Object ID | G9: Extracted by | H9: Extracted at | I9: Source URL
A10: FY2020 | B10: 2020-12-31 | C10: 990-EZ | D10: high | E10: b43c687f-8516-46e8-8070-d4c4369c9986 | F10: 202110479349200636 | G10: claude-opus-5 | H10: 2026-09-23T06:31:50+00:00 | I10: https://apps.irs.gov/pub/epostcard/990/xml/2021/2021_TEOS_XML_01A.zip#202110479349200636_public.xml
A11: FY2021 | B11: 2021-12-31 | C11: 990-EZ | D11: high | E11: 83fba5c2-5d8b-473c-9f53-800ae4e5b8de | F11: 202230589349200208 | G11: claude-opus-5 | H11: 2026-09-23T06:31:50+00:00 | I11: https://apps.irs.gov/pub/epostcard/990/xml/2022/2022_TEOS_XML_01A.zip#202230589349200208_public.xml
A12: FY2022 | B12: 2022-12-31 | C12: 990-EZ | D12: high | E12: 04d5a63b-709d-451c-a11c-898256716940 | F12: 202310489349201911 | G12: claude-opus-5 | H12: 2026-09-23T06:31:50+00:00 | I12: https://apps.irs.gov/pub/epostcard/990/xml/2023/2023_TEOS_XML_02A.zip#202310489349201911_public.xml
A13: FY2023 | B13: 2023-12-31 | C13: 990-EZ | D13: high | E13: 95553a82-a5e2-4e98-a905-46500679c181 | F13: 202400549349201270 | G13: claude-opus-5 | H13: 2026-09-23T06:31:50+00:00 | I13: https://apps.irs.gov/pub/epostcard/990/xml/2024/2024_TEOS_XML_03A.zip#202400549349201270_public.xml
A14: FY2024 | B14: 2024-12-31 | C14: 990-EZ | D14: high | E14: 68fe9070-11fc-4f95-803d-2cd8fe4a0710 | F14: 202510649349201726 | G14: claude-opus-5 | H14: 2026-09-23T06:31:50+00:00 | I14: https://apps.irs.gov/pub/epostcard/990/xml/2025/2025_TEOS_XML_03A.zip#202510649349201726_public.xml
A15: FY2025 | B15: 2025-12-31 | C15: 990-EZ | D15: high | E15: 8132e154-dbc5-479c-b277-7639a45414b4 | F15: 202600619349200225 | G15: claude-opus-5 | H15: 2026-09-23T06:31:50+00:00 | I15: https://apps.irs.gov/pub/epostcard/990/xml/2026/2026_TEOS_XML_03A.zip#202600619349200225_public.xml
A17: B. Figure citations (every figure on the statement tabs, keyed by cell)
A18: Tab | B18: Cell | C18: Line item | D18: Form 990 line | E18: Key path | F18: Confidence | G18: As filed
A19: Form 990-EZ Parts I & II | B19: B7 | C19: 3. Membership dues and assessments | D19: Part I line 3 | E19: part_i_revenue_expenses.membership_dues | F19: high | G19: 108539
A20: Form 990-EZ Parts I & II | B20: C7 | C20: 3. Membership dues and assessments | D20: Part I line 3 | E20: part_i_revenue_expenses.membership_dues | F20: high | G20: 114600
A21: Form 990-EZ Parts I & II | B21: D7 | C21: 3. Membership dues and assessments | D21: Part I line 3 | E21: part_i_revenue_expenses.membership_dues | F21: high | G21: 103994
A22: Form 990-EZ Parts I & II | B22: E7 | C22: 3. Membership dues and assessments | D22: Part I line 3 | E22: part_i_revenue_expenses.membership_dues | F22: high | G22: 113092
A23: Form 990-EZ Parts I & II | B23: F7 | C23: 3. Membership dues and assessments | D23: Part I line 3 | E23: part_i_revenue_expenses.membership_dues | F23: high | G23: 129550
A24: Form 990-EZ Parts I & II | B24: G7 | C24: 3. Membership dues and assessments | D24: Part I line 3 | E24: part_i_revenue_expenses.membership_dues | F24: high | G24: 139445
A25: Form 990-EZ Parts I & II | B25: B8 | C25: 4. Investment income | D25: Part I line 4 | E25: part_i_revenue_expenses.investment_income | F25: high | G25: 6
A26: Form 990-EZ Parts I & II | B26: C8 | C26: 4. Investment income | D26: Part I line 4 | E26: part_i_revenue_expenses.investment_income | F26: high | G26: 29
A27: Form 990-EZ Parts I & II | B27: D8 | C27: 4. Investment income | D27: Part I line 4 | E27: part_i_revenue_expenses.investment_income | F27: high | G27: 4
A28: Form 990-EZ Parts I & II | B28: E8 | C28: 4. Investment income | D28: Part I line 4 | E28: part_i_revenue_expenses.investment_income | F28: high | G28: 4
A29: Form 990-EZ Parts I & II | B29: F8 | C29: 4. Investment income | D29: Part I line 4 | E29: part_i_revenue_expenses.investment_income | F29: high | G29: 5
A30: Form 990-EZ Parts I & II | B30: G8 | C30: 4. Investment income | D30: Part I line 4 | E30: part_i_revenue_expenses.investment_income | F30: high | G30: 275
... A76: Form 990-EZ Parts I & II | B76: G27 | C76: 27. Net assets or fund balances | D76: Part II line 27 col B | E76: part_ii_balance_sheet.net_assets_eoy | F76: high | G76: 304014
A78: C. Tie-out checks (filed vs computed; any nonzero variance is flagged red)
A79: Tab | B79: Check | C79: Fiscal year | D79: Filed | E79: Computed | F79: Variance (computed - filed)
A80: Form 990-EZ Parts I & II | B80: 17. Total expenses | C80: FY2020 | D80: 90271 | E80: ='Form 990-EZ Parts I & II'!B14 | F80: =E80-D80
A81: Form 990-EZ Parts I & II | B81: 17. Total expenses | C81: FY2021 | D81: 98842 | E81: ='Form 990-EZ Parts I & II'!C14 | F81: =E81-D81
A82: Form 990-EZ Parts I & II | B82: 17. Total expenses | C82: FY2022 | D82: 101948 | E82: ='Form 990-EZ Parts I & II'!D14 | F82: =E82-D82
A83: Form 990-EZ Parts I & II | B83: 17. Total expenses | C83: FY2023 | D83: 124319 | E83: ='Form 990-EZ Parts I & II'!E14 | F83: =E83-D83
A84: Form 990-EZ Parts I & II | B84: 17. Total expenses | C84: FY2024 | D84: 135631 | E84: ='Form 990-EZ Parts I & II'!F14 | F84: =E84-D84
A85: Form 990-EZ Parts I & II | B85: 17. Total expenses | C85: FY2025 | D85: 134952 | E85: ='Form 990-EZ Parts I & II'!G14 | F85: =E85-D85
A86: Form 990-EZ Parts I & II | B86: 21. Net assets or fund balances, end of year | C86: FY2020 | D86: 295776 | E86: ='Form 990-EZ Parts I & II'!B19 | F86: =E86-D86
A87: Form 990-EZ Parts I & II | B87: 21. Net assets or fund balances, end of year | C87: FY2021 | D87: 311563 | E87: ='Form 990-EZ Parts I & II'!C19 | F87: =E87-D87
A88: Form 990-EZ Parts I & II | B88: 21. Net assets or fund balances, end of year | C88: FY2022 | D88: 313613 | E88: ='Form 990-EZ Parts I & II'!D19 | F88: =E88-D88
A89: Form 990-EZ Parts I & II | B89: 21. Net assets or fund balances, end of year | C89: FY2023 | D89: 302390 | E89: ='Form 990-EZ Parts I & II'!E19 | F89: =E89-D89
...

Sheet Provenance
A1: Build provenance | B1: Built from source commit d418ffb17485 (2026-10-06); source fingerprint a75a8eee82c65cf7; 192 companies (179 retail mutual, 4 irrigation mutual, 3 mutual, no PWSID, purpose not stated, 2 frozen non-mutual (special district), 2 wholesale mutual, 1 frozen non-mutual (investor-owned), 1 frozen non-mutual (municipal)); 91 gates; build id 3d08d6d2a855.
A2: source_commit | B2: d418ffb174855ab78000d391d42f898397b0d8aa
A3: source_commit_date | B3: 2026-10-06
A4: source_fingerprint | B4: a75a8eee82c65cf7096931f06e18affdc28686a02895b46538e7298b57c04d94
A5: gate_count | B5: 91
A6: build_id | B6: 3d08d6d2a855
A7: registry: frozen non-mutual (investor-owned) | B7: 1
A8: registry: frozen non-mutual (municipal) | B8: 1
A9: registry: frozen non-mutual (special district) | B9: 2
A10: registry: irrigation mutual | B10: 4
A11: registry: mutual, no PWSID, purpose not stated | B11: 3
A12: registry: retail mutual | B12: 179
A13: registry: wholesale mutual | B13: 2
