Workbook

Sheet Summary
A1: Rancho Robles Mutual Water & Road Co
A2: Financial Summary - multi-year overview (USD)
A3: Entity ID: cawc_0157 | Fiscal year ends December 31.
A5: Presentation standard: every figure on the statement tabs is verified to its source filing and shown clean. A cell the filing does not report reads "not reported" (never estimated, never guessed).
A6: Citations, confidence tiers, and the filed-vs-computed tie-out checks live on the "Sources & audit" tab, keyed by cell, so every number is fully traceable without cluttering the statements. These pages are ready to use as filed.
A8: Metric | B8: FY2020 | C8: FY2021 | D8: FY2022 | E8: FY2023 | F8: FY2024 | G8: FY2025
A9: Operating results (USD)
A10: Total revenue | B10: 133472 | C10: 141201 | D10: 155997 | E10: 150476 | F10: 178674 | G10: 192220
A11: Total expenses | B11: 130365 | C11: 150929 | D11: 172330 | E11: 141865 | F11: 205485 | G11: 185932
A12: Net income | B12: 3107 | C12: -9728 | D12: -16333 | E12: 8611 | F12: -26811 | G12: 6288
A14: Financial position (USD, end of year)
A15: Total assets | B15: 744720 | C15: 762992 | D15: 766881 | E15: 795560 | F15: 797312 | G15: 821657
A16: Total liabilities | B16: 1804 | C16: 3263 | D16: 1890 | E16: 2401 | F16: 7564 | G16: 2200
A17: Net assets | B17: 742916 | C17: 759729 | D17: 764991 | E17: 793159 | F17: 789748 | G17: 819457
A19: Headline ratios
A20: Operating margin | B20: 0.023278291 | C20: -0.068894696 | D20: -0.10470073 | E20: 0.057225072 | F20: -0.15005541 | G20: 0.032712517
A21: Revenue growth (YoY) | B21: 0.0099044362 | C21: 0.057907276 | D21: 0.10478679 | E21: -0.035391706 | F21: 0.18739201 | G21: 0.075814052
A22: Return on assets | B22: 0.0041720378 | C22: -0.012749806 | D22: -0.021297959 | E22: 0.010823822 | F22: -0.033626736 | G22: 0.0076528284
A24: Figures as reported in source filings (full provenance on the Sources & audit tab). Parentheses denote negatives; ratios are computed upstream in financials_annual.

Sheet Notes
A1: Notes
A2: Human annotations from the versioned store (data/notes/). Annotations only: they never change a reported figure or a confidence tier.
A4: Date | B4: Tag | C4: Author | D4: Note
A5: No notes recorded yet.

Sheet Financial Statements
A1: Rancho Robles Mutual Water & Road Co
A2: Financial Statements - income statement, balance sheet, cash flow, member income test (USD)
A3: Entity ID: cawc_0157 | Fiscal year ends December 31.
A5: INCOME STATEMENT - as reported (USD)
A6: Line item | B6: FY2020 | C6: FY2021 | D6: FY2022 | E6: FY2023 | F6: FY2024 | G6: FY2025
A7: Revenue
A8: Program service revenue | B8: 133290 | C8: 140221 | D8: 155185 | E8: 146799 | F8: 169318 | G8: 179825
A9: Investment income | B9: 182 | C9: 980 | D9: 0 | E9: 3677 | F9: 6884 | G9: 5117
A10: Net rental income | B10: 0 | C10: 0 | D10: 0 | E10: 0 | F10: 0 | G10: 0
A11: Net gain/(loss) on investment sales | B11: 0 | C11: 0 | D11: 0 | E11: 0 | F11: 0 | G11: 0
A12: Other revenue | B12: 0 | C12: 0 | D12: 812 | E12: 0 | F12: 2472 | G12: 7278
A13: Contributions & grants | B13: 0 | C13: 0 | D13: 0 | E13: 0 | F13: 0 | G13: 0
A14: Total revenue | B14: 133472 | C14: 141201 | D14: 155997 | E14: 150476 | F14: 178674 | G14: 192220
A16: Expenses
A17: Depreciation | B17: 37237 | C17: 49235 | D17: 53408 | E17: 55601 | F17: 60312 | G17: 65694
A18: Interest expense | B18: 0 | C18: 0 | D18: 0 | E18: 0 | F18: 0 | G18: 0
A19: Total expenses | B19: 130365 | C19: 150929 | D19: 172330 | E19: 141865 | F19: 205485 | G19: 185932
A21: Net income | B21: 3107 | C21: -9728 | D21: -16333 | E21: 8611 | F21: -26811 | G21: 6288
A24: BALANCE SHEET - as reported (USD, end of year)
A25: Line item | B25: FY2020 | C25: FY2021 | D25: FY2022 | E25: FY2023 | F25: FY2024 | G25: FY2025
A26: Assets
A27: Cash | B27: 267006 | C27: 134977 | D27: 171913 | E27: 223009 | F27: 103817 | G27: 99372
A28: Savings & temporary investments | B28: 0 | C28: 0 | D28: 0 | E28: 0 | F28: 131046 | G28: 67817
A29: Accounts receivable | B29: 0 | C29: 902 | D29: 3056 | E29: -777 | F29: 703 | G29: 4103
A30: Inventories | B30: 0 | C30: 0 | D30: 0 | E30: 0 | F30: 0 | G30: 0
A31: Prepaid expenses | B31: 0 | C31: 0 | D31: 0 | E31: 0 | F31: 0 | G31: 0
A32: Property, plant & equipment (gross) | B32: 947318 | C32: 1131168 | D32: 1154485 | E32: 1195754 | F32: 1244484 | G32: 1402006
A33: Less: accumulated depreciation | B33: -471859 | C33: -521094 | D33: -574502 | E33: -630103 | F33: -690415 | G33: -756109
A34: Net property, plant & equipment | B34: 475459 | C34: 610074 | D34: 579983 | E34: 565651 | F34: 554069 | G34: 645897
A35: Total assets | B35: 744720 | C35: 762992 | D35: 766881 | E35: 795560 | F35: 797312 | G35: 821657
A37: Liabilities
A38: Accounts payable | C38: 1463 | D38: 90 | E38: 601 | F38: 5763 | G38: 400
A39: Mortgages & notes payable
A40: Total liabilities | B40: 1804 | C40: 3263 | D40: 1890 | E40: 2401 | F40: 7564 | G40: 2200
A42: Net Assets / Equity
A43: Capital stock
A44: Paid-in capital | B44: 651305 | C44: 674705 | D44: 698105 | E44: 721505 | F44: 744905 | G44: 768336
A45: Retained earnings | B45: 91611 | C45: 85024 | D45: 66886 | E45: 71654 | F45: 44843 | G45: 51121
A46: Net assets | B46: 742916 | C46: 759729 | D46: 764991 | E46: 793159 | F46: 789748 | G46: 819457
A49: CASH FLOW - derived proxy (USD)
...

Sheet Balance Sheet
A1: Rancho Robles Mutual Water & Road Co
A2: Balance Sheet - as reported (USD, end of year)
A3: Entity ID: cawc_0157 | Fiscal year ends December 31.
A5: Line item | B5: FY2020 | C5: FY2021 | D5: FY2022 | E5: FY2023 | F5: FY2024 | G5: FY2025
A6: Assets
A7: Cash | B7: 267006 | C7: 134977 | D7: 171913 | E7: 223009 | F7: 103817 | G7: 99372
A8: Savings & temporary investments | B8: 0 | C8: 0 | D8: 0 | E8: 0 | F8: 131046 | G8: 67817
A9: Accounts receivable | B9: 0 | C9: 902 | D9: 3056 | E9: -777 | F9: 703 | G9: 4103
A10: Inventories | B10: 0 | C10: 0 | D10: 0 | E10: 0 | F10: 0 | G10: 0
A11: Prepaid expenses | B11: 0 | C11: 0 | D11: 0 | E11: 0 | F11: 0 | G11: 0
A12: Property, plant & equipment (gross) | B12: 947318 | C12: 1131168 | D12: 1154485 | E12: 1195754 | F12: 1244484 | G12: 1402006
A13: Less: accumulated depreciation | B13: -471859 | C13: -521094 | D13: -574502 | E13: -630103 | F13: -690415 | G13: -756109
A14: Net property, plant & equipment | B14: 475459 | C14: 610074 | D14: 579983 | E14: 565651 | F14: 554069 | G14: 645897
A15: Total assets | B15: 744720 | C15: 762992 | D15: 766881 | E15: 795560 | F15: 797312 | G15: 821657
A17: Liabilities
A18: Accounts payable | C18: 1463 | D18: 90 | E18: 601 | F18: 5763 | G18: 400
A19: Mortgages & notes payable
A20: Total liabilities | B20: 1804 | C20: 3263 | D20: 1890 | E20: 2401 | F20: 7564 | G20: 2200
A22: Net Assets / Equity
A23: Capital stock
A24: Paid-in capital | B24: 651305 | C24: 674705 | D24: 698105 | E24: 721505 | F24: 744905 | G24: 768336
A25: Retained earnings | B25: 91611 | C25: 85024 | D25: 66886 | E25: 71654 | F25: 44843 | G25: 51121
A26: Net assets | B26: 742916 | C26: 759729 | D26: 764991 | E26: 793159 | F26: 789748 | G26: 819457
A28: Balance check (assets − liab. − net assets) | B28: 0 | C28: 0 | D28: 0 | E28: 0 | F28: 0 | G28: 0
A30: Net PP&E is the reported ppe_net column (gross less accumulated depreciation). The balance check should be ~0 where all three totals are reported; a non-zero value flags a reporting or extraction discrepancy worth reviewing.

Sheet Officers & contractors
A1: Rancho Robles Mutual Water & Road Co
A2: Officers, Directors & Contractors - Form 990 Part VII (FY2025; USD)
A3: Entity ID: cawc_0157 | Fiscal year ends December 31.
A5: Section A - Officers, directors, trustees, key employees
A6: Name | B6: Title | C6: Reportable comp (org) | D6: Reportable comp (related) | E6: Other comp | F6: Total compensation
A7: BRANDON MERRILL | B7: President | C7: 0 | D7: 0 | E7: 0 | F7: 0
A8: AYHAN MENEKSHE | B8: Vice President | C8: 0 | D8: 0 | E8: 0 | F8: 0
A9: ROBERT STRICKLAND | B9: Treasurer | C9: 0 | D9: 0 | E9: 0 | F9: 0
A10: Larry Carr | B10: Member at Large | C10: 0 | D10: 0 | E10: 0 | F10: 0
A11: LAURA LUNDY | B11: Secretary | C11: 0 | D11: 0 | E11: 0 | F11: 0
A12: Robert Fernandez | B12: Member at Large | C12: 0 | D12: 0 | E12: 0 | F12: 0
A13: Scott Mackenzie | B13: Member at Large | C13: 0 | D13: 0 | E13: 0 | F13: 0
A15: Section B - Independent contractors (over $100,000)
A16: Contractor | B16: Services | C16: Compensation
A18: Section A lists every officer, director, trustee and key employee filed for the latest year; the two with the highest total compensation are highlighted. Total compensation is computed (reportable org + related + other). Section B lists each independent contractor paid over $100,000; the return reports 0 such contractor(s). Source and confidence for every figure are on the Sources & audit tab.

Sheet Revenue (detail)
A1: Rancho Robles Mutual Water & Road Co
A2: Revenue - Form 990 Part VIII (USD)
A3: Entity ID: cawc_0157 | Fiscal year ends December 31.
A5: Part VIII line | B5: FY2020 | C5: FY2021 | D5: FY2022 | E5: FY2023 | F5: FY2024 | G5: FY2025
A6: Revenue by category
A7: 1h. Total contributions, gifts, grants | B7: 0 | C7: 0 | D7: 0 | E7: 0 | F7: 0 | G7: 0
A8: 2g. Total program service revenue | B8: 133290 | C8: 140221 | D8: 155185 | E8: 146799 | F8: 169318 | G8: 179825
A9: 3. Investment income | B9: 182 | C9: 980 | D9: 0 | E9: 3677 | F9: 6884 | G9: 5117
A10: 6d. Net rental income | B10: 0 | C10: 0 | D10: 0 | E10: 0 | F10: 0 | G10: 0
A11: 7d. Net gain/(loss) from investment sales | B11: 0 | C11: 0 | D11: 0 | E11: 0 | F11: 0 | G11: 0
A12: 11e. Other revenue | B12: 0 | C12: 0 | D12: 812 | E12: 0 | F12: 2472 | G12: 7278
A13: 12. Total revenue | B13: =SUM(B7:B12) | C13: =SUM(C7:C12) | D13: =SUM(D7:D12) | E13: =SUM(E7:E12) | F13: =SUM(F7:F12) | G13: =SUM(G7:G12)
A15: Program service revenue detail - FY2025 (lines 2a-2f)
A16: Description | B16: Business code | C16: Total revenue
A17: MEMBER CHARGES | B17: 900099 | C17: 179825
A18: Revenue category subtotals are as filed. Total revenue (line 12) is a live SUM of the category cells above; its tie-out to the filed total is on the Sources & audit tab. Program service revenue detail is shown for the latest year, with its sum-to-line-2g check on that same audit tab.

Sheet Operating expenses (detail)
A1: Rancho Robles Mutual Water & Road Co
A2: Statement of Functional Expenses - Form 990 Part IX (USD)
A3: Entity ID: cawc_0157 | Fiscal year ends December 31.
A5: Part IX line (column A Total) | B5: FY2020 | C5: FY2021 | D5: FY2022 | E5: FY2023 | F5: FY2024 | G5: FY2025
A6: Functional expenses, column A Total - by year
A7: 1. Grants to domestic organizations and governments | B7: 0 | C7: 0 | D7: 0 | E7: 0 | F7: 0 | G7: 0
A8: 2. Grants to domestic individuals | B8: 0 | C8: 0 | D8: 0 | E8: 0 | F8: 0 | G8: 0
A9: 3. Grants to foreign organizations and individuals | B9: 0 | C9: 0 | D9: 0 | E9: 0 | F9: 0 | G9: 0
A10: 4. Benefits paid to or for members | B10: 0 | C10: 0 | D10: 0 | E10: 0 | F10: 0 | G10: 0
A11: 5. Compensation of current officers, directors, trustees | B11: 0 | C11: 0 | D11: 0 | E11: 0 | F11: 0 | G11: 0
A12: 6. Compensation to disqualified persons | B12: 0 | C12: 0 | D12: 0 | E12: 0 | F12: 0 | G12: 0
A13: 7. Other salaries and wages | B13: 0 | C13: 0 | D13: 0 | E13: 0 | F13: 0 | G13: 0
A14: 8. Pension plan accruals and contributions | B14: 0 | C14: 0 | D14: 0 | E14: 0 | F14: 0 | G14: 0
A15: 9. Other employee benefits | B15: 0 | C15: 0 | D15: 0 | E15: 0 | F15: 0 | G15: 0
A16: 10. Payroll taxes | B16: 0 | C16: 0 | D16: 0 | E16: 0 | F16: 0 | G16: 0
A17: 11a. Fees for services: management | B17: 0 | C17: 0 | D17: 0 | E17: 0 | F17: 0 | G17: 0
A18: 11b. Fees for services: legal | B18: 0 | C18: 0 | D18: 0 | E18: 0 | F18: 0 | G18: 0
... A36: 24. Utilities | B36: 35938 | C36: 45895 | D36: 28162 | E36: 34791 | F36: 36374 | G36: 63494
A37: 24. Lancscape services | B37: 12067 | C37: not reported | D37: 8885 | E37: 11330 | F37: not reported | G37: 9163
A38: 24. Water repairs and maintenance | B38: 9836 | C38: 10509 | D38: 13275 | E38: 3173 | F38: not reported | G38: 5743
A39: 24. Treatment/Distribution Operato | B39: 8700 | C39: 8700 | D39: not reported | E39: 10910 | F39: 10808 | G39: 8811
A40: 24. Laboratory testing | B40: not reported | C40: 8744 | D40: not reported | E40: not reported | F40: not reported | G40: not reported
A41: 24. WELL TAX | B41: not reported | C41: not reported | D41: 35111 | E41: not reported | F41: 21778 | G41: not reported
A42: 24. Road repairs & maneteance | B42: not reported | C42: not reported | D42: not reported | E42: not reported | F42: 20289 | G42: not reported
A43: 24e. All other expenses | B43: 14143 | C43: 14234 | D43: 21271 | E43: 11778 | F43: 41855 | G43: 18422
A44: 25. Total functional expenses | B44: =SUM(B7:B43) | C44: =SUM(C7:C43) | D44: =SUM(D7:D43) | E44: =SUM(E7:E43) | F44: =SUM(F7:F43) | G44: =SUM(G7:G43)
A46: Functional column split - FY2025 (col A = B + C + D)
A47: Part IX line | B47: A. Total | C47: B. Program services | D47: C. Management & general | E47: D. Fundraising
A48: 1. Grants to domestic organizations and governments | B48: 0
A49: 2. Grants to domestic individuals | B49: 0
A50: 3. Grants to foreign organizations and individuals | B50: 0
A51: 4. Benefits paid to or for members | B51: 0
A52: 5. Compensation of current officers, directors, trustees | B52: 0
A53: 6. Compensation to disqualified persons | B53: 0
A54: 7. Other salaries and wages | B54: 0
A55: 8. Pension plan accruals and contributions | B55: 0
A56: 9. Other employee benefits | B56: 0
A57: 10. Payroll taxes | B57: 0
A58: 11a. Fees for services: management | B58: 0
A59: 11b. Fees for services: legal | B59: 0
...

Sheet Balance sheet (detail)
A1: Rancho Robles Mutual Water & Road Co
A2: Balance Sheet - Form 990 Part X (end of year, USD)
A3: Entity ID: cawc_0157 | Fiscal year ends December 31.
A5: Part X line (column B, EOY) | B5: FY2020 | C5: FY2021 | D5: FY2022 | E5: FY2023 | F5: FY2024 | G5: FY2025
A6: Assets
A7: 1. Cash - non-interest-bearing | B7: 267006 | C7: 134977 | D7: 171913 | E7: 223009 | F7: 103817 | G7: 99372
A8: 2. Savings and temporary cash investments | B8: 0 | C8: 0 | D8: 0 | E8: 0 | F8: 131046 | G8: 67817
A9: 3. Pledges and grants receivable, net | B9: 0 | C9: 0 | D9: 0 | E9: 0 | F9: 0 | G9: 0
A10: 4. Accounts receivable, net | B10: 0 | C10: 902 | D10: 3056 | E10: -777 | F10: 703 | G10: 4103
A11: 5. Receivables from officers/directors/trustees | B11: 0 | C11: 0 | D11: 0 | E11: 0 | F11: 0 | G11: 0
A12: 6. Receivables from disqualified persons | B12: 0 | C12: 0 | D12: 0 | E12: 0 | F12: 0 | G12: 0
A13: 7. Notes and loans receivable, net | B13: 0 | C13: 0 | D13: 0 | E13: 0 | F13: 0 | G13: 0
A14: 8. Inventories for sale or use | B14: 0 | C14: 0 | D14: 0 | E14: 0 | F14: 0 | G14: 0
A15: 9. Prepaid expenses and deferred charges | B15: 0 | C15: 0 | D15: 0 | E15: 0 | F15: 0 | G15: 0
A16: 10c. Land, buildings, and equipment, net | B16: 475459 | C16: 610074 | D16: 579983 | E16: 565651 | F16: 554069 | G16: 645897
A17: 11. Investments - publicly traded securities | B17: 0 | C17: 0 | D17: 0 | E17: 0 | F17: 0 | G17: 0
A18: 12. Investments - other securities | B18: 0 | C18: 0 | D18: 0 | E18: 0 | F18: 0 | G18: 0
... A21: 15. Other assets | B21: 2255 | C21: 17039 | D21: 11929 | E21: 7677 | F21: 7677 | G21: 4468
A22: 16. Total assets | B22: =SUM(B7:B21) | C22: =SUM(C7:C21) | D22: =SUM(D7:D21) | E22: =SUM(E7:E21) | F22: =SUM(F7:F21) | G22: =SUM(G7:G21)
A24: Liabilities
A25: 17. Accounts payable and accrued expenses | B25: not reported | C25: 1463 | D25: 90 | E25: 601 | F25: 5763 | G25: 400
A26: 25. Other liabilities | B26: 1804 | C26: 1800 | D26: 1800 | E26: 1800 | F26: 1801 | G26: 1800
A27: 26. Total liabilities | B27: =SUM(B25:B26) | C27: =SUM(C25:C26) | D27: =SUM(D25:D26) | E27: =SUM(E25:E26) | F27: =SUM(F25:F26) | G27: =SUM(G25:G26)
A29: Net assets / fund balances
A30: 30. Paid-in or capital surplus | B30: 651305 | C30: 674705 | D30: 698105 | E30: 721505 | F30: 744905 | G30: 768336
A31: 31. Retained earnings / accumulated funds | B31: 91611 | C31: 85024 | D31: 66886 | E31: 71654 | F31: 44843 | G31: 51121
A32: 32. Total net assets / fund balances | B32: =SUM(B30:B31) | C32: =SUM(C30:C31) | D32: =SUM(D30:D31) | E32: =SUM(E30:E31) | F32: =SUM(F30:F31) | G32: =SUM(G30:G31)
A34: Every Part X line is end-of-year (column B), as filed. Section totals (lines 16 / 26 / 32) are live SUMs of the lines above; their tie-outs and the balance-sheet identity (16 = 26 + 32) are on the Sources & audit tab. This filer files as a non-FASB mutual, so net assets sit on lines 29-31 (capital stock / paid-in capital / retained earnings); lines this filer does not report are omitted. Lines 10a/10b net into line 10c (shown).

Sheet Net-assets reconciliation
A1: Rancho Robles Mutual Water & Road Co
A2: Reconciliation of Net Assets - Form 990 Part XI (USD)
A3: Entity ID: cawc_0157 | Fiscal year ends December 31.
A5: Part XI line | B5: FY2020 | C5: FY2021 | D5: FY2022 | E5: FY2023 | F5: FY2024 | G5: FY2025
A6: Reconciliation
A7: 4. Net assets, beginning of year | B7: 716409 | C7: 742916 | D7: 759729 | E7: 764991 | F7: 793159 | G7: 789748
A8: 3. Revenue less expenses | B8: 3107 | C8: -9728 | D8: -16333 | E8: 8611 | F8: -26811 | G8: 6288
A9: 8. Prior period adjustments | B9: not reported | C9: not reported | D9: not reported | E9: not reported | F9: not reported | G9: not reported
A10: 9. Other changes in net assets | B10: 23400 | C10: 26541 | D10: 21595 | E10: 19557 | F10: 23400 | G10: 19596
A11: 10. Net assets, end of year | B11: =SUM(B7,B8,B9,B10) | C11: =SUM(C7,C8,C9,C10) | D11: =SUM(D7,D8,D9,D10) | E11: =SUM(E7,E8,E9,E10) | F11: =SUM(F7,F8,F9,F10) | G11: =SUM(G7,G8,G9,G10)
A13: Part XI reconciles beginning to ending net assets. Ending net assets (line 10) is a live formula: beginning balance (line 4) + revenue less expenses (line 3) + prior-period adjustments (8) + other changes (9). Its tie-out to the filed line 10 (and to Part X line 32) is on the Sources & audit tab. Lines 5-7 (unrealized gains, donated services, investment expenses) are not filed by this entity.

Sheet Cash flow proxies
A1: Rancho Robles Mutual Water & Road Co
A2: Cash Flow Proxies - derived (USD)
A3: Entity ID: cawc_0157 | Fiscal year ends December 31.
A5: PROXY ONLY. The source filings contain no statement of cash flows. Lines below are derived from the reported income statement and year-over-year balance-sheet changes; treat as directional estimates, not GAAP cash flows. The earliest year has no prior period, so its delta cells are blank.
A7: Proxy line (USD) | B7: FY2020 | C7: FY2021 | D7: FY2022 | E7: FY2023 | F7: FY2024 | G7: FY2025
A8: Operating
A9: Net income | B9: 3107 | C9: -9728 | D9: -16333 | E9: 8611 | F9: -26811 | G9: 6288
A10: + Depreciation (reported) | B10: 37237 | C10: 49235 | D10: 53408 | E10: 55601 | F10: 60312 | G10: 65694
A11: − Δ Accounts receivable | C11: -902 | D11: -2154 | E11: 3833 | F11: -1480 | G11: -3400
A12: − Δ Inventories | C12: 0 | D12: 0 | E12: 0 | F12: 0 | G12: 0
A13: − Δ Prepaid expenses | C13: 0 | D13: 0 | E13: 0 | F13: 0 | G13: 0
A14: + Δ Accounts payable | D14: -1373 | E14: 511 | F14: 5162 | G14: -5363
A15: Operating cash flow proxy | C15: 38605 | D15: 33548 | E15: 68556 | F15: 37183 | G15: 63219
A17: Investing
A18: − Δ PP&E gross (capex proxy) | C18: -183850 | D18: -23317 | E18: -41269 | F18: -48730 | G18: -157522
A20: Financing
A21: Δ Mortgages & notes payable
A23: Reconciliation
A24: Δ Cash + temp. investments (actual) | C24: -132029 | D24: 36936 | E24: 51096 | F24: 11854 | G24: -67674
A26: The capex proxy assumes gross PP&E rises only via capital spending (it ignores disposals). 'Δ Cash + temp. investments (actual)' is the real reported change in liquid funds and is the most reliable line here; the operating/investing/financing proxies will not perfectly reconcile to it.

Sheet Ratios
A1: Rancho Robles Mutual Water & Road Co
A2: Financial Ratios
A3: Entity ID: cawc_0157 | Fiscal year ends December 31.
A5: Ratio | B5: FY2020 | C5: FY2021 | D5: FY2022 | E5: FY2023 | F5: FY2024 | G5: FY2025
A6: Profitability (computed upstream)
A7: Operating margin (NI / revenue) | B7: 0.023278291 | C7: -0.068894696 | D7: -0.10470073 | E7: 0.057225072 | F7: -0.15005541 | G7: 0.032712517
A8: Expense ratio (expenses / revenue) | B8: 0.97672171 | C8: 1.0688947 | D8: 1.1047007 | E8: 0.94277493 | F8: 1.1500554 | G8: 0.96728748
A9: Return on assets (NI / assets) | B9: 0.0041720378 | C9: -0.012749806 | D9: -0.021297959 | E9: 0.010823822 | F9: -0.033626736 | G9: 0.0076528284
A10: Revenue growth (YoY) | B10: 0.0099044362 | C10: 0.057907276 | D10: 0.10478679 | E10: -0.035391706 | F10: 0.18739201 | G10: 0.075814052
A12: Leverage & solvency
A13: Debt-to-assets (liab. / assets) | B13: 0.0024223869 | C13: 0.0042765848 | D13: 0.0024645284 | E13: 0.0030179999 | F13: 0.0094868759 | G13: 0.0026775163
A14: Equity ratio (net assets / assets) | B14: 0.99757761 | C14: 0.99572342 | D14: 0.99753547 | E14: 0.996982 | F14: 0.99051312 | G14: 0.99732248
A16: Liquidity & asset profile (derived here)
A17: Current ratio (current assets / AP) | C17: 92.876965 | D17: 1944.1 | E17: 369.77038 | F17: 40.875586 | G17: 428.23
A18: Cash ratio ((cash+temp inv.) / total liab.) | B18: 148.00776 | C18: 41.365921 | D18: 90.959259 | E18: 92.881716 | F18: 31.050106 | G18: 75.995
A19: Asset age proxy (accum. deprec. / gross PP&E) | B19: 0.4980999 | C19: 0.46066897 | D19: 0.49762621 | E19: 0.52695036 | F19: 0.55478013 | G19: 0.53930511
A21: Upstream ratios are read from financials_annual; derived ratios are computed only where inputs are reported. Current ratio uses accounts payable as the current-liability proxy (the filings do not split current vs. long-term liabilities). Asset age proxy: a higher % implies older / more depreciated infrastructure.

Sheet Unit economics
A1: Rancho Robles Mutual Water & Road Co
A2: Unit economics - per-customer revenue by category (USD)
A3: Entity ID: cawc_0157 | Fiscal year ends December 31.
A5: Every metric here is PER CUSTOMER (a metered service connection). It is not a per-member figure; the member (shareholder) count is a different denominator, shown in the denominator block. The visible cell shows the value and its classification; the numerator, denominator, formula, and rationale are in each metric's LOGIC popup.
A6: Per-customer denominator (service connections) | C6: State Water Board eAR Section 4
A7: Total annual revenue (eAR Section 8b B1.8) | C7: eAR Section 8b total annual revenue not reported for this system.
A8: Primary source
A10: Revenue categories (value, classification, per customer, share)
A11: Revenue category | B11: Classification | C11: Value (USD) | D11: Per customer | E11: Share of revenue
A12: Water sales revenue | B12: not reported | C12: not reported | D12: not reported | E12: not reported
A13: Assessment revenue (990 program-service revenue not matched to eAR water-rate revenue) | B13: IMPOSSIBLE | C13: IMPOSSIBLE | D13: IMPOSSIBLE | E13: IMPOSSIBLE
A14: Meter revenue | B14: not reported | C14: not reported | D14: not reported | E14: not reported
A15: Overage or tiered penalty revenue | B15: not reported | C15: not reported | D15: not reported | E15: not reported
A17: Water sales revenue - not reported
A18: Not reported: this system filed an eAR but no Section 8b revenue block, so there is no filed water-sales figure. Not fallen back to a different year.
A19: Reason: No filed eAR Section 8b water-rate revenue for this system.
A21: Assessment revenue (990 program-service revenue not matched to eAR water-rate revenue) - IMPOSSIBLE
A22: Not computed. A period-aligned residual is not possible for this filer.
A23: Reason: Not derivable. The eAR Section 8b is reporting year None while the Form 990 fiscal year ends None; the two period ends are not aligned, so a period-aligned residual cannot be computed.
A25: Meter revenue - not reported
A26: Not reported. This category is not built because doing so would double-count.
A27: Reason: The eAR Section 8a reports a base/meter rate PRICE, but the filing carries no meter revenue line and no tier volume, and the base charge is already inside the water-sales revenue (eAR Section 8b water rates). Building a separate meter figure would double-count. Not backed into from a total.
A29: Overage or tiered penalty revenue - not reported
A30: Not reported. This category is not built because doing so would double-count.
A31: Reason: The eAR Section 8a reports tiered/overage rate PRICES, but the filing carries no overage revenue and no tier consumption volume, and any overage billed is already inside the water-sales revenue. Building it would double-count. Not backed into from a total.

Sheet Rate structure
A1: Rancho Robles Mutual Water & Road Co
A2: Rate structure and representative bill - eAR Section 8a
A3: Entity ID: cawc_0157 | Fiscal year ends December 31.
A5: This block is a rate-schedule illustration at defined usage levels. It is NOT billed revenue and not a claim about any real customer's usage. The revenue side of unit economics is the separate Unit Economics block.
A6: No filed eAR Section 8a rate schedule is staged for this system.

Sheet Operational metrics
A1: Rancho Robles Mutual Water & Road Co
A2: Operational metrics - plant per acre, density, terrain
A3: Entity ID: cawc_0157 | Fiscal year ends December 31.
A5: Plant assets per acre
A6: Service-area acres | B6: 385.8 | C6: Geodesic area (WGS84 spherical excess) of the SABL service-area polygon.
A7: Fiscal year | B7: Gross plant per acre (primary) | C7: Net plant per acre
A8: FY2021 | B8: 2932.0062 | C8: 1581.3219
A9: FY2022 | B9: 2992.4443 | C9: 1503.3256
A10: FY2023 | B10: 3099.4142 | C10: 1466.1768
A11: FY2024 | B11: 3225.7232 | C11: 1436.156
A12: FY2025 | B12: 3634.0228 | C12: 1674.1757
A13: Infrastructure built per acre of service area. Gross plant per acre is the primary read because it measures how much plant the system has put in the ground per acre, and unlike net plant it does not fall over time purely because the assets depreciate on the books. Net plant per acre is shown alongside as the depreciated book value per acre.
A14: Formula: gross plant per acre = Form 990 Part X line 10a (land, buildings, and equipment, gross) / SABL service-area acres; net plant per acre uses Part X line 10c (net)
A15: Source lines: Form 990 Part X line 10a (gross) and line 10c (net); Geodesic area (WGS84 spherical excess) of the SABL service-area polygon.
A16: Confidence: medium. This is worked out from filed figures (a ratio, or a year-to-year change), so it is one step removed from the raw numbers.. Filed gross/net plant over the measured SABL service-area acreage.
A18: Connections per acre
A19: Connections per acre | B19: 0.1 | C19: 37 connections / 385.8 acres. CA State Water Board SABL SERVICE_CONNECTIONS; Geodesic area (WGS84 spherical excess) of the SABL service-area polygon.

Sheet Supply & weather
A1: Rancho Robles Mutual Water & Road Co
A2: Supply and weather indicators (DWR water year)
A3: Entity ID: cawc_0157 | Fiscal year ends December 31.
A5: Reporting calendar: Different reporting periods. The DWR water year runs October 1 to September 30; this system's fiscal year ends December 31, so the two period ends are three months apart. Read the two side by side with that in mind. Neither series is recast: both are reported as filed. A water year is named for the calendar year it ends in, so WY2024 and FY2024 share a number without covering the same twelve months.
A7: Indicator | B7: WY2021 | C7: WY2022 | D7: WY2023 | E7: WY2024 | F7: WY2025
A8: Water-year type (Sacramento Valley) | B8: Critical | C8: Critical | D8: Wet | E8: Above Normal | F8: not reported
A9: Peak drought, county County | B9: not reported | C9: not reported | D9: not reported | E9: not reported | F9: not reported
A10: Precip, percent of normal (8-Station Index) | B10: 48 | C10: 86 | D10: 133 | E10: 96 | F10: 113
A11: Snowpack, April 1 percent of average | B11: 59% | C11: 38% | D11: 237% | E11: 110% | F11: 96%
A12: State Water Project allocation | B12: 5% | C12: 5% | D12: 100% | E12: 40% | F12: 50%

Sheet How this was built
A1: Rancho Robles Mutual Water & Road Co
A2: How this was built - forensic lineage
A3: Entity ID: cawc_0157 | Fiscal year ends December 31.
A5: A plain account of the forensic lineage behind the hard-to-source metrics: what sources were checked, what was found, what was derived, and what could not be built and why. Every figure marked DERIVED or IMPOSSIBLE above is traceable to a line here.
A7: Water-sales revenue per customer - not reported
A8: Sources checked | B8: State Water Board eAR Section 8b (water-rate revenue B1.1/B1.2); State Water Board eAR Section 4 (connection count, same reporting year); audited financial statement (secondary cross-check, where published)
A9: What was found | B9: The eAR Section 8b reports water-rate revenue for reporting year None, so this is a DIRECT filed figure; per customer it is divided by the eAR Section 4 connection count for the same reporting year, so numerator and denominator share the year.
A11: Assessment revenue (residual) - IMPOSSIBLE
A12: Sources checked | B12: Form 990 Part VIII line 2 (program-service revenue); State Water Board eAR Section 8b (water-rate revenue B1.1/B1.2); eAR Section 8b filer comment (WRRevenueComments)
A13: What was found | B13: A period-aligned residual cannot be computed for this filer, so the metric is rendered IMPOSSIBLE rather than guessed.
A14: Caveat | B14: Not derivable. The eAR Section 8b is reporting year None while the Form 990 fiscal year ends None; the two period ends are not aligned, so a period-aligned residual cannot be computed.
A16: Meter revenue - not reported
A17: Sources checked | B17: State Water Board eAR Section 8a (rate prices); State Water Board eAR Section 8b (revenue lines); audited financial statement
A18: What was found | B18: The rate price exists in Section 8a but no revenue or tier volume is reported, and the base charge is already inside water sales.
A19: Caveat | B19: The eAR Section 8a reports a base/meter rate PRICE, but the filing carries no meter revenue line and no tier volume, and the base charge is already inside the water-sales revenue (eAR Section 8b water rates). Building a separate meter figure would double-count. Not backed into from a total.
A21: Overage / tiered-penalty revenue - not reported
A22: Sources checked | B22: State Water Board eAR Section 8a (rate prices); State Water Board eAR Section 8b (revenue lines); audited financial statement
A23: What was found | B23: The rate price exists in Section 8a but no revenue or tier volume is reported, and the base charge is already inside water sales.
A24: Caveat | B24: The eAR Section 8a reports tiered/overage rate PRICES, but the filing carries no overage revenue and no tier consumption volume, and any overage billed is already inside the water-sales revenue. Building it would double-count. Not backed into from a total.
A26: eAR Section 8b reporting-period basis - sourced
A27: Sources checked | B27: eAR Section 8b B0.1 (WRFinancialReportingPeriod); eAR Section 8b B0.2 (WRFiscalYearStartDate)
A28: What was found | B28: The reporting basis (fiscal vs calendar year) is read from the filer's own B0.1/B0.2 answer and staged verbatim, never hardcoded, so the 990 comparison and the residual are period-aligned.
A30: Member (shareholder) count denominator - not reported
A31: Sources checked | B31: Form 990 (no member count stated); company website
A32: What was found | B32: No filing states a member/shareholder count, so the per-member unit economics read not reported rather than borrowing the connection count.
A34: Water volume delivered (acre-feet) - not reported
A35: Sources checked | B35: Form 990 (not in the filing); Consumer Confidence Report; eAR Section 6 (PRA-gated)
A36: What was found | B36: Volume delivered in acre-feet is not in the Form 990 and the CCR states only a source mix, so the per-acre-foot metrics read not reported; the eAR Section 6 is named as the source still needed.

Sheet Anomaly Flags
A1: Rancho Robles Mutual Water & Road Co
A2: Anomaly Flags (automated; kept separate from the clean statements)
A3: Entity ID: cawc_0157 | Fiscal year ends December 31.
A5: Material irregularities found automatically in the filed financials by the Hydronomics anomaly flagger. Each flag has two clearly separated layers. WHAT is mechanical, certain, and sourced: the exact filed lines, years, and amounts, carried as filed and never reconciled. WHY is attempted: the filing's own narrative is checked first, and when it states no reason a single best-guess hypothesis is shown, clearly labelled as a guess that is not in the filing and is not a verified figure.
A7: Flag: FY2025 net assets do not sum to the lines we extract
A8: Affected figure | B8: Net assets FY2025
A9: Confidence | B9: medium
A10: What happened (filed, sourced) | B10: FY2025 net assets are carried exactly as filed at $819,457. The lines we extracted do not sum to that total: the ending net assets it reports (Form 990 Part XI line 10) should equal the beginning net assets (line 4) plus revenue less expenses (line 3) plus other changes (lines 5-9), which computes to $815,632 (a difference of $3,825 against the $819,457 on the form). This may mean a line on the form that we do not yet read, rather than an error by the company. The filed figure is kept and the difference is flagged, not reconciled.
A11: Source lines | B11: - Net assets, end of year (as filed): $819,457 (Form 990 Part XI line 10 / Part X line 32 (net assets, end of year)) - Net assets, end of year (recomputed from the lines we extract): $815,632 - Difference (as filed less our computed sum): $3,825
A12: Confidence reasoning | B12: The net-assets figure is a direct filed line item, carried exactly as filed; confidence is held to medium (not high) because the lines we extract do not sum to the total on the form, so the figure is flagged rather than presented as clean. That can mean a line we do not read as easily as an inconsistency in the filing, and this project has found the former three times. Nothing is reconciled.
A13: Why (not stated in the filing) | B13: The filing does not state a reason.
A14: Possible explanation (guess) | B14: Possible explanation, not stated in filing: an ending net-worth figure that does not equal the beginning balance plus the year's surplus or deficit usually reflects a prior-year adjustment, a reclassification between balance-sheet lines, or a rounding or transcription difference on the filed form. This is an educated guess, not something the filing actually says.

Sheet Sources & audit
A1: Rancho Robles Mutual Water & Road Co
A2: Sources & audit - full provenance and tie-outs (kept off the statements so they read clean)
A3: Entity ID: cawc_0157 | Fiscal year ends December 31.
A5: Presentation standard: every figure on the statement tabs is verified to its source filing and shown clean. A cell the filing does not report reads "not reported" (never estimated, never guessed).
A6: Citations, confidence tiers, and the filed-vs-computed tie-out checks live on the "Sources & audit" tab, keyed by cell, so every number is fully traceable without cluttering the statements. These pages are ready to use as filed.
A8: A. Filing provenance (one row per staged extraction)
A9: Fiscal year | B9: Period end | C9: Filing type | D9: Confidence | E9: Extraction ID | F9: Object ID | G9: Extracted by | H9: Extracted at | I9: Source URL
A10: FY2020 | B10: 2020-12-31 | C10: 990 | D10: high | E10: a4e17f40-22b9-45df-81bc-579f280e8dff | F10: 202101379349311685 | G10: claude-opus-5 | H10: 2026-10-05T16:06:09+00:00 | I10: https://apps.irs.gov/pub/epostcard/990/xml/2021/2021_TEOS_XML_01A.zip#202101379349311685_public.xml
A11: FY2021 | B11: 2021-12-31 | C11: 990 | D11: high | E11: 2db161fe-7380-4385-ad29-8e49b87cc60d | F11: 202300609349301135 | G11: claude-opus-5 | H11: 2026-10-05T16:06:09+00:00 | I11: https://apps.irs.gov/pub/epostcard/990/xml/2023/2023_TEOS_XML_03A.zip#202300609349301135_public.xml
A12: FY2022 | B12: 2022-12-31 | C12: 990 | D12: high | E12: ac303b7d-2963-4f72-b16c-ac31e61e4000 | F12: 202310829349301966 | G12: claude-opus-5 | H12: 2026-10-05T16:06:09+00:00 | I12: https://apps.irs.gov/pub/epostcard/990/xml/2023/2023_TEOS_XML_03A.zip#202310829349301966_public.xml
A13: FY2023 | B13: 2023-12-31 | C13: 990 | D13: high | E13: ca228490-6dae-404d-8e82-f48c827971d4 | F13: 202420739349301127 | G13: claude-opus-5 | H13: 2026-10-05T16:06:09+00:00 | I13: https://apps.irs.gov/pub/epostcard/990/xml/2024/2024_TEOS_XML_03A.zip#202420739349301127_public.xml
A14: FY2024 | B14: 2024-12-31 | C14: 990 | D14: high | E14: 5d9571d4-58b7-4d33-aa80-0574afee8146 | F14: 202510759349300806 | G14: claude-opus-5 | H14: 2026-10-05T16:06:09+00:00 | I14: https://apps.irs.gov/pub/epostcard/990/xml/2025/2025_TEOS_XML_03A.zip#202510759349300806_public.xml
A15: FY2025 | B15: 2025-12-31 | C15: 990 | D15: medium | E15: ba502e1a-f010-40cd-9211-0c0728263e56 | F15: 202611059349301041 | G15: claude-opus-5 | H15: 2026-10-05T16:06:09+00:00 | I15: https://apps.irs.gov/pub/epostcard/990/xml/2026/2026_TEOS_XML_04A.zip#202611059349301041_public.xml
A17: B. Figure citations (every figure on the statement tabs, keyed by cell)
A18: Tab | B18: Cell | C18: Line item | D18: Form 990 line | E18: Key path | F18: Confidence | G18: As filed
A19: Revenue (detail) | B19: B7 | C19: 1h. Total contributions, gifts, grants | D19: 1h | E19: part_viii_revenue.total_contributions | F19: high | G19: 0
A20: Revenue (detail) | B20: C7 | C20: 1h. Total contributions, gifts, grants | D20: 1h | E20: part_viii_revenue.total_contributions | F20: high | G20: 0
A21: Revenue (detail) | B21: D7 | C21: 1h. Total contributions, gifts, grants | D21: 1h | E21: part_viii_revenue.total_contributions | F21: high | G21: 0
A22: Revenue (detail) | B22: E7 | C22: 1h. Total contributions, gifts, grants | D22: 1h | E22: part_viii_revenue.total_contributions | F22: high | G22: 0
A23: Revenue (detail) | B23: F7 | C23: 1h. Total contributions, gifts, grants | D23: 1h | E23: part_viii_revenue.total_contributions | F23: high | G23: 0
A24: Revenue (detail) | B24: G7 | C24: 1h. Total contributions, gifts, grants | D24: 1h | E24: part_viii_revenue.total_contributions | F24: high | G24: 0
A25: Revenue (detail) | B25: B8 | C25: 2g. Total program service revenue | D25: 2g | E25: part_viii_revenue.total_program_service_revenue | F25: high | G25: 133290
A26: Revenue (detail) | B26: C8 | C26: 2g. Total program service revenue | D26: 2g | E26: part_viii_revenue.total_program_service_revenue | F26: high | G26: 140221
A27: Revenue (detail) | B27: D8 | C27: 2g. Total program service revenue | D27: 2g | E27: part_viii_revenue.total_program_service_revenue | F27: high | G27: 155185
A28: Revenue (detail) | B28: E8 | C28: 2g. Total program service revenue | D28: 2g | E28: part_viii_revenue.total_program_service_revenue | F28: high | G28: 146799
A29: Revenue (detail) | B29: F8 | C29: 2g. Total program service revenue | D29: 2g | E29: part_viii_revenue.total_program_service_revenue | F29: high | G29: 169318
A30: Revenue (detail) | B30: G8 | C30: 2g. Total program service revenue | D30: 2g | E30: part_viii_revenue.total_program_service_revenue | F30: high | G30: 179825
... A365: Net-assets reconciliation | B365: G10 | C365: 9. Other changes in net assets | D365: Part XI line 9 | E365: part_xi_reconciliation.other_changes_net_assets | F365: high | G365: 19596
A367: C. Tie-out checks (filed vs computed; any nonzero variance is flagged red)
A368: Tab | B368: Check | C368: Fiscal year | D368: Filed | E368: Computed | F368: Variance (computed - filed)
A369: Revenue (detail) | B369: 12. Total revenue | C369: FY2020 | D369: 133472 | E369: ='Revenue (detail)'!B13 | F369: =E369-D369
A370: Revenue (detail) | B370: 12. Total revenue | C370: FY2021 | D370: 141201 | E370: ='Revenue (detail)'!C13 | F370: =E370-D370
A371: Revenue (detail) | B371: 12. Total revenue | C371: FY2022 | D371: 155997 | E371: ='Revenue (detail)'!D13 | F371: =E371-D371
A372: Revenue (detail) | B372: 12. Total revenue | C372: FY2023 | D372: 150476 | E372: ='Revenue (detail)'!E13 | F372: =E372-D372
A373: Revenue (detail) | B373: 12. Total revenue | C373: FY2024 | D373: 178674 | E373: ='Revenue (detail)'!F13 | F373: =E373-D373
A374: Revenue (detail) | B374: 12. Total revenue | C374: FY2025 | D374: 192220 | E374: ='Revenue (detail)'!G13 | F374: =E374-D374
A375: Revenue (detail) | B375: 2g program service revenue = sum of lines 2a-2f (FY2025) | C375: FY2025 | D375: 179825 | E375: =SUM('Revenue (detail)'!C17:C17) | F375: =E375-D375
A376: Operating expenses (detail) | B376: 25. Total functional expenses | C376: FY2020 | D376: 130365 | E376: ='Operating expenses (detail)'!B44 | F376: =E376-D376
A377: Operating expenses (detail) | B377: 25. Total functional expenses | C377: FY2021 | D377: 150929 | E377: ='Operating expenses (detail)'!C44 | F377: =E377-D377
A378: Operating expenses (detail) | B378: 25. Total functional expenses | C378: FY2022 | D378: 172330 | E378: ='Operating expenses (detail)'!D44 | F378: =E378-D378
...

Sheet Provenance
A1: Build provenance | B1: Built from source commit d418ffb17485 (2026-10-06); source fingerprint a75a8eee82c65cf7; 192 companies (179 retail mutual, 4 irrigation mutual, 3 mutual, no PWSID, purpose not stated, 2 frozen non-mutual (special district), 2 wholesale mutual, 1 frozen non-mutual (investor-owned), 1 frozen non-mutual (municipal)); 91 gates; build id 3d08d6d2a855.
A2: source_commit | B2: d418ffb174855ab78000d391d42f898397b0d8aa
A3: source_commit_date | B3: 2026-10-06
A4: source_fingerprint | B4: a75a8eee82c65cf7096931f06e18affdc28686a02895b46538e7298b57c04d94
A5: gate_count | B5: 91
A6: build_id | B6: 3d08d6d2a855
A7: registry: frozen non-mutual (investor-owned) | B7: 1
A8: registry: frozen non-mutual (municipal) | B8: 1
A9: registry: frozen non-mutual (special district) | B9: 2
A10: registry: irrigation mutual | B10: 4
A11: registry: mutual, no PWSID, purpose not stated | B11: 3
A12: registry: retail mutual | B12: 179
A13: registry: wholesale mutual | B13: 2
