Workbook

Sheet Summary
A1: Michele Mutual Water Co
A2: Financial Summary - multi-year overview (USD)
A3: Entity ID: cawc_0167 | Fiscal year ends December 31.
A5: Presentation standard: every figure on the statement tabs is verified to its source filing and shown clean. A cell the filing does not report reads "not reported" (never estimated, never guessed).
A6: Citations, confidence tiers, and the filed-vs-computed tie-out checks live on the "Sources & audit" tab, keyed by cell, so every number is fully traceable without cluttering the statements. These pages are ready to use as filed.
A8: Metric | B8: FY2020 | C8: FY2021 | D8: FY2022 | E8: FY2023 | F8: FY2024
A9: Operating results (USD)
A10: Total revenue | B10: 51917 | C10: 36463 | D10: 85549 | E10: 187039 | F10: 138800
A11: Total expenses | B11: 11039 | C11: 25703 | D11: 34912 | E11: 47578 | F11: 84366
A12: Net income | B12: 40878 | C12: 10760 | D12: 50637 | E12: 139461 | F12: 54434
A14: Financial position (USD, end of year)
A15: Total assets | B15: 280083 | C15: 291267 | D15: 950618 | E15: 975609 | F15: 1001358
A16: Total liabilities | B16: 12600 | C16: 13024 | D16: 11960 | E16: 10686 | F16: 8146
A17: Net assets | B17: 267483 | C17: 278243 | D17: 938658 | E17: 964923 | F17: 993212
A19: Headline ratios
A20: Operating margin | B20: 0.78737215 | C20: 0.29509366 | D20: 0.59190639 | E20: 0.74562524 | F20: 0.39217579
A21: Revenue growth (YoY) | D21: 1.3461865 | E21: 1.1863377 | F21: -0.25790878
A22: Return on assets | B22: 0.14594959 | C22: 0.03694205 | D22: 0.053267453 | E22: 0.14294764 | F22: 0.054360179
A24: Figures as reported in source filings (full provenance on the Sources & audit tab). Parentheses denote negatives; ratios are computed upstream in financials_annual.

Sheet Notes
A1: Notes
A2: Human annotations from the versioned store (data/notes/). Annotations only: they never change a reported figure or a confidence tier.
A4: Date | B4: Tag | C4: Author | D4: Note
A5: 2026-10-05 | B5: clarification | C5: Claude | D5: The website recorded for this company, michelemutualwater.org, is served through Squarespace: the page footer carries "POWERED BY SQUARESPACE". That is a fact about who serves the page and not about whose page it is, and unlike cawc_0136 and cawc_0112, where the company's page sits on the HOST'S subdomain, this company controls the name itself. The site names "Michele Mutual Water Company", describes itself as "a non-profit water utility that is owned and operated by its members", holds meetings at 1495 Michele Way, and publishes PO Box 523 Fulton, California, 95439 and MicheleMutualWater@gmail.com. Fulton is in Sonoma County, matching the registration. Fetched and read on 2026-10-03, re-fetched on 2026-10-05 before seeding, HTTP 200 on all three address forms. The same search that found this page also returned it as a candidate for cawc_0169 Gill Creek Mutual Water Company, which is a different Sonoma County mutual and is recorded as researched with nothing found; this domain is this company's and not that one's.

Sheet Financial Statements
A1: Michele Mutual Water Co
A2: Financial Statements - income statement, balance sheet, cash flow, member income test (USD)
A3: Entity ID: cawc_0167 | Fiscal year ends December 31.
A5: INCOME STATEMENT - as reported (USD)
A6: Line item | B6: FY2020 | C6: FY2021 | D6: FY2022 | E6: FY2023 | F6: FY2024
A7: Revenue
A8: Program service revenue | D8: 88822 | E8: 86489 | F8: 17588
A9: Investment income | D9: 207 | E9: 451 | F9: 294
A10: Net rental income
A11: Net gain/(loss) on investment sales
A12: Other revenue | E12: 14976 | F12: 460
A13: Contributions & grants | D13: 15424 | E13: 85123 | F13: 120458
A14: Total revenue | D14: 85549 | E14: 187039 | F14: 138800
A16: Expenses
A17: Depreciation | D17: 4956
A18: Interest expense
A19: Total expenses | B19: 11039 | C19: 25703 | D19: 34912 | E19: 47578 | F19: 84366
A21: Net income | B21: 40878 | C21: 10760 | D21: 50637 | E21: 139461 | F21: 54434
A24: BALANCE SHEET - as reported (USD, end of year)
A25: Line item | B25: FY2020 | C25: FY2021 | D25: FY2022 | E25: FY2023 | F25: FY2024
A26: Assets
A27: Cash | B27: 89035 | C27: 63845 | D27: 55255 | E27: 150983 | F27: 215932
A28: Savings & temporary investments | D28: 34605
A29: Accounts receivable | D29: 33420 | E29: 28445 | F29: 19000
A30: Inventories
A31: Prepaid expenses
A32: Property, plant & equipment (gross) | D32: 855691 | E32: 825936 | F32: 796181
A33: Less: accumulated depreciation | D33: -29755 | E33: -29755 | F33: -29755
A34: Net property, plant & equipment | B34: 163278 | C34: 195982 | D34: 825936 | E34: 796181 | F34: 766426
A35: Total assets | B35: 280083 | C35: 291267 | D35: 950618 | E35: 975609 | F35: 1001358
A37: Liabilities
A38: Accounts payable | D38: 230
A39: Mortgages & notes payable
A40: Total liabilities | B40: 12600 | C40: 13024 | D40: 11960 | E40: 10686 | F40: 8146
A42: Net Assets / Equity
A43: Capital stock | D43: 0
A44: Paid-in capital | D44: 0
A45: Retained earnings | D45: 938658 | E45: 964923 | F45: 993212
A46: Net assets | B46: 267483 | C46: 278243 | D46: 938658 | E46: 964923 | F46: 993212
A49: CASH FLOW - derived proxy (USD)
...

Sheet Balance Sheet
A1: Michele Mutual Water Co
A2: Balance Sheet - as reported (USD, end of year)
A3: Entity ID: cawc_0167 | Fiscal year ends December 31.
A5: Line item | B5: FY2020 | C5: FY2021 | D5: FY2022 | E5: FY2023 | F5: FY2024
A6: Assets
A7: Cash | B7: 89035 | C7: 63845 | D7: 55255 | E7: 150983 | F7: 215932
A8: Savings & temporary investments | D8: 34605
A9: Accounts receivable | D9: 33420 | E9: 28445 | F9: 19000
A10: Inventories
A11: Prepaid expenses
A12: Property, plant & equipment (gross) | D12: 855691 | E12: 825936 | F12: 796181
A13: Less: accumulated depreciation | D13: -29755 | E13: -29755 | F13: -29755
A14: Net property, plant & equipment | B14: 163278 | C14: 195982 | D14: 825936 | E14: 796181 | F14: 766426
A15: Total assets | B15: 280083 | C15: 291267 | D15: 950618 | E15: 975609 | F15: 1001358
A17: Liabilities
A18: Accounts payable | D18: 230
A19: Mortgages & notes payable
A20: Total liabilities | B20: 12600 | C20: 13024 | D20: 11960 | E20: 10686 | F20: 8146
A22: Net Assets / Equity
A23: Capital stock | D23: 0
A24: Paid-in capital | D24: 0
A25: Retained earnings | D25: 938658 | E25: 964923 | F25: 993212
A26: Net assets | B26: 267483 | C26: 278243 | D26: 938658 | E26: 964923 | F26: 993212
A28: Balance check (assets − liab. − net assets) | B28: 0 | C28: 0 | D28: 0 | E28: 0 | F28: 0
A30: Net PP&E is the reported ppe_net column (gross less accumulated depreciation). The balance check should be ~0 where all three totals are reported; a non-zero value flags a reporting or extraction discrepancy worth reviewing.

Sheet Officers & contractors
A1: Michele Mutual Water Co
A2: Officers, Directors & Contractors - Form 990 Part VII (FY2024; USD)
A3: Entity ID: cawc_0167 | Fiscal year ends December 31.
A5: Section A - Officers, directors, trustees, key employees
A6: Name | B6: Title | C6: Reportable comp (org) | D6: Reportable comp (related) | E6: Other comp | F6: Total compensation
A7: DAVID GURLEY | B7: President | C7: 0 | D7: 0 | E7: 0 | F7: 0
A8: GREG WILSON | B8: Vice President | C8: 0 | D8: 0 | E8: 0 | F8: 0
A9: KAYLA PATANE | B9: Secretary | C9: 0 | D9: 0 | E9: 0 | F9: 0
A10: CATHY RECORD | B10: Treasurer | C10: 0 | D10: 0 | E10: 0 | F10: 0
A11: STEPHEN BARTKOWSKI | B11: Director | C11: 0 | D11: 0 | E11: 0 | F11: 0
A12: WENDY TROWBIRDGE | B12: Director | C12: 0 | D12: 0 | E12: 0 | F12: 0
A13: SARI SCHELLINGER | B13: Director | C13: 0 | D13: 0 | E13: 0 | F13: 0
A15: Section B - Independent contractors (over $100,000)
A16: Contractor | B16: Services | C16: Compensation
A18: Section A lists every officer, director, trustee and key employee filed for the latest year; the two with the highest total compensation are highlighted. Total compensation is computed (reportable org + related + other). Section B lists each independent contractor paid over $100,000; the return reports None such contractor(s). Source and confidence for every figure are on the Sources & audit tab.

Sheet Revenue (detail)
A1: Michele Mutual Water Co
A2: Revenue - Form 990 Part VIII (USD)
A3: Entity ID: cawc_0167 | Fiscal year ends December 31.
A5: Part VIII line | B5: FY2022 | C5: FY2023 | D5: FY2024
A6: Revenue by category
A7: 1h. Total contributions, gifts, grants | B7: 15424 | C7: 85123 | D7: 120458
A8: 2g. Total program service revenue | B8: 88822 | C8: 86489 | D8: 17588
A9: 3. Investment income | B9: 207 | C9: 451 | D9: 294
A10: 6d. Net rental income | B10: not reported | C10: not reported | D10: not reported
A11: 7d. Net gain/(loss) from investment sales | B11: not reported | C11: not reported | D11: not reported
A12: 11e. Other revenue | B12: not reported | C12: 14976 | D12: 460
A13: 12. Total revenue | B13: =SUM(B7:B12) | C13: =SUM(C7:C12) | D13: =SUM(D7:D12)
A15: Program service revenue detail - FY2024 (lines 2a-2f)
A16: Description | B16: Business code | C16: Total revenue
A17: Pipeline Project (Permit | C17: 17588
A18: Revenue category subtotals are as filed. Total revenue (line 12) is a live SUM of the category cells above; its tie-out to the filed total is on the Sources & audit tab. Program service revenue detail is shown for the latest year, with its sum-to-line-2g check on that same audit tab.

Sheet Operating expenses (detail)
A1: Michele Mutual Water Co
A2: Statement of Functional Expenses - Form 990 Part IX (USD)
A3: Entity ID: cawc_0167 | Fiscal year ends December 31.
A5: Part IX line (column A Total) | B5: FY2022 | C5: FY2023 | D5: FY2024
A6: Functional expenses, column A Total - by year
A7: 9. Other employee benefits | B7: not reported | C7: 271 | D7: not reported
A8: 11a. Fees for services: management | B8: not reported | C8: 4361 | D8: 29970
A9: 11b. Fees for services: legal | B9: 2334 | C9: 2343 | D9: 1131
A10: 11c. Fees for services: accounting | B10: 7268 | C10: 14190 | D10: 2906
A11: 11f. Fees for services: investment management | B11: not reported | C11: not reported | D11: 41037
A12: 11g. Fees for services: other | B12: 19060 | C12: not reported | D12: not reported
A13: 12. Advertising and promotion | B13: not reported | C13: not reported | D13: 356
A14: 13. Office expenses | B14: 317 | C14: 11219 | D14: 943
A15: 14. Information technology | B15: not reported | C15: 9511 | D15: not reported
A16: 22. Depreciation, depletion, and amortization | B16: 4956 | C16: not reported | D16: not reported
A17: 23. Insurance | B17: 977 | C17: 1642 | D17: 1721
A18: 24. Utilities | B18: not reported | C18: 4041 | D18: 6302
A19: 24. Other | B19: not reported | C19: 0 | D19: not reported
A20: 24e. All other expenses | B20: not reported | C20: not reported | D20: not reported
A21: 25. Total functional expenses | B21: =SUM(B7:B20) | C21: =SUM(C7:C20) | D21: =SUM(D7:D20)
A23: Functional column split - FY2024 (col A = B + C + D)
A24: Part IX line | B24: A. Total | C24: B. Program services | D24: C. Management & general | E24: D. Fundraising
A25: 11a. Fees for services: management | B25: 29970 | C25: 15389 | D25: 4581 | E25: 10000
A26: 11b. Fees for services: legal | B26: 1131 | D26: 1131
A27: 11c. Fees for services: accounting | B27: 2906 | D27: 2906
A28: 11f. Fees for services: investment management | B28: 41037 | C28: 41037
A29: 12. Advertising and promotion | B29: 356 | D29: 356
A30: 13. Office expenses | B30: 943 | D30: 943
A31: 23. Insurance | B31: 1721 | D31: 1721
A32: 25. Total (filed col A / B / C / D) | B32: 84366 | C32: 62728 | D32: 11638 | E32: 10000
A34: Top block: each Part IX line, column A (Total), by year, as filed. Total functional expenses (line 25) is a live SUM of the line cells; its tie-out to the filed total is on the Sources & audit tab. Filer-itemized 24a-24d rows show the most recent year's as-filed wording; rows are aligned across years case-insensitively with collapsed spacing, so a line filed only in a different capitalization or spacing shares one row, while genuinely different wording stays a separate row (every as-filed variant is recorded on the Sources & audit tab). Lower block: the program / management / fundraising split for the latest year, with its col A = B + C + D check on the audit tab. Lines this filer does not report are omitted rather than shown empty.

Sheet Balance sheet (detail)
A1: Michele Mutual Water Co
A2: Balance Sheet - Form 990 Part X (end of year, USD)
A3: Entity ID: cawc_0167 | Fiscal year ends December 31.
A5: Part X line (column B, EOY) | B5: FY2022 | C5: FY2023 | D5: FY2024
A6: Assets
A7: 1. Cash - non-interest-bearing | B7: 55255 | C7: 150983 | D7: 215932
A8: 2. Savings and temporary cash investments | B8: 34605 | C8: not reported | D8: not reported
A9: 3. Pledges and grants receivable, net | B9: 1402 | C9: not reported | D9: not reported
A10: 4. Accounts receivable, net | B10: 33420 | C10: 28445 | D10: 19000
A11: 10c. Land, buildings, and equipment, net | B11: 825936 | C11: 796181 | D11: 766426
A12: 16. Total assets | B12: =SUM(B7:B11) | C12: =SUM(C7:C11) | D12: =SUM(D7:D11)
A14: Liabilities
A15: 17. Accounts payable and accrued expenses | B15: 230 | C15: not reported | D15: not reported
A16: 24. Unsecured notes and loans payable | B16: 11730 | C16: 10686 | D16: 8146
A17: 26. Total liabilities | B17: =SUM(B15:B16) | C17: =SUM(C15:C16) | D17: =SUM(D15:D16)
A19: Net assets / fund balances
A20: 29. Capital stock or trust principal | B20: 0 | C20: not reported | D20: not reported
A21: 30. Paid-in or capital surplus | B21: 0 | C21: not reported | D21: not reported
A22: 31. Retained earnings / accumulated funds | B22: 938658 | C22: 964923 | D22: 993212
A23: 32. Total net assets / fund balances | B23: =SUM(B20:B22) | C23: =SUM(C20:C22) | D23: =SUM(D20:D22)
A25: Every Part X line is end-of-year (column B), as filed. Section totals (lines 16 / 26 / 32) are live SUMs of the lines above; their tie-outs and the balance-sheet identity (16 = 26 + 32) are on the Sources & audit tab. This filer files as a non-FASB mutual, so net assets sit on lines 29-31 (capital stock / paid-in capital / retained earnings); lines this filer does not report are omitted. Lines 10a/10b net into line 10c (shown).

Sheet Net-assets reconciliation
A1: Michele Mutual Water Co
A2: Reconciliation of Net Assets - Form 990 Part XI (USD)
A3: Entity ID: cawc_0167 | Fiscal year ends December 31.
A5: Part XI line | B5: FY2022 | C5: FY2023 | D5: FY2024
A6: Reconciliation
A7: 4. Net assets, beginning of year | B7: 278241 | C7: 938658 | D7: 964923
A8: 3. Revenue less expenses | B8: 50637 | C8: 139461 | D8: 54434
A9: 8. Prior period adjustments | B9: not reported | C9: not reported | D9: not reported
A10: 9. Other changes in net assets | B10: 609780 | C10: not reported | D10: 0
A11: 10. Net assets, end of year | B11: =SUM(B7,B8,B9,B10) | C11: =SUM(C7,C8,C9,C10) | D11: =SUM(D7,D8,D9,D10)
A13: Part XI reconciles beginning to ending net assets. Ending net assets (line 10) is a live formula: beginning balance (line 4) + revenue less expenses (line 3) + prior-period adjustments (8) + other changes (9). Its tie-out to the filed line 10 (and to Part X line 32) is on the Sources & audit tab. Lines 5-7 (unrealized gains, donated services, investment expenses) are not filed by this entity.

Sheet Cash flow proxies
A1: Michele Mutual Water Co
A2: Cash Flow Proxies - derived (USD)
A3: Entity ID: cawc_0167 | Fiscal year ends December 31.
A5: PROXY ONLY. The source filings contain no statement of cash flows. Lines below are derived from the reported income statement and year-over-year balance-sheet changes; treat as directional estimates, not GAAP cash flows. The earliest year has no prior period, so its delta cells are blank.
A7: Proxy line (USD) | B7: FY2020 | C7: FY2021 | D7: FY2022 | E7: FY2023 | F7: FY2024
A8: Operating
A9: Net income | B9: 40878 | C9: 10760 | D9: 50637 | E9: 139461 | F9: 54434
A10: + Depreciation (reported) | D10: 4956
A11: − Δ Accounts receivable | E11: 4975 | F11: 9445
A12: − Δ Inventories
A13: − Δ Prepaid expenses
A14: + Δ Accounts payable
A15: Operating cash flow proxy | C15: 10760 | D15: 55593 | E15: 144436 | F15: 63879
A17: Investing
A18: − Δ PP&E gross (capex proxy) | E18: 29755 | F18: 29755
A20: Financing
A21: Δ Mortgages & notes payable
A23: Reconciliation
A24: Δ Cash + temp. investments (actual) | C24: -25190 | D24: 26015 | E24: 61123 | F24: 64949
A26: The capex proxy assumes gross PP&E rises only via capital spending (it ignores disposals). 'Δ Cash + temp. investments (actual)' is the real reported change in liquid funds and is the most reliable line here; the operating/investing/financing proxies will not perfectly reconcile to it.

Sheet Ratios
A1: Michele Mutual Water Co
A2: Financial Ratios
A3: Entity ID: cawc_0167 | Fiscal year ends December 31.
A5: Ratio | B5: FY2020 | C5: FY2021 | D5: FY2022 | E5: FY2023 | F5: FY2024
A6: Profitability (computed upstream)
A7: Operating margin (NI / revenue) | B7: 0.78737215 | C7: 0.29509366 | D7: 0.59190639 | E7: 0.74562524 | F7: 0.39217579
A8: Expense ratio (expenses / revenue) | B8: 0.21262785 | C8: 0.70490634 | D8: 0.40809361 | E8: 0.25437476 | F8: 0.60782421
A9: Return on assets (NI / assets) | B9: 0.14594959 | C9: 0.03694205 | D9: 0.053267453 | E9: 0.14294764 | F9: 0.054360179
A10: Revenue growth (YoY) | D10: 1.3461865 | E10: 1.1863377 | F10: -0.25790878
A12: Leverage & solvency
A13: Debt-to-assets (liab. / assets) | B13: 0.044986665 | C13: 0.044714987 | D13: 0.012581289 | E13: 0.010953158 | F13: 0.0081349527
A14: Equity ratio (net assets / assets) | B14: 0.95501334 | C14: 0.95528501 | D14: 0.98741871 | E14: 0.98904684 | F14: 0.99186505
A16: Liquidity & asset profile (derived here)
A17: Current ratio (current assets / AP) | D17: 536
A18: Cash ratio ((cash+temp inv.) / total liab.) | B18: 7.0662698 | C18: 4.9021038 | D18: 7.5133779 | E18: 14.129047 | F18: 26.507734
A19: Asset age proxy (accum. deprec. / gross PP&E) | D19: 0.034773066 | E19: 0.036025794 | F19: 0.037372155
A21: Upstream ratios are read from financials_annual; derived ratios are computed only where inputs are reported. Current ratio uses accounts payable as the current-liability proxy (the filings do not split current vs. long-term liabilities). Asset age proxy: a higher % implies older / more depreciated infrastructure.

Sheet Unit economics
A1: Michele Mutual Water Co
A2: Unit economics - per-customer revenue by category (USD)
A3: Entity ID: cawc_0167 | Fiscal year ends December 31.
A5: Every metric here is PER CUSTOMER (a metered service connection). It is not a per-member figure; the member (shareholder) count is a different denominator, shown in the denominator block. The visible cell shows the value and its classification; the numerator, denominator, formula, and rationale are in each metric's LOGIC popup.
A6: Per-customer denominator (service connections) | C6: State Water Board eAR Section 4
A7: Total annual revenue (eAR Section 8b B1.8) | C7: eAR Section 8b total annual revenue not reported for this system.
A8: Primary source
A10: Revenue categories (value, classification, per customer, share)
A11: Revenue category | B11: Classification | C11: Value (USD) | D11: Per customer | E11: Share of revenue
A12: Water sales revenue | B12: not reported | C12: not reported | D12: not reported | E12: not reported
A13: Assessment revenue (990 program-service revenue not matched to eAR water-rate revenue) | B13: IMPOSSIBLE | C13: IMPOSSIBLE | D13: IMPOSSIBLE | E13: IMPOSSIBLE
A14: Meter revenue | B14: not reported | C14: not reported | D14: not reported | E14: not reported
A15: Overage or tiered penalty revenue | B15: not reported | C15: not reported | D15: not reported | E15: not reported
A17: Water sales revenue - not reported
A18: Not reported: this system filed an eAR but no Section 8b revenue block, so there is no filed water-sales figure. Not fallen back to a different year.
A19: Reason: No filed eAR Section 8b water-rate revenue for this system.
A21: Assessment revenue (990 program-service revenue not matched to eAR water-rate revenue) - IMPOSSIBLE
A22: Not computed. A period-aligned residual is not possible for this filer.
A23: Reason: Not derivable. The eAR Section 8b is reporting year None while the Form 990 fiscal year ends None; the two period ends are not aligned, so a period-aligned residual cannot be computed.
A25: Meter revenue - not reported
A26: Not reported. This category is not built because doing so would double-count.
A27: Reason: The eAR Section 8a reports a base/meter rate PRICE, but the filing carries no meter revenue line and no tier volume, and the base charge is already inside the water-sales revenue (eAR Section 8b water rates). Building a separate meter figure would double-count. Not backed into from a total.
A29: Overage or tiered penalty revenue - not reported
A30: Not reported. This category is not built because doing so would double-count.
A31: Reason: The eAR Section 8a reports tiered/overage rate PRICES, but the filing carries no overage revenue and no tier consumption volume, and any overage billed is already inside the water-sales revenue. Building it would double-count. Not backed into from a total.

Sheet Rate structure
A1: Michele Mutual Water Co
A2: Rate structure and representative bill - eAR Section 8a
A3: Entity ID: cawc_0167 | Fiscal year ends December 31.
A5: This block is a rate-schedule illustration at defined usage levels. It is NOT billed revenue and not a claim about any real customer's usage. The revenue side of unit economics is the separate Unit Economics block.
A6: No filed eAR Section 8a rate schedule is staged for this system.

Sheet Operational metrics
A1: Michele Mutual Water Co
A2: Operational metrics - plant per acre, density, terrain
A3: Entity ID: cawc_0167 | Fiscal year ends December 31.
A5: Plant assets per acre
A6: Service-area acres | B6: 71.2 | C6: Geodesic area (WGS84 spherical excess) of the SABL service-area polygon.
A7: Fiscal year | B7: Gross plant per acre (primary) | C7: Net plant per acre
A8: FY2020 | C8: 2293.2303
A9: FY2021 | C9: 2752.5562
A10: FY2022 | B10: 12018.132 | C10: 11600.225
A11: FY2023 | B11: 11600.225 | C11: 11182.317
A12: FY2024 | B12: 11182.317 | C12: 10764.41
A13: Infrastructure built per acre of service area. Gross plant per acre is the primary read because it measures how much plant the system has put in the ground per acre, and unlike net plant it does not fall over time purely because the assets depreciate on the books. Net plant per acre is shown alongside as the depreciated book value per acre.
A14: Formula: gross plant per acre = Form 990 Part X line 10a (land, buildings, and equipment, gross) / SABL service-area acres; net plant per acre uses Part X line 10c (net)
A15: Source lines: Form 990 Part X line 10a (gross) and line 10c (net); Geodesic area (WGS84 spherical excess) of the SABL service-area polygon.
A16: Confidence: medium. This is worked out from filed figures (a ratio, or a year-to-year change), so it is one step removed from the raw numbers.. Filed gross/net plant over the measured SABL service-area acreage.
A18: Connections per acre
A19: Connections per acre | B19: 0.66 | C19: 47 connections / 71.2 acres. CA State Water Board SABL SERVICE_CONNECTIONS; Geodesic area (WGS84 spherical excess) of the SABL service-area polygon.

Sheet Supply & weather
A1: Michele Mutual Water Co
A2: Supply and weather indicators (DWR water year)
A3: Entity ID: cawc_0167 | Fiscal year ends December 31.
A5: Reporting calendar: Different reporting periods. The DWR water year runs October 1 to September 30; this system's fiscal year ends December 31, so the two period ends are three months apart. Read the two side by side with that in mind. Neither series is recast: both are reported as filed. A water year is named for the calendar year it ends in, so WY2024 and FY2024 share a number without covering the same twelve months.
A7: Indicator | B7: WY2020 | C7: WY2021 | D7: WY2022 | E7: WY2023 | F7: WY2024
A8: Water-year type (Sacramento Valley) | B8: Dry | C8: Critical | D8: Critical | E8: Wet | F8: Above Normal
A9: Peak drought, county County | B9: not reported | C9: not reported | D9: not reported | E9: not reported | F9: not reported
A10: Precip, percent of normal (8-Station Index) | B10: 63 | C10: 48 | D10: 86 | E10: 133 | F10: 96
A11: Snowpack, April 1 percent of average | B11: 53% | C11: 59% | D11: 38% | E11: 237% | F11: 110%
A12: State Water Project allocation | B12: 20% | C12: 5% | D12: 5% | E12: 100% | F12: 40%

Sheet How this was built
A1: Michele Mutual Water Co
A2: How this was built - forensic lineage
A3: Entity ID: cawc_0167 | Fiscal year ends December 31.
A5: A plain account of the forensic lineage behind the hard-to-source metrics: what sources were checked, what was found, what was derived, and what could not be built and why. Every figure marked DERIVED or IMPOSSIBLE above is traceable to a line here.
A7: Water-sales revenue per customer - not reported
A8: Sources checked | B8: State Water Board eAR Section 8b (water-rate revenue B1.1/B1.2); State Water Board eAR Section 4 (connection count, same reporting year); audited financial statement (secondary cross-check, where published)
A9: What was found | B9: The eAR Section 8b reports water-rate revenue for reporting year None, so this is a DIRECT filed figure; per customer it is divided by the eAR Section 4 connection count for the same reporting year, so numerator and denominator share the year.
A11: Assessment revenue (residual) - IMPOSSIBLE
A12: Sources checked | B12: Form 990 Part VIII line 2 (program-service revenue); State Water Board eAR Section 8b (water-rate revenue B1.1/B1.2); eAR Section 8b filer comment (WRRevenueComments)
A13: What was found | B13: A period-aligned residual cannot be computed for this filer, so the metric is rendered IMPOSSIBLE rather than guessed.
A14: Caveat | B14: Not derivable. The eAR Section 8b is reporting year None while the Form 990 fiscal year ends None; the two period ends are not aligned, so a period-aligned residual cannot be computed.
A16: Meter revenue - not reported
A17: Sources checked | B17: State Water Board eAR Section 8a (rate prices); State Water Board eAR Section 8b (revenue lines); audited financial statement
A18: What was found | B18: The rate price exists in Section 8a but no revenue or tier volume is reported, and the base charge is already inside water sales.
A19: Caveat | B19: The eAR Section 8a reports a base/meter rate PRICE, but the filing carries no meter revenue line and no tier volume, and the base charge is already inside the water-sales revenue (eAR Section 8b water rates). Building a separate meter figure would double-count. Not backed into from a total.
A21: Overage / tiered-penalty revenue - not reported
A22: Sources checked | B22: State Water Board eAR Section 8a (rate prices); State Water Board eAR Section 8b (revenue lines); audited financial statement
A23: What was found | B23: The rate price exists in Section 8a but no revenue or tier volume is reported, and the base charge is already inside water sales.
A24: Caveat | B24: The eAR Section 8a reports tiered/overage rate PRICES, but the filing carries no overage revenue and no tier consumption volume, and any overage billed is already inside the water-sales revenue. Building it would double-count. Not backed into from a total.
A26: eAR Section 8b reporting-period basis - sourced
A27: Sources checked | B27: eAR Section 8b B0.1 (WRFinancialReportingPeriod); eAR Section 8b B0.2 (WRFiscalYearStartDate)
A28: What was found | B28: The reporting basis (fiscal vs calendar year) is read from the filer's own B0.1/B0.2 answer and staged verbatim, never hardcoded, so the 990 comparison and the residual are period-aligned.
A30: Member (shareholder) count denominator - not reported
A31: Sources checked | B31: Form 990 (no member count stated); company website
A32: What was found | B32: No filing states a member/shareholder count, so the per-member unit economics read not reported rather than borrowing the connection count.
A34: Water volume delivered (acre-feet) - not reported
A35: Sources checked | B35: Form 990 (not in the filing); Consumer Confidence Report; eAR Section 6 (PRA-gated)
A36: What was found | B36: Volume delivered in acre-feet is not in the Form 990 and the CCR states only a source mix, so the per-acre-foot metrics read not reported; the eAR Section 6 is named as the source still needed.

Sheet Anomaly Flags
A1: Michele Mutual Water Co
A2: Anomaly Flags (automated; kept separate from the clean statements)
A3: Entity ID: cawc_0167 | Fiscal year ends December 31.
A5: Material irregularities found automatically in the filed financials by the Hydronomics anomaly flagger. Each flag has two clearly separated layers. WHAT is mechanical, certain, and sourced: the exact filed lines, years, and amounts, carried as filed and never reconciled. WHY is attempted: the filing's own narrative is checked first, and when it states no reason a single best-guess hypothesis is shown, clearly labelled as a guess that is not in the filing and is not a verified figure.
A7: Flag: FY2023 net assets do not sum to the lines we extract
A8: Affected figure | B8: Net assets FY2023
A9: Confidence | B9: medium
A10: What happened (filed, sourced) | B10: FY2023 net assets are carried exactly as filed at $964,923. The lines we extracted do not sum to that total: the ending net assets it reports (Form 990 Part XI line 10) should equal the beginning net assets (line 4) plus revenue less expenses (line 3) plus other changes (lines 5-9), which computes to $1,078,119 (a difference of $-113,196 against the $964,923 on the form). This may mean a line on the form that we do not yet read, rather than an error by the company. The filed figure is kept and the difference is flagged, not reconciled.
A11: Source lines | B11: - Net assets, end of year (as filed): $964,923 (Form 990 Part XI line 10 / Part X line 32 (net assets, end of year)) - Net assets, end of year (recomputed from the lines we extract): $1,078,119 - Difference (as filed less our computed sum): $-113,196
A12: Confidence reasoning | B12: The net-assets figure is a direct filed line item, carried exactly as filed; confidence is held to medium (not high) because the lines we extract do not sum to the total on the form, so the figure is flagged rather than presented as clean. That can mean a line we do not read as easily as an inconsistency in the filing, and this project has found the former three times. Nothing is reconciled.
A13: Why (not stated in the filing) | B13: The filing does not state a reason.
A14: Possible explanation (guess) | B14: Possible explanation, not stated in filing: an ending net-worth figure that does not equal the beginning balance plus the year's surplus or deficit usually reflects a prior-year adjustment, a reclassification between balance-sheet lines, or a rounding or transcription difference on the filed form. This is an educated guess, not something the filing actually says.
A16: Flag: FY2024 net assets do not sum to the lines we extract
A17: Affected figure | B17: Net assets FY2024
A18: Confidence | B18: medium
A19: What happened (filed, sourced) | B19: FY2024 net assets are carried exactly as filed at $993,212. The lines we extracted do not sum to that total: the ending net assets it reports (Form 990 Part XI line 10) should equal the beginning net assets (line 4) plus revenue less expenses (line 3) plus other changes (lines 5-9), which computes to $1,019,357 (a difference of $-26,145 against the $993,212 on the form). This may mean a line on the form that we do not yet read, rather than an error by the company. The filed figure is kept and the difference is flagged, not reconciled.
A20: Source lines | B20: - Net assets, end of year (as filed): $993,212 (Form 990 Part XI line 10 / Part X line 32 (net assets, end of year)) - Net assets, end of year (recomputed from the lines we extract): $1,019,357 - Difference (as filed less our computed sum): $-26,145
A21: Confidence reasoning | B21: The net-assets figure is a direct filed line item, carried exactly as filed; confidence is held to medium (not high) because the lines we extract do not sum to the total on the form, so the figure is flagged rather than presented as clean. That can mean a line we do not read as easily as an inconsistency in the filing, and this project has found the former three times. Nothing is reconciled.
A22: Why (not stated in the filing) | B22: The filing does not state a reason.
A23: Possible explanation (guess) | B23: Possible explanation, not stated in filing: an ending net-worth figure that does not equal the beginning balance plus the year's surplus or deficit usually reflects a prior-year adjustment, a reclassification between balance-sheet lines, or a rounding or transcription difference on the filed form. This is an educated guess, not something the filing actually says.
A25: Flag: FY2022 opening net assets differ from FY2021 closing
A26: Affected figure | B26: Net assets FY2022
A27: Confidence | B27: high
A28: What happened (filed, sourced) | B28: The company filed $278,241 as its beginning net assets for FY2022 and $278,243 as its ending net assets for FY2021, a difference of $-2. Both figures are carried exactly as each year's own filing reports them. Neither is adjusted to match the other.
A29: Source lines | B29: - FY2022 net assets, beginning of year (as filed): $278,241 - FY2021 net assets, end of year (as filed): $278,243 - Difference: $-2
A30: Confidence reasoning | B30: Both are direct filed line items read from two different returns, so the difference between them is high confidence as an observation. What caused it is not stated on either form.
A31: Why (not stated in the filing) | B31: The filing does not state a reason.
A32: Possible explanation (guess) | B32: Possible explanation, not stated in filing: a beginning balance that differs from the prior year's ending balance usually means the earlier year was restated, or a balance-sheet line was reclassified between the two filings. This is an educated guess, not something either filing says.

Sheet Sources & audit
A1: Michele Mutual Water Co
A2: Sources & audit - full provenance and tie-outs (kept off the statements so they read clean)
A3: Entity ID: cawc_0167 | Fiscal year ends December 31.
A5: Presentation standard: every figure on the statement tabs is verified to its source filing and shown clean. A cell the filing does not report reads "not reported" (never estimated, never guessed).
A6: Citations, confidence tiers, and the filed-vs-computed tie-out checks live on the "Sources & audit" tab, keyed by cell, so every number is fully traceable without cluttering the statements. These pages are ready to use as filed.
A8: A. Filing provenance (one row per staged extraction)
A9: Fiscal year | B9: Period end | C9: Filing type | D9: Confidence | E9: Extraction ID | F9: Object ID | G9: Extracted by | H9: Extracted at | I9: Source URL
A10: FY2020 | B10: 2020-12-31 | C10: 990-EZ | D10: high | E10: 8f7e7c05-2f88-48d4-be8b-a05737e89329 | F10: 202142779349200139 | G10: claude-opus-5 | H10: 2026-10-05T16:06:10+00:00 | I10: https://apps.irs.gov/pub/epostcard/990/xml/2021/2021_TEOS_XML_01A.zip#202142779349200139_public.xml
A11: FY2021 | B11: 2021-12-31 | C11: 990-EZ | D11: high | E11: 5a21ee64-967e-4ac3-ac43-a0f30c2ea6b2 | F11: 202243199349212244 | G11: claude-opus-5 | H11: 2026-10-05T16:06:10+00:00 | I11: https://apps.irs.gov/pub/epostcard/990/xml/2022/2022_TEOS_XML_02A.zip#202243199349212244_public.xml
A12: FY2022 | B12: 2022-12-31 | C12: 990 | D12: high | E12: 20fcf6fe-f2dd-462b-aecc-f2152f9b85b3 | F12: 202323199349321087 | G12: claude-opus-5 | H12: 2026-10-05T16:06:10+00:00 | I12: https://apps.irs.gov/pub/epostcard/990/xml/2023/2023_TEOS_XML_11A.zip#202323199349321087_public.xml
A13: FY2023 | B13: 2023-12-31 | C13: 990 | D13: medium | E13: ca97d22c-3923-4423-976f-de073e4fcfa9 | F13: 202413219349300431 | G13: claude-opus-5 | H13: 2026-10-05T16:06:10+00:00 | I13: https://apps.irs.gov/pub/epostcard/990/xml/2024/2024_TEOS_XML_11A.zip#202413219349300431_public.xml
A14: FY2024 | B14: 2024-12-31 | C14: 990 | D14: medium | E14: 9845b888-2e44-4347-a53e-29f71464a8ed | F14: 202630149349300618 | G14: claude-opus-5 | H14: 2026-10-05T16:06:10+00:00 | I14: https://apps.irs.gov/pub/epostcard/990/xml/2026/2026_TEOS_XML_01A.zip#202630149349300618_public.xml
A16: B. Figure citations (every figure on the statement tabs, keyed by cell)
A17: Tab | B17: Cell | C17: Line item | D17: Form 990 line | E17: Key path | F17: Confidence | G17: As filed
A18: Financial Statements | B18: B73 | C18: 11a. Gross income from members or shareholders | D18: 11a | E18: part_v_other_irs_filings.members_and_shareholders_gross_income | F18: high | G18: 88822
A19: Financial Statements | B19: C73 | C19: 11a. Gross income from members or shareholders | D19: 11a | E19: part_v_other_irs_filings.members_and_shareholders_gross_income | F19: high | G19: 86489
A20: Financial Statements | B20: D73 | C20: 11a. Gross income from members or shareholders | D20: 11a | E20: part_v_other_irs_filings.members_and_shareholders_gross_income | F20: high | G20: 0
A21: Financial Statements | B21: B74 | C21: 11b. Gross income from other sources | D21: 11b | E21: part_v_other_irs_filings.other_sources_gross_income | F21: high | G21: 0
A22: Financial Statements | B22: D74 | C22: 11b. Gross income from other sources | D22: 11b | E22: part_v_other_irs_filings.other_sources_gross_income | F22: high | G22: 0
A23: Revenue (detail) | B23: B7 | C23: 1h. Total contributions, gifts, grants | D23: 1h | E23: part_viii_revenue.total_contributions | F23: high | G23: 15424
A24: Revenue (detail) | B24: C7 | C24: 1h. Total contributions, gifts, grants | D24: 1h | E24: part_viii_revenue.total_contributions | F24: high | G24: 85123
A25: Revenue (detail) | B25: D7 | C25: 1h. Total contributions, gifts, grants | D25: 1h | E25: part_viii_revenue.total_contributions | F25: high | G25: 120458
A26: Revenue (detail) | B26: B8 | C26: 2g. Total program service revenue | D26: 2g | E26: part_viii_revenue.total_program_service_revenue | F26: high | G26: 88822
A27: Revenue (detail) | B27: C8 | C27: 2g. Total program service revenue | D27: 2g | E27: part_viii_revenue.total_program_service_revenue | F27: high | G27: 86489
A28: Revenue (detail) | B28: D8 | C28: 2g. Total program service revenue | D28: 2g | E28: part_viii_revenue.total_program_service_revenue | F28: high | G28: 17588
A29: Revenue (detail) | B29: B9 | C29: 3. Investment income | D29: 3 | E29: part_viii_revenue.investment_income | F29: high | G29: 207
... A81: Net-assets reconciliation | B81: D10 | C81: 9. Other changes in net assets | D81: Part XI line 9 | E81: part_xi_reconciliation.other_changes_net_assets | F81: high | G81: 0
A83: C. Tie-out checks (filed vs computed; any nonzero variance is flagged red)
A84: Tab | B84: Check | C84: Fiscal year | D84: Filed | E84: Computed | F84: Variance (computed - filed)
A85: Revenue (detail) | B85: 12. Total revenue | C85: FY2022 | D85: 85549 | E85: ='Revenue (detail)'!B13 | F85: =E85-D85
A86: Revenue (detail) | B86: 12. Total revenue | C86: FY2023 | D86: 187039 | E86: ='Revenue (detail)'!C13 | F86: =E86-D86
A87: Revenue (detail) | B87: 12. Total revenue | C87: FY2024 | D87: 138800 | E87: ='Revenue (detail)'!D13 | F87: =E87-D87
A88: Revenue (detail) | B88: 2g program service revenue = sum of lines 2a-2f (FY2024) | C88: FY2024 | D88: 17588 | E88: =SUM('Revenue (detail)'!C17:C17) | F88: =E88-D88
A89: Operating expenses (detail) | B89: 25. Total functional expenses | C89: FY2022 | D89: 34912 | E89: ='Operating expenses (detail)'!B21 | F89: =E89-D89
A90: Operating expenses (detail) | B90: 25. Total functional expenses | C90: FY2023 | D90: 47578 | E90: ='Operating expenses (detail)'!C21 | F90: =E90-D90
A91: Operating expenses (detail) | B91: 25. Total functional expenses | C91: FY2024 | D91: 84366 | E91: ='Operating expenses (detail)'!D21 | F91: =E91-D91
A92: Operating expenses (detail) | B92: Part IX column split: col A = B + C + D (FY2024) | C92: FY2024 | D92: ='Operating expenses (detail)'!B32 | E92: ='Operating expenses (detail)'!C32+'Operating expenses (detail)'!D32+'Operating expenses (detail)'!E32 | F92: =E92-D92
A93: Balance sheet (detail) | B93: 16. Total assets | C93: FY2022 | D93: 950618 | E93: ='Balance sheet (detail)'!B12 | F93: =E93-D93
A94: Balance sheet (detail) | B94: 16. Total assets | C94: FY2023 | D94: 975609 | E94: ='Balance sheet (detail)'!C12 | F94: =E94-D94
A95: Balance sheet (detail) | B95: 16. Total assets | C95: FY2024 | D95: 1001358 | E95: ='Balance sheet (detail)'!D12 | F95: =E95-D95
...

Sheet Provenance
A1: Build provenance | B1: Built from source commit d418ffb17485 (2026-10-06); source fingerprint a75a8eee82c65cf7; 192 companies (179 retail mutual, 4 irrigation mutual, 3 mutual, no PWSID, purpose not stated, 2 frozen non-mutual (special district), 2 wholesale mutual, 1 frozen non-mutual (investor-owned), 1 frozen non-mutual (municipal)); 91 gates; build id 3d08d6d2a855.
A2: source_commit | B2: d418ffb174855ab78000d391d42f898397b0d8aa
A3: source_commit_date | B3: 2026-10-06
A4: source_fingerprint | B4: a75a8eee82c65cf7096931f06e18affdc28686a02895b46538e7298b57c04d94
A5: gate_count | B5: 91
A6: build_id | B6: 3d08d6d2a855
A7: registry: frozen non-mutual (investor-owned) | B7: 1
A8: registry: frozen non-mutual (municipal) | B8: 1
A9: registry: frozen non-mutual (special district) | B9: 2
A10: registry: irrigation mutual | B10: 4
A11: registry: mutual, no PWSID, purpose not stated | B11: 3
A12: registry: retail mutual | B12: 179
A13: registry: wholesale mutual | B13: 2
