Workbook

Sheet Summary
A1: East Valley Farms Mutual Water Company
A2: Financial Summary - multi-year overview (USD)
A3: Entity ID: cawc_0090 | Fiscal year ends December 31.
A5: Presentation standard: every figure on the statement tabs is verified to its source filing and shown clean. A cell the filing does not report reads "not reported" (never estimated, never guessed).
A6: Citations, confidence tiers, and the filed-vs-computed tie-out checks live on the "Sources & audit" tab, keyed by cell, so every number is fully traceable without cluttering the statements. These pages are ready to use as filed.
A8: Metric | B8: FY2022 | C8: FY2024 | D8: FY2025
A9: Operating results (USD)
A10: Total revenue | B10: 125375 | C10: 146200 | D10: 178822
A11: Total expenses | B11: 91784 | C11: 105064 | D11: 122933
A12: Net income | B12: 33591 | C12: 41136 | D12: 55889
A14: Financial position (USD, end of year)
A15: Total assets | B15: 314116 | C15: 352150 | D15: 386073
A16: Total liabilities | B16: 8088 | C16: 6975 | D16: 3255
A17: Net assets | B17: 306028 | C17: 345175 | D17: 382818
A19: Headline ratios
A20: Operating margin | B20: 0.26792423 | C20: 0.28136799 | D20: 0.31253984
A21: Revenue growth (YoY)
A22: Return on assets | B22: 0.1069382 | C22: 0.11681386 | D22: 0.14476278
A24: Figures as reported in source filings (full provenance on the Sources & audit tab). Parentheses denote negatives; ratios are computed upstream in financials_annual.

Sheet Notes
A1: Notes
A2: Human annotations from the versioned store (data/notes/). Annotations only: they never change a reported figure or a confidence tier.
A4: Date | B4: Tag | C4: Author | D4: Note
A5: No notes recorded yet.

Sheet Financial Statements
A1: East Valley Farms Mutual Water Company
A2: Financial Statements - income statement, balance sheet, cash flow, member income test (USD)
A3: Entity ID: cawc_0090 | Fiscal year ends December 31.
A5: INCOME STATEMENT - as reported (USD)
A6: Line item | B6: FY2022 | C6: FY2024 | D6: FY2025
A7: Revenue
A8: Program service revenue
A9: Investment income
A10: Net rental income
A11: Net gain/(loss) on investment sales
A12: Other revenue
A13: Contributions & grants
A14: Total revenue
A16: Expenses
A17: Depreciation
A18: Interest expense
A19: Total expenses | B19: 91784 | C19: 105064 | D19: 122933
A21: Net income | B21: 33591 | C21: 41136 | D21: 55889
A24: BALANCE SHEET - as reported (USD, end of year)
A25: Line item | B25: FY2022 | C25: FY2024 | D25: FY2025
A26: Assets
A27: Cash | B27: 291567 | C27: 324487 | D27: 371617
A28: Savings & temporary investments
A29: Accounts receivable
A30: Inventories
A31: Prepaid expenses
A32: Property, plant & equipment (gross)
A33: Less: accumulated depreciation
A34: Net property, plant & equipment
A35: Total assets | B35: 314116 | C35: 352150 | D35: 386073
A37: Liabilities
A38: Accounts payable
A39: Mortgages & notes payable
A40: Total liabilities | B40: 8088 | C40: 6975 | D40: 3255
A42: Net Assets / Equity
A43: Capital stock
A44: Paid-in capital
A45: Retained earnings
A46: Net assets | B46: 306028 | C46: 345175 | D46: 382818
A49: CASH FLOW - derived proxy (USD)
...

Sheet Balance Sheet
A1: East Valley Farms Mutual Water Company
A2: Balance Sheet - as reported (USD, end of year)
A3: Entity ID: cawc_0090 | Fiscal year ends December 31.
A5: Line item | B5: FY2022 | C5: FY2024 | D5: FY2025
A6: Assets
A7: Cash | B7: 291567 | C7: 324487 | D7: 371617
A8: Savings & temporary investments
A9: Accounts receivable
A10: Inventories
A11: Prepaid expenses
A12: Property, plant & equipment (gross)
A13: Less: accumulated depreciation
A14: Net property, plant & equipment
A15: Total assets | B15: 314116 | C15: 352150 | D15: 386073
A17: Liabilities
A18: Accounts payable
A19: Mortgages & notes payable
A20: Total liabilities | B20: 8088 | C20: 6975 | D20: 3255
A22: Net Assets / Equity
A23: Capital stock
A24: Paid-in capital
A25: Retained earnings
A26: Net assets | B26: 306028 | C26: 345175 | D26: 382818
A28: Balance check (assets − liab. − net assets) | B28: 0 | C28: 0 | D28: 0
A30: Net PP&E is the reported ppe_net column (gross less accumulated depreciation). The balance check should be ~0 where all three totals are reported; a non-zero value flags a reporting or extraction discrepancy worth reviewing.

Sheet Form 990-EZ Parts I & II
A1: East Valley Farms Mutual Water Company
A2: Form 990-EZ - Part I (revenue, expenses, net assets) and Part II (balance sheet), as filed (USD)
A3: Entity ID: cawc_0090 | Fiscal year ends December 31.
A5: Form 990-EZ line | B5: FY2022 | C5: FY2024 | D5: FY2025
A6: Revenue (Part I)
A7: 2. Program service revenue | B7: 92554 | C7: 108745 | D7: 138280
A8: 3. Membership dues and assessments | B8: 32400 | C8: 32400 | D8: 32400
A9: 4. Investment income | B9: 421 | C9: 5055 | D9: 8142
A10: 9. Total revenue | B10: 125375 | C10: 146200 | D10: 178822
A12: Expenses (Part I)
A13: 13. Fees for services (independent contractors) | B13: 3857 | C13: 10088 | D13: 15838
A14: 14. Occupancy, rent, utilities, maintenance | B14: not reported | C14: not reported | D14: 54705
A15: 16. Other expenses | B15: 87927 | C15: 94976 | D15: 52390
A16: 17. Total expenses | B16: =SUM(B13:B15) | C16: =SUM(C13:C15) | D16: =SUM(D13:D15)
A18: Net-assets reconciliation (Part I)
A19: 19. Net assets or fund balances, beginning of year | B19: 278524 | C19: 321562 | D19: 321562
A20: 18. Excess or (deficit) for the year | B20: 33591 | C20: 41136 | D20: 55889
A21: 21. Net assets or fund balances, end of year | B21: =SUM(B19,B20) | C21: =SUM(C19,C20) | D21: =SUM(D19,D20)
A23: Balance sheet (Part II, end of year - column B)
A24: 22. Cash, savings, and investments | B24: 291567 | C24: 324487 | D24: 371617
A25: 24. Other assets | B25: 22549 | C25: 27663 | D25: 14456
A26: 25. Total assets | B26: =SUM(B24:B25) | C26: =SUM(C24:C25) | D26: =SUM(D24:D25)
A27: 26. Total liabilities | B27: 8088 | C27: 6975 | D27: 3255
A28: 27. Net assets or fund balances | B28: 306028 | C28: 345175 | D28: 382818
A30: Form 990-EZ is the short form: revenue and expenses are on Part I and the balance sheet is the six-line Part II (no full-990 Parts VII-XI). Total expenses (line 17) and Total assets (line 25) are live SUMs of the lines above; Total revenue (line 9) is shown as filed because the EZ nets its lines 5-7 (sales of assets, gaming, inventory) into line 9 without itemizing them. Ending net assets (line 21) is recomputed live as beginning net assets (line 19) plus the excess or deficit (line 18); where the filer's own line 21 does not equal that sum, the variance is flagged red on the Sources & audit tab and carried exactly as filed, not reconciled. Every figure's citation and confidence are on the Sources & audit tab.

Sheet Cash flow proxies
A1: East Valley Farms Mutual Water Company
A2: Cash Flow Proxies - derived (USD)
A3: Entity ID: cawc_0090 | Fiscal year ends December 31.
A5: PROXY ONLY. The source filings contain no statement of cash flows. Lines below are derived from the reported income statement and year-over-year balance-sheet changes; treat as directional estimates, not GAAP cash flows. The earliest year has no prior period, so its delta cells are blank.
A7: Proxy line (USD) | B7: FY2022 | C7: FY2024 | D7: FY2025
A8: Operating
A9: Net income | B9: 33591 | C9: 41136 | D9: 55889
A10: + Depreciation (reported)
A11: − Δ Accounts receivable
A12: − Δ Inventories
A13: − Δ Prepaid expenses
A14: + Δ Accounts payable
A15: Operating cash flow proxy | C15: 41136 | D15: 55889
A17: Investing
A18: − Δ PP&E gross (capex proxy)
A20: Financing
A21: Δ Mortgages & notes payable
A23: Reconciliation
A24: Δ Cash + temp. investments (actual) | C24: 32920 | D24: 47130
A26: The capex proxy assumes gross PP&E rises only via capital spending (it ignores disposals). 'Δ Cash + temp. investments (actual)' is the real reported change in liquid funds and is the most reliable line here; the operating/investing/financing proxies will not perfectly reconcile to it.

Sheet Ratios
A1: East Valley Farms Mutual Water Company
A2: Financial Ratios
A3: Entity ID: cawc_0090 | Fiscal year ends December 31.
A5: Ratio | B5: FY2022 | C5: FY2024 | D5: FY2025
A6: Profitability (computed upstream)
A7: Operating margin (NI / revenue) | B7: 0.26792423 | C7: 0.28136799 | D7: 0.31253984
A8: Expense ratio (expenses / revenue) | B8: 0.73207577 | C8: 0.71863201 | D8: 0.68746016
A9: Return on assets (NI / assets) | B9: 0.1069382 | C9: 0.11681386 | D9: 0.14476278
A10: Revenue growth (YoY)
A12: Leverage & solvency
A13: Debt-to-assets (liab. / assets) | B13: 0.02574845 | C13: 0.0198069 | D13: 0.008431048
A14: Equity ratio (net assets / assets) | B14: 0.97425155 | C14: 0.9801931 | D14: 0.99156895
A16: Liquidity & asset profile (derived here)
A17: Current ratio (current assets / AP)
A18: Cash ratio ((cash+temp inv.) / total liab.) | B18: 36.049332 | C18: 46.521434 | D18: 114.16805
A19: Asset age proxy (accum. deprec. / gross PP&E)
A21: Upstream ratios are read from financials_annual; derived ratios are computed only where inputs are reported. Current ratio uses accounts payable as the current-liability proxy (the filings do not split current vs. long-term liabilities). Asset age proxy: a higher % implies older / more depreciated infrastructure.

Sheet Unit economics
A1: East Valley Farms Mutual Water Company
A2: Unit economics - per-customer revenue by category (USD)
A3: Entity ID: cawc_0090 | Fiscal year ends December 31.
A5: Every metric here is PER CUSTOMER (a metered service connection). It is not a per-member figure; the member (shareholder) count is a different denominator, shown in the denominator block. The visible cell shows the value and its classification; the numerator, denominator, formula, and rationale are in each metric's LOGIC popup.
A6: Per-customer denominator (service connections) | C6: State Water Board eAR Section 4
A7: Total annual revenue (eAR Section 8b B1.8) | C7: eAR Section 8b total annual revenue not reported for this system.
A8: Primary source
A10: Revenue categories (value, classification, per customer, share)
A11: Revenue category | B11: Classification | C11: Value (USD) | D11: Per customer | E11: Share of revenue
A12: Water sales revenue | B12: not reported | C12: not reported | D12: not reported | E12: not reported
A13: Assessment revenue (990 program-service revenue not matched to eAR water-rate revenue) | B13: IMPOSSIBLE | C13: IMPOSSIBLE | D13: IMPOSSIBLE | E13: IMPOSSIBLE
A14: Meter revenue | B14: not reported | C14: not reported | D14: not reported | E14: not reported
A15: Overage or tiered penalty revenue | B15: not reported | C15: not reported | D15: not reported | E15: not reported
A17: Water sales revenue - not reported
A18: Not reported: this system filed an eAR but no Section 8b revenue block, so there is no filed water-sales figure. Not fallen back to a different year.
A19: Reason: No filed eAR Section 8b water-rate revenue for this system.
A21: Assessment revenue (990 program-service revenue not matched to eAR water-rate revenue) - IMPOSSIBLE
A22: Not computed. A period-aligned residual is not possible for this filer.
A23: Reason: Not derivable. The eAR Section 8b is reporting year None while the Form 990 fiscal year ends None; the two period ends are not aligned, so a period-aligned residual cannot be computed.
A25: Meter revenue - not reported
A26: Not reported. This category is not built because doing so would double-count.
A27: Reason: The eAR Section 8a reports a base/meter rate PRICE, but the filing carries no meter revenue line and no tier volume, and the base charge is already inside the water-sales revenue (eAR Section 8b water rates). Building a separate meter figure would double-count. Not backed into from a total.
A29: Overage or tiered penalty revenue - not reported
A30: Not reported. This category is not built because doing so would double-count.
A31: Reason: The eAR Section 8a reports tiered/overage rate PRICES, but the filing carries no overage revenue and no tier consumption volume, and any overage billed is already inside the water-sales revenue. Building it would double-count. Not backed into from a total.

Sheet Rate structure
A1: East Valley Farms Mutual Water Company
A2: Rate structure and representative bill - eAR Section 8a
A3: Entity ID: cawc_0090 | Fiscal year ends December 31.
A5: This block is a rate-schedule illustration at defined usage levels. It is NOT billed revenue and not a claim about any real customer's usage. The revenue side of unit economics is the separate Unit Economics block.
A6: No filed eAR Section 8a rate schedule is staged for this system.

Sheet Operational metrics
A1: East Valley Farms Mutual Water Company
A2: Operational metrics - plant per acre, density, terrain
A3: Entity ID: cawc_0090 | Fiscal year ends December 31.
A5: Connections per acre
A6: Connections per acre | B6: 0.14 | C6: 45 connections / 321.5 acres. CA State Water Board SABL SERVICE_CONNECTIONS; Geodesic area (WGS84 spherical excess) of the SABL service-area polygon.

Sheet Supply & weather
A1: East Valley Farms Mutual Water Company
A2: Supply and weather indicators (DWR water year)
A3: Entity ID: cawc_0090 | Fiscal year ends December 31.
A5: Reporting calendar: Different reporting periods. The DWR water year runs October 1 to September 30; this system's fiscal year ends December 31, so the two period ends are three months apart. Read the two side by side with that in mind. Neither series is recast: both are reported as filed. A water year is named for the calendar year it ends in, so WY2024 and FY2024 share a number without covering the same twelve months.
A7: Indicator | B7: WY2022 | C7: WY2024 | D7: WY2025
A8: Water-year type (Sacramento Valley) | B8: Critical | C8: Above Normal | D8: not reported
A9: Peak drought, county County | B9: not reported | C9: not reported | D9: not reported
A10: Precip, percent of normal (8-Station Index) | B10: 86 | C10: 96 | D10: 113
A11: Snowpack, April 1 percent of average | B11: 38% | C11: 110% | D11: 96%
A12: State Water Project allocation | B12: 5% | C12: 40% | D12: 50%

Sheet How this was built
A1: East Valley Farms Mutual Water Company
A2: How this was built - forensic lineage
A3: Entity ID: cawc_0090 | Fiscal year ends December 31.
A5: A plain account of the forensic lineage behind the hard-to-source metrics: what sources were checked, what was found, what was derived, and what could not be built and why. Every figure marked DERIVED or IMPOSSIBLE above is traceable to a line here.
A7: Water-sales revenue per customer - not reported
A8: Sources checked | B8: State Water Board eAR Section 8b (water-rate revenue B1.1/B1.2); State Water Board eAR Section 4 (connection count, same reporting year); audited financial statement (secondary cross-check, where published)
A9: What was found | B9: The eAR Section 8b reports water-rate revenue for reporting year None, so this is a DIRECT filed figure; per customer it is divided by the eAR Section 4 connection count for the same reporting year, so numerator and denominator share the year.
A11: Assessment revenue (residual) - IMPOSSIBLE
A12: Sources checked | B12: Form 990 Part VIII line 2 (program-service revenue); State Water Board eAR Section 8b (water-rate revenue B1.1/B1.2); eAR Section 8b filer comment (WRRevenueComments)
A13: What was found | B13: A period-aligned residual cannot be computed for this filer, so the metric is rendered IMPOSSIBLE rather than guessed.
A14: Caveat | B14: Not derivable. The eAR Section 8b is reporting year None while the Form 990 fiscal year ends None; the two period ends are not aligned, so a period-aligned residual cannot be computed.
A16: Meter revenue - not reported
A17: Sources checked | B17: State Water Board eAR Section 8a (rate prices); State Water Board eAR Section 8b (revenue lines); audited financial statement
A18: What was found | B18: The rate price exists in Section 8a but no revenue or tier volume is reported, and the base charge is already inside water sales.
A19: Caveat | B19: The eAR Section 8a reports a base/meter rate PRICE, but the filing carries no meter revenue line and no tier volume, and the base charge is already inside the water-sales revenue (eAR Section 8b water rates). Building a separate meter figure would double-count. Not backed into from a total.
A21: Overage / tiered-penalty revenue - not reported
A22: Sources checked | B22: State Water Board eAR Section 8a (rate prices); State Water Board eAR Section 8b (revenue lines); audited financial statement
A23: What was found | B23: The rate price exists in Section 8a but no revenue or tier volume is reported, and the base charge is already inside water sales.
A24: Caveat | B24: The eAR Section 8a reports tiered/overage rate PRICES, but the filing carries no overage revenue and no tier consumption volume, and any overage billed is already inside the water-sales revenue. Building it would double-count. Not backed into from a total.
A26: eAR Section 8b reporting-period basis - sourced
A27: Sources checked | B27: eAR Section 8b B0.1 (WRFinancialReportingPeriod); eAR Section 8b B0.2 (WRFiscalYearStartDate)
A28: What was found | B28: The reporting basis (fiscal vs calendar year) is read from the filer's own B0.1/B0.2 answer and staged verbatim, never hardcoded, so the 990 comparison and the residual are period-aligned.
A30: Member (shareholder) count denominator - not reported
A31: Sources checked | B31: Form 990 (no member count stated); company website
A32: What was found | B32: No filing states a member/shareholder count, so the per-member unit economics read not reported rather than borrowing the connection count.
A34: Water volume delivered (acre-feet) - not reported
A35: Sources checked | B35: Form 990 (not in the filing); Consumer Confidence Report; eAR Section 6 (PRA-gated)
A36: What was found | B36: Volume delivered in acre-feet is not in the Form 990 and the CCR states only a source mix, so the per-acre-foot metrics read not reported; the eAR Section 6 is named as the source still needed.

Sheet Anomaly Flags
A1: East Valley Farms Mutual Water Company
A2: Anomaly Flags (automated; kept separate from the clean statements)
A3: Entity ID: cawc_0090 | Fiscal year ends December 31.
A5: Material irregularities found automatically in the filed financials by the Hydronomics anomaly flagger. Each flag has two clearly separated layers. WHAT is mechanical, certain, and sourced: the exact filed lines, years, and amounts, carried as filed and never reconciled. WHY is attempted: the filing's own narrative is checked first, and when it states no reason a single best-guess hypothesis is shown, clearly labelled as a guess that is not in the filing and is not a verified figure.
A7: Flag: FY2025 opening net assets differ from FY2024 closing
A8: Affected figure | B8: Net assets FY2025
A9: Confidence | B9: high
A10: What happened (filed, sourced) | B10: The company filed $321,562 as its beginning net assets for FY2025 and $345,175 as its ending net assets for FY2024, a difference of $-23,613. Both figures are carried exactly as each year's own filing reports them. Neither is adjusted to match the other.
A11: Source lines | B11: - FY2025 net assets, beginning of year (as filed): $321,562 - FY2024 net assets, end of year (as filed): $345,175 - Difference: $-23,613
A12: Confidence reasoning | B12: Both are direct filed line items read from two different returns, so the difference between them is high confidence as an observation. What caused it is not stated on either form.
A13: Why (not stated in the filing) | B13: The filing does not state a reason.
A14: Possible explanation (guess) | B14: Possible explanation, not stated in filing: a beginning balance that differs from the prior year's ending balance usually means the earlier year was restated, or a balance-sheet line was reclassified between the two filings. This is an educated guess, not something either filing says.

Sheet Sources & audit
A1: East Valley Farms Mutual Water Company
A2: Sources & audit - full provenance and tie-outs (kept off the statements so they read clean)
A3: Entity ID: cawc_0090 | Fiscal year ends December 31.
A5: Presentation standard: every figure on the statement tabs is verified to its source filing and shown clean. A cell the filing does not report reads "not reported" (never estimated, never guessed).
A6: Citations, confidence tiers, and the filed-vs-computed tie-out checks live on the "Sources & audit" tab, keyed by cell, so every number is fully traceable without cluttering the statements. These pages are ready to use as filed.
A8: A. Filing provenance (one row per staged extraction)
A9: Fiscal year | B9: Period end | C9: Filing type | D9: Confidence | E9: Extraction ID | F9: Object ID | G9: Extracted by | H9: Extracted at | I9: Source URL
A10: FY2022 | B10: 2022-12-31 | C10: 990-EZ | D10: low | E10: 268688ea-416f-4896-bf9c-af2528faca8e | F10: 202542269349200839 | G10: claude-opus-5 | H10: 2026-09-21T02:50:02+00:00 | I10: https://apps.irs.gov/pub/epostcard/990/xml/2025/2025_TEOS_XML_08A.zip#202542269349200839_public.xml
A11: FY2024 | B11: 2024-12-31 | C11: 990-EZ | D11: high | E11: 11c7c479-d461-4889-92e8-38b24a8f2660 | F11: 202511509349200841 | G11: claude-opus-5 | H11: 2026-09-21T02:50:02+00:00 | I11: https://apps.irs.gov/pub/epostcard/990/xml/2025/2025_TEOS_XML_06A.zip#202511509349200841_public.xml
A12: FY2025 | B12: 2025-12-31 | C12: 990-EZ | D12: high | E12: 5b72a320-29a4-4962-8955-a7e4b037da26 | F12: 202641499349200744 | G12: claude-opus-5 | H12: 2026-09-21T02:50:02+00:00 | I12: https://apps.irs.gov/pub/epostcard/990/xml/2026/2026_TEOS_XML_06A.zip#202641499349200744_public.xml
A14: B. Figure citations (every figure on the statement tabs, keyed by cell)
A15: Tab | B15: Cell | C15: Line item | D15: Form 990 line | E15: Key path | F15: Confidence | G15: As filed
A16: Form 990-EZ Parts I & II | B16: B7 | C16: 2. Program service revenue | D16: Part I line 2 | E16: part_i_revenue_expenses.program_service_revenue | F16: high | G16: 92554
A17: Form 990-EZ Parts I & II | B17: C7 | C17: 2. Program service revenue | D17: Part I line 2 | E17: part_i_revenue_expenses.program_service_revenue | F17: high | G17: 108745
A18: Form 990-EZ Parts I & II | B18: D7 | C18: 2. Program service revenue | D18: Part I line 2 | E18: part_i_revenue_expenses.program_service_revenue | F18: high | G18: 138280
A19: Form 990-EZ Parts I & II | B19: B8 | C19: 3. Membership dues and assessments | D19: Part I line 3 | E19: part_i_revenue_expenses.membership_dues | F19: high | G19: 32400
A20: Form 990-EZ Parts I & II | B20: C8 | C20: 3. Membership dues and assessments | D20: Part I line 3 | E20: part_i_revenue_expenses.membership_dues | F20: high | G20: 32400
A21: Form 990-EZ Parts I & II | B21: D8 | C21: 3. Membership dues and assessments | D21: Part I line 3 | E21: part_i_revenue_expenses.membership_dues | F21: high | G21: 32400
A22: Form 990-EZ Parts I & II | B22: B9 | C22: 4. Investment income | D22: Part I line 4 | E22: part_i_revenue_expenses.investment_income | F22: high | G22: 421
A23: Form 990-EZ Parts I & II | B23: C9 | C23: 4. Investment income | D23: Part I line 4 | E23: part_i_revenue_expenses.investment_income | F23: high | G23: 5055
A24: Form 990-EZ Parts I & II | B24: D9 | C24: 4. Investment income | D24: Part I line 4 | E24: part_i_revenue_expenses.investment_income | F24: high | G24: 8142
A25: Form 990-EZ Parts I & II | B25: B10 | C25: 9. Total revenue | D25: Part I line 9 | E25: part_i_revenue_expenses.total_revenue | F25: high | G25: 125375
A26: Form 990-EZ Parts I & II | B26: C10 | C26: 9. Total revenue | D26: Part I line 9 | E26: part_i_revenue_expenses.total_revenue | F26: high | G26: 146200
A27: Form 990-EZ Parts I & II | B27: D10 | C27: 9. Total revenue | D27: Part I line 9 | E27: part_i_revenue_expenses.total_revenue | F27: high | G27: 178822
... A52: Form 990-EZ Parts I & II | B52: D28 | C52: 27. Net assets or fund balances | D52: Part II line 27 col B | E52: part_ii_balance_sheet.net_assets_eoy | F52: high | G52: 382818
A54: C. Tie-out checks (filed vs computed; any nonzero variance is flagged red)
A55: Tab | B55: Check | C55: Fiscal year | D55: Filed | E55: Computed | F55: Variance (computed - filed)
A56: Form 990-EZ Parts I & II | B56: 17. Total expenses | C56: FY2022 | D56: 91784 | E56: ='Form 990-EZ Parts I & II'!B16 | F56: =E56-D56
A57: Form 990-EZ Parts I & II | B57: 17. Total expenses | C57: FY2024 | D57: 105064 | E57: ='Form 990-EZ Parts I & II'!C16 | F57: =E57-D57
A58: Form 990-EZ Parts I & II | B58: 17. Total expenses | C58: FY2025 | D58: 122933 | E58: ='Form 990-EZ Parts I & II'!D16 | F58: =E58-D58
A59: Form 990-EZ Parts I & II | B59: 21. Net assets or fund balances, end of year | C59: FY2022 | D59: 314116 | E59: ='Form 990-EZ Parts I & II'!B21 | F59: =E59-D59
A60: Form 990-EZ Parts I & II | B60: 21. Net assets or fund balances, end of year | C60: FY2024 | D60: 345175 | E60: ='Form 990-EZ Parts I & II'!C21 | F60: =E60-D60
A61: Form 990-EZ Parts I & II | B61: 21. Net assets or fund balances, end of year | C61: FY2025 | D61: 382818 | E61: ='Form 990-EZ Parts I & II'!D21 | F61: =E61-D61
A62: Form 990-EZ Parts I & II | B62: 25. Total assets | C62: FY2022 | D62: 314116 | E62: ='Form 990-EZ Parts I & II'!B26 | F62: =E62-D62
A63: Form 990-EZ Parts I & II | B63: 25. Total assets | C63: FY2024 | D63: 352150 | E63: ='Form 990-EZ Parts I & II'!C26 | F63: =E63-D63
A64: Form 990-EZ Parts I & II | B64: 25. Total assets | C64: FY2025 | D64: 386073 | E64: ='Form 990-EZ Parts I & II'!D26 | F64: =E64-D64
A65: Form 990-EZ Parts I & II | B65: Balance sheet identity: line 25 = line 26 + line 27 (EOY) | C65: FY2022 | D65: ='Form 990-EZ Parts I & II'!B26 | E65: =SUM('Form 990-EZ Parts I & II'!B27,'Form 990-EZ Parts I & II'!B28) | F65: =E65-D65
A66: Form 990-EZ Parts I & II | B66: Balance sheet identity: line 25 = line 26 + line 27 (EOY) | C66: FY2024 | D66: ='Form 990-EZ Parts I & II'!C26 | E66: =SUM('Form 990-EZ Parts I & II'!C27,'Form 990-EZ Parts I & II'!C28) | F66: =E66-D66
A67: Form 990-EZ Parts I & II | B67: Balance sheet identity: line 25 = line 26 + line 27 (EOY) | C67: FY2025 | D67: ='Form 990-EZ Parts I & II'!D26 | E67: =SUM('Form 990-EZ Parts I & II'!D27,'Form 990-EZ Parts I & II'!D28) | F67: =E67-D67
A69: D. Preparer / auditor trail (one row per fiscal year, as filed)
...

Sheet Provenance
A1: Build provenance | B1: Built from source commit d418ffb17485 (2026-10-06); source fingerprint a75a8eee82c65cf7; 192 companies (179 retail mutual, 4 irrigation mutual, 3 mutual, no PWSID, purpose not stated, 2 frozen non-mutual (special district), 2 wholesale mutual, 1 frozen non-mutual (investor-owned), 1 frozen non-mutual (municipal)); 91 gates; build id 3d08d6d2a855.
A2: source_commit | B2: d418ffb174855ab78000d391d42f898397b0d8aa
A3: source_commit_date | B3: 2026-10-06
A4: source_fingerprint | B4: a75a8eee82c65cf7096931f06e18affdc28686a02895b46538e7298b57c04d94
A5: gate_count | B5: 91
A6: build_id | B6: 3d08d6d2a855
A7: registry: frozen non-mutual (investor-owned) | B7: 1
A8: registry: frozen non-mutual (municipal) | B8: 1
A9: registry: frozen non-mutual (special district) | B9: 2
A10: registry: irrigation mutual | B10: 4
A11: registry: mutual, no PWSID, purpose not stated | B11: 3
A12: registry: retail mutual | B12: 179
A13: registry: wholesale mutual | B13: 2
